Workbook

Sheet Sheet1
A3: Row Labels | B3: Count of Application Long Name | C3: Sum of Current FTC | D3: Sum of Current FTE | E3: Sum of Current MGCC | F3: Sum of Target # of FTC | H3: Reduction by Area
A4: Common Service Platform | B4: 10 | C4: 98.095708 | D4: 35.314583 | E4: 65.37 | F4: 99.390146 | H4: =C4-F4 -> -1.2944375
A5: contract management | B5: 28 | C5: 203.93583 | D5: 26.814167 | E5: 0 | F5: 115.375 | H5: =C5-F5 -> 88.560833
A6: Corporate Related | B6: 33 | C6: 36.744706 | D6: 12.194167 | E6: 1.5 | F6: 25.219436 | H6: =C6-F6 -> 11.52527
A7: Customer Care / Call Center Related | B7: 8 | C7: 55.747917 | D7: 42.233333 | E7: 22.910417 | F7: 60.445833 | H7: =C7-F7 -> -4.6979167
A8: Data Infrastructure | B8: 3 | C8: 64.704594 | D8: 18.825 | E8: 15.991667 | F8: 50.382484 | H8: =C8-F8 -> 14.322109
A9: Fee Management | B9: 5 | C9: 38.147792 | D9: 9.7791667 | E9: 0.58333333 | F9: 24.255146 | H9: =C9-F9 -> 13.892646
A10: Insurance Claims and Benefits Payment Related | B10: 6 | C10: 85.448458 | D10: 13.479167 | E10: 22.645833 | F10: 60.786729 | H10: =C10-F10 -> 24.661729
A11: Marketing/Direct Business Related | B11: 9 | C11: 27.842083 | D11: 7.5270833 | E11: 8.785 | F11: 22.077083 | H11: =C11-F11 -> 5.765
A12: New Contract Related | B12: 12 | C12: 40.463542 | D12: 1.0270833 | E12: 0 | F12: 20.245313 | H12: =C12-F12 -> 20.218229
A13: Sales / Insurance Recruitment | B13: 13 | C13: 267.93104 | D13: 81.104167 | E13: 91.220833 | F13: 219.35698 | H13: =C13-F13 -> 48.574063
A14: Storage and Preservation Related | B14: 15 | C14: 25.462458 | D14: 25.966667 | E14: 11 | F14: 54.453875 | H14: =C14-F14 -> -28.991417
A15: Grand Total | B15: 142 | C15: 944.52413 | D15: 274.26458 | E15: 240.00708 | F15: 751.98803 | H15: =C15-F15 -> 192.53611
H16: =C16-F16 -> 0
H17: =C17-F17 -> 0
H18: =C18-F18 -> 0
A19: Row Labels | B19: Count of Application Long Name | C19: Sum of Current FTC | D19: Sum of Current FTE | E19: Sum of Current MGCC | F19: Sum of Target # of FTC | H19: Reduction by Practice
A20: Cloud | B20: 100 | C20: 618.29037 | D20: 193.12958 | E20: 202.64542 | F20: 529.00096 | H20: =C20-F20 -> 89.289416
A21: Data | B21: 3 | C21: 64.704594 | D21: 18.825 | E21: 15.991667 | F21: 50.382484 | H21: =C21-F21 -> 14.322109
A22: Digital | B22: 5 | C22: 41.781 | D22: 24.322917 | E22: 21.328333 | F22: 43.716125 | H22: =C22-F22 -> -1.935125
A23: Corporate Related | B23: 1 | C23: 2.4426667 | D23: 0.57083333 | E23: 0 | F23: 1.50675 | H23: =C23-F23 -> 0.93591667
A24: Customer Care / Call Center Related | B24: 1 | C24: 9.5833333 | D24: 11.3375 | E24: 7.0833333 | F24: 14.002083 | H24: =C24-F24 -> -4.41875
A25: Himawari | B25: 1 | C25: 9.5833333 | D25: 11.3375 | E25: 7.0833333 | F25: 14.002083 | H25: =C25-F25 -> -4.41875
A26: Fee Management | B26: 1 | F26: 0 | H26: =C26-F26 -> 0
A27: Marketing/Direct Business Related | B27: 1 | C27: 8.9216667 | D27: 2.4104167 | E27: 1.52 | F27: 6.4260417 | H27: =C27-F27 -> 2.495625
A28: Sales / Insurance Recruitment | B28: 1 | C28: 20.833333 | D28: 10.004167 | E28: 12.725 | F28: 21.78125 | H28: =C28-F28 -> -0.94791667
A29: WPSCFC-JPN | B29: 1 | C29: 20.833333 | D29: 10.004167 | E29: 12.725 | F29: 21.78125 | H29: =C29-F29 -> -0.94791667
A30: Mainframe | B30: 28 | C30: 207.90404 | D30: 29.60375 | E30: 0 | F30: 118.7539 | H30: =C30-F30 -> 89.150146
A31: contract management | B31: 26 | C31: 202.76654 | D31: 26.50375 | E31: 0 | F31: 114.63515 | H31: =C31-F31 -> 88.131396
A32: ASP Bridge(H) MF-JPN | B32: 1 | C32: 6.7267083 | D32: 1.4625 | E32: 0 | F32: 4.0946042 | H32: =C32-F32 -> 2.6321042
A33: CCA MF-JPN | B33: 1 | C33: 1.6308333 | D33: 0 | E33: 0 | F33: 0.81541667 | H33: =C33-F33 -> 0.81541667
A34: CT Salary MF-JPN | B34: 1 | C34: 0.2 | D34: 0 | E34: 0 | F34: 0.1 | H34: =C34-F34 -> 0.1
A35: Data Send System for BANC MF-JP | B35: 1 | C35: 9.2697083 | D35: 2.8458333 | E35: 0 | F35: 6.0577708 | H35: =C35-F35 -> 3.2119375
A36: Foreign MF-JPN | B36: 1 | F36: 0 | H36: =C36-F36 -> 0
A37: LC AACOMP MF-JPN | B37: 1 | C37: 13.545708 | D37: 3.14375 | E37: 0 | F37: 8.3447292 | H37: =C37-F37 -> 5.2009792
A38: LC AAPerf MF-JPN | B38: 1 | C38: 10.784167 | D38: 0.74583333 | E38: 0 | F38: 5.765 | H38: =C38-F38 -> 5.0191667
A39: LC Billing MF-JPN | B39: 1 | C39: 20.892167 | D39: 1.85375 | E39: 0 | F39: 11.372958 | H39: =C39-F39 -> 9.5192083
A40: LC Collection MF-JPN | B40: 1 | F40: 0 | H40: =C40-F40 -> 0
A41: LC Corresponding MF-JPN | B41: 1 | C41: 15.953625 | D41: 1.6541667 | E41: 0 | F41: 8.8038958 | H41: =C41-F41 -> 7.1497292
A42: LC GL/SC MF-JPN | B42: 1 | C42: 5.28875 | D42: 1.025 | E42: 0 | F42: 3.156875 | H42: =C42-F42 -> 2.131875
...

Sheet Sheet3
A3: Count of EAI Application ID | B3: Column Labels
A4: Row Labels | B4: Cloud | C4: Data | D4: Digital | E4: Mainframe | F4: (blank) | G4: Grand Total
A5: Common Service Platform | B5: 9 | F5: 1 | G5: 10
A6: contract management | B6: 2 | E6: 26 | G6: 28
A7: Corporate Related | B7: 29 | D7: 1 | E7: 2 | F7: 1 | G7: 33
A8: Customer Care / Call Center Related | B8: 6 | D8: 1 | F8: 1 | G8: 8
A9: Data Infrastructure | C9: 3 | G9: 3
A10: Fee Management | B10: 4 | D10: 1 | G10: 5
A11: Insurance Claims and Benefits Payment Related | B11: 6 | G11: 6
A12: Marketing/Direct Business Related | B12: 8 | D12: 1 | G12: 9
A13: New Contract Related | B13: 12 | G13: 12
A14: Sales / Insurance Recruitment | B14: 12 | D14: 1 | G14: 13
A15: Storage and Preservation Related | B15: 12 | F15: 3 | G15: 15
A16: Grand Total | B16: 100 | C16: 3 | D16: 5 | E16: 28 | F16: 6 | G16: 142
A18: Y/N | B18: (All)
B20: Column Labels
B21: Cloud | D21: Data | F21: Digital | H21: Mainframe | J21: (blank) | L21: Total Count of EAI Application ID | M21: Total Sum of Total
A22: Row Labels | B22: Count of EAI Application ID | C22: Sum of Total | D22: Count of EAI Application ID | E22: Sum of Total | F22: Count of EAI Application ID | G22: Sum of Total | H22: Count of EAI Application ID | I22: Sum of Total | J22: Count of EAI Application ID | K22: Sum of Total
A23: Common Service Platform | B23: 9 | C23: 198.53029 | J23: 1 | K23: 0.25 | L23: 10 | M23: 198.78029
A24: contract management | B24: 2 | C24: 1.4797083 | H24: 26 | I24: 229.27029 | L24: 28 | M24: 230.75
A25: Corporate Related | B25: 29 | C25: 38.408706 | F25: 1 | G25: 3.0135 | H25: 2 | I25: 8.2375 | J25: 1 | K25: 0.77916667 | L25: 33 | M25: 50.438873
A26: Customer Care / Call Center Related | B26: 6 | C26: 86.485 | F26: 1 | G26: 28.004167 | J26: 1 | K26: 6.4025 | L26: 8 | M26: 120.89167
A27: Data Infrastructure | D27: 3 | E27: 100.76497 | L27: 3 | M27: 100.76497
A28: Fee Management | B28: 4 | C28: 48.510292 | F28: 1 | L28: 5 | M28: 48.510292
A29: Insurance Claims and Benefits Payment Related | B29: 6 | C29: 121.57346 | L29: 6 | M29: 121.57346
A30: Marketing/Direct Business Related | B30: 8 | C30: 31.302083 | F30: 1 | G30: 12.852083 | L30: 9 | M30: 44.154167
A31: New Contract Related | B31: 12 | C31: 40.490625 | L31: 12 | M31: 40.490625
A32: Sales / Insurance Recruitment | B32: 12 | C32: 395.15146 | F32: 1 | G32: 43.5625 | L32: 13 | M32: 438.71396
A33: Storage and Preservation Related | B33: 12 | C33: 96.070292 | J33: 3 | K33: 12.837458 | L33: 15 | M33: 108.90775
A34: Grand Total | B34: 100 | C34: 1058.0019 | D34: 3 | E34: 100.76497 | F34: 5 | G34: 87.43225 | H34: 28 | I34: 237.50779 | J34: 6 | K34: 20.269125 | L34: 142 | M34: 1503.9761

Sheet ApplicationList
AM1: =AM3/AH3 -> 0.56752605 | AN1: Composition of Run | AR1: =SUM(AR3:AS3) -> 5.4512917 | AT1: =SUM(AT3:BA3) -> #REF!
AE3: =SUBTOTAL(9,AE5:AE146) -> 3.7637917 | AF3: =SUBTOTAL(9,AF5:AF146) -> 1.6875 | AG3: =SUBTOTAL(9,AG5:AG146) -> 0 | AH3: =SUBTOTAL(9,AH5:AH146) -> 5.4512917 | AI3: =SUBTOTAL(9,AI5:AI146) -> 1.4892072 | AJ3: =SUBTOTAL(9,AJ5:AJ146) -> 2.7256458 | AK3: =SUBTOTAL(9,AK5:AK146) -> 2.7256458 | AM3: =SUBTOTAL(9,AM5:AM146) -> 3.09375 | AN3: Capgemini Presence | AR3: =SUBTOTAL(9,AR5:AR146) -> 2.3575417 | AS3: =SUBTOTAL(9,AS5:AS146) -> 3.09375 | AT3: =SUBTOTAL(9,AT5:AT146) -> #REF! | AU3: =SUBTOTAL(9,AU5:AU146) -> #REF! | AV3: =SUBTOTAL(9,AV5:AV146) -> #REF! | AW3: =SUBTOTAL(9,AW5:AW146) -> #REF! | AX3: =SUBTOTAL(9,AX5:AX146) -> #REF! | AY3: =SUBTOTAL(9,AY5:AY146) -> #REF! | ... BA3: =SUBTOTAL(9,BA5:BA146) -> #REF!
A4: AD Coverage | B4: AMS Coverage | C4: QA Coverage | D4: Remarks | E4: EAI Application ID | F4: Application | G4: Application Long Name | H4: Application Description | I4: domain | J4: Group | K4: Team | L4: Host Support structure | M4: Application Class | N4: Application Status | O4: Primary Support Team | P4: Critical Application Indicator | Q4: Business Sponsor LOB | R4: Internet Facing Application | S4: Application Hosting | T4: General Application Profile | U4: Operating System/ Platform | V4: Primary Code Language | W4: Application Source Code Ownership | X4: Cloud_Platform | Y4: Cloud_Indicator | Z4: In Scope | AA4: Development | AB4: conservative | AC4: Infrastructure Operation | AD4: Priority Transfer Targets | AE4: Current FTC | AF4: Current FTE | AG4: Current MGCC | AH4: Total | AI4: % of PRJ | AJ4: Target # of FTC | AK4: Target # of FTE/MGCC | AL4: Comments | AM4: RUN FTE (based on %PRJ) | AN4: Y/N | AO4: T3 HC | AP4: CSO_QA ScopeHC | AQ4: in FTE equivalent (basis Billing) | AR4: AD Scope (Assumed) | AS4: AM Scope(Assumed) | AT4: BA | AU4: BSA | AV4: Dev | AW4: Tester | AX4: SRE | AY4: Scrum Master | AZ4: Architects | BA4: AM | BB4: Is Total Changed
A5: Digital | B5: Yes | E5: 9629 | F5: Global Sales Comp - Japan | G5: Global Sales Comp - Japan | H5: Responsible for data integration (ETL) between ICM (11004) and Life-Comm. Runs on US environments. | I5: Fee Management | J5: Core Insurance Systems Group 34956 | K5: Commission Systems Team 34958 | L5: MetLife IT Hosted/Supported | M5: Core Business Application | N5: Production | O5: AD Supported | P5: N | Q5: Asia Region | R5: Yes | S5: Yes | T5: Other#Schduler / orchastration tool call servers batches. | V5: Other#Infomatica workflow Bash shell Dos batch | W5: Non-MetLife Owned Application Code (3rd party/COTS) | X5: Software as a Service (SaaS) | Y5: Yes | Z5: Y | AA5: Y | AB5: Y | AC5: N | AD5: N | AL5: The number of personnel is included in 11004. | AM5: =AH5*(1-AI5) -> 0 | AN5: =VLOOKUP($E5,'Capgemini PResence and HC'!$B$2:$G$143,4,0) -> N | AO5: =VLOOKUP($E5,'Capgemini PResence and HC'!$B$2:$G$143,2,0) -> 0 | AP5: =VLOOKUP($E5,'Capgemini PResence and HC'!$B$2:$G$143,3,0) -> 0 | AQ5: =VLOOKUP($E5,'Capgemini PResence and HC'!$B$2:$G$143,6,0) -> 0 | BB5: =SUM(AE5:AG5)-AH5 -> 0
A6: Mainframe | B6: Yes | E6: 9796 | F6: LC POSPMC MF-JPN | G6: LifeComm POSPMC | H6: A subsystem based on LifeComm (mainframe package). Responsible for transaction processing for the contract management master. As a business domain, it handles contract maintenance (such as name changes, address changes, cancellations, and reductions). We continue to utilize the functions built with assemblers, continuously developing assemblers for new product development, other development projects, and maintenance projects. | I6: contract management | J6: Core Insurance Systems Group 34956 | K6: Policy Admin Systems Team 34957 | L6: MetLife IT Hosted/Supported | M6: Core Business Application | N6: Production | O6: AD Supported | P6: Y | Q6: Global Technology & Operations | R6: No | S6: Yes | T6: Other#Mainframe | V6: Assembler, COBOL, MU(EASYPLUS), JCL | W6: MetLife Owned Application Code | Y6: No | Z6: Y | AA6: Y | AB6: Y | AC6: N | AD6: N | AE6: 59.558958 | AF6: 7.7541667 | AG6: 0 | AH6: 67.313125 | AI6: 0.71176374 | AJ6: 33.656562 | AK6: 33.656563 | AM6: =AH6*(1-AI6) -> 19.402083 | AN6: =VLOOKUP($E6,'Capgemini PResence and HC'!$B$2:$G$143,4,0) -> N | AO6: =VLOOKUP($E6,'Capgemini PResence and HC'!$B$2:$G$143,2,0) -> 0 | AP6: =VLOOKUP($E6,'Capgemini PResence and HC'!$B$2:$G$143,3,0) -> 0 | AQ6: =VLOOKUP($E6,'Capgemini PResence and HC'!$B$2:$G$143,6,0) -> 0 | BB6: =SUM(AE6:AG6)-AH6 -> 0
A7: Mainframe | B7: Yes | E7: 9800 | F7: LC Billing MF-JPN | G7: LifeComm Billing | H7: A subsystem based on LifeComm (mainframe package). As a business domain, it handles insurance premium claims and payment contract protection (such as name changes, address changes, cancellations, and reductions). While we maintain the features built with assembler, our company's main features are developed in COBOL, and except for table modifications, we are not continuously developing assemblers. | I7: contract management | J7: Core Insurance Systems Group 34956 | K7: Policy Admin Systems Team 34957 | L7: MetLife IT Hosted/Supported | M7: Core Business Application | N7: Production | O7: AD Supported | P7: Y | Q7: Global Technology & Operations | R7: No | S7: Yes | T7: Other#Mainframe | V7: COBOL, Assembler, MU(EASYPLUS), JCL | W7: MetLife Owned Application Code | Y7: No | Z7: Y | AA7: Y | AB7: Y | AC7: N | AD7: N | AE7: 20.892167 | AF7: 1.85375 | AG7: 0 | AH7: 22.745917 | AI7: 0.94285788 | AJ7: 11.372958 | AK7: 11.372958 | AM7: =AH7*(1-AI7) -> 1.29975 | AN7: =VLOOKUP($E7,'Capgemini PResence and HC'!$B$2:$G$143,4,0) -> N | AO7: =VLOOKUP($E7,'Capgemini PResence and HC'!$B$2:$G$143,2,0) -> 0 | AP7: =VLOOKUP($E7,'Capgemini PResence and HC'!$B$2:$G$143,3,0) -> 0 | AQ7: =VLOOKUP($E7,'Capgemini PResence and HC'!$B$2:$G$143,6,0) -> 0 | BB7: =SUM(AE7:AG7)-AH7 -> 0
A8: Mainframe | B8: Yes | E8: 9801 | F8: LC Collection MF-JPN | G8: LifeComm Collection | H8: A subsystem based on LifeComm (mainframe package). As a business domain, it handles insurance premium claims and payment contract protection (such as name changes, address changes, cancellations, and reductions). While we maintain the features built with assembler, our company's main features are developed in COBOL, and except for table modifications, we are not continuously developing assemblers. | I8: contract management | J8: Core Insurance Systems Group 34956 | K8: Policy Admin Systems Team 34957 | L8: MetLife IT Hosted/Supported | M8: Core Business Application | N8: Production | O8: AD Supported | P8: Y | Q8: Global Technology & Operations | R8: No | S8: Yes | T8: Other#Mainframe | V8: COBOL, Assembler, MU(EASYPLUS), JCL | W8: MetLife Owned Application Code | Y8: No | Z8: Y | AA8: Y | AB8: Y | AC8: N | AD8: N | AL8: The number of staff is included in the 9,800 | AM8: =AH8*(1-AI8) -> 0 | AN8: =VLOOKUP($E8,'Capgemini PResence and HC'!$B$2:$G$143,4,0) -> N | AO8: =VLOOKUP($E8,'Capgemini PResence and HC'!$B$2:$G$143,2,0) -> 0 | AP8: =VLOOKUP($E8,'Capgemini PResence and HC'!$B$2:$G$143,3,0) -> 0 | AQ8: =VLOOKUP($E8,'Capgemini PResence and HC'!$B$2:$G$143,6,0) -> 0 | BB8: =SUM(AE8:AG8)-AH8 -> 0
A9: Mainframe | B9: Yes | E9: 9802 | F9: LC Corresponding MF-JPN | G9: LifeComm Corresponding | H9: A subsystem based on LifeComm (mainframe package). As a business domain, it is responsible for guidance (form creation). While we maintain the features built with assembler, our company's main features are developed in COBOL, and except for table modifications, we are not continuously developing assemblers. | I9: contract management | J9: Core Insurance Systems Group 34956 | K9: Policy Admin Systems Team 34957 | L9: MetLife IT Hosted/Supported | M9: Core Business Application | N9: Production | O9: AD Supported | P9: Y | Q9: Global Technology & Operations | R9: No | S9: Yes | T9: Other#Mainframe | V9: COBOL, Assembler, MU(EASYPLUS), JCL | W9: MetLife Owned Application Code | Y9: No | Z9: Y | AA9: Y | AB9: Y | AC9: N | AD9: N | AE9: 15.953625 | AF9: 1.6541667 | AG9: 0 | AH9: 17.607792 | AI9: 0.98287217 | AJ9: 8.8038958 | AK9: 8.8038958 | AM9: =AH9*(1-AI9) -> 0.30158333 | AN9: =VLOOKUP($E9,'Capgemini PResence and HC'!$B$2:$G$143,4,0) -> N | AO9: =VLOOKUP($E9,'Capgemini PResence and HC'!$B$2:$G$143,2,0) -> 0 | AP9: =VLOOKUP($E9,'Capgemini PResence and HC'!$B$2:$G$143,3,0) -> 0 | AQ9: =VLOOKUP($E9,'Capgemini PResence and HC'!$B$2:$G$143,6,0) -> 0 | BB9: =SUM(AE9:AG9)-AH9 -> 0
A10: Mainframe | B10: Yes | E10: 9803 | F10: LC UWI MF-JPN | G10: LifeComm UWI | H10: A subsystem based on LifeComm (mainframe package). As a business domain, it handles part of new contracts and contract maintenance (such as price reductions). Some contract preservation functions utilize new contract features, resulting in overlap between EAI:9796 and business domains. We continue to utilize the functions built with assemblers, continuously developing assemblers for new product development, other development projects, and maintenance projects. | I10: contract management | J10: Core Insurance Systems Group 34956 | K10: Policy Admin Systems Team 34957 | L10: MetLife IT Hosted/Supported | M10: Core Business Application | N10: Production | O10: AD Supported | P10: Y | Q10: Global Technology & Operations | R10: No | S10: Yes | T10: Other#Mainframe | V10: Assembler, COBOL, MU(EASYPLUS), JCL | W10: MetLife Owned Application Code | Y10: No | Z10: Y | AA10: Y | AB10: Y | AC10: N | AD10: N | AE10: 8.8045833 | AF10: 0.85 | AG10: 0 | AH10: 9.6545833 | AI10: 0.94821113 | AJ10: 4.8272917 | AK10: 4.8272917 | AM10: =AH10*(1-AI10) -> 0.5 | AN10: =VLOOKUP($E10,'Capgemini PResence and HC'!$B$2:$G$143,4,0) -> N | AO10: =VLOOKUP($E10,'Capgemini PResence and HC'!$B$2:$G$143,2,0) -> 0 | AP10: =VLOOKUP($E10,'Capgemini PResence and HC'!$B$2:$G$143,3,0) -> 0 | AQ10: =VLOOKUP($E10,'Capgemini PResence and HC'!$B$2:$G$143,6,0) -> 0 | BB10: =SUM(AE10:AG10)-AH10 -> 0
A11: Mainframe | B11: Yes | E11: 9804 | F11: LC AAPerf MF-JPN | G11: LifeComm AgentAgencyPerformance | H11: A subsystem based on LifeComm (mainframe package). As a business domain, it is responsible for performance (number of new contract ANPs, number of held ANPs, retention rate, etc.). While we maintain the features built with assembler, our company's main features are developed in COBOL, and except for table modifications, we are not continuously developing assemblers. | I11: contract management | J11: Core Insurance Systems Group 34956 | K11: Policy Admin Systems Team 34957 | L11: MetLife IT Hosted/Supported | M11: Core Business Application | N11: Production | O11: AD Supported | P11: Y | Q11: Asia Region | R11: No | S11: Yes | T11: Other#Mainframe | V11: COBOL, Assembler, MU(EASYPLUS), JCL | W11: MetLife Owned Application Code | Y11: No | Z11: Y | AA11: Y | AB11: Y | AC11: N | AD11: N | AE11: 10.784167 | AF11: 0.74583333 | AG11: 0 | AH11: 11.53 | AI11: 0.83304423 | AJ11: 5.765 | AK11: 5.765 | AM11: =AH11*(1-AI11) -> 1.925 | AN11: =VLOOKUP($E11,'Capgemini PResence and HC'!$B$2:$G$143,4,0) -> N | AO11: =VLOOKUP($E11,'Capgemini PResence and HC'!$B$2:$G$143,2,0) -> 0 | AP11: =VLOOKUP($E11,'Capgemini PResence and HC'!$B$2:$G$143,3,0) -> 0 | AQ11: =VLOOKUP($E11,'Capgemini PResence and HC'!$B$2:$G$143,6,0) -> 0 | BB11: =SUM(AE11:AG11)-AH11 -> 0
A12: Mainframe | B12: Yes | E12: 9805 | F12: LC Payment MF-JPN | G12: LifeComm Payment | H12: A subsystem based on LifeComm (mainframe package). As a business domain, it handles payments. While we maintain the features built with assembler, our company's main features are developed in COBOL, and except for table modifications, we are not continuously developing assemblers. | I12: contract management | J12: Core Insurance Systems Group 34956 | K12: Policy Admin Systems Team 34957 | L12: MetLife IT Hosted/Supported | M12: Core Business Application | N12: Production | O12: AD Supported | P12: Y | Q12: Global Technology & Operations | R12: No | S12: Yes | T12: Other#Mainframe | V12: COBOL, Assembler, MU(EASYPLUS), JCL | W12: MetLife Owned Application Code | Y12: No | Z12: Y | AA12: Y | AB12: Y | AC12: N | AD12: N | AE12: 2.8966667 | AF12: 0.025 | AG12: 0 | AH12: 2.9216667 | AI12: 0.90587564 | AJ12: 1.4608333 | AK12: 1.4608333 | AM12: =AH12*(1-AI12) -> 0.275 | AN12: =VLOOKUP($E12,'Capgemini PResence and HC'!$B$2:$G$143,4,0) -> N | AO12: =VLOOKUP($E12,'Capgemini PResence and HC'!$B$2:$G$143,2,0) -> 0 | AP12: =VLOOKUP($E12,'Capgemini PResence and HC'!$B$2:$G$143,3,0) -> 0 | AQ12: =VLOOKUP($E12,'Capgemini PResence and HC'!$B$2:$G$143,6,0) -> 0 | BB12: =SUM(AE12:AG12)-AH12 -> 0
A13: Mainframe | B13: Yes | E13: 9806 | F13: LC GL/SC MF-JPN | G13: LifeComm GL/SC | H13: A subsystem based on LifeComm (mainframe package). As a business domain, it is responsible for accounting. While we maintain the features built with assembler, our company's main features are developed in COBOL, and except for table modifications, we are not continuously developing assemblers. | I13: contract management | J13: Core Insurance Systems Group 34956 | K13: Policy Admin Systems Team 34957 | L13: MetLife IT Hosted/Supported | M13: Core Business Application | N13: Production | O13: AD Supported | P13: Y | Q13: Financial Management Group | R13: No | S13: Yes | T13: Other#Mainframe | V13: COBOL, Assembler, MU(EASYPLUS), JCL | W13: MetLife Owned Application Code | Y13: No | Z13: Y | AA13: Y | AB13: Y | AC13: N | AD13: N | AE13: 5.28875 | AF13: 1.025 | AG13: 0 | AH13: 6.31375 | AI13: 0.83765591 | AJ13: 3.156875 | AK13: 3.156875 | AM13: =AH13*(1-AI13) -> 1.025 | AN13: =VLOOKUP($E13,'Capgemini PResence and HC'!$B$2:$G$143,4,0) -> N | AO13: =VLOOKUP($E13,'Capgemini PResence and HC'!$B$2:$G$143,2,0) -> 0 | AP13: =VLOOKUP($E13,'Capgemini PResence and HC'!$B$2:$G$143,3,0) -> 0 | AQ13: =VLOOKUP($E13,'Capgemini PResence and HC'!$B$2:$G$143,6,0) -> 0 | BB13: =SUM(AE13:AG13)-AH13 -> 0
A14: Mainframe | B14: Yes | E14: 9807 | F14: LC Valuation MF-JPN | G14: LifeComm Valuation | H14: A subsystem based on LifeComm (mainframe package). As a business domain, it handles asset management (not real estate, but calculating the asset value of our insurance contracts). While we maintain the features built with assembler, our company's main features are developed in COBOL, and except for table modifications, we are not continuously developing assemblers. | I14: contract management | J14: Core Insurance Systems Group 34956 | K14: Policy Admin Systems Team 34957 | L14: MetLife IT Hosted/Supported | M14: Core Business Application | N14: Production | O14: AD Supported | P14: N | Q14: Financial Management Group | R14: No | S14: Yes | T14: Other#Mainframe | V14: COBOL, Assembler, MU(EASYPLUS), JCL | W14: MetLife Owned Application Code | Y14: No | Z14: Y | AA14: Y | AB14: Y | AC14: N | AD14: N | AE14: 9.76875 | AF14: 1.4833333 | AG14: 0 | AH14: 11.252083 | AI14: 0.8563229 | AJ14: 5.6260417 | AK14: 5.6260417 | AM14: =AH14*(1-AI14) -> 1.6166667 | AN14: =VLOOKUP($E14,'Capgemini PResence and HC'!$B$2:$G$143,4,0) -> N | AO14: =VLOOKUP($E14,'Capgemini PResence and HC'!$B$2:$G$143,2,0) -> 0 | AP14: =VLOOKUP($E14,'Capgemini PResence and HC'!$B$2:$G$143,3,0) -> 0 | AQ14: =VLOOKUP($E14,'Capgemini PResence and HC'!$B$2:$G$143,6,0) -> 0 | BB14: =SUM(AE14:AG14)-AH14 -> 0
A15: Mainframe | B15: Yes | E15: 9808 | F15: LC AACOMP MF-JPN | G15: LifeComm AgentAgencyComp | H15: A subsystem based on LifeComm (mainframe package). As a business domain, it handles fees (such as recruiter management, sales staff fees, agency fees, etc.). While we maintain the features built with assembler, our company's main features are developed in COBOL, and except for table modifications, we are not continuously developing assemblers. | I15: contract management | J15: Core Insurance Systems Group 34956 | K15: Policy Admin Systems Team 34957 | L15: MetLife IT Hosted/Supported | M15: Core Business Application | N15: Production | O15: AD Supported | P15: Y | Q15: Asia Region | R15: No | S15: Yes | T15: Other#Mainframe | V15: COBOL, Assembler, MU(EASYPLUS), JCL | W15: MetLife Owned Application Code | Y15: No | Z15: Y | AA15: Y | AB15: Y | AC15: N | AD15: N | AE15: 13.545708 | AF15: 3.14375 | AG15: 0 | AH15: 16.689458 | AI15: 0.72662384 | AJ15: 8.3447292 | AK15: 8.3447292 | AM15: =AH15*(1-AI15) -> 4.5625 | AN15: =VLOOKUP($E15,'Capgemini PResence and HC'!$B$2:$G$143,4,0) -> N | AO15: =VLOOKUP($E15,'Capgemini PResence and HC'!$B$2:$G$143,2,0) -> 0 | AP15: =VLOOKUP($E15,'Capgemini PResence and HC'!$B$2:$G$143,3,0) -> 0 | AQ15: =VLOOKUP($E15,'Capgemini PResence and HC'!$B$2:$G$143,6,0) -> 0 | BB15: =SUM(AE15:AG15)-AH15 -> 0
A16: Mainframe | B16: Yes | E16: 9810 | F16: Processor-I MF-JPN | G16: Claim payment (Processor-I) | H16: A subsystem based on a different package from LifeComm (mainframe package). As a business domain, it is responsible for payment of benefits and insurance claims. It is basically built with COBOL, and except for the LIFECOMM integration part, almost no assembler is used. | I16: contract management | J16: Core Insurance Systems Group 34956 | K16: Policy Admin Systems Team 34957 | L16: MetLife IT Hosted/Supported | M16: Core Business Application | N16: Production | O16: AD Supported | P16: Y | Q16: Global Technology & Operations | R16: No | S16: Yes | T16: Other#Mainframe | V16: COBOL, MU(EASYPLUS), Assembler, JCL | W16: MetLife Owned Application Code | Y16: No | Z16: Y | AA16: Y | AB16: Y | AC16: N | AD16: N | AE16: 7.6683333 | AF16: 1.1291667 | AG16: 0 | AH16: 8.7975 | AI16: 0.75561239 | AJ16: 4.39875 | AK16: 4.39875 | AM16: =AH16*(1-AI16) -> 2.15 | AN16: =VLOOKUP($E16,'Capgemini PResence and HC'!$B$2:$G$143,4,0) -> N | AO16: =VLOOKUP($E16,'Capgemini PResence and HC'!$B$2:$G$143,2,0) -> 0 | AP16: =VLOOKUP($E16,'Capgemini PResence and HC'!$B$2:$G$143,3,0) -> 0 | AQ16: =VLOOKUP($E16,'Capgemini PResence and HC'!$B$2:$G$143,6,0) -> 0 | BB16: =SUM(AE16:AG16)-AH16 -> 0
A17: Mainframe | B17: Yes | E17: 9811 | F17: LC Submit MF-JPN | G17: Submit Online | H17: A subsystem developed in-house. As a business domain, it provides daily performance updates. It is basically built with COBOL, and except for the LIFECOMM integration part, almost no assembler is used. | I17: contract management | J17: Core Insurance Systems Group 34956 | K17: Policy Admin Systems Team 34957 | L17: MetLife IT Hosted/Supported | M17: Core Business Application | N17: Production | O17: AD Supported | P17: Y | Q17: Asia Region | R17: No | S17: Yes | T17: Other#Mainframe | V17: COBOL, MU(EASYPLUS), Assembler, JCL | W17: MetLife Owned Application Code | Y17: No | Z17: Y | AA17: Y | AB17: Y | AC17: N | AD17: N | AE17: 1.9683333 | AF17: 0.16458333 | AG17: 0 | AH17: 2.1329167 | AI17: 0.95311584 | AJ17: 1.0664583 | AK17: 1.0664583 | AM17: =AH17*(1-AI17) -> 0.1 | AN17: =VLOOKUP($E17,'Capgemini PResence and HC'!$B$2:$G$143,4,0) -> N | AO17: =VLOOKUP($E17,'Capgemini PResence and HC'!$B$2:$G$143,2,0) -> 0 | AP17: =VLOOKUP($E17,'Capgemini PResence and HC'!$B$2:$G$143,3,0) -> 0 | AQ17: =VLOOKUP($E17,'Capgemini PResence and HC'!$B$2:$G$143,6,0) -> 0 | BB17: =SUM(AE17:AG17)-AH17 -> 0
A18: Mainframe | B18: Yes | E18: 9813 | F18: LC Micro MF-JPN | G18: Micro-Index | H18: A subsystem developed in-house. It is a collection of numerous detailed functions. It is basically built with COBOL, and except for the LIFECOMM integration part, almost no assembler is used. | I18: contract management | J18: Core Insurance Systems Group 34956 | K18: Policy Admin Systems Team 34957 | L18: MetLife IT Hosted/Supported | M18: Core Business Application | N18: Production | O18: AD Supported | P18: Y | Q18: Asia Region | R18: No | S18: Yes | T18: Other#Mainframe | V18: COBOL, MU(EASYPLUS), Assembler, JCL | W18: MetLife Owned Application Code | Y18: No | Z18: Y | AA18: Y | AB18: Y | AC18: N | AD18: N | AE18: 2.1175 | AF18: 0 | AG18: 0 | AH18: 2.1175 | AI18: 0.64580874 | AJ18: 1.05875 | AK18: 1.05875 | AM18: =AH18*(1-AI18) -> 0.75 | AN18: =VLOOKUP($E18,'Capgemini PResence and HC'!$B$2:$G$143,4,0) -> N | AO18: =VLOOKUP($E18,'Capgemini PResence and HC'!$B$2:$G$143,2,0) -> 0 | AP18: =VLOOKUP($E18,'Capgemini PResence and HC'!$B$2:$G$143,3,0) -> 0 | AQ18: =VLOOKUP($E18,'Capgemini PResence and HC'!$B$2:$G$143,6,0) -> 0 | BB18: =SUM(AE18:AG18)-AH18 -> 0
A19: Mainframe | B19: Yes | E19: 9814 | F19: Foreign MF-JPN | G19: Foreign | H19: A subsystem developed in-house. Responsible for managing foreign contracts. It is basically built with COBOL, and except for the LIFECOMM integration part, almost no assembler is used. | I19: contract management | J19: Core Insurance Systems Group 34956 | K19: Policy Admin Systems Team 34957 | L19: MetLife IT Hosted/Supported | M19: Core Business Application | N19: Production | O19: AD Supported | P19: N | Q19: Global Technology & Operations | R19: No | S19: Yes | T19: Other#Mainframe | V19: COBOL, MU(EASYPLUS), Assembler, JCL | W19: MetLife Owned Application Code | Y19: No | Z19: Y | AA19: Y | AB19: Y | AC19: N | AD19: N | AL19: The number of personnel is included in the 9813 | AM19: =AH19*(1-AI19) -> 0 | AN19: =VLOOKUP($E19,'Capgemini PResence and HC'!$B$2:$G$143,4,0) -> N | AO19: =VLOOKUP($E19,'Capgemini PResence and HC'!$B$2:$G$143,2,0) -> 0 | AP19: =VLOOKUP($E19,'Capgemini PResence and HC'!$B$2:$G$143,3,0) -> 0 | AQ19: =VLOOKUP($E19,'Capgemini PResence and HC'!$B$2:$G$143,6,0) -> 0 | BB19: =SUM(AE19:AG19)-AH19 -> 0
A20: Mainframe | B20: Yes | E20: 9816 | F20: CT Salary MF-JPN | G20: CT Salary System | H20: A subsystem developed in-house. As a business domain, it manages the salaries of our sales staff. However, since salaries based on performance are calculated using EAI:9808, only certain items such as base salary and deductions are covered. It is basically built with COBOL, and except for the LIFECOMM integration part, almost no assembler is used. | I20: contract management | J20: Core Insurance Systems Group 34956 | K20: Policy Admin Systems Team 34957 | L20: MetLife IT Hosted/Supported | M20: Core Business Application | N20: Production | O20: AD Supported | P20: Y | Q20: Asia Region | R20: No | S20: Yes | T20: Other#Mainframe | V20: COBOL, MU(EASYPLUS), Assembler, JCL | W20: MetLife Owned Application Code | Y20: No | Z20: Y | AA20: Y | AB20: Y | AC20: N | AD20: N | AE20: 0.2 | AF20: 0 | AG20: 0 | AH20: 0.2 | AI20: 0 | AJ20: 0.1 | AK20: 0.1 | AM20: =AH20*(1-AI20) -> 0.2 | AN20: =VLOOKUP($E20,'Capgemini PResence and HC'!$B$2:$G$143,4,0) -> N | AO20: =VLOOKUP($E20,'Capgemini PResence and HC'!$B$2:$G$143,2,0) -> 0 | AP20: =VLOOKUP($E20,'Capgemini PResence and HC'!$B$2:$G$143,3,0) -> 0 | AQ20: =VLOOKUP($E20,'Capgemini PResence and HC'!$B$2:$G$143,6,0) -> 0 | BB20: =SUM(AE20:AG20)-AH20 -> 0
A21: Mainframe | B21: Yes | E21: 9817 | F21: TaxCertification MF-JPN | G21: TaxCertification | H21: A subsystem developed in-house. As a business domain, it serves as proof of deductions. It is basically built with COBOL, and except for the LIFECOMM integration part, almost no assembler is used. | I21: contract management | J21: Core Insurance Systems Group 34956 | K21: Policy Admin Systems Team 34957 | L21: MetLife IT Hosted/Supported | M21: Core Business Application | N21: Production | O21: AD Supported | P21: N | Q21: Global Technology & Operations | R21: No | S21: Yes | T21: Other#Mainframe | V21: COBOL, MU(EASYPLUS), Assembler, JCL | W21: MetLife Owned Application Code | Y21: No | Z21: Y | AA21: Y | AB21: Y | AC21: N | AD21: N | AE21: 1.664875 | AF21: 0 | AG21: 0 | AH21: 1.664875 | AI21: 0.40748805 | AJ21: 0.8324375 | AK21: 0.8324375 | AM21: =AH21*(1-AI21) -> 0.98645833 | AN21: =VLOOKUP($E21,'Capgemini PResence and HC'!$B$2:$G$143,4,0) -> N | AO21: =VLOOKUP($E21,'Capgemini PResence and HC'!$B$2:$G$143,2,0) -> 0 | AP21: =VLOOKUP($E21,'Capgemini PResence and HC'!$B$2:$G$143,3,0) -> 0 | AQ21: =VLOOKUP($E21,'Capgemini PResence and HC'!$B$2:$G$143,6,0) -> 0 | BB21: =SUM(AE21:AG21)-AH21 -> 0
A22: Mainframe | B22: Yes | E22: 9818 | F22: SWINGMANAGER MF-JPN | G22: SWING MANAGER | H22: A subsystem developed in-house. He is responsible for managing the savings fund of Universal Life. It is managed together with EAI:9796. It is basically built with COBOL, and except for the LIFECOMM integration part, almost no assembler is used. | I22: contract management | J22: Core Insurance Systems Group 34956 | K22: Policy Admin Systems Team 34957 | L22: MetLife IT Hosted/Supported | M22: Core Business Application | N22: Production | O22: AD Supported | P22: N | Q22: Global Technology & Operations | R22: No | S22: Yes | T22: Other#Mainframe | V22: COBOL, MU(EASYPLUS), Assembler, JCL | W22: MetLife Owned Application Code | Y22: No | Z22: Y | AA22: Y | AB22: Y | AC22: N | AD22: N | AL22: The number of personnel is included in 9796. | AM22: =AH22*(1-AI22) -> 0 | AN22: =VLOOKUP($E22,'Capgemini PResence and HC'!$B$2:$G$143,4,0) -> N | AO22: =VLOOKUP($E22,'Capgemini PResence and HC'!$B$2:$G$143,2,0) -> 0 | AP22: =VLOOKUP($E22,'Capgemini PResence and HC'!$B$2:$G$143,3,0) -> 0 | AQ22: =VLOOKUP($E22,'Capgemini PResence and HC'!$B$2:$G$143,6,0) -> 0 | BB22: =SUM(AE22:AG22)-AH22 -> 0
A23: Mainframe | B23: Yes | E23: 9819 | F23: PremCollectDBMF-JPN | G23: Premium Collection History DB | H23: A subsystem developed in-house. It is responsible for the deposit history function. It is managed together with EAI:9796. It is basically built with COBOL, and except for the LIFECOMM integration part, almost no assembler is used. | I23: contract management | J23: Core Insurance Systems Group 34956 | K23: Policy Admin Systems Team 34957 | L23: MetLife IT Hosted/Supported | M23: Core Business Application | N23: Production | O23: AD Supported | P23: N | Q23: Global Technology & Operations | R23: No | S23: Yes | T23: Other#Mainframe | V23: COBOL, MU(EASYPLUS), Assembler, JCL | W23: MetLife Owned Application Code | Y23: No | Z23: Y | AA23: Y | AB23: Y | AC23: N | AD23: N | AL23: The number of personnel is included in 9796. | AM23: =AH23*(1-AI23) -> 0 | AN23: =VLOOKUP($E23,'Capgemini PResence and HC'!$B$2:$G$143,4,0) -> N | AO23: =VLOOKUP($E23,'Capgemini PResence and HC'!$B$2:$G$143,2,0) -> 0 | AP23: =VLOOKUP($E23,'Capgemini PResence and HC'!$B$2:$G$143,3,0) -> 0 | AQ23: =VLOOKUP($E23,'Capgemini PResence and HC'!$B$2:$G$143,6,0) -> 0 | BB23: =SUM(AE23:AG23)-AH23 -> 0
A24: Mainframe | B24: Yes | E24: 9820 | F24: MCFA CP DB MF-JPN | G24: MCFA Coupon DB | H24: A subsystem developed in-house. It serves as the fixed withdrawal function for MCFA (pension insurance). It is managed together with EAI:9796. It is basically built with COBOL, and except for the LIFECOMM integration part, almost no assembler is used. | I24: contract management | J24: Core Insurance Systems Group 34956 | K24: Policy Admin Systems Team 34957 | L24: MetLife IT Hosted/Supported | M24: Core Business Application | N24: Production | O24: AD Supported | P24: Y | Q24: Global Technology & Operations | R24: No | S24: Yes | T24: Other#Mainframe | V24: COBOL, MU(EASYPLUS), Assembler, JCL | W24: MetLife Owned Application Code | Y24: No | Z24: Y | AA24: Y | AB24: Y | AC24: N | AD24: N | AL24: The number of personnel is included in 9796. | AM24: =AH24*(1-AI24) -> 0 | AN24: =VLOOKUP($E24,'Capgemini PResence and HC'!$B$2:$G$143,4,0) -> N | AO24: =VLOOKUP($E24,'Capgemini PResence and HC'!$B$2:$G$143,2,0) -> 0 | AP24: =VLOOKUP($E24,'Capgemini PResence and HC'!$B$2:$G$143,3,0) -> 0 | AQ24: =VLOOKUP($E24,'Capgemini PResence and HC'!$B$2:$G$143,6,0) -> 0 | BB24: =SUM(AE24:AG24)-AH24 -> 0
A25: Mainframe | B25: Yes | E25: 9821 | F25: Maturity MF-JPN | G25: Payment maturity existing benefit etc | H25: A subsystem developed in-house. As a business domain, it serves as maturity. It is basically built with COBOL, and except for the LIFECOMM integration part, almost no assembler is used. | I25: contract management | J25: Core Insurance Systems Group 34956 | K25: Policy Admin Systems Team 34957 | L25: MetLife IT Hosted/Supported | M25: Core Business Application | N25: Production | O25: AD Supported | P25: Y | Q25: Global Technology & Operations | R25: No | S25: Yes | T25: Other#Mainframe | V25: COBOL, MU(EASYPLUS), Assembler, JCL | W25: MetLife Owned Application Code | Y25: No | Z25: Y | AA25: Y | AB25: Y | AC25: N | AD25: N | AE25: 4.3783333 | AF25: 0.97083333 | AG25: 0 | AH25: 5.3491667 | AI25: 0.62610999 | AJ25: 2.6745833 | AK25: 2.6745833 | AM25: =AH25*(1-AI25) -> 2 | AN25: =VLOOKUP($E25,'Capgemini PResence and HC'!$B$2:$G$143,4,0) -> N | AO25: =VLOOKUP($E25,'Capgemini PResence and HC'!$B$2:$G$143,2,0) -> 0 | AP25: =VLOOKUP($E25,'Capgemini PResence and HC'!$B$2:$G$143,3,0) -> 0 | AQ25: =VLOOKUP($E25,'Capgemini PResence and HC'!$B$2:$G$143,6,0) -> 0 | BB25: =SUM(AE25:AG25)-AH25 -> 0
A26: Mainframe | B26: Yes | E26: 9822 | F26: LC Reins MF-JPN | G26: Reinsurance | H26: A subsystem developed in-house. As a business domain, it handles reinsurance. It is basically built with COBOL, and except for the LIFECOMM integration part, almost no assembler is used. | I26: contract management | J26: Core Insurance Systems Group 34956 | K26: Policy Admin Systems Team 34957 | L26: MetLife IT Hosted/Supported | M26: Core Business Application | N26: Production | O26: AD Supported | P26: N | Q26: Financial Management Group | R26: No | S26: Yes | T26: Other#Mainframe | V26: COBOL, MU(EASYPLUS), Assembler, JCL | W26: MetLife Owned Application Code | Y26: No | Z26: Y | AA26: Y | AB26: Y | AC26: N | AD26: N | AE26: 6.0129167 | AF26: 0.25416667 | AG26: 0 | AH26: 6.2670833 | AI26: 0.78990759 | AJ26: 3.1335417 | AK26: 3.1335417 | AM26: =AH26*(1-AI26) -> 1.3166667 | AN26: =VLOOKUP($E26,'Capgemini PResence and HC'!$B$2:$G$143,4,0) -> N | AO26: =VLOOKUP($E26,'Capgemini PResence and HC'!$B$2:$G$143,2,0) -> 0 | AP26: =VLOOKUP($E26,'Capgemini PResence and HC'!$B$2:$G$143,3,0) -> 0 | AQ26: =VLOOKUP($E26,'Capgemini PResence and HC'!$B$2:$G$143,6,0) -> 0 | BB26: =SUM(AE26:AG26)-AH26 -> 0
A27: Mainframe | B27: Yes | E27: 9823 | F27: ASP Bridge(H) MF-JPN | G27: ASP Bridge (HOST) | H27: A subsystem developed in-house. It handles interfaces (data integration) with EAI:9925 and EAI:12559. It is basically built with COBOL, and except for the LIFECOMM integration part, almost no assembler is used. | I27: contract management | J27: Core Insurance Systems Group 34956 | K27: Policy Admin Systems Team 34957 | L27: MetLife IT Hosted/Supported | M27: Common Service Business Application | N27: Production | O27: AD Supported | P27: Y | Q27: Global Technology & Operations | R27: No | S27: Yes | T27: Other#Mainframe | V27: COBOL, MU(EASYPLUS), Assembler, JCL | W27: MetLife Owned Application Code | Y27: No | Z27: Y | AA27: Y | AB27: Y | AC27: N | AD27: N | AE27: 6.7267083 | AF27: 1.4625 | AG27: 0 | AH27: 8.1892083 | AI27: 0.72808727 | AJ27: 4.0946042 | AK27: 4.0946042 | AM27: =AH27*(1-AI27) -> 2.22675 | AN27: =VLOOKUP($E27,'Capgemini PResence and HC'!$B$2:$G$143,4,0) -> N | AO27: =VLOOKUP($E27,'Capgemini PResence and HC'!$B$2:$G$143,2,0) -> 0 | AP27: =VLOOKUP($E27,'Capgemini PResence and HC'!$B$2:$G$143,3,0) -> 0 | AQ27: =VLOOKUP($E27,'Capgemini PResence and HC'!$B$2:$G$143,6,0) -> 0 | BB27: =SUM(AE27:AG27)-AH27 -> 0
A28: Mainframe | B28: Yes | E28: 9824 | F28: CCA MF-JPN | G28: Client Contract Administration | H28: A subsystem based on a different package from LifeComm (mainframe package). As a business domain, it serves as a customer name impersonation. It is basically built with COBOL, and except for the LIFECOMM integration part, almost no assembler is used. | I28: contract management | J28: Core Insurance Systems Group 34956 | K28: Policy Admin Systems Team 34957 | L28: MetLife IT Hosted/Supported | M28: Core Business Application | N28: Production | O28: AD Supported | P28: Y | Q28: Global Technology & Operations | R28: No | S28: Yes | T28: Other#Mainframe | V28: COBOL, MU(EASYPLUS), Assembler, JCL | W28: MetLife Owned Application Code | Y28: No | Z28: Y | AA28: Y | AB28: Y | AC28: N | AD28: N | AE28: 1.6308333 | AF28: 0 | AG28: 0 | AH28: 1.6308333 | AI28: 0.38681656 | AJ28: 0.81541667 | AK28: 0.81541667 | AM28: =AH28*(1-AI28) -> 1 | AN28: =VLOOKUP($E28,'Capgemini PResence and HC'!$B$2:$G$143,4,0) -> N | AO28: =VLOOKUP($E28,'Capgemini PResence and HC'!$B$2:$G$143,2,0) -> 0 | AP28: =VLOOKUP($E28,'Capgemini PResence and HC'!$B$2:$G$143,3,0) -> 0 | AQ28: =VLOOKUP($E28,'Capgemini PResence and HC'!$B$2:$G$143,6,0) -> 0 | BB28: =SUM(AE28:AG28)-AH28 -> 0
A29: Cloud | B29: Yes | E29: 9833 | F29: C04NWC-JPN | G29: CenterServer | H29: Rule engine for new contract workflows | I29: New Contract Related | J29: Customer Service and Operations Systems Group 34965 | K29: New Business Team 34966 | L29: MetLife IT Hosted/Supported | M29: Core Business Application | N29: Production | O29: AD Supported | P29: N | Q29: Global Technology & Operations | R29: No | S29: Yes | T29: Other#ASP | V29: C/C++ | W29: MetLife Owned Application Code | Y29: No | Z29: Y | AA29: Y | AB29: Y | AC29: N | AD29: N | AE29: 8.7316667 | AF29: 0.11041667 | AG29: 0 | AH29: 8.8420833 | AI29: 0.91687479 | AJ29: 4.4210417 | AK29: 4.4210417 | AM29: =AH29*(1-AI29) -> 0.735 | AN29: =VLOOKUP($E29,'Capgemini PResence and HC'!$B$2:$G$143,4,0) -> Y | AO29: =VLOOKUP($E29,'Capgemini PResence and HC'!$B$2:$G$143,2,0) -> 0 | AP29: =VLOOKUP($E29,'Capgemini PResence and HC'!$B$2:$G$143,3,0) -> 1 | AQ29: =VLOOKUP($E29,'Capgemini PResence and HC'!$B$2:$G$143,6,0) -> 0 | BB29: =SUM(AE29:AG29)-AH29 -> 0
A30: Cloud | B30: Yes | E30: 9834 | F30: C03WRE-JPN | G30: POS Workflow Payment Workflow (Restoring cancelled | H30: Restoring and Cancelled Policy | I30: Storage and Preservation Related | J30: Customer Service and Operations Systems Group 34965 | K30: Policy Servicing Team 34967 | L30: MetLife IT Hosted/Supported | M30: Core Business Application | N30: Production | O30: AD Supported | P30: Y | Q30: Global Technology & Operations | R30: No | S30: Yes | T30: Thick Client | V30: VB.NET | W30: MetLife Owned Application Code | Y30: No | Z30: Y | AA30: Y | AB30: Y | AC30: N | AD30: N | AE30: 0.2 | AF30: 0.2 | AG30: 0 | AH30: 0.37083333 | AI30: 0.3258427 | AJ30: 0.18541667 | AK30: 0.18541667 | AM30: =AH30*(1-AI30) -> 0.25 | AN30: =VLOOKUP($E30,'Capgemini PResence and HC'!$B$2:$G$143,4,0) -> N | AO30: =VLOOKUP($E30,'Capgemini PResence and HC'!$B$2:$G$143,2,0) -> 0 | AP30: =VLOOKUP($E30,'Capgemini PResence and HC'!$B$2:$G$143,3,0) -> 0 | AQ30: =VLOOKUP($E30,'Capgemini PResence and HC'!$B$2:$G$143,6,0) -> 0 | BB30: =SUM(AE30:AG30)-AH30 -> 0.029166667
A31: Cloud | B31: Yes | E31: 9835 | F31: C12WNC-JPN | G31: POS Workflow Payment Workflow (Claim Transaction A | H31: Claim Transaction Automatic Development of Benefit | I31: Insurance Claims and Benefits Payment Related | J31: Customer Service and Operations Systems Group 34965 | K31: Claims Team 34968 | L31: MetLife IT Hosted/Supported | M31: Core Business Application | N31: Production | O31: AD Supported | P31: Y | Q31: Global Technology & Operations | R31: No | S31: Yes | T31: Thick Client | V31: VB.NET; C/C++; JAVA | W31: MetLife Owned Application Code | Y31: No | Z31: Y | AA31: Y | AB31: Y | AC31: N | AD31: N | AE31: 29.379875 | AF31: 5.6166667 | AG31: 0 | AH31: 34.996542 | AI31: 0.90522873 | AJ31: 17.498271 | AK31: 17.498271 | AM31: =AH31*(1-AI31) -> 3.3166667 | AN31: =VLOOKUP($E31,'Capgemini PResence and HC'!$B$2:$G$143,4,0) -> Y | AO31: =VLOOKUP($E31,'Capgemini PResence and HC'!$B$2:$G$143,2,0) -> 0 | AP31: =VLOOKUP($E31,'Capgemini PResence and HC'!$B$2:$G$143,3,0) -> 1 | AQ31: =VLOOKUP($E31,'Capgemini PResence and HC'!$B$2:$G$143,6,0) -> 0 | BB31: =SUM(AE31:AG31)-AH31 -> 0
A32: Cloud | B32: Yes | E32: 9836 | F32: C03WRD-JPN | G32: POS Workflow Payment Workflow (Reduction of paymen | H32: Storage and Maintenance Workflow (Reduction of Payment) | I32: Storage and Preservation Related | J32: Customer Service and Operations Systems Group 34965 | K32: Policy Servicing Team 34967 | L32: MetLife IT Hosted/Supported | M32: Core Business Application | N32: Production | O32: AD Supported | P32: Y | Q32: Global Technology & Operations | R32: No | S32: Yes | T32: Thick Client | V32: VB.NET | W32: MetLife Owned Application Code | Y32: No | Z32: Y | AA32: Y | AB32: Y | AC32: N | AD32: N | AE32: 0.3 | AF32: 0.3 | AG32: 0 | AH32: 2.5258333 | AI32: 0.90102276 | AJ32: 1.2629167 | AK32: 1.2629167 | AM32: =AH32*(1-AI32) -> 0.25 | AN32: =VLOOKUP($E32,'Capgemini PResence and HC'!$B$2:$G$143,4,0) -> Y | AO32: =VLOOKUP($E32,'Capgemini PResence and HC'!$B$2:$G$143,2,0) -> 0 | AP32: =VLOOKUP($E32,'Capgemini PResence and HC'!$B$2:$G$143,3,0) -> 1 | AQ32: =VLOOKUP($E32,'Capgemini PResence and HC'!$B$2:$G$143,6,0) -> 0 | BB32: =SUM(AE32:AG32)-AH32 -> -1.9258333
A33: Cloud | B33: Yes | E33: 9842 | F33: C03PCA-JPN | G33: Add Coverage | H33: Storage and Preservation Special Contract Mid-Term Additional Processing System | I33: Storage and Preservation Related | J33: Customer Service and Operations Systems Group 34965 | K33: Policy Servicing Team 34967 | L33: MetLife IT Hosted/Supported | M33: Core Business Application | N33: Production | O33: AD Supported | P33: N | Q33: Global Technology & Operations | R33: No | S33: Yes | T33: Other#C/S | V33: VB | W33: MetLife Owned Application Code | Y33: No | Z33: Y | AA33: Y | AB33: Y | AC33: N | AD33: N | AE33: 0.3 | AF33: 0.3 | AG33: 0 | AH33: 2.88625 | AI33: 0.90298831 | AJ33: 1.443125 | AK33: 1.443125 | AM33: =AH33*(1-AI33) -> 0.28 | AN33: =VLOOKUP($E33,'Capgemini PResence and HC'!$B$2:$G$143,4,0) -> Y | AO33: =VLOOKUP($E33,'Capgemini PResence and HC'!$B$2:$G$143,2,0) -> 0 | AP33: =VLOOKUP($E33,'Capgemini PResence and HC'!$B$2:$G$143,3,0) -> 1 | AQ33: =VLOOKUP($E33,'Capgemini PResence and HC'!$B$2:$G$143,6,0) -> 0 | BB33: =SUM(AE33:AG33)-AH33 -> -2.28625
A34: Cloud | B34: Yes | E34: 9843 | F34: C10CSS-JPN | G34: FSC Call Support | H34: Application for call centers for bank tellers (call history/case management) | I34: Customer Care / Call Center Related | J34: Customer Service and Operations Systems Group 34965 | K34: Customer Care Team 34969 | L34: MetLife IT Hosted/Supported | M34: Core Business Application | N34: Production | O34: AD Supported | P34: N | Q34: Global Technology & Operations | R34: No | S34: Yes | T34: Web Application Client | V34: VB.NET | W34: MetLife Owned Application Code | Y34: No | Z34: Y | AA34: Y | AB34: Y | AC34: N | AD34: N | AE34: 1.2120833 | AF34: 0.20833333 | AG34: 0 | AH34: 1.4204167 | AI34: 0.63596363 | AJ34: 0.71020833 | AK34: 0.71020833 | AM34: =AH34*(1-AI34) -> 0.51708333 | AN34: =VLOOKUP($E34,'Capgemini PResence and HC'!$B$2:$G$143,4,0) -> Y | AO34: =VLOOKUP($E34,'Capgemini PResence and HC'!$B$2:$G$143,2,0) -> 0 | AP34: =VLOOKUP($E34,'Capgemini PResence and HC'!$B$2:$G$143,3,0) -> 1 | AQ34: =VLOOKUP($E34,'Capgemini PResence and HC'!$B$2:$G$143,6,0) -> 0 | BB34: =SUM(AE34:AG34)-AH34 -> 0
A35: Cloud | B35: Yes | E35: 11011 | F35: WGLWLF-JPN | G35: Watch List Filtering system | H35: To prevent transactions with antisocial forces, internal customer data screening is conducted. It uses Actimize's package. | I35: Corporate Related | J35: Core Insurance Systems Group 34956 | K35: Corporate Systems Team 34959 | L35: MetLife IT Hosted/Supported | M35: Core Business Application | N35: Production | O35: AD Supported | P35: N | Q35: Global Risk Management | R35: No | S35: Yes | T35: Web Application Client | V35: JAVA | W35: MetLife Owned Application Code | Y35: No | Z35: Y | AA35: Y | AB35: Y | AC35: N | AD35: N | AE35: 6.0791667 | AF35: 1.0708333 | AG35: 0 | AH35: 7.15 | AI35: 0.90384615 | AJ35: 3.575 | AK35: 3.575 | AM35: =AH35*(1-AI35) -> 0.6875 | AN35: =VLOOKUP($E35,'Capgemini PResence and HC'!$B$2:$G$143,4,0) -> N | AO35: =VLOOKUP($E35,'Capgemini PResence and HC'!$B$2:$G$143,2,0) -> 0 | AP35: =VLOOKUP($E35,'Capgemini PResence and HC'!$B$2:$G$143,3,0) -> 0 | AQ35: =VLOOKUP($E35,'Capgemini PResence and HC'!$B$2:$G$143,6,0) -> 0 | AR35: =AH35-AS35 -> 6.4625 | AS35: =AM35 -> 0.6875 | AT35: =#REF!*AT$151 -> #REF! | AU35: =#REF!*AU$151 -> #REF! | AV35: =#REF!*AV$151 -> #REF! | AW35: =#REF!*AW$151 -> #REF! | AX35: =#REF!*AX$151 -> #REF! | AY35: =#REF!*AY$151 -> #REF! | AZ35: =#REF!*AZ$151 -> #REF! | BA35: =#REF!*BA$151 -> #REF! | BB35: =SUM(AE35:AG35)-AH35 -> 0
A36: Cloud | B36: Yes | E36: 9845 | F36: C04SYM-JPN | G36: Renewal symap Business Work Flow | H36: Workflow for Contract Renewal Process | I36: New Contract Related | J36: Customer Service and Operations Systems Group 34965 | K36: New Business Team 34966 | L36: MetLife IT Hosted/Supported | M36: Core Business Application | N36: Production | O36: AD Supported | P36: N | Q36: Global Technology & Operations | R36: No | S36: Yes | T36: Other#Thick Client | V36: VB.NET | W36: MetLife Owned Application Code | Y36: No | Z36: Y | AA36: Y | AB36: Y | AC36: N | AD36: N | AE36: 3.4049167 | AF36: 0 | AG36: 0 | AH36: 3.4049167 | AI36: 0.84091632 | AJ36: 1.7024583 | AK36: 1.7024583 | AM36: =AH36*(1-AI36) -> 0.54166667 | AN36: =VLOOKUP($E36,'Capgemini PResence and HC'!$B$2:$G$143,4,0) -> Y | AO36: =VLOOKUP($E36,'Capgemini PResence and HC'!$B$2:$G$143,2,0) -> 0 | AP36: =VLOOKUP($E36,'Capgemini PResence and HC'!$B$2:$G$143,3,0) -> 1 | AQ36: =VLOOKUP($E36,'Capgemini PResence and HC'!$B$2:$G$143,6,0) -> 0 | BB36: =SUM(AE36:AG36)-AH36 -> 0
A37: Cloud | B37: Yes | E37: 9846 | F37: C03VSV-JPN | G37: Variable Annuity Sun View | H37: Call Center Applications / Call History Management Related to Variable Pensions | I37: Customer Care / Call Center Related | J37: Customer Service and Operations Systems Group 34965 | K37: Customer Care Team 34969 | L37: MetLife IT Hosted/Supported | M37: Core Business Application | N37: Production | O37: AD Supported | P37: N | Q37: Global Technology & Operations | R37: No | S37: Yes | T37: Other#C/S | V37: VB.NET | W37: MetLife Owned Application Code | Y37: No | Z37: Y | AA37: Y | AB37: Y | AC37: N | AD37: N | AE37: 0.03125 | AF37: 0.4 | AG37: 0 | AH37: 0.43125 | AI37: 0.92753623 | AJ37: 0.215625 | AK37: 0.215625 | AM37: =AH37*(1-AI37) -> 0.03125 | AN37: =VLOOKUP($E37,'Capgemini PResence and HC'!$B$2:$G$143,4,0) -> Y | AO37: =VLOOKUP($E37,'Capgemini PResence and HC'!$B$2:$G$143,2,0) -> 0 | AP37: =VLOOKUP($E37,'Capgemini PResence and HC'!$B$2:$G$143,3,0) -> 1 | AQ37: =VLOOKUP($E37,'Capgemini PResence and HC'!$B$2:$G$143,6,0) -> 0 | BB37: =SUM(AE37:AG37)-AH37 -> 0
A38: Cloud | B38: Yes | E38: 9847 | F38: PinID tool_JPN | G38: PinID Increase tool | H38: EAI: A subsystem for managing PinID, a unique customer management number for 9925. Currently, it is built with .NET but is under development for migration to web applications. | I38: contract management | J38: Core Insurance Systems Group 34956 | K38: Policy Admin Systems Team 34957 | L38: MetLife IT Hosted/Supported | M38: Core Business Application | N38: Production | O38: AD Supported | P38: N | Q38: Global Technology & Operations | R38: No | S38: Yes | T38: Other#C/S | V38: VB.NET | W38: MetLife Owned Application Code | Y38: No | Z38: Y | AA38: Y | AB38: Y | AC38: N | AD38: N | AE38: 0.152625 | AF38: 0.3 | AG38: 0 | AH38: 0.452625 | AI38: 1 | AJ38: 0.2263125 | AK38: 0.2263125 | AM38: =AH38*(1-AI38) -> 0 | AN38: =VLOOKUP($E38,'Capgemini PResence and HC'!$B$2:$G$143,4,0) -> N | AO38: =VLOOKUP($E38,'Capgemini PResence and HC'!$B$2:$G$143,2,0) -> 0 | AP38: =VLOOKUP($E38,'Capgemini PResence and HC'!$B$2:$G$143,3,0) -> 0 | AQ38: =VLOOKUP($E38,'Capgemini PResence and HC'!$B$2:$G$143,6,0) -> 0 | BB38: =SUM(AE38:AG38)-AH38 -> 0
A39: Cloud | B39: Yes | E39: 9848 | F39: C11VCM-JPN | G39: Deposit Control System | H39: New Contract Related/Deposit Management System | I39: New Contract Related | J39: Customer Service and Operations Systems Group 34965 | K39: New Business Team 34966 | L39: MetLife IT Hosted/Supported | M39: Core Business Application | N39: Production | O39: AD Supported | P39: N | Q39: Global Technology & Operations | R39: No | S39: Yes | T39: Web Application Client | V39: VB.NET | W39: MetLife Owned Application Code | Y39: No | Z39: Y | AA39: Y | AB39: Y | AC39: N | AD39: N | AE39: 0.88541667 | AF39: 0 | AG39: 0 | AH39: 0.88541667 | AI39: 0.83058824 | AJ39: 0.44270833 | AK39: 0.44270833 | AM39: =AH39*(1-AI39) -> 0.15 | AN39: =VLOOKUP($E39,'Capgemini PResence and HC'!$B$2:$G$143,4,0) -> Y | AO39: =VLOOKUP($E39,'Capgemini PResence and HC'!$B$2:$G$143,2,0) -> 0 | AP39: =VLOOKUP($E39,'Capgemini PResence and HC'!$B$2:$G$143,3,0) -> 1 | AQ39: =VLOOKUP($E39,'Capgemini PResence and HC'!$B$2:$G$143,6,0) -> 0 | BB39: =SUM(AE39:AG39)-AH39 -> 0
A40: Cloud | B40: Yes | E40: 9849 | F40: C04OSI-JPN | G40: S Sum Total System(Open) | H40: New Contract Related/Comprehensive Management System | I40: New Contract Related | J40: Customer Service and Operations Systems Group 34965 | K40: New Business Team 34966 | L40: MetLife IT Hosted/Supported | M40: Common Service Business Application | N40: Production | O40: AD Supported | P40: N | Q40: Global Technology & Operations | R40: No | S40: Yes | T40: Web Application Client | V40: JAVA | W40: MetLife Owned Application Code | Y40: No | Z40: Y | AA40: Y | AB40: Y | AC40: N | AD40: N | AE40: 5.18625 | AF40: 0.38333333 | AG40: 0 | AH40: 5.5695833 | AI40: 0.8315254 | AJ40: 2.7847917 | AK40: 2.7847917 | AM40: =AH40*(1-AI40) -> 0.93833333 | AN40: =VLOOKUP($E40,'Capgemini PResence and HC'!$B$2:$G$143,4,0) -> Y | AO40: =VLOOKUP($E40,'Capgemini PResence and HC'!$B$2:$G$143,2,0) -> 0 | AP40: =VLOOKUP($E40,'Capgemini PResence and HC'!$B$2:$G$143,3,0) -> 1 | AQ40: =VLOOKUP($E40,'Capgemini PResence and HC'!$B$2:$G$143,6,0) -> 0 | BB40: =SUM(AE40:AG40)-AH40 -> 0
A41: Cloud | B41: Yes | E41: 13812 | F41: Corporate Batch | G41: OpenBatch system for Corporate | H41: EAI gathered batch processing when rebuilding the Infostation app into AppsPortal. It has the following features Automated email distribution, CRSDB, GIM/DOM, MetLifeSFTP, NVES | I41: Corporate Related | J41: Core Insurance Systems Group 34956 | K41: Corporate Systems Team 34959 | L41: MetLife IT Hosted/Supported | M41: Core Business Application | N41: Production | O41: AD Supported | P41: N | Q41: Global Technology & Operations | R41: No | S41: Yes | T41: Other#Batch | V41: VB.NET | W41: MetLife Owned Application Code | Y41: No | Z41: Y | AA41: Y | AB41: Y | AC41: N | AD41: N | AE41: 2.04 | AF41: 1.7 | AG41: 0 | AH41: 3.74 | AI41: 0.3083779 | AJ41: 1.87 | AK41: 1.87 | AM41: =AH41*(1-AI41) -> 2.5866667 | AN41: =VLOOKUP($E41,'Capgemini PResence and HC'!$B$2:$G$143,4,0) -> N | AO41: =VLOOKUP($E41,'Capgemini PResence and HC'!$B$2:$G$143,2,0) -> 0 | AP41: =VLOOKUP($E41,'Capgemini PResence and HC'!$B$2:$G$143,3,0) -> 0 | AQ41: =VLOOKUP($E41,'Capgemini PResence and HC'!$B$2:$G$143,6,0) -> 0 | AR41: =AH41-AS41 -> 1.1533333 | AS41: =AM41 -> 2.5866667 | AT41: =#REF!*AT$151 -> #REF! | AU41: =#REF!*AU$151 -> #REF! | AV41: =#REF!*AV$151 -> #REF! | AW41: =#REF!*AW$151 -> #REF! | AX41: =#REF!*AX$151 -> #REF! | AY41: =#REF!*AY$151 -> #REF! | AZ41: =#REF!*AZ$151 -> #REF! | BA41: =#REF!*BA$151 -> #REF! | BB41: =SUM(AE41:AG41)-AH41 -> 0
...

Sheet Sheet2

Sheet Capgemini PResence and HC
B1: EAI | C1: T3 HC | D1: CSO_QA ScopeHC | E1: Y/N | F1: CG Assgn | G1: Human momths | I1: This data is from Kiyohara sans sheet. Human Months is FTE equivalent which we will use
B2: 9629 | C2: 0 | D2: 0 | E2: N | F2: 0 | G2: 0
B3: 9796 | C3: 0 | D3: 0 | E3: N | F3: 0 | G3: 0
B4: 9800 | C4: 0 | D4: 0 | E4: N | F4: 0 | G4: 0
B5: 9801 | C5: 0 | D5: 0 | E5: N | F5: 0 | G5: 0
B6: 9802 | C6: 0 | D6: 0 | E6: N | F6: 0 | G6: 0
B7: 9803 | C7: 0 | D7: 0 | E7: N | F7: 0 | G7: 0
B8: 9804 | C8: 0 | D8: 0 | E8: N | F8: 0 | G8: 0
B9: 9805 | C9: 0 | D9: 0 | E9: N | F9: 0 | G9: 0
B10: 9806 | C10: 0 | D10: 0 | E10: N | F10: 0 | G10: 0
B11: 9807 | C11: 0 | D11: 0 | E11: N | F11: 0 | G11: 0
B12: 9808 | C12: 0 | D12: 0 | E12: N | F12: 0 | G12: 0
B13: 9810 | C13: 0 | D13: 0 | E13: N | F13: 0 | G13: 0
... B143: 14930 | C143: 0 | D143: 0 | E143: N | F143: 0 | G143: 0
