Workbook

Sheet README
A1: MetLife Japan | Golden Application Inventory — archetype classification
A2: The single reference every domain team classifies against. One rule set, applied identically to all 142 applications.
A4: WHAT THIS IS
B5: Purpose | C5: The authoritative archetype classification for all 142 applications in Appendix 3 v2. Every domain model must classify against this sheet rather than re-deriving its own.
B6: Why it exists | C6: The archetype sets three ceilings and one method for every application — the AI ceiling, the offshore ceiling, the transition mechanic and the sourcing construct. If two domains classify the same way differently, their prices are not comparable.
B7: It is live, not a snapshot | C7: The archetype column is a formula, not a value. Change a source field and the classification, the parameters and both summaries re-derive.
A8: HOW TO USE IT — FOR A DOMAIN TEAM
B9: 1 · Filter | C9: Open Golden Inventory and filter column E to your 領域. The sheet has an autofilter on row 4.
B10: 2 · Read your mix | C10: Go to Domain Summary and find your row. It gives your application count, effort, archetype mix and the weighted AI and offshore ceilings for your domain. Those are the starting parameters for your model.
B11: 3 · Cut your value streams | C11: Group your applications into functional value streams. Reconcile to your domain effort exactly before you build any pod.
B12: 4 · Do not re-derive the archetype | C12: If you believe an application is misclassified, use the Override column and record who and why. Do not change the rule.
A13: THE RULE, IN ORDER
B14: Rule 1 → D | C14: Primary code language contains COBOL, Assembler, ASM, RPG, EASYPLUS or PL/I. Mainframe and AS/400 estate.
B15: Rule 2 → C | C15: Not rule 1, and Priority Transfer Targets = Y. The ten applications MetLife has already flagged for transfer.
B16: Rule 3 → B | C16: Not rules 1 or 2, and Cloud Indicator = Yes. Cloud-migrated, so re-platformed, documented and specifiable.
B17: Rule 4 → A | C17: Everything else. On-premises, non-mainframe, not flagged for transfer — where Japanese business context is bound to the application.
B18: Order matters | C18: The rules are exclusive and evaluated top to bottom. An application matching more than one test takes the first.
A19: RECONCILIATION AGAINST SECTION 4.1
B20: Application counts | C20: Match exactly for all four archetypes: A 71, B 33, C 10, D 28.
B21: Effort | C21: B and C match exactly (379.5 and 569.9). A and D differ by 4.7 units in opposite directions — this sheet gives A 317.1 and D 237.5 against Section 4.1's A 321.8 and D 232.8.
B22: Which to use | C22: This sheet. The figures here are reproducible from the source fields; the Section 4.1 A/D split is not. Section 4.1 should be corrected to match.
A23: GOVERNANCE
B24: Owner | C24: Solution architecture. Changes to the rule require agreement across all eleven domain teams, because the rule sets the price.
B25: Overrides | C25: Permitted, but only on the Overrides sheet with a named owner, a date and a reason. An override changes one application, never the rule.
B26: Source | C26: Appendix 3 v2 — "03 [Appendix 3] Target EA Inventory v2.xlsx", sheet ApplicationList. 142 applications, 1,504.0 effort units.
B27: Known data gap | C27: Named supply (FTC + FTE + MGCC) sums to 1,458.8 against 1,504.0 of effort. The 45.2-unit gap sits in 15 applications, mostly Storage & Preservation and Data Infrastructure. Raised as a clarification; not allocated here.

Sheet Classification Rules
A1: Classification rules and the parameters each archetype carries
A2: Blue cells are inputs. The Golden Inventory reads every parameter from this sheet, so changing it here changes it everywhere.
A4: A. THE RULE — evaluated in order, first match wins
B5: Rule | C5: Archetype | D5: Name | E5: Test applied to the source field | F5: Apps | G5: Effort
B6: Rule 1 | C6: D | D6: Legacy-coupled core | E6: Primary code language contains COBOL, Assembler, ASM, RPG, EASYPLUS or PL/I | F6: =COUNTIF('Golden Inventory'!$AA:$AA,$C6) -> 28 | G6: =SUMIF('Golden Inventory'!$AA:$AA,$C6,'Golden Inventory'!$T:$T) -> 237.50779
B7: Rule 2 | C7: C | D7: MGCC-destined | E7: Not rule 1, and Priority Transfer Targets = Y | F7: =COUNTIF('Golden Inventory'!$AA:$AA,$C7) -> 10 | G7: =SUMIF('Golden Inventory'!$AA:$AA,$C7,'Golden Inventory'!$T:$T) -> 569.88025
B8: Rule 3 | C8: B | D8: Offshore-ready | E8: Not rules 1-2, and Cloud Indicator = Yes | F8: =COUNTIF('Golden Inventory'!$AA:$AA,$C8) -> 33 | G8: =SUMIF('Golden Inventory'!$AA:$AA,$C8,'Golden Inventory'!$T:$T) -> 379.50447
B9: Rule 4 | C9: A | D9: Language-locked | E9: Everything else — on premises, not mainframe, not a transfer target | F9: =COUNTIF('Golden Inventory'!$AA:$AA,$C9) -> 71 | G9: =SUMIF('Golden Inventory'!$AA:$AA,$C9,'Golden Inventory'!$T:$T) -> 317.08354
D10: Total | F10: =SUM(F6:F9) -> 142 | G10: =SUM(G6:G9) -> 1503.976
A12: B. WHY EACH ARCHETYPE IS ITS OWN GROUP
B13: D | C13: Legacy-coupled core | D13: Rules hard-coded across modules and design truth is not written down. AI does comprehension here, not generation.
B14: C | C14: MGCC-destined | D14: MetLife has already flagged these for transfer and nine of ten already carry MGCC people. Routing them through a vendor transition pays for the same knowledge transfer twice.
B15: B | C15: Offshore-ready | D15: Cloud migration has already forced re-platforming, documentation and specifiability. Highest AI and offshore ceiling in the estate.
B16: A | C16: Language-locked | D16: On-premises and non-mainframe, so the constraint is not the technology — it is that the business context exists only in Japanese, in few heads.
A18: C. AI CEILING — phase effort mix x AI-addressable share per phase
B19: Delivery phase | C19: Share of effort | D19: A | E19: B | F19: C | G19: D
B20: Requirements & impact analysis | C20: 0.15 | D20: 0.22 | E20: 0.35 | F20: 0.35 | G20: 0.35
B21: Design & architecture | C21: 0.1 | D21: 0.2 | E21: 0.3 | F21: 0.3 | G21: 0.22
B22: Build & code | C22: 0.3 | D22: 0.32 | E22: 0.55 | F22: 0.5 | G22: 0.2
B23: Test & quality assurance | C23: 0.25 | D23: 0.38 | E23: 0.6 | F23: 0.55 | G23: 0.4
B24: Release & deploy | C24: 0.05 | D24: 0.3 | E24: 0.5 | F24: 0.45 | G24: 0.25
B25: Run, monitor & coordinate | C25: 0.15 | D25: 0.3 | E25: 0.4 | F25: 0.4 | G25: 0.32
B26: Phase mix total (must equal 100%) | C26: =SUM(C20:C25) -> 1
B27: WEIGHTED AI CEILING | D27: =SUMPRODUCT($C$20:$C$25,D20:D25) -> 0.304 | E27: =SUMPRODUCT($C$20:$C$25,E20:E25) -> 0.4825 | F27: =SUMPRODUCT($C$20:$C$25,F20:F25) -> 0.4525 | G27: =SUMPRODUCT($C$20:$C$25,G20:G25) -> 0.295
A29: D. REALISATION, AND THE NON-AI COMPONENTS — portfolio defaults
B30: Driver | C30: Year 1 | D30: Year 2 | E30: Year 3 | G30: Note
B31: AI realisation — share of ceiling captured | C31: 0.25 | D31: 0.55 | E31: 0.75 | G31: Domain teams may lower this with a stated reason, e.g. a platform on a sunset path.
B32: Classical ADM productivity (cumulative) | C32: 0.02 | D32: 0.05 | E32: 0.07 | G32: Standardisation, defect reduction, shift-left.
B33: Operating-model productivity (cumulative) | C33: 0.03 | D33: 0.06 | E33: 0.08 | G33: Pod consolidation, span of control, one release train.
A35: E. OFFSHORE CEILING
C36: A | D36: B | E36: C | F36: D
B37: Offshore-able ceiling | C37: 0.15 | D37: 0.78 | E37: 0.85 | F37: 0.58
B38: Applied by policy | C38: 0.15 | D38: 0.78 | E38: 0 | F38: 0.58 | H38: Archetype C is held at zero: we take only the onshore Japanese-language roles while MGCC takes engineering.
B39: Realisation by Year 3 | C39: 0.93
A41: F. DERIVED PARAMETERS — what the Golden Inventory looks up
B42: Archetype | C42: Name | D42: AI ceiling | E42: Productivity by Y3 | F42: Offshore ceiling | G42: Offshore by Y3 | H42: Transition method | I42: Typical duration | J42: Sourcing construct
B43: A | C43: Language-locked | D43: =D$27 -> 0.304 | E43: =1-(1-D$27*$E$31)*(1-$E$32)*(1-$E$33) -> 0.3394768 | F43: =C$38 -> 0.15 | G43: =C$38*$C$39 -> 0.1395 | H43: Full transition into a Japanese-resident pod; knowledge capture is the critical path | I43: 10-14 weeks per cluster | J43: Fully sourced, onshore-weighted
B44: B | C44: Offshore-ready | D44: =E$27 -> 0.4825 | E44: =1-(1-E$27*$E$31)*(1-$E$32)*(1-$E$33) -> 0.45402025 | F44: =D$38 -> 0.78 | G44: =D$38*$C$39 -> 0.7254 | H44: Full transition, fastest ramp; artefacts already exist | I44: 6-8 weeks per cluster | J44: Fully sourced, moving to output units
B45: C | C45: MGCC-destined | D45: =F$27 -> 0.4525 | E45: =1-(1-F$27*$E$31)*(1-$E$32)*(1-$E$33) -> 0.43476925 | F45: =E$38 -> 0 | G45: =E$38*$C$39 -> 0 | H45: Role handover of onshore roles; MGCC takes engineering directly from the incumbents | I45: 6-8 weeks, role handover | J45: Co-sourced with MGCC, permanently
B46: D | C46: Legacy-coupled core | D46: =G$27 -> 0.295 | E46: =1-(1-G$27*$E$31)*(1-$E$32)*(1-$E$33) -> 0.3337015 | F46: =F$38 -> 0.58 | G46: =F$38*$C$39 -> 0.5394 | H46: Deepest and slowest; design truth recovered from source, schedulers and job logs | I46: 14-20 weeks per cluster | J46: Fully sourced, MetLife SMEs paired

Sheet Golden Inventory
A1: Golden inventory — 142 applications, archetype derived live from the source fields
A2: Column F is the Value Stream. Columns L, M and N are the only three fields the rule reads. Columns X to AK are formulas. Column Z is the only place to type.
A4: # | B4: EAI ID | C4: Application | D4: Application long name | E4: 領域 (domain) | F4: Value Stream | G4: Group | H4: Team | I4: Application class | J4: Business critical | K4: Hosting | L4: PRIMARY CODE LANGUAGE | M4: PRIORITY TRANSFER | N4: CLOUD INDICATOR | O4: Cloud platform | P4: Source code owner | Q4: Current FTC | R4: Current FTE | S4: Current MGCC | T4: Total effort | U4: % of PRJ | V4: Target FTC | W4: Target FTE/MGCC | X4: Rule fired | Y4: Derived archetype | Z4: OVERRIDE | AA4: FINAL ARCHETYPE | AB4: Archetype name | AC4: Evidence — what decided it | AD4: Why this archetype | AE4: AI ceiling | AF4: Productivity by Y3 | AG4: Offshore ceiling | AH4: Offshore by Y3 | AI4: Transition method | AJ4: Typical duration | AK4: Sourcing construct
A5: 1 | B5: 9629 | C5: Global Sales Comp - Japan | D5: Global Sales Comp - Japan | E5: Fee Management | F5: VS1: Commission Processing & Management | G5: Core Insurance Systems Group 34956 | H5: Commission Systems Team 34958 | I5: Core Business Application | J5: N | K5: Yes | L5: Other#Infomatica workflow Bash shell Dos batch | M5: N | N5: Yes | O5: Software as a Service (SaaS) | P5: Non-MetLife Owned Application Code (3rd party/COTS) | Q5: 0 | R5: 0 | S5: 0 | T5: 0 | U5: 0 | V5: 0 | W5: 0 | X5: =IF(OR(ISNUMBER(SEARCH("COBOL",$L5)),ISNUMBER(SEARCH("Assembler",$L5)),ISNUMBER(SEARCH("ASM",$L5)),ISNUMBER(SEARCH("RPG",$L5)),ISNUMBER(SEARCH("EASYPLUS",$L5)),ISNUMBER(SEARCH("PL/I",$L5))),"Rule 1",IF($M5="Y","Rule 2",IF($N5="Yes","Rule 3","Rule 4"))) -> Rule 3 | Y5: =IF($X5="Rule 1","D",IF($X5="Rule 2","C",IF($X5="Rule 3","B","A"))) -> B | AA5: =IF($Z5="",$Y5,$Z5) -> B | AB5: =IFERROR(INDEX('Classification Rules'!$C$43:$C$46,MATCH($AA5,'Classification Rules'!$B$43:$B$46,0)),"") -> Offshore-ready | AC5: =IF($X5="Rule 1","Language: "&$L5,IF($X5="Rule 2","Priority Transfer Target = Y",IF($X5="Rule 3","Cloud Indicator = Yes ("&$O5&")","Cloud Indicator = No, not mainframe, not a transfer target"))) -> Cloud Indicator = Yes (Software as a Service (SaaS)) | AD5: =IFERROR(INDEX('Classification Rules'!$D$13:$D$16,MATCH($AA5,'Classification Rules'!$B$13:$B$16,0)),"") -> Cloud migration has already forced re-platforming, documentation and specifiability. Highest AI and offshore ceiling in the estate. | AE5: =IFERROR(INDEX('Classification Rules'!$D$43:$D$46,MATCH($AA5,'Classification Rules'!$B$43:$B$46,0)),"") -> 0.4825 | AF5: =IFERROR(INDEX('Classification Rules'!$E$43:$E$46,MATCH($AA5,'Classification Rules'!$B$43:$B$46,0)),"") -> 0.45402025 | AG5: =IFERROR(INDEX('Classification Rules'!$F$43:$F$46,MATCH($AA5,'Classification Rules'!$B$43:$B$46,0)),"") -> 0.78 | AH5: =IFERROR(INDEX('Classification Rules'!$G$43:$G$46,MATCH($AA5,'Classification Rules'!$B$43:$B$46,0)),"") -> 0.7254 | AI5: =IFERROR(INDEX('Classification Rules'!$I$43:$I$46,MATCH($AA5,'Classification Rules'!$B$43:$B$46,0)),"") -> 6-8 weeks per cluster | AJ5: =IFERROR(INDEX('Classification Rules'!$J$43:$J$46,MATCH($AA5,'Classification Rules'!$B$43:$B$46,0)),"") -> Fully sourced, moving to output units | AK5: =IFERROR(INDEX('Classification Rules'!$K$43:$K$46,MATCH($AA5,'Classification Rules'!$B$43:$B$46,0)),"") -> 0
A6: 2 | B6: 9796 | C6: LC POSPMC MF-JPN | D6: LifeComm POSPMC | E6: contract management | F6: VS1: Policy Administration & Contract Servicing | G6: Core Insurance Systems Group 34956 | H6: Policy Admin Systems Team 34957 | I6: Core Business Application | J6: Y | K6: Yes | L6: Assembler, COBOL, MU(EASYPLUS), JCL | M6: N | N6: No | P6: MetLife Owned Application Code | Q6: 59.558958 | R6: 7.7541667 | S6: 0 | T6: 67.313125 | U6: 0.71176374 | V6: 33.656563 | W6: 33.656563 | X6: =IF(OR(ISNUMBER(SEARCH("COBOL",$L6)),ISNUMBER(SEARCH("Assembler",$L6)),ISNUMBER(SEARCH("ASM",$L6)),ISNUMBER(SEARCH("RPG",$L6)),ISNUMBER(SEARCH("EASYPLUS",$L6)),ISNUMBER(SEARCH("PL/I",$L6))),"Rule 1",IF($M6="Y","Rule 2",IF($N6="Yes","Rule 3","Rule 4"))) -> Rule 1 | Y6: =IF($X6="Rule 1","D",IF($X6="Rule 2","C",IF($X6="Rule 3","B","A"))) -> D | AA6: =IF($Z6="",$Y6,$Z6) -> D | AB6: =IFERROR(INDEX('Classification Rules'!$C$43:$C$46,MATCH($AA6,'Classification Rules'!$B$43:$B$46,0)),"") -> Legacy-coupled core | AC6: =IF($X6="Rule 1","Language: "&$L6,IF($X6="Rule 2","Priority Transfer Target = Y",IF($X6="Rule 3","Cloud Indicator = Yes ("&$O6&")","Cloud Indicator = No, not mainframe, not a transfer target"))) -> Language: Assembler, COBOL, MU(EASYPLUS), JCL | AD6: =IFERROR(INDEX('Classification Rules'!$D$13:$D$16,MATCH($AA6,'Classification Rules'!$B$13:$B$16,0)),"") -> Rules hard-coded across modules and design truth is not written down. AI does comprehension here, not generation. | AE6: =IFERROR(INDEX('Classification Rules'!$D$43:$D$46,MATCH($AA6,'Classification Rules'!$B$43:$B$46,0)),"") -> 0.295 | AF6: =IFERROR(INDEX('Classification Rules'!$E$43:$E$46,MATCH($AA6,'Classification Rules'!$B$43:$B$46,0)),"") -> 0.3337015 | AG6: =IFERROR(INDEX('Classification Rules'!$F$43:$F$46,MATCH($AA6,'Classification Rules'!$B$43:$B$46,0)),"") -> 0.58 | AH6: =IFERROR(INDEX('Classification Rules'!$G$43:$G$46,MATCH($AA6,'Classification Rules'!$B$43:$B$46,0)),"") -> 0.5394 | AI6: =IFERROR(INDEX('Classification Rules'!$I$43:$I$46,MATCH($AA6,'Classification Rules'!$B$43:$B$46,0)),"") -> 14-20 weeks per cluster | AJ6: =IFERROR(INDEX('Classification Rules'!$J$43:$J$46,MATCH($AA6,'Classification Rules'!$B$43:$B$46,0)),"") -> Fully sourced, MetLife SMEs paired | AK6: =IFERROR(INDEX('Classification Rules'!$K$43:$K$46,MATCH($AA6,'Classification Rules'!$B$43:$B$46,0)),"") -> 0
A7: 3 | B7: 9800 | C7: LC Billing MF-JPN | D7: LifeComm Billing | E7: contract management | F7: VS2: Billing, Collections & Payments | G7: Core Insurance Systems Group 34956 | H7: Policy Admin Systems Team 34957 | I7: Core Business Application | J7: Y | K7: Yes | L7: COBOL, Assembler, MU(EASYPLUS), JCL | M7: N | N7: No | P7: MetLife Owned Application Code | Q7: 20.892167 | R7: 1.85375 | S7: 0 | T7: 22.745917 | U7: 0.94285788 | V7: 11.372958 | W7: 11.372958 | X7: =IF(OR(ISNUMBER(SEARCH("COBOL",$L7)),ISNUMBER(SEARCH("Assembler",$L7)),ISNUMBER(SEARCH("ASM",$L7)),ISNUMBER(SEARCH("RPG",$L7)),ISNUMBER(SEARCH("EASYPLUS",$L7)),ISNUMBER(SEARCH("PL/I",$L7))),"Rule 1",IF($M7="Y","Rule 2",IF($N7="Yes","Rule 3","Rule 4"))) -> Rule 1 | Y7: =IF($X7="Rule 1","D",IF($X7="Rule 2","C",IF($X7="Rule 3","B","A"))) -> D | AA7: =IF($Z7="",$Y7,$Z7) -> D | AB7: =IFERROR(INDEX('Classification Rules'!$C$43:$C$46,MATCH($AA7,'Classification Rules'!$B$43:$B$46,0)),"") -> Legacy-coupled core | AC7: =IF($X7="Rule 1","Language: "&$L7,IF($X7="Rule 2","Priority Transfer Target = Y",IF($X7="Rule 3","Cloud Indicator = Yes ("&$O7&")","Cloud Indicator = No, not mainframe, not a transfer target"))) -> Language: COBOL, Assembler, MU(EASYPLUS), JCL | AD7: =IFERROR(INDEX('Classification Rules'!$D$13:$D$16,MATCH($AA7,'Classification Rules'!$B$13:$B$16,0)),"") -> Rules hard-coded across modules and design truth is not written down. AI does comprehension here, not generation. | AE7: =IFERROR(INDEX('Classification Rules'!$D$43:$D$46,MATCH($AA7,'Classification Rules'!$B$43:$B$46,0)),"") -> 0.295 | AF7: =IFERROR(INDEX('Classification Rules'!$E$43:$E$46,MATCH($AA7,'Classification Rules'!$B$43:$B$46,0)),"") -> 0.3337015 | AG7: =IFERROR(INDEX('Classification Rules'!$F$43:$F$46,MATCH($AA7,'Classification Rules'!$B$43:$B$46,0)),"") -> 0.58 | AH7: =IFERROR(INDEX('Classification Rules'!$G$43:$G$46,MATCH($AA7,'Classification Rules'!$B$43:$B$46,0)),"") -> 0.5394 | AI7: =IFERROR(INDEX('Classification Rules'!$I$43:$I$46,MATCH($AA7,'Classification Rules'!$B$43:$B$46,0)),"") -> 14-20 weeks per cluster | AJ7: =IFERROR(INDEX('Classification Rules'!$J$43:$J$46,MATCH($AA7,'Classification Rules'!$B$43:$B$46,0)),"") -> Fully sourced, MetLife SMEs paired | AK7: =IFERROR(INDEX('Classification Rules'!$K$43:$K$46,MATCH($AA7,'Classification Rules'!$B$43:$B$46,0)),"") -> 0
A8: 4 | B8: 9801 | C8: LC Collection MF-JPN | D8: LifeComm Collection | E8: contract management | F8: VS2: Billing, Collections & Payments | G8: Core Insurance Systems Group 34956 | H8: Policy Admin Systems Team 34957 | I8: Core Business Application | J8: Y | K8: Yes | L8: COBOL, Assembler, MU(EASYPLUS), JCL | M8: N | N8: No | P8: MetLife Owned Application Code | Q8: 0 | R8: 0 | S8: 0 | T8: 0 | U8: 0 | V8: 0 | W8: 0 | X8: =IF(OR(ISNUMBER(SEARCH("COBOL",$L8)),ISNUMBER(SEARCH("Assembler",$L8)),ISNUMBER(SEARCH("ASM",$L8)),ISNUMBER(SEARCH("RPG",$L8)),ISNUMBER(SEARCH("EASYPLUS",$L8)),ISNUMBER(SEARCH("PL/I",$L8))),"Rule 1",IF($M8="Y","Rule 2",IF($N8="Yes","Rule 3","Rule 4"))) -> Rule 1 | Y8: =IF($X8="Rule 1","D",IF($X8="Rule 2","C",IF($X8="Rule 3","B","A"))) -> D | AA8: =IF($Z8="",$Y8,$Z8) -> D | AB8: =IFERROR(INDEX('Classification Rules'!$C$43:$C$46,MATCH($AA8,'Classification Rules'!$B$43:$B$46,0)),"") -> Legacy-coupled core | AC8: =IF($X8="Rule 1","Language: "&$L8,IF($X8="Rule 2","Priority Transfer Target = Y",IF($X8="Rule 3","Cloud Indicator = Yes ("&$O8&")","Cloud Indicator = No, not mainframe, not a transfer target"))) -> Language: COBOL, Assembler, MU(EASYPLUS), JCL | AD8: =IFERROR(INDEX('Classification Rules'!$D$13:$D$16,MATCH($AA8,'Classification Rules'!$B$13:$B$16,0)),"") -> Rules hard-coded across modules and design truth is not written down. AI does comprehension here, not generation. | AE8: =IFERROR(INDEX('Classification Rules'!$D$43:$D$46,MATCH($AA8,'Classification Rules'!$B$43:$B$46,0)),"") -> 0.295 | AF8: =IFERROR(INDEX('Classification Rules'!$E$43:$E$46,MATCH($AA8,'Classification Rules'!$B$43:$B$46,0)),"") -> 0.3337015 | AG8: =IFERROR(INDEX('Classification Rules'!$F$43:$F$46,MATCH($AA8,'Classification Rules'!$B$43:$B$46,0)),"") -> 0.58 | AH8: =IFERROR(INDEX('Classification Rules'!$G$43:$G$46,MATCH($AA8,'Classification Rules'!$B$43:$B$46,0)),"") -> 0.5394 | AI8: =IFERROR(INDEX('Classification Rules'!$I$43:$I$46,MATCH($AA8,'Classification Rules'!$B$43:$B$46,0)),"") -> 14-20 weeks per cluster | AJ8: =IFERROR(INDEX('Classification Rules'!$J$43:$J$46,MATCH($AA8,'Classification Rules'!$B$43:$B$46,0)),"") -> Fully sourced, MetLife SMEs paired | AK8: =IFERROR(INDEX('Classification Rules'!$K$43:$K$46,MATCH($AA8,'Classification Rules'!$B$43:$B$46,0)),"") -> 0
A9: 5 | B9: 9802 | C9: LC Corresponding MF-JPN | D9: LifeComm Corresponding | E9: contract management | F9: VS4: Correspondence, Documents & Tax | G9: Core Insurance Systems Group 34956 | H9: Policy Admin Systems Team 34957 | I9: Core Business Application | J9: Y | K9: Yes | L9: COBOL, Assembler, MU(EASYPLUS), JCL | M9: N | N9: No | P9: MetLife Owned Application Code | Q9: 15.953625 | R9: 1.6541667 | S9: 0 | T9: 17.607792 | U9: 0.98287217 | V9: 8.8038958 | W9: 8.8038958 | X9: =IF(OR(ISNUMBER(SEARCH("COBOL",$L9)),ISNUMBER(SEARCH("Assembler",$L9)),ISNUMBER(SEARCH("ASM",$L9)),ISNUMBER(SEARCH("RPG",$L9)),ISNUMBER(SEARCH("EASYPLUS",$L9)),ISNUMBER(SEARCH("PL/I",$L9))),"Rule 1",IF($M9="Y","Rule 2",IF($N9="Yes","Rule 3","Rule 4"))) -> Rule 1 | Y9: =IF($X9="Rule 1","D",IF($X9="Rule 2","C",IF($X9="Rule 3","B","A"))) -> D | AA9: =IF($Z9="",$Y9,$Z9) -> D | AB9: =IFERROR(INDEX('Classification Rules'!$C$43:$C$46,MATCH($AA9,'Classification Rules'!$B$43:$B$46,0)),"") -> Legacy-coupled core | AC9: =IF($X9="Rule 1","Language: "&$L9,IF($X9="Rule 2","Priority Transfer Target = Y",IF($X9="Rule 3","Cloud Indicator = Yes ("&$O9&")","Cloud Indicator = No, not mainframe, not a transfer target"))) -> Language: COBOL, Assembler, MU(EASYPLUS), JCL | AD9: =IFERROR(INDEX('Classification Rules'!$D$13:$D$16,MATCH($AA9,'Classification Rules'!$B$13:$B$16,0)),"") -> Rules hard-coded across modules and design truth is not written down. AI does comprehension here, not generation. | AE9: =IFERROR(INDEX('Classification Rules'!$D$43:$D$46,MATCH($AA9,'Classification Rules'!$B$43:$B$46,0)),"") -> 0.295 | AF9: =IFERROR(INDEX('Classification Rules'!$E$43:$E$46,MATCH($AA9,'Classification Rules'!$B$43:$B$46,0)),"") -> 0.3337015 | AG9: =IFERROR(INDEX('Classification Rules'!$F$43:$F$46,MATCH($AA9,'Classification Rules'!$B$43:$B$46,0)),"") -> 0.58 | AH9: =IFERROR(INDEX('Classification Rules'!$G$43:$G$46,MATCH($AA9,'Classification Rules'!$B$43:$B$46,0)),"") -> 0.5394 | AI9: =IFERROR(INDEX('Classification Rules'!$I$43:$I$46,MATCH($AA9,'Classification Rules'!$B$43:$B$46,0)),"") -> 14-20 weeks per cluster | AJ9: =IFERROR(INDEX('Classification Rules'!$J$43:$J$46,MATCH($AA9,'Classification Rules'!$B$43:$B$46,0)),"") -> Fully sourced, MetLife SMEs paired | AK9: =IFERROR(INDEX('Classification Rules'!$K$43:$K$46,MATCH($AA9,'Classification Rules'!$B$43:$B$46,0)),"") -> 0
A10: 6 | B10: 9803 | C10: LC UWI MF-JPN | D10: LifeComm UWI | E10: contract management | F10: VS5: New Business, Underwriting & Interfaces | G10: Core Insurance Systems Group 34956 | H10: Policy Admin Systems Team 34957 | I10: Core Business Application | J10: Y | K10: Yes | L10: Assembler, COBOL, MU(EASYPLUS), JCL | M10: N | N10: No | P10: MetLife Owned Application Code | Q10: 8.8045833 | R10: 0.85 | S10: 0 | T10: 9.6545833 | U10: 0.94821113 | V10: 4.8272917 | W10: 4.8272917 | X10: =IF(OR(ISNUMBER(SEARCH("COBOL",$L10)),ISNUMBER(SEARCH("Assembler",$L10)),ISNUMBER(SEARCH("ASM",$L10)),ISNUMBER(SEARCH("RPG",$L10)),ISNUMBER(SEARCH("EASYPLUS",$L10)),ISNUMBER(SEARCH("PL/I",$L10))),"Rule 1",IF($M10="Y","Rule 2",IF($N10="Yes","Rule 3","Rule 4"))) -> Rule 1 | Y10: =IF($X10="Rule 1","D",IF($X10="Rule 2","C",IF($X10="Rule 3","B","A"))) -> D | AA10: =IF($Z10="",$Y10,$Z10) -> D | AB10: =IFERROR(INDEX('Classification Rules'!$C$43:$C$46,MATCH($AA10,'Classification Rules'!$B$43:$B$46,0)),"") -> Legacy-coupled core | AC10: =IF($X10="Rule 1","Language: "&$L10,IF($X10="Rule 2","Priority Transfer Target = Y",IF($X10="Rule 3","Cloud Indicator = Yes ("&$O10&")","Cloud Indicator = No, not mainframe, not a transfer target"))) -> Language: Assembler, COBOL, MU(EASYPLUS), JCL | AD10: =IFERROR(INDEX('Classification Rules'!$D$13:$D$16,MATCH($AA10,'Classification Rules'!$B$13:$B$16,0)),"") -> Rules hard-coded across modules and design truth is not written down. AI does comprehension here, not generation. | AE10: =IFERROR(INDEX('Classification Rules'!$D$43:$D$46,MATCH($AA10,'Classification Rules'!$B$43:$B$46,0)),"") -> 0.295 | AF10: =IFERROR(INDEX('Classification Rules'!$E$43:$E$46,MATCH($AA10,'Classification Rules'!$B$43:$B$46,0)),"") -> 0.3337015 | AG10: =IFERROR(INDEX('Classification Rules'!$F$43:$F$46,MATCH($AA10,'Classification Rules'!$B$43:$B$46,0)),"") -> 0.58 | AH10: =IFERROR(INDEX('Classification Rules'!$G$43:$G$46,MATCH($AA10,'Classification Rules'!$B$43:$B$46,0)),"") -> 0.5394 | AI10: =IFERROR(INDEX('Classification Rules'!$I$43:$I$46,MATCH($AA10,'Classification Rules'!$B$43:$B$46,0)),"") -> 14-20 weeks per cluster | AJ10: =IFERROR(INDEX('Classification Rules'!$J$43:$J$46,MATCH($AA10,'Classification Rules'!$B$43:$B$46,0)),"") -> Fully sourced, MetLife SMEs paired | AK10: =IFERROR(INDEX('Classification Rules'!$K$43:$K$46,MATCH($AA10,'Classification Rules'!$B$43:$B$46,0)),"") -> 0
A11: 7 | B11: 9804 | C11: LC AAPerf MF-JPN | D11: LifeComm AgentAgencyPerformance | E11: contract management | F11: VS3: Agency & Commission | G11: Core Insurance Systems Group 34956 | H11: Policy Admin Systems Team 34957 | I11: Core Business Application | J11: Y | K11: Yes | L11: COBOL, Assembler, MU(EASYPLUS), JCL | M11: N | N11: No | P11: MetLife Owned Application Code | Q11: 10.784167 | R11: 0.74583333 | S11: 0 | T11: 11.53 | U11: 0.83304423 | V11: 5.765 | W11: 5.765 | X11: =IF(OR(ISNUMBER(SEARCH("COBOL",$L11)),ISNUMBER(SEARCH("Assembler",$L11)),ISNUMBER(SEARCH("ASM",$L11)),ISNUMBER(SEARCH("RPG",$L11)),ISNUMBER(SEARCH("EASYPLUS",$L11)),ISNUMBER(SEARCH("PL/I",$L11))),"Rule 1",IF($M11="Y","Rule 2",IF($N11="Yes","Rule 3","Rule 4"))) -> Rule 1 | Y11: =IF($X11="Rule 1","D",IF($X11="Rule 2","C",IF($X11="Rule 3","B","A"))) -> D | AA11: =IF($Z11="",$Y11,$Z11) -> D | AB11: =IFERROR(INDEX('Classification Rules'!$C$43:$C$46,MATCH($AA11,'Classification Rules'!$B$43:$B$46,0)),"") -> Legacy-coupled core | AC11: =IF($X11="Rule 1","Language: "&$L11,IF($X11="Rule 2","Priority Transfer Target = Y",IF($X11="Rule 3","Cloud Indicator = Yes ("&$O11&")","Cloud Indicator = No, not mainframe, not a transfer target"))) -> Language: COBOL, Assembler, MU(EASYPLUS), JCL | AD11: =IFERROR(INDEX('Classification Rules'!$D$13:$D$16,MATCH($AA11,'Classification Rules'!$B$13:$B$16,0)),"") -> Rules hard-coded across modules and design truth is not written down. AI does comprehension here, not generation. | AE11: =IFERROR(INDEX('Classification Rules'!$D$43:$D$46,MATCH($AA11,'Classification Rules'!$B$43:$B$46,0)),"") -> 0.295 | AF11: =IFERROR(INDEX('Classification Rules'!$E$43:$E$46,MATCH($AA11,'Classification Rules'!$B$43:$B$46,0)),"") -> 0.3337015 | AG11: =IFERROR(INDEX('Classification Rules'!$F$43:$F$46,MATCH($AA11,'Classification Rules'!$B$43:$B$46,0)),"") -> 0.58 | AH11: =IFERROR(INDEX('Classification Rules'!$G$43:$G$46,MATCH($AA11,'Classification Rules'!$B$43:$B$46,0)),"") -> 0.5394 | AI11: =IFERROR(INDEX('Classification Rules'!$I$43:$I$46,MATCH($AA11,'Classification Rules'!$B$43:$B$46,0)),"") -> 14-20 weeks per cluster | AJ11: =IFERROR(INDEX('Classification Rules'!$J$43:$J$46,MATCH($AA11,'Classification Rules'!$B$43:$B$46,0)),"") -> Fully sourced, MetLife SMEs paired | AK11: =IFERROR(INDEX('Classification Rules'!$K$43:$K$46,MATCH($AA11,'Classification Rules'!$B$43:$B$46,0)),"") -> 0
A12: 8 | B12: 9805 | C12: LC Payment MF-JPN | D12: LifeComm Payment | E12: contract management | F12: VS2: Billing, Collections & Payments | G12: Core Insurance Systems Group 34956 | H12: Policy Admin Systems Team 34957 | I12: Core Business Application | J12: Y | K12: Yes | L12: COBOL, Assembler, MU(EASYPLUS), JCL | M12: N | N12: No | P12: MetLife Owned Application Code | Q12: 2.8966667 | R12: 0.025 | S12: 0 | T12: 2.9216667 | U12: 0.90587564 | V12: 1.4608333 | W12: 1.4608333 | X12: =IF(OR(ISNUMBER(SEARCH("COBOL",$L12)),ISNUMBER(SEARCH("Assembler",$L12)),ISNUMBER(SEARCH("ASM",$L12)),ISNUMBER(SEARCH("RPG",$L12)),ISNUMBER(SEARCH("EASYPLUS",$L12)),ISNUMBER(SEARCH("PL/I",$L12))),"Rule 1",IF($M12="Y","Rule 2",IF($N12="Yes","Rule 3","Rule 4"))) -> Rule 1 | Y12: =IF($X12="Rule 1","D",IF($X12="Rule 2","C",IF($X12="Rule 3","B","A"))) -> D | AA12: =IF($Z12="",$Y12,$Z12) -> D | AB12: =IFERROR(INDEX('Classification Rules'!$C$43:$C$46,MATCH($AA12,'Classification Rules'!$B$43:$B$46,0)),"") -> Legacy-coupled core | AC12: =IF($X12="Rule 1","Language: "&$L12,IF($X12="Rule 2","Priority Transfer Target = Y",IF($X12="Rule 3","Cloud Indicator = Yes ("&$O12&")","Cloud Indicator = No, not mainframe, not a transfer target"))) -> Language: COBOL, Assembler, MU(EASYPLUS), JCL | AD12: =IFERROR(INDEX('Classification Rules'!$D$13:$D$16,MATCH($AA12,'Classification Rules'!$B$13:$B$16,0)),"") -> Rules hard-coded across modules and design truth is not written down. AI does comprehension here, not generation. | AE12: =IFERROR(INDEX('Classification Rules'!$D$43:$D$46,MATCH($AA12,'Classification Rules'!$B$43:$B$46,0)),"") -> 0.295 | AF12: =IFERROR(INDEX('Classification Rules'!$E$43:$E$46,MATCH($AA12,'Classification Rules'!$B$43:$B$46,0)),"") -> 0.3337015 | AG12: =IFERROR(INDEX('Classification Rules'!$F$43:$F$46,MATCH($AA12,'Classification Rules'!$B$43:$B$46,0)),"") -> 0.58 | AH12: =IFERROR(INDEX('Classification Rules'!$G$43:$G$46,MATCH($AA12,'Classification Rules'!$B$43:$B$46,0)),"") -> 0.5394 | AI12: =IFERROR(INDEX('Classification Rules'!$I$43:$I$46,MATCH($AA12,'Classification Rules'!$B$43:$B$46,0)),"") -> 14-20 weeks per cluster | AJ12: =IFERROR(INDEX('Classification Rules'!$J$43:$J$46,MATCH($AA12,'Classification Rules'!$B$43:$B$46,0)),"") -> Fully sourced, MetLife SMEs paired | AK12: =IFERROR(INDEX('Classification Rules'!$K$43:$K$46,MATCH($AA12,'Classification Rules'!$B$43:$B$46,0)),"") -> 0
A13: 9 | B13: 9806 | C13: LC GL/SC MF-JPN | D13: LifeComm GL/SC | E13: contract management | F13: VS6: Finance, Valuation & Reinsurance | G13: Core Insurance Systems Group 34956 | H13: Policy Admin Systems Team 34957 | I13: Core Business Application | J13: Y | K13: Yes | L13: COBOL, Assembler, MU(EASYPLUS), JCL | M13: N | N13: No | P13: MetLife Owned Application Code | Q13: 5.28875 | R13: 1.025 | S13: 0 | T13: 6.31375 | U13: 0.83765591 | V13: 3.156875 | W13: 3.156875 | X13: =IF(OR(ISNUMBER(SEARCH("COBOL",$L13)),ISNUMBER(SEARCH("Assembler",$L13)),ISNUMBER(SEARCH("ASM",$L13)),ISNUMBER(SEARCH("RPG",$L13)),ISNUMBER(SEARCH("EASYPLUS",$L13)),ISNUMBER(SEARCH("PL/I",$L13))),"Rule 1",IF($M13="Y","Rule 2",IF($N13="Yes","Rule 3","Rule 4"))) -> Rule 1 | Y13: =IF($X13="Rule 1","D",IF($X13="Rule 2","C",IF($X13="Rule 3","B","A"))) -> D | AA13: =IF($Z13="",$Y13,$Z13) -> D | AB13: =IFERROR(INDEX('Classification Rules'!$C$43:$C$46,MATCH($AA13,'Classification Rules'!$B$43:$B$46,0)),"") -> Legacy-coupled core | AC13: =IF($X13="Rule 1","Language: "&$L13,IF($X13="Rule 2","Priority Transfer Target = Y",IF($X13="Rule 3","Cloud Indicator = Yes ("&$O13&")","Cloud Indicator = No, not mainframe, not a transfer target"))) -> Language: COBOL, Assembler, MU(EASYPLUS), JCL | AD13: =IFERROR(INDEX('Classification Rules'!$D$13:$D$16,MATCH($AA13,'Classification Rules'!$B$13:$B$16,0)),"") -> Rules hard-coded across modules and design truth is not written down. AI does comprehension here, not generation. | AE13: =IFERROR(INDEX('Classification Rules'!$D$43:$D$46,MATCH($AA13,'Classification Rules'!$B$43:$B$46,0)),"") -> 0.295 | AF13: =IFERROR(INDEX('Classification Rules'!$E$43:$E$46,MATCH($AA13,'Classification Rules'!$B$43:$B$46,0)),"") -> 0.3337015 | AG13: =IFERROR(INDEX('Classification Rules'!$F$43:$F$46,MATCH($AA13,'Classification Rules'!$B$43:$B$46,0)),"") -> 0.58 | AH13: =IFERROR(INDEX('Classification Rules'!$G$43:$G$46,MATCH($AA13,'Classification Rules'!$B$43:$B$46,0)),"") -> 0.5394 | AI13: =IFERROR(INDEX('Classification Rules'!$I$43:$I$46,MATCH($AA13,'Classification Rules'!$B$43:$B$46,0)),"") -> 14-20 weeks per cluster | AJ13: =IFERROR(INDEX('Classification Rules'!$J$43:$J$46,MATCH($AA13,'Classification Rules'!$B$43:$B$46,0)),"") -> Fully sourced, MetLife SMEs paired | AK13: =IFERROR(INDEX('Classification Rules'!$K$43:$K$46,MATCH($AA13,'Classification Rules'!$B$43:$B$46,0)),"") -> 0
A14: 10 | B14: 9807 | C14: LC Valuation MF-JPN | D14: LifeComm Valuation | E14: contract management | F14: VS6: Finance, Valuation & Reinsurance | G14: Core Insurance Systems Group 34956 | H14: Policy Admin Systems Team 34957 | I14: Core Business Application | J14: N | K14: Yes | L14: COBOL, Assembler, MU(EASYPLUS), JCL | M14: N | N14: No | P14: MetLife Owned Application Code | Q14: 9.76875 | R14: 1.4833333 | S14: 0 | T14: 11.252083 | U14: 0.8563229 | V14: 5.6260417 | W14: 5.6260417 | X14: =IF(OR(ISNUMBER(SEARCH("COBOL",$L14)),ISNUMBER(SEARCH("Assembler",$L14)),ISNUMBER(SEARCH("ASM",$L14)),ISNUMBER(SEARCH("RPG",$L14)),ISNUMBER(SEARCH("EASYPLUS",$L14)),ISNUMBER(SEARCH("PL/I",$L14))),"Rule 1",IF($M14="Y","Rule 2",IF($N14="Yes","Rule 3","Rule 4"))) -> Rule 1 | Y14: =IF($X14="Rule 1","D",IF($X14="Rule 2","C",IF($X14="Rule 3","B","A"))) -> D | AA14: =IF($Z14="",$Y14,$Z14) -> D | AB14: =IFERROR(INDEX('Classification Rules'!$C$43:$C$46,MATCH($AA14,'Classification Rules'!$B$43:$B$46,0)),"") -> Legacy-coupled core | AC14: =IF($X14="Rule 1","Language: "&$L14,IF($X14="Rule 2","Priority Transfer Target = Y",IF($X14="Rule 3","Cloud Indicator = Yes ("&$O14&")","Cloud Indicator = No, not mainframe, not a transfer target"))) -> Language: COBOL, Assembler, MU(EASYPLUS), JCL | AD14: =IFERROR(INDEX('Classification Rules'!$D$13:$D$16,MATCH($AA14,'Classification Rules'!$B$13:$B$16,0)),"") -> Rules hard-coded across modules and design truth is not written down. AI does comprehension here, not generation. | AE14: =IFERROR(INDEX('Classification Rules'!$D$43:$D$46,MATCH($AA14,'Classification Rules'!$B$43:$B$46,0)),"") -> 0.295 | AF14: =IFERROR(INDEX('Classification Rules'!$E$43:$E$46,MATCH($AA14,'Classification Rules'!$B$43:$B$46,0)),"") -> 0.3337015 | AG14: =IFERROR(INDEX('Classification Rules'!$F$43:$F$46,MATCH($AA14,'Classification Rules'!$B$43:$B$46,0)),"") -> 0.58 | AH14: =IFERROR(INDEX('Classification Rules'!$G$43:$G$46,MATCH($AA14,'Classification Rules'!$B$43:$B$46,0)),"") -> 0.5394 | AI14: =IFERROR(INDEX('Classification Rules'!$I$43:$I$46,MATCH($AA14,'Classification Rules'!$B$43:$B$46,0)),"") -> 14-20 weeks per cluster | AJ14: =IFERROR(INDEX('Classification Rules'!$J$43:$J$46,MATCH($AA14,'Classification Rules'!$B$43:$B$46,0)),"") -> Fully sourced, MetLife SMEs paired | AK14: =IFERROR(INDEX('Classification Rules'!$K$43:$K$46,MATCH($AA14,'Classification Rules'!$B$43:$B$46,0)),"") -> 0
A15: 11 | B15: 9808 | C15: LC AACOMP MF-JPN | D15: LifeComm AgentAgencyComp | E15: contract management | F15: VS3: Agency & Commission | G15: Core Insurance Systems Group 34956 | H15: Policy Admin Systems Team 34957 | I15: Core Business Application | J15: Y | K15: Yes | L15: COBOL, Assembler, MU(EASYPLUS), JCL | M15: N | N15: No | P15: MetLife Owned Application Code | Q15: 13.545708 | R15: 3.14375 | S15: 0 | T15: 16.689458 | U15: 0.72662384 | V15: 8.3447292 | W15: 8.3447292 | X15: =IF(OR(ISNUMBER(SEARCH("COBOL",$L15)),ISNUMBER(SEARCH("Assembler",$L15)),ISNUMBER(SEARCH("ASM",$L15)),ISNUMBER(SEARCH("RPG",$L15)),ISNUMBER(SEARCH("EASYPLUS",$L15)),ISNUMBER(SEARCH("PL/I",$L15))),"Rule 1",IF($M15="Y","Rule 2",IF($N15="Yes","Rule 3","Rule 4"))) -> Rule 1 | Y15: =IF($X15="Rule 1","D",IF($X15="Rule 2","C",IF($X15="Rule 3","B","A"))) -> D | AA15: =IF($Z15="",$Y15,$Z15) -> D | AB15: =IFERROR(INDEX('Classification Rules'!$C$43:$C$46,MATCH($AA15,'Classification Rules'!$B$43:$B$46,0)),"") -> Legacy-coupled core | AC15: =IF($X15="Rule 1","Language: "&$L15,IF($X15="Rule 2","Priority Transfer Target = Y",IF($X15="Rule 3","Cloud Indicator = Yes ("&$O15&")","Cloud Indicator = No, not mainframe, not a transfer target"))) -> Language: COBOL, Assembler, MU(EASYPLUS), JCL | AD15: =IFERROR(INDEX('Classification Rules'!$D$13:$D$16,MATCH($AA15,'Classification Rules'!$B$13:$B$16,0)),"") -> Rules hard-coded across modules and design truth is not written down. AI does comprehension here, not generation. | AE15: =IFERROR(INDEX('Classification Rules'!$D$43:$D$46,MATCH($AA15,'Classification Rules'!$B$43:$B$46,0)),"") -> 0.295 | AF15: =IFERROR(INDEX('Classification Rules'!$E$43:$E$46,MATCH($AA15,'Classification Rules'!$B$43:$B$46,0)),"") -> 0.3337015 | AG15: =IFERROR(INDEX('Classification Rules'!$F$43:$F$46,MATCH($AA15,'Classification Rules'!$B$43:$B$46,0)),"") -> 0.58 | AH15: =IFERROR(INDEX('Classification Rules'!$G$43:$G$46,MATCH($AA15,'Classification Rules'!$B$43:$B$46,0)),"") -> 0.5394 | AI15: =IFERROR(INDEX('Classification Rules'!$I$43:$I$46,MATCH($AA15,'Classification Rules'!$B$43:$B$46,0)),"") -> 14-20 weeks per cluster | AJ15: =IFERROR(INDEX('Classification Rules'!$J$43:$J$46,MATCH($AA15,'Classification Rules'!$B$43:$B$46,0)),"") -> Fully sourced, MetLife SMEs paired | AK15: =IFERROR(INDEX('Classification Rules'!$K$43:$K$46,MATCH($AA15,'Classification Rules'!$B$43:$B$46,0)),"") -> 0
A16: 12 | B16: 9810 | C16: Processor-I MF-JPN | D16: Claim payment (Processor-I) | E16: contract management | F16: VS2: Billing, Collections & Payments | G16: Core Insurance Systems Group 34956 | H16: Policy Admin Systems Team 34957 | I16: Core Business Application | J16: Y | K16: Yes | L16: COBOL, MU(EASYPLUS), Assembler, JCL | M16: N | N16: No | P16: MetLife Owned Application Code | Q16: 7.6683333 | R16: 1.1291667 | S16: 0 | T16: 8.7975 | U16: 0.75561239 | V16: 4.39875 | W16: 4.39875 | X16: =IF(OR(ISNUMBER(SEARCH("COBOL",$L16)),ISNUMBER(SEARCH("Assembler",$L16)),ISNUMBER(SEARCH("ASM",$L16)),ISNUMBER(SEARCH("RPG",$L16)),ISNUMBER(SEARCH("EASYPLUS",$L16)),ISNUMBER(SEARCH("PL/I",$L16))),"Rule 1",IF($M16="Y","Rule 2",IF($N16="Yes","Rule 3","Rule 4"))) -> Rule 1 | Y16: =IF($X16="Rule 1","D",IF($X16="Rule 2","C",IF($X16="Rule 3","B","A"))) -> D | AA16: =IF($Z16="",$Y16,$Z16) -> D | AB16: =IFERROR(INDEX('Classification Rules'!$C$43:$C$46,MATCH($AA16,'Classification Rules'!$B$43:$B$46,0)),"") -> Legacy-coupled core | AC16: =IF($X16="Rule 1","Language: "&$L16,IF($X16="Rule 2","Priority Transfer Target = Y",IF($X16="Rule 3","Cloud Indicator = Yes ("&$O16&")","Cloud Indicator = No, not mainframe, not a transfer target"))) -> Language: COBOL, MU(EASYPLUS), Assembler, JCL | AD16: =IFERROR(INDEX('Classification Rules'!$D$13:$D$16,MATCH($AA16,'Classification Rules'!$B$13:$B$16,0)),"") -> Rules hard-coded across modules and design truth is not written down. AI does comprehension here, not generation. | AE16: =IFERROR(INDEX('Classification Rules'!$D$43:$D$46,MATCH($AA16,'Classification Rules'!$B$43:$B$46,0)),"") -> 0.295 | AF16: =IFERROR(INDEX('Classification Rules'!$E$43:$E$46,MATCH($AA16,'Classification Rules'!$B$43:$B$46,0)),"") -> 0.3337015 | AG16: =IFERROR(INDEX('Classification Rules'!$F$43:$F$46,MATCH($AA16,'Classification Rules'!$B$43:$B$46,0)),"") -> 0.58 | AH16: =IFERROR(INDEX('Classification Rules'!$G$43:$G$46,MATCH($AA16,'Classification Rules'!$B$43:$B$46,0)),"") -> 0.5394 | AI16: =IFERROR(INDEX('Classification Rules'!$I$43:$I$46,MATCH($AA16,'Classification Rules'!$B$43:$B$46,0)),"") -> 14-20 weeks per cluster | AJ16: =IFERROR(INDEX('Classification Rules'!$J$43:$J$46,MATCH($AA16,'Classification Rules'!$B$43:$B$46,0)),"") -> Fully sourced, MetLife SMEs paired | AK16: =IFERROR(INDEX('Classification Rules'!$K$43:$K$46,MATCH($AA16,'Classification Rules'!$B$43:$B$46,0)),"") -> 0
A17: 13 | B17: 9811 | C17: LC Submit MF-JPN | D17: Submit Online | E17: contract management | F17: VS5: New Business, Underwriting & Interfaces | G17: Core Insurance Systems Group 34956 | H17: Policy Admin Systems Team 34957 | I17: Core Business Application | J17: Y | K17: Yes | L17: COBOL, MU(EASYPLUS), Assembler, JCL | M17: N | N17: No | P17: MetLife Owned Application Code | Q17: 1.9683333 | R17: 0.16458333 | S17: 0 | T17: 2.1329167 | U17: 0.95311584 | V17: 1.0664583 | W17: 1.0664583 | X17: =IF(OR(ISNUMBER(SEARCH("COBOL",$L17)),ISNUMBER(SEARCH("Assembler",$L17)),ISNUMBER(SEARCH("ASM",$L17)),ISNUMBER(SEARCH("RPG",$L17)),ISNUMBER(SEARCH("EASYPLUS",$L17)),ISNUMBER(SEARCH("PL/I",$L17))),"Rule 1",IF($M17="Y","Rule 2",IF($N17="Yes","Rule 3","Rule 4"))) -> Rule 1 | Y17: =IF($X17="Rule 1","D",IF($X17="Rule 2","C",IF($X17="Rule 3","B","A"))) -> D | AA17: =IF($Z17="",$Y17,$Z17) -> D | AB17: =IFERROR(INDEX('Classification Rules'!$C$43:$C$46,MATCH($AA17,'Classification Rules'!$B$43:$B$46,0)),"") -> Legacy-coupled core | AC17: =IF($X17="Rule 1","Language: "&$L17,IF($X17="Rule 2","Priority Transfer Target = Y",IF($X17="Rule 3","Cloud Indicator = Yes ("&$O17&")","Cloud Indicator = No, not mainframe, not a transfer target"))) -> Language: COBOL, MU(EASYPLUS), Assembler, JCL | AD17: =IFERROR(INDEX('Classification Rules'!$D$13:$D$16,MATCH($AA17,'Classification Rules'!$B$13:$B$16,0)),"") -> Rules hard-coded across modules and design truth is not written down. AI does comprehension here, not generation. | AE17: =IFERROR(INDEX('Classification Rules'!$D$43:$D$46,MATCH($AA17,'Classification Rules'!$B$43:$B$46,0)),"") -> 0.295 | AF17: =IFERROR(INDEX('Classification Rules'!$E$43:$E$46,MATCH($AA17,'Classification Rules'!$B$43:$B$46,0)),"") -> 0.3337015 | AG17: =IFERROR(INDEX('Classification Rules'!$F$43:$F$46,MATCH($AA17,'Classification Rules'!$B$43:$B$46,0)),"") -> 0.58 | AH17: =IFERROR(INDEX('Classification Rules'!$G$43:$G$46,MATCH($AA17,'Classification Rules'!$B$43:$B$46,0)),"") -> 0.5394 | AI17: =IFERROR(INDEX('Classification Rules'!$I$43:$I$46,MATCH($AA17,'Classification Rules'!$B$43:$B$46,0)),"") -> 14-20 weeks per cluster | AJ17: =IFERROR(INDEX('Classification Rules'!$J$43:$J$46,MATCH($AA17,'Classification Rules'!$B$43:$B$46,0)),"") -> Fully sourced, MetLife SMEs paired | AK17: =IFERROR(INDEX('Classification Rules'!$K$43:$K$46,MATCH($AA17,'Classification Rules'!$B$43:$B$46,0)),"") -> 0
... A40: 36 | B40: 9849 | C40: C04OSI-JPN | D40: S Sum Total System(Open) | E40: New Contract Related | F40: VS1: New Business Processing | G40: Customer Service and Operations Systems Group 34965 | H40: New Business Team 34966 | I40: Common Service Business Application | J40: N | K40: Yes | L40: JAVA | M40: N | N40: No | P40: MetLife Owned Application Code | Q40: 5.18625 | R40: 0.38333333 | S40: 0 | T40: 5.5695833 | U40: 0.8315254 | V40: 2.7847917 | W40: 2.7847917 | X40: =IF(OR(ISNUMBER(SEARCH("COBOL",$L40)),ISNUMBER(SEARCH("Assembler",$L40)),ISNUMBER(SEARCH("ASM",$L40)),ISNUMBER(SEARCH("RPG",$L40)),ISNUMBER(SEARCH("EASYPLUS",$L40)),ISNUMBER(SEARCH("PL/I",$L40))),"Rule 1",IF($M40="Y","Rule 2",IF($N40="Yes","Rule 3","Rule 4"))) -> Rule 4 | Y40: =IF($X40="Rule 1","D",IF($X40="Rule 2","C",IF($X40="Rule 3","B","A"))) -> A | AA40: =IF($Z40="",$Y40,$Z40) -> A | AB40: =IFERROR(INDEX('Classification Rules'!$C$43:$C$46,MATCH($AA40,'Classification Rules'!$B$43:$B$46,0)),"") -> Language-locked | AC40: =IF($X40="Rule 1","Language: "&$L40,IF($X40="Rule 2","Priority Transfer Target = Y",IF($X40="Rule 3","Cloud Indicator = Yes ("&$O40&")","Cloud Indicator = No, not mainframe, not a transfer target"))) -> Cloud Indicator = No, not mainframe, not a transfer target | AD40: =IFERROR(INDEX('Classification Rules'!$D$13:$D$16,MATCH($AA40,'Classification Rules'!$B$13:$B$16,0)),"") -> On-premises and non-mainframe, so the constraint is not the technology — it is that the business context exists only in Japanese, in few heads. | AE40: =IFERROR(INDEX('Classification Rules'!$D$43:$D$46,MATCH($AA40,'Classification Rules'!$B$43:$B$46,0)),"") -> 0.304 | AF40: =IFERROR(INDEX('Classification Rules'!$E$43:$E$46,MATCH($AA40,'Classification Rules'!$B$43:$B$46,0)),"") -> 0.3394768 | AG40: =IFERROR(INDEX('Classification Rules'!$F$43:$F$46,MATCH($AA40,'Classification Rules'!$B$43:$B$46,0)),"") -> 0.15 | AH40: =IFERROR(INDEX('Classification Rules'!$G$43:$G$46,MATCH($AA40,'Classification Rules'!$B$43:$B$46,0)),"") -> 0.1395 | AI40: =IFERROR(INDEX('Classification Rules'!$I$43:$I$46,MATCH($AA40,'Classification Rules'!$B$43:$B$46,0)),"") -> 10-14 weeks per cluster | AJ40: =IFERROR(INDEX('Classification Rules'!$J$43:$J$46,MATCH($AA40,'Classification Rules'!$B$43:$B$46,0)),"") -> Fully sourced, onshore-weighted | AK40: =IFERROR(INDEX('Classification Rules'!$K$43:$K$46,MATCH($AA40,'Classification Rules'!$B$43:$B$46,0)),"") -> 0
A41: 37 | B41: 9851 | C41: W03FIC-JPN | D41: Guidance Refusal Information Administration System | E41: Corporate Related | F41: VS3: Risk, Compliance & Governance | G41: Core Insurance Systems Group 34956 | H41: Corporate Systems Team 34959 | I41: Core Business Application | J41: N | K41: Yes | L41: JAVA | M41: N | N41: Yes | O41: Platform as a Service (PaaS) | P41: MetLife Owned Application Code | Q41: 0.29166667 | R41: 0.11666667 | S41: 0 | T41: 0.40833333 | U41: 0.82653061 | V41: 0.20416667 | W41: 0.20416667 | X41: =IF(OR(ISNUMBER(SEARCH("COBOL",$L41)),ISNUMBER(SEARCH("Assembler",$L41)),ISNUMBER(SEARCH("ASM",$L41)),ISNUMBER(SEARCH("RPG",$L41)),ISNUMBER(SEARCH("EASYPLUS",$L41)),ISNUMBER(SEARCH("PL/I",$L41))),"Rule 1",IF($M41="Y","Rule 2",IF($N41="Yes","Rule 3","Rule 4"))) -> Rule 3 | Y41: =IF($X41="Rule 1","D",IF($X41="Rule 2","C",IF($X41="Rule 3","B","A"))) -> B | AA41: =IF($Z41="",$Y41,$Z41) -> B | AB41: =IFERROR(INDEX('Classification Rules'!$C$43:$C$46,MATCH($AA41,'Classification Rules'!$B$43:$B$46,0)),"") -> Offshore-ready | AC41: =IF($X41="Rule 1","Language: "&$L41,IF($X41="Rule 2","Priority Transfer Target = Y",IF($X41="Rule 3","Cloud Indicator = Yes ("&$O41&")","Cloud Indicator = No, not mainframe, not a transfer target"))) -> Cloud Indicator = Yes (Platform as a Service (PaaS)) | AD41: =IFERROR(INDEX('Classification Rules'!$D$13:$D$16,MATCH($AA41,'Classification Rules'!$B$13:$B$16,0)),"") -> Cloud migration has already forced re-platforming, documentation and specifiability. Highest AI and offshore ceiling in the estate. | AE41: =IFERROR(INDEX('Classification Rules'!$D$43:$D$46,MATCH($AA41,'Classification Rules'!$B$43:$B$46,0)),"") -> 0.4825 | AF41: =IFERROR(INDEX('Classification Rules'!$E$43:$E$46,MATCH($AA41,'Classification Rules'!$B$43:$B$46,0)),"") -> 0.45402025 | AG41: =IFERROR(INDEX('Classification Rules'!$F$43:$F$46,MATCH($AA41,'Classification Rules'!$B$43:$B$46,0)),"") -> 0.78 | AH41: =IFERROR(INDEX('Classification Rules'!$G$43:$G$46,MATCH($AA41,'Classification Rules'!$B$43:$B$46,0)),"") -> 0.7254 | AI41: =IFERROR(INDEX('Classification Rules'!$I$43:$I$46,MATCH($AA41,'Classification Rules'!$B$43:$B$46,0)),"") -> 6-8 weeks per cluster | AJ41: =IFERROR(INDEX('Classification Rules'!$J$43:$J$46,MATCH($AA41,'Classification Rules'!$B$43:$B$46,0)),"") -> Fully sourced, moving to output units | AK41: =IFERROR(INDEX('Classification Rules'!$K$43:$K$46,MATCH($AA41,'Classification Rules'!$B$43:$B$46,0)),"") -> 0
A42: 38 | B42: 9852 | C42: C03APO-JPN | D42: Apollocs | E42: Corporate Related | F42: VS5: Corporate Integration & Batch Services | G42: Core Insurance Systems Group 34956 | H42: Corporate Systems Team 34959 | I42: Core Business Application | J42: N | K42: Yes | L42: Other#APOLLOCS | M42: N | N42: No | P42: Non-MetLife Owned Application Code (3rd party/COTS) | Q42: 0.50833333 | R42: 0 | S42: 0 | T42: 0.50833333 | U42: 0.36885246 | V42: 0.25416667 | W42: 0.25416667 | X42: =IF(OR(ISNUMBER(SEARCH("COBOL",$L42)),ISNUMBER(SEARCH("Assembler",$L42)),ISNUMBER(SEARCH("ASM",$L42)),ISNUMBER(SEARCH("RPG",$L42)),ISNUMBER(SEARCH("EASYPLUS",$L42)),ISNUMBER(SEARCH("PL/I",$L42))),"Rule 1",IF($M42="Y","Rule 2",IF($N42="Yes","Rule 3","Rule 4"))) -> Rule 4 | Y42: =IF($X42="Rule 1","D",IF($X42="Rule 2","C",IF($X42="Rule 3","B","A"))) -> A | AA42: =IF($Z42="",$Y42,$Z42) -> A | AB42: =IFERROR(INDEX('Classification Rules'!$C$43:$C$46,MATCH($AA42,'Classification Rules'!$B$43:$B$46,0)),"") -> Language-locked | AC42: =IF($X42="Rule 1","Language: "&$L42,IF($X42="Rule 2","Priority Transfer Target = Y",IF($X42="Rule 3","Cloud Indicator = Yes ("&$O42&")","Cloud Indicator = No, not mainframe, not a transfer target"))) -> Cloud Indicator = No, not mainframe, not a transfer target | AD42: =IFERROR(INDEX('Classification Rules'!$D$13:$D$16,MATCH($AA42,'Classification Rules'!$B$13:$B$16,0)),"") -> On-premises and non-mainframe, so the constraint is not the technology — it is that the business context exists only in Japanese, in few heads. | AE42: =IFERROR(INDEX('Classification Rules'!$D$43:$D$46,MATCH($AA42,'Classification Rules'!$B$43:$B$46,0)),"") -> 0.304 | AF42: =IFERROR(INDEX('Classification Rules'!$E$43:$E$46,MATCH($AA42,'Classification Rules'!$B$43:$B$46,0)),"") -> 0.3394768 | AG42: =IFERROR(INDEX('Classification Rules'!$F$43:$F$46,MATCH($AA42,'Classification Rules'!$B$43:$B$46,0)),"") -> 0.15 | AH42: =IFERROR(INDEX('Classification Rules'!$G$43:$G$46,MATCH($AA42,'Classification Rules'!$B$43:$B$46,0)),"") -> 0.1395 | AI42: =IFERROR(INDEX('Classification Rules'!$I$43:$I$46,MATCH($AA42,'Classification Rules'!$B$43:$B$46,0)),"") -> 10-14 weeks per cluster | AJ42: =IFERROR(INDEX('Classification Rules'!$J$43:$J$46,MATCH($AA42,'Classification Rules'!$B$43:$B$46,0)),"") -> Fully sourced, onshore-weighted | AK42: =IFERROR(INDEX('Classification Rules'!$K$43:$K$46,MATCH($AA42,'Classification Rules'!$B$43:$B$46,0)),"") -> 0
A43: 39 | B43: 9854 | C43: Z04IMA-JPN | D43: Image Search | E43: New Contract Related | F43: VS4: Imaging & Document Capture | G43: Customer Service and Operations Systems Group 34965 | H43: New Business Team 34966 | I43: Core Business Application | J43: N | K43: Yes | L43: CSS; JAVA;HTML; VB.NET | M43: N | N43: No | P43: MetLife Owned Application Code | Q43: 1.4004167 | R43: 0 | S43: 0 | T43: 1.4004167 | U43: 0.92859268 | V43: 0.70020833 | W43: 0.70020833 | X43: =IF(OR(ISNUMBER(SEARCH("COBOL",$L43)),ISNUMBER(SEARCH("Assembler",$L43)),ISNUMBER(SEARCH("ASM",$L43)),ISNUMBER(SEARCH("RPG",$L43)),ISNUMBER(SEARCH("EASYPLUS",$L43)),ISNUMBER(SEARCH("PL/I",$L43))),"Rule 1",IF($M43="Y","Rule 2",IF($N43="Yes","Rule 3","Rule 4"))) -> Rule 4 | Y43: =IF($X43="Rule 1","D",IF($X43="Rule 2","C",IF($X43="Rule 3","B","A"))) -> A | AA43: =IF($Z43="",$Y43,$Z43) -> A | AB43: =IFERROR(INDEX('Classification Rules'!$C$43:$C$46,MATCH($AA43,'Classification Rules'!$B$43:$B$46,0)),"") -> Language-locked | AC43: =IF($X43="Rule 1","Language: "&$L43,IF($X43="Rule 2","Priority Transfer Target = Y",IF($X43="Rule 3","Cloud Indicator = Yes ("&$O43&")","Cloud Indicator = No, not mainframe, not a transfer target"))) -> Cloud Indicator = No, not mainframe, not a transfer target | AD43: =IFERROR(INDEX('Classification Rules'!$D$13:$D$16,MATCH($AA43,'Classification Rules'!$B$13:$B$16,0)),"") -> On-premises and non-mainframe, so the constraint is not the technology — it is that the business context exists only in Japanese, in few heads. | AE43: =IFERROR(INDEX('Classification Rules'!$D$43:$D$46,MATCH($AA43,'Classification Rules'!$B$43:$B$46,0)),"") -> 0.304 | AF43: =IFERROR(INDEX('Classification Rules'!$E$43:$E$46,MATCH($AA43,'Classification Rules'!$B$43:$B$46,0)),"") -> 0.3394768 | AG43: =IFERROR(INDEX('Classification Rules'!$F$43:$F$46,MATCH($AA43,'Classification Rules'!$B$43:$B$46,0)),"") -> 0.15 | AH43: =IFERROR(INDEX('Classification Rules'!$G$43:$G$46,MATCH($AA43,'Classification Rules'!$B$43:$B$46,0)),"") -> 0.1395 | AI43: =IFERROR(INDEX('Classification Rules'!$I$43:$I$46,MATCH($AA43,'Classification Rules'!$B$43:$B$46,0)),"") -> 10-14 weeks per cluster | AJ43: =IFERROR(INDEX('Classification Rules'!$J$43:$J$46,MATCH($AA43,'Classification Rules'!$B$43:$B$46,0)),"") -> Fully sourced, onshore-weighted | AK43: =IFERROR(INDEX('Classification Rules'!$K$43:$K$46,MATCH($AA43,'Classification Rules'!$B$43:$B$46,0)),"") -> 0
A44: 40 | B44: 9857 | C44: W05AMS-JPN | D44: Annuity Information Management System(AIMS) | E44: Insurance Claims and Benefits Payment Related | F44: VS2: Pension, Benefits & Maturity Administration | G44: Customer Service and Operations Systems Group 34965 | H44: Claims Team 34968 | I44: Core Business Application | J44: Y | K44: Yes | L44: JAVA | M44: N | N44: No | P44: MetLife Owned Application Code | Q44: 20.211667 | R44: 1.8166667 | S44: 0 | T44: 22.028333 | U44: 0.92547477 | V44: 11.014167 | W44: 11.014167 | X44: =IF(OR(ISNUMBER(SEARCH("COBOL",$L44)),ISNUMBER(SEARCH("Assembler",$L44)),ISNUMBER(SEARCH("ASM",$L44)),ISNUMBER(SEARCH("RPG",$L44)),ISNUMBER(SEARCH("EASYPLUS",$L44)),ISNUMBER(SEARCH("PL/I",$L44))),"Rule 1",IF($M44="Y","Rule 2",IF($N44="Yes","Rule 3","Rule 4"))) -> Rule 4 | Y44: =IF($X44="Rule 1","D",IF($X44="Rule 2","C",IF($X44="Rule 3","B","A"))) -> A | AA44: =IF($Z44="",$Y44,$Z44) -> A | AB44: =IFERROR(INDEX('Classification Rules'!$C$43:$C$46,MATCH($AA44,'Classification Rules'!$B$43:$B$46,0)),"") -> Language-locked | AC44: =IF($X44="Rule 1","Language: "&$L44,IF($X44="Rule 2","Priority Transfer Target = Y",IF($X44="Rule 3","Cloud Indicator = Yes ("&$O44&")","Cloud Indicator = No, not mainframe, not a transfer target"))) -> Cloud Indicator = No, not mainframe, not a transfer target | AD44: =IFERROR(INDEX('Classification Rules'!$D$13:$D$16,MATCH($AA44,'Classification Rules'!$B$13:$B$16,0)),"") -> On-premises and non-mainframe, so the constraint is not the technology — it is that the business context exists only in Japanese, in few heads. | AE44: =IFERROR(INDEX('Classification Rules'!$D$43:$D$46,MATCH($AA44,'Classification Rules'!$B$43:$B$46,0)),"") -> 0.304 | AF44: =IFERROR(INDEX('Classification Rules'!$E$43:$E$46,MATCH($AA44,'Classification Rules'!$B$43:$B$46,0)),"") -> 0.3394768 | AG44: =IFERROR(INDEX('Classification Rules'!$F$43:$F$46,MATCH($AA44,'Classification Rules'!$B$43:$B$46,0)),"") -> 0.15 | AH44: =IFERROR(INDEX('Classification Rules'!$G$43:$G$46,MATCH($AA44,'Classification Rules'!$B$43:$B$46,0)),"") -> 0.1395 | AI44: =IFERROR(INDEX('Classification Rules'!$I$43:$I$46,MATCH($AA44,'Classification Rules'!$B$43:$B$46,0)),"") -> 10-14 weeks per cluster | AJ44: =IFERROR(INDEX('Classification Rules'!$J$43:$J$46,MATCH($AA44,'Classification Rules'!$B$43:$B$46,0)),"") -> Fully sourced, onshore-weighted | AK44: =IFERROR(INDEX('Classification Rules'!$K$43:$K$46,MATCH($AA44,'Classification Rules'!$B$43:$B$46,0)),"") -> 0
A45: 41 | B45: 9858 | C45: W02OPS-JPN | D45: Insurance Planning for Operator | E45: Marketing/Direct Business Related | F45: VS2: Customer Acquisition & Quotation | G45: Customer and Channel Engineering 34961 | I45: Core Business Application | J45: N | K45: Yes | L45: JAVA | M45: N | N45: No | P45: MetLife Owned Application Code | Q45: 4.8333333 | R45: 1 | S45: 1.0833333 | T45: 6.9166667 | U45: 0.71084337 | V45: 3.4583333 | W45: 3.4583333 | X45: =IF(OR(ISNUMBER(SEARCH("COBOL",$L45)),ISNUMBER(SEARCH("Assembler",$L45)),ISNUMBER(SEARCH("ASM",$L45)),ISNUMBER(SEARCH("RPG",$L45)),ISNUMBER(SEARCH("EASYPLUS",$L45)),ISNUMBER(SEARCH("PL/I",$L45))),"Rule 1",IF($M45="Y","Rule 2",IF($N45="Yes","Rule 3","Rule 4"))) -> Rule 4 | Y45: =IF($X45="Rule 1","D",IF($X45="Rule 2","C",IF($X45="Rule 3","B","A"))) -> A | AA45: =IF($Z45="",$Y45,$Z45) -> A | AB45: =IFERROR(INDEX('Classification Rules'!$C$43:$C$46,MATCH($AA45,'Classification Rules'!$B$43:$B$46,0)),"") -> Language-locked | AC45: =IF($X45="Rule 1","Language: "&$L45,IF($X45="Rule 2","Priority Transfer Target = Y",IF($X45="Rule 3","Cloud Indicator = Yes ("&$O45&")","Cloud Indicator = No, not mainframe, not a transfer target"))) -> Cloud Indicator = No, not mainframe, not a transfer target | AD45: =IFERROR(INDEX('Classification Rules'!$D$13:$D$16,MATCH($AA45,'Classification Rules'!$B$13:$B$16,0)),"") -> On-premises and non-mainframe, so the constraint is not the technology — it is that the business context exists only in Japanese, in few heads. | AE45: =IFERROR(INDEX('Classification Rules'!$D$43:$D$46,MATCH($AA45,'Classification Rules'!$B$43:$B$46,0)),"") -> 0.304 | AF45: =IFERROR(INDEX('Classification Rules'!$E$43:$E$46,MATCH($AA45,'Classification Rules'!$B$43:$B$46,0)),"") -> 0.3394768 | AG45: =IFERROR(INDEX('Classification Rules'!$F$43:$F$46,MATCH($AA45,'Classification Rules'!$B$43:$B$46,0)),"") -> 0.15 | AH45: =IFERROR(INDEX('Classification Rules'!$G$43:$G$46,MATCH($AA45,'Classification Rules'!$B$43:$B$46,0)),"") -> 0.1395 | AI45: =IFERROR(INDEX('Classification Rules'!$I$43:$I$46,MATCH($AA45,'Classification Rules'!$B$43:$B$46,0)),"") -> 10-14 weeks per cluster | AJ45: =IFERROR(INDEX('Classification Rules'!$J$43:$J$46,MATCH($AA45,'Classification Rules'!$B$43:$B$46,0)),"") -> Fully sourced, onshore-weighted | AK45: =IFERROR(INDEX('Classification Rules'!$K$43:$K$46,MATCH($AA45,'Classification Rules'!$B$43:$B$46,0)),"") -> 0
A46: 42 | B46: 9861 | C46: W04RRE-JPN | D46: Rule Engine | E46: New Contract Related | F46: VS2: Rules & Decisioning | G46: Customer Service and Operations Systems Group 34965 | H46: New Business Team 34966 | I46: Core Business Application | J46: Y | K46: Yes | L46: JAVA | M46: N | N46: No | P46: MetLife Owned Application Code | Q46: 6.3152917 | R46: 0 | S46: 0 | T46: 6.3152917 | U46: 0.87325737 | V46: 3.1576458 | W46: 3.1576458 | X46: =IF(OR(ISNUMBER(SEARCH("COBOL",$L46)),ISNUMBER(SEARCH("Assembler",$L46)),ISNUMBER(SEARCH("ASM",$L46)),ISNUMBER(SEARCH("RPG",$L46)),ISNUMBER(SEARCH("EASYPLUS",$L46)),ISNUMBER(SEARCH("PL/I",$L46))),"Rule 1",IF($M46="Y","Rule 2",IF($N46="Yes","Rule 3","Rule 4"))) -> Rule 4 | Y46: =IF($X46="Rule 1","D",IF($X46="Rule 2","C",IF($X46="Rule 3","B","A"))) -> A | AA46: =IF($Z46="",$Y46,$Z46) -> A | AB46: =IFERROR(INDEX('Classification Rules'!$C$43:$C$46,MATCH($AA46,'Classification Rules'!$B$43:$B$46,0)),"") -> Language-locked | AC46: =IF($X46="Rule 1","Language: "&$L46,IF($X46="Rule 2","Priority Transfer Target = Y",IF($X46="Rule 3","Cloud Indicator = Yes ("&$O46&")","Cloud Indicator = No, not mainframe, not a transfer target"))) -> Cloud Indicator = No, not mainframe, not a transfer target | AD46: =IFERROR(INDEX('Classification Rules'!$D$13:$D$16,MATCH($AA46,'Classification Rules'!$B$13:$B$16,0)),"") -> On-premises and non-mainframe, so the constraint is not the technology — it is that the business context exists only in Japanese, in few heads. | AE46: =IFERROR(INDEX('Classification Rules'!$D$43:$D$46,MATCH($AA46,'Classification Rules'!$B$43:$B$46,0)),"") -> 0.304 | AF46: =IFERROR(INDEX('Classification Rules'!$E$43:$E$46,MATCH($AA46,'Classification Rules'!$B$43:$B$46,0)),"") -> 0.3394768 | AG46: =IFERROR(INDEX('Classification Rules'!$F$43:$F$46,MATCH($AA46,'Classification Rules'!$B$43:$B$46,0)),"") -> 0.15 | AH46: =IFERROR(INDEX('Classification Rules'!$G$43:$G$46,MATCH($AA46,'Classification Rules'!$B$43:$B$46,0)),"") -> 0.1395 | AI46: =IFERROR(INDEX('Classification Rules'!$I$43:$I$46,MATCH($AA46,'Classification Rules'!$B$43:$B$46,0)),"") -> 10-14 weeks per cluster | AJ46: =IFERROR(INDEX('Classification Rules'!$J$43:$J$46,MATCH($AA46,'Classification Rules'!$B$43:$B$46,0)),"") -> Fully sourced, onshore-weighted | AK46: =IFERROR(INDEX('Classification Rules'!$K$43:$K$46,MATCH($AA46,'Classification Rules'!$B$43:$B$46,0)),"") -> 0
