Workbook

Sheet README
A1: Insurance Claims and Benefits Payment Related — domain framework v1
A2: Six applications, 121.573 units, and the most disposition-exposed 領域 in the estate. One application carrying 28.8% of the domain is marked Retire, two more carry a zero Year-3 target, and Capgemini has six people on the ground against a vendor population of eighty-five.
A4: WHAT THIS 領域 IS
B5: Six applications, three archetypes | C5: Claim Batch 43.8, C12WNC-JPN 35.0 and Pega for Claims 16.7 (D, distributed-proven, 95.5 units between them) · W05AMS-JPN 22.0 (J, Japan-locked) · MDRS and WZZMNB-JPN 4.1 (T, long tail). Three value streams: Annuity ＆ Maturity Payment 67.8, Claims Processing ＆ Adjudication 35.0, Claims Support Services 18.8.
B6: Onshore, and only just starting to move | C6: 71.6 of the 85.4 vendor units are in Tokyo — 84%, the most onshore-weighted Capgemini population of the 領域 modelled. 4.2 units are offshore and 9.6 nearshore. With MGCC, 30.0% of the domain is delivered away from Tokyo against a 65.3% ceiling.
B7: The only 領域 with material nearshore | C7: 9.589 units on C12WNC-JPN — roughly half of all the nearshore capacity in the portfolio. Every other 領域 modelled is Tokyo-and-India only. The NEAR rows in this workbook are live, not schema.
B8: Six Capgemini people are here, and all six sit on one application | C8: Against 85.4 vendor units — 7%, the weakest continuity position of the 領域 modelled. All six are on Claim Batch. On C12WNC-JPN, W05AMS-JPN, Pega, MDRS and WZZMNB-JPN we start from nothing.
A9: THE THREE FINDINGS THAT MATTER COMMERCIALLY
B10: C12WNC-JPN is marked RETIRE, and it is 28.8% of the domain | C10: 35.0 units, business-critical, Japanese specifications, 9.6 units nearshore, and the entire Claims Processing ＆ Adjudication value stream. This model freezes scope at Year 1 as every domain model does, so that exposure is carried, not netted. It is the largest single disposition exposure in the estate and it has to be resolved with MetLife before the price is fixed.
B11: Two more applications carry a ZERO Year-3 target | C11: Pega for Claims 16.7 and MDRS 2.1 — 18.8 units, 15.5% of the domain — are among the nine applications MetLife's own Appendix 3 model takes to zero. Taken with C12WNC-JPN, 44.3% of this 領域 is under a disposition question.
B12: NCD holds 60% of the vendor side, and we absorb it | C12: 51.244 of the 85.449 vendor units — the second-heaviest named-vendor concentration in the estate after FSI on Contract Management. Consistent with the other 領域 modelled we absorb NCD rather than retain them, which puts the whole vendor side into the transferable pool and makes the 50:50 reachable. It also makes Year 1 a large transition. That is a due-diligence decision — see Basis ＆ Assumptions.
A13: THE SHAPE OF THE ANSWER
B14: MGCC has a HIGHER ceiling than we do here | C14: MGCC 48.60% against Capgemini 44.73%, because MGCC is a build-and-test population and 78.5% of this estate is archetype D — where Build and Test ceilings are the highest in the classifier. Adoption still puts us ahead on committed productivity (44.7% against 38.9% effective), but the underlying capability runs the other way. Worth saying out loud.
B15: The transfer is 11.6 people, and most of it goes to MetLife Japan | C15: Organic convergence only takes the ratio from 70.3% to 66.8% by Year 3 — MetLife's side is small and shrinks slowly. The transfer does the rest. We send 6.4 to MetLife Japan and 5.2 to MGCC rather than the portfolio default 35/65, because 84% of the Capgemini population is in Tokyo and people in Tokyo are re-badged to MetLife Japan.
B16: Headcount 121.6 → 59.3 | C16: A 51.2% reduction over five years, in line with the three other 領域 whose five-year plan is fully solved. AI ceiling 44.71%, applied glidepath 0 / 23.0 / 37.6 / 46.2 / 51.2%.
A17: THE ENGINE
B18: Unchanged from the other 領域 modelled | C18: Six-rule archetype classifier → AI and offshore ceilings from Golden Inventory v4 → realisation curve → four-gate capability → carry-forward and pre-load → per-sourcing productivity → organic ratio convergence → guardrails → seat ledger.
B19: Seats deploy whole people | C19: Pod Library column K and Horizontal Teams column J are the people you hire for that role across the block — whole numbers, or halves where one person covers two units inside this 領域. The SIT Loading sheet turns them into requisitions.
A20: WHAT TO RAISE
B21: The role line needs the largest restatement in the estate | C21: Appendix 3 records ZERO project management and 1.00 maintenance unit across six applications carrying 732 incidents and 1,161 changes. 83% of the vendor population is booked as Developer. Restated to 4.50 maintenance, 3.50 PM and 2.50 architecture, taken from the developer line. Arithmetically neutral; MetLife should confirm.
B22: And MetLife's two views of run disagree by a factor of seven | C22: The maintenance role line says 1.00 unit. The AD / AMS effort split in the same spreadsheet implies 6.75. On a 122-person domain that is about six people of exposure, and it sets the AMS price.
B23: The disposition questions are the priority | C23: 44.3% of this 領域 is either marked Retire or carries a zero Year-3 target in MetLife's own model. No other 領域 comes close. Resolve before submission.

Sheet Basis & Assumptions
A1: Where every input comes from, and which ones are ours
A2: This is a first-version model, so there is nothing to change-log. What matters instead is the provenance of each input: which are measured, which are restated, and which are domain overrides.
B4: Element | C4: Source | D4: Value used | E4: Status | F4: Note
B5: Baseline | C5: Appendix 3 v5, 6 applications | D5: effort 121.574 · FTC 85.449 · FTE 13.479 · MGCC 22.646 · onshore 71.626 · offshore 4.233 · nearshore 9.589 | E5: SOURCE | F5: Internally consistent: FTC + FTE + MGCC ties exactly to Total, and the three location lines tie exactly to FTC. No unallocated capacity to carry.
B6: Archetypes | C6: Golden Inventory v4, six-rule classifier | D6: D 3 / 95.479 · J 1 / 22.028 · T 2 / 4.067 | E6: SOURCE | F6: AI ceiling 44.71%, offshore ceiling 65.27%. Archetype D is 78.5% of the effort, which is what makes the productivity case; W05AMS-JPN at a 12% offshore ceiling is what caps the location case.
B7: Delivery method | C7: Appendix 3 v5 | D7: 1 agile · 1 hybrid · 4 waterfall; 16.7 of 121.6 units agile today | E7: MEASURED | F7: Pega for Claims is the only agile application. Claim Batch is hybrid. Four of six run on Japanese specifications.
B8: Adoption factors | C8: Portfolio default | D8: 1.00 / 0.85 / 0.55 / 0.80 — unchanged | E8: STANDARD | F8: No case for raising MetLife's commitment here. Unlike Common Service Platform this is a mostly waterfall, Japanese-specification estate, and MetLife's own staff are only 11.1% of it.
B9: Role line | C9: BSA 5.958 · DEV 70.899 · TEST 6.817 · MNT 1.000 · PM 0.000 · OTH 0.775 | D9: MNT 4.50 · PM 3.50 · OTH 2.50, taken from DEV | E9: RESTATED | F9: ZERO project management across six applications and three value streams, and 1.00 maintenance unit against 732 incidents and 1,161 changes. 83% of the vendor population booked as Developer — the highest in the estate. Arithmetically neutral; the total does not move.
B10: Partner | C10: NCD named on four applications | D10: 51.244 of 85.449 vendor units — 60.0% | E10: DOMAIN DECISION | F10: MODELLED AS ABSORBED, NOT RETAINED. Consistent with the other 領域 modelled, where FSI was retained on entrenched Japanese-specification work and NCD was absorbed everywhere. Absorbing puts all 85.4 vendor units into the transferable pool, which is what makes the 50:50 reachable — if due diligence says NCD must be retained on C12WNC-JPN and W05AMS-JPN, the transfer arithmetic changes materially and the residual reappears. This is the single assumption in this workbook most worth challenging.
B11: Transfer split | C11: Portfolio default 35% to MetLife Japan | D11: 55% to MetLife Japan · 45% to MGCC | E11: DOMAIN OVERRIDE | F11: 71.6 of 85.4 vendor units are in Tokyo — 84%, the most onshore-weighted Capgemini population of the 領域 modelled. The default assumes an offshore-weighted population being re-badged mostly into MGCC. Here that is backwards: people in Tokyo are re-badged to MetLife Japan.
B12: Inherited workforce | C12: T3 reconciliation behind Golden v4 | D12: 6 people, 1 onshore, all on Claim Batch | E12: SOURCE | F12: 7% of the vendor population. The weakest continuity position of the 領域 modelled, and it is concentrated on a single application.
B13: Disposition | C13: New in Appendix 3 v5 | D13: C12WNC-JPN marked Retire — 34.997 units, 28.8% | E13: NEW | F13: Not netted out; the model holds effort frozen at Year 1 as every domain model does. Pega for Claims and MDRS additionally carry a zero Year-3 target in Appendix 3 — a further 18.8 units. Together 44.3% of the 領域 is under a disposition question. See the README.
B14: Guardrails | C14: Portfolio standard | D14: 50% vendor share · 55% per unit · 55% of build-and-test | E14: STANDARD | F14: All held in every year, including the Year-4 dip immediately after the transfer — but only because the transfer split was re-cut to 55/45. At the portfolio default the build-and-test guardrail breaches in Year 4 at 53.5%.
B15: Transfer | C15: One event at the end of Year 3 | D15: 11.6 people — 6.4 to MetLife Japan, 5.2 to MGCC | E15: MODELLED | F15: Organic convergence runs first but only moves the ratio from 70.3% to 66.8%, because MetLife's side is small and shrinks slowly. The transfer carries most of the distance here, unlike the other 領域 modelled.
A17: HOW TO READ THE STATUS COLUMN
B18: • SOURCE — taken directly from Appendix 3 v5 or Golden Application Inventory v4. Not ours to change.
B19: • MEASURED — MetLife has supplied it and we use it as given, where an earlier version made us assume.
B20: • RESTATED — the client figure is internally impossible and we have changed it. Every restatement is arithmetically neutral: people move between role lines, the total does not. These go back to MetLife.
B21: • DOMAIN OVERRIDE — a portfolio default deliberately changed for this 領域, with the reason stated. These are solution decisions and should be defended as such in the review.
B22: • MODELLED — a construct of ours with no direct client source: partner plans, transfer sizing, conversion quarters. The assumptions most worth challenging.

Sheet Change Control
A1: Change control — what must still hold after you edit a seat count
A2: Pod Library column J and Horizontal Teams column I are INPUTS. You may change them. Holding the yearly total is necessary but not sufficient — these are the other things that have to survive the edit. Every check below is live.
A4: A. WHERE THESE NUMBERS GO
B5: • Pod Library J and Horizontal Teams I are hard-typed values, not formulas. Nothing upstream computes them — they are the design. Everything downstream is derived from them.
B6: • Seat Ledger reads them cell by cell (912 references to Pod Library, 630 to Horizontal Teams) and multiplies by the unit count on Pod Plan. Team Build-Up, Cost & Commercial, Inherited Workforce and Unit Cost Sensitivity are all SUMIFS over the Seat Ledger. Change a seat and every one of them moves.
B7: • THE ONE THAT SURPRISES PEOPLE: the Logic Tree reads the roster back. Partner seats (row 59) drive the partner share (row 60), the span-of-control factor (row 61), the applied operating-model gain (row 43), capability (row 45) and therefore the HEADCOUNT TARGET itself (row 53). Changing partner seats moves the target you are trying to hit. It converges, but it does not stand still.
B8: • What does NOT move: the effort baseline, the archetype mix, the AI and offshore ceilings, the realisation curve and the agile conversion quarters. Those are inputs on the Logic Tree and Delivery Mode.
A10: B. THE INVARIANTS — all of these must stay green
B11: Check | C11: Y1 | D11: Y2 | E11: Y3 | F11: Y4 | G11: Y5 | H11: Tolerance | I11: Status
B12: Headcount delivered minus Logic Tree target | C12: ='Team Build-Up'!C12 -> -0.0735 | D12: ='Team Build-Up'!D12 -> -0.097752193 | E12: ='Team Build-Up'!E12 -> 0.11798058 | F12: ='Team Build-Up'!F12 -> 0.063256079 | G12: ='Team Build-Up'!G12 -> 0.1811651 | H12: ± 1.5 | I12: =IF(MAX(ABS(C12),ABS(D12),ABS(E12),ABS(F12),ABS(G12))<=1.5,"OK","CHECK") -> OK | J12: The productivity commitment. If you add seats you must remove others.
B13: Capgemini share inside each POD | C13: =IFERROR((SUMIFS('Pod Library'!$J$5:$J$95,'Pod Library'!$B$5:$B$95,1,'Pod Library'!$C$5:$C$95,"POD",'Pod Library'!$I$5:$I$95,"FTC")+SUMIFS('Pod Library'!$J$5:$J$95,'Pod Library'!$B$5:$B$95,1,'Pod Library'!$C$5:$C$95,"POD",'Pod Library'!$I$5:$I$95,"PT"))/(SUMIFS('Pod Library'!$J$5:$J$95,'Pod Library'!$B$5:$B$95,1,'Pod Library'!$C$5:$C$95,"POD")),"n/a") -> 0.5625 | D13: =IFERROR((SUMIFS('Pod Library'!$J$5:$J$95,'Pod Library'!$B$5:$B$95,2,'Pod Library'!$C$5:$C$95,"POD",'Pod Library'!$I$5:$I$95,"FTC")+SUMIFS('Pod Library'!$J$5:$J$95,'Pod Library'!$B$5:$B$95,2,'Pod Library'!$C$5:$C$95,"POD",'Pod Library'!$I$5:$I$95,"PT"))/(SUMIFS('Pod Library'!$J$5:$J$95,'Pod Library'!$B$5:$B$95,2,'Pod Library'!$C$5:$C$95,"POD")),"n/a") -> 0.6 | E13: =IFERROR((SUMIFS('Pod Library'!$J$5:$J$95,'Pod Library'!$B$5:$B$95,3,'Pod Library'!$C$5:$C$95,"POD",'Pod Library'!$I$5:$I$95,"FTC")+SUMIFS('Pod Library'!$J$5:$J$95,'Pod Library'!$B$5:$B$95,3,'Pod Library'!$C$5:$C$95,"POD",'Pod Library'!$I$5:$I$95,"PT"))/(SUMIFS('Pod Library'!$J$5:$J$95,'Pod Library'!$B$5:$B$95,3,'Pod Library'!$C$5:$C$95,"POD")),"n/a") -> 0.60869565 | F13: =IFERROR((SUMIFS('Pod Library'!$J$5:$J$95,'Pod Library'!$B$5:$B$95,4,'Pod Library'!$C$5:$C$95,"POD",'Pod Library'!$I$5:$I$95,"FTC")+SUMIFS('Pod Library'!$J$5:$J$95,'Pod Library'!$B$5:$B$95,4,'Pod Library'!$C$5:$C$95,"POD",'Pod Library'!$I$5:$I$95,"PT"))/(SUMIFS('Pod Library'!$J$5:$J$95,'Pod Library'!$B$5:$B$95,4,'Pod Library'!$C$5:$C$95,"POD")),"n/a") -> 0.5625 | G13: =IFERROR((SUMIFS('Pod Library'!$J$5:$J$95,'Pod Library'!$B$5:$B$95,5,'Pod Library'!$C$5:$C$95,"POD",'Pod Library'!$I$5:$I$95,"FTC")+SUMIFS('Pod Library'!$J$5:$J$95,'Pod Library'!$B$5:$B$95,5,'Pod Library'!$C$5:$C$95,"POD",'Pod Library'!$I$5:$I$95,"PT"))/(SUMIFS('Pod Library'!$J$5:$J$95,'Pod Library'!$B$5:$B$95,5,'Pod Library'!$C$5:$C$95,"POD")),"n/a") -> 0.56578947 | H13: ≥ 55% | I13: =IF(COUNTIF(C13:G13,"<0.5450")=0,"OK","CHECK") -> OK | J13: A POD in which Capgemini is a minority is one whose ways of working we do not set.
B14: Capgemini share inside each TEAM | C14: =IFERROR((SUMIFS('Pod Library'!$J$5:$J$95,'Pod Library'!$B$5:$B$95,1,'Pod Library'!$C$5:$C$95,"TEAM",'Pod Library'!$I$5:$I$95,"FTC")+SUMIFS('Pod Library'!$J$5:$J$95,'Pod Library'!$B$5:$B$95,1,'Pod Library'!$C$5:$C$95,"TEAM",'Pod Library'!$I$5:$I$95,"PT"))/(SUMIFS('Pod Library'!$J$5:$J$95,'Pod Library'!$B$5:$B$95,1,'Pod Library'!$C$5:$C$95,"TEAM")),"n/a") -> 0.76315789 | D14: =IFERROR((SUMIFS('Pod Library'!$J$5:$J$95,'Pod Library'!$B$5:$B$95,2,'Pod Library'!$C$5:$C$95,"TEAM",'Pod Library'!$I$5:$I$95,"FTC")+SUMIFS('Pod Library'!$J$5:$J$95,'Pod Library'!$B$5:$B$95,2,'Pod Library'!$C$5:$C$95,"TEAM",'Pod Library'!$I$5:$I$95,"PT"))/(SUMIFS('Pod Library'!$J$5:$J$95,'Pod Library'!$B$5:$B$95,2,'Pod Library'!$C$5:$C$95,"TEAM")),"n/a") -> 0.8372093 | E14: =IFERROR((SUMIFS('Pod Library'!$J$5:$J$95,'Pod Library'!$B$5:$B$95,3,'Pod Library'!$C$5:$C$95,"TEAM",'Pod Library'!$I$5:$I$95,"FTC")+SUMIFS('Pod Library'!$J$5:$J$95,'Pod Library'!$B$5:$B$95,3,'Pod Library'!$C$5:$C$95,"TEAM",'Pod Library'!$I$5:$I$95,"PT"))/(SUMIFS('Pod Library'!$J$5:$J$95,'Pod Library'!$B$5:$B$95,3,'Pod Library'!$C$5:$C$95,"TEAM")),"n/a") -> n/a | F14: =IFERROR((SUMIFS('Pod Library'!$J$5:$J$95,'Pod Library'!$B$5:$B$95,4,'Pod Library'!$C$5:$C$95,"TEAM",'Pod Library'!$I$5:$I$95,"FTC")+SUMIFS('Pod Library'!$J$5:$J$95,'Pod Library'!$B$5:$B$95,4,'Pod Library'!$C$5:$C$95,"TEAM",'Pod Library'!$I$5:$I$95,"PT"))/(SUMIFS('Pod Library'!$J$5:$J$95,'Pod Library'!$B$5:$B$95,4,'Pod Library'!$C$5:$C$95,"TEAM")),"n/a") -> n/a | G14: =IFERROR((SUMIFS('Pod Library'!$J$5:$J$95,'Pod Library'!$B$5:$B$95,5,'Pod Library'!$C$5:$C$95,"TEAM",'Pod Library'!$I$5:$I$95,"FTC")+SUMIFS('Pod Library'!$J$5:$J$95,'Pod Library'!$B$5:$B$95,5,'Pod Library'!$C$5:$C$95,"TEAM",'Pod Library'!$I$5:$I$95,"PT"))/(SUMIFS('Pod Library'!$J$5:$J$95,'Pod Library'!$B$5:$B$95,5,'Pod Library'!$C$5:$C$95,"TEAM")),"n/a") -> n/a | H14: ≥ 55% | I14: =IF(COUNTIF(C14:G14,"<0.5450")=0,"OK","CHECK") -> OK | J14: A TEAM in which Capgemini is a minority is one whose ways of working we do not set.
B15: Capgemini share of the delivery population | C15: =IFERROR((SUMIFS('Seat Ledger'!$M$5:$M$287,'Seat Ledger'!$B$5:$B$287,1,'Seat Ledger'!$J$5:$J$287,"FTC")+SUMIFS('Seat Ledger'!$M$5:$M$287,'Seat Ledger'!$B$5:$B$287,1,'Seat Ledger'!$J$5:$J$287,"PT"))/(SUMIFS('Seat Ledger'!$M$5:$M$287,'Seat Ledger'!$B$5:$B$287,1)),0) -> 0.69958848 | D15: =IFERROR((SUMIFS('Seat Ledger'!$M$5:$M$287,'Seat Ledger'!$B$5:$B$287,2,'Seat Ledger'!$J$5:$J$287,"FTC")+SUMIFS('Seat Ledger'!$M$5:$M$287,'Seat Ledger'!$B$5:$B$287,2,'Seat Ledger'!$J$5:$J$287,"PT"))/(SUMIFS('Seat Ledger'!$M$5:$M$287,'Seat Ledger'!$B$5:$B$287,2)),0) -> 0.68449198 | E15: =IFERROR((SUMIFS('Seat Ledger'!$M$5:$M$287,'Seat Ledger'!$B$5:$B$287,3,'Seat Ledger'!$J$5:$J$287,"FTC")+SUMIFS('Seat Ledger'!$M$5:$M$287,'Seat Ledger'!$B$5:$B$287,3,'Seat Ledger'!$J$5:$J$287,"PT"))/(SUMIFS('Seat Ledger'!$M$5:$M$287,'Seat Ledger'!$B$5:$B$287,3)),0) -> 0.67105263 | F15: =IFERROR((SUMIFS('Seat Ledger'!$M$5:$M$287,'Seat Ledger'!$B$5:$B$287,4,'Seat Ledger'!$J$5:$J$287,"FTC")+SUMIFS('Seat Ledger'!$M$5:$M$287,'Seat Ledger'!$B$5:$B$287,4,'Seat Ledger'!$J$5:$J$287,"PT"))/(SUMIFS('Seat Ledger'!$M$5:$M$287,'Seat Ledger'!$B$5:$B$287,4)),0) -> 0.52671756 | G15: =IFERROR((SUMIFS('Seat Ledger'!$M$5:$M$287,'Seat Ledger'!$B$5:$B$287,5,'Seat Ledger'!$J$5:$J$287,"FTC")+SUMIFS('Seat Ledger'!$M$5:$M$287,'Seat Ledger'!$B$5:$B$287,5,'Seat Ledger'!$J$5:$J$287,"PT"))/(SUMIFS('Seat Ledger'!$M$5:$M$287,'Seat Ledger'!$B$5:$B$287,5)),0) -> 0.50420168 | H15: ≥ 50% | I15: =IF(COUNTIF(C15:G15,"<0.4950")=0,"OK","CHECK") -> OK | J15: Below half the roster we cannot carry a productivity commitment we do not control.
B16: Blocks deploying a non-whole number of people | C16: =SUMPRODUCT(('Pod Library'!$B$5:$B$95=1)*(ABS('Pod Library'!$K$5:$K$95*2-ROUND('Pod Library'!$K$5:$K$95*2,0))>0.01))+SUMPRODUCT(('Horizontal Teams'!$B$5:$B$110=1)*(ABS('Horizontal Teams'!$J$5:$J$110*2-ROUND('Horizontal Teams'!$J$5:$J$110*2,0))>0.01)) -> 0 | D16: =SUMPRODUCT(('Pod Library'!$B$5:$B$95=2)*(ABS('Pod Library'!$K$5:$K$95*2-ROUND('Pod Library'!$K$5:$K$95*2,0))>0.01))+SUMPRODUCT(('Horizontal Teams'!$B$5:$B$110=2)*(ABS('Horizontal Teams'!$J$5:$J$110*2-ROUND('Horizontal Teams'!$J$5:$J$110*2,0))>0.01)) -> 0 | E16: =SUMPRODUCT(('Pod Library'!$B$5:$B$95=3)*(ABS('Pod Library'!$K$5:$K$95*2-ROUND('Pod Library'!$K$5:$K$95*2,0))>0.01))+SUMPRODUCT(('Horizontal Teams'!$B$5:$B$110=3)*(ABS('Horizontal Teams'!$J$5:$J$110*2-ROUND('Horizontal Teams'!$J$5:$J$110*2,0))>0.01)) -> 0 | F16: =SUMPRODUCT(('Pod Library'!$B$5:$B$95=4)*(ABS('Pod Library'!$K$5:$K$95*2-ROUND('Pod Library'!$K$5:$K$95*2,0))>0.01))+SUMPRODUCT(('Horizontal Teams'!$B$5:$B$110=4)*(ABS('Horizontal Teams'!$J$5:$J$110*2-ROUND('Horizontal Teams'!$J$5:$J$110*2,0))>0.01)) -> 0 | G16: =SUMPRODUCT(('Pod Library'!$B$5:$B$95=5)*(ABS('Pod Library'!$K$5:$K$95*2-ROUND('Pod Library'!$K$5:$K$95*2,0))>0.01))+SUMPRODUCT(('Horizontal Teams'!$B$5:$B$110=5)*(ABS('Horizontal Teams'!$J$5:$J$110*2-ROUND('Horizontal Teams'!$J$5:$J$110*2,0))>0.01)) -> 0 | H16: =0 -> 0 | I16: =IF(SUM(C16:G16)=0,"OK","CHECK") -> OK | J16: Column K of the Pod Library and column J of Horizontal Teams are the people you hire for that role across the whole block. Every one is a whole number, or a half where one person covers two units INSIDE this domain. The seat ratio beside it is the modelling quantity and will not always be round — on a 28-team block, nine engineers is a ratio of 0.32.
B17: Horizontal roles that have fallen below 0.02 FTE | C17: =COUNTIFS('Horizontal Teams'!$B$5:$B$110,1,'Horizontal Teams'!$I$5:$I$110,"<0.02") -> 0 | D17: =COUNTIFS('Horizontal Teams'!$B$5:$B$110,2,'Horizontal Teams'!$I$5:$I$110,"<0.02") -> 0 | E17: =COUNTIFS('Horizontal Teams'!$B$5:$B$110,3,'Horizontal Teams'!$I$5:$I$110,"<0.02") -> 0 | F17: =COUNTIFS('Horizontal Teams'!$B$5:$B$110,4,'Horizontal Teams'!$I$5:$I$110,"<0.02") -> 0 | G17: =COUNTIFS('Horizontal Teams'!$B$5:$B$110,5,'Horizontal Teams'!$I$5:$I$110,"<0.02") -> 0 | H17: =0 -> 0 | I17: =IF(SUM(C17:G17)=0,"OK","CHECK") -> OK | J17: A domain cannot run without a delivery head, a service manager or an architect. If a role must genuinely end, delete the row rather than leaving it at zero.
B18: Year-1 reconciliation to Appendix 3 — worst line | C18: ='Team Build-Up'!E32 -> 9.8985 | H18: ± 2.6 | I18: =IF(ABS(C18)<=2.6,"OK","CHECK") -> CHECK | J18: Year 1 must reproduce the client's own numbers: effort, the sourcing split, all three locations and all six role lines. The tolerance is ± 2.6 because seats sit on a 0.5 grid and a Year-1 team seat carries a multiplier of 5 — one grid step is 2.5 people. That is the deliberate price of an anatomy that can be staffed. Moving a seat between bands is free; moving it between ROLE, LOCATION or SOURCING is what actually breaks this.
A20: C. WHAT GOES STALE AND WILL NOT WARN YOU
B21: • SOURCING & PRODUCTIVITY is static. It is produced outside Excel by the per-sourcing solver and pasted in. If you change seat counts, the pool ceilings, the organic-convergence table and the transfer solve on that sheet no longer describe this roster. Re-run the solver or treat the sheet as superseded.
B22: • SIT LOADING is static for the same reason. Re-generate it after any seat change, or the requisition plan will not match the ledger.
B23: • The TRANSFER on the Logic Tree is a typed input (rows 65-66), sized on the Year-3 exit position produced by the solver. Change the Year-3 roster materially and the transfer needs re-sizing, or the 50:50 will not land.
B24: • THE RULE OF THUMB. Re-banding a seat, renaming it, or moving it between pods is safe. Changing its ROLE, LOCATION or SOURCING is not — those are the attributes Year 1 reconciles on and the guardrails measure.

Sheet Logic Tree
A1: Logic Tree — ten parametric drivers, five years
A2: Amber cells are inputs. Everything else re-derives. Section F is rebuilt on the measured day-1 position.
A4: A. BASELINE — Appendix 3 v5, read and never edited
B5: Domain | C5: Insurance Claims and Benefits Payment Related
B6: Applications | C6: 6
B7: Total effort (units) | C7: 121.5735
B8: Current FTC reported (Capgemini + partner) | C8: 85.4485
B9: Current FTE | C9: 13.4792
B10: Current MGCC | C10: 22.6458
B11: — of which onshore Tokyo | C11: 71.6261 | J11: 28.87 offshore, 15.99 MGCC and 0.96 nearshore against 35.55 onshore. This domain already delivers most of its work away from Tokyo.
B12: — of which offshore | C12: 4.2333
B13: — of which nearshore | C13: 9.589
B14: — of which onsite | C14: 0
B15: Role: BSA | C15: 5.9583
B16: Role: Developer | C16: 70.8985 | J16: All six role lines are populated for this domain and are used exactly as reported. No restatement was needed.
B17: Role: Tester | C17: 6.8167
B18: Role: Maintenance | C18: 1
B19: Role: PM | C19: 0
B20: Role: Other | C20: 0.775
B21: AD effort (% of PRJ weighted) | C21: 114.8276
B22: Appendix 3 Year-3 target, each side | C22: 60.7868
B23: Ratio today — Capgemini share | C23: =C8/(C8+C9+C10) -> 0.70285465
B24: OFFSHORE TODAY — whole team, measured | C24: =(C12+C13+C10)/C7 -> 0.29996751 | J24: 45.5% on day one — 28.87 offshore, 0.96 nearshore and 15.99 MGCC. The highest starting position of the eleven domains, which is why the ceiling here is reachable rather than aspirational.
A26: B. ARCHETYPE MIX — from the Golden Application Inventory v4
B27: Archetype | C27: Name | D27: Apps | E27: Effort | F27: Share | G27: AI ceiling | H27: Offshore ceiling
B28: D | C28: Distributed-proven | D28: 3 | E28: 95.4786 | F28: =E28/$E$33 -> 0.78535765 | G28: 0.4825 | H28: 0.78
B29: J | C29: Japan-locked | D29: 1 | E29: 22.0283 | F29: =E29/$E$33 -> 0.18119342 | G29: 0.304 | H29: 0.12
B30: T | C30: Long tail | D30: 2 | E30: 4.0665 | F30: =E30/$E$33 -> 0.033448929 | G30: 0.39 | H30: 0.55
C33: Total | D33: =SUM(D28:D32) -> 6 | E33: =SUM(E28:E32) -> 121.5734 | F33: =SUM(F28:F32) -> 1
B34: APPLICABLE AI CEILING | C34: =SUMPRODUCT($E$28:$E$32,$G$28:$G$32)/$E$33 -> 0.44706295 | J34: 46.74% on the golden phase mix — the highest of the eleven domains, because both archetypes present are M and D, the two the classifier treats as most machine-addressable. No domain-specific override is applied.
B35: APPLICABLE OFFSHORE CEILING | C35: =SUMPRODUCT($E$28:$E$32,$H$28:$H$32)/$E$33 -> 0.65271909 | J35: 65.27%. Three archetype-D applications carry 78.5% of the effort at a 78% ceiling, and this domain is nothing but M and D.
A37: C. REALISATION AND THE NON-AI COMPONENTS
B38: Driver | C38: Year 1 | D38: Year 2 | E38: Year 3 | F38: Year 4 | G38: Year 5 | H38: Basis
B39: AI realisation — share of ceiling | C39: 0.25 | D39: 0.55 | E39: 0.75 | F39: 0.85 | G39: 0.9 | J39: Adoption, guardrails and substrate maturity. Capped at 90%.
B40: Classical ADM productivity, cumulative | C40: 0.02 | D40: 0.05 | E40: 0.07 | F40: 0.09 | G40: 0.11 | J40: Standardisation, defect reduction, shift-left.
B41: Operating-model productivity, RAW | C41: 0.03 | D41: 0.06 | E41: 0.08 | F41: 0.1 | G41: 0.12 | J41: Pod consolidation and one release train — only available where the stream is agile.
B42: Agile share of the domain → from the Delivery Mode sheet | C42: ='Delivery Mode'!C20 -> 0.39477447 | D42: ='Delivery Mode'!D20 -> 0.85606843 | E42: ='Delivery Mode'!E20 -> 1 | F42: ='Delivery Mode'!F20 -> 1 | G42: ='Delivery Mode'!G20 -> 1
B43: Operating-model productivity, APPLIED = raw × agile share × span-of-control factor | C43: =C41*C42*C61 -> 0.011843234 | D43: =D41*D42*D61 -> 0.051364106 | E43: =E41*E42*E61 -> 0.08 | F43: =F41*F42*F61 -> 0.1 | G43: =G41*G42*G61 -> 0.12 | J43: Scaling by the agile share is what makes the operating-model gain earned rather than assumed. It costs 2.0 points of Year-1 capability: 16.0% unscaled against the 14.1% the model earns.
B44: AI-attributable productivity | C44: =$C$34*C39 -> 0.11176574 | D44: =$C$34*D39 -> 0.24588462 | E44: =$C$34*E39 -> 0.33529721 | F44: =$C$34*F39 -> 0.38000351 | G44: =$C$34*G39 -> 0.40235665
B45: CAPABILITY EARNED by end of year | C45: =1-(1-C44)*(1-C40)*(1-C43) -> 0.1398396 | D45: =1-(1-D44)*(1-D40)*(1-D43) -> 0.32038813 | E45: =1-(1-E44)*(1-E40)*(1-E43) -> 0.43128029 | F45: =1-(1-F44)*(1-F40)*(1-F43) -> 0.49222287 | G45: =1-(1-G44)*(1-G40)*(1-G43) -> 0.53192573
...

Sheet Sourcing & Productivity
A1: Sourcing and productivity — the same chain, applied differently to each population
A2: Productivity is not one number applied to everybody. The three populations do different work and we do not control all three, so each carries its own AI ceiling and its own adoption factor. This is what makes the 50:50 converge on its own rather than by transfer.
A4: A. WHY ONE RATE CANNOT APPLY TO ALL THREE — the Year-1 role mix
B5: Population | C5: Heads Y1 | D5: BSA | E5: Developer | F5: Tester | G5: Maint.
B6: FTC · Capgemini payroll | C6: 57.702 | D6: 0.093410974 | E6: 0.64380784 | F6: 0.089390316 | G6: 0.098280822 | I6: MetLife's own people are governance, domain SME and product ownership. MGCC is build and test. They are not doing the same work, so they cannot carry the same productivity rate.
B7: PT · Partner (sub-contracted) | C7: 7.68 | D7: 0.24101563 | E7: 0.75898438 | F7: 0 | G7: 0
B8: FTE · MetLife Japan | C8: 19.388 | D8: 0.39374871 | E8: 0 | F8: 0 | G8: 0.23411388
B9: MGCC · MetLife MGCC | C9: 15.993 | D9: 0 | E9: 1 | F9: 0 | G9: 0
A11: B. EACH POPULATION'S OWN AI CEILING AND ADOPTION — INPUT
B12: Population | C12: Own AI ceiling | D12: Adoption | E12: Effective ceiling | F12: vs domain blend
B13: FTC · Capgemini payroll | C13: 0.46171242 | D13: 1 | E13: 0.46171242 | F13: -0.012179166 | I13: ADOPTION is the share of the ceiling each population can actually realise, and it is a judgement about AUTHORITY, not about capability. We build the tooling, set the ways of working and mandate them on our own payroll — so 1.00. Everything below that is somebody else's decision.
B14: PT · Partner (sub-contracted) | C14: 0.4473668 | D14: 0.85 | E14: 0.38026178 | F14: -0.042871216
B15: FTE · MetLife Japan | C15: 0.38163811 | D15: 0.55 | E15: 0.20990096 | F15: -0.18349592
B16: MGCC · MetLife MGCC | C16: 0.47987351 | D16: 0.8 | E16: 0.38389881 | F16: 0.026675973
B17: Domain blended ceiling (unchanged, and still the headline commitment) | C17: 0.46740502
B18: Only the AI gate is scaled. Classical ADM productivity attaches to the work and the operating-model gain attaches to the delivery unit, so both flow to every population regardless of employer.
A20: C. WHAT EACH POPULATION IS THEREFORE ASKED TO DELIVER
B21: Applied to staffing | C21: Year 1 | D21: Year 2 | E21: Year 3 | F21: Year 4 | G21: Year 5
B22: FTC · Capgemini payroll | C22: 0 | D22: 0.23401506 | E22: 0.38388594 | F22: 0.47009789 | G22: 0.5211233 | I22: The headline commitment is UNCHANGED from the previous version. What has changed is that it is no longer assumed to fall equally on all three populations.
B23: PT · Partner (sub-contracted) | C23: 0 | D23: 0.20395522 | E23: 0.3375221 | F23: 0.4154649 | G23: 0.46392092
B24: FTE · MetLife Japan | C24: 0 | D24: 0.14108256 | E24: 0.24054827 | F24: 0.30119543 | G24: 0.34427736
B25: MGCC · MetLife MGCC | C25: 0 | D25: 0.20529749 | E25: 0.33959239 | F25: 0.41790443 | G25: 0.46647518
B26: Whole-domain commitment (the headline) | C26: 0 | D26: 0.23611595 | E26: 0.38712631 | F26: 0.47391621 | G26: 0.52512118
A28: D. THE THREE-WAY COMMITMENT SPLIT
B29: CAPGEMINI COMMITS | C29: Our own headcount reduction, on our own payroll, on tooling and ways of working we control. This is contractible and we should contract it.
B30: METLIFE MUST DELIVER | C30: The reduction of MetLife Japan and MGCC headcount. We size it, we enable it and we report it — but redeploying MetLife's own people is MetLife's decision, and MGCC runs to its own utilisation targets. This should be a joint commitment with named owners, not a Capgemini SLA.
B31: JOINTLY DEPENDENT | C31: AI adoption on MetLife's side: tooling access, shared standards, common telemetry, and the substrate being used rather than merely available. If adoption lands below the factors in section B, the whole-team headcount misses even if Capgemini delivers in full.
A33: E. ORGANIC CONVERGENCE TO 50:50 — before any transfer
B34: Measure | C34: Year 1 | D34: Year 2 | E34: Year 3 | F34: Year 4 | G34: Year 5
B35: MetLife Japan (FTE) — own curve | C35: 19.388 | D35: 16.652691 | E35: 14.72425 | F35: 14.696025 | G35: 13.404314 | I35: MetLife's populations follow their own slower curves. Capgemini takes the balance, which means we shrink our own book faster than productivity alone would justify. That extra reduction is not a productivity claim — it is a deliberate commercial choice to reach the ratio organically instead of by transferring people.
B36: MetLife MGCC — own curve | C36: 15.993 | D36: 12.709677 | E36: 10.561899 | F36: 11.809391 | G36: 10.521268
B37: Partner — per the partner plan | C37: 7.68 | D37: 5.5 | E37: 3.5 | F37: 2 | G37: 1.5
B38: Capgemini — absorbs the balance | C38: 57.704 | D38: 42.110408 | E38: 32.970068 | F38: 24.505417 | G38: 22.425582
B39: TOTAL = the headline commitment | C39: 100.765 | D39: 76.972776 | E39: 61.756217 | F39: 53.010834 | G39: 47.851164
B40: RATIO — Capgemini share | C40: 0.6488761 | D40: 0.61853567 | E40: 0.59054893 | F40: 0.5 | G40: 0.5
B41: — of which productivity-driven | C41: 0 | D41: 0.23401506 | E41: 0.38388594 | F41: 0.47009789 | G41: 0.5211233
B42: — of which RATIO-DRIVEN, over and above productivity | C42: -3.4660844e-05 | D42: 0.036193812 | E42: 0.044728879 | F42: 0.1052129 | G42: 0.090231908
B44: This is the mechanism that halves the transfer. Reaching the ratio by shrinking our own book is cheaper, lower-risk and entirely within our control; a transfer of employment is neither.
A46: F. THE GUARDRAILS — where organic convergence has to stop
B47: Test | C47: Year 1 | D47: Year 2 | E47: Year 3 | F47: Year 4 | G47: Year 5 | H47: Floor
...

Sheet Delivery Mode
A1: Delivery mode — measured per application, not assumed
A2: Appendix 3 v5 supplies the development method for every application here. Seven of the ten are agile today — 16.7 of 121.6 units. Four of six run on Japanese specifications and only two are cloud-flagged. and the productivity case rests on that.
A4: A. MODE TODAY AND TARGET, BY VALUE STREAM — INPUT
B5: Value stream | C5: Effort | D5: Archetype | E5: Mode today | F5: Agile from | G5: Why
B6: AMP · Annuity ＆ Maturity Payment | C6: 67.7544 | D6: D / J / T | E6: Hybrid | F6: Q3 | G6: Claim Batch is 43.8 of the 67.8 — cloud-flagged, hybrid method, and the only application in the 領域 Capgemini already sits on. W05AMS-JPN behind it is 22.0 units of Japan-locked waterfall. | I6: The mode column is MetLife's own data. MetLife records three value streams here. Claims Support Services already runs agile; Annuity ＆ Maturity Payment is hybrid-led; Claims Processing ＆ single release train and a stable pod shape, not about changing method. The quarter each stream Adjudication is waterfall, Japanese-specification and marked Retire, so it converts late by design: CSS Q2, AMP Q3, CPA Q7.
B7: CPA · Claims Processing & Adjudication | C7: 34.9965 | D7: D | E7: Waterfall | F7: Q7 | G7: C12WNC-JPN alone. Business-critical, Japanese specifications, 9.6 units nearshore, and MARKED RETIRE in Appendix 3 v5. Converted late on purpose.
B8: CSS · Claims Support Services | C8: 18.8225 | D8: D / T | E8: Agile | F8: Q2 | G8: Pega for Claims and MDRS. Already agile, English specifications, cloud-flagged — and both carry a ZERO Year-3 target in MetLife's own Appendix 3 model.
B9: Total | C9: =SUM(C6:C8) -> 121.5734
A11: B. AGILE SHARE BY YEAR — computed from the quarter each stream converts
B12: Value stream | C12: Year 1 | D12: Year 2 | E12: Year 3 | F12: Year 4 | G12: Year 5
B13: AMP | C13: 0.5 | D13: 1 | E13: 1 | F13: 1 | G13: 1
B14: CPA | C14: 0 | D14: 0.5 | E14: 1 | F14: 1 | G14: 1
B15: CSS | C15: 0.75 | D15: 1 | E15: 1 | F15: 1 | G15: 1
B16: Effort-weighted agile share of the domain | C16: =SUMPRODUCT($C$6:$C$8,C13:C15)/$C$9 -> 0.39477447 | D16: =SUMPRODUCT($C$6:$C$8,D13:D15)/$C$9 -> 0.85606843 | E16: =SUMPRODUCT($C$6:$C$8,E13:E15)/$C$9 -> 1 | F16: =SUMPRODUCT($C$6:$C$8,F13:F15)/$C$9 -> 1 | G16: =SUMPRODUCT($C$6:$C$8,G13:G15)/$C$9 -> 1
B18: Delivery units this produces
B19: — agile PODS | C19: 4 | D19: 7 | E19: 9 | F19: 9 | G19: 8
B20: — agile share (feeds the Logic Tree) | C20: =C16 -> 0.39477447 | D20: =D16 -> 0.85606843 | E20: =E16 -> 1 | F20: =F16 -> 1 | G20: =G16 -> 1
B21: — waterfall / hybrid TEAMS | C21: 5 | D21: 2 | E21: 0 | F21: 0 | G21: 0
A23: C. WHY THIS MATTERS TO THE NUMBER
B24: • Operating-model productivity — pod consolidation, one release train, span of control — is only available where the stream actually runs as a pod. Scaling the 3 / 6 / 8 / 10 / 12% curve by the Year-1 agile share of 39.5% cuts it to 1.2%, and that is the whole of the discount: NCD is absorbed rather than retained, so there is no partner share to net off. From Year 3 the domain is fully converted and the curve runs at full value.
B25: • The waterfall / hybrid TEAM is 12 seats with a separate test cell; the agile POD is 10 in Year 1 falling to 6 by Year 4, with test collapsed into SDET seats. Both carry MGCC seats from day one, which is what makes this domain's offshore movement cheap: the substrate is already there.
B26: • Year 1 runs 4 pods and 5 delivery teams. Teams are gone by Year 3 and the pod count runs 4 / 7 / 9 / 9 / 8 — it RISES before it falls, because conversion adds pods before productivity removes them. If Annuity ＆ Maturity Payment slips two quarters the Year-1 agile share falls from 39.5% to 11.7%, which costs nothing in staffing because Year 1 applies zero productivity by construction.
B27: • DECIDE the conversion quarters, not the modes. MetLife has given us the development method for every application, so the only assumption left on this sheet is WHEN each stream reaches the target pod shape — CSS Q2, AMP Q3, CPA Q7. The CPA quarter is the conservative one and it is deliberate — that stream is one them.

Sheet AMS & Ticket Load
A1: AMS and ticket load — the run team sized from evidence, for the first time
A2: 732 incidents and 1,161 changes over 32 months, from Appendix 3 v5.
A4: A. RECORDED VOLUMES — 1 Jan 2024 to 31 Aug 2026
B5: Measure | C5: Volume | D5: Per month | E5: Per unit of effort | F5: Share
B6: P1 — critical | C6: 0 | D6: =C6/$C$17 -> 0 | E6: =C6/'Logic Tree'!$C$7 -> 0 | F6: =C6/$C$11 -> 0 | I6: No P1 or P2 incidents at all in 32 months and 71% of incidents at P5. The estate is stable; the cost is in changing it, not in keeping it up.
B7: P2 — high | C7: 1 | D7: =C7/$C$17 -> 0.03125 | E7: =C7/'Logic Tree'!$C$7 -> 0.0082254768 | F7: =C7/$C$11 -> 0.0013661202
B8: P3 — medium | C8: 89 | D8: =C8/$C$17 -> 2.78125 | E8: =C8/'Logic Tree'!$C$7 -> 0.73206743 | F8: =C8/$C$11 -> 0.1215847
B9: P4 — low | C9: 143 | D9: =C9/$C$17 -> 4.46875 | E9: =C9/'Logic Tree'!$C$7 -> 1.1762432 | F9: =C9/$C$11 -> 0.19535519
B10: P5 — informational | C10: 499 | D10: =C10/$C$17 -> 15.59375 | E10: =C10/'Logic Tree'!$C$7 -> 4.1045129 | F10: =C10/$C$11 -> 0.68169399
B11: All incidents | C11: =SUM(C6:C10) -> 732 | D11: =C11/$C$17 -> 22.875 | E11: =C11/'Logic Tree'!$C$7 -> 6.021049
B12: Emergency change | C12: 34 | D12: =C12/$C$17 -> 1.0625 | E12: =C12/'Logic Tree'!$C$7 -> 0.27966621 | F12: =C12/$C$15 -> 0.029285099 | I12: 84% Standard and 4.3% Emergency. A high-volume, low-severity, highly repeatable change profile — the best automation case in the portfolio.
B13: Normal change | C13: 124 | D13: =C13/$C$17 -> 3.875 | E13: =C13/'Logic Tree'!$C$7 -> 1.0199591 | F13: =C13/$C$15 -> 0.10680448
B14: Standard change | C14: 1003 | D14: =C14/$C$17 -> 31.34375 | E14: =C14/'Logic Tree'!$C$7 -> 8.2501532 | F14: =C14/$C$15 -> 0.86391042
B15: All changes | C15: =SUM(C12:C14) -> 1161 | D15: =C15/$C$17 -> 36.28125 | E15: =C15/'Logic Tree'!$C$7 -> 9.5497785
B17: Observation window, months | C17: 32
A19: B. SIZING THE RUN TEAM — three independent bases, triangulated
B20: Basis | C20: Value | D20: Reading
B21: A. Maintenance role reported in Appendix 3 v5 | C21: ='Logic Tree'!C18 -> 1 | D21: MetLife's own HEADCOUNT view. Populated here, unlike Contract Management, so it is usable.
B22: B. Run effort implied by the AD / AMS split = (1 − AD share) x effort | C22: ='Logic Tree'!C7-'Logic Tree'!C21 -> 6.7459 | D22: MetLife's own EFFORT view: 13.5% of 100.765 units. It implies 2.4 times the run population the role line does, and both numbers come from the same spreadsheet.
B23: Total demand items per month (incidents + changes) | C23: =(C11+C15)/C17 -> 59.15625 | D23: 2,536 items in 32 months — 25.2 per unit of effort against 14.6 on Sales. High for a three-application estate, and 84% of the changes are Standard.
B24: C. Throughput implied by basis A — items per person per month | C24: =IFERROR(C23/C21,0) -> 59.15625 | D24: If the role line is right, each run person absorbs this many items a month.
B25: C. Throughput implied by basis B | C25: =IFERROR(C23/C22,0) -> 8.7692154 | D25: If the effort split is right, this is the rate. Industry L2 throughput on a modern data stack is 40 to 80 items per person per month; both of these sit far below it, which says these items carry investigation rather than triage.
B26: Run-facing seats in the Year-1 roster (Maintenance + Tester, all sourcing) | C26: ='Team Build-Up'!C64+'Team Build-Up'!C63 -> 20 | D26: Model output. Sized on the role line, which is the binding Year-1 reconciliation constraint, and reported here against the other two bases rather than averaged with them.
A28: C. WHAT THE TICKET DATA CHANGES
B29: • MetLife's two views of the run population disagree by a factor of 2.4. The Maintenance role line says 5.67 units; the AD / AMS effort split says 13.64. This model follows the role line, because Year 1 has to reconcile to Appendix 3 line by line — but the difference is 8 people and it is a real commercial exposure. PUT THIS TO METLIFE before the AMS price is fixed.
B30: • The severity profile is benign and the change profile is not. No P1 or P2 incidents in 32 months and 71% of incidents at P5 — this estate is stable. But 1,730 changes on 100.8 units, 84% of them Standard, is a high change rate, and Standard changes on a cloud data platform are exactly what pipeline automation and a release train remove. That is where the operating-model productivity in this domain actually comes from.
B31: • Ticket density is 25.2 items per unit of effort against 14.6 on Sales — the highest of the domains modelled so far. Combined with a 13.5% run share it suggests run work is sitting inside the Developer line, which is the same pattern Sales shows and the reason this cross-check is worth running on every domain.
B32: • DO ask MetLife which of the two run figures governs, and ask for the ticket-to-effort mapping behind the AD / AMS split. On a three-application domain this is a short conversation with a material price attached.

Sheet Inventory
A1: Inventory — the 10 Insurance Claims and Benefits Payment Related applications from Appendix 3 v5
A2: Classified by the six-rule classifier on the Golden Application Inventory v4.
B4: Application | C4: Arch | D4: Effort | E4: FTC | F4: FTE | G4: Onshore | H4: Nearshore | I4: Nearsh % | J4: BSA | K4: Dev | L4: AD % | M4: Crit | N4: Method | O4: Spec lang | P4: Lines of code | Q4: Batches | R4: Incidents | S4: Changes | T4: Primary code language
B5: Claim Batch | C5: D | D5: 43.782083 | E5: 20.590417 | F5: 5.0458333 | G5: 17.357083 | H5: 0 | I5: =IFERROR($H5/$D5,0) -> 0 | J5: 1.75 | K5: 12.24875 | L5: 0.9836596 | M5: N | N5: Hybrid | O5: Hybrid | P5: 711101 | Q5: 27 | R5: 46 | S5: 216 | T5: JAVA
B6: C12WNC-JPN | C6: D | D6: 34.996542 | E6: 29.379875 | F6: 5.6166667 | G6: 19.790833 | H6: 9.5890417 | I6: =IFERROR($H6/$D6,0) -> 0.27399969 | J6: 2 | K6: 27.379875 | L6: 0.90522873 | M6: Y | N6: Waterfall | O6: JP | P6: 0 | Q6: 170 | R6: 581 | S6: 608 | T6: VB.NET;C/C++;JAVA
B7: W05AMS-JPN | C7: J | D7: 22.028333 | E7: 20.211667 | F7: 1.8166667 | G7: 20.211667 | H7: 0 | I7: =IFERROR($H7/$D7,0) -> 0 | J7: 1.9166667 | K7: 18.295 | L7: 0.92547477 | M7: Y | N7: Waterfall | O7: JP | P7: 0 | Q7: 186 | R7: 86 | S7: 272 | T7: JAVA, C#, VC
B8: Pega for Claims | C8: D | D8: 16.7 | E8: 11.491667 | F8: 0.70833333 | G8: 10.491667 | H8: 0 | I8: =IFERROR($H8/$D8,0) -> 0 | J8: 0.29166667 | K8: 9.2 | L8: 0.98702595 | M8: N | N8: Agile | O8: EN | P8: 14772 | Q8: 1 | R8: 5 | S8: 9 | T8: JAVA
B9: MDRS | C9: T | D9: 2.1225 | E9: 2.1225 | F9: 0 | G9: 2.1225 | H9: 0 | I9: =IFERROR($H9/$D9,0) -> 0 | J9: 0 | K9: 2.1225 | L9: 0.75068708 | M9: Y | N9: Waterfall | O9: JP | P9: 537636 | Q9: 38 | R9: 4 | S9: 37 | T9: VB.NET
B10: WZZMNB-JPN | C10: T | D10: 1.944 | E10: 1.6523333 | F10: 0.29166667 | G10: 1.6523333 | H10: 0 | I10: =IFERROR($H10/$D10,0) -> 0 | J10: 0 | K10: 1.6523333 | L10: 0.83217593 | M10: N | N10: Waterfall | O10: JP | P10: 0 | Q10: 17 | R10: 10 | S10: 19 | T10: JAVA
B11: TOTAL | D11: =SUM(D5:D10) -> 121.57346 | E11: =SUM(E5:E10) -> 85.448458 | F11: =SUM(F5:F10) -> 13.479167 | G11: =SUM(G5:G10) -> 71.626083 | H11: =SUM(H5:H10) -> 9.5890417 | J11: =SUM(J5:J10) -> 5.9583333 | K11: =SUM(K5:K10) -> 70.898458 | P11: =SUM(P5:P10) -> 1263509 | Q11: =SUM(Q5:Q10) -> 439 | R11: =SUM(R5:R10) -> 732 | S11: =SUM(S5:S10) -> 1161
B13: All six carry a development method and a specification language. Four run on Japanese specifications, only two are cloud-flagged and none is marked 優先引継対象. Code volume totals 1.26 million lines across three applications. Read the disposition column before anything else: C12WNC-JPN is marked RETIRE and is 35.0 of the 121.6 units, and Pega for Claims and MDRS carry a zero Year-3 target in MetLife's own Appendix 3 model. Together that is 44.3% of the 領域 under a disposition question — the highest exposure of any 領域 modelled, and the first thing to resolve with MetLife.

Sheet Value Streams
A1: Delivery streams — reconciling to 10 applications and 198.780 units
A2: MetLife records THREE value streams here — Annuity ＆ Maturity Payment (3 applications, 67.754 units), Claims Processing ＆ Adjudication (1 application, 34.997) and Claims Support Services (2, 18.823). All three are used as given; no synthetic stream was needed.
B4: Code | C4: Value stream | D4: Apps | E4: Effort | F4: Arch | G4: Mode today | H4: Agile from | I4: Y1 pods | J4: Y2 | K4: Y3 | L4: Y4 | M4: Y5 | N4: Vendor position today
B5: AMP | C5: Annuity ＆ Maturity Payment | D5: 3 | E5: 67.7544 | F5: D / J / T | G5: Hybrid | H5: Q3 | I5: 2 + 3t | J5: 4 + 1t | K5: 5 | L5: 5 | M5: 4 | N5: NCD 21.9 · CG 20.6
B6: CPA | C6: Claims Processing & Adjudication | D6: 1 | E6: 34.9965 | F6: D | G6: Waterfall | H6: Q7 | I6: 0 + 2t | J6: 1 + 1t | K6: 2 | L6: 2 | M6: 2 | N6: NCD 29.4
B7: CSS | C7: Claims Support Services | D7: 2 | E7: 18.8225 | F7: D / T | G7: Agile | H7: Q2 | I7: 2 | J7: 2 | K7: 2 | L7: 2 | M7: 2 | N7: unnamed 13.6
C8: Total | D8: =SUM(D5:D7) -> 6 | E8: =SUM(E5:E7) -> 121.5734
B10: Pod counts read 'pods + teams'. Teams are gone from Year 2 — the fastest conversion in the portfolio, because both streams already run agile. No delivery unit carries a partner seat: there is no named sub-contractor of size in this 領域. Note the MGCC seats inside every pod from Year 1 — 22.6 units, 18.6% of the domain — which is the only capacity already away here cheap and the 50:50 already met.

Sheet Pod Library
A1: Pod library — every seat, with MetLife's own role taxonomy and four sourcing types
A2: INPUT. Sourcing FTC = Capgemini payroll · PT = named sub-contractor, zero in this 領域 · FTE = MetLife Japan · MGCC = MetLife Global Capability Centre. Only FTC can transfer, and here nothing needs to.
B4: Year | C4: Unit | D4: Seat | E4: Role detail | F4: Role | G4: Exp | H4: Loc | I4: Sourcing | J4: Count | K4: People in the block
B5: 1 | C5: POD | D5: 1 | E5: MetLife Claims Product Owner | F5: PM | G5: E4 | H5: ON | I5: FTE | J5: 0.25 | K5: =J5*4 -> 1
B6: 1 | C6: POD | D6: 2 | E6: MetLife Claims SME | F6: BSA | G6: E4 | H6: ON | I6: FTE | J6: 0.25 | K6: =J6*4 -> 1
B7: 1 | C7: POD | D7: 3 | E7: Business Analyst (bilingual) | F7: BSA | G7: E3 | H7: ON | I7: FTC | J7: 0.375 | K7: =J7*4 -> 1.5
B8: 1 | C8: POD | D8: 4 | E8: Pod lead / senior engineer | F8: DEV | G8: E4 | H8: ON | I8: FTC | J8: 2.375 | K8: =J8*4 -> 9.5
B9: 1 | C9: POD | D9: 5 | E9: Claims Engineer | F9: DEV | G9: E3 | H9: OFF | I9: FTC | J9: 0 | K9: =J9*4 -> 0
B10: 1 | C10: POD | D10: 6 | E10: Claims Engineer | F10: DEV | G10: E2 | H10: OFF | I10: FTC | J10: 0.25 | K10: =J10*4 -> 1
B11: 1 | C11: POD | D11: 7 | E11: MGCC Payments Engineer | F11: DEV | G11: E3 | H11: OFF | I11: MGCC | J11: 1.375 | K11: =J11*4 -> 5.5
B12: 1 | C12: POD | D12: 8 | E12: SDET / Automation Engineer | F12: TEST | G12: E3 | H12: OFF | I12: FTC | J12: 0 | K12: =J12*4 -> 0
B13: 1 | C13: POD | D13: 9 | E13: MGCC Quality Engineer | F13: TEST | G13: E2 | H13: OFF | I13: MGCC | J13: 0.75 | K13: =J13*4 -> 3
B14: 1 | C14: POD | D14: 10 | E14: Solution Architect | F14: OTH | G14: E5 | H14: ON | I14: FTC | J14: 0.375 | K14: =J14*4 -> 1.5
D15: POD size — Year 1 | J15: =SUM(J5:J14) -> 6
B17: 1 | C17: TEAM | D17: 1 | E17: MetLife Claims Product Owner | F17: PM | G17: E4 | H17: ON | I17: FTE | J17: 0.7 | K17: =J17*5 -> 3.5
B18: 1 | C18: TEAM | D18: 2 | E18: MetLife Claims SME | F18: BSA | G18: E4 | H18: ON | I18: FTE | J18: 0.8 | K18: =J18*5 -> 4
B19: 1 | C19: TEAM | D19: 3 | E19: MetLife Operations Analyst | F19: MNT | G19: E3 | H19: ON | I19: FTE | J19: 0.2 | K19: =J19*5 -> 1
B20: 1 | C20: TEAM | D20: 4 | E20: Business Analyst (bilingual) | F20: BSA | G20: E3 | H20: ON | I20: FTC | J20: 0.4 | K20: =J20*5 -> 2
B21: 1 | C21: TEAM | D21: 5 | E21: Team lead / senior engineer | F21: DEV | G21: E4 | H21: ON | I21: FTC | J21: 1.7 | K21: =J21*5 -> 8.5
B22: 1 | C22: TEAM | D22: 6 | E22: Application Developer | F22: DEV | G22: E3 | H22: ON | I22: FTC | J22: 3.2 | K22: =J22*5 -> 16
B23: 1 | C23: TEAM | D23: 7 | E23: Application Developer | F23: DEV | G23: E2 | H23: ON | I23: FTC | J23: 3.5 | K23: =J23*5 -> 17.5
B24: 1 | C24: TEAM | D24: 8 | E24: Application Developer | F24: DEV | G24: E3 | H24: NEAR | I24: FTC | J24: 1.6 | K24: =J24*5 -> 8
B25: 1 | C25: TEAM | D25: 9 | E25: Test Analyst | F25: TEST | G25: E3 | H25: ON | I25: FTC | J25: 1 | K25: =J25*5 -> 5
B26: 1 | C26: TEAM | D26: 10 | E26: Test Engineer | F26: TEST | G26: E2 | H26: NEAR | I26: FTC | J26: 0.2 | K26: =J26*5 -> 1
B27: 1 | C27: TEAM | D27: 11 | E27: MGCC Payments Engineer | F27: DEV | G27: E3 | H27: OFF | I27: MGCC | J27: 1.9 | K27: =J27*5 -> 9.5
B28: 1 | C28: TEAM | D28: 12 | E28: Technical Lead | F28: OTH | G28: E4 | H28: ON | I28: FTC | J28: 0 | K28: =J28*5 -> 0
D29: TEAM size — Year 1 | J29: =SUM(J17:J28) -> 15.2
B31: 2 | C31: POD | D31: 1 | E31: MetLife Claims Product Owner | F31: PM | G31: E4 | H31: ON | I31: FTE | J31: 0.57142857 | K31: =J31*7 -> 4
B32: 2 | C32: POD | D32: 2 | E32: MetLife Claims SME | F32: BSA | G32: E4 | H32: ON | I32: FTE | J32: 0.42857143 | K32: =J32*7 -> 3
B33: 2 | C33: POD | D33: 3 | E33: Business Analyst (bilingual) | F33: BSA | G33: E3 | H33: ON | I33: FTC | J33: 1 | K33: =J33*7 -> 7
B34: 2 | C34: POD | D34: 4 | E34: Pod lead / senior engineer | F34: DEV | G34: E4 | H34: ON | I34: FTC | J34: 1.3571429 | K34: =J34*7 -> 9.5
B35: 2 | C35: POD | D35: 5 | E35: Claims Engineer | F35: DEV | G35: E3 | H35: OFF | I35: FTC | J35: 0.64285714 | K35: =J35*7 -> 4.5
B36: 2 | C36: POD | D36: 6 | E36: Claims Engineer | F36: DEV | G36: E2 | H36: OFF | I36: FTC | J36: 0.57142857 | K36: =J36*7 -> 4
B37: 2 | C37: POD | D37: 7 | E37: MGCC Payments Engineer | F37: DEV | G37: E3 | H37: OFF | I37: MGCC | J37: 1.1428571 | K37: =J37*7 -> 8
B38: 2 | C38: POD | D38: 8 | E38: SDET / Automation Engineer | F38: TEST | G38: E3 | H38: OFF | I38: FTC | J38: 0 | K38: =J38*7 -> 0
B39: 2 | C39: POD | D39: 9 | E39: MGCC Quality Engineer | F39: TEST | G39: E2 | H39: OFF | I39: MGCC | J39: 0.71428571 | K39: =J39*7 -> 5
B40: 2 | C40: POD | D40: 10 | E40: Solution Architect | F40: OTH | G40: E5 | H40: ON | I40: FTC | J40: 0.71428571 | K40: =J40*7 -> 5
D41: POD size — Year 2 | J41: =SUM(J31:J40) -> 7.1428571
B43: 2 | C43: TEAM | D43: 1 | E43: MetLife Claims Product Owner | F43: PM | G43: E4 | H43: ON | I43: FTE | J43: 0 | K43: =J43*2 -> 0
B44: 2 | C44: TEAM | D44: 2 | E44: MetLife Claims SME | F44: BSA | G44: E4 | H44: ON | I44: FTE | J44: 0 | K44: =J44*2 -> 0
...

Sheet Pod Plan
A1: Pod plan — how many pods and how many waterfall teams, per stream per year
A2: INPUT. This is where productivity shows up in the headcount, and where the agile conversion shows up in the unit mix.
B4: Year | C4: VS | D4: Value stream | E4: Pods | F4: Teams | G4: Units | H4: People
B5: 1 | C5: AMP | D5: Annuity ＆ Maturity Payment | E5: 2 | F5: 3 | G5: =E5+F5 -> 5 | H5: =E5*SUM('Pod Library'!$J$5:$J$14)+F5*SUM('Pod Library'!$J$17:$J$28) -> 57.6
B6: 1 | C6: CPA | D6: Claims Processing & Adjudication | E6: 0 | F6: 2 | G6: =E6+F6 -> 2 | H6: =E6*SUM('Pod Library'!$J$5:$J$14)+F6*SUM('Pod Library'!$J$17:$J$28) -> 30.4
B7: 1 | C7: CSS | D7: Claims Support Services | E7: 2 | F7: 0 | G7: =E7+F7 -> 2 | H7: =E7*SUM('Pod Library'!$J$5:$J$14)+F7*SUM('Pod Library'!$J$17:$J$28) -> 12
D8: Year 1 total | E8: =SUM(E5:E7) -> 4 | F8: =SUM(F5:F7) -> 5 | G8: =SUM(G5:G7) -> 9 | H8: =SUM(H5:H7) -> 100
B10: 2 | C10: AMP | D10: Annuity ＆ Maturity Payment | E10: 4 | F10: 1 | G10: =E10+F10 -> 5 | H10: =E10*SUM('Pod Library'!$J$31:$J$40)+F10*SUM('Pod Library'!$J$43:$J$54) -> 39.321429
B11: 2 | C11: CPA | D11: Claims Processing & Adjudication | E11: 1 | F11: 1 | G11: =E11+F11 -> 2 | H11: =E11*SUM('Pod Library'!$J$31:$J$40)+F11*SUM('Pod Library'!$J$43:$J$54) -> 17.892857
B12: 2 | C12: CSS | D12: Claims Support Services | E12: 2 | F12: 0 | G12: =E12+F12 -> 2 | H12: =E12*SUM('Pod Library'!$J$31:$J$40)+F12*SUM('Pod Library'!$J$43:$J$54) -> 14.285714
D13: Year 2 total | E13: =SUM(E10:E12) -> 7 | F13: =SUM(F10:F12) -> 2 | G13: =SUM(G10:G12) -> 9 | H13: =SUM(H10:H12) -> 71.5
B15: 3 | C15: AMP | D15: Annuity ＆ Maturity Payment | E15: 5 | F15: 0 | G15: =E15+F15 -> 5 | H15: =E15*SUM('Pod Library'!$J$57:$J$66) -> 31.944444
B16: 3 | C16: CPA | D16: Claims Processing & Adjudication | E16: 2 | F16: 0 | G16: =E16+F16 -> 2 | H16: =E16*SUM('Pod Library'!$J$57:$J$66) -> 12.777778
B17: 3 | C17: CSS | D17: Claims Support Services | E17: 2 | F17: 0 | G17: =E17+F17 -> 2 | H17: =E17*SUM('Pod Library'!$J$57:$J$66) -> 12.777778
D18: Year 3 total | E18: =SUM(E15:E17) -> 9 | F18: =SUM(F15:F17) -> 0 | G18: =SUM(G15:G17) -> 9 | H18: =SUM(H15:H17) -> 57.5
B20: 4 | C20: AMP | D20: Annuity ＆ Maturity Payment | E20: 5 | F20: 0 | G20: =E20+F20 -> 5 | H20: =E20*SUM('Pod Library'!$J$69:$J$78) -> 26.666667
B21: 4 | C21: CPA | D21: Claims Processing & Adjudication | E21: 2 | F21: 0 | G21: =E21+F21 -> 2 | H21: =E21*SUM('Pod Library'!$J$69:$J$78) -> 10.666667
B22: 4 | C22: CSS | D22: Claims Support Services | E22: 2 | F22: 0 | G22: =E22+F22 -> 2 | H22: =E22*SUM('Pod Library'!$J$69:$J$78) -> 10.666667
D23: Year 4 total | E23: =SUM(E20:E22) -> 9 | F23: =SUM(F20:F22) -> 0 | G23: =SUM(G20:G22) -> 9 | H23: =SUM(H20:H22) -> 48
B25: 5 | C25: AMP | D25: Annuity ＆ Maturity Payment | E25: 4 | F25: 0 | G25: =E25+F25 -> 4 | H25: =E25*SUM('Pod Library'!$J$81:$J$90) -> 19
B26: 5 | C26: CPA | D26: Claims Processing & Adjudication | E26: 2 | F26: 0 | G26: =E26+F26 -> 2 | H26: =E26*SUM('Pod Library'!$J$81:$J$90) -> 9.5
B27: 5 | C27: CSS | D27: Claims Support Services | E27: 2 | F27: 0 | G27: =E27+F27 -> 2 | H27: =E27*SUM('Pod Library'!$J$81:$J$90) -> 9.5
D28: Year 5 total | E28: =SUM(E25:E27) -> 8 | F28: =SUM(F25:F27) -> 0 | G28: =SUM(G25:G27) -> 8 | H28: =SUM(H25:H27) -> 38

Sheet Horizontal Teams
A1: Horizontal teams — work that is not stream-bounded
A2: INPUT, defined per year rather than scaled, because the partner share and the sourcing mix inside the horizontal layer both change as the estate transitions.
B4: Year | C4: Team | D4: Role | E4: Role detail | F4: Exp | G4: Loc | H4: Sourcing | I4: Count | J4: People in the block
B5: 1 | C5: H1 | D5: PM | E5: Service Delivery Manager | F5: E5 | G5: ON | H5: FTC | I5: 1 | J5: =I5 -> 1
B6: 1 | C6: H1 | D6: MNT | E6: Incident & Problem Analyst | F6: E3 | G6: ON | H6: FTC | I6: 2 | J6: =I6 -> 2
B7: 1 | C7: H1 | D7: MNT | E7: L2 Application Support | F7: E2 | G7: OFF | H7: FTC | I7: 0.5 | J7: =I7 -> 0.5
B8: 1 | C8: H1 | D8: MNT | E8: L2 Application Support | F8: E2 | G8: NEAR | H8: FTC | I8: 0.5 | J8: =I8 -> 0.5
B9: 1 | C9: H1 | D9: OTH | E9: Observability / AIOps Engineer | F9: E3 | G9: OFF | H9: FTC | I9: 0.5 | J9: =I9 -> 0.5
B10: 1 | C10: H1 | D10: MNT | E10: MetLife Operations Lead | F10: E4 | G10: ON | H10: FTE | I10: 2.5 | J10: =I10 -> 2.5
B11: 1 | C11: H2 | D11: TEST | E11: Quality Lead | F11: E4 | G11: ON | H11: FTC | I11: 0.5 | J11: =I11 -> 0.5
B12: 1 | C12: H2 | D12: TEST | E12: Test Automation Engineer | F12: E3 | G12: OFF | H12: FTC | I12: 0.5 | J12: =I12 -> 0.5
B13: 1 | C13: H2 | D13: TEST | E13: Performance & Batch Test Engineer | F13: E3 | G13: OFF | H13: FTC | I13: 0.5 | J13: =I13 -> 0.5
B14: 1 | C14: H2 | D14: TEST | E14: MGCC Quality Engineer | F14: E2 | G14: OFF | H14: MGCC | I14: 3 | J14: =I14 -> 3
B15: 1 | C15: H2 | D15: BSA | E15: Payments Assurance Analyst | F15: E3 | G15: ON | H15: FTC | I15: 1.5 | J15: =I15 -> 1.5
B16: 1 | C16: H3 | D16: OTH | E16: Domain Solution Architect | F16: E5 | G16: ON | H16: FTC | I16: 0.5 | J16: =I16 -> 0.5
... B23: 1 | C23: H3 | D23: DEV | E23: MGCC Engineering Lead | F23: E4 | G23: OFF | H23: MGCC | I23: 1.5 | J23: =I23 -> 1.5
E24: Year 1 horizontal total | I24: =SUM(I5:I23) -> 21.5
B26: 2 | C26: H1 | D26: PM | E26: Service Delivery Manager | F26: E5 | G26: ON | H26: FTC | I26: 0.5 | J26: =I26 -> 0.5
B27: 2 | C27: H1 | D27: MNT | E27: Incident & Problem Analyst | F27: E3 | G27: ON | H27: FTC | I27: 1 | J27: =I27 -> 1
B28: 2 | C28: H1 | D28: MNT | E28: L2 Application Support | F28: E2 | G28: OFF | H28: FTC | I28: 0.5 | J28: =I28 -> 0.5
B29: 2 | C29: H1 | D29: MNT | E29: L2 Application Support | F29: E2 | G29: NEAR | H29: FTC | I29: 0.5 | J29: =I29 -> 0.5
B30: 2 | C30: H1 | D30: OTH | E30: Observability / AIOps Engineer | F30: E3 | G30: OFF | H30: FTC | I30: 1.5 | J30: =I30 -> 1.5
B31: 2 | C31: H1 | D31: MNT | E31: MetLife Operations Lead | F31: E4 | G31: ON | H31: FTE | I31: 2 | J31: =I31 -> 2
B32: 2 | C32: H2 | D32: TEST | E32: Quality Lead | F32: E4 | G32: ON | H32: FTC | I32: 1.5 | J32: =I32 -> 1.5
B33: 2 | C33: H2 | D33: TEST | E33: Test Automation Engineer | F33: E3 | G33: OFF | H33: FTC | I33: 2 | J33: =I33 -> 2
B34: 2 | C34: H2 | D34: TEST | E34: Performance & Batch Test Engineer | F34: E3 | G34: OFF | H34: FTC | I34: 0.5 | J34: =I34 -> 0.5
B35: 2 | C35: H2 | D35: TEST | E35: MGCC Quality Engineer | F35: E2 | G35: OFF | H35: MGCC | I35: 2 | J35: =I35 -> 2
B36: 2 | C36: H2 | D36: BSA | E36: Payments Assurance Analyst | F36: E3 | G36: ON | H36: FTC | I36: 2 | J36: =I36 -> 2
B37: 2 | C37: H3 | D37: OTH | E37: Domain Solution Architect | F37: E5 | G37: ON | H37: FTC | I37: 0.5 | J37: =I37 -> 0.5
... B44: 2 | C44: H3 | D44: DEV | E44: MGCC Engineering Lead | F44: E4 | G44: OFF | H44: MGCC | I44: 0.5 | J44: =I44 -> 0.5
E45: Year 2 horizontal total | I45: =SUM(I26:I44) -> 22
B47: 3 | C47: H1 | D47: PM | E47: Service Delivery Manager | F47: E5 | G47: ON | H47: FTC | I47: 0.5 | J47: =I47 -> 0.5
B48: 3 | C48: H1 | D48: MNT | E48: Incident & Problem Analyst | F48: E3 | G48: ON | H48: FTC | I48: 0.5 | J48: =I48 -> 0.5
B49: 3 | C49: H1 | D49: MNT | E49: L2 Application Support | F49: E2 | G49: OFF | H49: FTC | I49: 2.5 | J49: =I49 -> 2.5
B50: 3 | C50: H1 | D50: MNT | E50: L2 Application Support | F50: E2 | G50: NEAR | H50: FTC | I50: 1 | J50: =I50 -> 1
B51: 3 | C51: H1 | D51: OTH | E51: Observability / AIOps Engineer | F51: E3 | G51: OFF | H51: FTC | I51: 1.5 | J51: =I51 -> 1.5
B52: 3 | C52: H1 | D52: MNT | E52: MetLife Operations Lead | F52: E4 | G52: ON | H52: FTE | I52: 0.5 | J52: =I52 -> 0.5
B53: 3 | C53: H2 | D53: TEST | E53: Quality Lead | F53: E4 | G53: ON | H53: FTC | I53: 1 | J53: =I53 -> 1
B54: 3 | C54: H2 | D54: TEST | E54: Test Automation Engineer | F54: E3 | G54: OFF | H54: FTC | I54: 0.5 | J54: =I54 -> 0.5
B55: 3 | C55: H2 | D55: TEST | E55: Performance & Batch Test Engineer | F55: E3 | G55: OFF | H55: FTC | I55: 0.5 | J55: =I55 -> 0.5
...

Sheet Team Build-Up
A1: Team build-up — and the Year-1 reconciliation to Appendix 3 v5
A2: Nothing on this sheet is typed. Section B is the test that matters: the roster has to be the client's own Year-1 position on effort, sourcing, location AND role.
A4: A. HEADCOUNT
B5: Measure | C5: Year 1 | D5: Year 2 | E5: Year 3 | F5: Year 4 | G5: Year 5
B6: People in agile pods | C6: =SUMIFS('Seat Ledger'!$M$5:$M$287,'Seat Ledger'!$B$5:$B$287,1,'Seat Ledger'!$C$5:$C$287,"POD") -> 24 | D6: =SUMIFS('Seat Ledger'!$M$5:$M$287,'Seat Ledger'!$B$5:$B$287,2,'Seat Ledger'!$C$5:$C$287,"POD") -> 50 | E6: =SUMIFS('Seat Ledger'!$M$5:$M$287,'Seat Ledger'!$B$5:$B$287,3,'Seat Ledger'!$C$5:$C$287,"POD") -> 57.5 | F6: =SUMIFS('Seat Ledger'!$M$5:$M$287,'Seat Ledger'!$B$5:$B$287,4,'Seat Ledger'!$C$5:$C$287,"POD") -> 48 | G6: =SUMIFS('Seat Ledger'!$M$5:$M$287,'Seat Ledger'!$B$5:$B$287,5,'Seat Ledger'!$C$5:$C$287,"POD") -> 38
