Workbook

Sheet README
A1: Insurance Claims and Benefits Payment Related — domain framework v2
A2: Six applications, 121.573 units, and the only 領域 in the estate whose SCOPE CHANGES inside the five years. C12WNC-JPN (POS Workflow) is marked Retire and is 28.8% of the domain; from Year 4 the baseline is 86.577 units. Pega for Claims and MDRS are both Maintain in target state — the earlier claim that they carry a zero Year-3 target was wrong. Two value streams: the Claims Platform runs as an agile pod from day one; Payment & Records runs as a 12-seat team until POS Workflow goes, then converts to pods.
A4: WHAT THIS 領域 IS
B5: Six applications, three archetypes | C5: OpenBatch 43.8 units, POS Workflow 35.0 and Pega 16.7 are archetype D at a 78% offshore ceiling; Annuity Info 22.0 is Japan-locked at 12%; MDRS and My Number are 4.1 units of long tail at 55%.
B6: It splits into a platform and a records estate | C6: VS1 — Pega (SaaS on Pega Cloud, no-code, 99% AD) plus OpenBatch (cloud-flagged, hybrid) — is 60.5 units and holds ALL 22.6 of the domain’s MGCC. VS2 is four Japanese-specification applications, one of them retiring.
B7: The only 領域 with material nearshore | C7: 9.589 units on C12WNC-JPN — roughly half of all the nearshore capacity in the portfolio. Every other 領域 modelled is Tokyo-and-India only. The NEAR rows in this workbook are live, not schema.
B8: FSI holds four applications | C8: 7.0 of the 85.449 vendor units — 8.2%. POS Workflow (9835) 2 · Annuity Info (9857) 2 · OpenBatch (13820) 2 · Pega (14322) 1. Taper 7 / 7 / 7 / 5 / 4, onshore Japan in every year, all inside the streams.
A9: C12WNC-JPN, 35.0 units and the only nearshore capacity in the portfolio at 9.589 units. The baseline drops to 86.577 from Year 4 and nearshore goes to zero with it.
B10: C12WNC-JPN is marked RETIRE, and it is 28.8% of the domain | C10: 35.0 units, business-critical, Japanese specifications, 9.6 units nearshore, and the entire Claims Processing ＆ Adjudication value stream. This model freezes scope at Year 1 as every domain model does, so that exposure is carried, not netted. It is the largest single disposition exposure in the estate and it has to be resolved with MetLife before the price is fixed.
B11: Offshore reaches the re-cut ceiling | C11: 30.0% today — the highest starting position in the estate, because MGCC is 22.6 units on day one. The design delivers 31.3 / 40.7 / 49.0 / 53.4 / 59.8% against a ceiling that re-cuts from 65.27% to 60.13% when POS Workflow leaves. Year 5 lands on it.
B12: The 50:50 closes with NO transfer | C12: Organic convergence alone takes Capgemini from 70.4% of the delivery population to 50.6% by Year 5. The transfer mechanic is left live but set to zero in every year.
A13: 0 / 22.3 / 35.5 / 40.5 / 49.9%, measured against the scope that remains — not against the frozen 121.573, which would read 64.3% and would be claiming MetLife’s retirement as our saving.
B14: MGCC has a HIGHER ceiling than we do here | C14: MGCC 48.60% against Capgemini 44.73%, because MGCC is a build-and-test population and 78.5% of this estate is archetype D — where Build and Test ceilings are the highest in the classifier. Adoption still puts us ahead on committed productivity (44.7% against 38.9% effective), but the underlying capability runs the other way. Worth saying out loud.
B15: The transfer is 11.6 people, and most of it goes to MetLife Japan | C15: Organic convergence only takes the ratio from 70.3% to 66.8% by Year 3 — MetLife's side is small and shrinks slowly. The transfer does the rest. We send 6.4 to MetLife Japan and 5.2 to MGCC rather than the portfolio default 35/65, because 84% of the Capgemini population is in Tokyo and people in Tokyo are re-badged to MetLife Japan.
B16: Headcount 121.6 → 59.3 | C16: Pod Library column K and Horizontal Teams column J are the people you hire for that role across the block. Every one is a whole number or a half — the grid check is clean in all five years. SIT Loading turns them into requisitions.
A17: THE ENGINE
B18: The role line is restated, heavily | C18: Appendix 3 records 82.9% of the vendor line as Developer, 1.00 unit of maintenance, ZERO project management and 0.775 of architecture, against 732 incidents, 1,161 changes and 439 batch jobs a year. We move 20.4 units out of Developer into BSA, Tester, Maintenance, PM and Other. Arithmetically neutral, and the largest restatement in the portfolio. It is the only red on the Change Control sheet.
B19: The Year-4 cliff is scope, not delivery | C19: Headcount falls 78.5 to 51.5 between Years 3 and 4. About 24 of those 27 people are POS Workflow retiring; roughly 3 are productivity. Year 4 pre-loads none of its own in-year gain for exactly that reason.
A20: Every Capgemini role runs across the years it exists with no gaps and no re-banding — a grade is fixed for the life of the seat. Each unit keeps a lead, a bilingual analyst, a tester and a support seat in every year; design authority moves to the horizontal layer in Year 4 when pods shrink to six. Testers and junior builders are E1/E2 and E1 seats exist in all five years.
B21: The role line needs the largest restatement in the estate | C21: Appendix 3 records ZERO project management and 1.00 maintenance unit across six applications carrying 732 incidents and 1,161 changes. 83% of the vendor population is booked as Developer. Restated to 4.50 maintenance, 3.50 PM and 2.50 architecture, taken from the developer line. Arithmetically neutral; MetLife should confirm.
B22: And MetLife's two views of run disagree by a factor of seven | C22: The maintenance role line says 1.00 unit. The AD / AMS effort split in the same spreadsheet implies 6.75. On a 122-person domain that is about six people of exposure, and it sets the AMS price.
B23: The disposition questions are the priority | C23: 44.3% of this 領域 is either marked Retire or carries a zero Year-3 target in MetLife's own model. No other 領域 comes close. Resolve before submission.

Sheet Basis & Assumptions
A1: Where every input comes from, and which ones are ours
A2: v2. Two value streams, a scope that drops 28.8% at Year 4, and 7 FSI seats introduced where v1 modelled no partner. What matters here is the provenance of each input: which are measured, which are restated, and which are domain overrides.
B4: Element | C4: Source | D4: Value used | E4: Status | F4: Note
B5: Baseline | C5: Appendix 3 v5, 6 applications | D5: effort 121.574 · FTC 85.449 · FTE 13.479 · MGCC 22.646 · onshore 71.626 · offshore 4.233 · nearshore 9.589 | E5: SOURCE | F5: Internally consistent: FTC + FTE + MGCC ties exactly to Total, and the three location lines tie exactly to FTC. No unallocated capacity to carry.
B6: Archetypes | C6: Golden Inventory v4, six-rule classifier | D6: D 3 / 95.479 · J 1 / 22.028 · T 2 / 4.067 | E6: SOURCE | F6: AI ceiling 44.71%, offshore ceiling 65.27%. Archetype D is 78.5% of the effort, which is what makes the productivity case; W05AMS-JPN at a 12% offshore ceiling is what caps the location case.
B7: Delivery method | C7: Appendix 3 v5 | D7: VS1 agile from Year 1; VS2 waterfall to Year 3, pods from Year 4 | E7: MEASURED | F7: Holding Payment & Records as a team to Year 3 caps the agile share at 49.7% and costs about 0.6 and 1.9 points of Year-2 and Year-3 capability. It is the conservative reading of a stream whose largest application is being retired.
B8: Adoption factors | C8: Portfolio default | D8: 1.00 / 0.85 / 0.55 / 0.80 — unchanged | E8: STANDARD | F8: No case for raising MetLife's commitment here. Unlike Common Service Platform this is a mostly waterfall, Japanese-specification estate, and MetLife's own staff are only 11.1% of it.
B9: Role line | C9: BSA 5.958 · DEV 70.899 · TEST 6.817 · MNT 1.000 · PM 0.000 · OTH 0.775 | D9: MNT 4.50 · PM 3.50 · OTH 2.50, taken from DEV | E9: RESTATED | F9: ZERO project management across six applications and three value streams, and 1.00 maintenance unit against 732 incidents and 1,161 changes. 83% of the vendor population booked as Developer — the highest in the estate. Arithmetically neutral; the total does not move.
B10: Partner | C10: FSI named FTC supplied by MetLife against four EAI IDs | D10: 7.000 of 85.449 vendor units — 8.2% | E10: DOMAIN DECISION | F10: v1 modelled no partner at all. Introducing 7 FSI splits the Year-1 vendor number into Capgemini 78.5 + FSI 7.0 and switches on the span-of-control drag. Onshore Japan in every year; taper 7 / 7 / 7 / 5 / 4.
B11: Transfer split | C11: Portfolio default 35% to MetLife Japan | D11: 55% to MetLife Japan · 45% to MGCC | E11: DOMAIN OVERRIDE | F11: 71.6 of 85.4 vendor units are in Tokyo — 84%, the most onshore-weighted Capgemini population of the 領域 modelled. The default assumes an offshore-weighted population being re-badged mostly into MGCC. Here that is backwards: people in Tokyo are re-badged to MetLife Japan.
B12: Disposition | C12: EA inventory v5, target-state columns | D12: C12WNC-JPN RETIRE — 34.997 units. Pega and MDRS Maintain. | E12: SOURCE | F12: ACTED ON, unlike v1. The baseline drops to 86.577 from Year 4 and the archetype ceilings re-cut with it. Pega (Maintain — Evolve, Year-3 target 8.4) and MDRS (Maintain — Patch, 1.1) are NOT under a disposition question; the v1 claim that they carry a zero Year-3 target was wrong.
B13: Disposition | C13: New in Appendix 3 v5 | D13: 50% vendor share · 55% per unit · 55% of build-and-test · continuous role coverage | E13: NEW | F13: All held in every year. Tightest single unit 58.3%; tightest build-and-test 56.0% in Year 4, held above the floor by growing the MGCC Application Support line in the horizontal layer from 0.5 to 7.5.
B14: Guardrails | C14: Portfolio standard | D14: ZERO — organic convergence reaches 50.6% on its own | E14: STANDARD | F14: The mechanic is live so a transfer can be priced if MetLife asks, but none is needed.
B15: Scope treatment | C15: Domain override, v2 | D15: Productivity measured on RETAINED scope | E15: DOMAIN OVERRIDE | F15: Year-5 commitment 49.9% on 86.577 units. On the frozen 121.573 baseline the same roster reads 64.3%, and the difference is MetLife’s retirement. Reporting the lower number is the defensible choice.
A17: HOW TO READ THE STATUS COLUMN
B18: • SOURCE — taken directly from Appendix 3 v5 or Golden Application Inventory v4. Not ours to change.
B19: • MEASURED — MetLife has supplied it and we use it as given, where an earlier version made us assume.
B20: • RESTATED — the client figure is internally impossible and we have changed it. Every restatement is arithmetically neutral: people move between role lines, the total does not. These go back to MetLife.
B21: • DOMAIN OVERRIDE — a portfolio default deliberately changed for this 領域, with the reason stated. These are solution decisions and should be defended as such in the review.
B22: • MODELLED — a construct of ours with no direct client source: partner plans, transfer sizing, conversion quarters. The assumptions most worth challenging.

Sheet Change Control
A1: Change control — what must still hold after you edit a seat count
A2: Pod Library column J and Horizontal Teams column I are INPUTS. You may change them. Holding the yearly total is necessary but not sufficient — these are the other things that have to survive the edit. Every check below is live. Note that the headcount target is measured against the SCOPE BASELINE on Logic Tree row 46, which drops from 121.573 to 86.577 in Year 4 when POS Workflow retires.
A4: A. WHERE THESE NUMBERS GO
B5: • Pod Library J and Horizontal Teams I are hard-typed values, not formulas. Nothing upstream computes them — they are the design. Everything downstream is derived from them.
B6: • Seat Ledger reads them cell by cell (912 references to Pod Library, 630 to Horizontal Teams) and multiplies by the unit count on Pod Plan. Team Build-Up, Cost & Commercial, Inherited Workforce and Unit Cost Sensitivity are all SUMIFS over the Seat Ledger. Change a seat and every one of them moves.
B7: • THE ONE THAT SURPRISES PEOPLE: the Logic Tree reads the roster back. Partner seats (row 59) drive the partner share (row 60), the span-of-control factor (row 61), the applied operating-model gain (row 43), capability (row 45) and therefore the HEADCOUNT TARGET itself (row 53). Changing partner seats moves the target you are trying to hit. It converges, but it does not stand still.
B8: • What does NOT move: the effort baseline, the archetype mix, the AI and offshore ceilings, the realisation curve and the agile conversion quarters. Those are inputs on the Logic Tree and Delivery Mode.
A10: B. THE INVARIANTS — all of these must stay green
B11: Check | C11: Y1 | D11: Y2 | E11: Y3 | F11: Y4 | G11: Y5 | H11: Tolerance | I11: Status
B12: Headcount delivered minus Logic Tree target | C12: ='Team Build-Up'!C12 | D12: ='Team Build-Up'!D12 | E12: ='Team Build-Up'!E12 | F12: ='Team Build-Up'!F12 | G12: ='Team Build-Up'!G12 | H12: ± 1.5 | I12: =IF(MAX(ABS(C12),ABS(D12),ABS(E12),ABS(F12),ABS(G12))<=1.5,"OK","CHECK") | J12: The productivity commitment. If you add seats you must remove others.
B13: Capgemini share inside each POD | C13: =IFERROR((SUMIFS('Pod Library'!$J$5:$J$170,'Pod Library'!$B$5:$B$170,1,'Pod Library'!$C$5:$C$170,"POD",'Pod Library'!$I$5:$I$170,"FTC")+SUMIFS('Pod Library'!$J$5:$J$170,'Pod Library'!$B$5:$B$170,1,'Pod Library'!$C$5:$C$170,"POD",'Pod Library'!$I$5:$I$170,"PT"))/(SUMIFS('Pod Library'!$J$5:$J$170,'Pod Library'!$B$5:$B$170,1,'Pod Library'!$C$5:$C$170,"POD")),"n/a") | D13: =IFERROR((SUMIFS('Pod Library'!$J$5:$J$170,'Pod Library'!$B$5:$B$170,2,'Pod Library'!$C$5:$C$170,"POD",'Pod Library'!$I$5:$I$170,"FTC")+SUMIFS('Pod Library'!$J$5:$J$170,'Pod Library'!$B$5:$B$170,2,'Pod Library'!$C$5:$C$170,"POD",'Pod Library'!$I$5:$I$170,"PT"))/(SUMIFS('Pod Library'!$J$5:$J$170,'Pod Library'!$B$5:$B$170,2,'Pod Library'!$C$5:$C$170,"POD")),"n/a") | E13: =IFERROR((SUMIFS('Pod Library'!$J$5:$J$170,'Pod Library'!$B$5:$B$170,3,'Pod Library'!$C$5:$C$170,"POD",'Pod Library'!$I$5:$I$170,"FTC")+SUMIFS('Pod Library'!$J$5:$J$170,'Pod Library'!$B$5:$B$170,3,'Pod Library'!$C$5:$C$170,"POD",'Pod Library'!$I$5:$I$170,"PT"))/(SUMIFS('Pod Library'!$J$5:$J$170,'Pod Library'!$B$5:$B$170,3,'Pod Library'!$C$5:$C$170,"POD")),"n/a") | F13: =IFERROR((SUMIFS('Pod Library'!$J$5:$J$170,'Pod Library'!$B$5:$B$170,4,'Pod Library'!$C$5:$C$170,"POD",'Pod Library'!$I$5:$I$170,"FTC")+SUMIFS('Pod Library'!$J$5:$J$170,'Pod Library'!$B$5:$B$170,4,'Pod Library'!$C$5:$C$170,"POD",'Pod Library'!$I$5:$I$170,"PT"))/(SUMIFS('Pod Library'!$J$5:$J$170,'Pod Library'!$B$5:$B$170,4,'Pod Library'!$C$5:$C$170,"POD")),"n/a") | G13: =IFERROR((SUMIFS('Pod Library'!$J$5:$J$170,'Pod Library'!$B$5:$B$170,5,'Pod Library'!$C$5:$C$170,"POD",'Pod Library'!$I$5:$I$170,"FTC")+SUMIFS('Pod Library'!$J$5:$J$170,'Pod Library'!$B$5:$B$170,5,'Pod Library'!$C$5:$C$170,"POD",'Pod Library'!$I$5:$I$170,"PT"))/(SUMIFS('Pod Library'!$J$5:$J$170,'Pod Library'!$B$5:$B$170,5,'Pod Library'!$C$5:$C$170,"POD")),"n/a") | H13: ≥ 55% | I13: =IF(COUNTIF(C13:G13,"<0.5450")=0,"OK","CHECK") | J13: A POD in which Capgemini is a minority is one whose ways of working we do not set.
B14: Capgemini share inside each TEAM | C14: =IFERROR((SUMIFS('Pod Library'!$J$5:$J$170,'Pod Library'!$B$5:$B$170,1,'Pod Library'!$C$5:$C$170,"TEAM",'Pod Library'!$I$5:$I$170,"FTC")+SUMIFS('Pod Library'!$J$5:$J$170,'Pod Library'!$B$5:$B$170,1,'Pod Library'!$C$5:$C$170,"TEAM",'Pod Library'!$I$5:$I$170,"PT"))/(SUMIFS('Pod Library'!$J$5:$J$170,'Pod Library'!$B$5:$B$170,1,'Pod Library'!$C$5:$C$170,"TEAM")),"n/a") | D14: =IFERROR((SUMIFS('Pod Library'!$J$5:$J$170,'Pod Library'!$B$5:$B$170,2,'Pod Library'!$C$5:$C$170,"TEAM",'Pod Library'!$I$5:$I$170,"FTC")+SUMIFS('Pod Library'!$J$5:$J$170,'Pod Library'!$B$5:$B$170,2,'Pod Library'!$C$5:$C$170,"TEAM",'Pod Library'!$I$5:$I$170,"PT"))/(SUMIFS('Pod Library'!$J$5:$J$170,'Pod Library'!$B$5:$B$170,2,'Pod Library'!$C$5:$C$170,"TEAM")),"n/a") | E14: =IFERROR((SUMIFS('Pod Library'!$J$5:$J$170,'Pod Library'!$B$5:$B$170,3,'Pod Library'!$C$5:$C$170,"TEAM",'Pod Library'!$I$5:$I$170,"FTC")+SUMIFS('Pod Library'!$J$5:$J$170,'Pod Library'!$B$5:$B$170,3,'Pod Library'!$C$5:$C$170,"TEAM",'Pod Library'!$I$5:$I$170,"PT"))/(SUMIFS('Pod Library'!$J$5:$J$170,'Pod Library'!$B$5:$B$170,3,'Pod Library'!$C$5:$C$170,"TEAM")),"n/a") | F14: =IFERROR((SUMIFS('Pod Library'!$J$5:$J$170,'Pod Library'!$B$5:$B$170,4,'Pod Library'!$C$5:$C$170,"TEAM",'Pod Library'!$I$5:$I$170,"FTC")+SUMIFS('Pod Library'!$J$5:$J$170,'Pod Library'!$B$5:$B$170,4,'Pod Library'!$C$5:$C$170,"TEAM",'Pod Library'!$I$5:$I$170,"PT"))/(SUMIFS('Pod Library'!$J$5:$J$170,'Pod Library'!$B$5:$B$170,4,'Pod Library'!$C$5:$C$170,"TEAM")),"n/a") | G14: =IFERROR((SUMIFS('Pod Library'!$J$5:$J$170,'Pod Library'!$B$5:$B$170,5,'Pod Library'!$C$5:$C$170,"TEAM",'Pod Library'!$I$5:$I$170,"FTC")+SUMIFS('Pod Library'!$J$5:$J$170,'Pod Library'!$B$5:$B$170,5,'Pod Library'!$C$5:$C$170,"TEAM",'Pod Library'!$I$5:$I$170,"PT"))/(SUMIFS('Pod Library'!$J$5:$J$170,'Pod Library'!$B$5:$B$170,5,'Pod Library'!$C$5:$C$170,"TEAM")),"n/a") | H14: ≥ 55% | I14: =IF(COUNTIF(C14:G14,"<0.5450")=0,"OK","CHECK") | J14: A TEAM in which Capgemini is a minority is one whose ways of working we do not set. VS2 runs as a team only in Years 1-3, at 91.7% / 91.7% / 91.7%. The POD row covers VS1 in all five years and VS2 from Year 4; the tightest single unit in any year is 58.3%.
B15: Capgemini share of the delivery population | C15: =IFERROR((SUMIFS('Seat Ledger'!$M$5:$M$287,'Seat Ledger'!$B$5:$B$287,1,'Seat Ledger'!$J$5:$J$287,"FTC")+SUMIFS('Seat Ledger'!$M$5:$M$287,'Seat Ledger'!$B$5:$B$287,1,'Seat Ledger'!$J$5:$J$287,"PT"))/(SUMIFS('Seat Ledger'!$M$5:$M$287,'Seat Ledger'!$B$5:$B$287,1)),0) | D15: =IFERROR((SUMIFS('Seat Ledger'!$M$5:$M$287,'Seat Ledger'!$B$5:$B$287,2,'Seat Ledger'!$J$5:$J$287,"FTC")+SUMIFS('Seat Ledger'!$M$5:$M$287,'Seat Ledger'!$B$5:$B$287,2,'Seat Ledger'!$J$5:$J$287,"PT"))/(SUMIFS('Seat Ledger'!$M$5:$M$287,'Seat Ledger'!$B$5:$B$287,2)),0) | E15: =IFERROR((SUMIFS('Seat Ledger'!$M$5:$M$287,'Seat Ledger'!$B$5:$B$287,3,'Seat Ledger'!$J$5:$J$287,"FTC")+SUMIFS('Seat Ledger'!$M$5:$M$287,'Seat Ledger'!$B$5:$B$287,3,'Seat Ledger'!$J$5:$J$287,"PT"))/(SUMIFS('Seat Ledger'!$M$5:$M$287,'Seat Ledger'!$B$5:$B$287,3)),0) | F15: =IFERROR((SUMIFS('Seat Ledger'!$M$5:$M$287,'Seat Ledger'!$B$5:$B$287,4,'Seat Ledger'!$J$5:$J$287,"FTC")+SUMIFS('Seat Ledger'!$M$5:$M$287,'Seat Ledger'!$B$5:$B$287,4,'Seat Ledger'!$J$5:$J$287,"PT"))/(SUMIFS('Seat Ledger'!$M$5:$M$287,'Seat Ledger'!$B$5:$B$287,4)),0) | G15: =IFERROR((SUMIFS('Seat Ledger'!$M$5:$M$287,'Seat Ledger'!$B$5:$B$287,5,'Seat Ledger'!$J$5:$J$287,"FTC")+SUMIFS('Seat Ledger'!$M$5:$M$287,'Seat Ledger'!$B$5:$B$287,5,'Seat Ledger'!$J$5:$J$287,"PT"))/(SUMIFS('Seat Ledger'!$M$5:$M$287,'Seat Ledger'!$B$5:$B$287,5)),0) | H15: ≥ 50% | I15: =IF(COUNTIF(C15:G15,"<0.4950")=0,"OK","CHECK") | J15: Below half the roster we cannot carry a productivity commitment we do not control.
B16: Blocks deploying a non-whole number of people | C16: =SUMPRODUCT(('Pod Library'!$B$5:$B$170=1)*(ABS('Pod Library'!$K$5:$K$170*2-ROUND('Pod Library'!$K$5:$K$170*2,0))>0.01))+SUMPRODUCT(('Horizontal Teams'!$B$5:$B$95=1)*(ABS('Horizontal Teams'!$J$5:$J$95*2-ROUND('Horizontal Teams'!$J$5:$J$95*2,0))>0.01)) | D16: =SUMPRODUCT(('Pod Library'!$B$5:$B$170=2)*(ABS('Pod Library'!$K$5:$K$170*2-ROUND('Pod Library'!$K$5:$K$170*2,0))>0.01))+SUMPRODUCT(('Horizontal Teams'!$B$5:$B$95=2)*(ABS('Horizontal Teams'!$J$5:$J$95*2-ROUND('Horizontal Teams'!$J$5:$J$95*2,0))>0.01)) | E16: =SUMPRODUCT(('Pod Library'!$B$5:$B$170=3)*(ABS('Pod Library'!$K$5:$K$170*2-ROUND('Pod Library'!$K$5:$K$170*2,0))>0.01))+SUMPRODUCT(('Horizontal Teams'!$B$5:$B$95=3)*(ABS('Horizontal Teams'!$J$5:$J$95*2-ROUND('Horizontal Teams'!$J$5:$J$95*2,0))>0.01)) | F16: =SUMPRODUCT(('Pod Library'!$B$5:$B$170=4)*(ABS('Pod Library'!$K$5:$K$170*2-ROUND('Pod Library'!$K$5:$K$170*2,0))>0.01))+SUMPRODUCT(('Horizontal Teams'!$B$5:$B$95=4)*(ABS('Horizontal Teams'!$J$5:$J$95*2-ROUND('Horizontal Teams'!$J$5:$J$95*2,0))>0.01)) | G16: =SUMPRODUCT(('Pod Library'!$B$5:$B$170=5)*(ABS('Pod Library'!$K$5:$K$170*2-ROUND('Pod Library'!$K$5:$K$170*2,0))>0.01))+SUMPRODUCT(('Horizontal Teams'!$B$5:$B$95=5)*(ABS('Horizontal Teams'!$J$5:$J$95*2-ROUND('Horizontal Teams'!$J$5:$J$95*2,0))>0.01)) | H16: =0 | I16: =IF(SUM(C16:G16)=0,"OK","CHECK") | J16: Column K of the Pod Library and column J of Horizontal Teams are the people you hire for that role across the whole block. Every one is a whole number, or a half where one person covers two units INSIDE this domain. The seat ratio beside it is the modelling quantity and will not always be round — on a 28-team block, nine engineers is a ratio of 0.32.
B17: Horizontal roles that have fallen below 0.02 FTE | C17: =COUNTIFS('Horizontal Teams'!$B$5:$B$95,1,'Horizontal Teams'!$I$5:$I$95,"<0.02") | D17: =COUNTIFS('Horizontal Teams'!$B$5:$B$95,2,'Horizontal Teams'!$I$5:$I$95,"<0.02") | E17: =COUNTIFS('Horizontal Teams'!$B$5:$B$95,3,'Horizontal Teams'!$I$5:$I$95,"<0.02") | F17: =COUNTIFS('Horizontal Teams'!$B$5:$B$95,4,'Horizontal Teams'!$I$5:$I$95,"<0.02") | G17: =COUNTIFS('Horizontal Teams'!$B$5:$B$95,5,'Horizontal Teams'!$I$5:$I$95,"<0.02") | H17: =0 | I17: =IF(SUM(C17:G17)=0,"OK","CHECK") | J17: A domain cannot run without a delivery head, a service manager or an architect. If a role must genuinely end, delete the row rather than leaving it at zero.
B18: Year-1 reconciliation to Appendix 3 — worst line | C18: ='Team Build-Up'!E32 | H18: ± 2.6 | I18: =IF(ABS(C18)<=2.6,"OK","CHECK") | J18: Year 1 must reproduce the client's own numbers: effort, the sourcing split, all three locations and all six role lines. The tolerance is ± 2.6 because seats sit on a 0.5 grid and a Year-1 team seat carries a multiplier of 5 — one grid step is 2.5 people. That is the deliberate price of an anatomy that can be staffed. Moving a seat between bands is free; moving it between ROLE, LOCATION or SOURCING is what actually breaks this.
A20: C. WHAT GOES STALE AND WILL NOT WARN YOU
B21: • SOURCING & PRODUCTIVITY is static. It is produced outside Excel by the per-sourcing solver and pasted in. If you change seat counts, the pool ceilings, the organic-convergence table and the transfer solve on that sheet no longer describe this roster. Re-run the solver or treat the sheet as superseded.
B22: • SIT LOADING is static for the same reason. Re-generate it after any seat change, or the requisition plan will not match the ledger.
B23: • The TRANSFER on the Logic Tree is a typed input (rows 65-66), sized on the Year-3 exit position produced by the solver. Change the Year-3 roster materially and the transfer needs re-sizing, or the 50:50 will not land.
B24: • THE RULE OF THUMB. Re-banding a seat, renaming it, or moving it between pods is safe. Changing its ROLE, LOCATION or SOURCING is not — those are the attributes Year 1 reconciles on and the guardrails measure.

Sheet Logic Tree
A1: Logic Tree — ten parametric drivers, five years
A2: Amber cells are inputs. Everything else re-derives. Section F is rebuilt on the measured day-1 position.
A4: A. BASELINE — Appendix 3 v5, read and never edited
B5: Domain | C5: Insurance Claims and Benefits Payment Related
B6: Applications | C6: 6
B7: Total effort (units) | C7: 121.5735
B8: Current FTC reported (Capgemini + partner) | C8: 85.4485
B9: Current FTE | C9: 13.4792
B10: Current MGCC | C10: 22.6458
B11: — of which onshore Tokyo | C11: 71.6261 | J11: 28.87 offshore, 15.99 MGCC and 0.96 nearshore against 35.55 onshore. This domain already delivers most of its work away from Tokyo.
B12: — of which offshore | C12: 4.2333
B13: — of which nearshore | C13: 9.589
B14: — of which onsite | C14: 0
B15: Role: BSA | C15: 5.9583
B16: Role: Developer | C16: 70.8985 | J16: All six role lines are populated for this domain and are used exactly as reported. No restatement was needed.
B17: Role: Tester | C17: 6.8167
B18: Role: Maintenance | C18: 1
B19: Role: PM | C19: 0
B20: Role: Other | C20: 0.775
B21: AD effort (% of PRJ weighted) | C21: 114.8276
B22: Appendix 3 Year-3 target, each side | C22: 60.7868
B23: Ratio today — Capgemini share | C23: =C8/(C8+C9+C10)
B24: OFFSHORE TODAY — whole team, measured | C24: =(C12+C13+C10)/C7 | J24: 45.5% on day one — 28.87 offshore, 0.96 nearshore and 15.99 MGCC. The highest starting position of the eleven domains, which is why the ceiling here is reachable rather than aspirational.
A26: B. ARCHETYPE MIX — from the Golden Application Inventory v4
B27: Archetype | C27: Name | D27: Apps | E27: Effort | F27: Share | G27: AI ceiling | H27: Offshore ceiling
B28: D | C28: Distributed-proven | D28: 3 | E28: 95.4786 | F28: =E28/$E$33 | G28: 0.4825 | H28: 0.78
B29: J | C29: Japan-locked | D29: 1 | E29: 22.0283 | F29: =E29/$E$33 | G29: 0.304 | H29: 0.12
B30: T | C30: Long tail | D30: 2 | E30: 4.0665 | F30: =E30/$E$33 | G30: 0.39 | H30: 0.55
C33: Total | D33: =SUM(D28:D32) | E33: =SUM(E28:E32) | F33: =SUM(F28:F32)
B34: APPLICABLE AI CEILING | C34: =SUMPRODUCT($E$28:$E$32,$G$28:$G$32)/$E$33 | D34: 0.43273793 | E34: ← re-cut for Years 4-5, after POS Workflow leaves | J34: 44.71% on the Years 1-3 mix — three archetype-D applications carry 78.5% of the effort. Once POS Workflow leaves the surviving mix is slightly more Japan-locked as a share, so the ceiling re-cuts to 43.27% for Years 4-5.
B35: APPLICABLE OFFSHORE CEILING | C35: =SUMPRODUCT($E$28:$E$32,$H$28:$H$32)/$E$33 | D35: 0.60126834 | E35: ← re-cut for Years 4-5, after POS Workflow leaves | J35: 65.27% on the Years 1-3 mix, re-cut to 60.13% for Years 4-5. POS Workflow was archetype D at a 78% ceiling, so losing it LOWERS the blend: what remains is Annuity Info at 12% plus two long-tail applications at 55%, against the Claims Platform at 78%.
A37: C. REALISATION AND THE NON-AI COMPONENTS
B38: Driver | C38: Year 1 | D38: Year 2 | E38: Year 3 | F38: Year 4 | G38: Year 5 | H38: Basis
B39: AI realisation — share of ceiling | C39: 0.25 | D39: 0.55 | E39: 0.75 | F39: 0.85 | G39: 0.9 | J39: Adoption, guardrails and substrate maturity. Capped at 90%.
B40: Classical ADM productivity, cumulative | C40: 0.02 | D40: 0.05 | E40: 0.07 | F40: 0.09 | G40: 0.11 | J40: Standardisation, defect reduction, shift-left.
B41: Operating-model productivity, RAW | C41: 0.03 | D41: 0.06 | E41: 0.08 | F41: 0.1 | G41: 0.12 | J41: Pod consolidation and one release train — only available where the stream is agile.
B42: Agile share of the domain → from the Delivery Mode sheet | C42: ='Delivery Mode'!C20 | D42: ='Delivery Mode'!D20 | E42: ='Delivery Mode'!E20 | F42: ='Delivery Mode'!F20 | G42: ='Delivery Mode'!G20
B43: Operating-model productivity, APPLIED = raw × agile share × span-of-control factor | C43: =C41*C42*C61 | D43: =D41*D42*D61 | E43: =E41*E42*E61 | F43: =F41*F42*F61 | G43: =G41*G42*G61 | J43: Scaling by the agile share is what makes the operating-model gain earned rather than assumed. It costs 2.0 points of Year-1 capability: 16.0% unscaled against the 14.1% the model earns.
B44: AI-attributable productivity | C44: =$C$34*C39 | D44: =$C$34*D39 | E44: =$C$34*E39 | F44: =$D$34*F39 | G44: =$D$34*G39
B45: CAPABILITY EARNED by end of year | C45: =1-(1-C44)*(1-C40)*(1-C43) | D45: =1-(1-D44)*(1-D40)*(1-D43) | E45: =1-(1-E44)*(1-E40)*(1-E43) | F45: =1-(1-F44)*(1-F40)*(1-F43) | G45: =1-(1-G44)*(1-G40)*(1-G43)
...

Sheet Sourcing & Productivity
A1: Sourcing and productivity — the same chain, applied differently to each population
A2: Productivity is not one number applied to everybody. The four populations do different work and we do not control all four, so each carries its own AI ceiling and its own adoption factor. Regenerated from the two-stream roster, with the ceiling re-cut from Year 4 when POS Workflow retires.
A4: A. WHY ONE RATE CANNOT APPLY TO ALL THREE — the Year-1 role mix
B5: Population | C5: Heads Y1 | D5: BSA | E5: Developer | F5: Tester | G5: Maint.
B6: FTC · Capgemini payroll | C6: 78.5 | D6: 0.10828025 | E6: 0.59235669 | F6: 0.13375796 | G6: 0.070063694 | I6: MetLife's own people are governance, domain SME and product ownership. MGCC is build and test. They are not doing the same work, so they cannot carry the same productivity rate.
B7: PT · Partner (sub-contracted) | C7: 7 | D7: 0.42857143 | E7: 0.57142857 | F7: 0 | G7: 0
B8: FTE · MetLife Japan | C8: 13.5 | D8: 0.25925926 | E8: 0 | F8: 0 | G8: 0.25925926
B9: MGCC · MetLife MGCC | C9: 22.5 | D9: 0 | E9: 0.64444444 | F9: 0.33333333 | G9: 0.022222222
A11: B. EACH POPULATION'S OWN AI CEILING AND ADOPTION — INPUT
B12: Population | C12: Own AI ceiling | D12: Adoption | E12: Effective ceiling | F12: vs domain blend
B13: FTC · Capgemini payroll | C13: 0.4533 | D13: 1 | E13: 0.4533 | F13: 0.0062 | I13: ADOPTION is the share of the ceiling each population can realise, and it is a judgement about AUTHORITY, not capability. We build the tooling and mandate it on our own payroll — so 1.00. Everything below that is somebody else’s decision. The four ceilings are scaled so the Year-1 head-weighted blend reproduces the Logic Tree’s 44.71%, and all four re-cut proportionally from Year 4.
B14: PT · Partner (sub-contracted) | C14: 0.4393 | D14: 0.85 | E14: 0.3734 | F14: -0.0737
B15: FTE · MetLife Japan | C15: 0.3747 | D15: 0.55 | E15: 0.2061 | F15: -0.241
B16: MGCC · MetLife MGCC | C16: 0.4712 | D16: 0.8 | E16: 0.3769 | F16: -0.0701
B17: Domain blended ceiling, Years 1-3 (44.71%; re-cut to 43.27% from Year 4) | C17: 0.4471
B18: Only the AI gate is scaled. Classical ADM productivity attaches to the work and the operating-model gain attaches to the delivery unit, so both flow to every population regardless of employer.
A20: C. WHAT EACH POPULATION IS THEREFORE ASKED TO DELIVER
B21: Applied to staffing | C21: Year 1 | D21: Year 2 | E21: Year 3 | F21: Year 4 | G21: Year 5
B22: FTC · Capgemini payroll | C22: 0 | D22: 0.2254 | E22: 0.3582 | F22: 0.4093 | G22: 0.5028 | I22: The headline commitment is 49.9% by Year 5, measured on RETAINED SCOPE — 86.577 units, not the frozen 121.573. Year 4 pre-loads none of its own in-year gain: that year absorbs the retirement of POS Workflow and the conversion of Payment & Records to pods, and the headcount fall from 78.5 to 51.5 is about 24 people of scope and 3 of productivity.
B23: PT · Partner (sub-contracted) | C23: 0 | D23: 0.1954 | E23: 0.3111 | F23: 0.3556 | G23: 0.4482
B24: FTE · MetLife Japan | C24: 0 | D24: 0.1328 | E24: 0.2125 | F24: 0.2433 | G24: 0.334
B25: MGCC · MetLife MGCC | C25: 0 | D25: 0.1968 | E25: 0.3132 | F25: 0.358 | G25: 0.4507
B26: Whole-domain commitment (the headline) | C26: 0 | D26: 0.223 | E26: 0.3546 | F26: 0.4051 | G26: 0.4986
A28: D. THE THREE-WAY COMMITMENT SPLIT
B29: CAPGEMINI COMMITS | C29: Our own headcount reduction, on our own payroll, on tooling and ways of working we control. This is contractible and we should contract it.
B30: METLIFE MUST DELIVER | C30: The reduction of MetLife Japan and MGCC headcount. We size it, we enable it and we report it — but redeploying MetLife's own people is MetLife's decision, and MGCC runs to its own utilisation targets. This should be a joint commitment with named owners, not a Capgemini SLA.
B31: JOINTLY DEPENDENT | C31: AI adoption on MetLife's side: tooling access, shared standards, common telemetry, and the substrate being used rather than merely available. If adoption lands below the factors in section B, the whole-team headcount misses even if Capgemini delivers in full.
A33: E. ORGANIC CONVERGENCE TO 50:50 — before any transfer
B34: Measure | C34: Year 1 | D34: Year 2 | E34: Year 3 | F34: Year 4 | G34: Year 5
B35: MetLife Japan (FTE) — own curve | C35: 13.5 | D35: 12 | E35: 10 | F35: 9 | G35: 6 | I35: MetLife’s populations follow their own slower curves and MGCC grows as a share — 18.6% of the domain on day one, 35.6% by Year 5. Capgemini absorbs the balance, taking its own book from 70.4% to 50.6% without a single transfer.
B36: MetLife MGCC — own curve | C36: 22.5 | D36: 21.5 | E36: 19.5 | F36: 15.5 | G36: 15.5
B37: Partner — per the partner plan | C37: 7 | D37: 7 | E37: 7 | F37: 5 | G37: 4
B38: Capgemini — absorbs the balance | C38: 78.5 | D38: 54 | E38: 42 | F38: 22 | G38: 18
B39: TOTAL = the headline commitment | C39: 121.5 | D39: 94.5 | E39: 78.5 | F39: 51.5 | G39: 43.5
B40: RATIO — Capgemini share | C40: 0.7037 | D40: 0.6455 | E40: 0.6242 | F40: 0.5243 | G40: 0.5057
B41: — of which productivity-driven | C41: 0 | D41: 0.223 | E41: 0.3546 | F41: 0.4051 | G41: 0.4986
B42: — of which RATIO-DRIVEN: fall in the Capgemini share since Year 1 | C42: 0 | D42: 0.0582 | E42: 0.0795 | F42: 0.1794 | G42: 0.198
B44: This is the mechanism that halves the transfer. Reaching the ratio by shrinking our own book is cheaper, lower-risk and entirely within our control; a transfer of employment is neither.
A46: F. THE GUARDRAILS — where organic convergence has to stop
B47: Test | C47: Year 1 | D47: Year 2 | E47: Year 3 | F47: Year 4 | G47: Year 5 | H47: Floor
...

Sheet Delivery Mode
A1: Delivery mode — two streams, one conversion, one retirement
A2: Appendix 3 v5 gives the development method for every application. The estate is now cut on the line that matters: the Claims Platform (Pega, already agile and on Pega Cloud, plus OpenBatch, hybrid and cloud-flagged) runs as an agile pod from day one; everything else runs as a waterfall team until POS Workflow retires, and converts to pods in Year 4.
A4: A. MODE TODAY AND TARGET, BY VALUE STREAM — INPUT
B5: Value stream | C5: Effort | D5: Archetype | E5: Mode today | F5: Agile from | G5: Why
B6: VS1 · Claims Platform — Pega for Claims (14322) + OpenBatch (13820) | C6: 60.4821 | D6: D | E6: Agile / Hybrid | F6: Q1 | G6: Pega is SaaS on Pega Cloud, no-code, 99% AD, 14,772 lines — the cleanest application in the estate. OpenBatch is 43.8 units, cloud-flagged, hybrid method, and carries all 18.1 of the domain’s MGCC units. Runs as a POD from Year 1. | I6: The mode column is MetLife’s own data. Two streams: Claims Platform (2 applications, 60.482 units, 49.8% of the estate and 69.9% of it once POS Workflow retires) and Payment & Records (4 applications, 61.091 units falling to 26.095). The decision to argue about is not the method — it is whether Payment & Records converts before Year 4.
B7: VS2 · Payment & Records — POS Workflow (9835), Annuity Info (9857), Maturity & Deferral (14423), My Number (11012) | C7: 61.0913 | D7: D / J / T | E7: Waterfall | F7: Y4 | G7: POS Workflow is 35.0 of the 61.1 and is MARKED RETIRE — business-critical, Japanese specifications, and the only nearshore capacity in the portfolio at 9.589 units. Annuity Info behind it is 22.0 units of Japan-locked waterfall at a 12% offshore ceiling. Runs as a 12-seat TEAM to Year 3 and converts to PODs of 6 in Year 4.
B9: Total | C9: =SUM(C6:C7)
A11: B. AGILE SHARE BY YEAR — computed from the quarter each stream converts
B12: Value stream | C12: Year 1 | D12: Year 2 | E12: Year 3 | F12: Year 4 | G12: Year 5
B13: VS1 · Claims Platform | C13: 1 | D13: 1 | E13: 1 | F13: 1 | G13: 1
B14: VS2 · Payment & Records | C14: 0 | D14: 0 | E14: 0 | F14: 1 | G14: 1
B15: CSS
B16: Effort-weighted agile share of the domain | C16: 0.497492 | D16: 0.497492 | E16: 0.497492 | F16: 1 | G16: 1
B18: Delivery units this produces
B19: — agile PODS (VS1 all years; VS2 from Year 4) | C19: 5 | D19: 4 | E19: 3 | F19: 6 | G19: 5
B20: — agile share (feeds the Logic Tree) | C20: =C16 | D20: =D16 | E20: =E16 | F20: =F16 | G20: =G16
B21: — waterfall TEAMS of 12 (VS2, Years 1-3) | C21: 4 | D21: 3 | E21: 3 | F21: 0 | G21: 0
A23: C. WHY THIS MATTERS TO THE NUMBER
B24: • Operating-model productivity is only available where the stream runs as a pod. Payment & Records stays a waterfall team to Year 3, so the agile share is 49.7% for three years and only reaches 1.00 in Year 4. That costs about 0.6 points of Year-2 and 1.9 points of Year-3 capability against a fully converted estate — the price of not putting a pod structure on an application MetLife is retiring.
B25: • The waterfall TEAM is 12 seats with its own test cell and its own nearshore capacity. The agile POD is 10 seats in Year 1, 9, 8, then 6 in Years 4 and 5, with design authority moving to the horizontal layer when the pod shrinks to six. Every VS1 pod carries MGCC seats from day one — all 22.6 MGCC units sit on OpenBatch and Pega.
B26: • Year 4 is the structural break. POS Workflow retires, 34.997 units leave the scope, nearshore goes to zero, the two FSI seats on that application go with it, and Payment & Records converts from three teams of 12 to two pods of 6. Headcount falls 78.5 to 51.5 — about 24 of those 27 people are the retirement.
B27: • DECIDE whether Payment & Records converts earlier. Holding it waterfall to Year 3 is the conservative reading of an estate where the biggest application is being retired, and it is the single assumption most worth arguing.

Sheet AMS & Ticket Load
A1: AMS and ticket load — the run team sized from evidence, for the first time
A2: 732 incidents and 1,161 changes over 32 months, from Appendix 3 v5.
A4: A. RECORDED VOLUMES — 1 Jan 2024 to 31 Aug 2026
B5: Measure | C5: Volume | D5: Per month | E5: Per unit of effort | F5: Share
B6: P1 — critical | C6: 0 | D6: =C6/$C$17 | E6: =C6/'Logic Tree'!$C$7 | F6: =C6/$C$11 | I6: No P1 or P2 incidents at all in 32 months and 71% of incidents at P5. The estate is stable; the cost is in changing it, not in keeping it up.
B7: P2 — high | C7: 1 | D7: =C7/$C$17 | E7: =C7/'Logic Tree'!$C$7 | F7: =C7/$C$11
B8: P3 — medium | C8: 89 | D8: =C8/$C$17 | E8: =C8/'Logic Tree'!$C$7 | F8: =C8/$C$11
B9: P4 — low | C9: 143 | D9: =C9/$C$17 | E9: =C9/'Logic Tree'!$C$7 | F9: =C9/$C$11
B10: P5 — informational | C10: 499 | D10: =C10/$C$17 | E10: =C10/'Logic Tree'!$C$7 | F10: =C10/$C$11
B11: All incidents | C11: =SUM(C6:C10) | D11: =C11/$C$17 | E11: =C11/'Logic Tree'!$C$7
B12: Emergency change | C12: 34 | D12: =C12/$C$17 | E12: =C12/'Logic Tree'!$C$7 | F12: =C12/$C$15 | I12: 84% Standard and 4.3% Emergency. A high-volume, low-severity, highly repeatable change profile — the best automation case in the portfolio.
B13: Normal change | C13: 124 | D13: =C13/$C$17 | E13: =C13/'Logic Tree'!$C$7 | F13: =C13/$C$15
B14: Standard change | C14: 1003 | D14: =C14/$C$17 | E14: =C14/'Logic Tree'!$C$7 | F14: =C14/$C$15
B15: All changes | C15: =SUM(C12:C14) | D15: =C15/$C$17 | E15: =C15/'Logic Tree'!$C$7
B17: Observation window, months | C17: 32
A19: B. SIZING THE RUN TEAM — three independent bases, triangulated
B20: Basis | C20: Value | D20: Reading
B21: A. Maintenance role reported in Appendix 3 v5 | C21: ='Logic Tree'!C18 | D21: MetLife's own HEADCOUNT view. Populated here, unlike Contract Management, so it is usable.
B22: B. Run effort implied by the AD / AMS split = (1 − AD share) x effort | C22: ='Logic Tree'!C7-'Logic Tree'!C21 | D22: MetLife's own EFFORT view: 13.5% of 100.765 units. It implies 2.4 times the run population the role line does, and both numbers come from the same spreadsheet.
B23: Total demand items per month (incidents + changes) | C23: =(C11+C15)/C17 | D23: 2,536 items in 32 months — 25.2 per unit of effort against 14.6 on Sales. High for a three-application estate, and 84% of the changes are Standard.
B24: C. Throughput implied by basis A — items per person per month | C24: =IFERROR(C23/C21,0) | D24: If the role line is right, each run person absorbs this many items a month.
B25: C. Throughput implied by basis B | C25: =IFERROR(C23/C22,0) | D25: If the effort split is right, this is the rate. Industry L2 throughput on a modern data stack is 40 to 80 items per person per month; both of these sit far below it, which says these items carry investigation rather than triage.
B26: Run-facing seats in the Year-1 roster (Maintenance + Tester, all sourcing) | C26: ='Team Build-Up'!C64+'Team Build-Up'!C63 | D26: Model output. Sized on the role line, which is the binding Year-1 reconciliation constraint, and reported here against the other two bases rather than averaged with them.
A28: C. WHAT THE TICKET DATA CHANGES
B29: • MetLife's two views of the run population disagree by a factor of 2.4. The Maintenance role line says 5.67 units; the AD / AMS effort split says 13.64. This model follows the role line, because Year 1 has to reconcile to Appendix 3 line by line — but the difference is 8 people and it is a real commercial exposure. PUT THIS TO METLIFE before the AMS price is fixed.
B30: • The severity profile is benign and the change profile is not. No P1 or P2 incidents in 32 months and 71% of incidents at P5 — this estate is stable. But 1,730 changes on 100.8 units, 84% of them Standard, is a high change rate, and Standard changes on a cloud data platform are exactly what pipeline automation and a release train remove. That is where the operating-model productivity in this domain actually comes from.
B31: • Ticket density is 25.2 items per unit of effort against 14.6 on Sales — the highest of the domains modelled so far. Combined with a 13.5% run share it suggests run work is sitting inside the Developer line, which is the same pattern Sales shows and the reason this cross-check is worth running on every domain.
B32: • DO ask MetLife which of the two run figures governs, and ask for the ticket-to-effort mapping behind the AD / AMS split. On a three-application domain this is a short conversation with a material price attached.

Sheet Inventory
A1: Inventory — the 6 Insurance Claims and Benefits Payment Related applications from Appendix 3 v5
A2: Classified by the six-rule classifier on the Golden Application Inventory v4.
B4: Application | C4: Arch | D4: Effort | E4: FTC | F4: FTE | G4: Onshore | H4: Nearshore | I4: Nearsh % | J4: BSA | K4: Dev | L4: AD % | M4: Crit | N4: Method | O4: Spec lang | P4: Lines of code | Q4: Batches | R4: Incidents | S4: Changes | T4: Primary code language | U4: Value stream | V4: FSI FTC | W4: EAI ID | X4: Target state
B5: Claim Batch | C5: D | D5: 43.782083 | E5: 20.590417 | F5: 5.0458333 | G5: 17.357083 | H5: 0 | I5: =IFERROR($H5/$D5,0) | J5: 1.75 | K5: 12.24875 | L5: 0.9836596 | M5: N | N5: Hybrid | O5: Hybrid | P5: 711101 | Q5: 27 | R5: 46 | S5: 216 | T5: JAVA | U5: VS1 | V5: 2 | W5: 13820 | X5: Maintain
B6: C12WNC-JPN | C6: D | D6: 34.996542 | E6: 29.379875 | F6: 5.6166667 | G6: 19.790833 | H6: 9.5890417 | I6: =IFERROR($H6/$D6,0) | J6: 2 | K6: 27.379875 | L6: 0.90522873 | M6: Y | N6: Waterfall | O6: JP | P6: 0 | Q6: 170 | R6: 581 | S6: 608 | T6: VB.NET;C/C++;JAVA | U6: VS2 | V6: 2 | W6: 9835 | X6: RETIRE
B7: W05AMS-JPN | C7: J | D7: 22.028333 | E7: 20.211667 | F7: 1.8166667 | G7: 20.211667 | H7: 0 | I7: =IFERROR($H7/$D7,0) | J7: 1.9166667 | K7: 18.295 | L7: 0.92547477 | M7: Y | N7: Waterfall | O7: JP | P7: 0 | Q7: 186 | R7: 86 | S7: 272 | T7: JAVA, C#, VC | U7: VS2 | V7: 2 | W7: 9857 | X7: Maintain
B8: Pega for Claims | C8: D | D8: 16.7 | E8: 11.491667 | F8: 0.70833333 | G8: 10.491667 | H8: 0 | I8: =IFERROR($H8/$D8,0) | J8: 0.29166667 | K8: 9.2 | L8: 0.98702595 | M8: N | N8: Agile | O8: EN | P8: 14772 | Q8: 1 | R8: 5 | S8: 9 | T8: JAVA | U8: VS1 | V8: 1 | W8: 14322 | X8: Maintain (Evolve)
B9: MDRS | C9: T | D9: 2.1225 | E9: 2.1225 | F9: 0 | G9: 2.1225 | H9: 0 | I9: =IFERROR($H9/$D9,0) | J9: 0 | K9: 2.1225 | L9: 0.75068708 | M9: Y | N9: Waterfall | O9: JP | P9: 537636 | Q9: 38 | R9: 4 | S9: 37 | T9: VB.NET | U9: VS2 | V9: 0 | W9: 14423 | X9: Maintain (Patch)
B10: WZZMNB-JPN | C10: T | D10: 1.944 | E10: 1.6523333 | F10: 0.29166667 | G10: 1.6523333 | H10: 0 | I10: =IFERROR($H10/$D10,0) | J10: 0 | K10: 1.6523333 | L10: 0.83217593 | M10: N | N10: Waterfall | O10: JP | P10: 0 | Q10: 17 | R10: 10 | S10: 19 | T10: JAVA | U10: VS2 | V10: 0 | W10: 11012 | X10: Maintain
B11: TOTAL | D11: =SUM(D5:D10) | E11: =SUM(E5:E10) | F11: =SUM(F5:F10) | G11: =SUM(G5:G10) | H11: =SUM(H5:H10) | J11: =SUM(J5:J10) | K11: =SUM(K5:K10) | P11: =SUM(P5:P10) | Q11: =SUM(Q5:Q10) | R11: =SUM(R5:R10) | S11: =SUM(S5:S10) | U11: — | V11: =SUM(V5:V10)
B13: All six carry a development method and a specification language. Four run on Japanese specifications, two are cloud-flagged and none is marked 優先引継対象. Code volume totals 1.26 million lines across three applications. ONE application is under a disposition question, not three: C12WNC-JPN (POS Workflow, EAI 9835) is marked RETIRE and is 35.0 of the 121.6 units — 28.8%. Pega for Claims (14322) and MDRS (14423) are BOTH Maintain in all four target-state columns of the EA inventory, with Year-3 targets of 8.4 and 1.1 each side; the earlier claim that they carry a zero Year-3 target was wrong and is corrected here. Columns U-X are new: the value stream, the FSI sub-contracted FTC, the EAI ID and the target-state disposition.

Sheet Value Streams
A1: Delivery streams — two streams, and a scope that shrinks 28.8% at Year 4
A2: RESTATED. The estate is cut on platform versus records: VS1 is Pega for Claims plus OpenBatch — 2 applications, 60.482 units, both archetype D at a 78% offshore ceiling, and the home of all 22.6 MGCC units. VS2 is the other four. POS Workflow inside VS2 is 35.0 units and is marked RETIRE, so from Year 4 VS2 is 26.095 units and the domain baseline is 86.577.
B4: Code | C4: Value stream | D4: Apps | E4: Effort | F4: Arch | G4: Mode today | H4: Agile from | I4: Y1 pods | J4: Y2 | K4: Y3 | L4: Y4 | M4: Y5 | N4: Vendor position today
B5: VS1 | C5: Claims Platform — Pega & OpenBatch | D5: 2 | E5: 60.4821 | F5: D | G5: Agile / Hybrid | H5: Q1 | I5: 5p | J5: 4p | K5: 3p | L5: 4p | M5: 3p | N5: CG 29.1 · FSI 3.0 · MGCC 22.6
B6: VS2 | C6: Payment & Records | D6: 4 | E6: 61.0913 | F6: D / J / T | G6: Waterfall | H6: Y4 | I6: 4t | J6: 3t | K6: 3t | L6: 2p | M6: 2p | N6: CG 49.4 · FSI 4.0
C8: Total | D8: =SUM(D5:D6) | E8: =SUM(E5:E6)
B10: Counts read 'p' for pods and 't' for 12-seat teams. VS1 pod size is 10 / 9 / 8 / 6 / 6; VS2 teams are 12 seats and its Year-4/5 pods are 6. All seven FSI seats sit inside the streams — three in VS1 (OpenBatch 2, Pega 1) and four in VS2 (POS Workflow 2, Annuity Info 2) — onshore Japan, tapering 7 / 7 / 7 / 5 / 4 as POS Workflow retires in Year 4 and one OpenBatch seat comes out in Year 5. Note that every MGCC unit in this 領域 sits on OpenBatch (18.146) and Pega (4.5), which is why the MGCC surplus has to sit in the horizontal layer: at 4.5 per pod it would push Capgemini below the 55% floor inside VS1.

Sheet Pod Library
A1: Pod library — every seat, per value stream, with MetLife’s role taxonomy and four sourcing types
A2: INPUT. Two value streams. VS1 (Pega 14322 + OpenBatch 13820) runs as an agile POD in all five years. VS2 (POS Workflow 9835, Annuity Info 9857, Maturity & Deferral 14423, My Number 11012) runs as a 12-seat TEAM to Year 3 and converts to PODs of 6 in Year 4, once POS Workflow retires. Sourcing FTC = Capgemini payroll · PT = FSI, onshore Japan on four named applications · FTE = MetLife Japan · MGCC. Only FTC can transfer. Column J is the seat ratio inside one unit; column K is the people hired across every instance of that unit in that year, and every one is a whole number or a half.
B4: Year | C4: Unit | D4: Seat | E4: Role detail | F4: Role | G4: Exp | H4: Loc | I4: Sourcing | J4: Count | K4: People in the block
B5: 1 | C5: POD | D5: 1 | E5: MetLife Claims Product Owner | F5: PM | G5: E4 | H5: ON | I5: FTE | J5: 0.6 | K5: =J5*5
B6: 1 | C6: POD | D6: 2 | E6: MetLife Claims SME | F6: BSA | G6: E4 | H6: ON | I6: FTE | J6: 0.4 | K6: =J6*5
B7: 1 | C7: POD | D7: 3 | E7: FSI OpenBatch Developer (JP) — EAI 13820 | F7: DEV | G7: E3 | H7: ON | I7: PT | J7: 0.4 | K7: =J7*5
B8: 1 | C8: POD | D8: 4 | E8: FSI Pega Analyst (JP) — EAI 14322 | F8: BSA | G8: E3 | H8: ON | I8: PT | J8: 0.2 | K8: =J8*5
B9: 1 | C9: POD | D9: 5 | E9: Business Analyst (bilingual) — Claims Platform | F9: BSA | G9: E3 | H9: ON | I9: FTC | J9: 0.6 | K9: =J9*5
B10: 1 | C10: POD | D10: 6 | E10: Pod lead / senior engineer — Claims Platform | F10: DEV | G10: E4 | H10: ON | I10: FTC | J10: 1 | K10: =J10*5
B11: 1 | C11: POD | D11: 7 | E11: Senior Claims Engineer | F11: DEV | G11: E3 | H11: ON | I11: FTC | J11: 1.2 | K11: =J11*5
B12: 1 | C12: POD | D12: 8 | E12: Junior Claims Engineer | F12: DEV | G12: E2 | H12: ON | I12: FTC | J12: 1 | K12: =J12*5
B13: 1 | C13: POD | D13: 9 | E13: Quality Engineer (SDET) | F13: TEST | G13: E2 | H13: ON | I13: FTC | J13: 0.6 | K13: =J13*5
B14: 1 | C14: POD | D14: 10 | E14: Solution Architect — Claims Platform | F14: OTH | G14: E4 | H14: ON | I14: FTC | J14: 0.4 | K14: =J14*5
B15: 1 | C15: POD | D15: 11 | E15: Junior Claims Engineer — offshore | F15: DEV | G15: E2 | H15: OFF | I15: FTC | J15: 0.2 | K15: =J15*5
B16: 1 | C16: POD | D16: 12 | E16: Graduate Claims Engineer — offshore | F16: DEV | G16: E1 | H16: OFF | I16: FTC | J16: 0.2 | K16: =J16*5
... B20: 1 | C20: POD | D20: 16 | E20: MGCC Quality Engineer | F20: TEST | G20: E2 | H20: OFF | I20: MGCC | J20: 1 | K20: =J20*5
D21: POD size — Year 1 · VS1 | J21: =SUM(J5:J20) | K21: =SUM(K5:K20)
B23: 1 | C23: TEAM | D23: 1 | E23: MetLife Payments Product Owner | F23: PM | G23: E4 | H23: ON | I23: FTE | J23: 0.5 | K23: =J23*4
B24: 1 | C24: TEAM | D24: 2 | E24: MetLife Payments Operations Analyst | F24: MNT | G24: E3 | H24: ON | I24: FTE | J24: 0.375 | K24: =J24*4
B25: 1 | C25: TEAM | D25: 3 | E25: FSI POS Workflow Developer (JP) — EAI 9835 | F25: DEV | G25: E3 | H25: ON | I25: PT | J25: 0.5 | K25: =J25*4
B26: 1 | C26: TEAM | D26: 4 | E26: FSI Annuity Info Analyst (JP) — EAI 9857 | F26: BSA | G26: E3 | H26: ON | I26: PT | J26: 0.5 | K26: =J26*4
B27: 1 | C27: TEAM | D27: 5 | E27: Business Analyst (bilingual) — Payments | F27: BSA | G27: E3 | H27: ON | I27: FTC | J27: 0.75 | K27: =J27*4
B28: 1 | C28: TEAM | D28: 6 | E28: Team lead / senior engineer — Payments | F28: DEV | G28: E4 | H28: ON | I28: FTC | J28: 1 | K28: =J28*4
B29: 1 | C29: TEAM | D29: 7 | E29: Senior Application Developer (VB.NET / C++ / Java) | F29: DEV | G29: E3 | H29: ON | I29: FTC | J29: 2.5 | K29: =J29*4
B30: 1 | C30: TEAM | D30: 8 | E30: Junior Application Developer | F30: DEV | G30: E2 | H30: ON | I30: FTC | J30: 1.5 | K30: =J30*4
B31: 1 | C31: TEAM | D31: 9 | E31: Test Analyst | F31: TEST | G31: E3 | H31: ON | I31: FTC | J31: 0.875 | K31: =J31*4
B32: 1 | C32: TEAM | D32: 10 | E32: Application Support (L2) — Tokyo | F32: MNT | G32: E2 | H32: ON | I32: FTC | J32: 0.625 | K32: =J32*4
B33: 1 | C33: TEAM | D33: 11 | E33: Technical Lead / design authority — Payments | F33: OTH | G33: E4 | H33: ON | I33: FTC | J33: 0.25 | K33: =J33*4
B34: 1 | C34: TEAM | D34: 12 | E34: Senior Application Developer — nearshore | F34: DEV | G34: E3 | H34: NEAR | I34: FTC | J34: 1.875 | K34: =J34*4
... B36: 1 | C36: TEAM | D36: 14 | E36: Junior Application Developer — offshore | F36: DEV | G36: E2 | H36: OFF | I36: FTC | J36: 0.25 | K36: =J36*4
D37: TEAM size — Year 1 · VS2 | J37: =SUM(J23:J36) | K37: =SUM(K23:K36)
B39: 2 | C39: POD | D39: 1 | E39: MetLife Claims Product Owner | F39: PM | G39: E4 | H39: ON | I39: FTE | J39: 0.5 | K39: =J39*4
B40: 2 | C40: POD | D40: 2 | E40: MetLife Claims SME | F40: BSA | G40: E4 | H40: ON | I40: FTE | J40: 0.5 | K40: =J40*4
B41: 2 | C41: POD | D41: 3 | E41: FSI OpenBatch Developer (JP) — EAI 13820 | F41: DEV | G41: E3 | H41: ON | I41: PT | J41: 0.5 | K41: =J41*4
B42: 2 | C42: POD | D42: 4 | E42: FSI Pega Analyst (JP) — EAI 14322 | F42: BSA | G42: E3 | H42: ON | I42: PT | J42: 0.25 | K42: =J42*4
B43: 2 | C43: POD | D43: 5 | E43: Business Analyst (bilingual) — Claims Platform | F43: BSA | G43: E3 | H43: ON | I43: FTC | J43: 0.5 | K43: =J43*4
B44: 2 | C44: POD | D44: 6 | E44: Pod lead / senior engineer — Claims Platform | F44: DEV | G44: E4 | H44: ON | I44: FTC | J44: 0.75 | K44: =J44*4
B45: 2 | C45: POD | D45: 7 | E45: Senior Claims Engineer | F45: DEV | G45: E3 | H45: ON | I45: FTC | J45: 0.5 | K45: =J45*4
B46: 2 | C46: POD | D46: 8 | E46: Junior Claims Engineer | F46: DEV | G46: E2 | H46: ON | I46: FTC | J46: 0.5 | K46: =J46*4
B47: 2 | C47: POD | D47: 9 | E47: Quality Engineer (SDET) | F47: TEST | G47: E2 | H47: ON | I47: FTC | J47: 0.25 | K47: =J47*4
...

Sheet Pod Plan
A1: Unit plan — how many instances of each value stream’s unit, per year
A2: INPUT. VS1 is an agile POD in every year (10 seats in Year 1, 9, 8, then 6). VS2 is a 12-seat TEAM to Year 3 and a POD of 6 from Year 4, when POS Workflow retires and 35.0 units leave the scope.
B4: Year | C4: VS | D4: Value stream | E4: Pods | F4: Teams | G4: Units | H4: People
B5: 1 | C5: VS1 | D5: Claims Platform — Pega & OpenBatch | E5: 5 | F5: 0 | G5: =E5+F5 | H5: =G5*SUM('Pod Library'!$J$5:$J$20)
B6: 1 | C6: VS2 | D6: Payment & Records | E6: 0 | F6: 4 | G6: =E6+F6 | H6: =G6*SUM('Pod Library'!$J$23:$J$36)
D7: Year 1 total | E7: =SUM(E5:E6) | F7: =SUM(F5:F6) | G7: =SUM(G5:G6) | H7: =SUM(H5:H6)
B9: 2 | C9: VS1 | D9: Claims Platform — Pega & OpenBatch | E9: 4 | F9: 0 | G9: =E9+F9 | H9: =G9*SUM('Pod Library'!$J$39:$J$54)
B10: 2 | C10: VS2 | D10: Payment & Records | E10: 0 | F10: 3 | G10: =E10+F10 | H10: =G10*SUM('Pod Library'!$J$57:$J$71)
D11: Year 2 total | E11: =SUM(E9:E10) | F11: =SUM(F9:F10) | G11: =SUM(G9:G10) | H11: =SUM(H9:H10)
B13: 3 | C13: VS1 | D13: Claims Platform — Pega & OpenBatch | E13: 3 | F13: 0 | G13: =E13+F13 | H13: =G13*SUM('Pod Library'!$J$74:$J$89)
B14: 3 | C14: VS2 | D14: Payment & Records | E14: 0 | F14: 3 | G14: =E14+F14 | H14: =G14*SUM('Pod Library'!$J$92:$J$107)
D15: Year 3 total | E15: =SUM(E13:E14) | F15: =SUM(F13:F14) | G15: =SUM(G13:G14) | H15: =SUM(H13:H14)
B17: 4 | C17: VS1 | D17: Claims Platform — Pega & OpenBatch | E17: 4 | F17: 0 | G17: =E17+F17 | H17: =G17*SUM('Pod Library'!$J$110:$J$124)
B18: 4 | C18: VS2 | D18: Payment & Records | E18: 2 | F18: 0 | G18: =E18+F18 | H18: =G18*SUM('Pod Library'!$J$127:$J$135)
D19: Year 4 total | E19: =SUM(E17:E18) | F19: =SUM(F17:F18) | G19: =SUM(G17:G18) | H19: =SUM(H17:H18)
B21: 5 | C21: VS1 | D21: Claims Platform — Pega & OpenBatch | E21: 3 | F21: 0 | G21: =E21+F21 | H21: =G21*SUM('Pod Library'!$J$138:$J$149)
B22: 5 | C22: VS2 | D22: Payment & Records | E22: 2 | F22: 0 | G22: =E22+F22 | H22: =G22*SUM('Pod Library'!$J$152:$J$160)
D23: Year 5 total | E23: =SUM(E21:E22) | F23: =SUM(F21:F22) | G23: =SUM(G21:G22) | H23: =SUM(H21:H22)

Sheet Horizontal Teams
A1: Horizontal teams — work that is not stream-bounded
A2: INPUT, defined per year. H1 is run and AMS. H2 is quality and payments assurance. H3 is delivery leadership and architecture — and from Year 4 it also holds the Claims Platform design authority, which leaves the pods when they shrink to six seats. No FSI seat sits here: all seven partner seats are inside the value streams.
B4: Year | C4: Team | D4: Role | E4: Role detail | F4: Exp | G4: Loc | H4: Sourcing | I4: Count | J4: People in the block
B5: 1 | C5: H1 | D5: PM | E5: Service Delivery Manager | F5: E5 | G5: ON | H5: FTC | I5: 1 | J5: =I5
B6: 1 | C6: H1 | D6: MNT | E6: Incident & Problem Analyst | F6: E3 | G6: ON | H6: FTC | I6: 2 | J6: =I6
B7: 1 | C7: H1 | D7: MNT | E7: L2 Application Support — offshore | F7: E2 | G7: OFF | H7: FTC | I7: 0.5 | J7: =I7
B8: 1 | C8: H1 | D8: OTH | E8: Observability / AIOps Engineer — offshore | F8: E3 | G8: OFF | H8: FTC | I8: 0.5 | J8: =I8
B9: 1 | C9: H1 | D9: MNT | E9: MetLife Operations Lead | F9: E4 | G9: ON | H9: FTE | I9: 2 | J9: =I9
B10: 1 | C10: H1 | D10: DEV | E10: MGCC Platform SRE | F10: E3 | G10: OFF | H10: MGCC | I10: 4.5 | J10: =I10
B11: 1 | C11: H1 | D11: MNT | E11: MGCC Application Support | F11: E2 | G11: OFF | H11: MGCC | I11: 0.5 | J11: =I11
B12: 1 | C12: H2 | D12: TEST | E12: Quality Lead | F12: E4 | G12: ON | H12: FTC | I12: 1 | J12: =I12
B13: 1 | C13: H2 | D13: TEST | E13: Performance & Batch Test Engineer — offshore | F13: E3 | G13: OFF | H13: FTC | I13: 0.5 | J13: =I13
B14: 1 | C14: H2 | D14: BSA | E14: Payments Assurance Analyst | F14: E3 | G14: ON | H14: FTC | I14: 2 | J14: =I14
B15: 1 | C15: H2 | D15: TEST | E15: MGCC Quality Engineer — regression cell | F15: E2 | G15: OFF | H15: MGCC | I15: 2.5 | J15: =I15
B16: 1 | C16: H2 | D16: BSA | E16: MetLife Payments Assurance Lead | F16: E4 | G16: ON | H16: FTE | I16: 1.5 | J16: =I16
... B21: 1 | C21: H3 | D21: PM | E21: MetLife Portfolio Lead | F21: E4 | G21: ON | H21: FTE | I21: 1.5 | J21: =I21
E22: Year 1 horizontal total | I22: =SUM(I5:I21) | J22: =SUM(J5:J21)
B24: 2 | C24: H1 | D24: PM | E24: Service Delivery Manager | F24: E5 | G24: ON | H24: FTC | I24: 0.5 | J24: =I24
B25: 2 | C25: H1 | D25: MNT | E25: Incident & Problem Analyst | F25: E3 | G25: ON | H25: FTC | I25: 1.5 | J25: =I25
B26: 2 | C26: H1 | D26: MNT | E26: L2 Application Support — offshore | F26: E2 | G26: OFF | H26: FTC | I26: 0.5 | J26: =I26
B27: 2 | C27: H1 | D27: OTH | E27: Observability / AIOps Engineer — offshore | F27: E3 | G27: OFF | H27: FTC | I27: 0.5 | J27: =I27
B28: 2 | C28: H1 | D28: MNT | E28: MetLife Operations Lead | F28: E4 | G28: ON | H28: FTE | I28: 2 | J28: =I28
B29: 2 | C29: H1 | D29: DEV | E29: MGCC Platform SRE | F29: E3 | G29: OFF | H29: MGCC | I29: 4.5 | J29: =I29
B30: 2 | C30: H1 | D30: MNT | E30: MGCC Application Support | F30: E2 | G30: OFF | H30: MGCC | I30: 2.5 | J30: =I30
B31: 2 | C31: H2 | D31: TEST | E31: Quality Lead | F31: E4 | G31: ON | H31: FTC | I31: 0.5 | J31: =I31
B32: 2 | C32: H2 | D32: TEST | E32: Performance & Batch Test Engineer — offshore | F32: E3 | G32: OFF | H32: FTC | I32: 0.5 | J32: =I32
B33: 2 | C33: H2 | D33: BSA | E33: Payments Assurance Analyst | F33: E3 | G33: ON | H33: FTC | I33: 1.5 | J33: =I33
B34: 2 | C34: H2 | D34: TEST | E34: MGCC Quality Engineer — regression cell | F34: E2 | G34: OFF | H34: MGCC | I34: 2.5 | J34: =I34
B35: 2 | C35: H2 | D35: BSA | E35: MetLife Payments Assurance Lead | F35: E4 | G35: ON | H35: FTE | I35: 1.5 | J35: =I35
... B40: 2 | C40: H3 | D40: PM | E40: MetLife Portfolio Lead | F40: E4 | G40: ON | H40: FTE | I40: 1.5 | J40: =I40
E41: Year 2 horizontal total | I41: =SUM(I24:I40) | J41: =SUM(J24:J40)
B43: 3 | C43: H1 | D43: PM | E43: Service Delivery Manager | F43: E5 | G43: ON | H43: FTC | I43: 0.5 | J43: =I43
B44: 3 | C44: H1 | D44: MNT | E44: Incident & Problem Analyst | F44: E3 | G44: ON | H44: FTC | I44: 0.5 | J44: =I44
B45: 3 | C45: H1 | D45: MNT | E45: L2 Application Support — offshore | F45: E2 | G45: OFF | H45: FTC | I45: 0.5 | J45: =I45
B46: 3 | C46: H1 | D46: OTH | E46: Observability / AIOps Engineer — offshore | F46: E3 | G46: OFF | H46: FTC | I46: 0.5 | J46: =I46
B47: 3 | C47: H1 | D47: MNT | E47: MetLife Operations Lead | F47: E4 | G47: ON | H47: FTE | I47: 2 | J47: =I47
B48: 3 | C48: H1 | D48: DEV | E48: MGCC Platform SRE | F48: E3 | G48: OFF | H48: MGCC | I48: 4 | J48: =I48
B49: 3 | C49: H1 | D49: MNT | E49: MGCC Application Support | F49: E2 | G49: OFF | H49: MGCC | I49: 4 | J49: =I49
B50: 3 | C50: H2 | D50: TEST | E50: MGCC Quality Engineer — regression cell | F50: E2 | G50: OFF | H50: MGCC | I50: 2.5 | J50: =I50
B51: 3 | C51: H2 | D51: BSA | E51: MetLife Payments Assurance Lead | F51: E4 | G51: ON | H51: FTE | I51: 1.5 | J51: =I51
...

Sheet Team Build-Up
A1: Team build-up — and the Year-1 reconciliation to Appendix 3 v5
A2: Nothing on this sheet is typed. Section B is the test that matters: the roster has to be the client's own Year-1 position on effort, sourcing, location AND role.
A4: A. HEADCOUNT
B5: Measure | C5: Year 1 | D5: Year 2 | E5: Year 3 | F5: Year 4 | G5: Year 5
B6: People in agile pods (VS1 all years; VS2 from Year 4) | C6: =SUMIFS('Seat Ledger'!$M$5:$M$287,'Seat Ledger'!$B$5:$B$287,1,'Seat Ledger'!$C$5:$C$287,"POD") | D6: =SUMIFS('Seat Ledger'!$M$5:$M$287,'Seat Ledger'!$B$5:$B$287,2,'Seat Ledger'!$C$5:$C$287,"POD") | E6: =SUMIFS('Seat Ledger'!$M$5:$M$287,'Seat Ledger'!$B$5:$B$287,3,'Seat Ledger'!$C$5:$C$287,"POD") | F6: =SUMIFS('Seat Ledger'!$M$5:$M$287,'Seat Ledger'!$B$5:$B$287,4,'Seat Ledger'!$C$5:$C$287,"POD") | G6: =SUMIFS('Seat Ledger'!$M$5:$M$287,'Seat Ledger'!$B$5:$B$287,5,'Seat Ledger'!$C$5:$C$287,"POD")
