Workbook

Sheet README
A1: Storage and Preservation Related — domain framework v2
A2: A two-speed 領域, and now modelled as one. K2 is 62.6 of the 106.1 units — agile, hybrid-specification, distributed-proven — and is a value stream on its own. The other fourteen applications are 43.4 units of Japanese-specification waterfall and are the second. There are no pods: every delivery unit is a 12-seat TEAM, 4 + 3 in Year 1 falling to 3 + 1 by Year 4. Productivity lands at 44.6% by Year 5 and offshore at 54.7%, which is the blended archetype ceiling exactly.
A4: WHAT THIS 領域 IS
B5: Fifteen applications, three archetypes | C5: K2 62.6 units (D, distributed-proven, agile, hybrid specifications) · five Japan-locked applications totalling 34.2 · nine long-tail applications totalling 9.3. Two value streams: Policy Owner Servicing Work Flow 86.2 and Payment 19.9.
B6: It is really two domains | C6: K2 is 59.05% of the effort and is modern. Everything else is waterfall with Japanese-language specifications, and five of those are Japan-locked at a 12% offshore ceiling. The two value streams are drawn on exactly that line.
B7: 41 Capgemini people are already here | C7: 36.1 of them on K2 alone. Four are onshore. Banded E2 12 · E3 16 · E4 11 — mid-to-senior, and concentrated on the one modern application.
B8: FSI holds four applications | C8: 7.0 of the 69.426 vendor units — 10.1%. K2 (EAI 12117) 2 · POS-IMS (13453) 2 · W13WEP-JPN (9947) 2 · JP-RPASS (11604) 1. Tapers 7 / 7 / 6 / 5 / 4. Five of the seven sit in the Payment & Records team and two in the Work Flow team; 2 more (1 from Year 4) are held in horizontal H1 as a control cell.
B9: Two applications are marked Retire | C9: C03WRE-JPN and JP-PCI-RPASS, 3.3 units between them, from the disposition columns new in Appendix 3 v5.
A10: THE SHAPE OF THE ANSWER
B11: Offshore closes in full | C11: 16.9% today against a 54.73% ceiling. The design reaches 54.7%: 18.4 / 30.0 / 39.3 / 47.3 / 54.7%. Year 5 gets there by halving the K2 bilingual analyst to 0.5 per team; the onshore technical lead, the Tokyo L2 support hand and design authority are held in every year.
B12: The 50:50 closes with a small transfer | C12: Organic convergence takes Capgemini from 65.1% to 55.2% by Year 3 on its own; a transfer of 3.5 people — 1.5 to MetLife Japan, 2.0 to MGCC — closes the rest and lands the ratio at 49.99%.
B13: K2 is the whole modernisation case | C13: 62.6 units, agile already, a 78% offshore ceiling, and most of our inherited people. If K2 moves, the domain moves — and because the other fourteen never convert, K2 is also the ceiling on how far productivity can go here.
A14: THE ENGINE
B15: Unchanged from Sales / Insurance and Contract Management | C15: Six-rule archetype classifier → AI and offshore ceilings from Golden Inventory v4 → realisation curve → four-gate capability → carry-forward and pre-load → per-sourcing productivity → organic ratio convergence → guardrails → seat ledger.
B16: Seats deploy whole people | C16: Pod Library column K and Horizontal Teams column J are the people you hire for that role across the block. Every one is a whole number or a half — the 0.5-grid check on Change Control is clean in all five years. The SIT Loading sheet turns them into requisitions.
A17: WHAT TO RAISE
B18: The role line is restated | C18: Appendix 3 records 0.14 project-management units and ZERO architecture across fifteen applications, against 1,145 incidents and 2,071 changes. Restated to 5.0 maintenance, 3.0 PM and 2.5 architecture, taken from the developer line — far less than Contract Management needed.
B19: K2 concentration is the delivery risk | C19: 62.6 units and 36.1 of our 41 people on one application. That is the modernisation opportunity and the single point of failure in the same place.
B20: The retirement question | C20: 3.3 units leave the estate. The model holds effort frozen at the Year-1 baseline; if retirement is real the Year-4 and Year-5 baselines should shrink. Decide whether that is a saving we claim or a scope reduction MetLife prices out.
B21: Two streams, teams only | C21: v2 change. K2 is its own value stream; the other fourteen applications are the second, renamed Policy Owner Servicing Payment & Records. Every delivery unit is a 12-seat TEAM: 7 instances in Year 1, then 6, 5, 4 and 4. Headcount 106.0 → 85.0 → 72.5 → 64.5 → 58.5 against Logic Tree targets of 106.08 / 85.15 / 72.30 / 64.30 / 58.77.
B22: Composition is continuous | C22: v3, Capgemini seats only. Every Capgemini role in both team anatomies runs continuously across the five years with a monotone seat ratio — no seat appears, disappears and reappears. Each team keeps a technical lead, a bilingual analyst, a tester, a support seat and design authority in every year. Testers and junior builders are banded E1/E2 and E1 seats exist in all five years. NO SEAT IS EVER RE-BANDED: a grade is fixed for the life of the seat, so the senior share moves only because the number and size of the units move. MetLife FTE, MGCC and FSI seats are byte-identical to v2.

Sheet Basis & Assumptions
A1: Where every input comes from, and which ones are ours
A2: v2. The domain has been restated to two value streams — K2 alone, and the fourteen satellites — running as 12-seat TEAMS only, with no pods in any year. What matters here is the provenance of each input: which are measured, which are restated, and which are domain overrides.
B4: Element | C4: Source | D4: Value used | E4: Status | F4: Note
B5: Baseline | C5: Appendix 3 v5, 15 applications | D5: effort 106.080 · FTC 69.426 · FTE 25.654 · MGCC 11.000 · onshore 62.464 · offshore 6.963 | E5: SOURCE | F5: K2 is row 100; the duplicate K2 line at row 101 is excluded, as MetLife's own total does.
B6: Archetypes | C6: Golden Inventory v4, six-rule classifier | D6: D 1 / 62.642 · J 5 / 34.161 · T 9 / 9.277 | E6: SOURCE | F6: AI ceiling 41.69%, offshore ceiling 54.73%. Five Japan-locked applications at a 12% ceiling are what hold the blend down.
B7: Delivery method | C7: Appendix 3 v5 | D7: K2 agile 62.6 units; the other fourteen waterfall 43.4, and they never convert | E7: MEASURED | F7: Specification language splits the same way: 67.9 hybrid, 38.1 Japanese. Holding Payment & Records as waterfall to Year 5 caps the agile share at 59.05% and is the single biggest brake on the productivity number.
B8: Adoption factors | C8: Portfolio default | D8: 1.00 / 0.85 / 0.80 / 0.55 — unchanged | E8: STANDARD | F8: A largely waterfall, Japanese-language estate. No case for raising MetLife's commitment here.
B9: Role line | C9: BSA 8.642 · DEV 45.389 · TEST 11.775 · MNT 3.483 · PM 0.138 · OTH 0.000 | D9: MNT 5.00 · PM 3.00 · OTH 2.50, taken from DEV | E9: RESTATED | F9: 0.14 PM units and zero architecture across fifteen applications against 1,145 incidents. Arithmetically neutral and far smaller than Contract Management needed.
B10: Partner | C10: FSI named FTC supplied by MetLife against four EAI IDs | D10: 7.000 of 69.426 vendor units — 10.1% | E10: MODELLED | F10: K2 (EAI 12117) 2 · POS-IMS (13453) 2 · W13WEP-JPN (9947) 2 · JP-RPASS (11604) 1, as supplied by MetLife. Tapered 7 / 7 / 6 / 5 / 4. Five sit in the Payment & Records team, two in the Work Flow team, and 2 (1 from Year 4) in horizontal H1 as a control cell.
B11: Inherited workforce | C11: T3 reconciliation behind Golden v4 | D11: 41 people, 4 onshore, 36.1 on K2 | E11: SOURCE | F11: Banded E2 12 · E3 16 · E4 11.
B12: Disposition | C12: New in Appendix 3 v5 | D12: C03WRE-JPN and JP-PCI-RPASS marked Retire — 3.3 units | E12: NEW | F12: Not yet reflected in the baseline; the model holds effort frozen at Year 1. See the README.
B13: Guardrails | C13: Portfolio standard | D13: 50% vendor share · 55% per team · 55% of build-and-test · continuous role coverage | E13: STANDARD | F13: All held in every year. Tightest single team 58.3%. Added in v3: every Capgemini role runs continuously with a monotone ratio, each team holds a lead, an analyst, a tester, support and design authority in all five years, and no seat is re-banded across years — a grade is fixed for the life of the seat.
B14: Transfer | C14: One event at the end of Year 3 | D14: 3.5 people — 1.5 to MetLife Japan, 2.0 to MGCC | E14: MODELLED | F14: Organic convergence runs first, taking Capgemini from 65.1% to 55.2% before anyone moves. Ratio lands at 49.99%.
B15: Delivery structure | C15: Domain override, v2 | D15: TEAMS of 12 only — 4+3 / 4+2 / 3+2 / 3+1 / 3+1 instances | E15: DOMAIN OVERRIDE | F15: No pods anywhere, and team size never moves; instances retire instead. The horizontal layer flexes to reconcile to the Logic Tree target and rises in Year 4 as the last Payment & Records team retires into AMS.
A16: HOW TO READ THE STATUS COLUMN
B17: • SOURCE — taken directly from Appendix 3 v5 or Golden Application Inventory v4. Not ours to change.
B18: • MEASURED — MetLife has supplied it and we use it as given, where an earlier version made us assume.
B19: • RESTATED — the client figure is internally impossible and we have changed it. Every restatement is arithmetically neutral: people move between role lines, the total does not. These go back to MetLife.
B20: • DOMAIN OVERRIDE — a portfolio default deliberately changed for this 領域, with the reason stated. These are solution decisions and should be defended as such in the review.
B21: • MODELLED — a construct of ours with no direct client source: partner plans, transfer sizing, conversion quarters. The assumptions most worth challenging.

Sheet Change Control
A1: Change control — what must still hold after you edit a seat count
A2: Pod Library column J and Horizontal Teams column I are INPUTS. You may change them. Holding the yearly total is necessary but not sufficient — these are the other things that have to survive the edit. Every check below is live. This domain has no PODs, so the POD row reads n/a by construction.
A4: A. WHERE THESE NUMBERS GO
B5: • Pod Library J and Horizontal Teams I are hard-typed values, not formulas. Nothing upstream computes them — they are the design. Everything downstream is derived from them.
B6: • Seat Ledger reads them cell by cell (912 references to Pod Library, 630 to Horizontal Teams) and multiplies by the unit count on Pod Plan. Team Build-Up, Cost & Commercial, Inherited Workforce and Unit Cost Sensitivity are all SUMIFS over the Seat Ledger. Change a seat and every one of them moves.
B7: • THE ONE THAT SURPRISES PEOPLE: the Logic Tree reads the roster back. Partner seats (row 59) drive the partner share (row 60), the span-of-control factor (row 61), the applied operating-model gain (row 43), capability (row 45) and therefore the HEADCOUNT TARGET itself (row 53). Changing partner seats moves the target you are trying to hit. It converges, but it does not stand still.
B8: • What does NOT move: the effort baseline, the archetype mix, the AI and offshore ceilings, the realisation curve and the agile conversion quarters. Those are inputs on the Logic Tree and Delivery Mode.
A10: B. THE INVARIANTS — all of these must stay green
B11: Check | C11: Y1 | D11: Y2 | E11: Y3 | F11: Y4 | G11: Y5 | H11: Tolerance | I11: Status
B12: Headcount delivered minus Logic Tree target | C12: ='Team Build-Up'!C12 | D12: ='Team Build-Up'!D12 | E12: ='Team Build-Up'!E12 | F12: ='Team Build-Up'!F12 | G12: ='Team Build-Up'!G12 | H12: ± 1.5 | I12: =IF(MAX(ABS(C12),ABS(D12),ABS(E12),ABS(F12),ABS(G12))<=1.5,"OK","CHECK") | J12: The productivity commitment. If you add seats you must remove others.
B13: Capgemini share inside each POD | C13: =IFERROR((SUMIFS('Pod Library'!$J$5:$J$160,'Pod Library'!$B$5:$B$160,1,'Pod Library'!$C$5:$C$160,"POD",'Pod Library'!$I$5:$I$160,"FTC")+SUMIFS('Pod Library'!$J$5:$J$160,'Pod Library'!$B$5:$B$160,1,'Pod Library'!$C$5:$C$160,"POD",'Pod Library'!$I$5:$I$160,"PT"))/(SUMIFS('Pod Library'!$J$5:$J$160,'Pod Library'!$B$5:$B$160,1,'Pod Library'!$C$5:$C$160,"POD")),"n/a") | D13: =IFERROR((SUMIFS('Pod Library'!$J$5:$J$160,'Pod Library'!$B$5:$B$160,2,'Pod Library'!$C$5:$C$160,"POD",'Pod Library'!$I$5:$I$160,"FTC")+SUMIFS('Pod Library'!$J$5:$J$160,'Pod Library'!$B$5:$B$160,2,'Pod Library'!$C$5:$C$160,"POD",'Pod Library'!$I$5:$I$160,"PT"))/(SUMIFS('Pod Library'!$J$5:$J$160,'Pod Library'!$B$5:$B$160,2,'Pod Library'!$C$5:$C$160,"POD")),"n/a") | E13: =IFERROR((SUMIFS('Pod Library'!$J$5:$J$160,'Pod Library'!$B$5:$B$160,3,'Pod Library'!$C$5:$C$160,"POD",'Pod Library'!$I$5:$I$160,"FTC")+SUMIFS('Pod Library'!$J$5:$J$160,'Pod Library'!$B$5:$B$160,3,'Pod Library'!$C$5:$C$160,"POD",'Pod Library'!$I$5:$I$160,"PT"))/(SUMIFS('Pod Library'!$J$5:$J$160,'Pod Library'!$B$5:$B$160,3,'Pod Library'!$C$5:$C$160,"POD")),"n/a") | F13: =IFERROR((SUMIFS('Pod Library'!$J$5:$J$160,'Pod Library'!$B$5:$B$160,4,'Pod Library'!$C$5:$C$160,"POD",'Pod Library'!$I$5:$I$160,"FTC")+SUMIFS('Pod Library'!$J$5:$J$160,'Pod Library'!$B$5:$B$160,4,'Pod Library'!$C$5:$C$160,"POD",'Pod Library'!$I$5:$I$160,"PT"))/(SUMIFS('Pod Library'!$J$5:$J$160,'Pod Library'!$B$5:$B$160,4,'Pod Library'!$C$5:$C$160,"POD")),"n/a") | G13: =IFERROR((SUMIFS('Pod Library'!$J$5:$J$160,'Pod Library'!$B$5:$B$160,5,'Pod Library'!$C$5:$C$160,"POD",'Pod Library'!$I$5:$I$160,"FTC")+SUMIFS('Pod Library'!$J$5:$J$160,'Pod Library'!$B$5:$B$160,5,'Pod Library'!$C$5:$C$160,"POD",'Pod Library'!$I$5:$I$160,"PT"))/(SUMIFS('Pod Library'!$J$5:$J$160,'Pod Library'!$B$5:$B$160,5,'Pod Library'!$C$5:$C$160,"POD")),"n/a") | H13: ≥ 55% | I13: =IF(COUNTIF(C13:G13,"<0.5450")=0,"OK","CHECK") | J13: A POD in which Capgemini is a minority is one whose ways of working we do not set.
B14: Capgemini share inside each TEAM | C14: =IFERROR((SUMIFS('Pod Library'!$J$5:$J$160,'Pod Library'!$B$5:$B$160,1,'Pod Library'!$C$5:$C$160,"TEAM",'Pod Library'!$I$5:$I$160,"FTC")+SUMIFS('Pod Library'!$J$5:$J$160,'Pod Library'!$B$5:$B$160,1,'Pod Library'!$C$5:$C$160,"TEAM",'Pod Library'!$I$5:$I$160,"PT"))/(SUMIFS('Pod Library'!$J$5:$J$160,'Pod Library'!$B$5:$B$160,1,'Pod Library'!$C$5:$C$160,"TEAM")),"n/a") | D14: =IFERROR((SUMIFS('Pod Library'!$J$5:$J$160,'Pod Library'!$B$5:$B$160,2,'Pod Library'!$C$5:$C$160,"TEAM",'Pod Library'!$I$5:$I$160,"FTC")+SUMIFS('Pod Library'!$J$5:$J$160,'Pod Library'!$B$5:$B$160,2,'Pod Library'!$C$5:$C$160,"TEAM",'Pod Library'!$I$5:$I$160,"PT"))/(SUMIFS('Pod Library'!$J$5:$J$160,'Pod Library'!$B$5:$B$160,2,'Pod Library'!$C$5:$C$160,"TEAM")),"n/a") | E14: =IFERROR((SUMIFS('Pod Library'!$J$5:$J$160,'Pod Library'!$B$5:$B$160,3,'Pod Library'!$C$5:$C$160,"TEAM",'Pod Library'!$I$5:$I$160,"FTC")+SUMIFS('Pod Library'!$J$5:$J$160,'Pod Library'!$B$5:$B$160,3,'Pod Library'!$C$5:$C$160,"TEAM",'Pod Library'!$I$5:$I$160,"PT"))/(SUMIFS('Pod Library'!$J$5:$J$160,'Pod Library'!$B$5:$B$160,3,'Pod Library'!$C$5:$C$160,"TEAM")),"n/a") | F14: =IFERROR((SUMIFS('Pod Library'!$J$5:$J$160,'Pod Library'!$B$5:$B$160,4,'Pod Library'!$C$5:$C$160,"TEAM",'Pod Library'!$I$5:$I$160,"FTC")+SUMIFS('Pod Library'!$J$5:$J$160,'Pod Library'!$B$5:$B$160,4,'Pod Library'!$C$5:$C$160,"TEAM",'Pod Library'!$I$5:$I$160,"PT"))/(SUMIFS('Pod Library'!$J$5:$J$160,'Pod Library'!$B$5:$B$160,4,'Pod Library'!$C$5:$C$160,"TEAM")),"n/a") | G14: =IFERROR((SUMIFS('Pod Library'!$J$5:$J$160,'Pod Library'!$B$5:$B$160,5,'Pod Library'!$C$5:$C$160,"TEAM",'Pod Library'!$I$5:$I$160,"FTC")+SUMIFS('Pod Library'!$J$5:$J$160,'Pod Library'!$B$5:$B$160,5,'Pod Library'!$C$5:$C$160,"TEAM",'Pod Library'!$I$5:$I$160,"PT"))/(SUMIFS('Pod Library'!$J$5:$J$160,'Pod Library'!$B$5:$B$160,5,'Pod Library'!$C$5:$C$160,"TEAM")),"n/a") | H14: ≥ 55% | I14: =IF(COUNTIF(C14:G14,"<0.5450")=0,"OK","CHECK") | J14: A TEAM in which Capgemini is a minority is one whose ways of working we do not set. Measured across both value-stream anatomies together. Individually: 66.7% / 83.3% (Y1), 58.3% / 70.8% (Y2), 58.3% / 62.5% (Y3), 58.3% / 62.5% (Y4) and 58.3% / 58.3% (Y5). Sourcing mix per team is unchanged from v2 — only the Capgemini (FTC) seat anatomy was re-cut.
B15: Capgemini share of the delivery population | C15: =IFERROR((SUMIFS('Seat Ledger'!$M$5:$M$235,'Seat Ledger'!$B$5:$B$235,1,'Seat Ledger'!$J$5:$J$235,"FTC")+SUMIFS('Seat Ledger'!$M$5:$M$235,'Seat Ledger'!$B$5:$B$235,1,'Seat Ledger'!$J$5:$J$235,"PT"))/(SUMIFS('Seat Ledger'!$M$5:$M$235,'Seat Ledger'!$B$5:$B$235,1)),0) | D15: =IFERROR((SUMIFS('Seat Ledger'!$M$5:$M$235,'Seat Ledger'!$B$5:$B$235,2,'Seat Ledger'!$J$5:$J$235,"FTC")+SUMIFS('Seat Ledger'!$M$5:$M$235,'Seat Ledger'!$B$5:$B$235,2,'Seat Ledger'!$J$5:$J$235,"PT"))/(SUMIFS('Seat Ledger'!$M$5:$M$235,'Seat Ledger'!$B$5:$B$235,2)),0) | E15: =IFERROR((SUMIFS('Seat Ledger'!$M$5:$M$235,'Seat Ledger'!$B$5:$B$235,3,'Seat Ledger'!$J$5:$J$235,"FTC")+SUMIFS('Seat Ledger'!$M$5:$M$235,'Seat Ledger'!$B$5:$B$235,3,'Seat Ledger'!$J$5:$J$235,"PT"))/(SUMIFS('Seat Ledger'!$M$5:$M$235,'Seat Ledger'!$B$5:$B$235,3)),0) | F15: =IFERROR((SUMIFS('Seat Ledger'!$M$5:$M$235,'Seat Ledger'!$B$5:$B$235,4,'Seat Ledger'!$J$5:$J$235,"FTC")+SUMIFS('Seat Ledger'!$M$5:$M$235,'Seat Ledger'!$B$5:$B$235,4,'Seat Ledger'!$J$5:$J$235,"PT"))/(SUMIFS('Seat Ledger'!$M$5:$M$235,'Seat Ledger'!$B$5:$B$235,4)),0) | G15: =IFERROR((SUMIFS('Seat Ledger'!$M$5:$M$235,'Seat Ledger'!$B$5:$B$235,5,'Seat Ledger'!$J$5:$J$235,"FTC")+SUMIFS('Seat Ledger'!$M$5:$M$235,'Seat Ledger'!$B$5:$B$235,5,'Seat Ledger'!$J$5:$J$235,"PT"))/(SUMIFS('Seat Ledger'!$M$5:$M$235,'Seat Ledger'!$B$5:$B$235,5)),0) | H15: ≥ 50% | I15: =IF(COUNTIF(C15:G15,"<0.4950")=0,"OK","CHECK") | J15: Below half the roster we cannot carry a productivity commitment we do not control.
B16: Blocks deploying a non-whole number of people | C16: =SUMPRODUCT(('Pod Library'!$B$5:$B$160=1)*(ABS('Pod Library'!$K$5:$K$160*2-ROUND('Pod Library'!$K$5:$K$160*2,0))>0.01))+SUMPRODUCT(('Horizontal Teams'!$B$5:$B$120=1)*(ABS('Horizontal Teams'!$J$5:$J$120*2-ROUND('Horizontal Teams'!$J$5:$J$120*2,0))>0.01)) | D16: =SUMPRODUCT(('Pod Library'!$B$5:$B$160=2)*(ABS('Pod Library'!$K$5:$K$160*2-ROUND('Pod Library'!$K$5:$K$160*2,0))>0.01))+SUMPRODUCT(('Horizontal Teams'!$B$5:$B$120=2)*(ABS('Horizontal Teams'!$J$5:$J$120*2-ROUND('Horizontal Teams'!$J$5:$J$120*2,0))>0.01)) | E16: =SUMPRODUCT(('Pod Library'!$B$5:$B$160=3)*(ABS('Pod Library'!$K$5:$K$160*2-ROUND('Pod Library'!$K$5:$K$160*2,0))>0.01))+SUMPRODUCT(('Horizontal Teams'!$B$5:$B$120=3)*(ABS('Horizontal Teams'!$J$5:$J$120*2-ROUND('Horizontal Teams'!$J$5:$J$120*2,0))>0.01)) | F16: =SUMPRODUCT(('Pod Library'!$B$5:$B$160=4)*(ABS('Pod Library'!$K$5:$K$160*2-ROUND('Pod Library'!$K$5:$K$160*2,0))>0.01))+SUMPRODUCT(('Horizontal Teams'!$B$5:$B$120=4)*(ABS('Horizontal Teams'!$J$5:$J$120*2-ROUND('Horizontal Teams'!$J$5:$J$120*2,0))>0.01)) | G16: =SUMPRODUCT(('Pod Library'!$B$5:$B$160=5)*(ABS('Pod Library'!$K$5:$K$160*2-ROUND('Pod Library'!$K$5:$K$160*2,0))>0.01))+SUMPRODUCT(('Horizontal Teams'!$B$5:$B$120=5)*(ABS('Horizontal Teams'!$J$5:$J$120*2-ROUND('Horizontal Teams'!$J$5:$J$120*2,0))>0.01)) | H16: =0 | I16: =IF(SUM(C16:G16)=0,"OK","CHECK") | J16: Column K of the Pod Library and column J of Horizontal Teams are the people you hire for that role across the whole block. Every one is a whole number, or a half where one person covers two units INSIDE this domain. The seat ratio beside it is the modelling quantity and will not always be round — on a 28-team block, nine engineers is a ratio of 0.32.
B17: Horizontal roles that have fallen below 0.02 FTE | C17: =COUNTIFS('Horizontal Teams'!$B$5:$B$120,1,'Horizontal Teams'!$I$5:$I$120,"<0.02") | D17: =COUNTIFS('Horizontal Teams'!$B$5:$B$120,2,'Horizontal Teams'!$I$5:$I$120,"<0.02") | E17: =COUNTIFS('Horizontal Teams'!$B$5:$B$120,3,'Horizontal Teams'!$I$5:$I$120,"<0.02") | F17: =COUNTIFS('Horizontal Teams'!$B$5:$B$120,4,'Horizontal Teams'!$I$5:$I$120,"<0.02") | G17: =COUNTIFS('Horizontal Teams'!$B$5:$B$120,5,'Horizontal Teams'!$I$5:$I$120,"<0.02") | H17: =0 | I17: =IF(SUM(C17:G17)=0,"OK","CHECK") | J17: A domain cannot run without a delivery head, a service manager or an architect. If a role must genuinely end, delete the row rather than leaving it at zero.
B18: Year-1 reconciliation to Appendix 3 — worst line | C18: ='Team Build-Up'!E32 | H18: ± 2.6 | I18: =IF(ABS(C18)<=2.6,"OK","CHECK") | J18: Year 1 must reproduce the client's own numbers: effort, the sourcing split, all three locations and all six role lines. The tolerance is ± 2.6 because seats sit on a 0.5 grid and a Year-1 team seat carries a multiplier of 5 — one grid step is 2.5 people. That is the deliberate price of an anatomy that can be staffed. Moving a seat between bands is free; moving it between ROLE, LOCATION or SOURCING is what actually breaks this.
A20: C. WHAT GOES STALE AND WILL NOT WARN YOU
B21: • SOURCING & PRODUCTIVITY is static. It is produced outside Excel by the per-sourcing solver and pasted in. If you change seat counts, the pool ceilings, the organic-convergence table and the transfer solve on that sheet no longer describe this roster. Re-run the solver or treat the sheet as superseded.
B22: • SIT LOADING is static for the same reason. Re-generate it after any seat change, or the requisition plan will not match the ledger.
B23: • The TRANSFER on the Logic Tree is a typed input (rows 65-66), sized on the Year-3 exit position produced by the solver. Change the Year-3 roster materially and the transfer needs re-sizing, or the 50:50 will not land.
B24: • THE RULE OF THUMB. Re-banding a seat, renaming it, or moving it between pods is safe. Changing its ROLE, LOCATION or SOURCING is not — those are the attributes Year 1 reconciles on and the guardrails measure.

Sheet Logic Tree
A1: Logic Tree — ten parametric drivers, five years
A2: Amber cells are inputs. Everything else re-derives. Section F is rebuilt on the measured day-1 position.
A4: A. BASELINE — Appendix 3 v5, read and never edited
B5: Domain | C5: Storage and Preservation Related
B6: Applications | C6: 15
B7: Total effort (units) | C7: 106.0802
B8: Current FTC reported (Capgemini + partner) | C8: 69.4261 | D8: 7 | E8: — of which FSI (partner) | J8: FSI IS 7.0 OF THE 69.4261. Appendix 3 v5 reports the vendor as a single FTC number, so the partner sits inside it. The seven seats are EAI 12117 (K2) 2 · 13453 (POS-IMS) 2 · 9947 (W13WEP-JPN) 2 · 11604 (JP-RPASS) 1. Two of the seven are held in the horizontal control cell in Years 1-3 and one in Years 4-5; the rest sit in the value-stream team that owns the application.
B9: Current FTE | C9: 25.6542
B10: Current MGCC | C10: 11
B11: — of which onshore Tokyo | C11: 62.4636 | J11: 17.96 of the 106.08 units are already away from Tokyo — 6.96 offshore on the Capgemini side and 11.00 in MGCC. 62.46 vendor units are in Tokyo today, and eleven of the fifteen applications run on Japanese-language specifications.
B12: — of which offshore | C12: 6.9625
B13: — of which nearshore | C13: 0
B14: — of which onsite | C14: 0
B15: Role: BSA | C15: 8.6415
B16: Role: Developer | C16: 45.3887 | J16: All six role lines are populated for this domain and are used exactly as reported. No restatement was needed.
B17: Role: Tester | C17: 11.775
B18: Role: Maintenance | C18: 3.4833
B19: Role: PM | C19: 0.1375
B20: Role: Other | C20: 0
B21: AD effort (% of PRJ weighted) | C21: 88.4585
B22: Appendix 3 Year-3 target, each side | C22: 53.0464
B23: Ratio today — Capgemini share | C23: =C8/(C8+C9+C10)
B24: OFFSHORE TODAY — whole team, measured | C24: =(C12+C13+C10)/C7 | J24: 16.94% on day one. That is the measured start, not an assumption, and it is the number the whole offshore case has to move. The design closes the entire gap to the 54.73% ceiling by Year 5.
A26: B. ARCHETYPE MIX — from the Golden Application Inventory v4
B27: Archetype | C27: Name | D27: Apps | E27: Effort | F27: Share | G27: AI ceiling | H27: Offshore ceiling
B28: D | C28: Distributed-proven | D28: 1 | E28: 62.6424 | F28: =E28/$E$33 | G28: 0.4825 | H28: 0.78
B29: J | C29: Japan-locked | D29: 5 | E29: 34.1612 | F29: =E29/$E$33 | G29: 0.304 | H29: 0.12
B30: T | C30: Long tail | D30: 9 | E30: 9.2767 | F30: =E30/$E$33 | G30: 0.39 | H30: 0.55
C33: Total | D33: =SUM(D28:D32) | E33: =SUM(E28:E32) | F33: =SUM(F28:F32)
B34: APPLICABLE AI CEILING | C34: =SUMPRODUCT($E$28:$E$32,$G$28:$G$32)/$E$33 | J34: 41.69% on the golden phase mix. One D application at a 48.25% ceiling carries 59% of the effort; the five J applications behind it carry 30.4% and the nine T applications 39%. No domain-specific override is applied.
B35: APPLICABLE OFFSHORE CEILING | C35: =SUMPRODUCT($E$28:$E$32,$H$28:$H$32)/$E$33 | J35: 54.73%. K2 alone carries a 78% ceiling, but the five Japan-locked applications carry 12% and the long tail 55%. This is the hard constraint in this 領域 and the design now closes all of it.
A37: C. REALISATION AND THE NON-AI COMPONENTS
B38: Driver | C38: Year 1 | D38: Year 2 | E38: Year 3 | F38: Year 4 | G38: Year 5 | H38: Basis
B39: AI realisation — share of ceiling | C39: 0.22 | D39: 0.5 | E39: 0.68 | F39: 0.79 | G39: 0.86 | J39: Adoption, guardrails and substrate maturity, held DELIBERATELY BELOW the portfolio curve. K2 is 59% of this domain and its rules are carried in Japanese-language specifications and a hand-built VB.NET workflow; the constraint on AI realisation here is domain knowledge, not tooling. Capped at 86% in Year 5 rather than 90%.
B40: Classical ADM productivity, cumulative | C40: 0.02 | D40: 0.05 | E40: 0.07 | F40: 0.09 | G40: 0.11 | J40: Standardisation, defect reduction, shift-left.
B41: Operating-model productivity, RAW | C41: 0.03 | D41: 0.06 | E41: 0.08 | F41: 0.1 | G41: 0.12 | J41: Pod consolidation and one release train — only available where the stream is agile.
B42: Agile share of the domain → from the Delivery Mode sheet | C42: ='Delivery Mode'!C18 | D42: ='Delivery Mode'!D18 | E42: ='Delivery Mode'!E18 | F42: ='Delivery Mode'!F18 | G42: ='Delivery Mode'!G18
B43: Operating-model productivity, APPLIED = raw × agile share × span-of-control factor | C43: =C41*C42*C61 | D43: =D41*D42*D61 | E43: =E41*E42*E61 | F43: =F41*F42*F61 | G43: =G41*G42*G61 | J43: Scaling by the agile share is what makes the operating-model gain earned rather than assumed. Payment & Records never converts — fourteen Japanese-specification waterfall applications run as a waterfall team to Year 5 — so the agile share can never exceed K2’s 59.05% share of the estate. That caps the operating-model gain at 7.1% of its raw value by Year 5.
B44: AI-attributable productivity | C44: =$C$34*C39 | D44: =$C$34*D39 | E44: =$C$34*E39 | F44: =$C$34*F39 | G44: =$C$34*G39
B45: CAPABILITY EARNED by end of year | C45: =1-(1-C44)*(1-C40)*(1-C43) | D45: =1-(1-D44)*(1-D40)*(1-D43) | E45: =1-(1-E44)*(1-E40)*(1-E43) | F45: =1-(1-F44)*(1-F40)*(1-F43) | G45: =1-(1-G44)*(1-G40)*(1-G43)
...

Sheet Sourcing & Productivity
A1: Sourcing and productivity — the same chain, applied differently to each population
A2: Productivity is not one number applied to everybody. The four populations do different work and we do not control all four, so each carries its own AI ceiling and its own adoption factor. This sheet is regenerated from the restated two-stream, team-only roster.
A4: A. WHY ONE RATE CANNOT APPLY TO ALL THREE — the Year-1 role mix
B5: Population | C5: Heads Y1 | D5: BSA | E5: Developer | F5: Tester | G5: Maint.
B6: FTC · Capgemini payroll | C6: 62 | D6: 0.11290323 | E6: 0.52419355 | F6: 0.20967742 | G6: 0.072580645 | I6: MetLife’s own people are governance, domain SME and product ownership. MGCC is build, test and application support. FSI is Japanese-specification development and analysis on four named applications. They are not doing the same work, so they cannot carry the same productivity rate.
B7: PT · Partner (sub-contracted) | C7: 7 | D7: 0.21428571 | E7: 0.5 | F7: 0 | G7: 0.28571429
B8: FTE · MetLife Japan | C8: 26 | D8: 0.28846154 | E8: 0 | F8: 0 | G8: 0.19230769
B9: MGCC · MetLife MGCC | C9: 11 | D9: 0 | E9: 0.81818182 | F9: 0.18181818 | G9: 0
A11: B. EACH POPULATION'S OWN AI CEILING AND ADOPTION — INPUT
B12: Population | C12: Own AI ceiling | D12: Adoption | E12: Effective ceiling | F12: vs domain blend
B13: FTC · Capgemini payroll | C13: 0.4345 | D13: 1 | E13: 0.4345 | F13: 0.0176 | I13: ADOPTION is the share of the ceiling each population can actually realise, and it is a judgement about AUTHORITY, not capability. We build the tooling, set the ways of working and mandate them on our own payroll — so 1.00. Everything below that is somebody else’s decision. The four ceilings are scaled so that the Year-1 head-weighted blend reproduces the Logic Tree’s 41.69%.
B14: PT · Partner (sub-contracted) | C14: 0.4211 | D14: 0.85 | E14: 0.3579 | F14: -0.059
B15: FTE · MetLife Japan | C15: 0.3591 | D15: 0.55 | E15: 0.1975 | F15: -0.2194
B16: MGCC · MetLife MGCC | C16: 0.4517 | D16: 0.8 | E16: 0.3613 | F16: -0.0556
B17: Domain blended ceiling (the headline commitment, from the Logic Tree) | C17: 0.4169
B18: Only the AI gate is scaled. Classical ADM productivity attaches to the work and the operating-model gain attaches to the delivery unit, so both flow to every population regardless of employer.
A20: C. WHAT EACH POPULATION IS THEREFORE ASKED TO DELIVER
B21: Applied to staffing | C21: Year 1 | D21: Year 2 | E21: Year 3 | F21: Year 4 | G21: Year 5
B22: FTC · Capgemini payroll | C22: 0 | D22: 0.2032 | E22: 0.3278 | F22: 0.4051 | G22: 0.4583 | I22: The headline commitment is 44.6% by Year 5 — deliberately below the portfolio, because K2 is 59% of this domain and its business rules live in Japanese-language specifications, and because the fourteen satellites never convert to agile. What has changed is that the commitment is no longer assumed to fall equally on all four populations.
B23: PT · Partner (sub-contracted) | C23: 0 | D23: 0.1775 | E23: 0.2871 | F23: 0.356 | G23: 0.4049
B24: FTE · MetLife Japan | C24: 0 | D24: 0.1236 | E24: 0.2019 | F24: 0.2532 | G24: 0.2933
B25: MGCC · MetLife MGCC | C25: 0 | D25: 0.1786 | E25: 0.2889 | F25: 0.3582 | G25: 0.4073
B26: Whole-domain commitment (the headline) | C26: 0 | D26: 0.1973 | E26: 0.3185 | F26: 0.3938 | G26: 0.446
A28: D. THE THREE-WAY COMMITMENT SPLIT
B29: CAPGEMINI COMMITS | C29: Our own headcount reduction, on our own payroll, on tooling and ways of working we control. This is contractible and we should contract it.
B30: METLIFE MUST DELIVER | C30: The reduction of MetLife Japan and MGCC headcount. We size it, we enable it and we report it — but redeploying MetLife's own people is MetLife's decision, and MGCC runs to its own utilisation targets. This should be a joint commitment with named owners, not a Capgemini SLA.
B31: JOINTLY DEPENDENT | C31: AI adoption on MetLife's side: tooling access, shared standards, common telemetry, and the substrate being used rather than merely available. If adoption lands below the factors in section B, the whole-team headcount misses even if Capgemini delivers in full.
A33: E. ORGANIC CONVERGENCE TO 50:50 — before any transfer
B34: Measure | C34: Year 1 | D34: Year 2 | E34: Year 3 | F34: Year 4 | G34: Year 5
B35: MetLife Japan (FTE) — own curve | C35: 26 | D35: 21 | E35: 17.5 | F35: 17.5 | G35: 14 | I35: MetLife’s populations follow their own slower curves; MGCC grows as a share as offshore work lands there. Capgemini absorbs the balance, which means we shrink our own book faster than productivity alone would justify. That extra reduction is a deliberate commercial choice to reach the ratio organically rather than by transferring people.
B36: MetLife MGCC — own curve | C36: 11 | D36: 13 | E36: 15 | F36: 14 | G36: 13.5
B37: Partner — per the partner plan | C37: 7 | D37: 7 | E37: 6 | F37: 5 | G37: 4
B38: Capgemini — absorbs the balance | C38: 62 | D38: 44 | E38: 34 | F38: 28 | G38: 27
B39: TOTAL = the headline commitment | C39: 106 | D39: 85 | E39: 72.5 | F39: 64.5 | G39: 58.5
B40: RATIO — Capgemini share | C40: 0.6509 | D40: 0.6 | E40: 0.5517 | F40: 0.5116 | G40: 0.5299
B41: — of which productivity-driven | C41: 0 | D41: 0.1973 | E41: 0.3185 | F41: 0.3938 | G41: 0.446
B42: — of which RATIO-DRIVEN: fall in the Capgemini share since Year 1 | C42: 0 | D42: 0.0509 | E42: 0.0992 | F42: 0.1393 | G42: 0.121
B44: This is the mechanism that halves the transfer. Reaching the ratio by shrinking our own book is cheaper, lower-risk and entirely within our control; a transfer of employment is neither.
A46: F. THE GUARDRAILS — where organic convergence has to stop
B47: Test | C47: Year 1 | D47: Year 2 | E47: Year 3 | F47: Year 4 | G47: Year 5 | H47: Floor
...

Sheet Delivery Mode
A1: Delivery mode — measured per application, and the conversion that never happens
A2: Appendix 3 v5 supplies the development method for fourteen of the fifteen applications. K2 and DSP are agile — 63.6 of the 106.1 units — and the other twelve are waterfall. The domain is now modelled on that split: K2 is its own stream and converts at Q2; the fourteen satellites are one waterfall team that runs to Year 5 without converting at all.
A4: A. MODE TODAY AND TARGET, BY VALUE STREAM — INPUT
B5: Value stream | C5: Effort | D5: Archetype | E5: Mode today | F5: Agile from | G5: Why
B6: POSW · Policy Owner Servicing Work Flow (K2 only) | C6: 62.6424 | D6: D | E6: Agile | F6: Q2 | G6: K2 is 59.05% of the domain on its own and carries 34.1 of our inherited people. Agile already, hybrid specifications, 78% offshore ceiling. | I6: The mode column is MetLife’s own data. The two streams are now K2 (1 application, 62.642 units) and everything else (14 applications, 43.438 units). K2 converts at Q2. The satellites do not convert — that is the input to argue about, and it is the reason productivity here is capped below the portfolio.
B7: POSR · Policy Owner Servicing Payment & Records (14 applications) | C7: 43.4378 | D7: J / T | E7: Waterfall | F7: never | G7: Eleven Japanese-specification applications, five of them Japan-locked at a 12% offshore ceiling, two marked Retire. Runs as a waterfall team for all five years.
B8: Total | C8: =SUM(C6:C7)
A10: B. AGILE SHARE BY YEAR — computed from the quarter each stream converts
B11: Value stream | C11: Year 1 | D11: Year 2 | E11: Year 3 | F11: Year 4 | G11: Year 5
B12: POSW | C12: 0.75 | D12: 1 | E12: 1 | F12: 1 | G12: 1
B13: POSP | C13: 0 | D13: 0 | E13: 0 | F13: 0 | G13: 0
B14: Effort-weighted agile share of the domain | C14: =SUMPRODUCT($C$6:$C$7,C12:C13)/$C$8 | D14: =SUMPRODUCT($C$6:$C$7,D12:D13)/$C$8 | E14: =SUMPRODUCT($C$6:$C$7,E12:E13)/$C$8 | F14: =SUMPRODUCT($C$6:$C$7,F12:F13)/$C$8 | G14: =SUMPRODUCT($C$6:$C$7,G12:G13)/$C$8
B16: Delivery units this produces
B17: — agile PODS (none in this domain) | C17: 0 | D17: 0 | E17: 0 | F17: 0 | G17: 0
B18: — agile share (feeds the Logic Tree) | C18: =C14 | D18: =D14 | E18: =E14 | F18: =F14 | G18: =G14
B19: — TEAMS of 12 (instances) | C19: 7 | D19: 6 | E19: 5 | F19: 4 | G19: 4
A21: C. WHY THIS MATTERS TO THE NUMBER
B22: • Operating-model productivity — pod consolidation, one release train, span of control — is only available where the stream actually runs agile, and here that is K2 and nothing else. Scaling the 3 / 6 / 8 / 10 / 12% curve by the agile share (44.3% in Year 1, 59.05% thereafter) and by the span-of-control factor cuts the Year-5 gain from 12.0% to 7.0%. This is the single largest reason the productivity commitment here is 44.6% and not 50%.
B23: • Every delivery unit is a TEAM of 12 seats, in every year, in both streams. Team size never moves; instances retire instead — 4+3 in Year 1, then 4+2, 3+2, 3+1 and 3+1. Both anatomies carry MGCC seats from day one, which is what makes this domain’s offshore movement cheap: the substrate is already there.
B24: • Year 4 is the structural break: the last Payment & Records team retires and its residual run work moves to the horizontal layer, which is why horizontal rises from 12.5 to 16.5 that year before falling to 10.5 in Year 5.
B25: • DECIDE whether Payment & Records ever converts. Holding it as waterfall to Year 5 is the conservative reading and costs about 4 points of Year-5 capability. If MetLife will accept agile on even half of those fourteen applications from Year 3, the commitment moves back above 47%.

Sheet AMS & Ticket Load
A1: AMS and ticket load — the run team sized from evidence, for the first time
A2: 1,145 incidents and 2,071 changes over 32 months, from Appendix 3 v5.
A4: A. RECORDED VOLUMES — 1 Jan 2024 to 31 Aug 2026
B5: Measure | C5: Volume | D5: Per month | E5: Per unit of effort | F5: Share
B6: P1 — critical | C6: 0 | D6: =C6/$C$17 | E6: =C6/'Logic Tree'!$C$7 | F6: =C6/$C$11 | I6: No P1 or P2 incidents at all in 32 months and 71% of incidents at P5. The estate is stable; the cost is in changing it, not in keeping it up.
B7: P2 — high | C7: 0 | D7: =C7/$C$17 | E7: =C7/'Logic Tree'!$C$7 | F7: =C7/$C$11
B8: P3 — medium | C8: 179 | D8: =C8/$C$17 | E8: =C8/'Logic Tree'!$C$7 | F8: =C8/$C$11
B9: P4 — low | C9: 153 | D9: =C9/$C$17 | E9: =C9/'Logic Tree'!$C$7 | F9: =C9/$C$11
B10: P5 — informational | C10: 813 | D10: =C10/$C$17 | E10: =C10/'Logic Tree'!$C$7 | F10: =C10/$C$11
B11: All incidents | C11: =SUM(C6:C10) | D11: =C11/$C$17 | E11: =C11/'Logic Tree'!$C$7
B12: Emergency change | C12: 115 | D12: =C12/$C$17 | E12: =C12/'Logic Tree'!$C$7 | F12: =C12/$C$15 | I12: 84% Standard and 4.3% Emergency. A high-volume, low-severity, highly repeatable change profile — the best automation case in the portfolio.
B13: Normal change | C13: 233 | D13: =C13/$C$17 | E13: =C13/'Logic Tree'!$C$7 | F13: =C13/$C$15
B14: Standard change | C14: 1723 | D14: =C14/$C$17 | E14: =C14/'Logic Tree'!$C$7 | F14: =C14/$C$15
B15: All changes | C15: =SUM(C12:C14) | D15: =C15/$C$17 | E15: =C15/'Logic Tree'!$C$7
B17: Observation window, months | C17: 32
A19: B. SIZING THE RUN TEAM — three independent bases, triangulated
B20: Basis | C20: Value | D20: Reading
B21: A. Maintenance role reported in Appendix 3 v5 | C21: ='Logic Tree'!C18 | D21: MetLife's own HEADCOUNT view. Populated here, unlike Contract Management, so it is usable.
B22: B. Run effort implied by the AD / AMS split = (1 − AD share) x effort | C22: ='Logic Tree'!C7-'Logic Tree'!C21 | D22: MetLife's own EFFORT view: 13.5% of 100.765 units. It implies 2.4 times the run population the role line does, and both numbers come from the same spreadsheet.
B23: Total demand items per month (incidents + changes) | C23: =(C11+C15)/C17 | D23: 2,536 items in 32 months — 25.2 per unit of effort against 14.6 on Sales. High for a three-application estate, and 84% of the changes are Standard.
B24: C. Throughput implied by basis A — items per person per month | C24: =IFERROR(C23/C21,0) | D24: If the role line is right, each run person absorbs this many items a month.
B25: C. Throughput implied by basis B | C25: =IFERROR(C23/C22,0) | D25: If the effort split is right, this is the rate. Industry L2 throughput on a modern data stack is 40 to 80 items per person per month; both of these sit far below it, which says these items carry investigation rather than triage.
B26: Run-facing seats in the Year-1 roster (Maintenance + Tester, all sourcing) | C26: ='Team Build-Up'!C64+'Team Build-Up'!C63 | D26: Model output. Sized on the role line, which is the binding Year-1 reconciliation constraint, and reported here against the other two bases rather than averaged with them.
A28: C. WHAT THE TICKET DATA CHANGES
B29: • MetLife's two views of the run population disagree by a factor of 2.4. The Maintenance role line says 5.67 units; the AD / AMS effort split says 13.64. This model follows the role line, because Year 1 has to reconcile to Appendix 3 line by line — but the difference is 8 people and it is a real commercial exposure. PUT THIS TO METLIFE before the AMS price is fixed.
B30: • The severity profile is benign and the change profile is not. No P1 or P2 incidents in 32 months and 71% of incidents at P5 — this estate is stable. But 1,730 changes on 100.8 units, 84% of them Standard, is a high change rate, and Standard changes on a cloud data platform are exactly what pipeline automation and a release train remove. That is where the operating-model productivity in this domain actually comes from.
B31: • Ticket density is 25.2 items per unit of effort against 14.6 on Sales — the highest of the domains modelled so far. Combined with a 13.5% run share it suggests run work is sitting inside the Developer line, which is the same pattern Sales shows and the reason this cross-check is worth running on every domain.
B32: • DO ask MetLife which of the two run figures governs, and ask for the ticket-to-effort mapping behind the AD / AMS split. On a three-application domain this is a short conversation with a material price attached.

Sheet Inventory
A1: Inventory — the 15 Storage and Preservation Related applications from Appendix 3 v5
A2: Classified by the six-rule classifier on the Golden Application Inventory v4.
B4: Application | C4: Arch | D4: Effort | E4: FTC | F4: FTE | G4: Onshore | H4: Nearshore | I4: Nearsh % | J4: BSA | K4: Dev | L4: AD % | M4: Crit | N4: Method | O4: Spec lang | P4: Lines of code | Q4: Batches | R4: Incidents | S4: Changes | T4: Primary code language | U4: Value stream | V4: FSI FTC | W4: EAI ID
B5: K2 | C5: D | D5: 62.6424 | E5: 36.1049 | F5: 15.5375 | G5: 29.959 | H5: 0 | I5: =IFERROR($H5/$D5,0) | J5: 8.6415 | K5: 13.1092 | L5: 0.8631983 | M5: Y | N5: Agile | O5: Hybrid | P5: 0 | Q5: 37 | R5: 350 | S5: 794 | T5: VB.NET | U5: POSW | V5: 2 | W5: 12117
B6: POS-IMS | C6: J | D6: 9.9625 | E6: 9.6625 | F6: 0.3 | G6: 9.6625 | H6: 0 | I6: =IFERROR($H6/$D6,0) | J6: 0 | K6: 8.8625 | L6: 0.90440252 | M6: N | N6: Waterfall | O6: JP | P6: 1972920 | Q6: 57 | R6: 124 | S6: 199 | T6: VB.NET; JAVA | U6: POSR | V6: 2 | W6: 13453
B7: JP-RPASS | C7: J | D7: 9.7375 | E7: 5.6625 | F7: 4.075 | G7: 5.6625 | H7: 0 | I7: =IFERROR($H7/$D7,0) | J7: 0 | K7: 5.6625 | L7: 0.8973038 | M7: N | N7: Waterfall | O7: JP | P7: 0 | Q7: 44 | R7: 147 | S7: 254 | T7: Other#COTS from BluePrism | U7: POSR | V7: 1 | W7: 11604
B8: W13WEP-JPN | C8: J | D8: 7.185 | E8: 6.0308 | F8: 1.1542 | G8: 6.0308 | H8: 0 | I8: =IFERROR($H8/$D8,0) | J8: 0 | K8: 6.0308 | L8: 0.75904635 | M8: Y | N8: Waterfall | O8: JP | P8: 585527 | Q8: 57 | R8: 216 | S8: 389 | T8: JAVA | U8: POSR | V8: 2 | W8: 9947
B9: POS Batch | C9: J | D9: 4.2762 | E9: 4.0262 | F9: 0.25 | G9: 3.2512 | H9: 0 | I9: =IFERROR($H9/$D9,0) | J9: 0 | K9: 4.0262 | L9: 0.90909091 | M9: N | N9: Waterfall | O9: Hybrid | P9: 0 | Q9: 0 | R9: 8 | S9: 41 | T9: JAVA | U9: POSR | V9: 0
B10: JP-PCI-RPASS | C10: J | D10: 3 | E10: 1 | F10: 2 | G10: 1 | H10: 0 | I10: =IFERROR($H10/$D10,0) | J10: 0 | K10: 1 | L10: 0 | M10: N | N10: Waterfall | O10: JP | P10: 0 | Q10: 0 | R10: 0 | S10: 3 | T10: Other#This is coded within blueprism | U10: POSR | V10: 0
B11: C03PCA-JPN | C11: T | D11: 2.8862 | E11: 2.6362 | F11: 0.25 | G11: 2.6363 | H11: 0 | I11: =IFERROR($H11/$D11,0) | J11: 0 | K11: 2.6363 | L11: 0.90298831 | M11: N | N11: Waterfall | O11: JP | P11: 311649 | Q11: 9 | R11: 45 | S11: 38 | T11: VB | U11: POSR | V11: 0
B12: C03WRD-JPN | C12: T | D12: 2.5258 | E12: 2.2883 | F12: 0.2375 | G12: 2.2883 | H12: 0 | I12: =IFERROR($H12/$D12,0) | J12: 0 | K12: 2.1883 | L12: 0.90102276 | M12: Y | N12: Waterfall | O12: JP | P12: 125022 | Q12: 0 | R12: 58 | S12: 32 | T12: VB.NET | U12: POSR | V12: 0
B13: WPMAUD-JPN | C13: T | D13: 1.1729 | E13: 1.0229 | F13: 0.15 | G13: 1.0229 | H13: 0 | I13: =IFERROR($H13/$D13,0) | J13: 0 | K13: 1.0229 | L13: 0.42806394 | M13: N | N13: Waterfall | O13: JP | P13: 649133 | Q13: 32 | R13: 108 | S13: 196 | T13: JAVA | U13: POSR | V13: 0
B14: DSP | C14: T | D14: 1 | E14: 0 | F14: 1 | G14: 0 | H14: 0 | I14: =IFERROR($H14/$D14,0) | J14: 0 | K14: 0 | L14: 1 | M14: N | N14: Agile | O14: Hybrid | P14: 0 | Q14: 0 | R14: 1 | S14: 2 | T14: PL/SQL | U14: POSR | V14: 0
B15: Scan Manager | C15: T | D15: 0.5958 | E15: 0.3958 | F15: 0.2 | G15: 0.3542 | H15: 0 | I15: =IFERROR($H15/$D15,0) | J15: 0 | K15: 0.3542 | L15: 0.66433566 | M15: N | N15: Waterfall | O15: JP | P15: 16693 | Q15: 4 | R15: 3 | S15: 7 | T15: VB.NET | U15: POSR | V15: 0
B16: W03CCP-JPN | C16: T | D16: 0.3542 | E16: 0.2542 | F16: 0.1 | G16: 0.2542 | H16: 0 | I16: =IFERROR($H16/$D16,0) | J16: 0 | K16: 0.2542 | L16: 0.56470588 | M16: N | N16: Waterfall | O16: JP | P16: 22000 | Q16: 7 | R16: 4 | S16: 51 | T16: JAVA | U16: POSR | V16: 0
B17: C03WRE-JPN | C17: T | D17: 0.3333 | E17: 0.1333 | F17: 0.2 | G17: 0.1333 | H17: 0 | I17: =IFERROR($H17/$D17,0) | J17: 0 | K17: 0.0333 | L17: 0.3258427 | M17: Y | N17: Waterfall | O17: JP | P17: 183197 | Q17: 21 | R17: 69 | S17: 43 | T17: VB.NET | U17: POSR | V17: 0
B18: W03PIU-JPN | C18: T | D18: 0.3083 | E18: 0.2083 | F18: 0.1 | G18: 0.2083 | H18: 0 | I18: =IFERROR($H18/$D18,0) | J18: 0 | K18: 0.2083 | L18: 0.67567568 | M18: N | N18: Waterfall | O18: JP | P18: 228784 | Q18: 1 | R18: 12 | S18: 22 | T18: JAVA | U18: POSR | V18: 0
B19: JP-DB2-CONNECT | C19: T | D19: 0.1 | E19: 0 | F19: 0.1 | G19: 0 | H19: 0 | I19: =IFERROR($H19/$D19,0) | J19: 0 | K19: 0 | L19: 0 | M19: N | N19: N/A | O19: N/A | P19: 0 | Q19: 0 | R19: 0 | S19: 0 | T19: Other#COTS | U19: POSR | V19: 0
B20: TOTAL | D20: =SUM(D5:D19) | E20: =SUM(E5:E19) | F20: =SUM(F5:F19) | G20: =SUM(G5:G19) | H20: =SUM(H5:H19) | J20: =SUM(J5:J19) | K20: =SUM(K5:K19) | P20: =SUM(P5:P19) | Q20: =SUM(Q5:Q19) | R20: =SUM(R5:R19) | S20: =SUM(S5:S19) | U20: — | V20: =SUM(V5:V19)
B22: Fourteen of the fifteen carry a development method and a specification language; JP-DB2-CONNECT is a 0.10-unit MetLife-only line with neither. Eleven run on Japanese specifications and only two are cloud-flagged — the least modern stack of the 領域 modelled. Code volume totals 4.09 million lines, 48% of it in POS-IMS. K2 alone is 62.6 of the 106.1 units, which is why it is now a value stream on its own and the other fourteen are the second. Columns U-W are new: the stream each application sits in, the FSI sub-contracted FTC on it, and the EAI ID for the four applications FSI holds. Note that Appendix 3 v5 lists K2 twice; the duplicate line is excluded here, as MetLife’s own total does. Two applications — JP-PCI-RPASS and C03WRE-JPN, 3.3 units between them — are marked Retire in the new disposition columns; see the README.

Sheet Value Streams
A1: Delivery streams — two streams: K2, and the fourteen satellites
A2: RESTATED. The estate splits on the one thing that actually differentiates it: K2 or not K2. Policy Owner Servicing Work Flow now carries K2 alone — one application, 62.642 units, 59.05% of the domain, the only archetype-D and the only agile line. Policy Owner Servicing Payment & Records carries the other fourteen — 43.438 units of Japanese-specification waterfall. Both run as TEAMS; there are no pods in this domain.
B4: Code | C4: Value stream | D4: Apps | E4: Effort | F4: Arch | G4: Mode today | H4: Agile from | I4: Y1 pods | J4: Y2 | K4: Y3 | L4: Y4 | M4: Y5 | N4: Vendor position today
B5: POSW | C5: Policy Owner Servicing Work Flow | D5: 1 | E5: 62.6424 | F5: D | G5: Agile | H5: Q2 | I5: 4t | J5: 4t | K5: 3t | L5: 3t | M5: 3t | N5: CG 34.1 · FSI 2.0
B6: POSR | C6: Policy Owner Servicing Payment & Records | D6: 14 | E6: 43.4378 | F6: J / T | G6: Waterfall | H6: n/a | I6: 3t | J6: 2t | K6: 2t | L6: 1t | M6: 1t | N6: CG 28.3 · FSI 5.0
C7: Total | D7: =SUM(D5:D6) | E7: =SUM(E5:E6)
B9: Counts read 'team instances'. Every instance is 12 seats, in every year. K2 converts to agile at Q2 and the fourteen satellites never convert — which is the honest reading of eleven Japanese-specification waterfall applications and is what holds this domain’s productivity to 44.6% rather than the portfolio’s 50%+. Five of the seven FSI seats sit in the Payment & Records team (POS-IMS, W13WEP-JPN, JP-RPASS) and two in the Work Flow team (K2); a further 2 partner seats in Years 1-3, 1 in Years 4-5, are held in horizontal team H1 as a control cell.

Sheet Pod Library
A1: Pod library — every TEAM seat, per value stream, with MetLife’s role taxonomy and four sourcing types
A2: INPUT. This domain runs TEAMS only — no pods, in any year. Each value stream carries its own 12-seat team anatomy, instantiated 4+3 / 4+2 / 3+2 / 3+1 / 3+1 times across the five years. Sourcing FTC = Capgemini payroll · PT = FSI, the named incumbent on K2, POS-IMS, W13WEP-JPN and JP-RPASS · FTE = MetLife Japan · MGCC. Only FTC can transfer at the end of Year 3. Column J is the seat ratio inside one team; column K is the people you actually hire across every instance of that team in that year, and every one of them is a whole number or a half.
B4: Year | C4: Unit | D4: Seat | E4: Role detail | F4: Role | G4: Exp | H4: Loc | I4: Sourcing | J4: Count | K4: People in the block
B5: 1 | C5: TEAM | D5: 1 | E5: MetLife Product Owner — K2 | F5: PM | G5: E4 | H5: ON | I5: FTE | J5: 1 | K5: =J5*4
B6: 1 | C6: TEAM | D6: 2 | E6: MetLife Servicing SME — K2 | F6: BSA | G6: E4 | H6: ON | I6: FTE | J6: 1 | K6: =J6*4
B7: 1 | C7: TEAM | D7: 3 | E7: FSI K2 Developer (JP) — EAI 12117 | F7: DEV | G7: E3 | H7: ON | I7: PT | J7: 0.5 | K7: =J7*4
B8: 1 | C8: TEAM | D8: 4 | E8: Business Analyst (bilingual) — K2 | F8: BSA | G8: E3 | H8: ON | I8: FTC | J8: 1 | K8: =J8*4
B9: 1 | C9: TEAM | D9: 5 | E9: Team lead / senior engineer — K2 | F9: DEV | G9: E4 | H9: ON | I9: FTC | J9: 1 | K9: =J9*4
B10: 1 | C10: TEAM | D10: 6 | E10: Solution Architect — K2 | F10: OTH | G10: E4 | H10: ON | I10: FTC | J10: 0.5 | K10: =J10*4
B11: 1 | C11: TEAM | D11: 7 | E11: Senior Workflow Developer (VB.NET) — K2 | F11: DEV | G11: E3 | H11: ON | I11: FTC | J11: 1.5 | K11: =J11*4
B12: 1 | C12: TEAM | D12: 8 | E12: Junior Workflow Developer (VB.NET) — K2 | F12: DEV | G12: E2 | H12: ON | I12: FTC | J12: 1 | K12: =J12*4
B13: 1 | C13: TEAM | D13: 9 | E13: Quality Engineer — K2 | F13: TEST | G13: E2 | H13: ON | I13: FTC | J13: 1 | K13: =J13*4
B14: 1 | C14: TEAM | D14: 10 | E14: Junior Workflow Developer — offshore | F14: DEV | G14: E2 | H14: OFF | I14: FTC | J14: 0.5 | K14: =J14*4
B15: 1 | C15: TEAM | D15: 11 | E15: Junior Quality Engineer — offshore | F15: TEST | G15: E1 | H15: OFF | I15: FTC | J15: 0.5 | K15: =J15*4
B16: 1 | C16: TEAM | D16: 12 | E16: Application Support — offshore | F16: MNT | G16: E2 | H16: OFF | I16: FTC | J16: 0.5 | K16: =J16*4
... B18: 1 | C18: TEAM | D18: 14 | E18: MGCC Test Engineer | F18: TEST | G18: E2 | H18: OFF | I18: MGCC | J18: 0.5 | K18: =J18*4
D19: TEAM size — Year 1 · POSW | J19: =SUM(J5:J18) | K19: =SUM(K5:K18)
B21: 1 | C21: TEAM | D21: 1 | E21: MetLife Application Owner | F21: PM | G21: E4 | H21: ON | I21: FTE | J21: 1 | K21: =J21*3
B22: 1 | C22: TEAM | D22: 2 | E22: MetLife Operations Analyst | F22: MNT | G22: E3 | H22: ON | I22: FTE | J22: 1 | K22: =J22*3
B23: 1 | C23: TEAM | D23: 3 | E23: FSI Senior Developer (JP) — EAI 13453 / 9947 | F23: DEV | G23: E3 | H23: ON | I23: PT | J23: 0.5 | K23: =J23*3
B24: 1 | C24: TEAM | D24: 4 | E24: FSI Business Analyst (JP) — EAI 11604 | F24: BSA | G24: E3 | H24: ON | I24: PT | J24: 0.5 | K24: =J24*3
B25: 1 | C25: TEAM | D25: 5 | E25: Team lead / technical lead | F25: DEV | G25: E4 | H25: ON | I25: FTC | J25: 1 | K25: =J25*3
B26: 1 | C26: TEAM | D26: 6 | E26: Business Analyst (bilingual) | F26: BSA | G26: E3 | H26: ON | I26: FTC | J26: 1 | K26: =J26*3
B27: 1 | C27: TEAM | D27: 7 | E27: Senior Application Developer (VB.NET / Java) | F27: DEV | G27: E3 | H27: ON | I27: FTC | J27: 2.5 | K27: =J27*3
B28: 1 | C28: TEAM | D28: 8 | E28: Junior Application Developer (VB.NET / Java) | F28: DEV | G28: E2 | H28: ON | I28: FTC | J28: 1.5 | K28: =J28*3
B29: 1 | C29: TEAM | D29: 9 | E29: Test Engineer — Tokyo | F29: TEST | G29: E2 | H29: ON | I29: FTC | J29: 2 | K29: =J29*3
B30: 1 | C30: TEAM | D30: 10 | E30: Application Support (L2) — Tokyo | F30: MNT | G30: E2 | H30: ON | I30: FTC | J30: 0.5 | K30: =J30*3
B31: 1 | C31: TEAM | D31: 11 | E31: Junior Application Developer — offshore | F31: DEV | G31: E2 | H31: OFF | I31: FTC | J31: 0.5 | K31: =J31*3
D32: TEAM size — Year 1 · POSR | J32: =SUM(J21:J31) | K32: =SUM(K21:K31)
B34: 2 | C34: TEAM | D34: 1 | E34: MetLife Product Owner — K2 | F34: PM | G34: E4 | H34: ON | I34: FTE | J34: 1 | K34: =J34*4
B35: 2 | C35: TEAM | D35: 2 | E35: MetLife Servicing SME — K2 | F35: BSA | G35: E4 | H35: ON | I35: FTE | J35: 1.5 | K35: =J35*4
B36: 2 | C36: TEAM | D36: 3 | E36: FSI K2 Developer (JP) — EAI 12117 | F36: DEV | G36: E3 | H36: ON | I36: PT | J36: 0.5 | K36: =J36*4
B37: 2 | C37: TEAM | D37: 4 | E37: Business Analyst (bilingual) — K2 | F37: BSA | G37: E3 | H37: ON | I37: FTC | J37: 1 | K37: =J37*4
B38: 2 | C38: TEAM | D38: 5 | E38: Team lead / senior engineer — K2 | F38: DEV | G38: E4 | H38: ON | I38: FTC | J38: 1 | K38: =J38*4
B39: 2 | C39: TEAM | D39: 6 | E39: Solution Architect — K2 | F39: OTH | G39: E4 | H39: ON | I39: FTC | J39: 0.5 | K39: =J39*4
B40: 2 | C40: TEAM | D40: 7 | E40: Senior Workflow Developer (VB.NET) — K2 | F40: DEV | G40: E3 | H40: ON | I40: FTC | J40: 1 | K40: =J40*4
B41: 2 | C41: TEAM | D41: 8 | E41: Junior Workflow Developer (VB.NET) — K2 | F41: DEV | G41: E2 | H41: ON | I41: FTC | J41: 0.5 | K41: =J41*4
B42: 2 | C42: TEAM | D42: 9 | E42: Quality Engineer — K2 | F42: TEST | G42: E2 | H42: ON | I42: FTC | J42: 0.5 | K42: =J42*4
B43: 2 | C43: TEAM | D43: 10 | E43: Junior Workflow Developer — offshore | F43: DEV | G43: E2 | H43: OFF | I43: FTC | J43: 1 | K43: =J43*4
B44: 2 | C44: TEAM | D44: 11 | E44: Junior Quality Engineer — offshore | F44: TEST | G44: E1 | H44: OFF | I44: FTC | J44: 0.5 | K44: =J44*4
...

Sheet Pod Plan
A1: Team plan — how many instances of each value stream’s 12-seat team, per year
A2: INPUT. There are no pods in this domain. Productivity shows up here as instances retiring — 7 teams in Year 1, 6, 5, then 4 for Years 4 and 5 — and never as a team being shrunk below 12 seats.
B4: Year | C4: VS | D4: Value stream | E4: Teams (unused) | F4: Team instances | G4: Units | H4: People
B5: 1 | C5: POSW | D5: Policy Owner Servicing Work Flow | E5: 0 | F5: 4 | G5: =E5+F5 | H5: =F5*SUM('Pod Library'!$J$5:$J$18)
B6: 1 | C6: POSR | D6: Policy Owner Servicing Payment & Records | E6: 0 | F6: 3 | G6: =E6+F6 | H6: =F6*SUM('Pod Library'!$J$21:$J$31)
D7: Year 1 total | E7: =SUM(E5:E6) | F7: =SUM(F5:F6) | G7: =SUM(G5:G6) | H7: =SUM(H5:H6)
B9: 2 | C9: POSW | D9: Policy Owner Servicing Work Flow | E9: 0 | F9: 4 | G9: =E9+F9 | H9: =F9*SUM('Pod Library'!$J$34:$J$47)
B10: 2 | C10: POSR | D10: Policy Owner Servicing Payment & Records | E10: 0 | F10: 2 | G10: =E10+F10 | H10: =F10*SUM('Pod Library'!$J$50:$J$62)
D11: Year 2 total | E11: =SUM(E9:E10) | F11: =SUM(F9:F10) | G11: =SUM(G9:G10) | H11: =SUM(H9:H10)
B13: 3 | C13: POSW | D13: Policy Owner Servicing Work Flow | E13: 0 | F13: 3 | G13: =E13+F13 | H13: =F13*SUM('Pod Library'!$J$65:$J$77)
B14: 3 | C14: POSR | D14: Policy Owner Servicing Payment & Records | E14: 0 | F14: 2 | G14: =E14+F14 | H14: =F14*SUM('Pod Library'!$J$80:$J$92)
D15: Year 3 total | E15: =SUM(E13:E14) | F15: =SUM(F13:F14) | G15: =SUM(G13:G14) | H15: =SUM(H13:H14)
B17: 4 | C17: POSW | D17: Policy Owner Servicing Work Flow | E17: 0 | F17: 3 | G17: =E17+F17 | H17: =F17*SUM('Pod Library'!$J$95:$J$106)
B18: 4 | C18: POSR | D18: Policy Owner Servicing Payment & Records | E18: 0 | F18: 1 | G18: =E18+F18 | H18: =F18*SUM('Pod Library'!$J$109:$J$119)
D19: Year 4 total | E19: =SUM(E17:E18) | F19: =SUM(F17:F18) | G19: =SUM(G17:G18) | H19: =SUM(H17:H18)
B21: 5 | C21: POSW | D21: Policy Owner Servicing Work Flow | E21: 0 | F21: 3 | G21: =E21+F21 | H21: =F21*SUM('Pod Library'!$J$122:$J$133)
B22: 5 | C22: POSR | D22: Policy Owner Servicing Payment & Records | E22: 0 | F22: 1 | G22: =E22+F22 | H22: =F22*SUM('Pod Library'!$J$136:$J$146)
D23: Year 5 total | E23: =SUM(E21:E22) | F23: =SUM(F21:F22) | G23: =SUM(G21:G22) | H23: =SUM(H21:H22)

Sheet Horizontal Teams
A1: Horizontal teams — work that is not stream-bounded
A2: INPUT, defined per year rather than scaled. H1 is run and AMS, and carries the FSI control cell — 2 partner seats in Years 1-3 and 1 in Years 4-5, held outside the delivery teams deliberately so the partner relationship is governed rather than only consumed. H2 is records and quality governance. H3 is delivery leadership and architecture. Year 4 is the year the last Payment & Records team retires and its residual run work lands here, which is why the layer rises that year before falling again in Year 5.
B4: Year | C4: Team | D4: Role | E4: Role detail | F4: Exp | G4: Loc | H4: Sourcing | I4: Count | J4: People in the block
B5: 1 | C5: H1 | D5: MNT | E5: MetLife Operations Analyst | F5: E3 | G5: ON | H5: FTE | I5: 2 | J5: =I5
B6: 1 | C6: H1 | D6: MNT | E6: FSI Production Control cell — K2 / POS-IMS | F6: E3 | G6: ON | H6: PT | I6: 2 | J6: =I6
B7: 1 | C7: H1 | D7: PM | E7: Service Delivery Manager | F7: E5 | G7: ON | H7: FTC | I7: 1 | J7: =I7
B8: 1 | C8: H1 | D8: MNT | E8: Incident & Problem Analyst | F8: E3 | G8: ON | H8: FTC | I8: 1 | J8: =I8
B9: 1 | C9: H1 | D9: OTH | E9: Observability / AIOps Engineer | F9: E3 | G9: OFF | H9: FTC | I9: 1 | J9: =I9
B10: 1 | C10: H1 | D10: DEV | E10: MGCC Platform SRE | F10: E3 | G10: OFF | H10: MGCC | I10: 3 | J10: =I10
B11: 1 | C11: H2 | D11: BSA | E11: MetLife Servicing Governance | F11: E4 | G11: ON | H11: FTE | I11: 1.5 | J11: =I11
B12: 1 | C12: H2 | D12: TEST | E12: Head of Quality Engineering | F12: E4 | G12: ON | H12: FTC | I12: 1 | J12: =I12
B13: 1 | C13: H3 | D13: BSA | E13: MetLife Servicing Owner | F13: E5 | G13: ON | H13: FTE | I13: 2 | J13: =I13
B14: 1 | C14: H3 | D14: PM | E14: MetLife Portfolio Manager | F14: E4 | G14: ON | H14: FTE | I14: 2.5 | J14: =I14
B15: 1 | C15: H3 | D15: PM | E15: MetLife Application Owners — satellites | F15: E4 | G15: ON | H15: FTE | I15: 4 | J15: =I15
B16: 1 | C16: H3 | D16: PM | E16: Domain Delivery Head | F16: E5 | G16: ON | H16: FTC | I16: 0.5 | J16: =I16
B17: 1 | C17: H3 | D17: OTH | E17: Chief Architect — Servicing | F17: E5 | G17: ON | H17: FTC | I17: 0.5 | J17: =I17
E18: Year 1 horizontal total | I18: =SUM(I5:I17) | J18: =SUM(J5:J17)
B20: 2 | C20: H1 | D20: MNT | E20: MetLife Operations Analyst | F20: E3 | G20: ON | H20: FTE | I20: 1 | J20: =I20
B21: 2 | C21: H1 | D21: MNT | E21: FSI Production Control cell — K2 / POS-IMS | F21: E3 | G21: ON | H21: PT | I21: 2 | J21: =I21
B22: 2 | C22: H1 | D22: PM | E22: Service Delivery Manager | F22: E5 | G22: ON | H22: FTC | I22: 0.5 | J22: =I22
B23: 2 | C23: H1 | D23: MNT | E23: Incident & Problem Analyst | F23: E3 | G23: ON | H23: FTC | I23: 1 | J23: =I23
B24: 2 | C24: H1 | D24: OTH | E24: Observability / AIOps Engineer | F24: E3 | G24: OFF | H24: FTC | I24: 1 | J24: =I24
B25: 2 | C25: H1 | D25: DEV | E25: MGCC Platform SRE | F25: E3 | G25: OFF | H25: MGCC | I25: 2 | J25: =I25
B26: 2 | C26: H2 | D26: BSA | E26: MetLife Servicing Governance | F26: E4 | G26: ON | H26: FTE | I26: 1 | J26: =I26
B27: 2 | C27: H2 | D27: TEST | E27: Head of Quality Engineering | F27: E4 | G27: ON | H27: FTC | I27: 0.5 | J27: =I27
B28: 2 | C28: H3 | D28: BSA | E28: MetLife Servicing Owner | F28: E5 | G28: ON | H28: FTE | I28: 1.5 | J28: =I28
B29: 2 | C29: H3 | D29: PM | E29: MetLife Portfolio Manager | F29: E4 | G29: ON | H29: FTE | I29: 1.5 | J29: =I29
B30: 2 | C30: H3 | D30: PM | E30: Domain Delivery Head | F30: E5 | G30: ON | H30: FTC | I30: 0.5 | J30: =I30
B31: 2 | C31: H3 | D31: OTH | E31: Chief Architect — Servicing | F31: E5 | G31: ON | H31: FTC | I31: 0.5 | J31: =I31
E32: Year 2 horizontal total | I32: =SUM(I20:I31) | J32: =SUM(J20:J31)
B34: 3 | C34: H1 | D34: MNT | E34: MetLife Operations Analyst | F34: E3 | G34: ON | H34: FTE | I34: 2 | J34: =I34
B35: 3 | C35: H1 | D35: MNT | E35: FSI Production Control cell — K2 / POS-IMS | F35: E3 | G35: ON | H35: PT | I35: 2 | J35: =I35
B36: 3 | C36: H1 | D36: PM | E36: Service Delivery Manager | F36: E5 | G36: ON | H36: FTC | I36: 0.5 | J36: =I36
B37: 3 | C37: H1 | D37: OTH | E37: Observability / AIOps Engineer | F37: E3 | G37: OFF | H37: FTC | I37: 0.5 | J37: =I37
B38: 3 | C38: H1 | D38: DEV | E38: MGCC Platform SRE | F38: E3 | G38: OFF | H38: MGCC | I38: 2 | J38: =I38
B39: 3 | C39: H2 | D39: BSA | E39: MetLife Servicing Governance | F39: E4 | G39: ON | H39: FTE | I39: 1.5 | J39: =I39
