Workbook

Sheet README
A1: Sales / Insurance Recruitment — domain framework v6
A2: Rebuilt on Golden Application Inventory v4. The 99 Capgemini people already on these applications are identified by band and location, and they roll into Year 1 exactly as they are. MetLife's own value stream taxonomy replaces the cut we invented.
A4: WHAT GOLDEN INVENTORY v4 CHANGED FOR THIS DOMAIN
B5: We already hold 99 people here, and now we know who they are | C5: The T3 headcount reconciliation places 99 of the 277 named Capgemini people on Sales applications: 97 in India and 2 in Japan, banded E1 10 · E2 39 · E3 42 · E4 6 · E5 2 across both locations. 55.5 of them sit on JP-GSSP and 31.7 on JP-Banca Report. They are not a modelling assumption — they are on the payroll today.
B6: So the Year-1 offshore anatomy is designed around them, not the other way round | C6: The v5 pod library asked for 95.5 E2 seats offshore and 11.7 E3. We actually hold 39 E2 and 40 E3, plus 10 E1 and 8 seniors the anatomy had no offshore seat for at all. Every offshore unit in the library has been re-banded so the people we have fit the seats we designed. Year 1 now needs 11.9 E1 · 46.5 E2 · 42.0 E3 · 4.8 E4 · 2.0 E5 against a supply of 10 · 39 · 40 · 6 · 2 — the 97 who are offshore, the 2 in Japan sitting in onshore seats.
B7: MetLife's own value streams | C7: F2F Illustlation 230.871 (4 apps) · Banca Illustlation 168.917 (4) · F2F Agent Enablement 43.562 (1) · F2F SalesSupport 23.123 (4). The streams we invented in v4 and v5 are gone.
B8: There is effectively no partner dependency here | C8: Golden v4 names the vendor on every application. FSI holds 0.8 of the 284.5 vendor units in this 領域 and NCD holds 23.0. Contract Management needs a sub-contract to hold its service on day one; this domain does not. That contrast is deliberate and it is the clearest evidence that the partner strategy is targeted rather than generic.
A9: HOW THE INHERITED POPULATION IS EVOLVED, YEARS 2 TO 5
B10: Attrition and promotion, not an instruction | C10: The cohort is rolled forward with band-differentiated attrition — 22% at E1 offshore falling to 6% at E5, 10% to 4% onshore — and promotion applied to the survivors. 99 people become 83.8 · 71.6 · 61.6 · 53.5, and the senior share rises 8.1% → 14.0% → 20.5% → 27.3% → 34.3% without anyone being told to reshape anything.
B11: Which is most of the pyramid-to-diamond story | C11: The market does the work. What the solution has to do is stop hiring at the base and keep promoting, and the diamond arrives. That is a far more defensible claim than asserting a target shape and back-filling to it.
B12: Where it does not fit, the workbook says so | C12: Year 2 leaves 6.7 more E2 people than there are E2 seats; Year 4 leaves 7.8 more E3 than E3 seats. Both are absorbed by promotion into the band above, and both are reported as a reskill obligation rather than netted away.
B13: Solution tenets, not hard constraints | C13: The pyramid-to-diamond tenet is applied as a direction of travel. Where the inherited population makes the target shape unreachable in a given year, the model follows the people and records the deviation.
A14: WHAT IS RETAINED FROM v5
B15: The whole chain | C15: Six archetypes → AI and offshore ceilings → realisation → capability → carry-forward and pre-load → headcount target → unit design → seat ledger → every roll-up. Nothing in the structure moved. The J offshore ceiling is re-cut from 15% to 12% to match Golden v4, which moves the domain ceiling from 81.22% to 81.09%.
B16: Every Year-1 reconciliation | C16: Effort, sourcing, location and all six role lines still reconcile to Appendix 3 v3. Re-banding the offshore seats changes who sits in them, not how many or in what role.
B17: The measured offshore start | C17: 43.1% on day one — 107.1 offshore plus 93.8 MGCC — closing to 78.1% by Year 5 against a ceiling of 81.1%.
A18: WHAT TO RAISE
B19: The 99 is an allocation, not a register | C19: People are known by team, and teams are mapped to applications using the client's own 'CG HC by EAI' shape rescaled to the 277-name roster. It is the best available reconciliation of four sources that disagree (277 / 283 / 450 / 528), and it should be validated with T3 before it is quoted to MetLife.
B20: 185 of the 284.5 vendor units are not people we hold today | C20: Capgemini is the named incumbent on 177.3 of the vendor units but we hold only 99 heads against them; 83.4 units sit with unnamed vendors, 23.0 with NCD and 0.8 with FSI. Year 1 assumes Capgemini staffs all 284.5 from day one, which is a transition commitment of real size and is priced as a hire rather than a rebadge.
B21: Two people in Japan | C21: Of 99 inherited, 2 are onshore. Every bilingual onshore seat in Year 1 — 177.2 of them — is a hire or a redeployment into Tokyo. That is the single largest delivery risk in this 領域 and it is a recruitment problem, not a solution-design one.

Sheet Change Log v5 → v6
A1: What Golden Inventory v4 changed, and whether the core basis was shaken
A2: The test applied to each item: does the new evidence change an input, or does it change the structure that consumes the input? Only the second needs a rebuild.
B4: Element | C4: v5 basis | D4: v6 basis | E4: Verdict | F4: What it moved
B5: Baseline effort, sourcing, location, roles | C5: Appendix 3 v3 | D5: Appendix 3 v3, unchanged | E5: UNCHANGED | F5: 466.472 units, 13 applications, FTC 284.543 / FTE 88.129 / MGCC 93.800, onshore 177.368 / offshore 107.092.
B6: The Capgemini population already on these applications | C6: Not modelled. Every Year-1 seat treated as new. | D6: 99 named people: 97 India, 2 Japan, E1 10 · E2 39 · E3 42 · E4 6 · E5 2 | E6: NEW | F6: The largest addition in this version. 35% of the Capgemini seats in Year 1 are already filled, and their band and location are given rather than chosen.
B7: Offshore band mix in the unit library | C7: E2 95.5 and E3 11.7 in Year 1 — a hiring pyramid | D7: E1 11.9 · E2 46.5 · E3 42.0 · E4 4.8 · E5 2.0 | E7: REBUILT | F7: The library asked for a shape we do not have. Every offshore seat is re-banded so the inherited population fits. Roles, counts and every Year-1 reconciliation are untouched — only the band moves.
B8: Years 2 to 5 talent shape | C8: Asserted: a diamond by Year 4 | D8: Derived: band-differentiated attrition plus promotion, rolled forward | E8: REBUILT | F8: Senior share of the inherited cohort goes 8.1 → 14.0 → 20.5 → 27.3 → 34.3%. The diamond is now an outcome of the market rather than a target we set ourselves.
B9: Value streams | C9: Four streams, our own cut | D9: Four streams, MetLife's own taxonomy | E9: REBUILT | F9: F2F Illustlation 230.871 · Banca Illustlation 168.917 · F2F Agent Enablement 43.562 · F2F SalesSupport 23.123. The pod plan is re-cut stream by stream; the agile conversion quarters move with it.
B10: Vendor presence | C10: Not known | D10: Named per application in Golden v4 | E10: NEW | F10: FSI 0.8 units and NCD 23.0 of 284.5. Effectively no partner dependency in this 領域 — the opposite of Contract Management, where FSI holds 144.9 of 203.9.
B11: Archetypes, ceilings, realisation, carry-forward | C11: As built | D11: Unchanged | E11: RETAINED | F11: M 83.6% · D 10.4% · J 4.1% · P 1.6% · T 0.3%. AI ceiling 44.99%, offshore ceiling 81.09%, applied productivity 0 / 22.9 / 37.9 / 46.4 / 51.4%.
B12: Transfer mechanic | C12: One event at the end of Year 3 on the exit position | D12: Unchanged | E12: RETAINED | F12: No partner here, so the whole vendor population is transferable and the 50:50 closes inside the domain.
B13: Seat ledger, cost index, AMS sizing | C13: As built | D13: Unchanged | E13: RETAINED | F13: One sheet added — Inherited Workforce. Nothing removed.
A15: THE RULE APPLIED
B16: • Three rebuilds, and all three are in the staffing half of the model. The productivity half — ceilings, realisation, carry-forward, pre-load — is untouched for the second version running. That is worth stating plainly: the framework is stable and it is the workforce evidence that keeps moving.
B17: • Re-banding the offshore seats is the change with the most reach and the least visible effect. Year 1 still reconciles to Appendix 3 on all twelve quantities, because a Tester is a Tester whether they are E2 or E3. What changes is the cost index, the promotion plan and whether the Year-1 team can actually be assembled.
B18: • The pyramid-to-diamond tenet has moved from an assertion to a derivation, which means it can now be argued with. The attrition and promotion rates on the Inherited Workforce sheet are the two numbers to challenge.
B19: • Every other domain team must now re-run three things: the offshore band mix in their unit library, the inherited-population overlay, and their value streams against MetLife's taxonomy.

Sheet Change Control
A1: Change control — what must still hold after you edit a seat count
A2: Pod Library column J and Horizontal Teams column I are INPUTS. You may change them. Holding the yearly total is necessary but not sufficient — these are the other things that have to survive the edit. Every check below is live.
A4: A. WHERE THESE NUMBERS GO
B5: • Pod Library J and Horizontal Teams I are hard-typed values, not formulas. Nothing upstream computes them — they are the design. Everything downstream is derived from them.
B6: • Seat Ledger reads them cell by cell (912 references to Pod Library, 630 to Horizontal Teams) and multiplies by the unit count on Pod Plan. Team Build-Up, Cost & Commercial, Inherited Workforce and Unit Cost Sensitivity are all SUMIFS over the Seat Ledger. Change a seat and every one of them moves.
B7: • THE ONE THAT SURPRISES PEOPLE: the Logic Tree reads the roster back. Partner seats (row 59) drive the partner share (row 60), the span-of-control factor (row 61), the applied operating-model gain (row 43), capability (row 45) and therefore the HEADCOUNT TARGET itself (row 53). Changing partner seats moves the target you are trying to hit. It converges, but it does not stand still.
B8: • What does NOT move: the effort baseline, the archetype mix, the AI and offshore ceilings, the realisation curve and the agile conversion quarters. Those are inputs on the Logic Tree and Delivery Mode.
A10: B. THE INVARIANTS — all of these must stay green
B11: Check | C11: Y1 | D11: Y2 | E11: Y3 | F11: Y4 | G11: Y5 | H11: Tolerance | I11: Status
B12: Headcount delivered minus Logic Tree target | C12: ='Team Build-Up'!C12 -> 0.0277 | D12: ='Team Build-Up'!D12 -> 0.20246229 | E12: ='Team Build-Up'!E12 -> 0.1981292 | F12: ='Team Build-Up'!F12 -> 0.1723206 | G12: ='Team Build-Up'!G12 -> 0.027574688 | H12: ± 1.5 | I12: =IF(MAX(ABS(C12),ABS(D12),ABS(E12),ABS(F12),ABS(G12))<=1.5,"OK","CHECK") -> OK | J12: The productivity commitment. If you add seats you must remove others.
B13: Capgemini share inside each POD | C13: =IFERROR((SUMIFS('Pod Library'!$J$5:$J$111,'Pod Library'!$B$5:$B$111,1,'Pod Library'!$C$5:$C$111,"POD",'Pod Library'!$I$5:$I$111,"FTC")+SUMIFS('Pod Library'!$J$5:$J$111,'Pod Library'!$B$5:$B$111,1,'Pod Library'!$C$5:$C$111,"POD",'Pod Library'!$I$5:$I$111,"PT"))/(SUMIFS('Pod Library'!$J$5:$J$111,'Pod Library'!$B$5:$B$111,1,'Pod Library'!$C$5:$C$111,"POD")),"n/a") -> 0.73381295 | D13: =IFERROR((SUMIFS('Pod Library'!$J$5:$J$111,'Pod Library'!$B$5:$B$111,2,'Pod Library'!$C$5:$C$111,"POD",'Pod Library'!$I$5:$I$111,"FTC")+SUMIFS('Pod Library'!$J$5:$J$111,'Pod Library'!$B$5:$B$111,2,'Pod Library'!$C$5:$C$111,"POD",'Pod Library'!$I$5:$I$111,"PT"))/(SUMIFS('Pod Library'!$J$5:$J$111,'Pod Library'!$B$5:$B$111,2,'Pod Library'!$C$5:$C$111,"POD")),"n/a") -> 0.57439199 | E13: =IFERROR((SUMIFS('Pod Library'!$J$5:$J$111,'Pod Library'!$B$5:$B$111,3,'Pod Library'!$C$5:$C$111,"POD",'Pod Library'!$I$5:$I$111,"FTC")+SUMIFS('Pod Library'!$J$5:$J$111,'Pod Library'!$B$5:$B$111,3,'Pod Library'!$C$5:$C$111,"POD",'Pod Library'!$I$5:$I$111,"PT"))/(SUMIFS('Pod Library'!$J$5:$J$111,'Pod Library'!$B$5:$B$111,3,'Pod Library'!$C$5:$C$111,"POD")),"n/a") -> 0.5607759 | F13: =IFERROR((SUMIFS('Pod Library'!$J$5:$J$111,'Pod Library'!$B$5:$B$111,4,'Pod Library'!$C$5:$C$111,"POD",'Pod Library'!$I$5:$I$111,"FTC")+SUMIFS('Pod Library'!$J$5:$J$111,'Pod Library'!$B$5:$B$111,4,'Pod Library'!$C$5:$C$111,"POD",'Pod Library'!$I$5:$I$111,"PT"))/(SUMIFS('Pod Library'!$J$5:$J$111,'Pod Library'!$B$5:$B$111,4,'Pod Library'!$C$5:$C$111,"POD")),"n/a") -> 0.56060751 | G13: =IFERROR((SUMIFS('Pod Library'!$J$5:$J$111,'Pod Library'!$B$5:$B$111,5,'Pod Library'!$C$5:$C$111,"POD",'Pod Library'!$I$5:$I$111,"FTC")+SUMIFS('Pod Library'!$J$5:$J$111,'Pod Library'!$B$5:$B$111,5,'Pod Library'!$C$5:$C$111,"POD",'Pod Library'!$I$5:$I$111,"PT"))/(SUMIFS('Pod Library'!$J$5:$J$111,'Pod Library'!$B$5:$B$111,5,'Pod Library'!$C$5:$C$111,"POD")),"n/a") -> 0.56008695 | H13: ≥ 55% | I13: =IF(COUNTIF(C13:G13,"<0.5495")=0,"OK","CHECK") -> OK | J13: A POD in which Capgemini is a minority is one whose ways of working we do not set.
B14: Capgemini share inside each TEAM | C14: =IFERROR((SUMIFS('Pod Library'!$J$5:$J$111,'Pod Library'!$B$5:$B$111,1,'Pod Library'!$C$5:$C$111,"TEAM",'Pod Library'!$I$5:$I$111,"FTC")+SUMIFS('Pod Library'!$J$5:$J$111,'Pod Library'!$B$5:$B$111,1,'Pod Library'!$C$5:$C$111,"TEAM",'Pod Library'!$I$5:$I$111,"PT"))/(SUMIFS('Pod Library'!$J$5:$J$111,'Pod Library'!$B$5:$B$111,1,'Pod Library'!$C$5:$C$111,"TEAM")),"n/a") -> 0.58796992 | D14: =IFERROR((SUMIFS('Pod Library'!$J$5:$J$111,'Pod Library'!$B$5:$B$111,2,'Pod Library'!$C$5:$C$111,"TEAM",'Pod Library'!$I$5:$I$111,"FTC")+SUMIFS('Pod Library'!$J$5:$J$111,'Pod Library'!$B$5:$B$111,2,'Pod Library'!$C$5:$C$111,"TEAM",'Pod Library'!$I$5:$I$111,"PT"))/(SUMIFS('Pod Library'!$J$5:$J$111,'Pod Library'!$B$5:$B$111,2,'Pod Library'!$C$5:$C$111,"TEAM")),"n/a") -> 0.6 | E14: =IFERROR((SUMIFS('Pod Library'!$J$5:$J$111,'Pod Library'!$B$5:$B$111,3,'Pod Library'!$C$5:$C$111,"TEAM",'Pod Library'!$I$5:$I$111,"FTC")+SUMIFS('Pod Library'!$J$5:$J$111,'Pod Library'!$B$5:$B$111,3,'Pod Library'!$C$5:$C$111,"TEAM",'Pod Library'!$I$5:$I$111,"PT"))/(SUMIFS('Pod Library'!$J$5:$J$111,'Pod Library'!$B$5:$B$111,3,'Pod Library'!$C$5:$C$111,"TEAM")),"n/a") -> n/a | F14: =IFERROR((SUMIFS('Pod Library'!$J$5:$J$111,'Pod Library'!$B$5:$B$111,4,'Pod Library'!$C$5:$C$111,"TEAM",'Pod Library'!$I$5:$I$111,"FTC")+SUMIFS('Pod Library'!$J$5:$J$111,'Pod Library'!$B$5:$B$111,4,'Pod Library'!$C$5:$C$111,"TEAM",'Pod Library'!$I$5:$I$111,"PT"))/(SUMIFS('Pod Library'!$J$5:$J$111,'Pod Library'!$B$5:$B$111,4,'Pod Library'!$C$5:$C$111,"TEAM")),"n/a") -> n/a | G14: =IFERROR((SUMIFS('Pod Library'!$J$5:$J$111,'Pod Library'!$B$5:$B$111,5,'Pod Library'!$C$5:$C$111,"TEAM",'Pod Library'!$I$5:$I$111,"FTC")+SUMIFS('Pod Library'!$J$5:$J$111,'Pod Library'!$B$5:$B$111,5,'Pod Library'!$C$5:$C$111,"TEAM",'Pod Library'!$I$5:$I$111,"PT"))/(SUMIFS('Pod Library'!$J$5:$J$111,'Pod Library'!$B$5:$B$111,5,'Pod Library'!$C$5:$C$111,"TEAM")),"n/a") -> n/a | H14: ≥ 55% | I14: =IF(COUNTIF(C14:G14,"<0.5495")=0,"OK","CHECK") -> OK | J14: A TEAM in which Capgemini is a minority is one whose ways of working we do not set.
B15: Capgemini share of the delivery population | C15: =IFERROR((SUMIFS('Seat Ledger'!$M$5:$M$468,'Seat Ledger'!$B$5:$B$468,1,'Seat Ledger'!$J$5:$J$468,"FTC")+SUMIFS('Seat Ledger'!$M$5:$M$468,'Seat Ledger'!$B$5:$B$468,1,'Seat Ledger'!$J$5:$J$468,"PT"))/(SUMIFS('Seat Ledger'!$M$5:$M$468,'Seat Ledger'!$B$5:$B$468,1)),0) -> 0.60986066 | D15: =IFERROR((SUMIFS('Seat Ledger'!$M$5:$M$468,'Seat Ledger'!$B$5:$B$468,2,'Seat Ledger'!$J$5:$J$468,"FTC")+SUMIFS('Seat Ledger'!$M$5:$M$468,'Seat Ledger'!$B$5:$B$468,2,'Seat Ledger'!$J$5:$J$468,"PT"))/(SUMIFS('Seat Ledger'!$M$5:$M$468,'Seat Ledger'!$B$5:$B$468,2)),0) -> 0.58286986 | E15: =IFERROR((SUMIFS('Seat Ledger'!$M$5:$M$468,'Seat Ledger'!$B$5:$B$468,3,'Seat Ledger'!$J$5:$J$468,"FTC")+SUMIFS('Seat Ledger'!$M$5:$M$468,'Seat Ledger'!$B$5:$B$468,3,'Seat Ledger'!$J$5:$J$468,"PT"))/(SUMIFS('Seat Ledger'!$M$5:$M$468,'Seat Ledger'!$B$5:$B$468,3)),0) -> 0.55701875 | F15: =IFERROR((SUMIFS('Seat Ledger'!$M$5:$M$468,'Seat Ledger'!$B$5:$B$468,4,'Seat Ledger'!$J$5:$J$468,"FTC")+SUMIFS('Seat Ledger'!$M$5:$M$468,'Seat Ledger'!$B$5:$B$468,4,'Seat Ledger'!$J$5:$J$468,"PT"))/(SUMIFS('Seat Ledger'!$M$5:$M$468,'Seat Ledger'!$B$5:$B$468,4)),0) -> 0.51074367 | G15: =IFERROR((SUMIFS('Seat Ledger'!$M$5:$M$468,'Seat Ledger'!$B$5:$B$468,5,'Seat Ledger'!$J$5:$J$468,"FTC")+SUMIFS('Seat Ledger'!$M$5:$M$468,'Seat Ledger'!$B$5:$B$468,5,'Seat Ledger'!$J$5:$J$468,"PT"))/(SUMIFS('Seat Ledger'!$M$5:$M$468,'Seat Ledger'!$B$5:$B$468,5)),0) -> 0.5236415 | H15: ≥ 50% | I15: =IF(COUNTIF(C15:G15,"<0.4995")=0,"OK","CHECK") -> OK | J15: Below half the roster we cannot carry a productivity commitment we do not control.
B16: Blocks deploying a non-whole number of people | C16: =SUMPRODUCT(('Pod Library'!$B$5:$B$111=1)*(ABS('Pod Library'!$K$5:$K$111*2-ROUND('Pod Library'!$K$5:$K$111*2,0))>0.01))+SUMPRODUCT(('Horizontal Teams'!$B$5:$B$165=1)*(ABS('Horizontal Teams'!$J$5:$J$165*2-ROUND('Horizontal Teams'!$J$5:$J$165*2,0))>0.01)) -> 0 | D16: =SUMPRODUCT(('Pod Library'!$B$5:$B$111=2)*(ABS('Pod Library'!$K$5:$K$111*2-ROUND('Pod Library'!$K$5:$K$111*2,0))>0.01))+SUMPRODUCT(('Horizontal Teams'!$B$5:$B$165=2)*(ABS('Horizontal Teams'!$J$5:$J$165*2-ROUND('Horizontal Teams'!$J$5:$J$165*2,0))>0.01)) -> 2 | E16: =SUMPRODUCT(('Pod Library'!$B$5:$B$111=3)*(ABS('Pod Library'!$K$5:$K$111*2-ROUND('Pod Library'!$K$5:$K$111*2,0))>0.01))+SUMPRODUCT(('Horizontal Teams'!$B$5:$B$165=3)*(ABS('Horizontal Teams'!$J$5:$J$165*2-ROUND('Horizontal Teams'!$J$5:$J$165*2,0))>0.01)) -> 6 | F16: =SUMPRODUCT(('Pod Library'!$B$5:$B$111=4)*(ABS('Pod Library'!$K$5:$K$111*2-ROUND('Pod Library'!$K$5:$K$111*2,0))>0.01))+SUMPRODUCT(('Horizontal Teams'!$B$5:$B$165=4)*(ABS('Horizontal Teams'!$J$5:$J$165*2-ROUND('Horizontal Teams'!$J$5:$J$165*2,0))>0.01)) -> 6 | G16: =SUMPRODUCT(('Pod Library'!$B$5:$B$111=5)*(ABS('Pod Library'!$K$5:$K$111*2-ROUND('Pod Library'!$K$5:$K$111*2,0))>0.01))+SUMPRODUCT(('Horizontal Teams'!$B$5:$B$165=5)*(ABS('Horizontal Teams'!$J$5:$J$165*2-ROUND('Horizontal Teams'!$J$5:$J$165*2,0))>0.01)) -> 7 | H16: =0 -> 0 | I16: =IF(SUM(C16:G16)=0,"OK","CHECK") -> CHECK | J16: Column K of the Pod Library and column J of Horizontal Teams are the people you hire for that role across the whole block. Every one is a whole number, or a half where one person covers two units INSIDE this domain. The seat ratio beside it is the modelling quantity and will not always be round — on a 28-team block, nine engineers is a ratio of 0.32.
B17: Horizontal roles that have fallen below 0.02 FTE | C17: =COUNTIFS('Horizontal Teams'!$B$5:$B$165,1,'Horizontal Teams'!$I$5:$I$165,"<0.02") -> 0 | D17: =COUNTIFS('Horizontal Teams'!$B$5:$B$165,2,'Horizontal Teams'!$I$5:$I$165,"<0.02") -> 0 | E17: =COUNTIFS('Horizontal Teams'!$B$5:$B$165,3,'Horizontal Teams'!$I$5:$I$165,"<0.02") -> 0 | F17: =COUNTIFS('Horizontal Teams'!$B$5:$B$165,4,'Horizontal Teams'!$I$5:$I$165,"<0.02") -> 0 | G17: =COUNTIFS('Horizontal Teams'!$B$5:$B$165,5,'Horizontal Teams'!$I$5:$I$165,"<0.02") -> 0 | H17: =0 -> 0 | I17: =IF(SUM(C17:G17)=0,"OK","CHECK") -> OK | J17: A domain cannot run without a delivery head, a service manager or an architect. If a role must genuinely end, delete the row rather than leaving it at zero.
B18: Year-1 reconciliation to Appendix 3 — worst line | C18: ='Team Build-Up'!E28 -> 1.2083 | H18: ± 2.6 | I18: =IF(ABS(C18)<=2.6,"OK","CHECK") -> OK | J18: Year 1 must reproduce the client's own numbers: effort, the sourcing split, all three locations and all six role lines. The tolerance is ± 2.6 because seats sit on a 0.5 grid and a Year-1 team seat carries a multiplier of 5 — one grid step is 2.5 people. That is the deliberate price of an anatomy that can be staffed. Moving a seat between bands is free; moving it between ROLE, LOCATION or SOURCING is what actually breaks this.
A20: C. WHAT GOES STALE AND WILL NOT WARN YOU
B21: • SOURCING & PRODUCTIVITY is static. It is produced outside Excel by the per-sourcing solver and pasted in. If you change seat counts, the pool ceilings, the organic-convergence table and the transfer solve on that sheet no longer describe this roster. Re-run the solver or treat the sheet as superseded.
B22: • SIT LOADING is static for the same reason. Re-generate it after any seat change, or the requisition plan will not match the ledger.
B23: • The TRANSFER on the Logic Tree is a typed input (rows 65-66), sized on the Year-3 exit position produced by the solver. Change the Year-3 roster materially and the transfer needs re-sizing, or the 50:50 will not land.
B24: • THE RULE OF THUMB. Re-banding a seat, renaming it, or moving it between pods is safe. Changing its ROLE, LOCATION or SOURCING is not — those are the attributes Year 1 reconciles on and the guardrails measure.

Sheet Logic Tree
A1: Logic Tree — ten parametric drivers, five years
A2: Amber cells are inputs. Everything else re-derives. Section F is rebuilt on the measured day-1 position.
A4: A. BASELINE — Appendix 3 v3, read and never edited
B5: Domain | C5: sales / insurance recruitment
B6: Applications | C6: 13
B7: Total effort (units) | C7: 466.4723
B8: Current FTC | C8: 284.543
B9: Current FTE | C9: 88.1292
B10: Current MGCC | C10: 93.8
B11: — of which onshore Tokyo | C11: 177.3681 | J11: Location and role come from Appendix 3 v3. Both were Capgemini assumptions in v4.
B12: — of which offshore | C12: 107.0916
B13: — of which nearshore | C13: 0
B14: — of which onsite | C14: 0
B15: Role: BSA | C15: 47.7083
B16: Role: Developer | C16: 114.2306
B17: Role: Tester | C17: 103.9166
B18: Role: Maintenance | C18: 13.1458
B19: Role: PM | C19: 3.7917
B20: Role: Other | C20: 1.75
B21: AD effort (% of PRJ weighted) | C21: 444.5136
B22: Appendix 3 Year-3 target, each side | C22: 233.2362
B23: Ratio today — Capgemini share | C23: =C8/(C8+C9+C10) -> 0.60998919
B24: OFFSHORE TODAY — whole team, measured | C24: =(C12+C13+C10)/C7 -> 0.43066137 | J24: This is the number the offshore glidepath now starts from. In v4 it was assumed to be near zero.
A26: B. ARCHETYPE MIX — from the Golden Application Inventory v4
B27: Archetype | C27: Name | D27: Apps | E27: Effort | F27: Share | G27: AI ceiling | H27: Offshore ceiling
B28: M | C28: MGCC-destined | D28: 7 | E28: 390.1504 | F28: =E28/$E$33 -> 0.83638493 | G28: 0.4525 | H28: 0.85
B29: D | C29: Distributed-proven | D29: 1 | E29: 48.667 | F29: =E29/$E$33 -> 0.10432988 | G29: 0.4825 | H29: 0.78
B30: J | C30: Japan-locked | D30: 2 | E30: 19.0521 | F30: =E30/$E$33 -> 0.04084294 | G30: 0.304 | H30: 0.12
B31: P | C31: Portable, not moved | D31: 1 | E31: 7.2617 | F31: =E31/$E$33 -> 0.015567269 | G31: 0.4825 | H31: 0.78
B32: T | C32: Long tail | D32: 2 | E32: 1.3411 | F32: =E32/$E$33 -> 0.0028749831 | G32: 0.39 | H32: 0.55
C33: Total | D33: =SUM(D28:D32) -> 13 | E33: =SUM(E28:E32) -> 466.4723 | F33: =SUM(F28:F32) -> 1
B34: APPLICABLE AI CEILING | C34: =SUMPRODUCT($E$28:$E$32,$G$28:$G$32)/$E$33 -> 0.44985205 | J34: 44.99% against 44.73% on the four-archetype scheme. The segmentation changed; the answer did not.
B35: APPLICABLE OFFSHORE CEILING | C35: =SUMPRODUCT($E$28:$E$32,$H$28:$H$32)/$E$33 -> 0.81092936
A37: C. REALISATION AND THE NON-AI COMPONENTS
B38: Driver | C38: Year 1 | D38: Year 2 | E38: Year 3 | F38: Year 4 | G38: Year 5 | H38: Basis
B39: AI realisation — share of ceiling | C39: 0.25 | D39: 0.55 | E39: 0.75 | F39: 0.85 | G39: 0.9 | J39: Adoption, guardrails and substrate maturity. Capped at 90%.
B40: Classical ADM productivity, cumulative | C40: 0.02 | D40: 0.05 | E40: 0.07 | F40: 0.09 | G40: 0.11 | J40: Standardisation, defect reduction, shift-left.
B41: Operating-model productivity, RAW | C41: 0.03 | D41: 0.06 | E41: 0.08 | F41: 0.1 | G41: 0.12 | J41: Pod consolidation and one release train — only available where the stream is agile.
B42: Agile share of the domain → from the Delivery Mode sheet | C42: ='Delivery Mode'!C22 -> 0.18425542 | D42: ='Delivery Mode'!D22 -> 0.90947121 | E42: ='Delivery Mode'!E22 -> 1 | F42: ='Delivery Mode'!F22 -> 1 | G42: ='Delivery Mode'!G22 -> 1
B43: Operating-model productivity, APPLIED | C43: =C41*C42 -> 0.0055276626 | D43: =D41*D42 -> 0.054568272 | E43: =E41*E42 -> 0.08 | F43: =F41*F42 -> 0.1 | G43: =G41*G42 -> 0.12 | J43: Scaling by the agile share is what makes the operating-model gain earned rather than assumed. It costs 2.1 points of Year-1 capability.
...

Sheet Sourcing & Productivity
A1: Sourcing and productivity — the same chain, applied differently to each population
A2: Productivity is not one number applied to everybody. The three populations do different work and we do not control all three, so each carries its own AI ceiling and its own adoption factor. This is what makes the 50:50 converge on its own rather than by transfer.
A4: A. WHY ONE RATE CANNOT APPLY TO ALL THREE — the Year-1 role mix
B5: Population | C5: Heads Y1 | D5: BSA | E5: Developer | F5: Tester | G5: Maint.
B6: FTC · Capgemini payroll | C6: 284.533 | D6: 0.16761149 | E6: 0.40155975 | F6: 0.36525816 | G6: 0.046142275 | I6: MetLife's own people are governance, domain SME and product ownership. MGCC is build and test. They are not doing the same work, so they cannot carry the same productivity rate.
B7: FTE · MetLife Japan | C7: 88.11 | D7: 0.39021677 | E7: 0 | F7: 0.02268755 | G7: 0.20863693
B8: MGCC · MetLife MGCC | C8: 93.787 | D8: 0 | E8: 0.6786335 | F8: 0.3213665 | G8: 0
A10: B. EACH POPULATION'S OWN AI CEILING AND ADOPTION — INPUT
B11: Population | C11: Own AI ceiling | D11: Adoption | E11: Effective ceiling | F11: vs domain blend
B12: FTC · Capgemini payroll | C12: 0.46444913 | D12: 1 | E12: 0.46444913 | F12: 0.032448614 | I12: ADOPTION is the share of the ceiling each population can actually realise, and it is a judgement about AUTHORITY, not about capability. We build the tooling, set the ways of working and mandate them on our own payroll — so 1.00. Everything below that is somebody else's decision.
B13: FTE · MetLife Japan | C13: 0.37804868 | D13: 0.55 | E13: 0.20792677 | F13: -0.15961552
B14: MGCC · MetLife MGCC | C14: 0.48397907 | D14: 0.8 | E14: 0.38718325 | F14: 0.075862751
B15: Domain blended ceiling (unchanged, and still the headline commitment) | C15: 0.44985205
B16: Only the AI gate is scaled. Classical ADM productivity attaches to the work and the operating-model gain attaches to the delivery unit, so both flow to every population regardless of employer.
A18: C. WHAT EACH POPULATION IS THEREFORE ASKED TO DELIVER
B19: Applied to staffing | C19: Year 1 | D19: Year 2 | E19: Year 3 | F19: Year 4 | G19: Year 5
B20: FTC · Capgemini payroll | C20: 0 | D20: 0.23492517 | E20: 0.3868546 | F20: 0.47338163 | G20: 0.52425358 | I20: The headline commitment is UNCHANGED from the previous version. What has changed is that it is no longer assumed to fall equally on all three populations.
B21: FTE · MetLife Japan | C21: 0 | D21: 0.14031539 | E21: 0.24118991 | F21: 0.30178742 | G21: 0.34455582
B22: MGCC · MetLife MGCC | C22: 0 | D22: 0.20642821 | E22: 0.34297963 | F22: 0.42169656 | G22: 0.47012768
B23: Whole-domain commitment (the headline) | C23: 0 | D23: 0.22954152 | E23: 0.37856574 | F23: 0.46361728 | G23: 0.51402811
A25: D. THE THREE-WAY COMMITMENT SPLIT
B26: CAPGEMINI COMMITS | C26: Our own headcount reduction, on our own payroll, on tooling and ways of working we control. This is contractible and we should contract it.
B27: METLIFE MUST DELIVER | C27: The reduction of MetLife Japan and MGCC headcount. We size it, we enable it and we report it — but redeploying MetLife's own people is MetLife's decision, and MGCC runs to its own utilisation targets. This should be a joint commitment with named owners, not a Capgemini SLA.
B28: JOINTLY DEPENDENT | C28: AI adoption on MetLife's side: tooling access, shared standards, common telemetry, and the substrate being used rather than merely available. If adoption lands below the factors in section B, the whole-team headcount misses even if Capgemini delivers in full.
A30: E. ORGANIC CONVERGENCE TO 50:50 — before any transfer
B31: Measure | C31: Year 1 | D31: Year 2 | E31: Year 3 | F31: Year 4 | G31: Year 5
B32: MetLife Japan (FTE) — own curve | C32: 88.11 | D32: 75.746811 | E32: 66.858757 | F32: 64.305437 | G32: 58.948238 | I32: MetLife's populations follow their own slower curves. Capgemini takes the balance, which means we shrink our own book faster than productivity alone would justify. That extra reduction is not a productivity claim — it is a deliberate commercial choice to reach the ratio organically instead of by transferring people.
B33: MetLife MGCC — own curve | C33: 93.787 | D33: 74.426717 | E33: 61.619969 | F33: 60.798403 | G33: 54.397974
B34: Partner — per the partner plan | C34: 0 | D34: 0 | E34: 0 | F34: 0 | G34: 0
B35: Capgemini — absorbs the balance | C35: 284.5753 | D35: 209.22401 | E35: 161.40314 | F35: 125.10384 | G35: 113.34621
B36: TOTAL = the headline commitment | C36: 466.4723 | D36: 359.39754 | E36: 289.88187 | F36: 250.20768 | G36: 226.69243
B37: RATIO — Capgemini share | C37: 0.6100583 | D37: 0.58215204 | E37: 0.55678937 | F37: 0.5 | G37: 0.5
B38: — of which productivity-driven | C38: 0 | D38: 0.23492517 | E38: 0.3868546 | F38: 0.47338163 | G38: 0.52425358
B39: — of which RATIO-DRIVEN, over and above productivity | C39: -0.00014866465 | D39: 0.029750597 | E39: 0.045889076 | F39: 0.086937066 | G39: 0.077387661
B41: This is the mechanism that halves the transfer. Reaching the ratio by shrinking our own book is cheaper, lower-risk and entirely within our control; a transfer of employment is neither.
A43: F. THE GUARDRAILS — where organic convergence has to stop
B44: Test | C44: Year 1 | D44: Year 2 | E44: Year 3 | F44: Year 4 | G44: Year 5 | H44: Floor
B45: Capgemini share of the delivery population | C45: 0.61002294 | D45: 0.58192752 | E45: 0.55690746 | F45: 0.50013783 | G45: 0.50004191 | H45: 0.5 | I45: THE POINT OF THE FLOOR. If Capgemini becomes a minority of the delivery population, or of the build-and-test seats, or of any single pod, we no longer set the ways of working — and a productivity commitment we cannot enforce is not a commitment. Convergence stops here, and from that year MetLife's population follows the whole-team curve rather than its own slower one.
B46: Capgemini share of build-and-test seats | C46: 0.69492087 | D46: 0.66125934 | E46: 0.65582205 | F46: 0.596437 | G46: 0.60016504 | H46: 0.55
B47: Capgemini share inside every single delivery unit | C47: held | D47: held | E47: held | F47: held | G47: held | H47: 0.55
...

Sheet Delivery Mode
A1: Delivery mode — not everything is a pod on day one
A2: Only 4 applications in the whole estate are flagged agile, and Sales has no method data at all. This sheet is where that assumption lives, in the open, as an input.
A4: A. MODE TODAY AND TARGET, BY VALUE STREAM — INPUT
B5: Value stream | C5: Effort | D5: Archetype | E5: Mode today | F5: Agile from | G5: Why
B6: F2FILL · F2F Illustlation | C6: 230.8708 | D6: M | E6: Hybrid | F6: Q4 | G6: JP-GSSP is 229.9 of the 230.9. Capgemini is the named incumbent and 55.5 of our 99 inherited people sit here. 1,780 P4 incidents and 669 normal changes in 32 months. | I6: MetLife supplied no development method for any Sales application. These four rows are Capgemini planning assumptions, drawn from the platform each stream runs on. They are the single largest unevidenced input in this workbook.
B7: BANCA · Banca Illustlation | C7: 168.9167 | D7: M / D / J / T | E7: Hybrid | F7: Q6 | G7: JP-BANCA 103.5 is unnamed in the vendor mapping and JP-Banca Report 48.7 is where 31.7 of our people are. The VBA illustration tool P02BKE is NCD's and is the drag.
B8: AGENT · F2F Agent Enablement | C8: 43.5625 | D8: M | E8: Hybrid | F8: Q4 | G8: WPSCFC-JPN. Capgemini-named, single application, 8.8 of our people.
B9: SUPP · F2F SalesSupport | C9: 23.1223 | D9: M / P / J / T | E9: Agile | F9: Q2 | G9: Small, modern, closest to an agile construct already. Remote Closing is ours.
B10: Total | C10: =SUM(C6:C9) -> 466.4723
A12: B. AGILE SHARE BY YEAR — computed from the quarter each stream converts
B13: Value stream | C13: Year 1 | D13: Year 2 | E13: Year 3 | F13: Year 4 | G13: Year 5
B14: F2FILL | C14: 0.25 | D14: 1 | E14: 1 | F14: 1 | G14: 1
B15: BANCA | C15: 0 | D15: 0.75 | E15: 1 | F15: 1 | G15: 1
B16: AGENT | C16: 0.25 | D16: 1 | E16: 1 | F16: 1 | G16: 1
B17: SUPP | C17: 0.75 | D17: 1 | E17: 1 | F17: 1 | G17: 1
B18: Effort-weighted agile share of the domain | C18: =SUMPRODUCT($C$6:$C$9,C14:C17)/$C$10 -> 0.18425542 | D18: =SUMPRODUCT($C$6:$C$9,D14:D17)/$C$10 -> 0.90947121 | E18: =SUMPRODUCT($C$6:$C$9,E14:E17)/$C$10 -> 1 | F18: =SUMPRODUCT($C$6:$C$9,F14:F17)/$C$10 -> 1 | G18: =SUMPRODUCT($C$6:$C$9,G14:G17)/$C$10 -> 1
B20: Delivery units this produces
B21: — agile PODS | C21: 7 | D21: 35 | E21: 36 | F21: 36 | G21: 33
B22: — agile share (feeds the Logic Tree) | C22: =C18 -> 0.18425542 | D22: =D18 -> 0.90947121 | E22: =E18 -> 1 | F22: =F18 -> 1 | G22: =G18 -> 1
B23: — waterfall / hybrid TEAMS | C23: 28 | D23: 3 | E23: 0 | F23: 0 | G23: 0
A25: C. WHY THIS MATTERS TO THE NUMBER
B26: • Operating-model productivity — pod consolidation, one release train, span of control — is only available where the stream actually runs as a pod. Scaling the 3 / 6 / 8 / 10 / 12% curve by the agile share turns it from an assumption into an earned outcome, and costs 2.1 points of Year-1 capability.
B27: • The waterfall TEAM is 12 seats with separate analysis and test cells; the agile POD is 10 with the test cell collapsed into SDET seats. That structural difference is what reproduces the 37% tester share Appendix 3 v3 reports — and what makes it fall as streams convert.
B28: • Year 1 runs 7 pods and 28 teams. Year 2 runs 35 pods and 3 teams. By Year 3 there are no teams left. If the conversion slips a year, Year-2 capability falls from 32.4% to about 27% and the whole glidepath moves with it.
B29: • DECIDE whether we put this profile to MetLife as an assumption to confirm, or ask for the development method data first. Asking is cheap and it removes the largest unevidenced input in the model.

Sheet AMS & Ticket Load
A1: AMS and ticket load — the run team sized from evidence, for the first time
A2: 3,807 incidents and 2,979 changes over 32 months, from Appendix 3 v3.
A4: A. RECORDED VOLUMES — 1 Jan 2024 to 31 Aug 2026
B5: Measure | C5: Volume | D5: Per month | E5: Per unit of effort | F5: Share
B6: P1 — critical | C6: 1 | D6: =C6/$C$17 -> 0.03125 | E6: =C6/'Logic Tree'!$C$7 -> 0.00214375 | F6: =C6/$C$11 -> 0.00026267402 | I6: Six incidents at P1 or P2 in 32 months on a 466-unit domain. The load is overwhelmingly P4 and P5 — high volume, low severity, and the profile automation and AIOps address best.
B7: P2 — high | C7: 5 | D7: =C7/$C$17 -> 0.15625 | E7: =C7/'Logic Tree'!$C$7 -> 0.01071875 | F7: =C7/$C$11 -> 0.0013133701
B8: P3 — medium | C8: 115 | D8: =C8/$C$17 -> 3.59375 | E8: =C8/'Logic Tree'!$C$7 -> 0.24653125 | F8: =C8/$C$11 -> 0.030207512
B9: P4 — low | C9: 1910 | D9: =C9/$C$17 -> 59.6875 | E9: =C9/'Logic Tree'!$C$7 -> 4.0945625 | F9: =C9/$C$11 -> 0.50170738
B10: P5 — informational | C10: 1776 | D10: =C10/$C$17 -> 55.5 | E10: =C10/'Logic Tree'!$C$7 -> 3.8073 | F10: =C10/$C$11 -> 0.46650906
B11: All incidents | C11: =SUM(C6:C10) -> 3807 | D11: =C11/$C$17 -> 118.96875 | E11: =C11/'Logic Tree'!$C$7 -> 8.1612563
B12: Emergency change | C12: 50 | D12: =C12/$C$17 -> 1.5625 | E12: =C12/'Logic Tree'!$C$7 -> 0.1071875 | F12: =C12/$C$15 -> 0.016784156 | I12: 68% of changes are Standard. That is the share a release train and pipeline automation can absorb, and it is the operating-model productivity case in one number.
B13: Normal change | C13: 901 | D13: =C13/$C$17 -> 28.15625 | E13: =C13/'Logic Tree'!$C$7 -> 1.9315188 | F13: =C13/$C$15 -> 0.30245049
B14: Standard change | C14: 2028 | D14: =C14/$C$17 -> 63.375 | E14: =C14/'Logic Tree'!$C$7 -> 4.347525 | F14: =C14/$C$15 -> 0.68076536
B15: All changes | C15: =SUM(C12:C14) -> 2979 | D15: =C15/$C$17 -> 93.09375 | E15: =C15/'Logic Tree'!$C$7 -> 6.3862313
B17: Observation window, months | C17: 32
A19: B. TWO INDEPENDENT SIZINGS OF THE RUN TEAM
B20: Basis | C20: Value | D20: Reading
B21: Tickets per analyst per month — INPUT | C21: 9.05 | D21: SOLVED, not assumed: this is the throughput that makes the ticket-derived run team equal the Maintenance role MetLife reports. It is the output of the cross-check, not an input to it.
B22: Implied run team from incident volume | C22: =C11/C17/C21 -> 13.145718 | D22: Incidents per month divided by throughput per analyst.
B23: Maintenance role reported in Appendix 3 v3 | C23: ='Logic Tree'!C18 -> 13.1458 | D23: MetLife's own count of the Capgemini maintenance population on this domain.
B24: Variance between the two | C24: =C22-C23 -> -8.1767956e-05 | D24: Zero by construction. The question is whether 9.05 tickets per analyst per month is credible — see below.
B25: Maintenance seats in the Year-1 roster | C25: ='Team Build-Up'!C48 -> 31.5 | D25: Model output. Wider than the Maintenance role: it includes the horizontal L2, incident and release seats as well as the in-team support seats.
A27: C. WHAT THE TICKET DATA CHANGES
B28: • THE CROSS-CHECK DOES NOT CLOSE, AND THAT IS THE FINDING. MetLife reports 13.1 Capgemini maintenance units against 119 incidents a month — 9 tickets per analyst per month. Industry L2 throughput is 60 to 100. Either run work is being done by people counted as developers, or these tickets carry far more investigation than a normal L2 queue. Both readings matter for how AMS is priced, and neither can be settled from this pack.
B29: • The severity profile is the automation case. 96.8% of incidents are P4 or P5 and 68% of changes are Standard. Those are the categories where MSP benchmarks put MTTR reduction at 20-40% and technician throughput at 15-25%, and they are why the run-phase AI addressable share is set at 40%.
B30: • Ticket density varies by archetype across the portfolio by a factor of four — 6.8 incidents per unit on distributed-proven applications against 25.6 on the long tail. Sales sits at 8.2, which is why its horizontal layer is 13% of the roster against 22% on Contract Management.
B31: • DO put the throughput question to MetLife. Appendix 3 records 95.3% of this domain's effort as project work and only 4.7% as run, against 3,807 incidents and 2,979 changes in 32 months. Either run work is sitting inside the developer line or the AMS price is wrong. Repeat this cross-check on every domain — Contract Management reports 2,610 incidents against ZERO maintenance units, which cannot be right.

Sheet Inventory
A1: Inventory — the 13 Sales / Insurance Recruitment applications from Appendix 3 v3
A2: Classified by the six-rule classifier on the Golden Application Inventory v4.
B4: Application | C4: Arch | D4: Effort | E4: FTC | F4: FTE | G4: MGCC | H4: Onshore | I4: Offshore | J4: Offsh % | K4: BSA | L4: Dev | M4: Test | N4: Mnt | O4: PM | P4: Oth | Q4: AD % | R4: Crit | S4: Cloud | T4: Prio | U4: Incidents | V4: Changes | W4: Primary code language
B5: JP-GSSP | C5: M | D5: 229.9125 | E5: 151.7708 | F5: 30.9375 | G5: 47.2042 | H5: 102.8125 | I5: 48.9583 | J5: =IFERROR(($I5+$G5)/$D5,0) -> 0.41825695 | K5: 23.7083 | L5: 43.8333 | M5: 67.8333 | N5: 12.1458 | O5: 3.75 | P5: 0.5 | Q5: 0.9472 | R5: Y | S5: Yes | T5: Y | U5: 1973 | V5: 1694 | W5: JAVA;JavaScript
B6: JP-BANCA | C6: M | D6: 103.5083 | E6: 51.3 | F6: 27.2083 | G6: 25 | H6: 21.4583 | I6: 29.8417 | J6: =IFERROR(($I6+$G6)/$D6,0) -> 0.52982901 | K6: 12.6667 | L6: 14.5917 | M6: 22.75 | N6: 0 | O6: 0.0417 | P6: 1.25 | Q6: 0.9924 | R6: N | S6: Yes | T6: Y | U6: 8 | V6: 15 | W6: JavaScript;JAVA
B7: JP-Banca Report | C7: D | D7: 48.6667 | E7: 31.6875 | F7: 11.4 | G7: 5.5792 | H7: 19 | I7: 12.6875 | J7: =IFERROR(($I7+$G7)/$D7,0) -> 0.37534289 | K7: 7.0833 | L7: 18.6042 | M7: 6 | N7: 0 | O7: 0 | P7: 0 | Q7: 1 | R7: N | S7: Yes | T7: N | U7: 29 | V7: 102 | W7: JAVA
B8: WPSCFC-JPN | C8: M | D8: 43.5625 | E8: 20.8333 | F8: 10.0042 | G8: 12.725 | H8: 7.5833 | I8: 13.25 | J8: =IFERROR(($I8+$G8)/$D8,0) -> 0.59626973 | K8: 4.25 | L8: 9.5833 | M8: 6 | N8: 1 | O8: 0 | P8: 0 | Q8: 0.8692 | R8: N | S8: Yes | T8: Y | U8: 1425 | V8: 530 | W8: Other#APEX;HTML;JavaScript
B9: P02BKE-JPN | C9: J | D9: 15.8583 | E9: 13.5833 | F9: 2.275 | G9: 0 | H9: 13.5833 | I9: 0 | J9: =IFERROR(($I9+$G9)/$D9,0) -> 0 | K9: 0 | L9: 13.5833 | M9: 0 | N9: 0 | O9: 0 | P9: 0 | Q9: 0.9173 | R9: N | S9: No | T9: N | U9: 2 | V9: 49 | W9: Other#VBA
B10: JP - Remote Closing | C10: M | D10: 12.2083 | E10: 4.6458 | F10: 4.5625 | G10: 3 | H10: 2.625 | I10: 2.0208 | J10: =IFERROR(($I10+$G10)/$D10,0) -> 0.41126119 | K10: 0 | L10: 3.3125 | M10: 1.3333 | N10: 0 | O10: 0 | P10: 0 | Q10: 1 | R10: N | S10: Yes | T10: Y | U10: 171 | V10: 128 | W10: JAVA
B11: WAAATF-JPN | C11: P | D11: 7.2621 | E11: 6.6142 | F11: 0.6479 | G11: 0 | H11: 6.6142 | I11: 0 | J11: =IFERROR(($I11+$G11)/$D11,0) -> 0 | K11: 0 | L11: 6.6142 | M11: 0 | N11: 0 | O11: 0 | P11: 0 | Q11: 0.9391 | R11: N | S11: Yes | T11: N | U11: 44 | V11: 52 | W11: JAVA
B12: W08NAV-JPN | C12: J | D12: 3.194 | E12: 2.8419 | F12: 0.3521 | G12: 0 | H12: 2.8419 | I12: 0 | J12: =IFERROR(($I12+$G12)/$D12,0) -> 0 | K12: 0 | L12: 2.8419 | M12: 0 | N12: 0 | O12: 0 | P12: 0 | Q12: 0.7919 | R12: N | S12: No | T12: N | U12: 13 | V12: 96 | W12: VB
B13: W09WSD-JPN BIS | C13: T | D13: 0.8833 | E13: 0.8083 | F13: 0.075 | G13: 0 | H13: 0.8083 | I13: 0 | J13: =IFERROR(($I13+$G13)/$D13,0) -> 0 | K13: 0 | L13: 0.8083 | M13: 0 | N13: 0 | O13: 0 | P13: 0 | Q13: 0.4811 | R13: N | S13: No | T13: N | U13: 43 | V13: 204 | W13: VB.NET
B14: Distribution Systems - Internal | C14: M | D14: 0.6667 | E14: 0.3333 | F14: 0.25 | G14: 0.0833 | H14: 0 | I14: 0.3333 | J14: =IFERROR(($I14+$G14)/$D14,0) -> 0.62486876 | K14: 0 | L14: 0.3333 | M14: 0 | N14: 0 | O14: 0 | P14: 0 | Q14: 1 | R14: N | S14: Yes | T14: Y | U14: 43 | V14: 56 | W14: JAVA
B15: WGLRPC-JPN | C15: T | D15: 0.4579 | E15: 0.0413 | F15: 0.4167 | G15: 0 | H15: 0.0413 | I15: 0 | J15: =IFERROR(($I15+$G15)/$D15,0) -> 0 | K15: 0 | L15: 0.0413 | M15: 0 | N15: 0 | O15: 0 | P15: 0 | Q15: 0 | R15: N | S15: No | T15: N | U15: 18 | V15: 5 | W15: JAVA
B16: IVR Tekigosei | C16: M | D16: 0.1667 | E16: 0.0833 | F16: 0 | G16: 0.0833 | H16: 0 | I16: 0 | J16: =IFERROR(($I16+$G16)/$D16,0) -> 0.49970006 | K16: 0 | L16: 0.0833 | M16: 0 | N16: 0 | O16: 0 | P16: 0 | Q16: 1 | R16: N | S16: Yes | T16: Y | U16: 34 | V16: 5 | W16: Other#N/A
B17: WCC | C17: M | D17: 0.125 | E17: 0 | F17: 0 | G17: 0.125 | H17: 0 | I17: 0 | J17: =IFERROR(($I17+$G17)/$D17,0) -> 1 | K17: 0 | L17: 0 | M17: 0 | N17: 0 | O17: 0 | P17: 0 | Q17: 1 | R17: N | S17: Yes | T17: Y | U17: 4 | V17: 43 | W17: JAVA;HTML5;JavaScript
B18: TOTAL | D18: =SUM(D5:D17) -> 466.4723 | E18: =SUM(E5:E17) -> 284.543 | F18: =SUM(F5:F17) -> 88.1292 | G18: =SUM(G5:G17) -> 93.8 | H18: =SUM(H5:H17) -> 177.3681 | I18: =SUM(I5:I17) -> 107.0916 | K18: =SUM(K5:K17) -> 47.7083 | L18: =SUM(L5:L17) -> 114.2306 | M18: =SUM(M5:M17) -> 103.9166 | N18: =SUM(N5:N17) -> 13.1458 | O18: =SUM(O5:O17) -> 3.7917 | P18: =SUM(P5:P17) -> 1.75 | U18: =SUM(U5:U17) -> 3807 | V18: =SUM(V5:V17) -> 2979
B20: Note — development method, specification language, lines of code, screens, batches, APIs and file interfaces are BLANK for all 13 applications in this domain. They are omitted here rather than shown as empty columns. See the README.

Sheet Value Streams
A1: Four value streams — MetLife's own taxonomy, reconciling to 13 applications and 466.472 units
A2: New in v6. The streams we invented in v4 and v5 are replaced by the ones MetLife uses, so the pod plan is readable against the client's own map of the estate.
B4: Code | C4: Value stream | D4: Apps | E4: Effort | F4: Arch | G4: Mode today | H4: Agile from | I4: Y1 pods | J4: Y2 | K4: Y3 | L4: Y4 | M4: Y5 | N4: Vendor today | O4: CG heads today
B5: F2FILL | C5: F2F Illustlation | D5: 4 | E5: 230.8708 | F5: M | G5: Hybrid | H5: Q4 | I5: 5 + 13t | J5: 19 | K5: 18 | L5: 18 | M5: 16 | N5: CG 151.8 · unnamed 0.4 | O5: 55.5
B6: BANCA | C6: Banca Illustlation | D6: 4 | E6: 168.9167 | F6: M / D / J / T | G6: Hybrid | H6: Q6 | I6: 0 + 12t | J6: 10 + 3t | K6: 13 | L6: 13 | M6: 12 | N6: NCD 13.6 · FSI 0.8 · unnamed 83.0 | O6: 32
B7: AGENT | C7: F2F Agent Enablement | D7: 1 | E7: 43.5625 | F7: M | G7: Hybrid | H7: Q4 | I7: 1 + 2t | J7: 4 | K7: 3 | L7: 3 | M7: 3 | N7: CG 20.8 | O7: 8.8
B8: SUPP | C8: F2F SalesSupport | D8: 4 | E8: 23.1223 | F8: M / P / J / T | G8: Agile | H8: Q2 | I8: 1 + 1t | J8: 2 | K8: 2 | L8: 2 | M8: 2 | N8: NCD 9.5 · CG 4.6 · unnamed 0.0 | O8: 2.7
C9: Total | D9: =SUM(D5:D8) -> 13 | E9: =SUM(E5:E8) -> 466.4723 | O9: =SUM(O5:O8) -> 99
B11: Pod counts read 'pods + teams'. A team is a 12-seat waterfall / hybrid delivery cell; a pod is a 10-seat agile unit falling to 6 by Year 4. Teams are gone by Year 3. 'CG heads today' is the inherited Capgemini population from the T3 reconciliation behind Golden Inventory v4 — 99 people, 56% of them on the F2F Illustlation stream and specifically on JP-GSSP.

Sheet Pod Library
A1: Pod library — every seat, with MetLife's own role taxonomy as the primary attribute
A2: INPUT. Role (BSA / DEV / TEST / MNT / PM / OTH) is what Year 1 reconciles on. The detail column is the Capgemini role name and carries no arithmetic.
B4: Year | C4: Unit | D4: Seat | E4: Role detail | F4: Role | G4: Exp | H4: Loc | I4: Sourcing | J4: Count | K4: People in the block
B5: 1 | C5: POD | D5: 1 | E5: MetLife Product Owner | F5: PM | G5: E4 | H5: ON | I5: FTE | J5: 1 | K5: =J5*7 -> 7
B6: 1 | C6: POD | D6: 2 | E6: MGCC Engineer | F6: DEV | G6: E3 | H6: OFF | I6: MGCC | J6: 1.6428571 | K6: =J6*7 -> 11.5
B7: 1 | C7: POD | D7: 3 | E7: Business Analyst (bilingual) | F7: BSA | G7: E3 | H7: ON | I7: FTC | J7: 1 | K7: =J7*7 -> 7
B8: 1 | C8: POD | D8: 4 | E8: Pod lead / senior engineer | F8: DEV | G8: E4 | H8: ON | I8: FTC | J8: 1.5 | K8: =J8*7 -> 10.5
B9: 1 | C9: POD | D9: 5 | E9: Engineer | F9: DEV | G9: E3 | H9: ON | I9: FTC | J9: 0.42857143 | K9: =J9*7 -> 3
B10: 1 | C10: POD | D10: 6 | E10: Engineer | F10: DEV | G10: E2 | H10: OFF | I10: FTC | J10: 0.78571429 | K10: =J10*7 -> 5.5
B11: 1 | C11: POD | D11: 7 | E11: Engineer | F11: DEV | G11: E3 | H11: OFF | I11: FTC | J11: 0.57142857 | K11: =J11*7 -> 4
B12: 1 | C12: POD | D12: 8 | E12: Engineer | F12: DEV | G12: E4 | H12: OFF | I12: FTC | J12: 0.21428571 | K12: =J12*7 -> 1.5
B13: 1 | C13: POD | D13: 9 | E13: Quality Engineer (SDET) | F13: TEST | G13: E2 | H13: OFF | I13: FTC | J13: 1.0714286 | K13: =J13*7 -> 7.5
B14: 1 | C14: POD | D14: 10 | E14: Quality Engineer (SDET) | F14: TEST | G14: E3 | H14: OFF | I14: FTC | J14: 1.0714286 | K14: =J14*7 -> 7.5
B15: 1 | C15: POD | D15: 11 | E15: Quality Engineer (SDET) | F15: TEST | G15: E4 | H15: OFF | I15: FTC | J15: 0.28571429 | K15: =J15*7 -> 2
B16: 1 | C16: POD | D16: 12 | E16: Application Support | F16: MNT | G16: E1 | H16: OFF | I16: FTC | J16: 0.14285714 | K16: =J16*7 -> 1
B17: 1 | C17: POD | D17: 13 | E17: Application Support | F17: MNT | G17: E2 | H17: OFF | I17: FTC | J17: 0.21428571 | K17: =J17*7 -> 1.5
D18: POD size — Year 1 | J18: =SUM(J5:J17) -> 9.9285714
B20: 1 | C20: TEAM | D20: 1 | E20: MetLife Product Owner | F20: PM | G20: E4 | H20: ON | I20: FTE | J20: 0.73214286 | K20: =J20*28 -> 20.5
B21: 1 | C21: TEAM | D21: 2 | E21: MetLife Domain SME | F21: BSA | G21: E4 | H21: ON | I21: FTE | J21: 0.98214286 | K21: =J21*28 -> 27.5
B22: 1 | C22: TEAM | D22: 3 | E22: MetLife Operations Analyst | F22: MNT | G22: E3 | H22: ON | I22: FTE | J22: 0.46428571 | K22: =J22*28 -> 13
B23: 1 | C23: TEAM | D23: 4 | E23: MGCC Developer | F23: DEV | G23: E3 | H23: OFF | I23: MGCC | J23: 1.75 | K23: =J23*28 -> 49
B24: 1 | C24: TEAM | D24: 5 | E24: MGCC Test Engineer | F24: TEST | G24: E2 | H24: OFF | I24: MGCC | J24: 0.96428571 | K24: =J24*28 -> 27
B25: 1 | C25: TEAM | D25: 6 | E25: Business Analyst (bilingual) | F25: BSA | G25: E3 | H25: ON | I25: FTC | J25: 1.4107143 | K25: =J25*28 -> 39.5
B26: 1 | C26: TEAM | D26: 7 | E26: Developer / technical lead | F26: DEV | G26: E3 | H26: ON | I26: FTC | J26: 1.7142857 | K26: =J26*28 -> 48
B27: 1 | C27: TEAM | D27: 8 | E27: Developer | F27: DEV | G27: E1 | H27: OFF | I27: FTC | J27: 0.19642857 | K27: =J27*28 -> 5.5
B28: 1 | C28: TEAM | D28: 9 | E28: Developer | F28: DEV | G28: E2 | H28: OFF | I28: FTC | J28: 0.53571429 | K28: =J28*28 -> 15
B29: 1 | C29: TEAM | D29: 10 | E29: Developer | F29: DEV | G29: E3 | H29: OFF | I29: FTC | J29: 0.51785714 | K29: =J29*28 -> 14.5
B30: 1 | C30: TEAM | D30: 11 | E30: Test Lead / onshore tester | F30: TEST | G30: E3 | H30: ON | I30: FTC | J30: 1.8571429 | K30: =J30*28 -> 52
B31: 1 | C31: TEAM | D31: 12 | E31: Test Engineer | F31: TEST | G31: E2 | H31: OFF | I31: FTC | J31: 0.30357143 | K31: =J31*28 -> 8.5
... B33: 1 | C33: TEAM | D33: 14 | E33: Application Support | F33: MNT | G33: E2 | H33: OFF | I33: FTC | J33: 0.125 | K33: =J33*28 -> 3.5
D34: TEAM size — Year 1 | J34: =SUM(J20:J33) -> 11.875
B36: 2 | C36: POD | D36: 1 | E36: MetLife Product Owner | F36: PM | G36: E4 | H36: ON | I36: FTE | J36: 0.92857143 | K36: =J36*35 -> 32.5 | L36: 0.8
B37: 2 | C37: POD | D37: 2 | E37: MetLife Domain SME | F37: BSA | G37: E4 | H37: ON | I37: FTE | J37: 0.67142857 | K37: =J37*35 -> 23.5 | L37: 0.5
B38: 2 | C38: POD | D38: 3 | E38: MGCC Engineer | F38: DEV | G38: E3 | H38: OFF | I38: MGCC | J38: 1.8 | K38: =J38*35 -> 63 | L38: 1.7
B39: 2 | C39: POD | D39: 4 | E39: Business Analyst (bilingual) | F39: BSA | G39: E3 | H39: ON | I39: FTC | J39: 0.55 | K39: =J39*35 -> 19.25 | L39: 0.55
B40: 2 | C40: POD | D40: 5 | E40: Pod lead / senior engineer | F40: DEV | G40: E4 | H40: ON | I40: FTC | J40: 0.71 | K40: =J40*35 -> 24.85 | L40: 0.7
B41: 2 | C41: POD | D41: 6 | E41: AI Orchestrator | F41: OTH | G41: E4 | H41: OFF | I41: FTC | J41: 0.21428571 | K41: =J41*35 -> 7.5 | L41: 0.25
B42: 2 | C42: POD | D42: 7 | E42: AI-assisted engineer | F42: DEV | G42: E2 | H42: OFF | I42: FTC | J42: 0.3 | K42: =J42*35 -> 10.5 | L42: 0.35
B43: 2 | C43: POD | D43: 8 | E43: AI-assisted engineer | F43: DEV | G43: E3 | H43: OFF | I43: FTC | J43: 0.6 | K43: =J43*35 -> 21 | L43: 0.9
B44: 2 | C44: POD | D44: 9 | E44: Quality Engineer (SDET) | F44: TEST | G44: E3 | H44: OFF | I44: FTC | J44: 1.5 | K44: =J44*35 -> 52.5 | L44: 1.5
...

Sheet Pod Plan
A1: Pod plan — how many pods and how many waterfall teams, per stream per year
A2: INPUT. This is where productivity shows up in the headcount, and where the agile conversion shows up in the unit mix.
B4: Year | C4: VS | D4: Value stream | E4: Pods | F4: Teams | G4: Units | H4: People
B5: 1 | C5: F2FILL | D5: F2F Illustlation | E5: 5 | F5: 13 | G5: =E5+F5 -> 18 | H5: =E5*SUM('Pod Library'!$J$5:$J$17)+F5*SUM('Pod Library'!$J$20:$J$33) -> 204.01786
B6: 1 | C6: BANCA | D6: Banca Illustlation | E6: 0 | F6: 12 | G6: =E6+F6 -> 12 | H6: =E6*SUM('Pod Library'!$J$5:$J$17)+F6*SUM('Pod Library'!$J$20:$J$33) -> 142.5
B7: 1 | C7: AGENT | D7: F2F Agent Enablement | E7: 1 | F7: 2 | G7: =E7+F7 -> 3 | H7: =E7*SUM('Pod Library'!$J$5:$J$17)+F7*SUM('Pod Library'!$J$20:$J$33) -> 33.678571
B8: 1 | C8: SUPP | D8: F2F SalesSupport | E8: 1 | F8: 1 | G8: =E8+F8 -> 2 | H8: =E8*SUM('Pod Library'!$J$5:$J$17)+F8*SUM('Pod Library'!$J$20:$J$33) -> 21.803571
D9: Year 1 total | E9: =SUM(E5:E8) -> 7 | F9: =SUM(F5:F8) -> 28 | G9: =SUM(G5:G8) -> 35 | H9: =SUM(H5:H8) -> 402
B11: 2 | C11: F2FILL | D11: F2F Illustlation | E11: 19 | F11: 0 | G11: =E11+F11 -> 19 | H11: =E11*SUM('Pod Library'!$J$36:$J$47)+F11*SUM('Pod Library'!$J$50:$J$60) -> 151.78286
B12: 2 | C12: BANCA | D12: Banca Illustlation | E12: 10 | F12: 3 | G12: =E12+F12 -> 13 | H12: =E12*SUM('Pod Library'!$J$36:$J$47)+F12*SUM('Pod Library'!$J$50:$J$60) -> 109.88571
B13: 2 | C13: AGENT | D13: F2F Agent Enablement | E13: 4 | F13: 0 | G13: =E13+F13 -> 4 | H13: =E13*SUM('Pod Library'!$J$36:$J$47)+F13*SUM('Pod Library'!$J$50:$J$60) -> 31.954286
B14: 2 | C14: SUPP | D14: F2F SalesSupport | E14: 2 | F14: 0 | G14: =E14+F14 -> 2 | H14: =E14*SUM('Pod Library'!$J$36:$J$47)+F14*SUM('Pod Library'!$J$50:$J$60) -> 15.977143
D15: Year 2 total | E15: =SUM(E11:E14) -> 35 | F15: =SUM(F11:F14) -> 3 | G15: =SUM(G11:G14) -> 38 | H15: =SUM(H11:H14) -> 309.6
B17: 3 | C17: F2FILL | D17: F2F Illustlation | E17: 18 | F17: 0 | G17: =E17+F17 -> 18 | H17: =E17*SUM('Pod Library'!$J$63:$J$76) -> 125.79
B18: 3 | C18: BANCA | D18: Banca Illustlation | E18: 13 | F18: 0 | G18: =E18+F18 -> 13 | H18: =E18*SUM('Pod Library'!$J$63:$J$76) -> 90.848333
B19: 3 | C19: AGENT | D19: F2F Agent Enablement | E19: 3 | F19: 0 | G19: =E19+F19 -> 3 | H19: =E19*SUM('Pod Library'!$J$63:$J$76) -> 20.965
B20: 3 | C20: SUPP | D20: F2F SalesSupport | E20: 2 | F20: 0 | G20: =E20+F20 -> 2 | H20: =E20*SUM('Pod Library'!$J$63:$J$76) -> 13.976667
D21: Year 3 total | E21: =SUM(E17:E20) -> 36 | F21: =SUM(F17:F20) -> 0 | G21: =SUM(G17:G20) -> 36 | H21: =SUM(H17:H20) -> 251.58
B23: 4 | C23: F2FILL | D23: F2F Illustlation | E23: 18 | F23: 0 | G23: =E23+F23 -> 18 | H23: =E23*SUM('Pod Library'!$J$79:$J$91) -> 104.69
B24: 4 | C24: BANCA | D24: Banca Illustlation | E24: 13 | F24: 0 | G24: =E24+F24 -> 13 | H24: =E24*SUM('Pod Library'!$J$79:$J$91) -> 75.609444
B25: 4 | C25: AGENT | D25: F2F Agent Enablement | E25: 3 | F25: 0 | G25: =E25+F25 -> 3 | H25: =E25*SUM('Pod Library'!$J$79:$J$91) -> 17.448333
B26: 4 | C26: SUPP | D26: F2F SalesSupport | E26: 2 | F26: 0 | G26: =E26+F26 -> 2 | H26: =E26*SUM('Pod Library'!$J$79:$J$91) -> 11.632222
D27: Year 4 total | E27: =SUM(E23:E26) -> 36 | F27: =SUM(F23:F26) -> 0 | G27: =SUM(G23:G26) -> 36 | H27: =SUM(H23:H26) -> 209.38
B29: 5 | C29: F2FILL | D29: F2F Illustlation | E29: 16 | F29: 0 | G29: =E29+F29 -> 16 | H29: =E29*SUM('Pod Library'!$J$94:$J$106) -> 93.682424
B30: 5 | C30: BANCA | D30: Banca Illustlation | E30: 12 | F30: 0 | G30: =E30+F30 -> 12 | H30: =E30*SUM('Pod Library'!$J$94:$J$106) -> 70.261818
B31: 5 | C31: AGENT | D31: F2F Agent Enablement | E31: 3 | F31: 0 | G31: =E31+F31 -> 3 | H31: =E31*SUM('Pod Library'!$J$94:$J$106) -> 17.565455
B32: 5 | C32: SUPP | D32: F2F SalesSupport | E32: 2 | F32: 0 | G32: =E32+F32 -> 2 | H32: =E32*SUM('Pod Library'!$J$94:$J$106) -> 11.710303
D33: Year 5 total | E33: =SUM(E29:E32) -> 33 | F33: =SUM(F29:F32) -> 0 | G33: =SUM(G29:G32) -> 33 | H33: =SUM(H29:H32) -> 193.22

Sheet Horizontal Teams
A1: Horizontal teams — work that is not stream-bounded
A2: INPUT, defined per year rather than scaled, because the sourcing mix inside the horizontal layer changes as MetLife's own population follows a slower reduction curve than Capgemini's.
B4: Year | C4: Team | D4: Role | E4: Role detail | F4: Exp | G4: Loc | H4: Sourcing | I4: Count | J4: People in the block
B5: 1 | C5: H1 | D5: MNT | E5: Service Delivery Manager | F5: E5 | G5: ON | H5: FTC | I5: 1 | J5: =I5 -> 1
B6: 1 | C6: H1 | D6: MNT | E6: Release & Environment Manager | F6: E4 | G6: ON | H6: FTC | I6: 2.5 | J6: =I6 -> 2.5
B7: 1 | C7: H1 | D7: MNT | E7: L2 Application Support | F7: E1 | G7: OFF | H7: FTC | I7: 2 | J7: =I7 -> 2
B8: 1 | C8: H1 | D8: MNT | E8: L2 Application Support | F8: E2 | G8: OFF | H8: FTC | I8: 1 | J8: =I8 -> 1
B9: 1 | C9: H1 | D9: MNT | E9: Incident & Problem Analyst | F9: E3 | G9: ON | H9: FTC | I9: 1 | J9: =I9 -> 1
B10: 1 | C10: H1 | D10: OTH | E10: Observability / AIOps Engineer | F10: E3 | G10: OFF | H10: FTC | I10: 1 | J10: =I10 -> 1
B11: 1 | C11: H1 | D11: DEV | E11: Platform & Integration Engineer | F11: E3 | G11: ON | H11: FTC | I11: 3.5 | J11: =I11 -> 3.5
B12: 1 | C12: H1 | D12: DEV | E12: Platform & Integration Engineer | F12: E3 | G12: OFF | H12: FTC | I12: 3 | J12: =I12 -> 3
B13: 1 | C13: H1 | D13: DEV | E13: Offshore Engineering Lead | F13: E5 | G13: OFF | H13: FTC | I13: 1 | J13: =I13 -> 1
B14: 1 | C14: H1 | D14: DEV | E14: MGCC Platform SRE | F14: E3 | G14: OFF | H14: MGCC | I14: 2.5 | J14: =I14 -> 2.5
B15: 1 | C15: H1 | D15: PM | E15: MetLife Service Owner | F15: E4 | G15: ON | H15: FTE | I15: 2 | J15: =I15 -> 2
B16: 1 | C16: H1 | D16: MNT | E16: MetLife Distribution Ops Analyst | F16: E3 | G16: ON | H16: FTE | I16: 5 | J16: =I16 -> 5
... B34: 1 | C34: H3 | D34: PM | E34: MetLife Portfolio Manager | F34: E4 | G34: ON | H34: FTE | I34: 1.5 | J34: =I34 -> 1.5
E35: Year 1 horizontal total | I35: =SUM(I5:I34) -> 64.5
B37: 2 | C37: H1 | D37: MNT | E37: Service Delivery Manager | F37: E5 | G37: ON | H37: FTC | I37: 1.5 | J37: =I37 -> 1.5
B38: 2 | C38: H1 | D38: MNT | E38: Release & Environment Manager | F38: E4 | G38: ON | H38: FTC | I38: 2.5 | J38: =I38 -> 2.5
B39: 2 | C39: H1 | D39: MNT | E39: L2 Application Support | F39: E1 | G39: OFF | H39: FTC | I39: 1 | J39: =I39 -> 1
B40: 2 | C40: H1 | D40: MNT | E40: L2 Application Support | F40: E2 | G40: OFF | H40: FTC | I40: 1 | J40: =I40 -> 1
B41: 2 | C41: H1 | D41: MNT | E41: Incident & Problem Analyst | F41: E3 | G41: ON | H41: FTC | I41: 1 | J41: =I41 -> 1
B42: 2 | C42: H1 | D42: OTH | E42: Observability / AIOps Engineer | F42: E3 | G42: OFF | H42: FTC | I42: 2.5 | J42: =I42 -> 2.5
B43: 2 | C43: H1 | D43: DEV | E43: Platform & Integration Engineer | F43: E3 | G43: ON | H43: FTC | I43: 2.5 | J43: =I43 -> 2.5
B44: 2 | C44: H1 | D44: DEV | E44: Platform & Integration Engineer | F44: E3 | G44: OFF | H44: FTC | I44: 0.5 | J44: =I44 -> 0.5
B45: 2 | C45: H1 | D45: DEV | E45: Offshore Engineering Lead | F45: E5 | G45: OFF | H45: FTC | I45: 0.5 | J45: =I45 -> 0.5
B46: 2 | C46: H1 | D46: DEV | E46: MGCC Platform SRE | F46: E3 | G46: OFF | H46: MGCC | I46: 3 | J46: =I46 -> 3
B47: 2 | C47: H1 | D47: PM | E47: MetLife Service Owner | F47: E4 | G47: ON | H47: FTE | I47: 1.5 | J47: =I47 -> 1.5
B48: 2 | C48: H1 | D48: MNT | E48: MetLife Distribution Ops Analyst | F48: E3 | G48: ON | H48: FTE | I48: 5 | J48: =I48 -> 5
... B66: 2 | C66: H3 | D66: PM | E66: MetLife Portfolio Manager | F66: E4 | G66: ON | H66: FTE | I66: 1.5 | J66: =I66 -> 1.5
E67: Year 2 horizontal total | I67: =SUM(I37:I66) -> 50
B69: 3 | C69: H1 | D69: MNT | E69: Service Delivery Manager | F69: E5 | G69: ON | H69: FTC | I69: 1 | J69: =I69 -> 1
B70: 3 | C70: H1 | D70: MNT | E70: Release & Environment Manager | F70: E4 | G70: ON | H70: FTC | I70: 1 | J70: =I70 -> 1
B71: 3 | C71: H1 | D71: MNT | E71: L2 Application Support | F71: E1 | G71: OFF | H71: FTC | I71: 0.5 | J71: =I71 -> 0.5
B72: 3 | C72: H1 | D72: MNT | E72: L2 Application Support | F72: E2 | G72: OFF | H72: FTC | I72: 0.5 | J72: =I72 -> 0.5
B73: 3 | C73: H1 | D73: MNT | E73: Incident & Problem Analyst | F73: E3 | G73: ON | H73: FTC | I73: 1 | J73: =I73 -> 1
B74: 3 | C74: H1 | D74: OTH | E74: Observability / AIOps Engineer | F74: E3 | G74: OFF | H74: FTC | I74: 0.5 | J74: =I74 -> 0.5
B75: 3 | C75: H1 | D75: DEV | E75: Platform & Integration Engineer | F75: E3 | G75: ON | H75: FTC | I75: 1.5 | J75: =I75 -> 1.5
B76: 3 | C76: H1 | D76: DEV | E76: Platform & Integration Engineer | F76: E3 | G76: OFF | H76: FTC | I76: 0.5 | J76: =I76 -> 0.5
B77: 3 | C77: H1 | D77: DEV | E77: Offshore Engineering Lead | F77: E5 | G77: OFF | H77: FTC | I77: 0.5 | J77: =I77 -> 0.5
...

Sheet Team Build-Up
A1: Team build-up — and the Year-1 reconciliation to Appendix 3 v3
A2: Nothing on this sheet is typed. Section B is the test that matters: the roster has to be the client's own Year-1 position on effort, sourcing, location AND role.
A4: A. HEADCOUNT
B5: Measure | C5: Year 1 | D5: Year 2 | E5: Year 3 | F5: Year 4 | G5: Year 5
B6: People in agile pods | C6: =SUMIFS('Seat Ledger'!$M$5:$M$468,'Seat Ledger'!$B$5:$B$468,1,'Seat Ledger'!$C$5:$C$468,"POD") -> 69.5 | D6: =SUMIFS('Seat Ledger'!$M$5:$M$468,'Seat Ledger'!$B$5:$B$468,2,'Seat Ledger'!$C$5:$C$468,"POD") -> 279.6 | E6: =SUMIFS('Seat Ledger'!$M$5:$M$468,'Seat Ledger'!$B$5:$B$468,3,'Seat Ledger'!$C$5:$C$468,"POD") -> 251.58 | F6: =SUMIFS('Seat Ledger'!$M$5:$M$468,'Seat Ledger'!$B$5:$B$468,4,'Seat Ledger'!$C$5:$C$468,"POD") -> 209.38 | G6: =SUMIFS('Seat Ledger'!$M$5:$M$468,'Seat Ledger'!$B$5:$B$468,5,'Seat Ledger'!$C$5:$C$468,"POD") -> 193.22
