Workbook

Sheet README
A1: MetLife Japan | Fee Management — Operating Model & Pricing Engine
A2: INTERNAL — Capgemini review copy. Not for issue to MetLife. Domain filtered from Appendix 3 v2 (142 apps / 1,504.0 units); this domain is 5 apps / 48.5 units.
A4: HOW THIS WORKBOOK IS BUILT
B5: Direction of travel | C5: Everything is bottom-up. You define seats in pods; the workbook derives headcount, productivity, offshore share, experience mix and cost. Nothing is asserted.
B6: The two logic trees | C6: 'Logic Tree' derives a TARGET productivity and offshore % for any domain from its archetype mix. 'Glidepath & 50-50' compares that target against what the pod design actually delivers. The gap is the transition & enablement drag.
B7: Re-using for another domain | C7: Change the domain on 'Logic Tree' cell C5. The archetype mix, effort base and target percentages re-derive from 'Inventory'. The pod library and pod plan must then be re-cut for that domain's value streams.
A8: CELL COLOUR CONVENTION
B9: Blue text | C9: Input. Change these.
B10: Black text | C10: Formula. Do not overwrite.
B11: Green text | C11: Link to another sheet in this workbook.
B12: Amber fill | C12: Key assumption requiring sign-off before this model is used to price.
A13: SHEET MAP
B14: Logic Tree | C14: Parametric drivers. Phase effort mix, AI-addressable ceiling per archetype, realisation curve, offshore ceiling, re-badge plan, cost index.
B15: Inventory | C15: All 142 applications with derived archetype. Filter to a domain to see its mix.
B16: Value Streams | C16: The three functional value streams inside Fee Management and the AD / AMS split of each.
B17: Pod Library | C17: INPUT. Every seat in every pod archetype, for Y1 / Y2 / Y3. Role, skill family, experience band, location, sourcing.
B18: Pod Plan | C18: INPUT. How many co-sourced and fully-sourced pods each value stream runs in each year.
B19: Horizontal Teams | C19: INPUT. Seats in the three cross-cutting teams that are not value-stream bounded.
B20: Seat Ledger | C20: Computed. Every pod-library line multiplied out by the pod plan, plus the horizontal seats. All roll-ups read from here.
B21: Team Build-Up | C21: Computed. Headcount by year, by value stream, by sourcing, by location, by experience band and by skill family.
B22: Glidepath & 50-50 | C22: Computed. Productivity target vs delivered, offshore target vs delivered, and the re-badge volume needed to reach 50:50.
B23: Cost & Commercial | C23: Computed. Cost index, cost per unit of original scope, and the Capgemini billable position after re-badging.
A24: ASSUMPTIONS THAT NEED SIGN-OFF
B25: Cost index | C25: Relative only. Onshore Tokyo E2 = 1.00, offshore at roughly one third at like-for-like band. Replace with the approved rate card before pricing.
B26: AI-addressable ceilings | C26: Derived from published evidence, not from a Capgemini delivery baseline. See the sources block on the Logic Tree sheet.
B27: Re-badge feasibility | C27: Assumes transfer of employment (転籍) is achievable with individual consent and that MetLife will accept the receiving cost base. Not tested.
B28: Effort unit = one person | C28: Appendix 3 states effort in FTE-equivalents. One unit is treated as one seat throughout.
B30: Built | C30: September 2026 · Capgemini · Fee Management domain model v1

Sheet Logic Tree
A1: Logic Tree — parametric drivers for productivity and offshore share
A2: Change the blue cells. Every downstream number re-derives. Amber cells need sign-off.
A4: A. DOMAIN SELECTION AND EFFORT BASE
B5: Domain | C5: fee management | I5: Type any domain name from the Inventory sheet, lower case.
B6: Applications in domain | C6: =SUMIFS(Inventory!$U:$U,Inventory!$E:$E,$C$5) -> 5
B7: Total effort (units) | C7: =SUMIFS(Inventory!$AD:$AD,Inventory!$E:$E,$C$5) -> 48.510292
B8: Current FTC | C8: =SUMIFS(Inventory!$AA:$AA,Inventory!$E:$E,$C$5) -> 38.147792
B9: Current FTE | C9: =SUMIFS(Inventory!$AB:$AB,Inventory!$E:$E,$C$5) -> 9.7791667
B10: Current MGCC | C10: =SUMIFS(Inventory!$AC:$AC,Inventory!$E:$E,$C$5) -> 0.58333333
B11: AD effort (%PRJ weighted) | C11: =SUMIFS(Inventory!$AF:$AF,Inventory!$E:$E,$C$5) -> 43.118625
B12: AMS effort | C12: =C7-C11 -> 5.3916667
B13: AD share of effort | C13: =IF(C7=0,0,C11/C7) -> 0.8888552
A15: B. ARCHETYPE MIX OF THE SELECTED DOMAIN — this is what drives the applicable percentages
B16: Archetype | C16: Definition | D16: Apps | E16: Effort | F16: Share of effort
B17: A | C17: Language-locked — Japanese business content bound to the application | D17: =SUMIFS(Inventory!$U:$U,Inventory!$E:$E,$C$5,Inventory!$AG:$AG,$B17) -> 2 | E17: =SUMIFS(Inventory!$AD:$AD,Inventory!$E:$E,$C$5,Inventory!$AG:$AG,$B17) -> 29.235292 | F17: =IF($C$7=0,0,E17/$C$7) -> 0.60266163
B18: B | C18: Offshore-ready — modern stack, documented, no language lock | D18: =SUMIFS(Inventory!$U:$U,Inventory!$E:$E,$C$5,Inventory!$AG:$AG,$B18) -> 3 | E18: =SUMIFS(Inventory!$AD:$AD,Inventory!$E:$E,$C$5,Inventory!$AG:$AG,$B18) -> 19.275 | F18: =IF($C$7=0,0,E18/$C$7) -> 0.39733837
B19: C | C19: MGCC-destined — flagged Priority Transfer Target | D19: =SUMIFS(Inventory!$U:$U,Inventory!$E:$E,$C$5,Inventory!$AG:$AG,$B19) -> 0 | E19: =SUMIFS(Inventory!$AD:$AD,Inventory!$E:$E,$C$5,Inventory!$AG:$AG,$B19) -> 0 | F19: =IF($C$7=0,0,E19/$C$7) -> 0
B20: D | C20: Legacy-coupled core — mainframe / AS400, COBOL / Assembler | D20: =SUMIFS(Inventory!$U:$U,Inventory!$E:$E,$C$5,Inventory!$AG:$AG,$B20) -> 0 | E20: =SUMIFS(Inventory!$AD:$AD,Inventory!$E:$E,$C$5,Inventory!$AG:$AG,$B20) -> 0 | F20: =IF($C$7=0,0,E20/$C$7) -> 0
B21: Total | D21: =SUM(D17:D20) -> 5 | E21: =SUM(E17:E20) -> 48.510292 | F21: =SUM(F17:F20) -> 1
A23: C. PRODUCTIVITY TREE — LEVEL 1 : where the effort sits across the delivery lifecycle
B24: Delivery phase | C24: Share of effort
B25: Requirements & impact analysis | C25: 0.15
B26: Design & architecture | C26: 0.1
B27: Build & code | C27: 0.3
B28: Test & quality assurance | C28: 0.25
B29: Release & deploy | C29: 0.05
B30: Run, monitor & coordinate | C30: 0.15
B31: Total (must equal 100%) | C31: =SUM(C25:C30) -> 1
A33: D. PRODUCTIVITY TREE — LEVEL 2 : how much of each phase AI can address, by archetype
B34: The ceiling if the capability were fully mature and fully adopted. Not a forecast.
B35: Delivery phase | C35: A | D35: B | E35: C | F35: D
B36: Requirements & impact analysis | C36: 0.22 | D36: 0.35 | E36: 0.35 | F36: 0.35
B37: Design & architecture | C37: 0.2 | D37: 0.3 | E37: 0.3 | F37: 0.22
B38: Build & code | C38: 0.32 | D38: 0.55 | E38: 0.5 | F38: 0.2
B39: Test & quality assurance | C39: 0.38 | D39: 0.6 | E39: 0.55 | F39: 0.4
B40: Release & deploy | C40: 0.3 | D40: 0.5 | E40: 0.45 | F40: 0.25
B41: Run, monitor & coordinate | C41: 0.3 | D41: 0.4 | E41: 0.4 | F41: 0.32
B42: Weighted AI ceiling by archetype | C42: =SUMPRODUCT($C$25:$C$30,C36:C41) -> 0.304 | D42: =SUMPRODUCT($C$25:$C$30,D36:D41) -> 0.4825 | E42: =SUMPRODUCT($C$25:$C$30,E36:E41) -> 0.4525 | F42: =SUMPRODUCT($C$25:$C$30,F36:F41) -> 0.295
B43: Applicable AI ceiling for THIS domain | C43: =IF($C$7=0,0,(C42*$E$17+D42*$E$18+E42*$E$19+F42*$E$20)/$C$7) -> 0.3749249
A46: E. PRODUCTIVITY TREE — LEVEL 3 : realisation curve, and the two non-AI components
...

Sheet Inventory
A1: Application inventory — Appendix 3 v2, with derived archetype and value stream
A2: Archetype is DERIVED, not asserted: mainframe language → D; else Priority Transfer Target → C; else SaaS → A; else B.
A4: # | B4: EAI ID | C4: Application | D4: Long name | E4: Domain | F4: Group | G4: Team | H4: Class | I4: Critical | J4: Hosting | K4: Primary code language | L4: Cloud platform | M4: Priority transfer | N4: Current FTC | O4: Current FTE | P4: Current MGCC | Q4: Total | R4: % of PRJ | S4: Target FTC | T4: Target FTE/MGCC | U4: App count | AA4: FTC | AB4: FTE | AC4: MGCC | AD4: Effort | AE4: AD share | AF4: AD effort | AG4: Archetype | AH4: Value stream
A5: 1 | B5: 9629 | C5: Global Sales Comp - Japan | D5: Global Sales Comp - Japan | E5: fee management | F5: Core Insurance Systems Group 34956 | G5: Commission Systems Team 34958 | H5: Core Business Application | I5: N | J5: Yes | K5: Other#Infomatica workflow Bash shell Dos batch | L5: Software as a Service (SaaS) | M5: N | N5: 0 | O5: 0 | P5: 0 | Q5: 0 | R5: 0 | U5: 1 | AA5: =N5 -> 0 | AB5: =O5 -> 0 | AC5: =P5 -> 0 | AD5: =Q5 -> 0 | AE5: =R5 -> 0 | AF5: =Q5*R5 -> 0 | AG5: A | AH5: VS1
A6: 2 | B6: 9796 | C6: LC POSPMC MF-JPN | D6: LifeComm POSPMC | E6: contract management | F6: Core Insurance Systems Group 34956 | G6: Policy Admin Systems Team 34957 | H6: Core Business Application | I6: Y | J6: Yes | K6: Assembler, COBOL, MU(EASYPLUS), JCL | M6: N | N6: 59.558958 | O6: 7.7541667 | P6: 0 | Q6: 67.313125 | R6: 0.71176374 | S6: 33.656562 | T6: 33.656562 | U6: 1 | AA6: =N6 -> 59.558958 | AB6: =O6 -> 7.7541667 | AC6: =P6 -> 0 | AD6: =Q6 -> 67.313125 | AE6: =R6 -> 0.71176374 | AF6: =Q6*R6 -> 47.911042 | AG6: D | AH6: VS1
A7: 3 | B7: 9800 | C7: LC Billing MF-JPN | D7: LifeComm Billing | E7: contract management | F7: Core Insurance Systems Group 34956 | G7: Policy Admin Systems Team 34957 | H7: Core Business Application | I7: Y | J7: Yes | K7: COBOL, Assembler, MU(EASYPLUS), JCL | M7: N | N7: 20.892167 | O7: 1.85375 | P7: 0 | Q7: 22.745917 | R7: 0.94285788 | S7: 11.372958 | T7: 11.372958 | U7: 1 | AA7: =N7 -> 20.892167 | AB7: =O7 -> 1.85375 | AC7: =P7 -> 0 | AD7: =Q7 -> 22.745917 | AE7: =R7 -> 0.94285788 | AF7: =Q7*R7 -> 21.446167 | AG7: D | AH7: VS2
A8: 4 | B8: 9801 | C8: LC Collection MF-JPN | D8: LifeComm Collection | E8: contract management | F8: Core Insurance Systems Group 34956 | G8: Policy Admin Systems Team 34957 | H8: Core Business Application | I8: Y | J8: Yes | K8: COBOL, Assembler, MU(EASYPLUS), JCL | M8: N | N8: 0 | O8: 0 | P8: 0 | Q8: 0 | R8: 0 | U8: 1 | AA8: =N8 -> 0 | AB8: =O8 -> 0 | AC8: =P8 -> 0 | AD8: =Q8 -> 0 | AE8: =R8 -> 0 | AF8: =Q8*R8 -> 0 | AG8: D | AH8: VS2
A9: 5 | B9: 9802 | C9: LC Corresponding MF-JPN | D9: LifeComm Corresponding | E9: contract management | F9: Core Insurance Systems Group 34956 | G9: Policy Admin Systems Team 34957 | H9: Core Business Application | I9: Y | J9: Yes | K9: COBOL, Assembler, MU(EASYPLUS), JCL | M9: N | N9: 15.953625 | O9: 1.6541667 | P9: 0 | Q9: 17.607792 | R9: 0.98287217 | S9: 8.8038958 | T9: 8.8038958 | U9: 1 | AA9: =N9 -> 15.953625 | AB9: =O9 -> 1.6541667 | AC9: =P9 -> 0 | AD9: =Q9 -> 17.607792 | AE9: =R9 -> 0.98287217 | AF9: =Q9*R9 -> 17.306208 | AG9: D | AH9: VS4
A10: 6 | B10: 9803 | C10: LC UWI MF-JPN | D10: LifeComm UWI | E10: contract management | F10: Core Insurance Systems Group 34956 | G10: Policy Admin Systems Team 34957 | H10: Core Business Application | I10: Y | J10: Yes | K10: Assembler, COBOL, MU(EASYPLUS), JCL | M10: N | N10: 8.8045833 | O10: 0.85 | P10: 0 | Q10: 9.6545833 | R10: 0.94821113 | S10: 4.8272917 | T10: 4.8272917 | U10: 1 | AA10: =N10 -> 8.8045833 | AB10: =O10 -> 0.85 | AC10: =P10 -> 0 | AD10: =Q10 -> 9.6545833 | AE10: =R10 -> 0.94821113 | AF10: =Q10*R10 -> 9.1545833 | AG10: D | AH10: VS1
A11: 7 | B11: 9804 | C11: LC AAPerf MF-JPN | D11: LifeComm AgentAgencyPerformance | E11: contract management | F11: Core Insurance Systems Group 34956 | G11: Policy Admin Systems Team 34957 | H11: Core Business Application | I11: Y | J11: Yes | K11: COBOL, Assembler, MU(EASYPLUS), JCL | M11: N | N11: 10.784167 | O11: 0.74583333 | P11: 0 | Q11: 11.53 | R11: 0.83304423 | S11: 5.765 | T11: 5.765 | U11: 1 | AA11: =N11 -> 10.784167 | AB11: =O11 -> 0.74583333 | AC11: =P11 -> 0 | AD11: =Q11 -> 11.53 | AE11: =R11 -> 0.83304423 | AF11: =Q11*R11 -> 9.605 | AG11: D | AH11: VS3
A12: 8 | B12: 9805 | C12: LC Payment MF-JPN | D12: LifeComm Payment | E12: contract management | F12: Core Insurance Systems Group 34956 | G12: Policy Admin Systems Team 34957 | H12: Core Business Application | I12: Y | J12: Yes | K12: COBOL, Assembler, MU(EASYPLUS), JCL | M12: N | N12: 2.8966667 | O12: 0.025 | P12: 0 | Q12: 2.9216667 | R12: 0.90587564 | S12: 1.4608333 | T12: 1.4608333 | U12: 1 | AA12: =N12 -> 2.8966667 | AB12: =O12 -> 0.025 | AC12: =P12 -> 0 | AD12: =Q12 -> 2.9216667 | AE12: =R12 -> 0.90587564 | AF12: =Q12*R12 -> 2.6466667 | AG12: D | AH12: VS2
A13: 9 | B13: 9806 | C13: LC GL/SC MF-JPN | D13: LifeComm GL/SC | E13: contract management | F13: Core Insurance Systems Group 34956 | G13: Policy Admin Systems Team 34957 | H13: Core Business Application | I13: Y | J13: Yes | K13: COBOL, Assembler, MU(EASYPLUS), JCL | M13: N | N13: 5.28875 | O13: 1.025 | P13: 0 | Q13: 6.31375 | R13: 0.83765591 | S13: 3.156875 | T13: 3.156875 | U13: 1 | AA13: =N13 -> 5.28875 | AB13: =O13 -> 1.025 | AC13: =P13 -> 0 | AD13: =Q13 -> 6.31375 | AE13: =R13 -> 0.83765591 | AF13: =Q13*R13 -> 5.28875 | AG13: D | AH13: VS6
A14: 10 | B14: 9807 | C14: LC Valuation MF-JPN | D14: LifeComm Valuation | E14: contract management | F14: Core Insurance Systems Group 34956 | G14: Policy Admin Systems Team 34957 | H14: Core Business Application | I14: N | J14: Yes | K14: COBOL, Assembler, MU(EASYPLUS), JCL | M14: N | N14: 9.76875 | O14: 1.4833333 | P14: 0 | Q14: 11.252083 | R14: 0.8563229 | S14: 5.6260417 | T14: 5.6260417 | U14: 1 | AA14: =N14 -> 9.76875 | AB14: =O14 -> 1.4833333 | AC14: =P14 -> 0 | AD14: =Q14 -> 11.252083 | AE14: =R14 -> 0.8563229 | AF14: =Q14*R14 -> 9.6354167 | AG14: D | AH14: VS6
A15: 11 | B15: 9808 | C15: LC AACOMP MF-JPN | D15: LifeComm AgentAgencyComp | E15: contract management | F15: Core Insurance Systems Group 34956 | G15: Policy Admin Systems Team 34957 | H15: Core Business Application | I15: Y | J15: Yes | K15: COBOL, Assembler, MU(EASYPLUS), JCL | M15: N | N15: 13.545708 | O15: 3.14375 | P15: 0 | Q15: 16.689458 | R15: 0.72662384 | S15: 8.3447292 | T15: 8.3447292 | U15: 1 | AA15: =N15 -> 13.545708 | AB15: =O15 -> 3.14375 | AC15: =P15 -> 0 | AD15: =Q15 -> 16.689458 | AE15: =R15 -> 0.72662384 | AF15: =Q15*R15 -> 12.126958 | AG15: D | AH15: VS3
A16: 12 | B16: 9810 | C16: Processor-I MF-JPN | D16: Claim payment (Processor-I) | E16: contract management | F16: Core Insurance Systems Group 34956 | G16: Policy Admin Systems Team 34957 | H16: Core Business Application | I16: Y | J16: Yes | K16: COBOL, MU(EASYPLUS), Assembler, JCL | M16: N | N16: 7.6683333 | O16: 1.1291667 | P16: 0 | Q16: 8.7975 | R16: 0.75561239 | S16: 4.39875 | T16: 4.39875 | U16: 1 | AA16: =N16 -> 7.6683333 | AB16: =O16 -> 1.1291667 | AC16: =P16 -> 0 | AD16: =Q16 -> 8.7975 | AE16: =R16 -> 0.75561239 | AF16: =Q16*R16 -> 6.6475 | AG16: D | AH16: VS2
A17: 13 | B17: 9811 | C17: LC Submit MF-JPN | D17: Submit Online | E17: contract management | F17: Core Insurance Systems Group 34956 | G17: Policy Admin Systems Team 34957 | H17: Core Business Application | I17: Y | J17: Yes | K17: COBOL, MU(EASYPLUS), Assembler, JCL | M17: N | N17: 1.9683333 | O17: 0.16458333 | P17: 0 | Q17: 2.1329167 | R17: 0.95311584 | S17: 1.0664583 | T17: 1.0664583 | U17: 1 | AA17: =N17 -> 1.9683333 | AB17: =O17 -> 0.16458333 | AC17: =P17 -> 0 | AD17: =Q17 -> 2.1329167 | AE17: =R17 -> 0.95311584 | AF17: =Q17*R17 -> 2.0329167 | AG17: D | AH17: VS1
A18: 14 | B18: 9813 | C18: LC Micro MF-JPN | D18: Micro-Index | E18: contract management | F18: Core Insurance Systems Group 34956 | G18: Policy Admin Systems Team 34957 | H18: Core Business Application | I18: Y | J18: Yes | K18: COBOL, MU(EASYPLUS), Assembler, JCL | M18: N | N18: 2.1175 | O18: 0 | P18: 0 | Q18: 2.1175 | R18: 0.64580874 | S18: 1.05875 | T18: 1.05875 | U18: 1 | AA18: =N18 -> 2.1175 | AB18: =O18 -> 0 | AC18: =P18 -> 0 | AD18: =Q18 -> 2.1175 | AE18: =R18 -> 0.64580874 | AF18: =Q18*R18 -> 1.3675 | AG18: D | AH18: VS1
A19: 15 | B19: 9814 | C19: Foreign MF-JPN | D19: Foreign | E19: contract management | F19: Core Insurance Systems Group 34956 | G19: Policy Admin Systems Team 34957 | H19: Core Business Application | I19: N | J19: Yes | K19: COBOL, MU(EASYPLUS), Assembler, JCL | M19: N | N19: 0 | O19: 0 | P19: 0 | Q19: 0 | R19: 0 | U19: 1 | AA19: =N19 -> 0 | AB19: =O19 -> 0 | AC19: =P19 -> 0 | AD19: =Q19 -> 0 | AE19: =R19 -> 0 | AF19: =Q19*R19 -> 0 | AG19: D | AH19: VS1
A20: 16 | B20: 9816 | C20: CT Salary MF-JPN | D20: CT Salary System | E20: contract management | F20: Core Insurance Systems Group 34956 | G20: Policy Admin Systems Team 34957 | H20: Core Business Application | I20: Y | J20: Yes | K20: COBOL, MU(EASYPLUS), Assembler, JCL | M20: N | N20: 0.2 | O20: 0 | P20: 0 | Q20: 0.2 | R20: 0 | S20: 0.1 | T20: 0.1 | U20: 1 | AA20: =N20 -> 0.2 | AB20: =O20 -> 0 | AC20: =P20 -> 0 | AD20: =Q20 -> 0.2 | AE20: =R20 -> 0 | AF20: =Q20*R20 -> 0 | AG20: D | AH20: VS6
A21: 17 | B21: 9817 | C21: TaxCertification MF-JPN | D21: TaxCertification | E21: contract management | F21: Core Insurance Systems Group 34956 | G21: Policy Admin Systems Team 34957 | H21: Core Business Application | I21: N | J21: Yes | K21: COBOL, MU(EASYPLUS), Assembler, JCL | M21: N | N21: 1.664875 | O21: 0 | P21: 0 | Q21: 1.664875 | R21: 0.40748805 | S21: 0.8324375 | T21: 0.8324375 | U21: 1 | AA21: =N21 -> 1.664875 | AB21: =O21 -> 0 | AC21: =P21 -> 0 | AD21: =Q21 -> 1.664875 | AE21: =R21 -> 0.40748805 | AF21: =Q21*R21 -> 0.67841667 | AG21: D | AH21: VS4
A22: 18 | B22: 9818 | C22: SWINGMANAGER MF-JPN | D22: SWING MANAGER | E22: contract management | F22: Core Insurance Systems Group 34956 | G22: Policy Admin Systems Team 34957 | H22: Core Business Application | I22: N | J22: Yes | K22: COBOL, MU(EASYPLUS), Assembler, JCL | M22: N | N22: 0 | O22: 0 | P22: 0 | Q22: 0 | R22: 0 | U22: 1 | AA22: =N22 -> 0 | AB22: =O22 -> 0 | AC22: =P22 -> 0 | AD22: =Q22 -> 0 | AE22: =R22 -> 0 | AF22: =Q22*R22 -> 0 | AG22: D | AH22: VS1
A23: 19 | B23: 9819 | C23: PremCollectDBMF-JPN | D23: Premium Collection History DB | E23: contract management | F23: Core Insurance Systems Group 34956 | G23: Policy Admin Systems Team 34957 | H23: Core Business Application | I23: N | J23: Yes | K23: COBOL, MU(EASYPLUS), Assembler, JCL | M23: N | N23: 0 | O23: 0 | P23: 0 | Q23: 0 | R23: 0 | U23: 1 | AA23: =N23 -> 0 | AB23: =O23 -> 0 | AC23: =P23 -> 0 | AD23: =Q23 -> 0 | AE23: =R23 -> 0 | AF23: =Q23*R23 -> 0 | AG23: D | AH23: VS1
A24: 20 | B24: 9820 | C24: MCFA CP DB MF-JPN | D24: MCFA Coupon DB | E24: contract management | F24: Core Insurance Systems Group 34956 | G24: Policy Admin Systems Team 34957 | H24: Core Business Application | I24: Y | J24: Yes | K24: COBOL, MU(EASYPLUS), Assembler, JCL | M24: N | N24: 0 | O24: 0 | P24: 0 | Q24: 0 | R24: 0 | U24: 1 | AA24: =N24 -> 0 | AB24: =O24 -> 0 | AC24: =P24 -> 0 | AD24: =Q24 -> 0 | AE24: =R24 -> 0 | AF24: =Q24*R24 -> 0 | AG24: D | AH24: VS1
A25: 21 | B25: 9821 | C25: Maturity MF-JPN | D25: Payment maturity existing benefit etc | E25: contract management | F25: Core Insurance Systems Group 34956 | G25: Policy Admin Systems Team 34957 | H25: Core Business Application | I25: Y | J25: Yes | K25: COBOL, MU(EASYPLUS), Assembler, JCL | M25: N | N25: 4.3783333 | O25: 0.97083333 | P25: 0 | Q25: 5.3491667 | R25: 0.62610999 | S25: 2.6745833 | T25: 2.6745833 | U25: 1 | AA25: =N25 -> 4.3783333 | AB25: =O25 -> 0.97083333 | AC25: =P25 -> 0 | AD25: =Q25 -> 5.3491667 | AE25: =R25 -> 0.62610999 | AF25: =Q25*R25 -> 3.3491667 | AG25: D | AH25: VS2
A26: 22 | B26: 9822 | C26: LC Reins MF-JPN | D26: Reinsurance | E26: contract management | F26: Core Insurance Systems Group 34956 | G26: Policy Admin Systems Team 34957 | H26: Core Business Application | I26: N | J26: Yes | K26: COBOL, MU(EASYPLUS), Assembler, JCL | M26: N | N26: 6.0129167 | O26: 0.25416667 | P26: 0 | Q26: 6.2670833 | R26: 0.78990759 | S26: 3.1335417 | T26: 3.1335417 | U26: 1 | AA26: =N26 -> 6.0129167 | AB26: =O26 -> 0.25416667 | AC26: =P26 -> 0 | AD26: =Q26 -> 6.2670833 | AE26: =R26 -> 0.78990759 | AF26: =Q26*R26 -> 4.9504167 | AG26: D | AH26: VS6
A27: 23 | B27: 9823 | C27: ASP Bridge(H) MF-JPN | D27: ASP Bridge (HOST) | E27: contract management | F27: Core Insurance Systems Group 34956 | G27: Policy Admin Systems Team 34957 | H27: Common Service Business Application | I27: Y | J27: Yes | K27: COBOL, MU(EASYPLUS), Assembler, JCL | M27: N | N27: 6.7267083 | O27: 1.4625 | P27: 0 | Q27: 8.1892083 | R27: 0.72808727 | S27: 4.0946042 | T27: 4.0946042 | U27: 1 | AA27: =N27 -> 6.7267083 | AB27: =O27 -> 1.4625 | AC27: =P27 -> 0 | AD27: =Q27 -> 8.1892083 | AE27: =R27 -> 0.72808727 | AF27: =Q27*R27 -> 5.9624583 | AG27: D | AH27: VS5
A28: 24 | B28: 9824 | C28: CCA MF-JPN | D28: Client Contract Administration | E28: contract management | F28: Core Insurance Systems Group 34956 | G28: Policy Admin Systems Team 34957 | H28: Core Business Application | I28: Y | J28: Yes | K28: COBOL, MU(EASYPLUS), Assembler, JCL | M28: N | N28: 1.6308333 | O28: 0 | P28: 0 | Q28: 1.6308333 | R28: 0.38681656 | S28: 0.81541667 | T28: 0.81541667 | U28: 1 | AA28: =N28 -> 1.6308333 | AB28: =O28 -> 0 | AC28: =P28 -> 0 | AD28: =Q28 -> 1.6308333 | AE28: =R28 -> 0.38681656 | AF28: =Q28*R28 -> 0.63083333 | AG28: D | AH28: VS1
A29: 25 | B29: 9833 | C29: C04NWC-JPN | D29: CenterServer | E29: new contract related | F29: Customer Service and Operations Systems Group 34965 | G29: New Business Team 34966 | H29: Core Business Application | I29: N | J29: Yes | K29: C/C++ | M29: N | N29: 8.7316667 | O29: 0.11041667 | P29: 0 | Q29: 8.8420833 | R29: 0.91687479 | S29: 4.4210417 | T29: 4.4210417 | U29: 1 | AA29: =N29 -> 8.7316667 | AB29: =O29 -> 0.11041667 | AC29: =P29 -> 0 | AD29: =Q29 -> 8.8420833 | AE29: =R29 -> 0.91687479 | AF29: =Q29*R29 -> 8.1070833 | AG29: B | AH29: VS2
A30: 26 | B30: 9834 | C30: C03WRE-JPN | D30: POS Workflow Payment Workflow (Restoring cancelled | E30: storage and preservation related | F30: Customer Service and Operations Systems Group 34965 | G30: Policy Servicing Team 34967 | H30: Core Business Application | I30: Y | J30: Yes | K30: VB.NET | M30: N | N30: 0.2 | O30: 0.2 | P30: 0 | Q30: 0.37083333 | R30: 0.3258427 | S30: 0.18541667 | T30: 0.18541667 | U30: 1 | AA30: =N30 -> 0.2 | AB30: =O30 -> 0.2 | AC30: =P30 -> 0 | AD30: =Q30 -> 0.37083333 | AE30: =R30 -> 0.3258427 | AF30: =Q30*R30 -> 0.12083333 | AG30: B | AH30: VS1
A31: 27 | B31: 9835 | C31: C12WNC-JPN | D31: POS Workflow Payment Workflow (Claim Transaction A | E31: insurance claims and benefits payment related | F31: Customer Service and Operations Systems Group 34965 | G31: Claims Team 34968 | H31: Core Business Application | I31: Y | J31: Yes | K31: VB.NET; C/C++; JAVA | M31: N | N31: 29.379875 | O31: 5.6166667 | P31: 0 | Q31: 34.996542 | R31: 0.90522873 | S31: 17.498271 | T31: 17.498271 | U31: 1 | AA31: =N31 -> 29.379875 | AB31: =O31 -> 5.6166667 | AC31: =P31 -> 0 | AD31: =Q31 -> 34.996542 | AE31: =R31 -> 0.90522873 | AF31: =Q31*R31 -> 31.679875 | AG31: B | AH31: VS1
A32: 28 | B32: 9836 | C32: C03WRD-JPN | D32: POS Workflow Payment Workflow (Reduction of paymen | E32: storage and preservation related | F32: Customer Service and Operations Systems Group 34965 | G32: Policy Servicing Team 34967 | H32: Core Business Application | I32: Y | J32: Yes | K32: VB.NET | M32: N | N32: 0.3 | O32: 0.3 | P32: 0 | Q32: 2.5258333 | R32: 0.90102276 | S32: 1.2629167 | T32: 1.2629167 | U32: 1 | AA32: =N32 -> 0.3 | AB32: =O32 -> 0.3 | AC32: =P32 -> 0 | AD32: =Q32 -> 2.5258333 | AE32: =R32 -> 0.90102276 | AF32: =Q32*R32 -> 2.2758333 | AG32: B | AH32: VS1
A33: 29 | B33: 9842 | C33: C03PCA-JPN | D33: Add Coverage | E33: storage and preservation related | F33: Customer Service and Operations Systems Group 34965 | G33: Policy Servicing Team 34967 | H33: Core Business Application | I33: N | J33: Yes | K33: VB | M33: N | N33: 0.3 | O33: 0.3 | P33: 0 | Q33: 2.88625 | R33: 0.90298831 | S33: 1.443125 | T33: 1.443125 | U33: 1 | AA33: =N33 -> 0.3 | AB33: =O33 -> 0.3 | AC33: =P33 -> 0 | AD33: =Q33 -> 2.88625 | AE33: =R33 -> 0.90298831 | AF33: =Q33*R33 -> 2.60625 | AG33: B | AH33: VS2
A34: 30 | B34: 9843 | C34: C10CSS-JPN | D34: FSC Call Support | E34: customer care / call center related | F34: Customer Service and Operations Systems Group 34965 | G34: Customer Care Team 34969 | H34: Core Business Application | I34: N | J34: Yes | K34: VB.NET | M34: N | N34: 1.2120833 | O34: 0.20833333 | P34: 0 | Q34: 1.4204167 | R34: 0.63596363 | S34: 0.71020833 | T34: 0.71020833 | U34: 1 | AA34: =N34 -> 1.2120833 | AB34: =O34 -> 0.20833333 | AC34: =P34 -> 0 | AD34: =Q34 -> 1.4204167 | AE34: =R34 -> 0.63596363 | AF34: =Q34*R34 -> 0.90333333 | AG34: B | AH34: VS2
A35: 31 | B35: 9844 | C35: C04VAS-JPN | D35: Voucher Approval System for AS400 | E35: corporate related | F35: Core Insurance Systems Group 34956 | G35: Corporate Systems Team 34959 | H35: Core Business Application | I35: Y | J35: Yes | K35: VB.NET | M35: N | N35: 0.67083333 | O35: 0.68333333 | P35: 0 | Q35: 1.3541667 | R35: 0.36923077 | S35: 0.67708333 | T35: 0.67708333 | U35: 1 | AA35: =N35 -> 0.67083333 | AB35: =O35 -> 0.68333333 | AC35: =P35 -> 0 | AD35: =Q35 -> 1.3541667 | AE35: =R35 -> 0.36923077 | AF35: =Q35*R35 -> 0.5 | AG35: B | AH35: VS6
A36: 32 | B36: 9845 | C36: C04SYM-JPN | D36: Renewal symap Business Work Flow | E36: new contract related | F36: Customer Service and Operations Systems Group 34965 | G36: New Business Team 34966 | H36: Core Business Application | I36: N | J36: Yes | K36: VB.NET | M36: N | N36: 3.4049167 | O36: 0 | P36: 0 | Q36: 3.4049167 | R36: 0.84091632 | S36: 1.7024583 | T36: 1.7024583 | U36: 1 | AA36: =N36 -> 3.4049167 | AB36: =O36 -> 0 | AC36: =P36 -> 0 | AD36: =Q36 -> 3.4049167 | AE36: =R36 -> 0.84091632 | AF36: =Q36*R36 -> 2.86325 | AG36: B | AH36: VS4
... A40: 36 | B40: 9849 | C40: C04OSI-JPN | D40: S Sum Total System(Open) | E40: new contract related | F40: Customer Service and Operations Systems Group 34965 | G40: New Business Team 34966 | H40: Common Service Business Application | I40: N | J40: Yes | K40: JAVA | M40: N | N40: 5.18625 | O40: 0.38333333 | P40: 0 | Q40: 5.5695833 | R40: 0.8315254 | S40: 2.7847917 | T40: 2.7847917 | U40: 1 | AA40: =N40 -> 5.18625 | AB40: =O40 -> 0.38333333 | AC40: =P40 -> 0 | AD40: =Q40 -> 5.5695833 | AE40: =R40 -> 0.8315254 | AF40: =Q40*R40 -> 4.63125 | AG40: B | AH40: VS1
A41: 37 | B41: 9851 | C41: W03FIC-JPN | D41: Guidance Refusal Information Administration System | E41: corporate related | F41: Core Insurance Systems Group 34956 | G41: Corporate Systems Team 34959 | H41: Core Business Application | I41: N | J41: Yes | K41: JAVA | L41: Platform as a Service (PaaS) | M41: N | N41: 0.29166667 | O41: 0.11666667 | P41: 0 | Q41: 0.40833333 | R41: 0.82653061 | S41: 0.20416667 | T41: 0.20416667 | U41: 1 | AA41: =N41 -> 0.29166667 | AB41: =O41 -> 0.11666667 | AC41: =P41 -> 0 | AD41: =Q41 -> 0.40833333 | AE41: =R41 -> 0.82653061 | AF41: =Q41*R41 -> 0.3375 | AG41: B | AH41: VS3
A42: 38 | B42: 9852 | C42: C03APO-JPN | D42: Apollocs | E42: corporate related | F42: Core Insurance Systems Group 34956 | G42: Corporate Systems Team 34959 | H42: Core Business Application | I42: N | J42: Yes | K42: Other#APOLLOCS | M42: N | N42: 0.50833333 | O42: 0 | P42: 0 | Q42: 0.50833333 | R42: 0.36885246 | S42: 0.25416667 | T42: 0.25416667 | U42: 1 | AA42: =N42 -> 0.50833333 | AB42: =O42 -> 0 | AC42: =P42 -> 0 | AD42: =Q42 -> 0.50833333 | AE42: =R42 -> 0.36885246 | AF42: =Q42*R42 -> 0.1875 | AG42: B | AH42: VS5
A43: 39 | B43: 9854 | C43: Z04IMA-JPN | D43: Image Search | E43: new contract related | F43: Customer Service and Operations Systems Group 34965 | G43: New Business Team 34966 | H43: Core Business Application | I43: N | J43: Yes | K43: CSS; JAVA;HTML; VB.NET | M43: N | N43: 1.4004167 | O43: 0 | P43: 0 | Q43: 1.4004167 | R43: 0.92859268 | S43: 0.70020833 | T43: 0.70020833 | U43: 1 | AA43: =N43 -> 1.4004167 | AB43: =O43 -> 0 | AC43: =P43 -> 0 | AD43: =Q43 -> 1.4004167 | AE43: =R43 -> 0.92859268 | AF43: =Q43*R43 -> 1.3004167 | AG43: B | AH43: VS4
A44: 40 | B44: 9857 | C44: W05AMS-JPN | D44: Annuity Information Management System(AIMS) | E44: insurance claims and benefits payment related | F44: Customer Service and Operations Systems Group 34965 | G44: Claims Team 34968 | H44: Core Business Application | I44: Y | J44: Yes | K44: JAVA | M44: N | N44: 20.211667 | O44: 1.8166667 | P44: 0 | Q44: 22.028333 | R44: 0.92547477 | S44: 11.014167 | T44: 11.014167 | U44: 1 | AA44: =N44 -> 20.211667 | AB44: =O44 -> 1.8166667 | AC44: =P44 -> 0 | AD44: =Q44 -> 22.028333 | AE44: =R44 -> 0.92547477 | AF44: =Q44*R44 -> 20.386667 | AG44: B | AH44: VS2
...

Sheet Value Streams
A1: Fee management — three functional value streams
A2: Reconciles to the fee management domain's 5 applications and 48.5 effort units. Every application sits in one and only one stream. Two apps (Global Sales Comp - Japan, Commission Calculation Service) carry zero current effort and reconcile here but add no pod headcount.
B4: Code | C4: Value stream | D4: Apps | E4: Effort | F4: AD effort | G4: AMS effort | H4: AD share | I4: Y1 co-src pods | J4: Y1 full-src pods | K4: Y1 people
B5: VS1 | C5: Incentive Compensation Calculation | D5: =SUMIFS(Inventory!$U:$U,Inventory!$E:$E,"fee management",Inventory!$AH:$AH,$B5) -> 2 | E5: =SUMIFS(Inventory!$AD:$AD,Inventory!$E:$E,"fee management",Inventory!$AH:$AH,$B5) -> 29.235292 | F5: =SUMIFS(Inventory!$AF:$AF,Inventory!$E:$E,"fee management",Inventory!$AH:$AH,$B5) -> 24.293625 | G5: =E5-F5 -> 4.9416667 | H5: =IF(E5=0,0,F5/E5) -> 0.83096913 | I5: =SUMIFS('Pod Plan'!$E:$E,'Pod Plan'!$B:$B,1,'Pod Plan'!$C:$C,$B5) -> 3 | J5: =SUMIFS('Pod Plan'!$F:$F,'Pod Plan'!$B:$B,1,'Pod Plan'!$C:$C,$B5) -> 2 | K5: ='Pod Plan'!H5 -> 26
B6: VS2 | C6: Compensation Administration & Reporting | D6: =SUMIFS(Inventory!$U:$U,Inventory!$E:$E,"fee management",Inventory!$AH:$AH,$B6) -> 1 | E6: =SUMIFS(Inventory!$AD:$AD,Inventory!$E:$E,"fee management",Inventory!$AH:$AH,$B6) -> 16.316667 | F6: =SUMIFS(Inventory!$AF:$AF,Inventory!$E:$E,"fee management",Inventory!$AH:$AH,$B6) -> 16.116667 | G6: =E6-F6 -> 0.2 | H6: =IF(E6=0,0,F6/E6) -> 0.98774259 | I6: =SUMIFS('Pod Plan'!$E:$E,'Pod Plan'!$B:$B,1,'Pod Plan'!$C:$C,$B6) -> 2 | J6: =SUMIFS('Pod Plan'!$F:$F,'Pod Plan'!$B:$B,1,'Pod Plan'!$C:$C,$B6) -> 1 | K6: ='Pod Plan'!H6 -> 16
B7: VS3 | C7: Distributor Portal & Commission Services | D7: =SUMIFS(Inventory!$U:$U,Inventory!$E:$E,"fee management",Inventory!$AH:$AH,$B7) -> 2 | E7: =SUMIFS(Inventory!$AD:$AD,Inventory!$E:$E,"fee management",Inventory!$AH:$AH,$B7) -> 2.9583333 | F7: =SUMIFS(Inventory!$AF:$AF,Inventory!$E:$E,"fee management",Inventory!$AH:$AH,$B7) -> 2.7083333 | G7: =E7-F7 -> 0.25 | H7: =IF(E7=0,0,F7/E7) -> 0.91549296 | I7: =SUMIFS('Pod Plan'!$E:$E,'Pod Plan'!$B:$B,1,'Pod Plan'!$C:$C,$B7) -> 0 | J7: =SUMIFS('Pod Plan'!$F:$F,'Pod Plan'!$B:$B,1,'Pod Plan'!$C:$C,$B7) -> 1 | K7: ='Pod Plan'!H7 -> 3
C8: Total | D8: =SUM(D5:D7) -> 5 | E8: =SUM(E5:E7) -> 48.510292 | F8: =SUM(F5:F7) -> 43.118625 | G8: =SUM(G5:G7) -> 5.3916667 | H8: =IF(E8=0,0,F8/E8) -> 0.8888552 | I8: =SUM(I5:I7) -> 5 | J8: =SUM(J5:J7) -> 4 | K8: =SUM(K5:K7) -> 45
C13: Application-to-value-stream mapping
B14: Value stream | C14: Applications
B15: VS1 | C15: ITS-PCIS (Mutual Fund System, incl. Bestway) · FATCA Oracle EDQ · BSRec · Variable Insurance Guarantee Calculation System (Vcalc)
B16: VS2 | C16: Report Template Management System · eSTATION · Japan Payroll System · Business Content Management · kintone and paperlogic electronic contract system · Commission System Support Tool
B17: VS3 | C17: Guidance Refusal Information Administration System · Watch List Filtering system · Misconduct Management system
B18: VS4 | C18: Conservation Contact Personnel Entry System · Commission Inquiry · Career Information System · Producers Information Entry System · Web Work Flow · Call Control System · New Submit Online System · Group Policy Inquiry System for Intranet · Commission and Performance System · Conservation Contract Transferring System
B19: VS5 | C19: Apollocs · .NET Common Infrastructure · Dr.SUM · ProductXpress · ASP Bridge (Open) · OpenBatch System for Corporate · Retirement Allowance Payment System
B20: VS6 | C20: Voucher Approval System for AS400 · AS400 Mass Marketing System · Group Policy Management System

Sheet Pod Library
A1: Pod library — every seat, by year, value stream and pod type
A2: INPUT. One shared seat template per value stream per pod type per year; Pod Plan's co-sourced/fully-sourced pod counts multiply it out. VS1 and VS2 use the standard modern-stack CO/FS templates, sized to their real effort share. VS3's real footprint is tiny (2.96 effort units, one live app) so it gets a single lean fully-sourced pod instead — no co-sourced pod, no dedicated product-owner seats. The one MGCC seat sits in VS3, reflecting External Portal's real current MGCC use; VS1/VS2 stay FTC/FTE only, matching this domain's near-zero real MGCC baseline.
B4: Year | C4: VS | D4: Pod type | E4: Role | F4: Skill | G4: Exp | H4: Location | I4: Sourcing | J4: Count
B5: 1 | C5: VS1 | D5: CO | E5: Product Owner | F5: LEAD | G5: E4 | H5: ON | I5: FTE | J5: 1
B6: 1 | C6: VS1 | D6: CO | E6: Incentive Compensation SME | F6: BA | G6: E4 | H6: ON | I6: FTE | J6: 1
B7: 1 | C7: VS1 | D7: CO | E7: Application Owner (Technical) | F7: ENG | G7: E4 | H7: ON | I7: FTE | J7: 1
B8: 1 | C8: VS1 | D8: CO | E8: Pod Delivery Lead | F8: LEAD | G8: E4 | H8: ON | I8: FTC | J8: 1
B9: 1 | C9: VS1 | D9: CO | E9: Senior Developer | F9: DEV | G9: E3 | H9: OFF | I9: FTC | J9: 1
B10: 1 | C10: VS1 | D10: CO | E10: QA / Test Engineer | F10: TEST | G10: E2 | H10: OFF | I10: FTC | J10: 1
E11: Pod size — Year 1 VS1 co-sourced | J11: =SUM(J5:J10) -> 6
B12: 1 | C12: VS1 | D12: FS | E12: Pod Lead (output owner) | F12: LEAD | G12: E4 | H12: ON | I12: FTC | J12: 1
B13: 1 | C13: VS1 | D13: FS | E13: Developer | F13: DEV | G13: E3 | H13: OFF | I13: FTC | J13: 1
B14: 1 | C14: VS1 | D14: FS | E14: Developer | F14: DEV | G14: E2 | H14: OFF | I14: FTC | J14: 1
B15: 1 | C15: VS1 | D15: FS | E15: QA Engineer | F15: TEST | G15: E2 | H15: OFF | I15: FTC | J15: 1
E16: Pod size — Year 1 VS1 fully-sourced | J16: =SUM(J12:J15) -> 4
B18: 1 | C18: VS2 | D18: CO | E18: Product Owner | F18: LEAD | G18: E4 | H18: ON | I18: FTE | J18: 1
B19: 1 | C19: VS2 | D19: CO | E19: Compensation Administration SME | F19: BA | G19: E4 | H19: ON | I19: FTE | J19: 1
B20: 1 | C20: VS2 | D20: CO | E20: Application Owner (Technical) | F20: ENG | G20: E4 | H20: ON | I20: FTE | J20: 1
B21: 1 | C21: VS2 | D21: CO | E21: Pod Delivery Lead | F21: LEAD | G21: E4 | H21: ON | I21: FTC | J21: 1
B22: 1 | C22: VS2 | D22: CO | E22: Senior Developer | F22: DEV | G22: E3 | H22: OFF | I22: FTC | J22: 1
B23: 1 | C23: VS2 | D23: CO | E23: QA / Test Engineer | F23: TEST | G23: E2 | H23: OFF | I23: FTC | J23: 1
E24: Pod size — Year 1 VS2 co-sourced | J24: =SUM(J18:J23) -> 6
B25: 1 | C25: VS2 | D25: FS | E25: Pod Lead (output owner) | F25: LEAD | G25: E4 | H25: ON | I25: FTC | J25: 1
B26: 1 | C26: VS2 | D26: FS | E26: Developer | F26: DEV | G26: E3 | H26: OFF | I26: FTC | J26: 1
B27: 1 | C27: VS2 | D27: FS | E27: Developer | F27: DEV | G27: E2 | H27: OFF | I27: FTC | J27: 1
B28: 1 | C28: VS2 | D28: FS | E28: QA Engineer | F28: TEST | G28: E2 | H28: OFF | I28: FTC | J28: 1
E29: Pod size — Year 1 VS2 fully-sourced | J29: =SUM(J25:J28) -> 4
B31: 1 | C31: VS3 | D31: FS | E31: Pod Lead (output owner) | F31: LEAD | G31: E4 | H31: ON | I31: FTC | J31: 1
B32: 1 | C32: VS3 | D32: FS | E32: Developer — MGCC Hyderabad | F32: DEV | G32: E3 | H32: OFF | I32: MGCC | J32: 1
B33: 1 | C33: VS3 | D33: FS | E33: QA Engineer | F33: TEST | G33: E2 | H33: OFF | I33: FTC | J33: 1
E34: Pod size — Year 1 VS3 fully-sourced | J34: =SUM(J31:J33) -> 3
B36: 2 | C36: VS1 | D36: CO | E36: Product Owner | F36: LEAD | G36: E4 | H36: ON | I36: FTE | J36: 1
B37: 2 | C37: VS1 | D37: CO | E37: Incentive Compensation SME | F37: BA | G37: E4 | H37: ON | I37: FTE | J37: 1
B38: 2 | C38: VS1 | D38: CO | E38: Application Owner (Technical) | F38: ENG | G38: E4 | H38: ON | I38: FTE | J38: 1
B39: 2 | C39: VS1 | D39: CO | E39: AI-assisted Developer | F39: DEV | G39: E3 | H39: OFF | I39: FTC | J39: 1
B40: 2 | C40: VS1 | D40: CO | E40: Quality Engineer (SDET) | F40: TEST | G40: E3 | H40: OFF | I40: FTC | J40: 1
E41: Pod size — Year 2 VS1 co-sourced | J41: =SUM(J36:J40) -> 5
B42: 2 | C42: VS1 | D42: FS | E42: Pod Lead / AI Orchestrator | F42: LEAD | G42: E4 | H42: OFF | I42: FTC | J42: 1
B43: 2 | C43: VS1 | D43: FS | E43: AI-assisted Developer | F43: DEV | G43: E3 | H43: OFF | I43: FTC | J43: 1
B44: 2 | C44: VS1 | D44: FS | E44: QA Engineer | F44: TEST | G44: E2 | H44: OFF | I44: FTC | J44: 1
...

Sheet Pod Plan
A1: Pod plan — how many pods each value stream runs, each year
A2: INPUT SHEET. Fewer pods and smaller pods is how productivity shows up in the headcount. Nothing else reduces it.
B4: Year | C4: VS | D4: Value stream | E4: Co-sourced pods | F4: Fully-sourced pods | G4: Pods | H4: People
B5: 1 | C5: VS1 | D5: Incentive Compensation Calculation | E5: 3 | F5: 2 | G5: =E5+F5 -> 5 | H5: =E5*SUMIFS('Pod Library'!$J:$J,'Pod Library'!$B:$B,$B5,'Pod Library'!$C:$C,$C5,'Pod Library'!$D:$D,"CO")+F5*SUMIFS('Pod Library'!$J:$J,'Pod Library'!$B:$B,$B5,'Pod Library'!$C:$C,$C5,'Pod Library'!$D:$D,"FS") -> 26
B6: 1 | C6: VS2 | D6: Compensation Administration & Reporting | E6: 2 | F6: 1 | G6: =E6+F6 -> 3 | H6: =E6*SUMIFS('Pod Library'!$J:$J,'Pod Library'!$B:$B,$B6,'Pod Library'!$C:$C,$C6,'Pod Library'!$D:$D,"CO")+F6*SUMIFS('Pod Library'!$J:$J,'Pod Library'!$B:$B,$B6,'Pod Library'!$C:$C,$C6,'Pod Library'!$D:$D,"FS") -> 16
B7: 1 | C7: VS3 | D7: Distributor Portal & Commission Services | E7: 0 | F7: 1 | G7: =E7+F7 -> 1 | H7: =E7*SUMIFS('Pod Library'!$J:$J,'Pod Library'!$B:$B,$B7,'Pod Library'!$C:$C,$C7,'Pod Library'!$D:$D,"CO")+F7*SUMIFS('Pod Library'!$J:$J,'Pod Library'!$B:$B,$B7,'Pod Library'!$C:$C,$C7,'Pod Library'!$D:$D,"FS") -> 3
D8: Year 1 total | E8: =SUM(E5:E7) -> 5 | F8: =SUM(F5:F7) -> 4 | G8: =SUM(G5:G7) -> 9 | H8: =SUM(H5:H7) -> 45
B10: 2 | C10: VS1 | D10: Incentive Compensation Calculation | E10: 3 | F10: 2 | G10: =E10+F10 -> 5 | H10: =E10*SUMIFS('Pod Library'!$J:$J,'Pod Library'!$B:$B,$B10,'Pod Library'!$C:$C,$C10,'Pod Library'!$D:$D,"CO")+F10*SUMIFS('Pod Library'!$J:$J,'Pod Library'!$B:$B,$B10,'Pod Library'!$C:$C,$C10,'Pod Library'!$D:$D,"FS") -> 21
B11: 2 | C11: VS2 | D11: Compensation Administration & Reporting | E11: 2 | F11: 1 | G11: =E11+F11 -> 3 | H11: =E11*SUMIFS('Pod Library'!$J:$J,'Pod Library'!$B:$B,$B11,'Pod Library'!$C:$C,$C11,'Pod Library'!$D:$D,"CO")+F11*SUMIFS('Pod Library'!$J:$J,'Pod Library'!$B:$B,$B11,'Pod Library'!$C:$C,$C11,'Pod Library'!$D:$D,"FS") -> 13
B12: 2 | C12: VS3 | D12: Distributor Portal & Commission Services | E12: 0 | F12: 1 | G12: =E12+F12 -> 1 | H12: =E12*SUMIFS('Pod Library'!$J:$J,'Pod Library'!$B:$B,$B12,'Pod Library'!$C:$C,$C12,'Pod Library'!$D:$D,"CO")+F12*SUMIFS('Pod Library'!$J:$J,'Pod Library'!$B:$B,$B12,'Pod Library'!$C:$C,$C12,'Pod Library'!$D:$D,"FS") -> 2
D13: Year 2 total | E13: =SUM(E10:E12) -> 5 | F13: =SUM(F10:F12) -> 4 | G13: =SUM(G10:G12) -> 9 | H13: =SUM(H10:H12) -> 36
B15: 3 | C15: VS1 | D15: Incentive Compensation Calculation | E15: 3 | F15: 2 | G15: =E15+F15 -> 5 | H15: =E15*SUMIFS('Pod Library'!$J:$J,'Pod Library'!$B:$B,$B15,'Pod Library'!$C:$C,$C15,'Pod Library'!$D:$D,"CO")+F15*SUMIFS('Pod Library'!$J:$J,'Pod Library'!$B:$B,$B15,'Pod Library'!$C:$C,$C15,'Pod Library'!$D:$D,"FS") -> 16
B16: 3 | C16: VS2 | D16: Compensation Administration & Reporting | E16: 2 | F16: 1 | G16: =E16+F16 -> 3 | H16: =E16*SUMIFS('Pod Library'!$J:$J,'Pod Library'!$B:$B,$B16,'Pod Library'!$C:$C,$C16,'Pod Library'!$D:$D,"CO")+F16*SUMIFS('Pod Library'!$J:$J,'Pod Library'!$B:$B,$B16,'Pod Library'!$C:$C,$C16,'Pod Library'!$D:$D,"FS") -> 10
B17: 3 | C17: VS3 | D17: Distributor Portal & Commission Services | E17: 0 | F17: 1 | G17: =E17+F17 -> 1 | H17: =E17*SUMIFS('Pod Library'!$J:$J,'Pod Library'!$B:$B,$B17,'Pod Library'!$C:$C,$C17,'Pod Library'!$D:$D,"CO")+F17*SUMIFS('Pod Library'!$J:$J,'Pod Library'!$B:$B,$B17,'Pod Library'!$C:$C,$C17,'Pod Library'!$D:$D,"FS") -> 1
D18: Year 3 total | E18: =SUM(E15:E17) -> 5 | F18: =SUM(F15:F17) -> 4 | G18: =SUM(G15:G17) -> 9 | H18: =SUM(H15:H17) -> 27

Sheet Horizontal Teams
A1: Horizontal teams — work that is not value-stream bounded
A2: INPUT. Real cross-stream functions for a fee/compensation domain: compensation plan administration & governance, calculation QA & audit, regulatory/compliance support for fee and commission rules, and a small architecture & governance core. Kept lean given this domain's small overall scale.
B5: 1 | C5: H1 | D5: Compensation Plan Administration & Governance | E5: Compensation Plan Administration Lead | F5: LEAD | G5: E4 | H5: ON | I5: FTC | J5: 1
E6: H1 total | J6: =SUM(J5:J5) -> 1
B7: 1 | C7: H2 | D7: Calculation QA & Audit | E7: Calculation QA & Audit Analyst | F7: TEST | G7: E3 | H7: OFF | I7: FTC | J7: 1
E8: H2 total | J8: =SUM(J7:J7) -> 1
B9: 1 | C9: H3 | D9: Regulatory / Compliance Support | E9: Compliance & Regulatory Analyst (Fee & Commission Rules) | F9: BA | G9: E3 | H9: ON | I9: FTC | J9: 1
E10: H3 total | J10: =SUM(J9:J9) -> 1
B11: 1 | C11: H4 | D11: Architecture & Governance | E11: Domain Delivery Head | F11: LEAD | G11: E5 | H11: ON | I11: FTC | J11: 1
B12: 1 | C12: H4 | D12: Architecture & Governance | E12: Chief Fee Systems Architect (MetLife) | F12: ENG | G12: E5 | H12: ON | I12: FTE | J12: 1
E13: H4 total | J13: =SUM(J11:J12) -> 2
E14: Year 1 horizontal total | J14: =SUMIFS($J$5:$J$13,$B$5:$B$13,1) -> 5
B16: 2 | C16: H1 | D16: Compensation Plan Administration & Governance | E16: Compensation Plan Administration Lead | F16: LEAD | G16: E4 | H16: ON | I16: FTC | J16: 1
E17: H1 total | J17: =SUM(J16:J16) -> 1
B18: 2 | C18: H2 | D18: Calculation QA & Audit | E18: Calculation QA & Audit Analyst | F18: TEST | G18: E3 | H18: OFF | I18: FTC | J18: 1
E19: H2 total | J19: =SUM(J18:J18) -> 1
B20: 2 | C20: H4 | D20: Architecture & Governance | E20: Domain Delivery Head | F20: LEAD | G20: E5 | H20: ON | I20: FTC | J20: 1
B21: 2 | C21: H4 | D21: Architecture & Governance | E21: Chief Fee Systems Architect (MetLife) | F21: ENG | G21: E5 | H21: ON | I21: FTE | J21: 1
E22: H4 total | J22: =SUM(J20:J21) -> 2
E23: Year 2 horizontal total | J23: =SUMIFS($J$16:$J$22,$B$16:$B$22,2) -> 4
B25: 3 | C25: H1 | D25: Compensation Plan Administration & Governance | E25: Compensation Plan Administration Lead | F25: LEAD | G25: E4 | H25: OFF | I25: FTC | J25: 1
E26: H1 total | J26: =SUM(J25:J25) -> 1
B27: 3 | C27: H4 | D27: Architecture & Governance | E27: Domain Delivery Head | F27: LEAD | G27: E5 | H27: OFF | I27: FTC | J27: 1
B28: 3 | C28: H4 | D28: Architecture & Governance | E28: Chief Fee Systems Architect (MetLife) | F28: ENG | G28: E5 | H28: ON | I28: FTE | J28: 1
E29: H4 total | J29: =SUM(J27:J28) -> 2
E30: Year 3 horizontal total | J30: =SUMIFS($J$25:$J$29,$B$25:$B$29,3) -> 3

Sheet Team Build-Up
A1: Team build-up — headcount, sourcing, location, experience and skill, all derived from the seat ledger
A2: Nothing on this sheet is typed. Change a seat on Pod Library or a pod count on Pod Plan and every figure here moves.
A4: A. POD SIZES (read from the Pod Library)
B5: Pod size (avg per VS running that pod type — CO: 2, FS: 3) | C5: Y1 co-src | D5: Y1 full-src | E5: Y2 co-src | F5: Y2 full-src | G5: Y3 co-src | H5: Y3 full-src
B6: Seats per pod | C6: =SUMIFS('Pod Library'!$J:$J,'Pod Library'!$B:$B,1,'Pod Library'!$D:$D,"CO")/2 -> 6 | D6: =SUMIFS('Pod Library'!$J:$J,'Pod Library'!$B:$B,1,'Pod Library'!$D:$D,"FS")/3 -> 3.6666667 | E6: =SUMIFS('Pod Library'!$J:$J,'Pod Library'!$B:$B,2,'Pod Library'!$D:$D,"CO")/2 -> 5 | F6: =SUMIFS('Pod Library'!$J:$J,'Pod Library'!$B:$B,2,'Pod Library'!$D:$D,"FS")/3 -> 2.6666667 | G6: =SUMIFS('Pod Library'!$J:$J,'Pod Library'!$B:$B,3,'Pod Library'!$D:$D,"CO")/2 -> 4 | H6: =SUMIFS('Pod Library'!$J:$J,'Pod Library'!$B:$B,3,'Pod Library'!$D:$D,"FS")/3 -> 1.6666667
A8: B. HEADCOUNT
B9: Measure | C9: Year 1 | D9: Year 2 | E9: Year 3
B10: People in value-stream pods | C10: =SUMIFS('Seat Ledger'!$L$5:$L$70,'Seat Ledger'!$A$5:$A$70,1,'Seat Ledger'!$B$5:$B$70,"POD") -> 45 | D10: =SUMIFS('Seat Ledger'!$L$5:$L$70,'Seat Ledger'!$A$5:$A$70,2,'Seat Ledger'!$B$5:$B$70,"POD") -> 36 | E10: =SUMIFS('Seat Ledger'!$L$5:$L$70,'Seat Ledger'!$A$5:$A$70,3,'Seat Ledger'!$B$5:$B$70,"POD") -> 27
B11: People in horizontal teams | C11: =SUMIFS('Seat Ledger'!$L$5:$L$70,'Seat Ledger'!$A$5:$A$70,1,'Seat Ledger'!$B$5:$B$70,"HZ") -> 5 | D11: =SUMIFS('Seat Ledger'!$L$5:$L$70,'Seat Ledger'!$A$5:$A$70,2,'Seat Ledger'!$B$5:$B$70,"HZ") -> 4 | E11: =SUMIFS('Seat Ledger'!$L$5:$L$70,'Seat Ledger'!$A$5:$A$70,3,'Seat Ledger'!$B$5:$B$70,"HZ") -> 3
B12: TOTAL PEOPLE | C12: =C10+C11 -> 50 | D12: =D10+D11 -> 40 | E12: =E10+E11 -> 30
B13: Number of pods | C13: =SUMIFS('Pod Plan'!$G:$G,'Pod Plan'!$B:$B,1) -> 9 | D13: =SUMIFS('Pod Plan'!$G:$G,'Pod Plan'!$B:$B,2) -> 9 | E13: =SUMIFS('Pod Plan'!$G:$G,'Pod Plan'!$B:$B,3) -> 9
B14: Average pod size | C14: =IF(C13=0,0,C10/C13) -> 5 | D14: =IF(D13=0,0,D10/D13) -> 4 | E14: =IF(E13=0,0,E10/E13) -> 3
A16: C. SOURCING — before any transfer of employment
B17: Measure | C17: Year 1 | D17: Year 2 | E17: Year 3
B18: Capgemini (FTC) | C18: =SUMIFS('Seat Ledger'!$L$5:$L$70,'Seat Ledger'!$A$5:$A$70,1,'Seat Ledger'!$I$5:$I$70,"FTC") -> 33 | D18: =SUMIFS('Seat Ledger'!$L$5:$L$70,'Seat Ledger'!$A$5:$A$70,2,'Seat Ledger'!$I$5:$I$70,"FTC") -> 23 | E18: =SUMIFS('Seat Ledger'!$L$5:$L$70,'Seat Ledger'!$A$5:$A$70,3,'Seat Ledger'!$I$5:$I$70,"FTC") -> 13
B19: MetLife Japan (FTE) | C19: =SUMIFS('Seat Ledger'!$L$5:$L$70,'Seat Ledger'!$A$5:$A$70,1,'Seat Ledger'!$I$5:$I$70,"FTE") -> 16 | D19: =SUMIFS('Seat Ledger'!$L$5:$L$70,'Seat Ledger'!$A$5:$A$70,2,'Seat Ledger'!$I$5:$I$70,"FTE") -> 16 | E19: =SUMIFS('Seat Ledger'!$L$5:$L$70,'Seat Ledger'!$A$5:$A$70,3,'Seat Ledger'!$I$5:$I$70,"FTE") -> 16
B20: MetLife MGCC (Hyderabad) | C20: =SUMIFS('Seat Ledger'!$L$5:$L$70,'Seat Ledger'!$A$5:$A$70,1,'Seat Ledger'!$I$5:$I$70,"MGCC") -> 1 | D20: =SUMIFS('Seat Ledger'!$L$5:$L$70,'Seat Ledger'!$A$5:$A$70,2,'Seat Ledger'!$I$5:$I$70,"MGCC") -> 1 | E20: =SUMIFS('Seat Ledger'!$L$5:$L$70,'Seat Ledger'!$A$5:$A$70,3,'Seat Ledger'!$I$5:$I$70,"MGCC") -> 1
B21: Check — sums to total | C21: =C18+C19+C20-C12 -> 0 | D21: =D18+D19+D20-D12 -> 0 | E21: =E18+E19+E20-E12 -> 0
A23: D. LOCATION
B24: Measure | C24: Year 1 | D24: Year 2 | E24: Year 3
B25: Onshore Tokyo | C25: =SUMIFS('Seat Ledger'!$L$5:$L$70,'Seat Ledger'!$A$5:$A$70,1,'Seat Ledger'!$H$5:$H$70,"ON") -> 28 | D25: =SUMIFS('Seat Ledger'!$L$5:$L$70,'Seat Ledger'!$A$5:$A$70,2,'Seat Ledger'!$H$5:$H$70,"ON") -> 18 | E25: =SUMIFS('Seat Ledger'!$L$5:$L$70,'Seat Ledger'!$A$5:$A$70,3,'Seat Ledger'!$H$5:$H$70,"ON") -> 16
B26: Offshore Hyderabad | C26: =SUMIFS('Seat Ledger'!$L$5:$L$70,'Seat Ledger'!$A$5:$A$70,1,'Seat Ledger'!$H$5:$H$70,"OFF") -> 22 | D26: =SUMIFS('Seat Ledger'!$L$5:$L$70,'Seat Ledger'!$A$5:$A$70,2,'Seat Ledger'!$H$5:$H$70,"OFF") -> 22 | E26: =SUMIFS('Seat Ledger'!$L$5:$L$70,'Seat Ledger'!$A$5:$A$70,3,'Seat Ledger'!$H$5:$H$70,"OFF") -> 14
B27: Offshore share (delivered, bottom-up) | C27: =IF(C12=0,0,C26/C12) -> 0.44 | D27: =IF(D12=0,0,D26/D12) -> 0.55 | E27: =IF(E12=0,0,E26/E12) -> 0.46666667
A29: E. EXPERIENCE MIX — built grounds-up from named seats, not applied as a percentage
B30: Experience band | C30: Year 1 | D30: Year 2 | E30: Year 3 | G30: Y1 % | H30: Y2 % | I30: Y3 %
B31: E1 Associate 0-3 years | C31: =SUMIFS('Seat Ledger'!$L$5:$L$70,'Seat Ledger'!$A$5:$A$70,1,'Seat Ledger'!$G$5:$G$70,"E1") -> 0 | D31: =SUMIFS('Seat Ledger'!$L$5:$L$70,'Seat Ledger'!$A$5:$A$70,2,'Seat Ledger'!$G$5:$G$70,"E1") -> 0 | E31: =SUMIFS('Seat Ledger'!$L$5:$L$70,'Seat Ledger'!$A$5:$A$70,3,'Seat Ledger'!$G$5:$G$70,"E1") -> 0 | G31: =IF(C$12=0,0,C31/C$12) -> 0 | H31: =IF(D$12=0,0,D31/D$12) -> 0 | I31: =IF(E$12=0,0,E31/E$12) -> 0
B32: E2 Engineer 3-6 years | C32: =SUMIFS('Seat Ledger'!$L$5:$L$70,'Seat Ledger'!$A$5:$A$70,1,'Seat Ledger'!$G$5:$G$70,"E2") -> 12 | D32: =SUMIFS('Seat Ledger'!$L$5:$L$70,'Seat Ledger'!$A$5:$A$70,2,'Seat Ledger'!$G$5:$G$70,"E2") -> 3 | E32: =SUMIFS('Seat Ledger'!$L$5:$L$70,'Seat Ledger'!$A$5:$A$70,3,'Seat Ledger'!$G$5:$G$70,"E2") -> 0 | G32: =IF(C$12=0,0,C32/C$12) -> 0.24 | H32: =IF(D$12=0,0,D32/D$12) -> 0.075 | I32: =IF(E$12=0,0,E32/E$12) -> 0
B33: E3 Senior 6-10 years | C33: =SUMIFS('Seat Ledger'!$L$5:$L$70,'Seat Ledger'!$A$5:$A$70,1,'Seat Ledger'!$G$5:$G$70,"E3") -> 11 | D33: =SUMIFS('Seat Ledger'!$L$5:$L$70,'Seat Ledger'!$A$5:$A$70,2,'Seat Ledger'!$G$5:$G$70,"E3") -> 15 | E33: =SUMIFS('Seat Ledger'!$L$5:$L$70,'Seat Ledger'!$A$5:$A$70,3,'Seat Ledger'!$G$5:$G$70,"E3") -> 9 | G33: =IF(C$12=0,0,C33/C$12) -> 0.22 | H33: =IF(D$12=0,0,D33/D$12) -> 0.375 | I33: =IF(E$12=0,0,E33/E$12) -> 0.3
B34: E4 Lead / specialist 10-15 years | C34: =SUMIFS('Seat Ledger'!$L$5:$L$70,'Seat Ledger'!$A$5:$A$70,1,'Seat Ledger'!$G$5:$G$70,"E4") -> 25 | D34: =SUMIFS('Seat Ledger'!$L$5:$L$70,'Seat Ledger'!$A$5:$A$70,2,'Seat Ledger'!$G$5:$G$70,"E4") -> 20 | E34: =SUMIFS('Seat Ledger'!$L$5:$L$70,'Seat Ledger'!$A$5:$A$70,3,'Seat Ledger'!$G$5:$G$70,"E4") -> 19 | G34: =IF(C$12=0,0,C34/C$12) -> 0.5 | H34: =IF(D$12=0,0,D34/D$12) -> 0.5 | I34: =IF(E$12=0,0,E34/E$12) -> 0.63333333
B35: E5 Principal / architect 15 years+ | C35: =SUMIFS('Seat Ledger'!$L$5:$L$70,'Seat Ledger'!$A$5:$A$70,1,'Seat Ledger'!$G$5:$G$70,"E5") -> 2 | D35: =SUMIFS('Seat Ledger'!$L$5:$L$70,'Seat Ledger'!$A$5:$A$70,2,'Seat Ledger'!$G$5:$G$70,"E5") -> 2 | E35: =SUMIFS('Seat Ledger'!$L$5:$L$70,'Seat Ledger'!$A$5:$A$70,3,'Seat Ledger'!$G$5:$G$70,"E5") -> 2 | G35: =IF(C$12=0,0,C35/C$12) -> 0.04 | H35: =IF(D$12=0,0,D35/D$12) -> 0.05 | I35: =IF(E$12=0,0,E35/E$12) -> 0.066666667
B36: Talent shape | C36: =IF((C34+C35)/C12>0.55,"Obelisk",IF((C34+C35)/C12>0.4,"Diamond","Pyramid")) -> Diamond | D36: =IF((D34+D35)/D12>0.55,"Obelisk",IF((D34+D35)/D12>0.4,"Diamond","Pyramid")) -> Diamond | E36: =IF((E34+E35)/E12>0.55,"Obelisk",IF((E34+E35)/E12>0.4,"Diamond","Pyramid")) -> Obelisk
B37: Senior share (E4 + E5) | C37: =IF(C12=0,0,(C34+C35)/C12) -> 0.54 | D37: =IF(D12=0,0,(D34+D35)/D12) -> 0.55 | E37: =IF(E12=0,0,(E34+E35)/E12) -> 0.7
A39: F. SKILL DISTRIBUTION — also grounds-up
B40: Skill family | C40: Year 1 | D40: Year 2 | E40: Year 3 | G40: Y1 % | H40: Y2 % | I40: Y3 %
B41: Leadership & delivery management | C41: =SUMIFS('Seat Ledger'!$L$5:$L$70,'Seat Ledger'!$A$5:$A$70,1,'Seat Ledger'!$F$5:$F$70,"LEAD") -> 16 | D41: =SUMIFS('Seat Ledger'!$L$5:$L$70,'Seat Ledger'!$A$5:$A$70,2,'Seat Ledger'!$F$5:$F$70,"LEAD") -> 11 | E41: =SUMIFS('Seat Ledger'!$L$5:$L$70,'Seat Ledger'!$A$5:$A$70,3,'Seat Ledger'!$F$5:$F$70,"LEAD") -> 7 | G41: =IF(C$12=0,0,C41/C$12) -> 0.32 | H41: =IF(D$12=0,0,D41/D$12) -> 0.275 | I41: =IF(E$12=0,0,E41/E$12) -> 0.23333333
B42: Business analysis & domain | C42: =SUMIFS('Seat Ledger'!$L$5:$L$70,'Seat Ledger'!$A$5:$A$70,1,'Seat Ledger'!$F$5:$F$70,"BA") -> 6 | D42: =SUMIFS('Seat Ledger'!$L$5:$L$70,'Seat Ledger'!$A$5:$A$70,2,'Seat Ledger'!$F$5:$F$70,"BA") -> 5 | E42: =SUMIFS('Seat Ledger'!$L$5:$L$70,'Seat Ledger'!$A$5:$A$70,3,'Seat Ledger'!$F$5:$F$70,"BA") -> 5 | G42: =IF(C$12=0,0,C42/C$12) -> 0.12 | H42: =IF(D$12=0,0,D42/D$12) -> 0.125 | I42: =IF(E$12=0,0,E42/E$12) -> 0.16666667
B43: Development | C43: =SUMIFS('Seat Ledger'!$L$5:$L$70,'Seat Ledger'!$A$5:$A$70,1,'Seat Ledger'!$F$5:$F$70,"DEV") -> 12 | D43: =SUMIFS('Seat Ledger'!$L$5:$L$70,'Seat Ledger'!$A$5:$A$70,2,'Seat Ledger'!$F$5:$F$70,"DEV") -> 9 | E43: =SUMIFS('Seat Ledger'!$L$5:$L$70,'Seat Ledger'!$A$5:$A$70,3,'Seat Ledger'!$F$5:$F$70,"DEV") -> 3 | G43: =IF(C$12=0,0,C43/C$12) -> 0.24 | H43: =IF(D$12=0,0,D43/D$12) -> 0.225 | I43: =IF(E$12=0,0,E43/E$12) -> 0.1
B44: Engineering, AI & platform | C44: =SUMIFS('Seat Ledger'!$L$5:$L$70,'Seat Ledger'!$A$5:$A$70,1,'Seat Ledger'!$F$5:$F$70,"ENG") -> 6 | D44: =SUMIFS('Seat Ledger'!$L$5:$L$70,'Seat Ledger'!$A$5:$A$70,2,'Seat Ledger'!$F$5:$F$70,"ENG") -> 6 | E44: =SUMIFS('Seat Ledger'!$L$5:$L$70,'Seat Ledger'!$A$5:$A$70,3,'Seat Ledger'!$F$5:$F$70,"ENG") -> 15 | G44: =IF(C$12=0,0,C44/C$12) -> 0.12 | H44: =IF(D$12=0,0,D44/D$12) -> 0.15 | I44: =IF(E$12=0,0,E44/E$12) -> 0.5
B45: Test & quality engineering | C45: =SUMIFS('Seat Ledger'!$L$5:$L$70,'Seat Ledger'!$A$5:$A$70,1,'Seat Ledger'!$F$5:$F$70,"TEST") -> 10 | D45: =SUMIFS('Seat Ledger'!$L$5:$L$70,'Seat Ledger'!$A$5:$A$70,2,'Seat Ledger'!$F$5:$F$70,"TEST") -> 9 | E45: =SUMIFS('Seat Ledger'!$L$5:$L$70,'Seat Ledger'!$A$5:$A$70,3,'Seat Ledger'!$F$5:$F$70,"TEST") -> 0 | G45: =IF(C$12=0,0,C45/C$12) -> 0.2 | H45: =IF(D$12=0,0,D45/D$12) -> 0.225 | I45: =IF(E$12=0,0,E45/E$12) -> 0
B46: Operations & production support | C46: =SUMIFS('Seat Ledger'!$L$5:$L$70,'Seat Ledger'!$A$5:$A$70,1,'Seat Ledger'!$F$5:$F$70,"OPS") -> 0 | D46: =SUMIFS('Seat Ledger'!$L$5:$L$70,'Seat Ledger'!$A$5:$A$70,2,'Seat Ledger'!$F$5:$F$70,"OPS") -> 0 | E46: =SUMIFS('Seat Ledger'!$L$5:$L$70,'Seat Ledger'!$A$5:$A$70,3,'Seat Ledger'!$F$5:$F$70,"OPS") -> 0 | G46: =IF(C$12=0,0,C46/C$12) -> 0 | H46: =IF(D$12=0,0,D46/D$12) -> 0 | I46: =IF(E$12=0,0,E46/E$12) -> 0
...

Sheet Glidepath & 50-50
A1: Glidepath — target from the logic tree, delivered from the pod design, and the transfer needed for 50:50
A2: The tree says what the archetype mix should allow. The pod design says what we have actually staffed to. The gap is transition drag.
A4: A. BASELINE — MetLife current state for this domain
B5: Measure | C5: Value
B6: Applications | C6: ='Logic Tree'!C6 -> 5
B7: Total effort (units) | C7: ='Logic Tree'!C7 -> 48.510292
B8: Current Capgemini FTC | C8: ='Logic Tree'!C8 -> 38.147792
B9: Current MetLife FTE | C9: ='Logic Tree'!C9 -> 9.7791667
B10: Current MetLife MGCC | C10: ='Logic Tree'!C10 -> 0.58333333
B11: MetLife Appendix 3 Year-3 target FTC | C11: ='Logic Tree'!C7/2 -> 24.255146
B12: Implied MetLife productivity assumption | C12: =0 -> 0 | H12: Appendix 3 v2 halves every application and leaves the portfolio unchanged, so it assumes zero productivity.
A14: B. PRODUCTIVITY — target vs delivered
B15: Measure | C15: Year 1 | D15: Year 2 | E15: Year 3
B16: Headcount delivered by the pod design | C16: ='Team Build-Up'!C12 -> 50 | D16: ='Team Build-Up'!D12 -> 40 | E16: ='Team Build-Up'!E12 -> 30 | H16: Year 1 absorbs the whole of the drag: knowledge acquisition, substrate build and dual running are real work that consumes the productivity earned.
B17: Delivered productivity vs baseline | C17: =IF($C$7=0,0,1-'Team Build-Up'!C12/$C$7) -> -0.030709119 | D17: =IF($C$7=0,0,1-'Team Build-Up'!D12/$C$7) -> 0.1754327 | E17: =IF($C$7=0,0,1-'Team Build-Up'!E12/$C$7) -> 0.38157453
B18: Target productivity from the logic tree | C18: ='Logic Tree'!C53 -> 0.1385009 | D18: ='Logic Tree'!D53 -> 0.29114436 | E18: ='Logic Tree'!E53 -> 0.38498931
B19: Transition & enablement drag (target less delivered) | C19: =C18-C17 -> 0.16921002 | D19: =D18-D17 -> 0.11571166 | E19: =E18-E17 -> 0.0034147788
A22: C. OFFSHORE — target vs delivered
B23: Measure | C23: Year 1 | D23: Year 2 | E23: Year 3
B24: Delivered offshore share (bottom-up from seats) | C24: ='Team Build-Up'!C27 -> 0.44 | D24: ='Team Build-Up'!D27 -> 0.55 | E24: ='Team Build-Up'!E27 -> 0.46666667
B25: Target offshore share from the logic tree | C25: ='Logic Tree'!C62 -> 0.22818421 | D25: ='Logic Tree'!D62 -> 0.34027469 | E25: ='Logic Tree'!E62 -> 0.37230055
B26: Variance | C26: =C24-C25 -> 0.21181579 | D26: =D24-D25 -> 0.20972531 | E26: =E24-E25 -> 0.094366118
A28: D. THE 50:50 SOLVE
B29: Productivity shrinks the Capgemini side and the MetLife side together, so it cannot move the ratio. Only transfer of employment can.
B30: Measure | C30: Year 1 | D30: Year 2 | E30: Year 3
B31: Total people | C31: ='Team Build-Up'!C12 -> 50 | D31: ='Team Build-Up'!D12 -> 40 | E31: ='Team Build-Up'!E12 -> 30
B32: Capgemini FTC before transfer | C32: ='Team Build-Up'!C18 -> 33 | D32: ='Team Build-Up'!D18 -> 23 | E32: ='Team Build-Up'!E18 -> 13
B33: MetLife FTE before transfer | C33: ='Team Build-Up'!C19 -> 16 | D33: ='Team Build-Up'!D19 -> 16 | E33: ='Team Build-Up'!E19 -> 16
B34: MetLife MGCC before transfer | C34: ='Team Build-Up'!C20 -> 1 | D34: ='Team Build-Up'!D20 -> 1 | E34: ='Team Build-Up'!E20 -> 1
B35: Ratio before transfer FTC : MetLife | C35: =IF(C31=0,0,C32/C31) -> 0.66 | D35: =IF(D31=0,0,D32/D31) -> 0.575 | E35: =IF(E31=0,0,E32/E31) -> 0.43333333
B36: Transferred to MetLife FTE this year | C36: ='Logic Tree'!C67 -> 0 | D36: ='Logic Tree'!D67 -> 0 | E36: ='Logic Tree'!E67 -> 0
B37: Transferred to MetLife MGCC this year | C37: ='Logic Tree'!C68 -> 0 | D37: ='Logic Tree'!D68 -> 0 | E37: ='Logic Tree'!E68 -> 0
B38: Cumulative transferred | C38: ='Logic Tree'!C69 -> 0 | D38: ='Logic Tree'!D69 -> 0 | E38: ='Logic Tree'!E69 -> 0
B39: Capgemini FTC after transfer | C39: =C32-C38 -> 33 | D39: =D32-D38 -> 23 | E39: =E32-E38 -> 13
B40: MetLife side after transfer | C40: =C33+C34+C38 -> 17 | D40: =D33+D34+D38 -> 17 | E40: =E33+E34+E38 -> 17
B41: RATIO ACHIEVED — Capgemini share | C41: =IF(C31=0,0,C39/C31) -> 0.66 | D41: =IF(D31=0,0,D39/D31) -> 0.575 | E41: =IF(E31=0,0,E39/E31) -> 0.43333333 | H41: A negative shortfall means the plan transfers more than 50:50 requires.
B42: Transfer required for exactly 50:50 (cumulative) | C42: =C31/2-C33-C34 -> 8 | D42: =D31/2-D33-D34 -> 3 | E42: =E31/2-E33-E34 -> -2
B43: Shortfall against 50:50 | C43: =C42-C38 -> 8 | D43: =D42-D38 -> 3 | E43: =E42-E38 -> -2
B45: Of the fall in the Capgemini population from Year 1 to Year 3:
B46: attributable to productivity and offshore mix | C46: =C32-E32 -> 20 | H46: Transfer moves revenue rather than creating efficiency. It has to be priced separately.
...

Sheet Cost & Commercial
A1: Cost and commercial position — relative index only, pending the approved rate card
A2: Onshore Tokyo band E2 = 1.00. Every figure moves if the cost index on the Logic Tree changes.
A4: A. TOTAL COST OF DELIVERING THE DOMAIN (MetLife view — all three sourcing types)
B5: Measure | C5: Year 1 | D5: Year 2 | E5: Year 3
B6: Total cost index | C6: =SUMIFS('Seat Ledger'!$M$5:$M$70,'Seat Ledger'!$A$5:$A$70,1) -> 60.5 | D6: =SUMIFS('Seat Ledger'!$M$5:$M$70,'Seat Ledger'!$A$5:$A$70,2) -> 44.3 | E6: =SUMIFS('Seat Ledger'!$M$5:$M$70,'Seat Ledger'!$A$5:$A$70,3) -> 37.33
B7: Headcount | C7: ='Team Build-Up'!C12 -> 50 | D7: ='Team Build-Up'!D12 -> 40 | E7: ='Team Build-Up'!E12 -> 30
B8: Average cost per head | C8: =IF(C7=0,0,C6/C7) -> 1.21 | D8: =IF(D7=0,0,D6/D7) -> 1.1075 | E8: =IF(E7=0,0,E6/E7) -> 1.2443333 | G8: Watch this line. Average cost per head falls in Year 2 on offshore leverage, then rises in Year 3 as juniors leave and the shape turns obelisk.
B9: Cost per unit of original scope | C9: =IF('Glidepath & 50-50'!$C$7=0,0,C6/'Glidepath & 50-50'!$C$7) -> 1.247158 | D9: =IF('Glidepath & 50-50'!$C$7=0,0,D6/'Glidepath & 50-50'!$C$7) -> 0.91320828 | E9: =IF('Glidepath & 50-50'!$C$7=0,0,E6/'Glidepath & 50-50'!$C$7) -> 0.76952743
B10: Unit cost reduction vs Year 1 | C10: =IF($C$9=0,0,1-C9/$C$9) -> 0 | D10: =IF($C$9=0,0,1-D9/$C$9) -> 0.2677686 | E10: =IF($C$9=0,0,1-E9/$C$9) -> 0.38297521 | G10: This is the number to quote commercially, not the headcount reduction.
A12: B. CAPGEMINI BILLABLE POSITION (after transfer of employment)
B13: Measure | C13: Year 1 | D13: Year 2 | E13: Year 3
B14: Capgemini heads billed | C14: ='Glidepath & 50-50'!C39 -> 33 | D14: ='Glidepath & 50-50'!D39 -> 23 | E14: ='Glidepath & 50-50'!E39 -> 13
