Workbook

Sheet README
A1: MetLife Japan | Data Infrastructure — Domain Framework & Pricing Engine
A2: INTERNAL — Capgemini review copy. Three applications, two value streams, MGCC already embedded.
A4: WHAT IS DIFFERENT ABOUT THIS DOMAIN
B5: Scale | C5: Three applications, 100.8 effort units — 6.7% of the portfolio. Contract Management is 28 applications and 230.8 units.
B6: Two value streams | C6: Informatica (BCMETL + BCMHRP, 50.7u) and Azure Synapse (JDPREP, 50.1u). Almost exactly half each.
B7: Sunset asymmetry | C7: Synapse is the go-forward platform. Informatica is on a sunset path, but the modernisation is OUT OF SCOPE of this RFP — so we run it, we do not migrate it, and we do not build an agent estate for it.
B8: MGCC is already here | C8: 16.0 units of MGCC across both platforms. Contract Management had none. That changes the 50:50 arithmetic completely.
B9: The headline finding | C9: Productivity alone crosses 50:50 during Year 3 and lands at 41:59. Year 2 sits just short at 52:48. No transfer of employment is required in this domain — the opposite question arises.
A10: HOW THE MODEL WORKS
B11: Direction of travel | C11: Bottom-up. You define seats in pods; the workbook derives headcount, productivity, offshore share, experience mix and cost. Nothing is asserted.
B12: Realisation is per value stream | C12: Not just per archetype. Informatica realises less of its AI ceiling because we are not investing in a platform being retired.
B13: Offshore is measured on Capgemini effort | C13: The 19 onshore MetLife FTE are their placement decision, not ours. The ceiling governs the work we can place, so the tree is applied to Capgemini seats.
B14: Pod sizes are not a uniform ladder | C14: Synapse 9→7→6, Informatica 8→7→6, and fully-sourced pods differ from co-sourced. See the Pod Library sheet.
B15: Fully-sourced pods carry MetLife too | C15: A product owner, and on Synapse a data architect — fractional in Year 1 where shared across two pods. Full ownership of the output still sits with Capgemini.
A16: CELL COLOUR CONVENTION
B17: Blue text | C17: Input. Change these.
B18: Black text | C18: Formula. Do not overwrite.
B19: Green text | C19: Link to another sheet in this workbook.
B20: Amber fill | C20: Key assumption requiring sign-off before this model is used to price.
A21: SHEET MAP
B22: Logic Tree | C22: Parametric drivers: phase mix, AI ceiling per archetype, realisation per value stream, offshore ceilings, cost index.
B23: Inventory | C23: All 142 applications with derived archetype. Filter to a domain to see its mix.
B24: Value Streams | C24: The two streams, their applications and the AD / run split.
B25: Pod Library | C25: INPUT. Every seat in every pod archetype, by year AND by value stream. Counts may be fractional.
B26: Pod Plan | C26: INPUT. Co-sourced and fully-sourced pod counts per stream per year.
B27: Horizontal Teams | C27: INPUT. The three cross-cutting teams.
B28: Seat Ledger | C28: Computed. Every pod line multiplied out, plus horizontals. All roll-ups read from here.
B29: Team Build-Up | C29: Computed. Headcount by year, sourcing, location, experience band and skill family.
B30: Glidepath & 50-50 | C30: Computed. Productivity and offshore, target vs delivered, and the ratio.
B31: Cost & Commercial | C31: Computed. Cost index, unit cost, and the Capgemini position.
B32: Unit Cost Sensitivity | C32: NEW. How experience mix, offshore share and productivity interact to move unit cost.
A33: ASSUMPTIONS REQUIRING SIGN-OFF
B34: Cost index | C34: Relative only. Onshore Tokyo E2 = 1.00, offshore roughly one third at like-for-like band. Replace with the approved rate card before pricing.
B35: Informatica realisation | C35: 20 / 40 / 55% against its ceiling, versus 25 / 55 / 75% for Synapse. This is the sunset discount and it is a judgement, not a measurement.
B36: Informatica is a priority transfer target | C36: Both BCMETL and BCMHRP carry Priority Transfer Targets = Y. The portfolio bedrock says route archetype C to MGCC. Because this platform is being retired, transferring it builds a capability MetLife will not keep — see the decision on Glidepath & 50-50.

Sheet Logic Tree
A1: Logic Tree — parametric drivers for productivity, offshore and cost
A2: Change the blue cells. Every downstream number re-derives.
A4: A. DOMAIN AND EFFORT BASE
B5: Domain | C5: Data Infrastructure | I5: Must match the Inventory domain column exactly.
B6: Applications in domain | C6: =SUMIFS(Inventory!$U:$U,Inventory!$E:$E,$C$5) -> 3
B7: Total effort (units) | C7: =SUMIFS(Inventory!$AD:$AD,Inventory!$E:$E,$C$5) -> 100.76497
B8: Current FTC | C8: =SUMIFS(Inventory!$AA:$AA,Inventory!$E:$E,$C$5) -> 64.704594
B9: Current FTE | C9: =SUMIFS(Inventory!$AB:$AB,Inventory!$E:$E,$C$5) -> 18.825
B10: Current MGCC | C10: =SUMIFS(Inventory!$AC:$AC,Inventory!$E:$E,$C$5) -> 15.991667
B11: AD effort (%PRJ weighted) | C11: =SUMIFS(Inventory!$AF:$AF,Inventory!$E:$E,$C$5) -> 87.126844
B12: Run effort | C12: =C7-C11 -> 13.638125
B13: AD share of effort | C13: =IF(C7=0,0,C11/C7) -> 0.8646541
A15: B. ARCHETYPE MIX OF THIS DOMAIN
B16: Archetype | C16: Definition | D16: Apps | E16: Effort | F16: Share
B17: A | C17: Language-locked | D17: =SUMIFS(Inventory!$U:$U,Inventory!$E:$E,$C$5,Inventory!$AG:$AG,$B17) -> 0 | E17: =SUMIFS(Inventory!$AD:$AD,Inventory!$E:$E,$C$5,Inventory!$AG:$AG,$B17) -> 0 | F17: =IF($C$7=0,0,E17/$C$7) -> 0
B18: B | C18: Offshore-ready — modern stack, not a transfer target | D18: =SUMIFS(Inventory!$U:$U,Inventory!$E:$E,$C$5,Inventory!$AG:$AG,$B18) -> 1 | E18: =SUMIFS(Inventory!$AD:$AD,Inventory!$E:$E,$C$5,Inventory!$AG:$AG,$B18) -> 50.06501 | F18: =IF($C$7=0,0,E18/$C$7) -> 0.49684936
B19: C | C19: MGCC-destined — Priority Transfer Target = Y | D19: =SUMIFS(Inventory!$U:$U,Inventory!$E:$E,$C$5,Inventory!$AG:$AG,$B19) -> 2 | E19: =SUMIFS(Inventory!$AD:$AD,Inventory!$E:$E,$C$5,Inventory!$AG:$AG,$B19) -> 50.699958 | F19: =IF($C$7=0,0,E19/$C$7) -> 0.50315064
B20: D | C20: Legacy-coupled core | D20: =SUMIFS(Inventory!$U:$U,Inventory!$E:$E,$C$5,Inventory!$AG:$AG,$B20) -> 0 | E20: =SUMIFS(Inventory!$AD:$AD,Inventory!$E:$E,$C$5,Inventory!$AG:$AG,$B20) -> 0 | F20: =IF($C$7=0,0,E20/$C$7) -> 0
B21: Total | D21: =SUM(D17:D20) -> 3 | E21: =SUM(E17:E20) -> 100.76497 | F21: =SUM(F17:F20) -> 1
A23: C. PRODUCTIVITY — GATE 1 : where the effort sits
B24: Delivery phase | C24: Share of effort
B25: Requirements & impact analysis | C25: 0.12
B26: Design & architecture | C26: 0.13
B27: Build & code | C27: 0.3
B28: Test & quality assurance | C28: 0.25
B29: Release & deploy | C29: 0.05
B30: Run, monitor & coordinate | C30: 0.15
B31: Total (must equal 100%) | C31: =SUM(C25:C30) -> 1
A33: D. PRODUCTIVITY — GATE 2 : AI-addressable share per phase, per archetype
B34: Delivery phase | C34: A | D34: B | E34: C | F34: D
B35: Requirements & impact analysis | C35: 0.22 | D35: 0.3 | E35: 0.15 | F35: 0.35 | G35: Potential Metlife internal AI Tools
B36: Design & architecture | C36: 0.2 | D36: 0.35 | E36: 0.12 | F36: 0.22 | G36: MetIQ
B37: Build & code | C37: 0.32 | D37: 0.5 | E37: 0.25 | F37: 0.2 | G37: Github Copilot
B38: Test & quality assurance | C38: 0.38 | D38: 0.6 | E38: 0.3 | F38: 0.4 | G38: Databricks Genie
B39: Release & deploy | C39: 0.3 | D39: 0.35 | E39: 0.1 | F39: 0.25 | G39: MS Foundry
B40: Run, monitor & coordinate | C40: 0.3 | D40: 0.3 | E40: 0.08 | F40: 0.32
B41: Weighted AI ceiling | C41: =SUMPRODUCT($C$25:$C$30,C35:C40) -> 0.3034 | D41: =SUMPRODUCT($C$25:$C$30,D35:D40) -> 0.444 | E41: =SUMPRODUCT($C$25:$C$30,E35:E40) -> 0.2006 | F41: =SUMPRODUCT($C$25:$C$30,F35:F40) -> 0.2911 | G41: Informatica legacy estate's AI-driven productivity is much lesser as it is On-premise and also undergoing modernization so GenAI tools are not fully effective for Archetype C-2 Apps; compared to Modern Azure Stack for Archetype B -1 App
A43: E. GATE 3 : realisation, PER VALUE STREAM — Informatica carries a sunset discount
B44: Value stream | C44: Archetype | D44: Year 1 | E44: Year 2 | F44: Year 3 | G44: Why it differs
B45: VS1 · Informatica | C45: C | D45: 0.2 | E45: 0.4 | F45: 0 | G45: Sunset path — no agent estate is built for a platform being retired
...

Sheet Inventory
A1: Application inventory — Appendix 3 v2, with derived archetype and value stream
A2: Archetype applied at build time by the rule: mainframe language → D; else Priority Transfer Target → C; else SaaS → A; else B. Columns AG and AH are literals, re-derived when the model is rebuilt.
A4: # | B4: EAI ID | C4: Application | D4: Long name | E4: Domain | F4: Group | G4: Team | H4: Class | I4: Critical | J4: Hosting | K4: Primary code language | L4: Cloud platform | M4: Priority transfer | N4: Current FTC | O4: Current FTE | P4: Current MGCC | Q4: Total | R4: % of PRJ | S4: Target FTC | T4: Target FTE/MGCC | U4: App count | AA4: FTC | AB4: FTE | AC4: MGCC | AD4: Effort | AE4: AD share | AF4: AD effort | AG4: Archetype | AH4: Value stream
A5: 1 | B5: 9629 | C5: Global Sales Comp - Japan | D5: Global Sales Comp - Japan | E5: Fee Management | F5: Core Insurance Systems Group 34956 | G5: Commission Systems Team 34958 | H5: Core Business Application | I5: N | J5: Yes | K5: Other#Infomatica workflow Bash shell Dos batch | L5: Software as a Service (SaaS) | M5: N | N5: 0 | O5: 0 | P5: 0 | Q5: 0 | R5: 0 | U5: 1 | AA5: =N5 -> 0 | AB5: =O5 -> 0 | AC5: =P5 -> 0 | AD5: =Q5 -> 0 | AE5: =R5 -> 0 | AF5: =Q5*R5 -> 0 | AG5: A
A6: 2 | B6: 9796 | C6: LC POSPMC MF-JPN | D6: LifeComm POSPMC | E6: contract management | F6: Core Insurance Systems Group 34956 | G6: Policy Admin Systems Team 34957 | H6: Core Business Application | I6: Y | J6: Yes | K6: Assembler, COBOL, MU(EASYPLUS), JCL | M6: N | N6: 59.558958 | O6: 7.7541667 | P6: 0 | Q6: 67.313125 | R6: 0.71176374 | S6: 33.656563 | T6: 33.656563 | U6: 1 | AA6: =N6 -> 59.558958 | AB6: =O6 -> 7.7541667 | AC6: =P6 -> 0 | AD6: =Q6 -> 67.313125 | AE6: =R6 -> 0.71176374 | AF6: =Q6*R6 -> 47.911042 | AG6: D
A7: 3 | B7: 9800 | C7: LC Billing MF-JPN | D7: LifeComm Billing | E7: contract management | F7: Core Insurance Systems Group 34956 | G7: Policy Admin Systems Team 34957 | H7: Core Business Application | I7: Y | J7: Yes | K7: COBOL, Assembler, MU(EASYPLUS), JCL | M7: N | N7: 20.892167 | O7: 1.85375 | P7: 0 | Q7: 22.745917 | R7: 0.94285788 | S7: 11.372958 | T7: 11.372958 | U7: 1 | AA7: =N7 -> 20.892167 | AB7: =O7 -> 1.85375 | AC7: =P7 -> 0 | AD7: =Q7 -> 22.745917 | AE7: =R7 -> 0.94285788 | AF7: =Q7*R7 -> 21.446167 | AG7: D
A8: 4 | B8: 9801 | C8: LC Collection MF-JPN | D8: LifeComm Collection | E8: contract management | F8: Core Insurance Systems Group 34956 | G8: Policy Admin Systems Team 34957 | H8: Core Business Application | I8: Y | J8: Yes | K8: COBOL, Assembler, MU(EASYPLUS), JCL | M8: N | N8: 0 | O8: 0 | P8: 0 | Q8: 0 | R8: 0 | U8: 1 | AA8: =N8 -> 0 | AB8: =O8 -> 0 | AC8: =P8 -> 0 | AD8: =Q8 -> 0 | AE8: =R8 -> 0 | AF8: =Q8*R8 -> 0 | AG8: D
A9: 5 | B9: 9802 | C9: LC Corresponding MF-JPN | D9: LifeComm Corresponding | E9: contract management | F9: Core Insurance Systems Group 34956 | G9: Policy Admin Systems Team 34957 | H9: Core Business Application | I9: Y | J9: Yes | K9: COBOL, Assembler, MU(EASYPLUS), JCL | M9: N | N9: 15.953625 | O9: 1.6541667 | P9: 0 | Q9: 17.607792 | R9: 0.98287217 | S9: 8.8038958 | T9: 8.8038958 | U9: 1 | AA9: =N9 -> 15.953625 | AB9: =O9 -> 1.6541667 | AC9: =P9 -> 0 | AD9: =Q9 -> 17.607792 | AE9: =R9 -> 0.98287217 | AF9: =Q9*R9 -> 17.306208 | AG9: D
A10: 6 | B10: 9803 | C10: LC UWI MF-JPN | D10: LifeComm UWI | E10: contract management | F10: Core Insurance Systems Group 34956 | G10: Policy Admin Systems Team 34957 | H10: Core Business Application | I10: Y | J10: Yes | K10: Assembler, COBOL, MU(EASYPLUS), JCL | M10: N | N10: 8.8045833 | O10: 0.85 | P10: 0 | Q10: 9.6545833 | R10: 0.94821113 | S10: 4.8272917 | T10: 4.8272917 | U10: 1 | AA10: =N10 -> 8.8045833 | AB10: =O10 -> 0.85 | AC10: =P10 -> 0 | AD10: =Q10 -> 9.6545833 | AE10: =R10 -> 0.94821113 | AF10: =Q10*R10 -> 9.1545833 | AG10: D
A11: 7 | B11: 9804 | C11: LC AAPerf MF-JPN | D11: LifeComm AgentAgencyPerformance | E11: contract management | F11: Core Insurance Systems Group 34956 | G11: Policy Admin Systems Team 34957 | H11: Core Business Application | I11: Y | J11: Yes | K11: COBOL, Assembler, MU(EASYPLUS), JCL | M11: N | N11: 10.784167 | O11: 0.74583333 | P11: 0 | Q11: 11.53 | R11: 0.83304423 | S11: 5.765 | T11: 5.765 | U11: 1 | AA11: =N11 -> 10.784167 | AB11: =O11 -> 0.74583333 | AC11: =P11 -> 0 | AD11: =Q11 -> 11.53 | AE11: =R11 -> 0.83304423 | AF11: =Q11*R11 -> 9.605 | AG11: D
A12: 8 | B12: 9805 | C12: LC Payment MF-JPN | D12: LifeComm Payment | E12: contract management | F12: Core Insurance Systems Group 34956 | G12: Policy Admin Systems Team 34957 | H12: Core Business Application | I12: Y | J12: Yes | K12: COBOL, Assembler, MU(EASYPLUS), JCL | M12: N | N12: 2.8966667 | O12: 0.025 | P12: 0 | Q12: 2.9216667 | R12: 0.90587564 | S12: 1.4608333 | T12: 1.4608333 | U12: 1 | AA12: =N12 -> 2.8966667 | AB12: =O12 -> 0.025 | AC12: =P12 -> 0 | AD12: =Q12 -> 2.9216667 | AE12: =R12 -> 0.90587564 | AF12: =Q12*R12 -> 2.6466667 | AG12: D
A13: 9 | B13: 9806 | C13: LC GL/SC MF-JPN | D13: LifeComm GL/SC | E13: contract management | F13: Core Insurance Systems Group 34956 | G13: Policy Admin Systems Team 34957 | H13: Core Business Application | I13: Y | J13: Yes | K13: COBOL, Assembler, MU(EASYPLUS), JCL | M13: N | N13: 5.28875 | O13: 1.025 | P13: 0 | Q13: 6.31375 | R13: 0.83765591 | S13: 3.156875 | T13: 3.156875 | U13: 1 | AA13: =N13 -> 5.28875 | AB13: =O13 -> 1.025 | AC13: =P13 -> 0 | AD13: =Q13 -> 6.31375 | AE13: =R13 -> 0.83765591 | AF13: =Q13*R13 -> 5.28875 | AG13: D
A14: 10 | B14: 9807 | C14: LC Valuation MF-JPN | D14: LifeComm Valuation | E14: contract management | F14: Core Insurance Systems Group 34956 | G14: Policy Admin Systems Team 34957 | H14: Core Business Application | I14: N | J14: Yes | K14: COBOL, Assembler, MU(EASYPLUS), JCL | M14: N | N14: 9.76875 | O14: 1.4833333 | P14: 0 | Q14: 11.252083 | R14: 0.8563229 | S14: 5.6260417 | T14: 5.6260417 | U14: 1 | AA14: =N14 -> 9.76875 | AB14: =O14 -> 1.4833333 | AC14: =P14 -> 0 | AD14: =Q14 -> 11.252083 | AE14: =R14 -> 0.8563229 | AF14: =Q14*R14 -> 9.6354167 | AG14: D
A15: 11 | B15: 9808 | C15: LC AACOMP MF-JPN | D15: LifeComm AgentAgencyComp | E15: contract management | F15: Core Insurance Systems Group 34956 | G15: Policy Admin Systems Team 34957 | H15: Core Business Application | I15: Y | J15: Yes | K15: COBOL, Assembler, MU(EASYPLUS), JCL | M15: N | N15: 13.545708 | O15: 3.14375 | P15: 0 | Q15: 16.689458 | R15: 0.72662384 | S15: 8.3447292 | T15: 8.3447292 | U15: 1 | AA15: =N15 -> 13.545708 | AB15: =O15 -> 3.14375 | AC15: =P15 -> 0 | AD15: =Q15 -> 16.689458 | AE15: =R15 -> 0.72662384 | AF15: =Q15*R15 -> 12.126958 | AG15: D
A16: 12 | B16: 9810 | C16: Processor-I MF-JPN | D16: Claim payment (Processor-I) | E16: contract management | F16: Core Insurance Systems Group 34956 | G16: Policy Admin Systems Team 34957 | H16: Core Business Application | I16: Y | J16: Yes | K16: COBOL, MU(EASYPLUS), Assembler, JCL | M16: N | N16: 7.6683333 | O16: 1.1291667 | P16: 0 | Q16: 8.7975 | R16: 0.75561239 | S16: 4.39875 | T16: 4.39875 | U16: 1 | AA16: =N16 -> 7.6683333 | AB16: =O16 -> 1.1291667 | AC16: =P16 -> 0 | AD16: =Q16 -> 8.7975 | AE16: =R16 -> 0.75561239 | AF16: =Q16*R16 -> 6.6475 | AG16: D
A17: 13 | B17: 9811 | C17: LC Submit MF-JPN | D17: Submit Online | E17: contract management | F17: Core Insurance Systems Group 34956 | G17: Policy Admin Systems Team 34957 | H17: Core Business Application | I17: Y | J17: Yes | K17: COBOL, MU(EASYPLUS), Assembler, JCL | M17: N | N17: 1.9683333 | O17: 0.16458333 | P17: 0 | Q17: 2.1329167 | R17: 0.95311584 | S17: 1.0664583 | T17: 1.0664583 | U17: 1 | AA17: =N17 -> 1.9683333 | AB17: =O17 -> 0.16458333 | AC17: =P17 -> 0 | AD17: =Q17 -> 2.1329167 | AE17: =R17 -> 0.95311584 | AF17: =Q17*R17 -> 2.0329167 | AG17: D
A18: 14 | B18: 9813 | C18: LC Micro MF-JPN | D18: Micro-Index | E18: contract management | F18: Core Insurance Systems Group 34956 | G18: Policy Admin Systems Team 34957 | H18: Core Business Application | I18: Y | J18: Yes | K18: COBOL, MU(EASYPLUS), Assembler, JCL | M18: N | N18: 2.1175 | O18: 0 | P18: 0 | Q18: 2.1175 | R18: 0.64580874 | S18: 1.05875 | T18: 1.05875 | U18: 1 | AA18: =N18 -> 2.1175 | AB18: =O18 -> 0 | AC18: =P18 -> 0 | AD18: =Q18 -> 2.1175 | AE18: =R18 -> 0.64580874 | AF18: =Q18*R18 -> 1.3675 | AG18: D
A19: 15 | B19: 9814 | C19: Foreign MF-JPN | D19: Foreign | E19: contract management | F19: Core Insurance Systems Group 34956 | G19: Policy Admin Systems Team 34957 | H19: Core Business Application | I19: N | J19: Yes | K19: COBOL, MU(EASYPLUS), Assembler, JCL | M19: N | N19: 0 | O19: 0 | P19: 0 | Q19: 0 | R19: 0 | U19: 1 | AA19: =N19 -> 0 | AB19: =O19 -> 0 | AC19: =P19 -> 0 | AD19: =Q19 -> 0 | AE19: =R19 -> 0 | AF19: =Q19*R19 -> 0 | AG19: D
A20: 16 | B20: 9816 | C20: CT Salary MF-JPN | D20: CT Salary System | E20: contract management | F20: Core Insurance Systems Group 34956 | G20: Policy Admin Systems Team 34957 | H20: Core Business Application | I20: Y | J20: Yes | K20: COBOL, MU(EASYPLUS), Assembler, JCL | M20: N | N20: 0.2 | O20: 0 | P20: 0 | Q20: 0.2 | R20: 0 | S20: 0.1 | T20: 0.1 | U20: 1 | AA20: =N20 -> 0.2 | AB20: =O20 -> 0 | AC20: =P20 -> 0 | AD20: =Q20 -> 0.2 | AE20: =R20 -> 0 | AF20: =Q20*R20 -> 0 | AG20: D
A21: 17 | B21: 9817 | C21: TaxCertification MF-JPN | D21: TaxCertification | E21: contract management | F21: Core Insurance Systems Group 34956 | G21: Policy Admin Systems Team 34957 | H21: Core Business Application | I21: N | J21: Yes | K21: COBOL, MU(EASYPLUS), Assembler, JCL | M21: N | N21: 1.664875 | O21: 0 | P21: 0 | Q21: 1.664875 | R21: 0.40748805 | S21: 0.8324375 | T21: 0.8324375 | U21: 1 | AA21: =N21 -> 1.664875 | AB21: =O21 -> 0 | AC21: =P21 -> 0 | AD21: =Q21 -> 1.664875 | AE21: =R21 -> 0.40748805 | AF21: =Q21*R21 -> 0.67841667 | AG21: D
A22: 18 | B22: 9818 | C22: SWINGMANAGER MF-JPN | D22: SWING MANAGER | E22: contract management | F22: Core Insurance Systems Group 34956 | G22: Policy Admin Systems Team 34957 | H22: Core Business Application | I22: N | J22: Yes | K22: COBOL, MU(EASYPLUS), Assembler, JCL | M22: N | N22: 0 | O22: 0 | P22: 0 | Q22: 0 | R22: 0 | U22: 1 | AA22: =N22 -> 0 | AB22: =O22 -> 0 | AC22: =P22 -> 0 | AD22: =Q22 -> 0 | AE22: =R22 -> 0 | AF22: =Q22*R22 -> 0 | AG22: D
A23: 19 | B23: 9819 | C23: PremCollectDBMF-JPN | D23: Premium Collection History DB | E23: contract management | F23: Core Insurance Systems Group 34956 | G23: Policy Admin Systems Team 34957 | H23: Core Business Application | I23: N | J23: Yes | K23: COBOL, MU(EASYPLUS), Assembler, JCL | M23: N | N23: 0 | O23: 0 | P23: 0 | Q23: 0 | R23: 0 | U23: 1 | AA23: =N23 -> 0 | AB23: =O23 -> 0 | AC23: =P23 -> 0 | AD23: =Q23 -> 0 | AE23: =R23 -> 0 | AF23: =Q23*R23 -> 0 | AG23: D
A24: 20 | B24: 9820 | C24: MCFA CP DB MF-JPN | D24: MCFA Coupon DB | E24: contract management | F24: Core Insurance Systems Group 34956 | G24: Policy Admin Systems Team 34957 | H24: Core Business Application | I24: Y | J24: Yes | K24: COBOL, MU(EASYPLUS), Assembler, JCL | M24: N | N24: 0 | O24: 0 | P24: 0 | Q24: 0 | R24: 0 | U24: 1 | AA24: =N24 -> 0 | AB24: =O24 -> 0 | AC24: =P24 -> 0 | AD24: =Q24 -> 0 | AE24: =R24 -> 0 | AF24: =Q24*R24 -> 0 | AG24: D
A25: 21 | B25: 9821 | C25: Maturity MF-JPN | D25: Payment maturity existing benefit etc | E25: contract management | F25: Core Insurance Systems Group 34956 | G25: Policy Admin Systems Team 34957 | H25: Core Business Application | I25: Y | J25: Yes | K25: COBOL, MU(EASYPLUS), Assembler, JCL | M25: N | N25: 4.3783333 | O25: 0.97083333 | P25: 0 | Q25: 5.3491667 | R25: 0.62610999 | S25: 2.6745833 | T25: 2.6745833 | U25: 1 | AA25: =N25 -> 4.3783333 | AB25: =O25 -> 0.97083333 | AC25: =P25 -> 0 | AD25: =Q25 -> 5.3491667 | AE25: =R25 -> 0.62610999 | AF25: =Q25*R25 -> 3.3491667 | AG25: D
A26: 22 | B26: 9822 | C26: LC Reins MF-JPN | D26: Reinsurance | E26: contract management | F26: Core Insurance Systems Group 34956 | G26: Policy Admin Systems Team 34957 | H26: Core Business Application | I26: N | J26: Yes | K26: COBOL, MU(EASYPLUS), Assembler, JCL | M26: N | N26: 6.0129167 | O26: 0.25416667 | P26: 0 | Q26: 6.2670833 | R26: 0.78990759 | S26: 3.1335417 | T26: 3.1335417 | U26: 1 | AA26: =N26 -> 6.0129167 | AB26: =O26 -> 0.25416667 | AC26: =P26 -> 0 | AD26: =Q26 -> 6.2670833 | AE26: =R26 -> 0.78990759 | AF26: =Q26*R26 -> 4.9504167 | AG26: D
A27: 23 | B27: 9823 | C27: ASP Bridge(H) MF-JPN | D27: ASP Bridge (HOST) | E27: contract management | F27: Core Insurance Systems Group 34956 | G27: Policy Admin Systems Team 34957 | H27: Common Service Business Application | I27: Y | J27: Yes | K27: COBOL, MU(EASYPLUS), Assembler, JCL | M27: N | N27: 6.7267083 | O27: 1.4625 | P27: 0 | Q27: 8.1892083 | R27: 0.72808727 | S27: 4.0946042 | T27: 4.0946042 | U27: 1 | AA27: =N27 -> 6.7267083 | AB27: =O27 -> 1.4625 | AC27: =P27 -> 0 | AD27: =Q27 -> 8.1892083 | AE27: =R27 -> 0.72808727 | AF27: =Q27*R27 -> 5.9624583 | AG27: D
A28: 24 | B28: 9824 | C28: CCA MF-JPN | D28: Client Contract Administration | E28: contract management | F28: Core Insurance Systems Group 34956 | G28: Policy Admin Systems Team 34957 | H28: Core Business Application | I28: Y | J28: Yes | K28: COBOL, MU(EASYPLUS), Assembler, JCL | M28: N | N28: 1.6308333 | O28: 0 | P28: 0 | Q28: 1.6308333 | R28: 0.38681656 | S28: 0.81541667 | T28: 0.81541667 | U28: 1 | AA28: =N28 -> 1.6308333 | AB28: =O28 -> 0 | AC28: =P28 -> 0 | AD28: =Q28 -> 1.6308333 | AE28: =R28 -> 0.38681656 | AF28: =Q28*R28 -> 0.63083333 | AG28: D
A29: 25 | B29: 9833 | C29: C04NWC-JPN | D29: CenterServer | E29: New Contract Related | F29: Customer Service and Operations Systems Group 34965 | G29: New Business Team 34966 | H29: Core Business Application | I29: N | J29: Yes | K29: C/C++ | M29: N | N29: 8.7316667 | O29: 0.11041667 | P29: 0 | Q29: 8.8420833 | R29: 0.91687479 | S29: 4.4210417 | T29: 4.4210417 | U29: 1 | AA29: =N29 -> 8.7316667 | AB29: =O29 -> 0.11041667 | AC29: =P29 -> 0 | AD29: =Q29 -> 8.8420833 | AE29: =R29 -> 0.91687479 | AF29: =Q29*R29 -> 8.1070833 | AG29: B
A30: 26 | B30: 9834 | C30: C03WRE-JPN | D30: POS Workflow Payment Workflow (Restoring cancelled | E30: Storage and Preservation Related | F30: Customer Service and Operations Systems Group 34965 | G30: Policy Servicing Team 34967 | H30: Core Business Application | I30: Y | J30: Yes | K30: VB.NET | M30: N | N30: 0.2 | O30: 0.2 | P30: 0 | Q30: 0.37083333 | R30: 0.3258427 | S30: 0.18541667 | T30: 0.18541667 | U30: 1 | AA30: =N30 -> 0.2 | AB30: =O30 -> 0.2 | AC30: =P30 -> 0 | AD30: =Q30 -> 0.37083333 | AE30: =R30 -> 0.3258427 | AF30: =Q30*R30 -> 0.12083333 | AG30: B
A31: 27 | B31: 9835 | C31: C12WNC-JPN | D31: POS Workflow Payment Workflow (Claim Transaction A | E31: Insurance Claims and Benefits Payment Related | F31: Customer Service and Operations Systems Group 34965 | G31: Claims Team 34968 | H31: Core Business Application | I31: Y | J31: Yes | K31: VB.NET; C/C++; JAVA | M31: N | N31: 29.379875 | O31: 5.6166667 | P31: 0 | Q31: 34.996542 | R31: 0.90522873 | S31: 17.498271 | T31: 17.498271 | U31: 1 | AA31: =N31 -> 29.379875 | AB31: =O31 -> 5.6166667 | AC31: =P31 -> 0 | AD31: =Q31 -> 34.996542 | AE31: =R31 -> 0.90522873 | AF31: =Q31*R31 -> 31.679875 | AG31: B
A32: 28 | B32: 9836 | C32: C03WRD-JPN | D32: POS Workflow Payment Workflow (Reduction of paymen | E32: Storage and Preservation Related | F32: Customer Service and Operations Systems Group 34965 | G32: Policy Servicing Team 34967 | H32: Core Business Application | I32: Y | J32: Yes | K32: VB.NET | M32: N | N32: 0.3 | O32: 0.3 | P32: 0 | Q32: 2.5258333 | R32: 0.90102276 | S32: 1.2629167 | T32: 1.2629167 | U32: 1 | AA32: =N32 -> 0.3 | AB32: =O32 -> 0.3 | AC32: =P32 -> 0 | AD32: =Q32 -> 2.5258333 | AE32: =R32 -> 0.90102276 | AF32: =Q32*R32 -> 2.2758333 | AG32: B
A33: 29 | B33: 9842 | C33: C03PCA-JPN | D33: Add Coverage | E33: Storage and Preservation Related | F33: Customer Service and Operations Systems Group 34965 | G33: Policy Servicing Team 34967 | H33: Core Business Application | I33: N | J33: Yes | K33: VB | M33: N | N33: 0.3 | O33: 0.3 | P33: 0 | Q33: 2.88625 | R33: 0.90298831 | S33: 1.443125 | T33: 1.443125 | U33: 1 | AA33: =N33 -> 0.3 | AB33: =O33 -> 0.3 | AC33: =P33 -> 0 | AD33: =Q33 -> 2.88625 | AE33: =R33 -> 0.90298831 | AF33: =Q33*R33 -> 2.60625 | AG33: B
A34: 30 | B34: 9843 | C34: C10CSS-JPN | D34: FSC Call Support | E34: Customer Care / Call Center Related | F34: Customer Service and Operations Systems Group 34965 | G34: Customer Care Team 34969 | H34: Core Business Application | I34: N | J34: Yes | K34: VB.NET | M34: N | N34: 1.2120833 | O34: 0.20833333 | P34: 0 | Q34: 1.4204167 | R34: 0.63596363 | S34: 0.71020833 | T34: 0.71020833 | U34: 1 | AA34: =N34 -> 1.2120833 | AB34: =O34 -> 0.20833333 | AC34: =P34 -> 0 | AD34: =Q34 -> 1.4204167 | AE34: =R34 -> 0.63596363 | AF34: =Q34*R34 -> 0.90333333 | AG34: B
A35: 31 | B35: 9844 | C35: C04VAS-JPN | D35: Voucher Approval System for AS400 | E35: Corporate Related | F35: Core Insurance Systems Group 34956 | G35: Corporate Systems Team 34959 | H35: Core Business Application | I35: Y | J35: Yes | K35: VB.NET | M35: N | N35: 0.67083333 | O35: 0.68333333 | P35: 0 | Q35: 1.3541667 | R35: 0.36923077 | S35: 0.67708333 | T35: 0.67708333 | U35: 1 | AA35: =N35 -> 0.67083333 | AB35: =O35 -> 0.68333333 | AC35: =P35 -> 0 | AD35: =Q35 -> 1.3541667 | AE35: =R35 -> 0.36923077 | AF35: =Q35*R35 -> 0.5 | AG35: B
A36: 32 | B36: 9845 | C36: C04SYM-JPN | D36: Renewal symap Business Work Flow | E36: New Contract Related | F36: Customer Service and Operations Systems Group 34965 | G36: New Business Team 34966 | H36: Core Business Application | I36: N | J36: Yes | K36: VB.NET | M36: N | N36: 3.4049167 | O36: 0 | P36: 0 | Q36: 3.4049167 | R36: 0.84091632 | S36: 1.7024583 | T36: 1.7024583 | U36: 1 | AA36: =N36 -> 3.4049167 | AB36: =O36 -> 0 | AC36: =P36 -> 0 | AD36: =Q36 -> 3.4049167 | AE36: =R36 -> 0.84091632 | AF36: =Q36*R36 -> 2.86325 | AG36: B
... A40: 36 | B40: 9849 | C40: C04OSI-JPN | D40: S Sum Total System(Open) | E40: New Contract Related | F40: Customer Service and Operations Systems Group 34965 | G40: New Business Team 34966 | H40: Common Service Business Application | I40: N | J40: Yes | K40: JAVA | M40: N | N40: 5.18625 | O40: 0.38333333 | P40: 0 | Q40: 5.5695833 | R40: 0.8315254 | S40: 2.7847917 | T40: 2.7847917 | U40: 1 | AA40: =N40 -> 5.18625 | AB40: =O40 -> 0.38333333 | AC40: =P40 -> 0 | AD40: =Q40 -> 5.5695833 | AE40: =R40 -> 0.8315254 | AF40: =Q40*R40 -> 4.63125 | AG40: B
A41: 37 | B41: 9851 | C41: W03FIC-JPN | D41: Guidance Refusal Information Administration System | E41: Corporate Related | F41: Core Insurance Systems Group 34956 | G41: Corporate Systems Team 34959 | H41: Core Business Application | I41: N | J41: Yes | K41: JAVA | L41: Platform as a Service (PaaS) | M41: N | N41: 0.29166667 | O41: 0.11666667 | P41: 0 | Q41: 0.40833333 | R41: 0.82653061 | S41: 0.20416667 | T41: 0.20416667 | U41: 1 | AA41: =N41 -> 0.29166667 | AB41: =O41 -> 0.11666667 | AC41: =P41 -> 0 | AD41: =Q41 -> 0.40833333 | AE41: =R41 -> 0.82653061 | AF41: =Q41*R41 -> 0.3375 | AG41: B
A42: 38 | B42: 9852 | C42: C03APO-JPN | D42: Apollocs | E42: Corporate Related | F42: Core Insurance Systems Group 34956 | G42: Corporate Systems Team 34959 | H42: Core Business Application | I42: N | J42: Yes | K42: Other#APOLLOCS | M42: N | N42: 0.50833333 | O42: 0 | P42: 0 | Q42: 0.50833333 | R42: 0.36885246 | S42: 0.25416667 | T42: 0.25416667 | U42: 1 | AA42: =N42 -> 0.50833333 | AB42: =O42 -> 0 | AC42: =P42 -> 0 | AD42: =Q42 -> 0.50833333 | AE42: =R42 -> 0.36885246 | AF42: =Q42*R42 -> 0.1875 | AG42: B
A43: 39 | B43: 9854 | C43: Z04IMA-JPN | D43: Image Search | E43: New Contract Related | F43: Customer Service and Operations Systems Group 34965 | G43: New Business Team 34966 | H43: Core Business Application | I43: N | J43: Yes | K43: CSS; JAVA;HTML; VB.NET | M43: N | N43: 1.4004167 | O43: 0 | P43: 0 | Q43: 1.4004167 | R43: 0.92859268 | S43: 0.70020833 | T43: 0.70020833 | U43: 1 | AA43: =N43 -> 1.4004167 | AB43: =O43 -> 0 | AC43: =P43 -> 0 | AD43: =Q43 -> 1.4004167 | AE43: =R43 -> 0.92859268 | AF43: =Q43*R43 -> 1.3004167 | AG43: B
A44: 40 | B44: 9857 | C44: W05AMS-JPN | D44: Annuity Information Management System(AIMS) | E44: Insurance Claims and Benefits Payment Related | F44: Customer Service and Operations Systems Group 34965 | G44: Claims Team 34968 | H44: Core Business Application | I44: Y | J44: Yes | K44: JAVA | M44: N | N44: 20.211667 | O44: 1.8166667 | P44: 0 | Q44: 22.028333 | R44: 0.92547477 | S44: 11.014167 | T44: 11.014167 | U44: 1 | AA44: =N44 -> 20.211667 | AB44: =O44 -> 1.8166667 | AC44: =P44 -> 0 | AD44: =Q44 -> 22.028333 | AE44: =R44 -> 0.92547477 | AF44: =Q44*R44 -> 20.386667 | AG44: B
...

Sheet Value Streams
A1: Data Infrastructure — two value streams
A2: Informatica is the sunset platform; Azure Synapse is go-forward. The modernisation path between them is OUT OF SCOPE of this RFP.
B4: Code | C4: Value stream | D4: Apps | E4: Effort | F4: AD effort | G4: Run effort | H4: AD share | I4: Y1 co-src pods | J4: Y1 full-src pods | K4: Archetype
B5: VS1 | C5: Informatica — ETL, IDQ, Address Doctor & HOST/AS400 data cooperation | D5: =SUMIFS(Inventory!$U:$U,Inventory!$AH:$AH,$B5) -> 2 | E5: =SUMIFS(Inventory!$AD:$AD,Inventory!$AH:$AH,$B5) -> 50.699958 | F5: =SUMIFS(Inventory!$AF:$AF,Inventory!$AH:$AH,$B5) -> 43.938708 | G5: =E5-F5 -> 6.76125 | H5: =IF(E5=0,0,F5/E5) -> 0.8666419 | I5: =SUMIFS('Pod Plan'!$E:$E,'Pod Plan'!$B:$B,1,'Pod Plan'!$C:$C,$B5) -> 4 | J5: =SUMIFS('Pod Plan'!$F:$F,'Pod Plan'!$B:$B,1,'Pod Plan'!$C:$C,$B5) -> 1 | K5: C
B6: VS2 | C6: Azure Synapse — Japan Data Platform & BI/reporting | D6: =SUMIFS(Inventory!$U:$U,Inventory!$AH:$AH,$B6) -> 1 | E6: =SUMIFS(Inventory!$AD:$AD,Inventory!$AH:$AH,$B6) -> 50.06501 | F6: =SUMIFS(Inventory!$AF:$AF,Inventory!$AH:$AH,$B6) -> 43.188135 | G6: =E6-F6 -> 6.876875 | H6: =IF(E6=0,0,F6/E6) -> 0.8626411 | I6: =SUMIFS('Pod Plan'!$E:$E,'Pod Plan'!$B:$B,1,'Pod Plan'!$C:$C,$B6) -> 2 | J6: =SUMIFS('Pod Plan'!$F:$F,'Pod Plan'!$B:$B,1,'Pod Plan'!$C:$C,$B6) -> 2 | K6: B
C7: Total | D7: =SUM(D5:D6) -> 3 | E7: =SUM(E5:E6) -> 100.76497 | F7: =SUM(F5:F6) -> 87.126844 | G7: =SUM(G5:G6) -> 13.638125 | H7: =IF(E7=0,0,F7/E7) -> 0.8646541 | I7: =SUM(I5:I6) -> 6 | J7: =SUM(J5:J6) -> 3
B9: Value stream | C9: Applications and what they are
B10: VS1 | C10: BCMETL-JPN Informatica Platform (42.8u) — common ETL, IDQ and Address Doctor. · BCMHRP-JPN Data cooperation (7.9u) — batch integration between the open estate and HOST/AS400.
B11: VS2 | C11: JDPREP Japan Data Platform and Reporting (50.1u) — Azure PaaS data platform and BI/reporting, Transact-SQL.
B13: Note | C13: Both Informatica applications carry Priority Transfer Targets = Y, so the portfolio bedrock classifies them archetype C and routes engineering to MGCC. Because the platform is being retired, transferring it builds a capability MetLife will not keep. Recommendation on Glidepath & 50-50.

Sheet Pod Library
A1: Pod library — every seat, by year, value stream and pod type
A2: INPUT. Pod sizes are deliberately NOT a uniform ladder: Synapse 9→7→6, Informatica 8→7→6. Counts may be fractional where a MetLife role is shared across two pods.
B4: Year | C4: VS | D4: Pod type | E4: Seat | F4: Role | G4: Skill | H4: Exp | I4: Location | J4: Sourcing | K4: Count
B5: 1 | C5: VS1 | D5: CO | E5: 1 | F5: Product Owner — Informatica Data Platform | G5: LEAD | H5: E4 | I5: ON | J5: FTE | K5: 1
B6: 1 | C6: VS1 | D6: CO | E6: 2 | F6: Data Domain SME | G6: BA | H6: E4 | I6: ON | J6: FTE | K6: 1
B7: 1 | C7: VS1 | D7: CO | E7: 3 | F7: Informatica Lead Engineer | G7: ENG | H7: E3 | I7: OFF | J7: FTC | K7: 1
B8: 1 | C8: VS1 | D8: CO | E8: 4 | F8: Data Modeler | G8: DEV | H8: E3 | I8: OFF | J8: MGCC | K8: 1
B9: 1 | C9: VS1 | D9: CO | E9: 5 | F9: Pod Delivery Lead (Informatica Tech Lead) | G9: LEAD | H9: E4 | I9: ON | J9: FTC | K9: 1
B10: 1 | C10: VS1 | D10: CO | E10: 6 | F10: Senior Informatica Developer | G10: DEV | H10: E3 | I10: ON | J10: FTC | K10: 1
B11: 1 | C11: VS1 | D11: CO | E11: 7 | F11: Informatica Developer | G11: DEV | H11: E2 | I11: OFF | J11: FTC | K11: 1
B12: 1 | C12: VS1 | D12: CO | E12: 8 | F12: Data Tester | G12: TEST | H12: E2 | I12: OFF | J12: FTC | K12: 1
F13: Pod size — Y1 VS1 co-sourced | K13: =SUM(K5:K12) -> 8
B15: 1 | C15: VS1 | D15: FS | E15: 1 | F15: Product Owner- Data Platform | G15: LEAD | H15: E4 | I15: ON | J15: FTE | K15: 1
B16: 1 | C16: VS1 | D16: FS | E16: 2 | F16: Pod Delivery Lead (Informatica Tech Lead) | G16: LEAD | H16: E4 | I16: ON | J16: FTC | K16: 1
B17: 1 | C17: VS1 | D17: FS | E17: 3 | F17: Data Modeler | G17: ENG | H17: E4 | I17: ON | J17: FTC | K17: 1
B18: 1 | C18: VS1 | D18: FS | E18: 4 | F18: Business Analyst (bilingual) | G18: BA | H18: E3 | I18: ON | J18: FTC | K18: 1
B19: 1 | C19: VS1 | D19: FS | E19: 5 | F19: Senior Informatica Developer | G19: DEV | H19: E3 | I19: OFF | J19: FTC | K19: 1
B20: 1 | C20: VS1 | D20: FS | E20: 6 | F20: Informatica Developer | G20: DEV | H20: E2 | I20: OFF | J20: FTC | K20: 2
B21: 1 | C21: VS1 | D21: FS | E21: 7 | F21: Data Tester | G21: TEST | H21: E2 | I21: OFF | J21: FTC | K21: 1
B22: 1 | C22: VS1 | D22: FS | E22: 8 | F22: L2 Data Support | G22: OPS | H22: E2 | I22: OFF | J22: FTC | K22: 0
F23: Pod size — Y1 VS1 fully-sourced | K23: =SUM(K15:K22) -> 8
B25: 1 | C25: VS2 | D25: CO | E25: 1 | F25: Product Owner- Data Platform | G25: LEAD | H25: E4 | I25: ON | J25: FTE | K25: 1
B26: 1 | C26: VS2 | D26: CO | E26: 2 | F26: Azure Data Architect (MetLife) | G26: ENG | H26: E5 | I26: ON | J26: FTE | K26: 1
B27: 1 | C27: VS2 | D27: CO | E27: 3 | F27: BI / Reporting Engineer | G27: DEV | H27: E3 | I27: OFF | J27: FTC | K27: 1
B28: 1 | C28: VS2 | D28: CO | E28: 4 | F28: Synapse Platform Engineer | G28: ENG | H28: E4 | I28: OFF | J28: MGCC | K28: 1
B29: 1 | C29: VS2 | D29: CO | E29: 5 | F29: Azure Data Engineer | G29: DEV | H29: E3 | I29: OFF | J29: MGCC | K29: 1
B30: 1 | C30: VS2 | D30: CO | E30: 6 | F30: Pod Delivery Lead ( Azure Data Engineering) | G30: LEAD | H30: E4 | I30: ON | J30: FTC | K30: 1
B31: 1 | C31: VS2 | D31: CO | E31: 7 | F31: Senior Azure Data Engineer | G31: DEV | H31: E3 | I31: ON | J31: MGCC | K31: 1
B32: 1 | C32: VS2 | D32: CO | E32: 8 | F32: Azure Data Engineer | G32: DEV | H32: E2 | I32: OFF | J32: FTC | K32: 1
B33: 1 | C33: VS2 | D33: CO | E33: 9 | F33: Data Tester | G33: TEST | H33: E2 | I33: OFF | J33: FTC | K33: 1
F34: Pod size — Y1 VS2 co-sourced | K34: =SUM(K25:K33) -> 9
B36: 1 | C36: VS2 | D36: FS | E36: 1 | F36: Product Owner- Data Platform (shared 0.5) | G36: LEAD | H36: E4 | I36: ON | J36: FTE | K36: 0.5
B37: 1 | C37: VS2 | D37: FS | E37: 2 | F37: Azure Data Architect (MetLife)- shared | G37: ENG | H37: E5 | I37: ON | J37: FTE | K37: 0.5
B38: 1 | C38: VS2 | D38: FS | E38: 3 | F38: Pod Delivery Lead ( Azure Data Engineering) | G38: LEAD | H38: E4 | I38: ON | J38: FTC | K38: 1
B39: 1 | C39: VS2 | D39: FS | E39: 4 | F39: Data Modeler | G39: ENG | H39: E4 | I39: OFF | J39: FTC | K39: 1
B40: 1 | C40: VS2 | D40: FS | E40: 5 | F40: Business Analyst (bilingual) | G40: BA | H40: E3 | I40: ON | J40: FTC | K40: 1
B41: 1 | C41: VS2 | D41: FS | E41: 6 | F41: Senior Azure Data Engineer | G41: DEV | H41: E3 | I41: OFF | J41: FTC | K41: 1
B42: 1 | C42: VS2 | D42: FS | E42: 7 | F42: Azure Data Engineer | G42: DEV | H42: E2 | I42: OFF | J42: FTC | K42: 2
B43: 1 | C43: VS2 | D43: FS | E43: 8 | F43: BI / Reporting Engineer | G43: DEV | H43: E3 | I43: OFF | J43: FTC | K43: 1
B44: 1 | C44: VS2 | D44: FS | E44: 9 | F44: Data Tester | G44: TEST | H44: E2 | I44: OFF | J44: FTC | K44: 1
...

Sheet Pod Plan
A1: Pod plan — pods per value stream per year
A2: INPUT. Fewer pods and smaller pods is how productivity shows up in the headcount.
B4: Year | C4: VS | D4: Value stream | E4: Co-sourced pods | F4: Fully-sourced pods | G4: Pods | H4: People
B5: 1 | C5: VS1 | D5: Informatica — ETL, IDQ, Address Doctor & HOST/AS400 data cooperation | E5: 4 | F5: 1 | G5: =E5+F5 -> 5 | H5: =E5*SUMIFS('Pod Library'!$K:$K,'Pod Library'!$B:$B,$B5,'Pod Library'!$C:$C,$C5,'Pod Library'!$D:$D,"CO")+F5*SUMIFS('Pod Library'!$K:$K,'Pod Library'!$B:$B,$B5,'Pod Library'!$C:$C,$C5,'Pod Library'!$D:$D,"FS") -> 40
B6: 1 | C6: VS2 | D6: Azure Synapse — Japan Data Platform & BI/reporting | E6: 2 | F6: 2 | G6: =E6+F6 -> 4 | H6: =E6*SUMIFS('Pod Library'!$K:$K,'Pod Library'!$B:$B,$B6,'Pod Library'!$C:$C,$C6,'Pod Library'!$D:$D,"CO")+F6*SUMIFS('Pod Library'!$K:$K,'Pod Library'!$B:$B,$B6,'Pod Library'!$C:$C,$C6,'Pod Library'!$D:$D,"FS") -> 36
D7: Year 1 total | E7: =SUM(E5:E6) -> 6 | F7: =SUM(F5:F6) -> 3 | G7: =SUM(G5:G6) -> 9 | H7: =SUM(H5:H6) -> 76
B9: 2 | C9: VS1 | D9: Informatica — ETL, IDQ, Address Doctor & HOST/AS400 data cooperation | E9: 2 | F9: 1 | G9: =E9+F9 -> 3 | H9: =E9*SUMIFS('Pod Library'!$K:$K,'Pod Library'!$B:$B,$B9,'Pod Library'!$C:$C,$C9,'Pod Library'!$D:$D,"CO")+F9*SUMIFS('Pod Library'!$K:$K,'Pod Library'!$B:$B,$B9,'Pod Library'!$C:$C,$C9,'Pod Library'!$D:$D,"FS") -> 21
B10: 2 | C10: VS2 | D10: Azure Synapse — Japan Data Platform & BI/reporting | E10: 3 | F10: 2 | G10: =E10+F10 -> 5 | H10: =E10*SUMIFS('Pod Library'!$K:$K,'Pod Library'!$B:$B,$B10,'Pod Library'!$C:$C,$C10,'Pod Library'!$D:$D,"CO")+F10*SUMIFS('Pod Library'!$K:$K,'Pod Library'!$B:$B,$B10,'Pod Library'!$C:$C,$C10,'Pod Library'!$D:$D,"FS") -> 37
D11: Year 2 total | E11: =SUM(E9:E10) -> 5 | F11: =SUM(F9:F10) -> 3 | G11: =SUM(G9:G10) -> 8 | H11: =SUM(H9:H10) -> 58
B13: 3 | C13: VS1 | D13: Informatica — ETL, IDQ, Address Doctor & HOST/AS400 data cooperation | E13: 0 | F13: 0 | G13: =E13+F13 -> 0 | H13: =E13*SUMIFS('Pod Library'!$K:$K,'Pod Library'!$B:$B,$B13,'Pod Library'!$C:$C,$C13,'Pod Library'!$D:$D,"CO")+F13*SUMIFS('Pod Library'!$K:$K,'Pod Library'!$B:$B,$B13,'Pod Library'!$C:$C,$C13,'Pod Library'!$D:$D,"FS") -> 0 | I13: All Informatica Workloads modernized
B14: 3 | C14: VS2 | D14: Azure Synapse — Japan Data Platform & BI/reporting | E14: 4 | F14: 2 | G14: =E14+F14 -> 6 | H14: =E14*SUMIFS('Pod Library'!$K:$K,'Pod Library'!$B:$B,$B14,'Pod Library'!$C:$C,$C14,'Pod Library'!$D:$D,"CO")+F14*SUMIFS('Pod Library'!$K:$K,'Pod Library'!$B:$B,$B14,'Pod Library'!$C:$C,$C14,'Pod Library'!$D:$D,"FS") -> 42
D15: Year 3 total | E15: =SUM(E13:E14) -> 4 | F15: =SUM(F13:F14) -> 2 | G15: =SUM(G13:G14) -> 6 | H15: =SUM(H13:H14) -> 42

Sheet Horizontal Teams
A1: Horizontal teams — work that is not value-stream bounded
A2: INPUT. As pods consolidate, MetLife seats displaced from them land here — governance and platform operations do not shrink with delivery volume.
B4: Year | C4: Team | D4: Team name | E4: Role | F4: Skill | G4: Exp | H4: Location | I4: Sourcing | J4: Count
B5: 1 | C5: H1 | D5: Platform Operations & Data Reliability | E5: Service Delivery Lead | F5: LEAD | G5: E4 | H5: ON | I5: FTC | J5: 1
B6: 1 | C6: H1 | D6: Platform Operations & Data Reliability | E6: MetLife Data Infrastructure Domain Lead | F6: OPS | G6: E4 | H6: ON | I6: FTE | J6: 1
B7: 1 | C7: H1 | D7: Platform Operations & Data Reliability | E7: L2 Support Data Engr Lead | F7: OPS | G7: E2 | H7: ON | I7: FTC | J7: 1
B8: 1 | C8: H1 | D8: Platform Operations & Data Reliability | E8: L2 Support Data Engr-Informatica and Azure | F8: OPS | G8: E2 | H8: OFF | I8: FTC | J8: 3
B9: 1 | C9: H1 | D9: Platform Operations & Data Reliability | E9: Data Platform SRE | F9: ENG | G9: E3 | H9: OFF | I9: MGCC | J9: 6
E10: H1 total | J10: =SUM(J5:J9) -> 12
B11: 1 | C11: H2 | D11: Data Quality, Test & Environments | E11: Head of Data Platform Testing (MetLife) | F11: LEAD | G11: E5 | H11: ON | I11: FTE | J11: 1
B12: 1 | C12: H2 | D12: Data Quality, Test & Environments | E12: Data Platform Test Lead | F12: TEST | G12: E4 | H12: ON | I12: FTC | J12: 1
B13: 1 | C13: H2 | D13: Data Quality, Test & Environments | E13: Penetration and Data Security Testers | F13: TEST | G13: E2 | H13: OFF | I13: FTC | J13: 2
B14: 1 | C14: H2 | D14: Data Quality, Test & Environments | E14: Stress and Performance Testers | F14: TEST | G14: E2 | H14: OFF | I14: FTC | J14: 2
E15: H2 total | J15: =SUM(J11:J14) -> 6
B16: 1 | C16: H3 | D16: Architecture, Release Train & Governance | E16: Data Domain Delivery Head | F16: LEAD | G16: E5 | H16: ON | I16: FTC | J16: 1
B17: 1 | C17: H3 | D17: Architecture, Release Train & Governance | E17: Chief Data Architect (MetLife) | F17: ENG | G17: E5 | H17: ON | I17: FTE | J17: 1
B18: 1 | C18: H3 | D18: Architecture, Release Train & Governance | E18: DevOps Lead | F18: LEAD | G18: E3 | H18: ON | I18: FTC | J18: 1
B19: 1 | C19: H3 | D19: Architecture, Release Train & Governance | E19: Transition & Substrate Lead | F19: ENG | G19: E5 | H19: ON | I19: FTC | J19: 1
B20: 1 | C20: H3 | D20: Architecture, Release Train & Governance | E20: Business Analyst (MetLife) | F20: BA | G20: E4 | H20: ON | I20: FTE | J20: 2
E21: H3 total | J21: =SUM(J16:J20) -> 6
E22: Year 1 horizontal total | J22: =SUMIFS($J$5:$J$21,$B$5:$B$21,1) -> 24
B24: 2 | C24: H1 | D24: Platform Operations & Data Reliability | E24: Service Delivery Lead | F24: LEAD | G24: E4 | H24: ON | I24: FTC | J24: 1
B25: 2 | C25: H1 | D25: Platform Operations & Data Reliability | E25: MetLife Data Infrastructure Domain Lead | F25: OPS | G25: E4 | H25: ON | I25: FTE | J25: 1
B26: 2 | C26: H1 | D26: Platform Operations & Data Reliability | E26: MetLife Platform Operations Engineers | F26: OPS | G26: E3 | H26: ON | I26: FTE | J26: 1
B27: 2 | C27: H1 | D27: Platform Operations & Data Reliability | E27: Data Platform SRE | F27: ENG | G27: E3 | H27: OFF | I27: MGCC | J27: 3
B28: 2 | C28: H1 | D28: Platform Operations & Data Reliability | E28: L2 Support Data Engr-Informatica | F28: ENG | G28: E3 | H28: OFF | I28: FTC | J28: 2
B29: 2 | C29: H1 | D29: Platform Operations & Data Reliability | E29: L2 Support Data Engr-Azure | F29: ENG | G29: E2 | H29: OFF | I29: FTC | J29: 2
E30: H1 total | J30: =SUM(J24:J29) -> 10
B31: 2 | C31: H2 | D31: Data Quality, Test & Environments | E31: Head of Data Platform Testing (MetLife) | F31: LEAD | G31: E5 | H31: ON | I31: FTE | J31: 1
B32: 2 | C32: H2 | D32: Data Quality, Test & Environments | E32: MetLife Data Reconciliation and Quality Tester | F32: TEST | G32: E3 | H32: ON | I32: FTE | J32: 1
B33: 2 | C33: H2 | D33: Data Quality, Test & Environments | E33: AI Test Automation Engineer | F33: TEST | G33: E3 | H33: OFF | I33: MGCC | J33: 3
B34: 2 | C34: H2 | D34: Data Quality, Test & Environments | E34: Data Platform Test Lead | F34: TEST | G34: E4 | H34: ON | I34: FTC | J34: 1
E35: H2 total | J35: =SUM(J31:J34) -> 6
B36: 2 | C36: H3 | D36: Architecture, Release Train & Governance | E36: Data Domain Delivery Head | F36: LEAD | G36: E5 | H36: ON | I36: FTC | J36: 1
B37: 2 | C37: H3 | D37: Architecture, Release Train & Governance | E37: Chief Data Architect (MetLife) | F37: ENG | G37: E5 | H37: ON | I37: FTE | J37: 1
B38: 2 | C38: H3 | D38: Architecture, Release Train & Governance | E38: DevOps Lead | F38: LEAD | G38: E3 | H38: ON | I38: FTC | J38: 1
B39: 2 | C39: H3 | D39: Architecture, Release Train & Governance | E39: AI Enablement Lead | F39: ENG | G39: E4 | H39: ON | I39: FTC | J39: 1
B40: 2 | C40: H3 | D40: Architecture, Release Train & Governance | E40: Business Analyst (MetLife) | F40: BA | G40: E4 | H40: ON | I40: FTE | J40: 1
E41: H3 total | J41: =SUM(J36:J40) -> 5
E42: Year 2 horizontal total | J42: =SUMIFS($J$24:$J$41,$B$24:$B$41,2) -> 21
...

Sheet Team Build-Up
A1: Team build-up — everything derived from the seat ledger
A2: Nothing on this sheet is typed.
A4: A. POD SIZES (read from the Pod Library)
B5: Pod size | C5: VS1 co | D5: VS1 full | E5: VS2 co | F5: VS2 full
B6: Year 1 | C6: =SUMIFS('Pod Library'!$K:$K,'Pod Library'!$B:$B,1,'Pod Library'!$C:$C,"VS1",'Pod Library'!$D:$D,"CO") -> 8 | D6: =SUMIFS('Pod Library'!$K:$K,'Pod Library'!$B:$B,1,'Pod Library'!$C:$C,"VS1",'Pod Library'!$D:$D,"FS") -> 8 | E6: =SUMIFS('Pod Library'!$K:$K,'Pod Library'!$B:$B,1,'Pod Library'!$C:$C,"VS2",'Pod Library'!$D:$D,"CO") -> 9 | F6: =SUMIFS('Pod Library'!$K:$K,'Pod Library'!$B:$B,1,'Pod Library'!$C:$C,"VS2",'Pod Library'!$D:$D,"FS") -> 9
B7: Year 2 | C7: =SUMIFS('Pod Library'!$K:$K,'Pod Library'!$B:$B,2,'Pod Library'!$C:$C,"VS1",'Pod Library'!$D:$D,"CO") -> 7 | D7: =SUMIFS('Pod Library'!$K:$K,'Pod Library'!$B:$B,2,'Pod Library'!$C:$C,"VS1",'Pod Library'!$D:$D,"FS") -> 7 | E7: =SUMIFS('Pod Library'!$K:$K,'Pod Library'!$B:$B,2,'Pod Library'!$C:$C,"VS2",'Pod Library'!$D:$D,"CO") -> 7 | F7: =SUMIFS('Pod Library'!$K:$K,'Pod Library'!$B:$B,2,'Pod Library'!$C:$C,"VS2",'Pod Library'!$D:$D,"FS") -> 8
B8: Year 3 | C8: =SUMIFS('Pod Library'!$K:$K,'Pod Library'!$B:$B,3,'Pod Library'!$C:$C,"VS1",'Pod Library'!$D:$D,"CO") -> 0 | D8: =SUMIFS('Pod Library'!$K:$K,'Pod Library'!$B:$B,3,'Pod Library'!$C:$C,"VS1",'Pod Library'!$D:$D,"FS") -> 0 | E8: =SUMIFS('Pod Library'!$K:$K,'Pod Library'!$B:$B,3,'Pod Library'!$C:$C,"VS2",'Pod Library'!$D:$D,"CO") -> 7 | F8: =SUMIFS('Pod Library'!$K:$K,'Pod Library'!$B:$B,3,'Pod Library'!$C:$C,"VS2",'Pod Library'!$D:$D,"FS") -> 7
A10: B. HEADCOUNT
B11: Measure | C11: Year 1 | D11: Year 2 | E11: Year 3
B12: People in value-stream pods | C12: =SUMIFS('Seat Ledger'!$L$5:$L$138,'Seat Ledger'!$A$5:$A$138,1,'Seat Ledger'!$B$5:$B$138,"POD") -> 76 | D12: =SUMIFS('Seat Ledger'!$L$5:$L$138,'Seat Ledger'!$A$5:$A$138,2,'Seat Ledger'!$B$5:$B$138,"POD") -> 58 | E12: =SUMIFS('Seat Ledger'!$L$5:$L$138,'Seat Ledger'!$A$5:$A$138,3,'Seat Ledger'!$B$5:$B$138,"POD") -> 42
B13: People in horizontal teams | C13: =SUMIFS('Seat Ledger'!$L$5:$L$138,'Seat Ledger'!$A$5:$A$138,1,'Seat Ledger'!$B$5:$B$138,"HZ") -> 24 | D13: =SUMIFS('Seat Ledger'!$L$5:$L$138,'Seat Ledger'!$A$5:$A$138,2,'Seat Ledger'!$B$5:$B$138,"HZ") -> 21 | E13: =SUMIFS('Seat Ledger'!$L$5:$L$138,'Seat Ledger'!$A$5:$A$138,3,'Seat Ledger'!$B$5:$B$138,"HZ") -> 21
B14: TOTAL PEOPLE | C14: =C12+C13 -> 100 | D14: =D12+D13 -> 79 | E14: =E12+E13 -> 63
B15: Number of pods | C15: =SUMIFS('Pod Plan'!$G:$G,'Pod Plan'!$B:$B,1) -> 9 | D15: =SUMIFS('Pod Plan'!$G:$G,'Pod Plan'!$B:$B,2) -> 8 | E15: =SUMIFS('Pod Plan'!$G:$G,'Pod Plan'!$B:$B,3) -> 6
B16: Average pod size | C16: =IF(C15=0,0,C12/C15) -> 8.4444444 | D16: =IF(D15=0,0,D12/D15) -> 7.25 | E16: =IF(E15=0,0,E12/E15) -> 7
A18: C. SOURCING — MetLife FTE and MGCC are more or less held stable at their current level in every year
B19: Measure | C19: Year 1 | D19: Year 2 | E19: Year 3 | G19: Appendix 3 today
B20: Capgemini (FTC) | C20: =SUMIFS('Seat Ledger'!$L$5:$L$138,'Seat Ledger'!$A$5:$A$138,1,'Seat Ledger'!$I$5:$I$138,"FTC") -> 64 | D20: =SUMIFS('Seat Ledger'!$L$5:$L$138,'Seat Ledger'!$A$5:$A$138,2,'Seat Ledger'!$I$5:$I$138,"FTC") -> 44 | E20: =SUMIFS('Seat Ledger'!$L$5:$L$138,'Seat Ledger'!$A$5:$A$138,3,'Seat Ledger'!$I$5:$I$138,"FTC") -> 28 | G20: 64.7 | H20: Y1
B21: MetLife Japan (FTE) | C21: =SUMIFS('Seat Ledger'!$L$5:$L$138,'Seat Ledger'!$A$5:$A$138,1,'Seat Ledger'!$I$5:$I$138,"FTE") -> 20 | D21: =SUMIFS('Seat Ledger'!$L$5:$L$138,'Seat Ledger'!$A$5:$A$138,2,'Seat Ledger'!$I$5:$I$138,"FTE") -> 19 | E21: =SUMIFS('Seat Ledger'!$L$5:$L$138,'Seat Ledger'!$A$5:$A$138,3,'Seat Ledger'!$I$5:$I$138,"FTE") -> 17 | G21: 18.82 | H21: Y1
B22: MetLife MGCC | C22: =SUMIFS('Seat Ledger'!$L$5:$L$138,'Seat Ledger'!$A$5:$A$138,1,'Seat Ledger'!$I$5:$I$138,"MGCC") -> 16 | D22: =SUMIFS('Seat Ledger'!$L$5:$L$138,'Seat Ledger'!$A$5:$A$138,2,'Seat Ledger'!$I$5:$I$138,"MGCC") -> 16 | E22: =SUMIFS('Seat Ledger'!$L$5:$L$138,'Seat Ledger'!$A$5:$A$138,3,'Seat Ledger'!$I$5:$I$138,"MGCC") -> 18 | G22: 15.99 | H22: Y1
B23: Check — sums to total | C23: =C20+C21+C22-C14 -> 0 | D23: =D20+D21+D22-D14 -> 0 | E23: =E20+E21+E22-E14 -> 0
A25: D. LOCATION
B26: Measure | C26: Year 1 | D26: Year 2 | E26: Year 3
B27: Onshore Tokyo | C27: =SUMIFS('Seat Ledger'!$L$5:$L$138,'Seat Ledger'!$A$5:$A$138,1,'Seat Ledger'!$H$5:$H$138,"ON") -> 45 | D27: =SUMIFS('Seat Ledger'!$L$5:$L$138,'Seat Ledger'!$A$5:$A$138,2,'Seat Ledger'!$H$5:$H$138,"ON") -> 35 | E27: =SUMIFS('Seat Ledger'!$L$5:$L$138,'Seat Ledger'!$A$5:$A$138,3,'Seat Ledger'!$H$5:$H$138,"ON") -> 27
B28: Offshore Hyderabad | C28: =SUMIFS('Seat Ledger'!$L$5:$L$138,'Seat Ledger'!$A$5:$A$138,1,'Seat Ledger'!$H$5:$H$138,"OFF") -> 55 | D28: =SUMIFS('Seat Ledger'!$L$5:$L$138,'Seat Ledger'!$A$5:$A$138,2,'Seat Ledger'!$H$5:$H$138,"OFF") -> 44 | E28: =SUMIFS('Seat Ledger'!$L$5:$L$138,'Seat Ledger'!$A$5:$A$138,3,'Seat Ledger'!$H$5:$H$138,"OFF") -> 36
B29: Whole-team offshore share | C29: =IF(C14=0,0,C28/C14) -> 0.55 | D29: =IF(D14=0,0,D28/D14) -> 0.55696203 | E29: =IF(E14=0,0,E28/E14) -> 0.57142857
B30: Capgemini offshore share (what the ceiling governs) | C30: =IF(C20=0,0,SUMIFS('Seat Ledger'!$L$5:$L$138,'Seat Ledger'!$A$5:$A$138,1,'Seat Ledger'!$H$5:$H$138,"OFF",'Seat Ledger'!$I$5:$I$138,"FTC")/C20) -> 0.640625 | D30: =IF(D20=0,0,SUMIFS('Seat Ledger'!$L$5:$L$138,'Seat Ledger'!$A$5:$A$138,2,'Seat Ledger'!$H$5:$H$138,"OFF",'Seat Ledger'!$I$5:$I$138,"FTC")/D20) -> 0.63636364 | E30: =IF(E20=0,0,SUMIFS('Seat Ledger'!$L$5:$L$138,'Seat Ledger'!$A$5:$A$138,3,'Seat Ledger'!$H$5:$H$138,"OFF",'Seat Ledger'!$I$5:$I$138,"FTC")/E20) -> 0.64285714
A32: E. EXPERIENCE MIX — counted from named seats
B33: Experience band | C33: Year 1 | D33: Year 2 | E33: Year 3 | G33: Y1 % | H33: Y2 % | I33: Y3 %
B34: E1 Associate 0-3 years | C34: =SUMIFS('Seat Ledger'!$L$5:$L$138,'Seat Ledger'!$A$5:$A$138,1,'Seat Ledger'!$G$5:$G$138,"E1") -> 0 | D34: =SUMIFS('Seat Ledger'!$L$5:$L$138,'Seat Ledger'!$A$5:$A$138,2,'Seat Ledger'!$G$5:$G$138,"E1") -> 0 | E34: =SUMIFS('Seat Ledger'!$L$5:$L$138,'Seat Ledger'!$A$5:$A$138,3,'Seat Ledger'!$G$5:$G$138,"E1") -> 0 | G34: =IF(C$14=0,0,C34/C$14) -> 0 | H34: =IF(D$14=0,0,D34/D$14) -> 0 | I34: =IF(E$14=0,0,E34/E$14) -> 0
B35: E2 Engineer 3-6 years | C35: =SUMIFS('Seat Ledger'!$L$5:$L$138,'Seat Ledger'!$A$5:$A$138,1,'Seat Ledger'!$G$5:$G$138,"E2") -> 29 | D35: =SUMIFS('Seat Ledger'!$L$5:$L$138,'Seat Ledger'!$A$5:$A$138,2,'Seat Ledger'!$G$5:$G$138,"E2") -> 2 | E35: =SUMIFS('Seat Ledger'!$L$5:$L$138,'Seat Ledger'!$A$5:$A$138,3,'Seat Ledger'!$G$5:$G$138,"E2") -> 6 | G35: =IF(C$14=0,0,C35/C$14) -> 0.29 | H35: =IF(D$14=0,0,D35/D$14) -> 0.025316456 | I35: =IF(E$14=0,0,E35/E$14) -> 0.095238095
B36: E3 Senior 6-10 years | C36: =SUMIFS('Seat Ledger'!$L$5:$L$138,'Seat Ledger'!$A$5:$A$138,1,'Seat Ledger'!$G$5:$G$138,"E3") -> 33 | D36: =SUMIFS('Seat Ledger'!$L$5:$L$138,'Seat Ledger'!$A$5:$A$138,2,'Seat Ledger'!$G$5:$G$138,"E3") -> 40 | E36: =SUMIFS('Seat Ledger'!$L$5:$L$138,'Seat Ledger'!$A$5:$A$138,3,'Seat Ledger'!$G$5:$G$138,"E3") -> 27 | G36: =IF(C$14=0,0,C36/C$14) -> 0.33 | H36: =IF(D$14=0,0,D36/D$14) -> 0.50632911 | I36: =IF(E$14=0,0,E36/E$14) -> 0.42857143
B37: E4 Lead / specialist 10-15 years | C37: =SUMIFS('Seat Ledger'!$L$5:$L$138,'Seat Ledger'!$A$5:$A$138,1,'Seat Ledger'!$G$5:$G$138,"E4") -> 31 | D37: =SUMIFS('Seat Ledger'!$L$5:$L$138,'Seat Ledger'!$A$5:$A$138,2,'Seat Ledger'!$G$5:$G$138,"E4") -> 30 | E37: =SUMIFS('Seat Ledger'!$L$5:$L$138,'Seat Ledger'!$A$5:$A$138,3,'Seat Ledger'!$G$5:$G$138,"E4") -> 22 | G37: =IF(C$14=0,0,C37/C$14) -> 0.31 | H37: =IF(D$14=0,0,D37/D$14) -> 0.37974684 | I37: =IF(E$14=0,0,E37/E$14) -> 0.34920635
B38: E5 Principal / architect 15 years+ | C38: =SUMIFS('Seat Ledger'!$L$5:$L$138,'Seat Ledger'!$A$5:$A$138,1,'Seat Ledger'!$G$5:$G$138,"E5") -> 7 | D38: =SUMIFS('Seat Ledger'!$L$5:$L$138,'Seat Ledger'!$A$5:$A$138,2,'Seat Ledger'!$G$5:$G$138,"E5") -> 7 | E38: =SUMIFS('Seat Ledger'!$L$5:$L$138,'Seat Ledger'!$A$5:$A$138,3,'Seat Ledger'!$G$5:$G$138,"E5") -> 8 | G38: =IF(C$14=0,0,C38/C$14) -> 0.07 | H38: =IF(D$14=0,0,D38/D$14) -> 0.088607595 | I38: =IF(E$14=0,0,E38/E$14) -> 0.12698413
B39: Senior share (E4 + E5) | C39: =IF(C14=0,0,(C37+C38)/C14) -> 0.38 | D39: =IF(D14=0,0,(D37+D38)/D14) -> 0.46835443 | E39: =IF(E14=0,0,(E37+E38)/E14) -> 0.47619048
B40: Talent shape | C40: =IF((C37+C38)/C14>0.58,"Obelisk",IF((C37+C38)/C14>0.42,"Diamond","Pyramid")) -> Pyramid | D40: =IF((D37+D38)/D14>0.58,"Obelisk",IF((D37+D38)/D14>0.42,"Diamond","Pyramid")) -> Diamond | E40: =IF((E37+E38)/E14>0.58,"Obelisk",IF((E37+E38)/E14>0.42,"Diamond","Pyramid")) -> Diamond
A42: F. SKILL DISTRIBUTION
B43: Skill family | C43: Year 1 | D43: Year 2 | E43: Year 3 | G43: Y1 % | H43: Y2 % | I43: Y3 %
B44: Leadership & delivery management | C44: =SUMIFS('Seat Ledger'!$L$5:$L$138,'Seat Ledger'!$A$5:$A$138,1,'Seat Ledger'!$F$5:$F$138,"LEAD") -> 21 | D44: =SUMIFS('Seat Ledger'!$L$5:$L$138,'Seat Ledger'!$A$5:$A$138,2,'Seat Ledger'!$F$5:$F$138,"LEAD") -> 19 | E44: =SUMIFS('Seat Ledger'!$L$5:$L$138,'Seat Ledger'!$A$5:$A$138,3,'Seat Ledger'!$F$5:$F$138,"LEAD") -> 15 | G44: =IF(C$14=0,0,C44/C$14) -> 0.21 | H44: =IF(D$14=0,0,D44/D$14) -> 0.24050633 | I44: =IF(E$14=0,0,E44/E$14) -> 0.23809524
B45: Business analysis & domain | C45: =SUMIFS('Seat Ledger'!$L$5:$L$138,'Seat Ledger'!$A$5:$A$138,1,'Seat Ledger'!$F$5:$F$138,"BA") -> 9 | D45: =SUMIFS('Seat Ledger'!$L$5:$L$138,'Seat Ledger'!$A$5:$A$138,2,'Seat Ledger'!$F$5:$F$138,"BA") -> 6 | E45: =SUMIFS('Seat Ledger'!$L$5:$L$138,'Seat Ledger'!$A$5:$A$138,3,'Seat Ledger'!$F$5:$F$138,"BA") -> 3 | G45: =IF(C$14=0,0,C45/C$14) -> 0.09 | H45: =IF(D$14=0,0,D45/D$14) -> 0.075949367 | I45: =IF(E$14=0,0,E45/E$14) -> 0.047619048
B46: Development | C46: =SUMIFS('Seat Ledger'!$L$5:$L$138,'Seat Ledger'!$A$5:$A$138,1,'Seat Ledger'!$F$5:$F$138,"DEV") -> 31 | D46: =SUMIFS('Seat Ledger'!$L$5:$L$138,'Seat Ledger'!$A$5:$A$138,2,'Seat Ledger'!$F$5:$F$138,"DEV") -> 21 | E46: =SUMIFS('Seat Ledger'!$L$5:$L$138,'Seat Ledger'!$A$5:$A$138,3,'Seat Ledger'!$F$5:$F$138,"DEV") -> 10 | G46: =IF(C$14=0,0,C46/C$14) -> 0.31 | H46: =IF(D$14=0,0,D46/D$14) -> 0.26582278 | I46: =IF(E$14=0,0,E46/E$14) -> 0.15873016
...

Sheet Glidepath & 50-50
A1: Glidepath — and why this domain needs no transfer of employment
A2: Productivity alone crosses 50:50 during Year 3 without any transfer of employment. The Contract Management problem runs the other way.
A4: A. BASELINE
B5: Measure | C5: Value
B6: Applications | C6: ='Logic Tree'!C6 -> 3
B7: Total effort (units) | C7: ='Logic Tree'!C7 -> 100.76497
B8: Current Capgemini FTC | C8: ='Logic Tree'!C8 -> 64.704594
B9: Current MetLife FTE | C9: ='Logic Tree'!C9 -> 18.825
B10: Current MetLife MGCC | C10: ='Logic Tree'!C10 -> 15.991667
B11: Ratio today FTC : MetLife | C11: =C8/C7 -> 0.64213381 | G11: Data Infra domain starts at 64:36 — MGCC is already here. And CG also partially supports
B12: Appendix 3 Year-3 target FTC (from Inventory) | C12: =SUMIFS(Inventory!$S:$S,Inventory!$E:$E,'Logic Tree'!$C$5) -> 50.382484 | D12: Target FTE/MGCC | E12: =SUMIFS(Inventory!$T:$T,Inventory!$E:$E,'Logic Tree'!$C$5) -> 50.382484 | G12: The two Appendix 3 targets are equal by construction — the client plan halves every application.
A14: B. PRODUCTIVITY — target vs delivered
B15: Measure | C15: Year 1 | D15: Year 2 | E15: Year 3
B16: Headcount delivered by the pod design | C16: ='Team Build-Up'!C14 -> 100 | D16: ='Team Build-Up'!D14 -> 79 | E16: ='Team Build-Up'!E14 -> 63 | G16: Year 1 absorbs the transition. Transition here is fast — modern stack, artefacts exist — but the substrate build still consumes it.
B17: Delivered productivity vs baseline | C17: =IF($C$7=0,0,1-'Team Build-Up'!C14/$C$7) -> 0.007591614 | D17: =IF($C$7=0,0,1-'Team Build-Up'!D14/$C$7) -> 0.21599738 | E17: =IF($C$7=0,0,1-'Team Build-Up'!E14/$C$7) -> 0.37478272
B18: Target from the logic tree | C18: ='Logic Tree'!C57 -> 0.12101505 | D18: ='Logic Tree'!D57 -> 0.25140116 | E18: ='Logic Tree'!E57 -> 0.28595974
B19: Transition & enablement drag | C19: =C18-C17 -> 0.11342344 | D19: =D18-D17 -> 0.03540378 | E19: =E18-E17 -> -0.08882298
A21: C. OFFSHORE — measured on Capgemini-delivered effort
B22: Measure | C22: Year 1 | D22: Year 2 | E22: Year 3
B23: Delivered — Capgemini offshore share | C23: ='Team Build-Up'!C30 -> 0.640625 | D23: ='Team Build-Up'!D30 -> 0.63636364 | E23: ='Team Build-Up'!E30 -> 0.64285714
B24: Target from the logic tree | C24: ='Logic Tree'!D65 -> 0.55481096 | D24: ='Logic Tree'!E65 -> 0.6509782 | E24: ='Logic Tree'!F65 -> 0.70276055
B25: Whole-team offshore share (includes MGCC) | C25: ='Team Build-Up'!C29 -> 0.55 | D25: ='Team Build-Up'!D29 -> 0.55696203 | E25: ='Team Build-Up'!E29 -> 0.57142857
A27: D. THE 50:50 POSITION — no transfer of employment in this domain
B28: MetLife FTE and MGCC are held constant. As the domain shrinks on productivity, their share rises on its own.
B29: Measure | C29: Year 1 | D29: Year 2 | E29: Year 3
B30: Total people | C30: ='Team Build-Up'!C14 -> 100 | D30: ='Team Build-Up'!D14 -> 79 | E30: ='Team Build-Up'!E14 -> 63
B31: Capgemini FTC | C31: ='Team Build-Up'!C20 -> 64 | D31: ='Team Build-Up'!D20 -> 44 | E31: ='Team Build-Up'!E20 -> 28
B32: MetLife FTE | C32: ='Team Build-Up'!C21 -> 20 | D32: ='Team Build-Up'!D21 -> 19 | E32: ='Team Build-Up'!E21 -> 17
B33: MetLife MGCC | C33: ='Team Build-Up'!C22 -> 16 | D33: ='Team Build-Up'!D22 -> 16 | E33: ='Team Build-Up'!E22 -> 18
B34: MetLife side total | C34: =C32+C33 -> 36 | D34: =D32+D33 -> 35 | E34: =E32+E33 -> 35
B35: Transferred this year (Logic Tree) | C35: ='Logic Tree'!C71 -> 0 | D35: ='Logic Tree'!D71 -> 0 | E35: ='Logic Tree'!E71 -> 0
B36: RATIO — Capgemini share | C36: =IF(C30=0,0,(C31-C35)/C30) -> 0.64 | D36: =IF(D30=0,0,(D31-D35)/D30) -> 0.55696203 | E36: =IF(E30=0,0,(E31-E35)/E30) -> 0.44444444
B37: Transfer that would be needed for exactly 50:50 | C37: =C30/2-C34 -> 14 | D37: =D30/2-D34 -> 4.5 | E37: =E30/2-E34 -> -3.5
B38: A NEGATIVE number above means the ratio has already passed 50:50 without any transfer.
A40: E. THE DECISION THIS DOMAIN RAISES INSTEAD
B41: • Data Infrastructure needs ~15 people moved to MetLife to reach 50:50. This domain reaches it on productivity alone, during Year 3 — Year 2 still sits just short at 56:44.
B42: • By Year 3 MetLife holds ~56% of a 65-person domain. Roughly 3-4 MetLife-side people are surplus to the ratio and could be redeployed to a domain that needs them.
B43: • Do not offer a transfer here. Offer the reverse: a redeployment plan that moves MetLife capacity out of Data Infrastructure and into the archetype-D domains where the 50:50 gap is real.
B44: • Both Informatica applications are Priority Transfer Targets, so the bedrock would route them to MGCC. The platform is being retired, so that transfer builds a capability MetLife will not keep. Run it to sunset instead and point MGCC growth at Synapse.

Sheet Cost & Commercial
A1: Cost and commercial position — relative index pending the approved rate card
A2: Onshore Tokyo band E2 = 1.00. Unit cost divides by the frozen baseline effort, because the scope MetLife buys does not change.
A4: A. TOTAL COST OF DELIVERING THE DOMAIN
B5: Measure | C5: Year 1 | D5: Year 2 | E5: Year 3
B6: Total cost index | C6: =SUMIFS('Seat Ledger'!$M$5:$M$138,'Seat Ledger'!$A$5:$A$138,1) -> 102.76 | D6: =SUMIFS('Seat Ledger'!$M$5:$M$138,'Seat Ledger'!$A$5:$A$138,2) -> 86.33 | E6: =SUMIFS('Seat Ledger'!$M$5:$M$138,'Seat Ledger'!$A$5:$A$138,3) -> 68.89
B7: Headcount | C7: ='Team Build-Up'!C14 -> 100 | D7: ='Team Build-Up'!D14 -> 79 | E7: ='Team Build-Up'!E14 -> 63
B8: Average cost per head | C8: =IF(C7=0,0,C6/C7) -> 1.0276 | D8: =IF(D7=0,0,D6/D7) -> 1.0927848 | E8: =IF(E7=0,0,E6/E7) -> 1.0934921 | G8: Average cost per head rises as the shape gets more senior. Offshore movement is what stops it rising faster.
B9: Cost per unit of frozen scope | C9: =IF('Glidepath & 50-50'!$C$7=0,0,C6/'Glidepath & 50-50'!$C$7) -> 1.0197989 | D9: =IF('Glidepath & 50-50'!$C$7=0,0,D6/'Glidepath & 50-50'!$C$7) -> 0.85674616 | E9: =IF('Glidepath & 50-50'!$C$7=0,0,E6/'Glidepath & 50-50'!$C$7) -> 0.68367014
B10: Unit cost reduction vs Year 1 | C10: =IF($C$9=0,0,1-C9/$C$9) -> 0 | D10: =IF($C$9=0,0,1-D9/$C$9) -> 0.15988712 | E10: =IF($C$9=0,0,1-E9/$C$9) -> 0.32960296
A12: B. WHAT MOVED THE UNIT COST — decomposition
B13: Effect | C13: Year 1 → Year 2 | D13: Year 1 → Year 3
B14: Headcount reduction (productivity) | C14: =IF($C$7=0,0,D7/$C$7-1) -> -0.21 | D14: =IF($C$7=0,0,E7/$C$7-1) -> -0.37
