Workbook

Sheet START HERE
A1: Domain framework template — set one cell, everything else re-derives
A2: MetLife Japan Application Development Services. Appendix 3 v5 · Golden Application Inventory v4 · the per-sourcing productivity engine used on Sales / Insurance, Contract Management, Data Infrastructure, Common Service Platform and Storage & Preservation.
B4: STEP 1 — choose your 領域
B5: Domain | C5: Corporate Related | E5: Pick from the drop-down. Every sheet that says (auto) re-derives the moment this changes: the baseline, the archetype mix, the AI and offshore ceilings, the capability chain, the five-year target headcount, the per-sourcing plan, the transfer solve, the value streams and the ticket load. Nothing else on this sheet needs to be touched to get a first cut.
B7: STEP 2 — read what the data says
B8: Measure | C8: Value | E8: What it tells you
B9: Applications in this 領域 | C9: =SUMPRODUCT(--('Inventory v5'!$D$5:$D$146='START HERE'!$C$5)) | E9: How many application lines the SUMIFS are reading. If this is 0 the domain name is misspelt.
B10: Total effort — units of person-capacity | C10: =SUMIFS('Inventory v5'!$J$5:$J$146,'Inventory v5'!$D$5:$D$146,'START HERE'!$C$5) | E10: The frozen scope. Every target in the model is a percentage reduction against this number, and it never changes across the five years.
B11: Vendor today (Appendix 3 'Current FTC') | C11: =SUMIFS('Inventory v5'!$K$5:$K$146,'Inventory v5'!$D$5:$D$146,'START HERE'!$C$5) | E11: Capgemini plus any named sub-contractor. Appendix 3 reports the two as one number, which is why the model carries PT separately.
B12: MetLife Japan today (FTE) | C12: =SUMIFS('Inventory v5'!$L$5:$L$146,'Inventory v5'!$D$5:$D$146,'START HERE'!$C$5) | E12: MetLife's own people. Mostly BSA and PM work — see the Role × Sourcing sheet.
B13: MetLife MGCC today | C13: =SUMIFS('Inventory v5'!$M$5:$M$146,'Inventory v5'!$D$5:$D$146,'START HERE'!$C$5) | E13: MetLife's global capability centre. Mostly build and test.
B14: Capgemini heads on these applications today | C14: ='Logic Tree'!C14 | E14: From the Golden Inventory's application-level Capgemini headcount. The gap to the vendor number is FSI, NCD or unnamed — see the Vendor column on the inventory.
B15: MetLife share of the whole 領域 on day one | C15: =IF(C10=0,0,(C12+C13)/C10) | E15: THE NUMBER THAT SETS YOUR POSTURE. Above 50% and the 50:50 is already met — argue against further convergence. Below 40% and you have a real transfer to size.
B16: Blended AI ceiling | C16: ='Logic Tree'!C38 | E16: Effort-weighted across the archetypes present. This is the ceiling, not the commitment.
B17: Blended offshore ceiling | C17: ='Logic Tree'!C39 | E17: Same weighting, on the offshore ceilings. J applications cap at 12% and drag this down hard.
B18: Delivered offshore or by MGCC today | C18: ='Logic Tree'!C130 | E18: Offshore plus MGCC as a share of total effort. The gap between this and the ceiling is the offshore case.
B20: STEP 3 — make the judgements that are yours
B21: Sheet | C21: What you decide there | E21: Why it matters
B22: Rates & Tables | C22: Adoption factors, realisation curve, classical ADM curve, operating-model curve, pre-load, partner drag, transfer cap, guardrail floors, cost index. | E22: The amber cells here are the solution position, not data. Read the notes before changing any of them. The one most worth thinking about for your 領域 is ADOPTION: how much of the AI ceiling MetLife's own people and MGCC can realistically commit to. Common Service Platform raised them; Storage & Preservation left them at the portfolio default. Both are defensible; neither is automatic.
B23: Value Streams & Delivery Mode | C23: The quarter each stream converts to pod delivery, and the pod / team counts by year. | E23: The stream list, effort and today's method all fill in automatically. What you decide is WHEN each stream converts and how many delivery units you run. Pod and team counts drive the whole seat plan.
B24: Role × Sourcing | C24: How each sourcing pool's headcount splits across the six client roles. | E24: Seeded with the observed split across the five 領域 already modelled — 1,102 units of Year-1 roster. Change it only if you know your 領域 differs, and say why. This matrix is what makes the per-sourcing AI ceilings differ from each other.
B25: Partner plan | C25: On the Logic Tree, section E — the sub-contracted population by year. | E25: Seeded at today's named-vendor figure held flat. If your 領域 has a real incumbent, taper it deliberately: partner seats can never transfer to MetLife, so they make the 50:50 harder.
B26: Seat Planner | C26: The delivery anatomy: every seat in every pod, team and horizontal function. | E26: THIS IS THE WORK. The model tells you how many people of each sourcing type you may have in each year; the anatomy decides who they are. Keep deployed heads on a 0.5 grid and keep sharing inside the 領域 — MetLife may award the eleven 領域 to two or three vendors.
B27: Reconciliation & Checks | C27: Nothing to enter. Read it. | E27: Every invariant the five built models are held to, as live formulas. Green in every year is the bar for a solution review.
B29: HOW WE KNOW THE ENGINE IS RIGHT
B30: • The engine here was tested against two models built independently in Python and already under practice review. Set the domain to Common Service Platform, enter its conversion quarters and pod plan, and raise the two MetLife adoption factors to 0.92 and 0.72 as that 領域 argues for, and the template reproduces the built model to within 0.14 of a person on every sourcing line in every year, and 0.09 of a percentage point on the Capgemini ratio.
B31: • Set it to Storage and Preservation Related, enter its conversion quarters, pod plan and FSI taper, and it reproduces that model to within 0.11 of a person and 0.15 of a percentage point, including the six-person Year-3 transfer.
B32: • The small residual is the role × sourcing matrix: this template seeds it from the portfolio average, while each built model uses its own Year-1 anatomy. That is the one place to tune if you want an exact match to a hand-built model.
B35: WHAT THIS TEMPLATE DOES NOT DO
B36: • It does not solve the seat plan for you. The five built models were fitted numerically: seats were optimised against the per-sourcing targets, the role lines, the location split and three guardrails simultaneously, then quantised onto a 0.5 head grid. Excel cannot do that. What this template does is give you every target the solver was aiming at, and check your hand-built anatomy against all of them.
B37: • It does not carry the inherited Capgemini workforce roll-forward. That needs the billing and staff-mapping files and is domain-specific; the Golden Inventory's CG heads today is carried here as the starting point.
B38: • It does not net out applications marked Retire in the Appendix 3 v5 disposition columns. The baseline is frozen at today's effort in every year, as it is in all five built models. If your 領域 has material retirements, that is an argument to make explicitly, not silently.
B39: • It does not price anything. The cost index is relative, onshore Tokyo E2 = 1.00, and exists so you can see the shape of the cost curve before the rate card lands.

Sheet Logic Tree
A1: Logic tree (auto) — every driver, five years, one domain name
A2: Green figures are derived from the inventory or from the rates tables. Amber cells are the few genuine inputs left on this sheet. Nothing here needs editing to produce a first cut.
A4: A. BASELINE — Appendix 3 v5, read and never edited
B5: Domain | C5: ='START HERE'!$C$5 | I5: The one cell that drives the workbook. Change it on START HERE.
B6: Applications in scope | C6: =SUMPRODUCT(--('Inventory v5'!$D$5:$D$146='START HERE'!$C$5)) | I6: Zero here means the name is misspelt.
B7: TOTAL EFFORT — the frozen scope | C7: =SUMIFS('Inventory v5'!$J$5:$J$146,'Inventory v5'!$D$5:$D$146,'START HERE'!$C$5) | I7: Units of person-capacity. Held constant across all five years: productivity shows as fewer people doing the same scope, never as scope walking out of the model.
B8: Vendor today (Appendix 3 'Current FTC') | C8: =SUMIFS('Inventory v5'!$K$5:$K$146,'Inventory v5'!$D$5:$D$146,'START HERE'!$C$5) | I8: Capgemini plus any named sub-contractor.
B9: MetLife Japan today (FTE) | C9: =SUMIFS('Inventory v5'!$L$5:$L$146,'Inventory v5'!$D$5:$D$146,'START HERE'!$C$5) | I9: Governance, product ownership, domain SME.
B10: MetLife MGCC today | C10: =SUMIFS('Inventory v5'!$M$5:$M$146,'Inventory v5'!$D$5:$D$146,'START HERE'!$C$5) | I10: MetLife's captive delivery centre.
B11: Onshore Tokyo | C11: =SUMIFS('Inventory v5'!$N$5:$N$146,'Inventory v5'!$D$5:$D$146,'START HERE'!$C$5) | I11: Vendor only. MEASURED, not assumed.
B12: Offshore | C12: =SUMIFS('Inventory v5'!$O$5:$O$146,'Inventory v5'!$D$5:$D$146,'START HERE'!$C$5) | I12: Vendor only. MGCC is excluded — it is MetLife's, not ours.
B13: Nearshore | C13: =SUMIFS('Inventory v5'!$P$5:$P$146,'Inventory v5'!$D$5:$D$146,'START HERE'!$C$5) | I13: Zero in most 領域. Carried so every domain model shares one schema.
B14: Capgemini heads on these applications today | C14: =SUMIFS('Inventory v5'!$AN$5:$AN$146,'Inventory v5'!$D$5:$D$146,'START HERE'!$C$5) | I14: From the Golden Inventory v4 workforce reconciliation. The continuity argument starts here.
B16: Rows 7 to 13 are the reconciliation target. A Year-1 seat plan that does not reproduce these numbers is not a plan for this 領域 — it is a plan for a different one.
A18: B. THE ROLE LINE — as reported, and as restated where it is internally impossible
B19: Client role | C19: Appendix 3 v5 | D19: Restated — INPUT | E19: Difference | I19: Note
B20: BSA | C20: =SUMIFS('Inventory v5'!$Q$5:$Q$146,'Inventory v5'!$D$5:$D$146,'START HERE'!$C$5) | D20: 3.67447 | E20: =D20-C20 | I20: Bilingual analysis. Scarce in every 領域.
B21: Developer | C21: =SUMIFS('Inventory v5'!$R$5:$R$146,'Inventory v5'!$D$5:$D$146,'START HERE'!$C$5) | D21: 13.962986 | E21: =D21-C21 | I21: The line restatements are taken FROM here, which is why it is the only one that falls.
B22: Tester | C22: =SUMIFS('Inventory v5'!$S$5:$S$146,'Inventory v5'!$D$5:$D$146,'START HERE'!$C$5) | D22: 6.246599 | E22: =D22-C22 | I22: Where the AI ceiling is highest. A thin tester line understates what is achievable.
B23: Maintenance | C23: =SUMIFS('Inventory v5'!$T$5:$T$146,'Inventory v5'!$D$5:$D$146,'START HERE'!$C$5) | D23: 8.083834 | E23: =D23-C23 | I23: Compare to the ticket load on the AMS sheet. Several 領域 report one person of run against a thousand incidents a year; that is a coding convention, not a plan.
B24: PM | C24: =SUMIFS('Inventory v5'!$U$5:$U$146,'Inventory v5'!$D$5:$D$146,'START HERE'!$C$5) | D24: 2.572129 | E24: =D24-C24 | I24: Compare to the number of delivery units you intend to run.
B25: Other | C25: =SUMIFS('Inventory v5'!$V$5:$V$146,'Inventory v5'!$D$5:$D$146,'START HERE'!$C$5) | D25: 2.204682 | E25: =D25-C25 | I25: Architecture and enablement. Reported as zero in several 領域.
B26: Total — must equal the vendor number, and must not move | C26: =SUM(C20:C25) | D26: =SUM(D20:D25) | E26: =D26-C26
B27: Neutrality check | C27: =IF(ABS(E26)<0.005,"OK — arithmetically neutral","FAIL — the restatement changes the total")
B28: A RESTATEMENT MOVES PEOPLE BETWEEN ROLE LINES. IT NEVER CHANGES THE TOTAL. Overwrite the amber column where MetLife's own figure is internally impossible, take the difference out of Developer, and check that row 27 still says OK. Every restatement goes back to MetLife as a clarification question — we are not silently re-pricing their data.
A30: C. ARCHETYPES — the six-rule classifier, and the two ceilings it sets
B31: Archetype | C31: Apps | D31: Effort | E31: Share of effort | F31: AI ceiling | G31: Offshore ceiling | I31: Note
B32: M | C32: =SUMPRODUCT(--('Inventory v5'!$D$5:$D$146='START HERE'!$C$5),--('Inventory v5'!$G$5:$G$146="M")) | D32: =SUMIFS('Inventory v5'!$J$5:$J$146,'Inventory v5'!$D$5:$D$146,'START HERE'!$C$5,'Inventory v5'!$G$5:$G$146,"M") | E32: =IF($C$7=0,0,D32/$C$7) | F32: ='Rates & Tables'!$I$6 | G32: ='Rates & Tables'!$C$27
B33: L | C33: =SUMPRODUCT(--('Inventory v5'!$D$5:$D$146='START HERE'!$C$5),--('Inventory v5'!$G$5:$G$146="L")) | D33: =SUMIFS('Inventory v5'!$J$5:$J$146,'Inventory v5'!$D$5:$D$146,'START HERE'!$C$5,'Inventory v5'!$G$5:$G$146,"L") | E33: =IF($C$7=0,0,D33/$C$7) | F33: ='Rates & Tables'!$I$7 | G33: ='Rates & Tables'!$C$28
B34: D | C34: =SUMPRODUCT(--('Inventory v5'!$D$5:$D$146='START HERE'!$C$5),--('Inventory v5'!$G$5:$G$146="D")) | D34: =SUMIFS('Inventory v5'!$J$5:$J$146,'Inventory v5'!$D$5:$D$146,'START HERE'!$C$5,'Inventory v5'!$G$5:$G$146,"D") | E34: =IF($C$7=0,0,D34/$C$7) | F34: ='Rates & Tables'!$I$8 | G34: ='Rates & Tables'!$C$29
B35: P | C35: =SUMPRODUCT(--('Inventory v5'!$D$5:$D$146='START HERE'!$C$5),--('Inventory v5'!$G$5:$G$146="P")) | D35: =SUMIFS('Inventory v5'!$J$5:$J$146,'Inventory v5'!$D$5:$D$146,'START HERE'!$C$5,'Inventory v5'!$G$5:$G$146,"P") | E35: =IF($C$7=0,0,D35/$C$7) | F35: ='Rates & Tables'!$I$9 | G35: ='Rates & Tables'!$C$30
B36: J | C36: =SUMPRODUCT(--('Inventory v5'!$D$5:$D$146='START HERE'!$C$5),--('Inventory v5'!$G$5:$G$146="J")) | D36: =SUMIFS('Inventory v5'!$J$5:$J$146,'Inventory v5'!$D$5:$D$146,'START HERE'!$C$5,'Inventory v5'!$G$5:$G$146,"J") | E36: =IF($C$7=0,0,D36/$C$7) | F36: ='Rates & Tables'!$I$10 | G36: ='Rates & Tables'!$C$31
B37: T | C37: =SUMPRODUCT(--('Inventory v5'!$D$5:$D$146='START HERE'!$C$5),--('Inventory v5'!$G$5:$G$146="T")) | D37: =SUMIFS('Inventory v5'!$J$5:$J$146,'Inventory v5'!$D$5:$D$146,'START HERE'!$C$5,'Inventory v5'!$G$5:$G$146,"T") | E37: =IF($C$7=0,0,D37/$C$7) | F37: ='Rates & Tables'!$I$11 | G37: ='Rates & Tables'!$C$32
B38: BLENDED AI CEILING | C38: =IF($C$7=0,0,SUMPRODUCT($D$32:$D$37,$F$32:$F$37)/$C$7) | I38: Effort-weighted. This is what the estate could theoretically support, before realisation, before adoption, and before anyone has to agree to it.
B39: BLENDED OFFSHORE CEILING | C39: =IF($C$7=0,0,SUMPRODUCT($D$32:$D$37,$G$32:$G$37)/$C$7) | I39: The number that decides whether an offshore case exists at all. A 領域 that is mostly J applications cannot be moved, however good the tooling.
A41: D. THE CAPABILITY CHAIN — four gates, compounded, then pre-loaded
B42: Driver | C42: Year 1 | D42: Year 2 | E42: Year 3 | F42: Year 4 | G42: Year 5 | I42: Basis
B43: Agile share of effort | C43: ='Value Streams & Delivery Mode'!D33 | D43: ='Value Streams & Delivery Mode'!E33 | E43: ='Value Streams & Delivery Mode'!F33 | F43: ='Value Streams & Delivery Mode'!G33 | G43: ='Value Streams & Delivery Mode'!H33 | I43: From the Value Streams sheet. Operating-model gain is only available where the stream actually runs as a pod, so this scales it.
B44: Operating-model productivity — pass 1 | C44: ='Rates & Tables'!C47*C43 | D44: ='Rates & Tables'!D47*D43 | E44: ='Rates & Tables'!E47*E43 | F44: ='Rates & Tables'!F47*F43 | G44: ='Rates & Tables'!G47*G43 | I44: Pass one, before the partner discount. It exists only to give the partner share something to divide by.
B45: Blended capability — pass 1 | C45: =1-(1-$C$38*'Rates & Tables'!C45)*(1-'Rates & Tables'!C46)*(1-C44) | D45: =1-(1-$C$38*'Rates & Tables'!D45)*(1-'Rates & Tables'!D46)*(1-D44) | E45: =1-(1-$C$38*'Rates & Tables'!E45)*(1-'Rates & Tables'!E46)*(1-E44) | F45: =1-(1-$C$38*'Rates & Tables'!F45)*(1-'Rates & Tables'!F46)*(1-F44) | G45: =1-(1-$C$38*'Rates & Tables'!G45)*(1-'Rates & Tables'!G46)*(1-G44) | I45: 1 − (1 − ceiling × realisation)(1 − classical)(1 − operating model). The gates are independent, so they compound rather than add.
...

Sheet Value Streams & Delivery Mode
A1: Value streams and delivery mode — the streams fill in, the conversion is yours
A2: Stream names, application counts, effort and today's development method are read from Appendix 3 v5. What you decide is when each stream converts to pod delivery and how many units you run.
A4: A. THE STREAMS IN THIS 領域 (auto, except the conversion quarter)
B5: # | C5: Value stream | D5: Apps | E5: Effort | F5: Share | G5: Method today | H5: Converts in Q — INPUT
B6: 1 | C6: =IFERROR(INDEX('Stream Catalogue'!$E$5:$E$31,MATCH('START HERE'!$C$5&"|"&$B6,'Stream Catalogue'!$B$5:$B$31,0)),"") | D6: =IFERROR(INDEX('Stream Catalogue'!$F$5:$F$31,MATCH('START HERE'!$C$5&"|"&$B6,'Stream Catalogue'!$B$5:$B$31,0)),"") | E6: =IFERROR(INDEX('Stream Catalogue'!$G$5:$G$31,MATCH('START HERE'!$C$5&"|"&$B6,'Stream Catalogue'!$B$5:$B$31,0)),"") | F6: =IF($E6="","",IF('Logic Tree'!$C$7=0,0,$E6/'Logic Tree'!$C$7)) | G6: =IFERROR(INDEX('Stream Catalogue'!$H$5:$H$31,MATCH('START HERE'!$C$5&"|"&$B6,'Stream Catalogue'!$B$5:$B$31,0)),"") | H6: 1 | J6: Blank rows mean your 領域 has fewer than six value streams — that is normal, most have two or three. If row 13 is not zero, your 領域 has MORE than six and the catalogue needs extending; tell whoever maintains this template.
B7: 2 | C7: =IFERROR(INDEX('Stream Catalogue'!$E$5:$E$31,MATCH('START HERE'!$C$5&"|"&$B7,'Stream Catalogue'!$B$5:$B$31,0)),"") | D7: =IFERROR(INDEX('Stream Catalogue'!$F$5:$F$31,MATCH('START HERE'!$C$5&"|"&$B7,'Stream Catalogue'!$B$5:$B$31,0)),"") | E7: =IFERROR(INDEX('Stream Catalogue'!$G$5:$G$31,MATCH('START HERE'!$C$5&"|"&$B7,'Stream Catalogue'!$B$5:$B$31,0)),"") | F7: =IF($E7="","",IF('Logic Tree'!$C$7=0,0,$E7/'Logic Tree'!$C$7)) | G7: =IFERROR(INDEX('Stream Catalogue'!$H$5:$H$31,MATCH('START HERE'!$C$5&"|"&$B7,'Stream Catalogue'!$B$5:$B$31,0)),"") | H7: 5
B8: 3 | C8: =IFERROR(INDEX('Stream Catalogue'!$E$5:$E$31,MATCH('START HERE'!$C$5&"|"&$B8,'Stream Catalogue'!$B$5:$B$31,0)),"") | D8: =IFERROR(INDEX('Stream Catalogue'!$F$5:$F$31,MATCH('START HERE'!$C$5&"|"&$B8,'Stream Catalogue'!$B$5:$B$31,0)),"") | E8: =IFERROR(INDEX('Stream Catalogue'!$G$5:$G$31,MATCH('START HERE'!$C$5&"|"&$B8,'Stream Catalogue'!$B$5:$B$31,0)),"") | F8: =IF($E8="","",IF('Logic Tree'!$C$7=0,0,$E8/'Logic Tree'!$C$7)) | G8: =IFERROR(INDEX('Stream Catalogue'!$H$5:$H$31,MATCH('START HERE'!$C$5&"|"&$B8,'Stream Catalogue'!$B$5:$B$31,0)),"") | H8: 7
B9: 4 | C9: =IFERROR(INDEX('Stream Catalogue'!$E$5:$E$31,MATCH('START HERE'!$C$5&"|"&$B9,'Stream Catalogue'!$B$5:$B$31,0)),"") | D9: =IFERROR(INDEX('Stream Catalogue'!$F$5:$F$31,MATCH('START HERE'!$C$5&"|"&$B9,'Stream Catalogue'!$B$5:$B$31,0)),"") | E9: =IFERROR(INDEX('Stream Catalogue'!$G$5:$G$31,MATCH('START HERE'!$C$5&"|"&$B9,'Stream Catalogue'!$B$5:$B$31,0)),"") | F9: =IF($E9="","",IF('Logic Tree'!$C$7=0,0,$E9/'Logic Tree'!$C$7)) | G9: =IFERROR(INDEX('Stream Catalogue'!$H$5:$H$31,MATCH('START HERE'!$C$5&"|"&$B9,'Stream Catalogue'!$B$5:$B$31,0)),"") | H9: 9 | J9: THE CONVERSION QUARTER IS THE ASSUMPTION TO ARGUE ABOUT. Q1 means the stream runs as pods from day one; Q9 means it converts at the start of Year 3. A stream that is already recorded Agile in Appendix 3 should convert early — the work is proving the pod shape, not changing method. A Japanese-specification waterfall stream should convert late or not at all.
B10: 5 | C10: =IFERROR(INDEX('Stream Catalogue'!$E$5:$E$31,MATCH('START HERE'!$C$5&"|"&$B10,'Stream Catalogue'!$B$5:$B$31,0)),"") | D10: =IFERROR(INDEX('Stream Catalogue'!$F$5:$F$31,MATCH('START HERE'!$C$5&"|"&$B10,'Stream Catalogue'!$B$5:$B$31,0)),"") | E10: =IFERROR(INDEX('Stream Catalogue'!$G$5:$G$31,MATCH('START HERE'!$C$5&"|"&$B10,'Stream Catalogue'!$B$5:$B$31,0)),"") | F10: =IF($E10="","",IF('Logic Tree'!$C$7=0,0,$E10/'Logic Tree'!$C$7)) | G10: =IFERROR(INDEX('Stream Catalogue'!$H$5:$H$31,MATCH('START HERE'!$C$5&"|"&$B10,'Stream Catalogue'!$B$5:$B$31,0)),"") | H10: 11
B11: 6 | C11: =IFERROR(INDEX('Stream Catalogue'!$E$5:$E$31,MATCH('START HERE'!$C$5&"|"&$B11,'Stream Catalogue'!$B$5:$B$31,0)),"") | D11: =IFERROR(INDEX('Stream Catalogue'!$F$5:$F$31,MATCH('START HERE'!$C$5&"|"&$B11,'Stream Catalogue'!$B$5:$B$31,0)),"") | E11: =IFERROR(INDEX('Stream Catalogue'!$G$5:$G$31,MATCH('START HERE'!$C$5&"|"&$B11,'Stream Catalogue'!$B$5:$B$31,0)),"") | F11: =IF($E11="","",IF('Logic Tree'!$C$7=0,0,$E11/'Logic Tree'!$C$7)) | G11: =IFERROR(INDEX('Stream Catalogue'!$H$5:$H$31,MATCH('START HERE'!$C$5&"|"&$B11,'Stream Catalogue'!$B$5:$B$31,0)),"") | H11: 13
C12: Total — must equal the frozen scope | D12: =SUM(D6:D11) | E12: =SUM(E6:E11) | F12: =IF('Logic Tree'!$C$7=0,0,E12/'Logic Tree'!$C$7)
C13: Reconciliation to the Logic Tree | E13: =E12-'Logic Tree'!$C$7
A15: B. DELIVERY UNITS BY YEAR — INPUT
B16: # | C16: Value stream | D16: Y1 pods | E16: Y1 teams | F16: Y2 pods | G16: Y2 teams | H16: Y3 pods | I16: Y3 teams | J16: Y4 pods | K16: Y4 teams | L16: Y5 pods | M16: Y5 teams
B17: 1 | C17: =C6 | D17: 1 | E17: 0 | F17: 1 | G17: 0 | H17: 1 | I17: 0 | J17: 1 | K17: 0 | L17: 1 | M17: 0 | O17: A POD is a cross-functional unit that owns a stream end to end; a TEAM is the waterfall or hybrid shape with a separate test cell. Across the five 領域 modelled, pods run 10 seats in Year 1 falling to 6 by Year 4, and teams run 11 to 12 with the test cell attached. Enter the counts here; the Seat Planner multiplies them by the seat anatomy you design.
B18: 2 | C18: =C7 | D18: 0 | E18: 1 | F18: 1 | G18: 0 | H18: 1 | I18: 0 | J18: 1 | K18: 0 | L18: 1 | M18: 0
B19: 3 | C19: =C8 | D19: 0 | E19: 1 | F19: 0 | G19: 1 | H19: 1 | I19: 0 | J19: 1 | K19: 0 | L19: 1 | M19: 0
B20: 4 | C20: =C9 | D20: 0 | E20: 0 | F20: 0 | G20: 0 | H20: 0 | I20: 0 | J20: 0 | K20: 0 | L20: 0 | M20: 0 | O20: Teams should disappear as streams convert. If you still have teams in Year 5, either the conversion quarters above are wrong or you are telling MetLife the 領域 never modernises — which may be the right answer for a Japan-locked estate, but say it out loud.
B21: 5 | C21: =C10 | D21: 0 | E21: 0 | F21: 0 | G21: 0 | H21: 0 | I21: 0 | J21: 0 | K21: 0 | L21: 0 | M21: 0
B22: 6 | C22: =C11 | D22: 0 | E22: 0 | F22: 0 | G22: 0 | H22: 0 | I22: 0 | J22: 0 | K22: 0 | L22: 0 | M22: 0
C23: TOTAL DELIVERY UNITS | D23: =SUM(D17:D22) | E23: =SUM(E17:E22) | F23: =SUM(F17:F22) | G23: =SUM(G17:G22) | H23: =SUM(H17:H22) | I23: =SUM(I17:I22) | J23: =SUM(J17:J22) | K23: =SUM(K17:K22) | ... M23: =SUM(M17:M22)
A25: C. AGILE SHARE BY YEAR (auto) — read by the Logic Tree
B26: # | C26: Value stream | D26: Year 1 | E26: Year 2 | F26: Year 3 | G26: Year 4 | H26: Year 5
B27: 1 | C27: =C6 | D27: =IF($C27="",0,MAX(0,MIN(4,4-$H6+1))/4) | E27: =IF($C27="",0,MAX(0,MIN(4,8-$H6+1))/4) | F27: =IF($C27="",0,MAX(0,MIN(4,12-$H6+1))/4) | G27: =IF($C27="",0,MAX(0,MIN(4,16-$H6+1))/4) | H27: =IF($C27="",0,MAX(0,MIN(4,20-$H6+1))/4)
B28: 2 | C28: =C7 | D28: =IF($C28="",0,MAX(0,MIN(4,4-$H7+1))/4) | E28: =IF($C28="",0,MAX(0,MIN(4,8-$H7+1))/4) | F28: =IF($C28="",0,MAX(0,MIN(4,12-$H7+1))/4) | G28: =IF($C28="",0,MAX(0,MIN(4,16-$H7+1))/4) | H28: =IF($C28="",0,MAX(0,MIN(4,20-$H7+1))/4)
B29: 3 | C29: =C8 | D29: =IF($C29="",0,MAX(0,MIN(4,4-$H8+1))/4) | E29: =IF($C29="",0,MAX(0,MIN(4,8-$H8+1))/4) | F29: =IF($C29="",0,MAX(0,MIN(4,12-$H8+1))/4) | G29: =IF($C29="",0,MAX(0,MIN(4,16-$H8+1))/4) | H29: =IF($C29="",0,MAX(0,MIN(4,20-$H8+1))/4)
B30: 4 | C30: =C9 | D30: =IF($C30="",0,MAX(0,MIN(4,4-$H9+1))/4) | E30: =IF($C30="",0,MAX(0,MIN(4,8-$H9+1))/4) | F30: =IF($C30="",0,MAX(0,MIN(4,12-$H9+1))/4) | G30: =IF($C30="",0,MAX(0,MIN(4,16-$H9+1))/4) | H30: =IF($C30="",0,MAX(0,MIN(4,20-$H9+1))/4)
B31: 5 | C31: =C10 | D31: =IF($C31="",0,MAX(0,MIN(4,4-$H10+1))/4) | E31: =IF($C31="",0,MAX(0,MIN(4,8-$H10+1))/4) | F31: =IF($C31="",0,MAX(0,MIN(4,12-$H10+1))/4) | G31: =IF($C31="",0,MAX(0,MIN(4,16-$H10+1))/4) | H31: =IF($C31="",0,MAX(0,MIN(4,20-$H10+1))/4)
B32: 6 | C32: =C11 | D32: =IF($C32="",0,MAX(0,MIN(4,4-$H11+1))/4) | E32: =IF($C32="",0,MAX(0,MIN(4,8-$H11+1))/4) | F32: =IF($C32="",0,MAX(0,MIN(4,12-$H11+1))/4) | G32: =IF($C32="",0,MAX(0,MIN(4,16-$H11+1))/4) | H32: =IF($C32="",0,MAX(0,MIN(4,20-$H11+1))/4)
C33: EFFORT-WEIGHTED AGILE SHARE OF THE 領域 | D33: =IF($E$12=0,0,SUMPRODUCT($E$6:$E$11,D27:D32)/$E$12) | E33: =IF($E$12=0,0,SUMPRODUCT($E$6:$E$11,E27:E32)/$E$12) | F33: =IF($E$12=0,0,SUMPRODUCT($E$6:$E$11,F27:F32)/$E$12) | G33: =IF($E$12=0,0,SUMPRODUCT($E$6:$E$11,G27:G32)/$E$12) | H33: =IF($E$12=0,0,SUMPRODUCT($E$6:$E$11,H27:H32)/$E$12)
B34: This row scales the operating-model gate in the Logic Tree. Pod consolidation, a single release train and a wider span of control are only available where the stream actually runs as a pod, so a 領域 that converts late earns less of that gate — correctly.

Sheet Role x Sourcing
A1: Role × sourcing — why the four populations cannot carry the same commitment
A2: The one place a judgement about MetLife's own people is made explicit. Seeded from the observed Year-1 roster across the five 領域 already modelled — 1,102 units of seat plan.
A4: A. AI CEILING BY CLIENT ROLE, ON THIS 領域'S ARCHETYPE MIX (auto)
B5: Archetype | C5: Share of effort | D5: BSA | E5: Developer | F5: Tester | G5: Maintenance | H5: PM | I5: Other
B6: M | C6: ='Logic Tree'!$E$32 | D6: =SUMPRODUCT('Rates & Tables'!$C$17:$H$17,'Rates & Tables'!$C$6:$H$6) | E6: =SUMPRODUCT('Rates & Tables'!$C$18:$H$18,'Rates & Tables'!$C$6:$H$6) | F6: =SUMPRODUCT('Rates & Tables'!$C$19:$H$19,'Rates & Tables'!$C$6:$H$6) | G6: =SUMPRODUCT('Rates & Tables'!$C$20:$H$20,'Rates & Tables'!$C$6:$H$6) | H6: =SUMPRODUCT('Rates & Tables'!$C$21:$H$21,'Rates & Tables'!$C$6:$H$6) | I6: =SUMPRODUCT('Rates & Tables'!$C$22:$H$22,'Rates & Tables'!$C$6:$H$6)
B7: L | C7: ='Logic Tree'!$E$33 | D7: =SUMPRODUCT('Rates & Tables'!$C$17:$H$17,'Rates & Tables'!$C$7:$H$7) | E7: =SUMPRODUCT('Rates & Tables'!$C$18:$H$18,'Rates & Tables'!$C$7:$H$7) | F7: =SUMPRODUCT('Rates & Tables'!$C$19:$H$19,'Rates & Tables'!$C$7:$H$7) | G7: =SUMPRODUCT('Rates & Tables'!$C$20:$H$20,'Rates & Tables'!$C$7:$H$7) | H7: =SUMPRODUCT('Rates & Tables'!$C$21:$H$21,'Rates & Tables'!$C$7:$H$7) | I7: =SUMPRODUCT('Rates & Tables'!$C$22:$H$22,'Rates & Tables'!$C$7:$H$7)
B8: D | C8: ='Logic Tree'!$E$34 | D8: =SUMPRODUCT('Rates & Tables'!$C$17:$H$17,'Rates & Tables'!$C$8:$H$8) | E8: =SUMPRODUCT('Rates & Tables'!$C$18:$H$18,'Rates & Tables'!$C$8:$H$8) | F8: =SUMPRODUCT('Rates & Tables'!$C$19:$H$19,'Rates & Tables'!$C$8:$H$8) | G8: =SUMPRODUCT('Rates & Tables'!$C$20:$H$20,'Rates & Tables'!$C$8:$H$8) | H8: =SUMPRODUCT('Rates & Tables'!$C$21:$H$21,'Rates & Tables'!$C$8:$H$8) | I8: =SUMPRODUCT('Rates & Tables'!$C$22:$H$22,'Rates & Tables'!$C$8:$H$8)
B9: P | C9: ='Logic Tree'!$E$35 | D9: =SUMPRODUCT('Rates & Tables'!$C$17:$H$17,'Rates & Tables'!$C$9:$H$9) | E9: =SUMPRODUCT('Rates & Tables'!$C$18:$H$18,'Rates & Tables'!$C$9:$H$9) | F9: =SUMPRODUCT('Rates & Tables'!$C$19:$H$19,'Rates & Tables'!$C$9:$H$9) | G9: =SUMPRODUCT('Rates & Tables'!$C$20:$H$20,'Rates & Tables'!$C$9:$H$9) | H9: =SUMPRODUCT('Rates & Tables'!$C$21:$H$21,'Rates & Tables'!$C$9:$H$9) | I9: =SUMPRODUCT('Rates & Tables'!$C$22:$H$22,'Rates & Tables'!$C$9:$H$9)
B10: J | C10: ='Logic Tree'!$E$36 | D10: =SUMPRODUCT('Rates & Tables'!$C$17:$H$17,'Rates & Tables'!$C$10:$H$10) | E10: =SUMPRODUCT('Rates & Tables'!$C$18:$H$18,'Rates & Tables'!$C$10:$H$10) | F10: =SUMPRODUCT('Rates & Tables'!$C$19:$H$19,'Rates & Tables'!$C$10:$H$10) | G10: =SUMPRODUCT('Rates & Tables'!$C$20:$H$20,'Rates & Tables'!$C$10:$H$10) | H10: =SUMPRODUCT('Rates & Tables'!$C$21:$H$21,'Rates & Tables'!$C$10:$H$10) | I10: =SUMPRODUCT('Rates & Tables'!$C$22:$H$22,'Rates & Tables'!$C$10:$H$10)
B11: T | C11: ='Logic Tree'!$E$37 | D11: =SUMPRODUCT('Rates & Tables'!$C$17:$H$17,'Rates & Tables'!$C$11:$H$11) | E11: =SUMPRODUCT('Rates & Tables'!$C$18:$H$18,'Rates & Tables'!$C$11:$H$11) | F11: =SUMPRODUCT('Rates & Tables'!$C$19:$H$19,'Rates & Tables'!$C$11:$H$11) | G11: =SUMPRODUCT('Rates & Tables'!$C$20:$H$20,'Rates & Tables'!$C$11:$H$11) | H11: =SUMPRODUCT('Rates & Tables'!$C$21:$H$21,'Rates & Tables'!$C$11:$H$11) | I11: =SUMPRODUCT('Rates & Tables'!$C$22:$H$22,'Rates & Tables'!$C$11:$H$11)
B12: AI CEILING FOR THIS ROLE | D12: =SUMPRODUCT($C$6:$C$11,D6:D11) | E12: =SUMPRODUCT($C$6:$C$11,E6:E11) | F12: =SUMPRODUCT($C$6:$C$11,F6:F11) | G12: =SUMPRODUCT($C$6:$C$11,G6:G11) | H12: =SUMPRODUCT($C$6:$C$11,H6:H11) | I12: =SUMPRODUCT($C$6:$C$11,I6:I11) | L12: Each role's time distribution run through each archetype's phase ceilings, weighted by how much of this 領域 each archetype is. On a mainframe-heavy 領域 every number here falls; on a cloud 領域 every number rises. Tester is always the highest and PM always the lowest.
A14: B. HOW EACH POOL'S HEADCOUNT SPLITS ACROSS THE SIX ROLES — INPUT
B15: Sourcing pool | D15: BSA | E15: Developer | F15: Tester | G15: Maintenance | H15: PM | I15: Other | J15: Check
B16: FTC | D16: 0.108253 | E16: 0.331456 | F16: 0.176442 | G16: 0.23342 | H16: 0.080962 | I16: 0.06945 | J16: =SUM(D16:I16) | L16: Capgemini payroll. Broad, because we carry the delivery.
B17: PT | D17: 0.0476 | E17: 0.6882 | F17: 0.1291 | G17: 0.1348 | H17: 0.0004 | I17: 0 | J17: =SUM(D17:I17) | L17: Sub-contractor. Overwhelmingly developers with a maintenance tail.
B18: FTE | D18: 0.4082 | E18: 0 | F18: 0.0102 | G18: 0.1827 | H18: 0.3886 | I18: 0.0102 | J18: =SUM(D18:I18) | L18: MetLife Japan. 41% BSA and 39% PM — this is a governance population, not a build one.
B19: MGCC | D19: 0 | E19: 0.7407 | F19: 0.2593 | G19: 0 | H19: 0 | I19: 0 | J19: =SUM(D19:I19) | L19: MGCC. 74% developers, 26% testers, nothing else.
B20: EACH ROW MUST SUM TO 100%. These are shares of that pool's own headcount, not of the 領域. Change them only where you know your 領域 differs from the portfolio pattern, and write down why — this matrix is the entire reason the four populations end up with different productivity commitments, and MetLife will ask about it.
A22: C. THE RESULTING YEAR-1 HEADCOUNT MATRIX (auto)
B23: Sourcing pool | C23: Year-1 population | D23: BSA | E23: Developer | F23: Tester | G23: Maintenance | H23: PM | I23: Other | J23: Total
B24: FTC | C24: ='Logic Tree'!$C$63 | D24: =$C24*D16 | E24: =$C24*E16 | F24: =$C24*F16 | G24: =$C24*G16 | H24: =$C24*H16 | I24: =$C24*I16 | J24: =SUM(D24:I24)
B25: PT | C25: ='Logic Tree'!$C$64 | D25: =$C25*D17 | E25: =$C25*E17 | F25: =$C25*F17 | G25: =$C25*G17 | H25: =$C25*H17 | I25: =$C25*I17 | J25: =SUM(D25:I25)
B26: FTE | C26: ='Logic Tree'!$C$65 | D26: =$C26*D18 | E26: =$C26*E18 | F26: =$C26*F18 | G26: =$C26*G18 | H26: =$C26*H18 | I26: =$C26*I18 | J26: =SUM(D26:I26)
B27: MGCC | C27: ='Logic Tree'!$C$66 | D27: =$C27*D19 | E27: =$C27*E19 | F27: =$C27*F19 | G27: =$C27*G19 | H27: =$C27*H19 | I27: =$C27*I19 | J27: =SUM(D27:I27)
B28: Vendor rows only (FTC + PT) | D28: =D24+D25 | E28: =E24+E25 | F28: =F24+F25 | G28: =G24+G25 | H28: =H24+H25 | I28: =I24+I25 | J28: =SUM(D28:I28)
B29: Appendix 3 v5, restated — the vendor role line | D29: ='Logic Tree'!$D$20 | E29: ='Logic Tree'!$D$21 | F29: ='Logic Tree'!$D$22 | G29: ='Logic Tree'!$D$23 | H29: ='Logic Tree'!$D$24 | I29: ='Logic Tree'!$D$25 | J29: =SUM(D29:I29)
B30: Variance | D30: =D28-D29 | E30: =E28-E29 | F30: =F28-F29 | G30: =G28-G29 | H30: =H28-H29 | I30: =I28-I29 | J30: =D30+E30+F30+G30+H30+I30
B31: Largest single role variance | C31: =MAX(ABS(D30),ABS(E30),ABS(F30),ABS(G30),ABS(H30),ABS(I30))
B32: Row 30 is the honest check on row 16. Appendix 3 tells us the vendor role line but not how it splits between Capgemini and a sub-contractor, and it tells us nothing at all about how MetLife's own people or MGCC are deployed. If row 31 is large, the FTC or PT row above is wrong for your 領域 — tune it until the vendor side reconciles, then leave the MetLife rows alone unless you have evidence.
A34: D. THE PER-SOURCING AI CEILING (auto) — read by the Logic Tree
B35: This is the output of everything above: each pool's own role mix run through each role's own ceiling. It is what makes MGCC a high-ceiling population and MetLife Japan a low-ceiling one — not an opinion about the people, but an observation about the work they do.
B39: Sourcing pool | C39: Dominant roles | D39: AI CEILING | E39: Adoption | F39: Ceiling × adoption | L39: Reading
B40: FTC | C40: =INDEX($D$15:$I$15,MATCH(MAX(D16:I16),D16:I16,0))&" "&TEXT(MAX(D16:I16),"0%") | D40: =SUMPRODUCT($D$12:$I$12,D16:I16) | E40: ='Rates & Tables'!$C$36 | F40: =D40*E40 | L40: Column D is capability — what the work would support. Column E is authority — how much of it that population can actually commit to. Column F is the product, and it is the number that decides how much of the productivity promise sits on Capgemini's side of the contract.
B41: PT | C41: =INDEX($D$15:$I$15,MATCH(MAX(D17:I17),D17:I17,0))&" "&TEXT(MAX(D17:I17),"0%") | D41: =SUMPRODUCT($D$12:$I$12,D17:I17) | E41: ='Rates & Tables'!$C$37 | F41: =D41*E41
B42: FTE | C42: =INDEX($D$15:$I$15,MATCH(MAX(D18:I18),D18:I18,0))&" "&TEXT(MAX(D18:I18),"0%") | D42: =SUMPRODUCT($D$12:$I$12,D18:I18) | E42: ='Rates & Tables'!$C$38 | F42: =D42*E42
B43: MGCC | C43: =INDEX($D$15:$I$15,MATCH(MAX(D19:I19),D19:I19,0))&" "&TEXT(MAX(D19:I19),"0%") | D43: =SUMPRODUCT($D$12:$I$12,D19:I19) | E43: ='Rates & Tables'!$C$39 | F43: =D43*E43

Sheet AMS & Ticket Load
A1: AMS and ticket load (auto) — and the one contradiction to put back to MetLife
A2: Incident and change volumes from Appendix 3 v5, against the maintenance role line and against MetLife's own AD / AMS effort split. In several 領域 the two disagree by a factor of three.
A4: A. THE LOAD (auto)
B5: Measure | C5: Volume | D5: Per application | G5: Note
B6: P1 — critical incidents | C6: =SUMIFS('Inventory v5'!$AE$5:$AE$146,'Inventory v5'!$D$5:$D$146,'START HERE'!$C$5) | D6: =IF('Logic Tree'!$C$6=0,0,C6/'Logic Tree'!$C$6) | G6: Outage-class. A 領域 with P1s needs a named onshore first responder.
B7: P2 — high | C7: =SUMIFS('Inventory v5'!$AF$5:$AF$146,'Inventory v5'!$D$5:$D$146,'START HERE'!$C$5) | D7: =IF('Logic Tree'!$C$6=0,0,C7/'Logic Tree'!$C$6) | G7: Business-impacting.
B8: P3 — medium | C8: =SUMIFS('Inventory v5'!$AG$5:$AG$146,'Inventory v5'!$D$5:$D$146,'START HERE'!$C$5) | D8: =IF('Logic Tree'!$C$6=0,0,C8/'Logic Tree'!$C$6) | G8: The bulk of the analyst load in most 領域.
B9: P4 — low | C9: =SUMIFS('Inventory v5'!$AH$5:$AH$146,'Inventory v5'!$D$5:$D$146,'START HERE'!$C$5) | D9: =IF('Logic Tree'!$C$6=0,0,C9/'Logic Tree'!$C$6)
B10: P5 — cosmetic / request | C10: =SUMIFS('Inventory v5'!$AI$5:$AI$146,'Inventory v5'!$D$5:$D$146,'START HERE'!$C$5) | D10: =IF('Logic Tree'!$C$6=0,0,C10/'Logic Tree'!$C$6) | G10: Often the largest volume and the cheapest to automate away.
B12: Emergency changes | C12: =SUMIFS('Inventory v5'!$AJ$5:$AJ$146,'Inventory v5'!$D$5:$D$146,'START HERE'!$C$5) | D12: =IF('Logic Tree'!$C$6=0,0,C12/'Logic Tree'!$C$6) | G12: Unplanned production change. High volume here signals brittle release practice.
B13: Normal changes | C13: =SUMIFS('Inventory v5'!$AK$5:$AK$146,'Inventory v5'!$D$5:$D$146,'START HERE'!$C$5) | D13: =IF('Logic Tree'!$C$6=0,0,C13/'Logic Tree'!$C$6)
B14: Standard changes | C14: =SUMIFS('Inventory v5'!$AL$5:$AL$146,'Inventory v5'!$D$5:$D$146,'START HERE'!$C$5) | D14: =IF('Logic Tree'!$C$6=0,0,C14/'Logic Tree'!$C$6) | G14: Pre-approved and repeatable — the natural first target for automation.
B16: TOTAL INCIDENTS | C16: =SUM(C6:C10)
B17: TOTAL CHANGES | C17: =SUM(C12:C14)
B18: P1 + P2 as a share of incidents | C18: =IF(C16=0,0,(C6+C7)/C16) | G18: Below 1% and the estate is stable; the AMS case is about volume, not severity. Above 5% and you need an onshore incident cell whatever the offshore ceiling says.
A20: B. WHAT IT TAKES TO SERVE IT — INPUT
B21: Driver | C21: Value | G21: Note
B22: Average handling time — incident (hours) | C22: 3.5 | G22: Across the five 領域 modelled. Weight it up on a mainframe estate and down on a cloud one.
B23: Average handling time — change (hours) | C23: 5 | G23: Build, test and release of a small change.
B24: Productive hours per analyst per year | C24: 1500 | G24: 1,800 gross less leave, training and ceremony. Deliberately conservative.
B25: Share of the load carried by the horizontal AMS function | C25: 0.7 | G25: The rest sits inside the pods, which is where shift-left actually happens.
B26: IMPLIED AMS PEOPLE | C26: =IF(C24=0,0,(C16*C22+C17*C23)/C24) | G26: A SANITY CHECK, NOT A TARGET. It exists so that a maintenance line of one person against a thousand incidents is visibly impossible rather than quietly accepted.
B27: — of which in the horizontal function (H1) | C27: =C26*C25
A29: C. THE TWO METLIFE VIEWS OF RUN — and they disagree (auto)
B30: View | C30: Units of run | G30: Where it comes from
B31: The role line — Maintenance, as restated | C31: ='Logic Tree'!$D$23 | G31: Logic Tree section B. This is the figure the seat plan reconciles to.
B32: The AD / AMS effort split — 1 − % of PRJ | C32: ='Logic Tree'!$C$7-SUMPRODUCT(('Inventory v5'!$D$5:$D$146='START HERE'!$C$5)*'Inventory v5'!$J$5:$J$146*'Inventory v5'!$W$5:$W$146) | G32: Appendix 3's own '% of PRJ' column, applied application by application. Same spreadsheet, different answer.
B33: THE GAP | C33: =C32-C31 | G33: PUT THIS BACK TO METLIFE BEFORE THE AMS PRICE IS FIXED. It is not a modelling choice — it is a contradiction inside the client's own data, and whichever way it resolves it moves the run-side commercial position.

Sheet Seat Planner
A1: Seat planner — the delivery anatomy, and the only sheet you build by hand
A2: One row per seat per unit type per year. Columns L to P are computed. COMPOSITION RULES, applied in this version: every seat has a unique Role detail inside its unit-year block; a grade is fixed for the life of a seat (no seat is re-banded across years); a move between Tokyo and offshore is shown in the seat name, never silently in the Loc column; and the people arriving from the Year-3 transfer sit in their own named seats so the base seats taper monotonically.
B4: Year | C4: Unit | D4: Stream | E4: Seat | F4: Role detail | G4: Role | H4: Exp | I4: Loc | J4: Sourcing | K4: Seats per unit | L4: Units | M4: HEADS | N4: Cost index | O4: Cost | P4: Key
B5: 1 | C5: POD | D5: 1 | E5: 1 | F5: MetLife Product Owner | G5: PM | H5: E4 | I5: ON | J5: FTE | K5: 1 | L5: =IF($B5="",0,IF($C5="HZ",1,IFERROR(INDEX('Value Streams & Delivery Mode'!$D$17:$M$22,MATCH($D5,'Value Streams & Delivery Mode'!$B$17:$B$22,0),($B5-1)*2+IF($C5="POD",1,2)),0))) | M5: =IF($B5="",0,$K5*$L5) | N5: =IF($B5="",0,IFERROR(INDEX('Rates & Tables'!$C$61:$G$63,MATCH($I5,'Rates & Tables'!$J$61:$J$63,0),MATCH($H5,'Rates & Tables'!$C$60:$G$60,0)),0)) | O5: =IF($B5="",0,$M5*$N5) | P5: =IF($B5="","",$B5&"|"&$G5&"|"&$J5)
B6: 1 | C6: POD | D6: 1 | E6: 2 | F6: MetLife Group Policy SME | G6: BSA | H6: E4 | I6: ON | J6: FTE | K6: 1 | L6: =IF($B6="",0,IF($C6="HZ",1,IFERROR(INDEX('Value Streams & Delivery Mode'!$D$17:$M$22,MATCH($D6,'Value Streams & Delivery Mode'!$B$17:$B$22,0),($B6-1)*2+IF($C6="POD",1,2)),0))) | M6: =IF($B6="",0,$K6*$L6) | N6: =IF($B6="",0,IFERROR(INDEX('Rates & Tables'!$C$61:$G$63,MATCH($I6,'Rates & Tables'!$J$61:$J$63,0),MATCH($H6,'Rates & Tables'!$C$60:$G$60,0)),0)) | O6: =IF($B6="",0,$M6*$N6) | P6: =IF($B6="","",$B6&"|"&$G6&"|"&$J6)
B7: 1 | C7: POD | D7: 1 | E7: 3 | F7: FSI Senior Developer (JP) | G7: DEV | H7: E3 | I7: ON | J7: PT | K7: 2 | L7: =IF($B7="",0,IF($C7="HZ",1,IFERROR(INDEX('Value Streams & Delivery Mode'!$D$17:$M$22,MATCH($D7,'Value Streams & Delivery Mode'!$B$17:$B$22,0),($B7-1)*2+IF($C7="POD",1,2)),0))) | M7: =IF($B7="",0,$K7*$L7) | N7: =IF($B7="",0,IFERROR(INDEX('Rates & Tables'!$C$61:$G$63,MATCH($I7,'Rates & Tables'!$J$61:$J$63,0),MATCH($H7,'Rates & Tables'!$C$60:$G$60,0)),0)) | O7: =IF($B7="",0,$M7*$N7) | P7: =IF($B7="","",$B7&"|"&$G7&"|"&$J7)
B8: 1 | C8: POD | D8: 1 | E8: 4 | F8: FSI Application Support | G8: MNT | H8: E2 | I8: ON | J8: PT | K8: 1 | L8: =IF($B8="",0,IF($C8="HZ",1,IFERROR(INDEX('Value Streams & Delivery Mode'!$D$17:$M$22,MATCH($D8,'Value Streams & Delivery Mode'!$B$17:$B$22,0),($B8-1)*2+IF($C8="POD",1,2)),0))) | M8: =IF($B8="",0,$K8*$L8) | N8: =IF($B8="",0,IFERROR(INDEX('Rates & Tables'!$C$61:$G$63,MATCH($I8,'Rates & Tables'!$J$61:$J$63,0),MATCH($H8,'Rates & Tables'!$C$60:$G$60,0)),0)) | O8: =IF($B8="",0,$M8*$N8) | P8: =IF($B8="","",$B8&"|"&$G8&"|"&$J8)
B9: 1 | C9: POD | D9: 1 | E9: 5 | F9: Pod lead / senior engineer | G9: DEV | H9: E3 | I9: ON | J9: FTC | K9: 1 | L9: =IF($B9="",0,IF($C9="HZ",1,IFERROR(INDEX('Value Streams & Delivery Mode'!$D$17:$M$22,MATCH($D9,'Value Streams & Delivery Mode'!$B$17:$B$22,0),($B9-1)*2+IF($C9="POD",1,2)),0))) | M9: =IF($B9="",0,$K9*$L9) | N9: =IF($B9="",0,IFERROR(INDEX('Rates & Tables'!$C$61:$G$63,MATCH($I9,'Rates & Tables'!$J$61:$J$63,0),MATCH($H9,'Rates & Tables'!$C$60:$G$60,0)),0)) | O9: =IF($B9="",0,$M9*$N9) | P9: =IF($B9="","",$B9&"|"&$G9&"|"&$J9)
B10: 1 | C10: POD | D10: 1 | E10: 6 | F10: Business Analyst (bilingual) | G10: BSA | H10: E2 | I10: ON | J10: FTC | K10: 0.5 | L10: =IF($B10="",0,IF($C10="HZ",1,IFERROR(INDEX('Value Streams & Delivery Mode'!$D$17:$M$22,MATCH($D10,'Value Streams & Delivery Mode'!$B$17:$B$22,0),($B10-1)*2+IF($C10="POD",1,2)),0))) | M10: =IF($B10="",0,$K10*$L10) | N10: =IF($B10="",0,IFERROR(INDEX('Rates & Tables'!$C$61:$G$63,MATCH($I10,'Rates & Tables'!$J$61:$J$63,0),MATCH($H10,'Rates & Tables'!$C$60:$G$60,0)),0)) | O10: =IF($B10="",0,$M10*$N10) | P10: =IF($B10="","",$B10&"|"&$G10&"|"&$J10)
B11: 1 | C11: POD | D11: 1 | E11: 7 | F11: Java Developer | G11: DEV | H11: E2 | I11: OFF | J11: FTC | K11: 0.5 | L11: =IF($B11="",0,IF($C11="HZ",1,IFERROR(INDEX('Value Streams & Delivery Mode'!$D$17:$M$22,MATCH($D11,'Value Streams & Delivery Mode'!$B$17:$B$22,0),($B11-1)*2+IF($C11="POD",1,2)),0))) | M11: =IF($B11="",0,$K11*$L11) | N11: =IF($B11="",0,IFERROR(INDEX('Rates & Tables'!$C$61:$G$63,MATCH($I11,'Rates & Tables'!$J$61:$J$63,0),MATCH($H11,'Rates & Tables'!$C$60:$G$60,0)),0)) | O11: =IF($B11="",0,$M11*$N11) | P11: =IF($B11="","",$B11&"|"&$G11&"|"&$J11)
B12: 1 | C12: POD | D12: 1 | E12: 8 | F12: Quality Engineer (SDET) | G12: TEST | H12: E3 | I12: ON | J12: FTC | K12: 1 | L12: =IF($B12="",0,IF($C12="HZ",1,IFERROR(INDEX('Value Streams & Delivery Mode'!$D$17:$M$22,MATCH($D12,'Value Streams & Delivery Mode'!$B$17:$B$22,0),($B12-1)*2+IF($C12="POD",1,2)),0))) | M12: =IF($B12="",0,$K12*$L12) | N12: =IF($B12="",0,IFERROR(INDEX('Rates & Tables'!$C$61:$G$63,MATCH($I12,'Rates & Tables'!$J$61:$J$63,0),MATCH($H12,'Rates & Tables'!$C$60:$G$60,0)),0)) | O12: =IF($B12="",0,$M12*$N12) | P12: =IF($B12="","",$B12&"|"&$G12&"|"&$J12)
B13: 1 | C13: POD | D13: 1 | E13: 9 | F13: Junior Application Support — offshore | G13: MNT | H13: E1 | I13: OFF | J13: FTC | K13: 0.5 | L13: =IF($B13="",0,IF($C13="HZ",1,IFERROR(INDEX('Value Streams & Delivery Mode'!$D$17:$M$22,MATCH($D13,'Value Streams & Delivery Mode'!$B$17:$B$22,0),($B13-1)*2+IF($C13="POD",1,2)),0))) | M13: =IF($B13="",0,$K13*$L13) | N13: =IF($B13="",0,IFERROR(INDEX('Rates & Tables'!$C$61:$G$63,MATCH($I13,'Rates & Tables'!$J$61:$J$63,0),MATCH($H13,'Rates & Tables'!$C$60:$G$60,0)),0)) | O13: =IF($B13="",0,$M13*$N13) | P13: =IF($B13="","",$B13&"|"&$G13&"|"&$J13)
B14: 1 | C14: TEAM | D14: 2 | E14: 1 | F14: MetLife Product Owner | G14: PM | H14: E4 | I14: ON | J14: FTE | K14: 1 | L14: =IF($B14="",0,IF($C14="HZ",1,IFERROR(INDEX('Value Streams & Delivery Mode'!$D$17:$M$22,MATCH($D14,'Value Streams & Delivery Mode'!$B$17:$B$22,0),($B14-1)*2+IF($C14="POD",1,2)),0))) | M14: =IF($B14="",0,$K14*$L14) | N14: =IF($B14="",0,IFERROR(INDEX('Rates & Tables'!$C$61:$G$63,MATCH($I14,'Rates & Tables'!$J$61:$J$63,0),MATCH($H14,'Rates & Tables'!$C$60:$G$60,0)),0)) | O14: =IF($B14="",0,$M14*$N14) | P14: =IF($B14="","",$B14&"|"&$G14&"|"&$J14)
B15: 1 | C15: TEAM | D15: 2 | E15: 2 | F15: MetLife Compliance SME | G15: BSA | H15: E4 | I15: ON | J15: FTE | K15: 1 | L15: =IF($B15="",0,IF($C15="HZ",1,IFERROR(INDEX('Value Streams & Delivery Mode'!$D$17:$M$22,MATCH($D15,'Value Streams & Delivery Mode'!$B$17:$B$22,0),($B15-1)*2+IF($C15="POD",1,2)),0))) | M15: =IF($B15="",0,$K15*$L15) | N15: =IF($B15="",0,IFERROR(INDEX('Rates & Tables'!$C$61:$G$63,MATCH($I15,'Rates & Tables'!$J$61:$J$63,0),MATCH($H15,'Rates & Tables'!$C$60:$G$60,0)),0)) | O15: =IF($B15="",0,$M15*$N15) | P15: =IF($B15="","",$B15&"|"&$G15&"|"&$J15)
B16: 1 | C16: TEAM | D16: 2 | E16: 3 | F16: MetLife Operations Analyst | G16: MNT | H16: E3 | I16: ON | J16: FTE | K16: 0.5 | L16: =IF($B16="",0,IF($C16="HZ",1,IFERROR(INDEX('Value Streams & Delivery Mode'!$D$17:$M$22,MATCH($D16,'Value Streams & Delivery Mode'!$B$17:$B$22,0),($B16-1)*2+IF($C16="POD",1,2)),0))) | M16: =IF($B16="",0,$K16*$L16) | N16: =IF($B16="",0,IFERROR(INDEX('Rates & Tables'!$C$61:$G$63,MATCH($I16,'Rates & Tables'!$J$61:$J$63,0),MATCH($H16,'Rates & Tables'!$C$60:$G$60,0)),0)) | O16: =IF($B16="",0,$M16*$N16) | P16: =IF($B16="","",$B16&"|"&$G16&"|"&$J16)
... B35: 1 | C35: TEAM | D35: 3 | E35: 10 | F35: Batch Monitoring Engineer | G35: MNT | H35: E1 | I35: ON | J35: FTC | K35: 1 | L35: =IF($B35="",0,IF($C35="HZ",1,IFERROR(INDEX('Value Streams & Delivery Mode'!$D$17:$M$22,MATCH($D35,'Value Streams & Delivery Mode'!$B$17:$B$22,0),($B35-1)*2+IF($C35="POD",1,2)),0))) | M35: =IF($B35="",0,$K35*$L35) | N35: =IF($B35="",0,IFERROR(INDEX('Rates & Tables'!$C$61:$G$63,MATCH($I35,'Rates & Tables'!$J$61:$J$63,0),MATCH($H35,'Rates & Tables'!$C$60:$G$60,0)),0)) | O35: =IF($B35="",0,$M35*$N35) | P35: =IF($B35="","",$B35&"|"&$G35&"|"&$J35)
B36: 1 | C36: HZ | D36: H3 | E36: 1 | F36: Domain Service Manager | G36: PM | H36: E5 | I36: ON | J36: FTC | K36: 1 | L36: =IF($B36="",0,IF($C36="HZ",1,IFERROR(INDEX('Value Streams & Delivery Mode'!$D$17:$M$22,MATCH($D36,'Value Streams & Delivery Mode'!$B$17:$B$22,0),($B36-1)*2+IF($C36="POD",1,2)),0))) | M36: =IF($B36="",0,$K36*$L36) | N36: =IF($B36="",0,IFERROR(INDEX('Rates & Tables'!$C$61:$G$63,MATCH($I36,'Rates & Tables'!$J$61:$J$63,0),MATCH($H36,'Rates & Tables'!$C$60:$G$60,0)),0)) | O36: =IF($B36="",0,$M36*$N36) | P36: =IF($B36="","",$B36&"|"&$G36&"|"&$J36)
B37: 1 | C37: HZ | D37: H3 | E37: 2 | F37: Delivery / Project Manager | G37: PM | H37: E3 | I37: ON | J37: FTC | K37: 1.5 | L37: =IF($B37="",0,IF($C37="HZ",1,IFERROR(INDEX('Value Streams & Delivery Mode'!$D$17:$M$22,MATCH($D37,'Value Streams & Delivery Mode'!$B$17:$B$22,0),($B37-1)*2+IF($C37="POD",1,2)),0))) | M37: =IF($B37="",0,$K37*$L37) | N37: =IF($B37="",0,IFERROR(INDEX('Rates & Tables'!$C$61:$G$63,MATCH($I37,'Rates & Tables'!$J$61:$J$63,0),MATCH($H37,'Rates & Tables'!$C$60:$G$60,0)),0)) | O37: =IF($B37="",0,$M37*$N37) | P37: =IF($B37="","",$B37&"|"&$G37&"|"&$J37)
B38: 1 | C38: HZ | D38: H3 | E38: 3 | F38: Lead BSA (bilingual) | G38: BSA | H38: E4 | I38: ON | J38: FTC | K38: 1 | L38: =IF($B38="",0,IF($C38="HZ",1,IFERROR(INDEX('Value Streams & Delivery Mode'!$D$17:$M$22,MATCH($D38,'Value Streams & Delivery Mode'!$B$17:$B$22,0),($B38-1)*2+IF($C38="POD",1,2)),0))) | M38: =IF($B38="",0,$K38*$L38) | N38: =IF($B38="",0,IFERROR(INDEX('Rates & Tables'!$C$61:$G$63,MATCH($I38,'Rates & Tables'!$J$61:$J$63,0),MATCH($H38,'Rates & Tables'!$C$60:$G$60,0)),0)) | O38: =IF($B38="",0,$M38*$N38) | P38: =IF($B38="","",$B38&"|"&$G38&"|"&$J38)
B39: 1 | C39: HZ | D39: H3 | E39: 4 | F39: Solution Architect | G39: OTH | H39: E4 | I39: ON | J39: FTC | K39: 1 | L39: =IF($B39="",0,IF($C39="HZ",1,IFERROR(INDEX('Value Streams & Delivery Mode'!$D$17:$M$22,MATCH($D39,'Value Streams & Delivery Mode'!$B$17:$B$22,0),($B39-1)*2+IF($C39="POD",1,2)),0))) | M39: =IF($B39="",0,$K39*$L39) | N39: =IF($B39="",0,IFERROR(INDEX('Rates & Tables'!$C$61:$G$63,MATCH($I39,'Rates & Tables'!$J$61:$J$63,0),MATCH($H39,'Rates & Tables'!$C$60:$G$60,0)),0)) | O39: =IF($B39="",0,$M39*$N39) | P39: =IF($B39="","",$B39&"|"&$G39&"|"&$J39)
B40: 1 | C40: HZ | D40: H3 | E40: 5 | F40: Release / DevOps engineer | G40: OTH | H40: E2 | I40: ON | J40: FTC | K40: 1.5 | L40: =IF($B40="",0,IF($C40="HZ",1,IFERROR(INDEX('Value Streams & Delivery Mode'!$D$17:$M$22,MATCH($D40,'Value Streams & Delivery Mode'!$B$17:$B$22,0),($B40-1)*2+IF($C40="POD",1,2)),0))) | M40: =IF($B40="",0,$K40*$L40) | N40: =IF($B40="",0,IFERROR(INDEX('Rates & Tables'!$C$61:$G$63,MATCH($I40,'Rates & Tables'!$J$61:$J$63,0),MATCH($H40,'Rates & Tables'!$C$60:$G$60,0)),0)) | O40: =IF($B40="",0,$M40*$N40) | P40: =IF($B40="","",$B40&"|"&$G40&"|"&$J40)
B41: 1 | C41: HZ | D41: H3 | E41: 6 | F41: MetLife Regulatory Liaison | G41: BSA | H41: E4 | I41: ON | J41: FTE | K41: 1.5 | L41: =IF($B41="",0,IF($C41="HZ",1,IFERROR(INDEX('Value Streams & Delivery Mode'!$D$17:$M$22,MATCH($D41,'Value Streams & Delivery Mode'!$B$17:$B$22,0),($B41-1)*2+IF($C41="POD",1,2)),0))) | M41: =IF($B41="",0,$K41*$L41) | N41: =IF($B41="",0,IFERROR(INDEX('Rates & Tables'!$C$61:$G$63,MATCH($I41,'Rates & Tables'!$J$61:$J$63,0),MATCH($H41,'Rates & Tables'!$C$60:$G$60,0)),0)) | O41: =IF($B41="",0,$M41*$N41) | P41: =IF($B41="","",$B41&"|"&$G41&"|"&$J41)
B42: 1 | C42: HZ | D42: H3 | E42: 7 | F42: MetLife Domain Architect | G42: OTH | H42: E4 | I42: ON | J42: FTE | K42: 1.5 | L42: =IF($B42="",0,IF($C42="HZ",1,IFERROR(INDEX('Value Streams & Delivery Mode'!$D$17:$M$22,MATCH($D42,'Value Streams & Delivery Mode'!$B$17:$B$22,0),($B42-1)*2+IF($C42="POD",1,2)),0))) | M42: =IF($B42="",0,$K42*$L42) | N42: =IF($B42="",0,IFERROR(INDEX('Rates & Tables'!$C$61:$G$63,MATCH($I42,'Rates & Tables'!$J$61:$J$63,0),MATCH($H42,'Rates & Tables'!$C$60:$G$60,0)),0)) | O42: =IF($B42="",0,$M42*$N42) | P42: =IF($B42="","",$B42&"|"&$G42&"|"&$J42)
B43: 1 | C43: HZ | D43: H1 | E43: 8 | F43: AMS Team Lead | G43: MNT | H43: E3 | I43: ON | J43: FTC | K43: 1 | L43: =IF($B43="",0,IF($C43="HZ",1,IFERROR(INDEX('Value Streams & Delivery Mode'!$D$17:$M$22,MATCH($D43,'Value Streams & Delivery Mode'!$B$17:$B$22,0),($B43-1)*2+IF($C43="POD",1,2)),0))) | M43: =IF($B43="",0,$K43*$L43) | N43: =IF($B43="",0,IFERROR(INDEX('Rates & Tables'!$C$61:$G$63,MATCH($I43,'Rates & Tables'!$J$61:$J$63,0),MATCH($H43,'Rates & Tables'!$C$60:$G$60,0)),0)) | O43: =IF($B43="",0,$M43*$N43) | P43: =IF($B43="","",$B43&"|"&$G43&"|"&$J43)
B44: 1 | C44: HZ | D44: H1 | E44: 9 | F44: L2/L3 Application Support — Tokyo | G44: MNT | H44: E2 | I44: ON | J44: FTC | K44: 0.5 | L44: =IF($B44="",0,IF($C44="HZ",1,IFERROR(INDEX('Value Streams & Delivery Mode'!$D$17:$M$22,MATCH($D44,'Value Streams & Delivery Mode'!$B$17:$B$22,0),($B44-1)*2+IF($C44="POD",1,2)),0))) | M44: =IF($B44="",0,$K44*$L44) | N44: =IF($B44="",0,IFERROR(INDEX('Rates & Tables'!$C$61:$G$63,MATCH($I44,'Rates & Tables'!$J$61:$J$63,0),MATCH($H44,'Rates & Tables'!$C$60:$G$60,0)),0)) | O44: =IF($B44="",0,$M44*$N44) | P44: =IF($B44="","",$B44&"|"&$G44&"|"&$J44)
B45: 1 | C45: HZ | D45: H1 | E45: 10 | F45: Junior Application Support — offshore | G45: MNT | H45: E1 | I45: OFF | J45: FTC | K45: 0.5 | L45: =IF($B45="",0,IF($C45="HZ",1,IFERROR(INDEX('Value Streams & Delivery Mode'!$D$17:$M$22,MATCH($D45,'Value Streams & Delivery Mode'!$B$17:$B$22,0),($B45-1)*2+IF($C45="POD",1,2)),0))) | M45: =IF($B45="",0,$K45*$L45) | N45: =IF($B45="",0,IFERROR(INDEX('Rates & Tables'!$C$61:$G$63,MATCH($I45,'Rates & Tables'!$J$61:$J$63,0),MATCH($H45,'Rates & Tables'!$C$60:$G$60,0)),0)) | O45: =IF($B45="",0,$M45*$N45) | P45: =IF($B45="","",$B45&"|"&$G45&"|"&$J45)
B46: 1 | C46: HZ | D46: H1 | E46: 11 | F46: Batch Monitoring Engineer | G46: MNT | H46: E1 | I46: ON | J46: FTC | K46: 0.5 | L46: =IF($B46="",0,IF($C46="HZ",1,IFERROR(INDEX('Value Streams & Delivery Mode'!$D$17:$M$22,MATCH($D46,'Value Streams & Delivery Mode'!$B$17:$B$22,0),($B46-1)*2+IF($C46="POD",1,2)),0))) | M46: =IF($B46="",0,$K46*$L46) | N46: =IF($B46="",0,IFERROR(INDEX('Rates & Tables'!$C$61:$G$63,MATCH($I46,'Rates & Tables'!$J$61:$J$63,0),MATCH($H46,'Rates & Tables'!$C$60:$G$60,0)),0)) | O46: =IF($B46="",0,$M46*$N46) | P46: =IF($B46="","",$B46&"|"&$G46&"|"&$J46)
B47: 1 | C47: HZ | D47: H1 | E47: 12 | F47: SaaS Administrator | G47: MNT | H47: E2 | I47: ON | J47: FTC | K47: 1 | L47: =IF($B47="",0,IF($C47="HZ",1,IFERROR(INDEX('Value Streams & Delivery Mode'!$D$17:$M$22,MATCH($D47,'Value Streams & Delivery Mode'!$B$17:$B$22,0),($B47-1)*2+IF($C47="POD",1,2)),0))) | M47: =IF($B47="",0,$K47*$L47) | N47: =IF($B47="",0,IFERROR(INDEX('Rates & Tables'!$C$61:$G$63,MATCH($I47,'Rates & Tables'!$J$61:$J$63,0),MATCH($H47,'Rates & Tables'!$C$60:$G$60,0)),0)) | O47: =IF($B47="",0,$M47*$N47) | P47: =IF($B47="","",$B47&"|"&$G47&"|"&$J47)
... B52: 1 | C52: HZ | D52: H2 | E52: 17 | F52: MGCC Test Engineer | G52: TEST | H52: E2 | I52: OFF | J52: MGCC | K52: 0.5 | L52: =IF($B52="",0,IF($C52="HZ",1,IFERROR(INDEX('Value Streams & Delivery Mode'!$D$17:$M$22,MATCH($D52,'Value Streams & Delivery Mode'!$B$17:$B$22,0),($B52-1)*2+IF($C52="POD",1,2)),0))) | M52: =IF($B52="",0,$K52*$L52) | N52: =IF($B52="",0,IFERROR(INDEX('Rates & Tables'!$C$61:$G$63,MATCH($I52,'Rates & Tables'!$J$61:$J$63,0),MATCH($H52,'Rates & Tables'!$C$60:$G$60,0)),0)) | O52: =IF($B52="",0,$M52*$N52) | P52: =IF($B52="","",$B52&"|"&$G52&"|"&$J52)
B53: 2 | C53: POD | D53: 1 | E53: 1 | F53: MetLife Product Owner | G53: PM | H53: E4 | I53: ON | J53: FTE | K53: 1 | L53: =IF($B53="",0,IF($C53="HZ",1,IFERROR(INDEX('Value Streams & Delivery Mode'!$D$17:$M$22,MATCH($D53,'Value Streams & Delivery Mode'!$B$17:$B$22,0),($B53-1)*2+IF($C53="POD",1,2)),0))) | M53: =IF($B53="",0,$K53*$L53) | N53: =IF($B53="",0,IFERROR(INDEX('Rates & Tables'!$C$61:$G$63,MATCH($I53,'Rates & Tables'!$J$61:$J$63,0),MATCH($H53,'Rates & Tables'!$C$60:$G$60,0)),0)) | O53: =IF($B53="",0,$M53*$N53) | P53: =IF($B53="","",$B53&"|"&$G53&"|"&$J53)
B54: 2 | C54: POD | D54: 1 | E54: 2 | F54: MetLife Group Policy SME | G54: BSA | H54: E4 | I54: ON | J54: FTE | K54: 0.5 | L54: =IF($B54="",0,IF($C54="HZ",1,IFERROR(INDEX('Value Streams & Delivery Mode'!$D$17:$M$22,MATCH($D54,'Value Streams & Delivery Mode'!$B$17:$B$22,0),($B54-1)*2+IF($C54="POD",1,2)),0))) | M54: =IF($B54="",0,$K54*$L54) | N54: =IF($B54="",0,IFERROR(INDEX('Rates & Tables'!$C$61:$G$63,MATCH($I54,'Rates & Tables'!$J$61:$J$63,0),MATCH($H54,'Rates & Tables'!$C$60:$G$60,0)),0)) | O54: =IF($B54="",0,$M54*$N54) | P54: =IF($B54="","",$B54&"|"&$G54&"|"&$J54)
B55: 2 | C55: POD | D55: 1 | E55: 3 | F55: FSI Senior Developer (JP) | G55: DEV | H55: E3 | I55: ON | J55: PT | K55: 2 | L55: =IF($B55="",0,IF($C55="HZ",1,IFERROR(INDEX('Value Streams & Delivery Mode'!$D$17:$M$22,MATCH($D55,'Value Streams & Delivery Mode'!$B$17:$B$22,0),($B55-1)*2+IF($C55="POD",1,2)),0))) | M55: =IF($B55="",0,$K55*$L55) | N55: =IF($B55="",0,IFERROR(INDEX('Rates & Tables'!$C$61:$G$63,MATCH($I55,'Rates & Tables'!$J$61:$J$63,0),MATCH($H55,'Rates & Tables'!$C$60:$G$60,0)),0)) | O55: =IF($B55="",0,$M55*$N55) | P55: =IF($B55="","",$B55&"|"&$G55&"|"&$J55)
B56: 2 | C56: POD | D56: 1 | E56: 4 | F56: FSI Application Support | G56: MNT | H56: E2 | I56: ON | J56: PT | K56: 1 | L56: =IF($B56="",0,IF($C56="HZ",1,IFERROR(INDEX('Value Streams & Delivery Mode'!$D$17:$M$22,MATCH($D56,'Value Streams & Delivery Mode'!$B$17:$B$22,0),($B56-1)*2+IF($C56="POD",1,2)),0))) | M56: =IF($B56="",0,$K56*$L56) | N56: =IF($B56="",0,IFERROR(INDEX('Rates & Tables'!$C$61:$G$63,MATCH($I56,'Rates & Tables'!$J$61:$J$63,0),MATCH($H56,'Rates & Tables'!$C$60:$G$60,0)),0)) | O56: =IF($B56="",0,$M56*$N56) | P56: =IF($B56="","",$B56&"|"&$G56&"|"&$J56)
B57: 2 | C57: POD | D57: 1 | E57: 5 | F57: Pod lead / senior engineer | G57: DEV | H57: E3 | I57: ON | J57: FTC | K57: 1 | L57: =IF($B57="",0,IF($C57="HZ",1,IFERROR(INDEX('Value Streams & Delivery Mode'!$D$17:$M$22,MATCH($D57,'Value Streams & Delivery Mode'!$B$17:$B$22,0),($B57-1)*2+IF($C57="POD",1,2)),0))) | M57: =IF($B57="",0,$K57*$L57) | N57: =IF($B57="",0,IFERROR(INDEX('Rates & Tables'!$C$61:$G$63,MATCH($I57,'Rates & Tables'!$J$61:$J$63,0),MATCH($H57,'Rates & Tables'!$C$60:$G$60,0)),0)) | O57: =IF($B57="",0,$M57*$N57) | P57: =IF($B57="","",$B57&"|"&$G57&"|"&$J57)
B58: 2 | C58: POD | D58: 1 | E58: 6 | F58: Business Analyst (bilingual) | G58: BSA | H58: E2 | I58: ON | J58: FTC | K58: 0.5 | L58: =IF($B58="",0,IF($C58="HZ",1,IFERROR(INDEX('Value Streams & Delivery Mode'!$D$17:$M$22,MATCH($D58,'Value Streams & Delivery Mode'!$B$17:$B$22,0),($B58-1)*2+IF($C58="POD",1,2)),0))) | M58: =IF($B58="",0,$K58*$L58) | N58: =IF($B58="",0,IFERROR(INDEX('Rates & Tables'!$C$61:$G$63,MATCH($I58,'Rates & Tables'!$J$61:$J$63,0),MATCH($H58,'Rates & Tables'!$C$60:$G$60,0)),0)) | O58: =IF($B58="",0,$M58*$N58) | P58: =IF($B58="","",$B58&"|"&$G58&"|"&$J58)
B59: 2 | C59: POD | D59: 1 | E59: 7 | F59: Junior Java Developer — offshore | G59: DEV | H59: E2 | I59: OFF | J59: FTC | K59: 1 | L59: =IF($B59="",0,IF($C59="HZ",1,IFERROR(INDEX('Value Streams & Delivery Mode'!$D$17:$M$22,MATCH($D59,'Value Streams & Delivery Mode'!$B$17:$B$22,0),($B59-1)*2+IF($C59="POD",1,2)),0))) | M59: =IF($B59="",0,$K59*$L59) | N59: =IF($B59="",0,IFERROR(INDEX('Rates & Tables'!$C$61:$G$63,MATCH($I59,'Rates & Tables'!$J$61:$J$63,0),MATCH($H59,'Rates & Tables'!$C$60:$G$60,0)),0)) | O59: =IF($B59="",0,$M59*$N59) | P59: =IF($B59="","",$B59&"|"&$G59&"|"&$J59)
B60: 2 | C60: POD | D60: 1 | E60: 8 | F60: Quality Engineer (SDET) — offshore | G60: TEST | H60: E3 | I60: OFF | J60: FTC | K60: 1 | L60: =IF($B60="",0,IF($C60="HZ",1,IFERROR(INDEX('Value Streams & Delivery Mode'!$D$17:$M$22,MATCH($D60,'Value Streams & Delivery Mode'!$B$17:$B$22,0),($B60-1)*2+IF($C60="POD",1,2)),0))) | M60: =IF($B60="",0,$K60*$L60) | N60: =IF($B60="",0,IFERROR(INDEX('Rates & Tables'!$C$61:$G$63,MATCH($I60,'Rates & Tables'!$J$61:$J$63,0),MATCH($H60,'Rates & Tables'!$C$60:$G$60,0)),0)) | O60: =IF($B60="",0,$M60*$N60) | P60: =IF($B60="","",$B60&"|"&$G60&"|"&$J60)
B61: 2 | C61: POD | D61: 1 | E61: 9 | F61: Junior Application Support — offshore | G61: MNT | H61: E1 | I61: OFF | J61: FTC | K61: 0.5 | L61: =IF($B61="",0,IF($C61="HZ",1,IFERROR(INDEX('Value Streams & Delivery Mode'!$D$17:$M$22,MATCH($D61,'Value Streams & Delivery Mode'!$B$17:$B$22,0),($B61-1)*2+IF($C61="POD",1,2)),0))) | M61: =IF($B61="",0,$K61*$L61) | N61: =IF($B61="",0,IFERROR(INDEX('Rates & Tables'!$C$61:$G$63,MATCH($I61,'Rates & Tables'!$J$61:$J$63,0),MATCH($H61,'Rates & Tables'!$C$60:$G$60,0)),0)) | O61: =IF($B61="",0,$M61*$N61) | P61: =IF($B61="","",$B61&"|"&$G61&"|"&$J61)
B62: 2 | C62: POD | D62: 2 | E62: 1 | F62: MetLife Product Owner | G62: PM | H62: E4 | I62: ON | J62: FTE | K62: 1 | L62: =IF($B62="",0,IF($C62="HZ",1,IFERROR(INDEX('Value Streams & Delivery Mode'!$D$17:$M$22,MATCH($D62,'Value Streams & Delivery Mode'!$B$17:$B$22,0),($B62-1)*2+IF($C62="POD",1,2)),0))) | M62: =IF($B62="",0,$K62*$L62) | N62: =IF($B62="",0,IFERROR(INDEX('Rates & Tables'!$C$61:$G$63,MATCH($I62,'Rates & Tables'!$J$61:$J$63,0),MATCH($H62,'Rates & Tables'!$C$60:$G$60,0)),0)) | O62: =IF($B62="",0,$M62*$N62) | P62: =IF($B62="","",$B62&"|"&$G62&"|"&$J62)
B63: 2 | C63: POD | D63: 2 | E63: 2 | F63: MetLife Compliance SME | G63: BSA | H63: E4 | I63: ON | J63: FTE | K63: 0.5 | L63: =IF($B63="",0,IF($C63="HZ",1,IFERROR(INDEX('Value Streams & Delivery Mode'!$D$17:$M$22,MATCH($D63,'Value Streams & Delivery Mode'!$B$17:$B$22,0),($B63-1)*2+IF($C63="POD",1,2)),0))) | M63: =IF($B63="",0,$K63*$L63) | N63: =IF($B63="",0,IFERROR(INDEX('Rates & Tables'!$C$61:$G$63,MATCH($I63,'Rates & Tables'!$J$61:$J$63,0),MATCH($H63,'Rates & Tables'!$C$60:$G$60,0)),0)) | O63: =IF($B63="",0,$M63*$N63) | P63: =IF($B63="","",$B63&"|"&$G63&"|"&$J63)
...

Sheet Seat Planner — how
A1: How to build the seat plan — and what good looks like
A2: The model tells you how many people of each sourcing type you may have in each year. The anatomy decides who they are. That judgement is the practice team's, not the model's.
A4: THE SHAPE OF A ROW
B5: Year | C5: 1 to 5. A seat that exists in every year needs five rows — the anatomy changes as pods shrink.
B6: Unit | C6: POD, TEAM or HZ. POD and TEAM rows are multiplied by the unit counts on the Value Streams sheet. HZ rows are counted once — a horizontal function is not per-stream.
B7: Stream | C7: For POD and TEAM rows, the stream number from the Value Streams sheet (1 to 6). For HZ rows put the function: H1 for run and support, H2 for quality and assurance, H3 for architecture, release and enablement.
B8: Role | C8: MetLife's own taxonomy: BSA, DEV, TEST, MNT, PM, OTH. Use it exactly — every role-line reconciliation in this workbook depends on it.
B9: Role detail | C9: Your name for the seat. 'Pod lead / senior engineer', 'MGCC Platform Engineer', 'MetLife Product Owner'. This is what the practice team and the resource manager read.
