Workbook

Sheet FTE
A1: TOTAL FTE Year 1 | B1: 39
B2: Year1 | C2: Year2 | D2: Year3 | E2: Year4 | F2: Year5
A3: Onsite FTE (non-FSI) | B3: 3 | C3: 3 | D3: 1 | E3: 1 | F3: 1
A4: Onsite FTE (FSI) | B4: 6 | C4: 4 | D4: 2 | E4: 1 | F4: 0
A5: Onsite FTE (Landed) | B5: 7 | C5: 2 | D5: 1 | E5: 1 | F5: 1
A6: Onsite | B6: =B3+B4+B5 -> 16 | C6: =C3+C4+C5 -> 9 | D6: =D3+D4+D5 -> 4 | E6: =E3+E4+E5 -> 3 | F6: =F3+F4+F5 -> 2
A7: Offshore | B7: 10 | C7: 13 | D7: 14 | E7: 12 | F7: 12
A8: Total | B8: =SUM(B6:B7) -> 26 | C8: =SUM(C6:C7) -> 22 | D8: =SUM(D6:D7) -> 18 | E8: =SUM(E6:E7) -> 15 | F8: =SUM(F6:F7) -> 14

Sheet India Role Distribution
A2: India | B2: BSA | C2: 0.112 | D2: 1
A3: India | B3: Developer | C3: 0.398 | D3: 4
A4: India | B4: Tester | C4: 0.265 | D4: 3
A5: India | B5: Maintenance | C5: 0.108 | D5: 1
A6: India | B6: PM | C6: 0.074 | D6: 1
A7: India | B7: Other | C7: 0.043 | D7: 0
C13: =10*C3 -> 3.98

Sheet Onsite Role Distribution
C2: Year1 | D2: Year2 | E2: Year3 | F2: Year4 | G2: Year5
A3: Onsite | B3: PM | C3: 0 | D3: 0 | E3: 0 | F3: 0 | G3: 0
B4: Lead | C4: 1 | D4: 1 | E4: 0 | F4: 0 | G4: 0
B5: BSA | C5: 0 | D5: 0 | E5: 0 | F5: 0 | G5: 0
B6: Dev | C6: 1 | D6: 1 | E6: 1 | F6: 1 | G6: 0
B7: Tester | C7: 1 | D7: 1 | E7: 0 | F7: 0 | G7: 0
A8: Onsite-FSI | B8: PM
B9: Lead
B10: BSA | C10: 2 | D10: 1 | E10: 1 | F10: 0 | G10: 0
B11: Dev | C11: 4 | D11: 3 | E11: 1 | F11: 1 | G11: 0
B12: Tester
A13: Onsite-Landed | B13: PM
B14: Lead | C14: 1 | D14: 0 | E14: 0 | F14: 0 | G14: 0
B15: BSA | C15: 2 | D15: 1 | E15: 0 | F15: 0 | G15: 0
B16: Dev | C16: 2 | D16: 1 | E16: 1 | F16: 1 | G16: 1
B17: Tester | C17: 2 | D17: 0 | E17: 0 | F17: 0 | G17: 0

Sheet Productivity
B2: Year1 | C2: Year2 | D2: Year3 | E2: Year4 | F2: Year5
A3: Productivity | C3: 0.15 | D3: 0.34 | E3: 0.39 | F3: 0.44

Sheet Unit Distribution
A2: Unit | B2: Percentage | C2: Year2 | D2: Year3 | E2: Year4 | F2: Year5
A3: POD1 | B3: =7/23 -> 0.30434783 | C3: =6/18 -> 0.33333333 | D3: =7/14 -> 0.5 | E3: =6/12 -> 0.5 | F3: =6/12 -> 0.5
A4: POD2 | B4: =7/23 -> 0.30434783 | C4: =7/18 -> 0.38888889 | D4: =7/14 -> 0.5 | E4: =6/12 -> 0.5 | F4: =6/12 -> 0.5
A5: Team | B5: =9/23 -> 0.39130435 | C5: =5/18 -> 0.27777778 | D5: 0 | E5: 0 | F5: 0

Sheet Transfer
B2: Year1 | C2: Year2 | D2: Year3 | E2: Year4 | F2: Year5
A3: Transfer | E3: 0.15 | F3: 0.15

Sheet RLS
A25: Role | B25: Location | C25: RoleLocation | D25: M1 | E25: M2 | F25: M3 | G25: M4 | H25: M5 | I25: M6 | J25: M7 | K25: M8 | L25: M9 | M25: M10 | N25: M11 | O25: M12 | P25: M13 | Q25: M14 | R25: M15 | S25: M16 | T25: M17 | U25: M18 | V25: M19 | W25: M20 | X25: M21 | Y25: M22 | Z25: M23 | AA25: M24 | AB25: M25 | AC25: M26 | AD25: M27 | AE25: M28 | AF25: M29 | AG25: M30 | AH25: M31 | AI25: M32 | AJ25: M33 | AK25: M34 | AL25: M35 | AM25: M36 | AN25: M37 | AO25: M38 | AP25: M39 | AQ25: M40 | AR25: M41 | AS25: M42 | AT25: M43 | AU25: M44 | AV25: M45 | AW25: M46 | AX25: M47 | AY25: M48 | AZ25: M49 | BA25: M50 | BB25: M51 | BC25: M52 | BD25: M53 | BE25: M54 | BF25: M55 | BG25: M56 | BH25: M57 | BI25: M58 | BJ25: M59 | BK25: M60
A26: BSA | B26: India | C26: =A26&B26 -> BSAIndia | D26: =ROUND(FTE!$B$7*'India Role Distribution'!$C2,0) -> 1 | E26: =ROUND(FTE!$B$7*'India Role Distribution'!$C2,0) -> 1 | F26: =ROUND(FTE!$B$7*'India Role Distribution'!$C2,0) -> 1 | G26: =ROUND(FTE!$B$7*'India Role Distribution'!$C2,0) -> 1 | H26: =ROUND(FTE!$B$7*'India Role Distribution'!$C2,0) -> 1 | I26: =ROUND(FTE!$B$7*'India Role Distribution'!$C2,0) -> 1 | J26: =ROUND(FTE!$B$7*'India Role Distribution'!$C2,0) -> 1 | K26: =ROUND(FTE!$B$7*'India Role Distribution'!$C2,0) -> 1 | ... O26: =ROUND(FTE!$B$7*'India Role Distribution'!$C2,0) -> 1 | P26: =FTE!$C$7-SUM(P27:P31) -> 2 | Q26: =FTE!$C$7-SUM(Q27:Q31) -> 2 | R26: =FTE!$C$7-SUM(R27:R31) -> 2 | S26: =FTE!$C$7-SUM(S27:S31) -> 2 | T26: =FTE!$C$7-SUM(T27:T31) -> 2 | U26: =FTE!$C$7-SUM(U27:U31) -> 2 | V26: =FTE!$C$7-SUM(V27:V31) -> 2 | W26: =FTE!$C$7-SUM(W27:W31) -> 2 | ... AA26: =FTE!$C$7-SUM(AA27:AA31) -> 2 | AB26: =ROUND(FTE!$D$7*'India Role Distribution'!$C2,0) -> 2 | AC26: =ROUND(FTE!$D$7*'India Role Distribution'!$C2,0) -> 2 | AD26: =ROUND(FTE!$D$7*'India Role Distribution'!$C2,0) -> 2 | AE26: =ROUND(FTE!$D$7*'India Role Distribution'!$C2,0) -> 2 | AF26: =ROUND(FTE!$D$7*'India Role Distribution'!$C2,0) -> 2 | AG26: =ROUND(FTE!$D$7*'India Role Distribution'!$C2,0) -> 2 | AH26: =ROUND(FTE!$D$7*'India Role Distribution'!$C2,0) -> 2 | AI26: =ROUND(FTE!$D$7*'India Role Distribution'!$C2,0) -> 2 | ... AM26: =ROUND(FTE!$D$7*'India Role Distribution'!$C2,0) -> 2 | AN26: =ROUND(FTE!$E$7*'India Role Distribution'!$C2,0) -> 1 | AO26: =ROUND(FTE!$E$7*'India Role Distribution'!$C2,0) -> 1 | AP26: =ROUND(FTE!$E$7*'India Role Distribution'!$C2,0) -> 1 | AQ26: =ROUND(FTE!$E$7*'India Role Distribution'!$C2,0) -> 1 | AR26: =ROUND(FTE!$E$7*'India Role Distribution'!$C2,0) -> 1 | AS26: =ROUND(FTE!$E$7*'India Role Distribution'!$C2,0) -> 1 | AT26: =ROUND(FTE!$E$7*'India Role Distribution'!$C2,0) -> 1 | AU26: =ROUND(FTE!$E$7*'India Role Distribution'!$C2,0) -> 1 | ... AY26: =ROUND(FTE!$E$7*'India Role Distribution'!$C2,0) -> 1 | AZ26: 2 | BA26: 2 | BB26: 2 | BC26: 2 | BD26: 2 | BE26: 2 | BF26: 2 | BG26: 2 | BH26: 2 | BI26: 2 | BJ26: 2 | BK26: 2
A27: Dev | B27: India | C27: =A27&B27 -> DevIndia | D27: =ROUND(FTE!$B$7*'India Role Distribution'!$C3,0) -> 4 | E27: =ROUND(FTE!$B$7*'India Role Distribution'!$C3,0) -> 4 | F27: =ROUND(FTE!$B$7*'India Role Distribution'!$C3,0) -> 4 | G27: =ROUND(FTE!$B$7*'India Role Distribution'!$C3,0) -> 4 | H27: =ROUND(FTE!$B$7*'India Role Distribution'!$C3,0) -> 4 | I27: =ROUND(FTE!$B$7*'India Role Distribution'!$C3,0) -> 4 | J27: =ROUND(FTE!$B$7*'India Role Distribution'!$C3,0) -> 4 | K27: =ROUND(FTE!$B$7*'India Role Distribution'!$C3,0) -> 4 | ... O27: =ROUND(FTE!$B$7*'India Role Distribution'!$C3,0) -> 4 | P27: =ROUND(FTE!$C$7*'India Role Distribution'!$C3,0) -> 5 | Q27: =ROUND(FTE!$C$7*'India Role Distribution'!$C3,0) -> 5 | R27: =ROUND(FTE!$C$7*'India Role Distribution'!$C3,0) -> 5 | S27: =ROUND(FTE!$C$7*'India Role Distribution'!$C3,0) -> 5 | T27: =ROUND(FTE!$C$7*'India Role Distribution'!$C3,0) -> 5 | U27: =ROUND(FTE!$C$7*'India Role Distribution'!$C3,0) -> 5 | V27: =ROUND(FTE!$C$7*'India Role Distribution'!$C3,0) -> 5 | W27: =ROUND(FTE!$C$7*'India Role Distribution'!$C3,0) -> 5 | ... AA27: =ROUND(FTE!$C$7*'India Role Distribution'!$C3,0) -> 5 | AB27: =FTE!$D$7-(AB26+AB28+AB29+AB30+AB31) -> 4 | AC27: =FTE!$D$7-(AC26+AC28+AC29+AC30+AC31) -> 4 | AD27: =FTE!$D$7-(AD26+AD28+AD29+AD30+AD31) -> 4 | AE27: =FTE!$D$7-(AE26+AE28+AE29+AE30+AE31) -> 4 | AF27: =FTE!$D$7-(AF26+AF28+AF29+AF30+AF31) -> 4 | AG27: =FTE!$D$7-(AG26+AG28+AG29+AG30+AG31) -> 4 | AH27: =FTE!$D$7-(AH26+AH28+AH29+AH30+AH31) -> 4 | AI27: =FTE!$D$7-(AI26+AI28+AI29+AI30+AI31) -> 4 | ... AM27: =FTE!$D$7-(AM26+AM28+AM29+AM30+AM31) -> 4 | AN27: =ROUND(FTE!$E$7*'India Role Distribution'!$C3,0) -> 5 | AO27: =ROUND(FTE!$E$7*'India Role Distribution'!$C3,0) -> 5 | AP27: =ROUND(FTE!$E$7*'India Role Distribution'!$C3,0) -> 5 | AQ27: =ROUND(FTE!$E$7*'India Role Distribution'!$C3,0) -> 5 | AR27: =ROUND(FTE!$E$7*'India Role Distribution'!$C3,0) -> 5 | AS27: =ROUND(FTE!$E$7*'India Role Distribution'!$C3,0) -> 5 | AT27: =ROUND(FTE!$E$7*'India Role Distribution'!$C3,0) -> 5 | AU27: =ROUND(FTE!$E$7*'India Role Distribution'!$C3,0) -> 5 | ... AY27: =ROUND(FTE!$E$7*'India Role Distribution'!$C3,0) -> 5 | AZ27: 5 | BA27: 5 | BB27: 5 | BC27: 5 | BD27: 5 | BE27: 5 | BF27: 5 | BG27: 5 | BH27: 5 | BI27: 5 | BJ27: 5 | BK27: 5
A28: Tester | B28: India | C28: =A28&B28 -> TesterIndia | D28: =ROUND(FTE!$B$7*'India Role Distribution'!$C4,0) -> 3 | E28: =ROUND(FTE!$B$7*'India Role Distribution'!$C4,0) -> 3 | F28: =ROUND(FTE!$B$7*'India Role Distribution'!$C4,0) -> 3 | G28: =ROUND(FTE!$B$7*'India Role Distribution'!$C4,0) -> 3 | H28: =ROUND(FTE!$B$7*'India Role Distribution'!$C4,0) -> 3 | I28: =ROUND(FTE!$B$7*'India Role Distribution'!$C4,0) -> 3 | J28: =ROUND(FTE!$B$7*'India Role Distribution'!$C4,0) -> 3 | K28: =ROUND(FTE!$B$7*'India Role Distribution'!$C4,0) -> 3 | ... O28: =ROUND(FTE!$B$7*'India Role Distribution'!$C4,0) -> 3 | P28: =ROUND(FTE!$C$7*'India Role Distribution'!$C4,0) -> 3 | Q28: =ROUND(FTE!$C$7*'India Role Distribution'!$C4,0) -> 3 | R28: =ROUND(FTE!$C$7*'India Role Distribution'!$C4,0) -> 3 | S28: =ROUND(FTE!$C$7*'India Role Distribution'!$C4,0) -> 3 | T28: =ROUND(FTE!$C$7*'India Role Distribution'!$C4,0) -> 3 | U28: =ROUND(FTE!$C$7*'India Role Distribution'!$C4,0) -> 3 | V28: =ROUND(FTE!$C$7*'India Role Distribution'!$C4,0) -> 3 | W28: =ROUND(FTE!$C$7*'India Role Distribution'!$C4,0) -> 3 | ... AA28: =ROUND(FTE!$C$7*'India Role Distribution'!$C4,0) -> 3 | AB28: =ROUND(FTE!$D$7*'India Role Distribution'!$C4,0) -> 4 | AC28: =ROUND(FTE!$D$7*'India Role Distribution'!$C4,0) -> 4 | AD28: =ROUND(FTE!$D$7*'India Role Distribution'!$C4,0) -> 4 | AE28: =ROUND(FTE!$D$7*'India Role Distribution'!$C4,0) -> 4 | AF28: =ROUND(FTE!$D$7*'India Role Distribution'!$C4,0) -> 4 | AG28: =ROUND(FTE!$D$7*'India Role Distribution'!$C4,0) -> 4 | AH28: =ROUND(FTE!$D$7*'India Role Distribution'!$C4,0) -> 4 | AI28: =ROUND(FTE!$D$7*'India Role Distribution'!$C4,0) -> 4 | ... AM28: =ROUND(FTE!$D$7*'India Role Distribution'!$C4,0) -> 4 | AN28: =ROUND(FTE!$E$7*'India Role Distribution'!$C4,0) -> 3 | AO28: =ROUND(FTE!$E$7*'India Role Distribution'!$C4,0) -> 3 | AP28: =ROUND(FTE!$E$7*'India Role Distribution'!$C4,0) -> 3 | AQ28: =ROUND(FTE!$E$7*'India Role Distribution'!$C4,0) -> 3 | AR28: =ROUND(FTE!$E$7*'India Role Distribution'!$C4,0) -> 3 | AS28: =ROUND(FTE!$E$7*'India Role Distribution'!$C4,0) -> 3 | AT28: =ROUND(FTE!$E$7*'India Role Distribution'!$C4,0) -> 3 | AU28: =ROUND(FTE!$E$7*'India Role Distribution'!$C4,0) -> 3 | ... AY28: =ROUND(FTE!$E$7*'India Role Distribution'!$C4,0) -> 3 | AZ28: 3 | BA28: =ROUND(FTE!$F$7*'India Role Distribution'!$C4,0) -> 3 | BB28: =ROUND(FTE!$F$7*'India Role Distribution'!$C4,0) -> 3 | BC28: =ROUND(FTE!$F$7*'India Role Distribution'!$C4,0) -> 3 | BD28: =ROUND(FTE!$F$7*'India Role Distribution'!$C4,0) -> 3 | BE28: =ROUND(FTE!$F$7*'India Role Distribution'!$C4,0) -> 3 | BF28: =ROUND(FTE!$F$7*'India Role Distribution'!$C4,0) -> 3 | BG28: =ROUND(FTE!$F$7*'India Role Distribution'!$C4,0) -> 3 | BH28: =ROUND(FTE!$F$7*'India Role Distribution'!$C4,0) -> 3 | ... BK28: =ROUND(FTE!$F$7*'India Role Distribution'!$C4,0) -> 3
A29: Maintenance | B29: India | C29: =A29&B29 -> MaintenanceIndia | D29: =ROUND(FTE!$B$7*'India Role Distribution'!$C5,0) -> 1 | E29: =ROUND(FTE!$B$7*'India Role Distribution'!$C5,0) -> 1 | F29: =ROUND(FTE!$B$7*'India Role Distribution'!$C5,0) -> 1 | G29: =ROUND(FTE!$B$7*'India Role Distribution'!$C5,0) -> 1 | H29: =ROUND(FTE!$B$7*'India Role Distribution'!$C5,0) -> 1 | I29: =ROUND(FTE!$B$7*'India Role Distribution'!$C5,0) -> 1 | J29: =ROUND(FTE!$B$7*'India Role Distribution'!$C5,0) -> 1 | K29: =ROUND(FTE!$B$7*'India Role Distribution'!$C5,0) -> 1 | ... O29: =ROUND(FTE!$B$7*'India Role Distribution'!$C5,0) -> 1 | P29: =ROUND(FTE!$C$7*'India Role Distribution'!$C5,0) -> 1 | Q29: =ROUND(FTE!$C$7*'India Role Distribution'!$C5,0) -> 1 | R29: =ROUND(FTE!$C$7*'India Role Distribution'!$C5,0) -> 1 | S29: =ROUND(FTE!$C$7*'India Role Distribution'!$C5,0) -> 1 | T29: =ROUND(FTE!$C$7*'India Role Distribution'!$C5,0) -> 1 | U29: =ROUND(FTE!$C$7*'India Role Distribution'!$C5,0) -> 1 | V29: =ROUND(FTE!$C$7*'India Role Distribution'!$C5,0) -> 1 | W29: =ROUND(FTE!$C$7*'India Role Distribution'!$C5,0) -> 1 | ... AA29: =ROUND(FTE!$C$7*'India Role Distribution'!$C5,0) -> 1 | AB29: =ROUND(FTE!$D$7*'India Role Distribution'!$C5,0) -> 2 | AC29: =ROUND(FTE!$D$7*'India Role Distribution'!$C5,0) -> 2 | AD29: =ROUND(FTE!$D$7*'India Role Distribution'!$C5,0) -> 2 | AE29: =ROUND(FTE!$D$7*'India Role Distribution'!$C5,0) -> 2 | AF29: =ROUND(FTE!$D$7*'India Role Distribution'!$C5,0) -> 2 | AG29: =ROUND(FTE!$D$7*'India Role Distribution'!$C5,0) -> 2 | AH29: =ROUND(FTE!$D$7*'India Role Distribution'!$C5,0) -> 2 | AI29: =ROUND(FTE!$D$7*'India Role Distribution'!$C5,0) -> 2 | ... AM29: =ROUND(FTE!$D$7*'India Role Distribution'!$C5,0) -> 2 | AN29: =ROUND(FTE!$E$7*'India Role Distribution'!$C5,0) -> 1 | AO29: =ROUND(FTE!$E$7*'India Role Distribution'!$C5,0) -> 1 | AP29: =ROUND(FTE!$E$7*'India Role Distribution'!$C5,0) -> 1 | AQ29: =ROUND(FTE!$E$7*'India Role Distribution'!$C5,0) -> 1 | AR29: =ROUND(FTE!$E$7*'India Role Distribution'!$C5,0) -> 1 | AS29: =ROUND(FTE!$E$7*'India Role Distribution'!$C5,0) -> 1 | AT29: =ROUND(FTE!$E$7*'India Role Distribution'!$C5,0) -> 1 | AU29: =ROUND(FTE!$E$7*'India Role Distribution'!$C5,0) -> 1 | ... AY29: =ROUND(FTE!$E$7*'India Role Distribution'!$C5,0) -> 1 | AZ29: 1 | BA29: =ROUND(FTE!$F$7*'India Role Distribution'!$C5,0) -> 1 | BB29: =ROUND(FTE!$F$7*'India Role Distribution'!$C5,0) -> 1 | BC29: =ROUND(FTE!$F$7*'India Role Distribution'!$C5,0) -> 1 | BD29: =ROUND(FTE!$F$7*'India Role Distribution'!$C5,0) -> 1 | BE29: =ROUND(FTE!$F$7*'India Role Distribution'!$C5,0) -> 1 | BF29: =ROUND(FTE!$F$7*'India Role Distribution'!$C5,0) -> 1 | BG29: =ROUND(FTE!$F$7*'India Role Distribution'!$C5,0) -> 1 | BH29: =ROUND(FTE!$F$7*'India Role Distribution'!$C5,0) -> 1 | ... BK29: =ROUND(FTE!$F$7*'India Role Distribution'!$C5,0) -> 1
A30: PM | B30: India | C30: =A30&B30 -> PMIndia | D30: =FTE!$B$7-SUM(D26:D29,D31) -> 0 | E30: =FTE!$B$7-SUM(E26:E29,E31) -> 0 | F30: =FTE!$B$7-SUM(F26:F29,F31) -> 0 | G30: =FTE!$B$7-SUM(G26:G29,G31) -> 0 | H30: =FTE!$B$7-SUM(H26:H29,H31) -> 0 | I30: =FTE!$B$7-SUM(I26:I29,I31) -> 0 | J30: =FTE!$B$7-SUM(J26:J29,J31) -> 0 | K30: =FTE!$B$7-SUM(K26:K29,K31) -> 0 | ... O30: =FTE!$B$7-SUM(O26:O29,O31) -> 0 | P30: =ROUND(FTE!$C$7*'India Role Distribution'!$C6,0) -> 1 | Q30: =ROUND(FTE!$C$7*'India Role Distribution'!$C6,0) -> 1 | R30: =ROUND(FTE!$C$7*'India Role Distribution'!$C6,0) -> 1 | S30: =ROUND(FTE!$C$7*'India Role Distribution'!$C6,0) -> 1 | T30: =ROUND(FTE!$C$7*'India Role Distribution'!$C6,0) -> 1 | U30: =ROUND(FTE!$C$7*'India Role Distribution'!$C6,0) -> 1 | V30: =ROUND(FTE!$C$7*'India Role Distribution'!$C6,0) -> 1 | W30: =ROUND(FTE!$C$7*'India Role Distribution'!$C6,0) -> 1 | ... AA30: =ROUND(FTE!$C$7*'India Role Distribution'!$C6,0) -> 1 | AB30: =ROUND(FTE!$D$7*'India Role Distribution'!$C6,0) -> 1 | AC30: =ROUND(FTE!$D$7*'India Role Distribution'!$C6,0) -> 1 | AD30: =ROUND(FTE!$D$7*'India Role Distribution'!$C6,0) -> 1 | AE30: =ROUND(FTE!$D$7*'India Role Distribution'!$C6,0) -> 1 | AF30: =ROUND(FTE!$D$7*'India Role Distribution'!$C6,0) -> 1 | AG30: =ROUND(FTE!$D$7*'India Role Distribution'!$C6,0) -> 1 | AH30: =ROUND(FTE!$D$7*'India Role Distribution'!$C6,0) -> 1 | AI30: =ROUND(FTE!$D$7*'India Role Distribution'!$C6,0) -> 1 | ... AM30: =ROUND(FTE!$D$7*'India Role Distribution'!$C6,0) -> 1 | AN30: =ROUND(FTE!$E$7*'India Role Distribution'!$C6,0) -> 1 | AO30: =ROUND(FTE!$E$7*'India Role Distribution'!$C6,0) -> 1 | AP30: =ROUND(FTE!$E$7*'India Role Distribution'!$C6,0) -> 1 | AQ30: =ROUND(FTE!$E$7*'India Role Distribution'!$C6,0) -> 1 | AR30: =ROUND(FTE!$E$7*'India Role Distribution'!$C6,0) -> 1 | AS30: =ROUND(FTE!$E$7*'India Role Distribution'!$C6,0) -> 1 | AT30: =ROUND(FTE!$E$7*'India Role Distribution'!$C6,0) -> 1 | AU30: =ROUND(FTE!$E$7*'India Role Distribution'!$C6,0) -> 1 | ... AY30: =ROUND(FTE!$E$7*'India Role Distribution'!$C6,0) -> 1 | AZ30: 0 | BA30: 0 | BB30: 0 | BC30: 0 | BD30: 0 | BE30: 0 | BF30: 0 | BG30: 0 | BH30: 0 | BI30: 0 | BJ30: 0 | BK30: 0
A31: Lead | B31: India | C31: =A31&B31 -> LeadIndia | D31: 1 | E31: 1 | F31: 1 | G31: 1 | H31: 1 | I31: 1 | J31: 1 | K31: 1 | L31: 1 | M31: 1 | N31: 1 | O31: 1 | P31: =ROUND(FTE!$C$7*'India Role Distribution'!$C7,0) -> 1 | Q31: =ROUND(FTE!$C$7*'India Role Distribution'!$C7,0) -> 1 | R31: =ROUND(FTE!$C$7*'India Role Distribution'!$C7,0) -> 1 | S31: =ROUND(FTE!$C$7*'India Role Distribution'!$C7,0) -> 1 | T31: =ROUND(FTE!$C$7*'India Role Distribution'!$C7,0) -> 1 | U31: =ROUND(FTE!$C$7*'India Role Distribution'!$C7,0) -> 1 | V31: =ROUND(FTE!$C$7*'India Role Distribution'!$C7,0) -> 1 | W31: =ROUND(FTE!$C$7*'India Role Distribution'!$C7,0) -> 1 | ... AA31: =ROUND(FTE!$C$7*'India Role Distribution'!$C7,0) -> 1 | AB31: =ROUND(FTE!$D$7*'India Role Distribution'!$C7,0) -> 1 | AC31: =ROUND(FTE!$D$7*'India Role Distribution'!$C7,0) -> 1 | AD31: =ROUND(FTE!$D$7*'India Role Distribution'!$C7,0) -> 1 | AE31: =ROUND(FTE!$D$7*'India Role Distribution'!$C7,0) -> 1 | AF31: =ROUND(FTE!$D$7*'India Role Distribution'!$C7,0) -> 1 | AG31: =ROUND(FTE!$D$7*'India Role Distribution'!$C7,0) -> 1 | AH31: =ROUND(FTE!$D$7*'India Role Distribution'!$C7,0) -> 1 | AI31: =ROUND(FTE!$D$7*'India Role Distribution'!$C7,0) -> 1 | ... AM31: =ROUND(FTE!$D$7*'India Role Distribution'!$C7,0) -> 1 | AN31: =ROUND(FTE!$E$7*'India Role Distribution'!$C7,0) -> 1 | AO31: =ROUND(FTE!$E$7*'India Role Distribution'!$C7,0) -> 1 | AP31: =ROUND(FTE!$E$7*'India Role Distribution'!$C7,0) -> 1 | AQ31: =ROUND(FTE!$E$7*'India Role Distribution'!$C7,0) -> 1 | AR31: =ROUND(FTE!$E$7*'India Role Distribution'!$C7,0) -> 1 | AS31: =ROUND(FTE!$E$7*'India Role Distribution'!$C7,0) -> 1 | AT31: =ROUND(FTE!$E$7*'India Role Distribution'!$C7,0) -> 1 | AU31: =ROUND(FTE!$E$7*'India Role Distribution'!$C7,0) -> 1 | ... AY31: =ROUND(FTE!$E$7*'India Role Distribution'!$C7,0) -> 1 | AZ31: 1 | BA31: =ROUND(FTE!$F$7*'India Role Distribution'!$C7,0) -> 1 | BB31: =ROUND(FTE!$F$7*'India Role Distribution'!$C7,0) -> 1 | BC31: =ROUND(FTE!$F$7*'India Role Distribution'!$C7,0) -> 1 | BD31: =ROUND(FTE!$F$7*'India Role Distribution'!$C7,0) -> 1 | BE31: =ROUND(FTE!$F$7*'India Role Distribution'!$C7,0) -> 1 | BF31: =ROUND(FTE!$F$7*'India Role Distribution'!$C7,0) -> 1 | BG31: =ROUND(FTE!$F$7*'India Role Distribution'!$C7,0) -> 1 | BH31: =ROUND(FTE!$F$7*'India Role Distribution'!$C7,0) -> 1 | ... BK31: =ROUND(FTE!$F$7*'India Role Distribution'!$C7,0) -> 1
A32: BSA | B32: Onsite | C32: =A32&B32 -> BSAOnsite | D32: =VLOOKUP($A32,'Onsite Role Distribution'!$B$3:$G$7,2,FALSE)+VLOOKUP($A32,'Onsite Role Distribution'!$B$8:$G$12,2,FALSE) -> 2 | E32: =VLOOKUP($A32,'Onsite Role Distribution'!$B$3:$G$7,2,FALSE)+VLOOKUP($A32,'Onsite Role Distribution'!$B$8:$G$12,2,FALSE) -> 2 | F32: =VLOOKUP($A32,'Onsite Role Distribution'!$B$3:$G$7,2,FALSE)+VLOOKUP($A32,'Onsite Role Distribution'!$B$8:$G$12,2,FALSE) -> 2 | G32: =VLOOKUP($A32,'Onsite Role Distribution'!$B$3:$G$7,2,FALSE)+VLOOKUP($A32,'Onsite Role Distribution'!$B$8:$G$12,2,FALSE) -> 2 | H32: =VLOOKUP($A32,'Onsite Role Distribution'!$B$3:$G$7,2,FALSE)+VLOOKUP($A32,'Onsite Role Distribution'!$B$8:$G$12,2,FALSE) -> 2 | I32: =VLOOKUP($A32,'Onsite Role Distribution'!$B$3:$G$7,2,FALSE)+VLOOKUP($A32,'Onsite Role Distribution'!$B$8:$G$12,2,FALSE) -> 2 | J32: =VLOOKUP($A32,'Onsite Role Distribution'!$B$3:$G$7,2,FALSE)+VLOOKUP($A32,'Onsite Role Distribution'!$B$8:$G$12,2,FALSE) -> 2 | K32: =VLOOKUP($A32,'Onsite Role Distribution'!$B$3:$G$7,2,FALSE)+VLOOKUP($A32,'Onsite Role Distribution'!$B$8:$G$12,2,FALSE) -> 2 | ... O32: =VLOOKUP($A32,'Onsite Role Distribution'!$B$3:$G$7,2,FALSE)+VLOOKUP($A32,'Onsite Role Distribution'!$B$8:$G$12,2,FALSE) -> 2 | P32: =VLOOKUP($A32,'Onsite Role Distribution'!$B$3:$G$7,3,FALSE)+VLOOKUP($A32,'Onsite Role Distribution'!$B$8:$G$12,3,FALSE) -> 1 | Q32: =VLOOKUP($A32,'Onsite Role Distribution'!$B$3:$G$7,3,FALSE)+VLOOKUP($A32,'Onsite Role Distribution'!$B$8:$G$12,3,FALSE) -> 1 | R32: =VLOOKUP($A32,'Onsite Role Distribution'!$B$3:$G$7,3,FALSE)+VLOOKUP($A32,'Onsite Role Distribution'!$B$8:$G$12,3,FALSE) -> 1 | S32: =VLOOKUP($A32,'Onsite Role Distribution'!$B$3:$G$7,3,FALSE)+VLOOKUP($A32,'Onsite Role Distribution'!$B$8:$G$12,3,FALSE) -> 1 | T32: =VLOOKUP($A32,'Onsite Role Distribution'!$B$3:$G$7,3,FALSE)+VLOOKUP($A32,'Onsite Role Distribution'!$B$8:$G$12,3,FALSE) -> 1 | U32: =VLOOKUP($A32,'Onsite Role Distribution'!$B$3:$G$7,3,FALSE)+VLOOKUP($A32,'Onsite Role Distribution'!$B$8:$G$12,3,FALSE) -> 1 | V32: =VLOOKUP($A32,'Onsite Role Distribution'!$B$3:$G$7,3,FALSE)+VLOOKUP($A32,'Onsite Role Distribution'!$B$8:$G$12,3,FALSE) -> 1 | W32: =VLOOKUP($A32,'Onsite Role Distribution'!$B$3:$G$7,3,FALSE)+VLOOKUP($A32,'Onsite Role Distribution'!$B$8:$G$12,3,FALSE) -> 1 | ... AA32: =VLOOKUP($A32,'Onsite Role Distribution'!$B$3:$G$7,3,FALSE)+VLOOKUP($A32,'Onsite Role Distribution'!$B$8:$G$12,3,FALSE) -> 1 | AB32: =VLOOKUP($A32,'Onsite Role Distribution'!$B$3:$G$7,4,FALSE)+VLOOKUP($A32,'Onsite Role Distribution'!$B$8:$G$12,4,FALSE) -> 1 | AC32: =VLOOKUP($A32,'Onsite Role Distribution'!$B$3:$G$7,4,FALSE)+VLOOKUP($A32,'Onsite Role Distribution'!$B$8:$G$12,4,FALSE) -> 1 | AD32: =VLOOKUP($A32,'Onsite Role Distribution'!$B$3:$G$7,4,FALSE)+VLOOKUP($A32,'Onsite Role Distribution'!$B$8:$G$12,4,FALSE) -> 1 | AE32: =VLOOKUP($A32,'Onsite Role Distribution'!$B$3:$G$7,4,FALSE)+VLOOKUP($A32,'Onsite Role Distribution'!$B$8:$G$12,4,FALSE) -> 1 | AF32: =VLOOKUP($A32,'Onsite Role Distribution'!$B$3:$G$7,4,FALSE)+VLOOKUP($A32,'Onsite Role Distribution'!$B$8:$G$12,4,FALSE) -> 1 | AG32: =VLOOKUP($A32,'Onsite Role Distribution'!$B$3:$G$7,4,FALSE)+VLOOKUP($A32,'Onsite Role Distribution'!$B$8:$G$12,4,FALSE) -> 1 | AH32: =VLOOKUP($A32,'Onsite Role Distribution'!$B$3:$G$7,4,FALSE)+VLOOKUP($A32,'Onsite Role Distribution'!$B$8:$G$12,4,FALSE) -> 1 | AI32: =VLOOKUP($A32,'Onsite Role Distribution'!$B$3:$G$7,4,FALSE)+VLOOKUP($A32,'Onsite Role Distribution'!$B$8:$G$12,4,FALSE) -> 1 | ... AM32: =VLOOKUP($A32,'Onsite Role Distribution'!$B$3:$G$7,4,FALSE)+VLOOKUP($A32,'Onsite Role Distribution'!$B$8:$G$12,4,FALSE) -> 1 | AN32: =VLOOKUP($A32,'Onsite Role Distribution'!$B$3:$G$7,5,FALSE)+VLOOKUP($A32,'Onsite Role Distribution'!$B$8:$G$12,5,FALSE) -> 0 | AO32: =VLOOKUP($A32,'Onsite Role Distribution'!$B$3:$G$7,5,FALSE)+VLOOKUP($A32,'Onsite Role Distribution'!$B$8:$G$12,5,FALSE) -> 0 | AP32: =VLOOKUP($A32,'Onsite Role Distribution'!$B$3:$G$7,5,FALSE)+VLOOKUP($A32,'Onsite Role Distribution'!$B$8:$G$12,5,FALSE) -> 0 | AQ32: =VLOOKUP($A32,'Onsite Role Distribution'!$B$3:$G$7,5,FALSE)+VLOOKUP($A32,'Onsite Role Distribution'!$B$8:$G$12,5,FALSE) -> 0 | AR32: =VLOOKUP($A32,'Onsite Role Distribution'!$B$3:$G$7,5,FALSE)+VLOOKUP($A32,'Onsite Role Distribution'!$B$8:$G$12,5,FALSE) -> 0 | AS32: =VLOOKUP($A32,'Onsite Role Distribution'!$B$3:$G$7,5,FALSE)+VLOOKUP($A32,'Onsite Role Distribution'!$B$8:$G$12,5,FALSE) -> 0 | AT32: =VLOOKUP($A32,'Onsite Role Distribution'!$B$3:$G$7,5,FALSE)+VLOOKUP($A32,'Onsite Role Distribution'!$B$8:$G$12,5,FALSE) -> 0 | AU32: =VLOOKUP($A32,'Onsite Role Distribution'!$B$3:$G$7,5,FALSE)+VLOOKUP($A32,'Onsite Role Distribution'!$B$8:$G$12,5,FALSE) -> 0 | ... AY32: =VLOOKUP($A32,'Onsite Role Distribution'!$B$3:$G$7,5,FALSE)+VLOOKUP($A32,'Onsite Role Distribution'!$B$8:$G$12,5,FALSE) -> 0 | AZ32: 0 | BA32: =VLOOKUP($A32,'Onsite Role Distribution'!$B$3:$G$7,6,FALSE)+VLOOKUP($A32,'Onsite Role Distribution'!$B$8:$G$12,6,FALSE) -> 0 | BB32: =VLOOKUP($A32,'Onsite Role Distribution'!$B$3:$G$7,6,FALSE)+VLOOKUP($A32,'Onsite Role Distribution'!$B$8:$G$12,6,FALSE) -> 0 | BC32: =VLOOKUP($A32,'Onsite Role Distribution'!$B$3:$G$7,6,FALSE)+VLOOKUP($A32,'Onsite Role Distribution'!$B$8:$G$12,6,FALSE) -> 0 | BD32: =VLOOKUP($A32,'Onsite Role Distribution'!$B$3:$G$7,6,FALSE)+VLOOKUP($A32,'Onsite Role Distribution'!$B$8:$G$12,6,FALSE) -> 0 | BE32: =VLOOKUP($A32,'Onsite Role Distribution'!$B$3:$G$7,6,FALSE)+VLOOKUP($A32,'Onsite Role Distribution'!$B$8:$G$12,6,FALSE) -> 0 | BF32: =VLOOKUP($A32,'Onsite Role Distribution'!$B$3:$G$7,6,FALSE)+VLOOKUP($A32,'Onsite Role Distribution'!$B$8:$G$12,6,FALSE) -> 0 | BG32: =VLOOKUP($A32,'Onsite Role Distribution'!$B$3:$G$7,6,FALSE)+VLOOKUP($A32,'Onsite Role Distribution'!$B$8:$G$12,6,FALSE) -> 0 | BH32: =VLOOKUP($A32,'Onsite Role Distribution'!$B$3:$G$7,6,FALSE)+VLOOKUP($A32,'Onsite Role Distribution'!$B$8:$G$12,6,FALSE) -> 0 | ... BK32: =VLOOKUP($A32,'Onsite Role Distribution'!$B$3:$G$7,6,FALSE)+VLOOKUP($A32,'Onsite Role Distribution'!$B$8:$G$12,6,FALSE) -> 0
A33: Dev | B33: Onsite | C33: =A33&B33 -> DevOnsite | D33: =VLOOKUP($A33,'Onsite Role Distribution'!$B$3:$G$7,2,FALSE)+VLOOKUP($A33,'Onsite Role Distribution'!$B$8:$G$12,2,FALSE) -> 5 | E33: =VLOOKUP($A33,'Onsite Role Distribution'!$B$3:$G$7,2,FALSE)+VLOOKUP($A33,'Onsite Role Distribution'!$B$8:$G$12,2,FALSE) -> 5 | F33: =VLOOKUP($A33,'Onsite Role Distribution'!$B$3:$G$7,2,FALSE)+VLOOKUP($A33,'Onsite Role Distribution'!$B$8:$G$12,2,FALSE) -> 5 | G33: =VLOOKUP($A33,'Onsite Role Distribution'!$B$3:$G$7,2,FALSE)+VLOOKUP($A33,'Onsite Role Distribution'!$B$8:$G$12,2,FALSE) -> 5 | H33: =VLOOKUP($A33,'Onsite Role Distribution'!$B$3:$G$7,2,FALSE)+VLOOKUP($A33,'Onsite Role Distribution'!$B$8:$G$12,2,FALSE) -> 5 | I33: =VLOOKUP($A33,'Onsite Role Distribution'!$B$3:$G$7,2,FALSE)+VLOOKUP($A33,'Onsite Role Distribution'!$B$8:$G$12,2,FALSE) -> 5 | J33: =VLOOKUP($A33,'Onsite Role Distribution'!$B$3:$G$7,2,FALSE)+VLOOKUP($A33,'Onsite Role Distribution'!$B$8:$G$12,2,FALSE) -> 5 | K33: =VLOOKUP($A33,'Onsite Role Distribution'!$B$3:$G$7,2,FALSE)+VLOOKUP($A33,'Onsite Role Distribution'!$B$8:$G$12,2,FALSE) -> 5 | ... O33: =VLOOKUP($A33,'Onsite Role Distribution'!$B$3:$G$7,2,FALSE)+VLOOKUP($A33,'Onsite Role Distribution'!$B$8:$G$12,2,FALSE) -> 5 | P33: =VLOOKUP($A33,'Onsite Role Distribution'!$B$3:$G$7,3,FALSE)+VLOOKUP($A33,'Onsite Role Distribution'!$B$8:$G$12,3,FALSE) -> 4 | Q33: =VLOOKUP($A33,'Onsite Role Distribution'!$B$3:$G$7,3,FALSE)+VLOOKUP($A33,'Onsite Role Distribution'!$B$8:$G$12,3,FALSE) -> 4 | R33: =VLOOKUP($A33,'Onsite Role Distribution'!$B$3:$G$7,3,FALSE)+VLOOKUP($A33,'Onsite Role Distribution'!$B$8:$G$12,3,FALSE) -> 4 | S33: =VLOOKUP($A33,'Onsite Role Distribution'!$B$3:$G$7,3,FALSE)+VLOOKUP($A33,'Onsite Role Distribution'!$B$8:$G$12,3,FALSE) -> 4 | T33: =VLOOKUP($A33,'Onsite Role Distribution'!$B$3:$G$7,3,FALSE)+VLOOKUP($A33,'Onsite Role Distribution'!$B$8:$G$12,3,FALSE) -> 4 | U33: =VLOOKUP($A33,'Onsite Role Distribution'!$B$3:$G$7,3,FALSE)+VLOOKUP($A33,'Onsite Role Distribution'!$B$8:$G$12,3,FALSE) -> 4 | V33: =VLOOKUP($A33,'Onsite Role Distribution'!$B$3:$G$7,3,FALSE)+VLOOKUP($A33,'Onsite Role Distribution'!$B$8:$G$12,3,FALSE) -> 4 | W33: =VLOOKUP($A33,'Onsite Role Distribution'!$B$3:$G$7,3,FALSE)+VLOOKUP($A33,'Onsite Role Distribution'!$B$8:$G$12,3,FALSE) -> 4 | ... AA33: =VLOOKUP($A33,'Onsite Role Distribution'!$B$3:$G$7,3,FALSE)+VLOOKUP($A33,'Onsite Role Distribution'!$B$8:$G$12,3,FALSE) -> 4 | AB33: =VLOOKUP($A33,'Onsite Role Distribution'!$B$3:$G$7,4,FALSE)+VLOOKUP($A33,'Onsite Role Distribution'!$B$8:$G$12,4,FALSE) -> 2 | AC33: =VLOOKUP($A33,'Onsite Role Distribution'!$B$3:$G$7,4,FALSE)+VLOOKUP($A33,'Onsite Role Distribution'!$B$8:$G$12,4,FALSE) -> 2 | AD33: =VLOOKUP($A33,'Onsite Role Distribution'!$B$3:$G$7,4,FALSE)+VLOOKUP($A33,'Onsite Role Distribution'!$B$8:$G$12,4,FALSE) -> 2 | AE33: =VLOOKUP($A33,'Onsite Role Distribution'!$B$3:$G$7,4,FALSE)+VLOOKUP($A33,'Onsite Role Distribution'!$B$8:$G$12,4,FALSE) -> 2 | AF33: =VLOOKUP($A33,'Onsite Role Distribution'!$B$3:$G$7,4,FALSE)+VLOOKUP($A33,'Onsite Role Distribution'!$B$8:$G$12,4,FALSE) -> 2 | AG33: =VLOOKUP($A33,'Onsite Role Distribution'!$B$3:$G$7,4,FALSE)+VLOOKUP($A33,'Onsite Role Distribution'!$B$8:$G$12,4,FALSE) -> 2 | AH33: =VLOOKUP($A33,'Onsite Role Distribution'!$B$3:$G$7,4,FALSE)+VLOOKUP($A33,'Onsite Role Distribution'!$B$8:$G$12,4,FALSE) -> 2 | AI33: =VLOOKUP($A33,'Onsite Role Distribution'!$B$3:$G$7,4,FALSE)+VLOOKUP($A33,'Onsite Role Distribution'!$B$8:$G$12,4,FALSE) -> 2 | ... AM33: =VLOOKUP($A33,'Onsite Role Distribution'!$B$3:$G$7,4,FALSE)+VLOOKUP($A33,'Onsite Role Distribution'!$B$8:$G$12,4,FALSE) -> 2 | AN33: =VLOOKUP($A33,'Onsite Role Distribution'!$B$3:$G$7,5,FALSE)+VLOOKUP($A33,'Onsite Role Distribution'!$B$8:$G$12,5,FALSE) -> 2 | AO33: =VLOOKUP($A33,'Onsite Role Distribution'!$B$3:$G$7,5,FALSE)+VLOOKUP($A33,'Onsite Role Distribution'!$B$8:$G$12,5,FALSE) -> 2 | AP33: =VLOOKUP($A33,'Onsite Role Distribution'!$B$3:$G$7,5,FALSE)+VLOOKUP($A33,'Onsite Role Distribution'!$B$8:$G$12,5,FALSE) -> 2 | AQ33: =VLOOKUP($A33,'Onsite Role Distribution'!$B$3:$G$7,5,FALSE)+VLOOKUP($A33,'Onsite Role Distribution'!$B$8:$G$12,5,FALSE) -> 2 | AR33: =VLOOKUP($A33,'Onsite Role Distribution'!$B$3:$G$7,5,FALSE)+VLOOKUP($A33,'Onsite Role Distribution'!$B$8:$G$12,5,FALSE) -> 2 | AS33: =VLOOKUP($A33,'Onsite Role Distribution'!$B$3:$G$7,5,FALSE)+VLOOKUP($A33,'Onsite Role Distribution'!$B$8:$G$12,5,FALSE) -> 2 | AT33: =VLOOKUP($A33,'Onsite Role Distribution'!$B$3:$G$7,5,FALSE)+VLOOKUP($A33,'Onsite Role Distribution'!$B$8:$G$12,5,FALSE) -> 2 | AU33: =VLOOKUP($A33,'Onsite Role Distribution'!$B$3:$G$7,5,FALSE)+VLOOKUP($A33,'Onsite Role Distribution'!$B$8:$G$12,5,FALSE) -> 2 | ... AY33: =VLOOKUP($A33,'Onsite Role Distribution'!$B$3:$G$7,5,FALSE)+VLOOKUP($A33,'Onsite Role Distribution'!$B$8:$G$12,5,FALSE) -> 2 | AZ33: 1 | BA33: 1 | BB33: 1 | BC33: 1 | BD33: 1 | BE33: 1 | BF33: 1 | BG33: 1 | BH33: 1 | BI33: 1 | BJ33: 1 | BK33: 1
A34: Tester | B34: Onsite | C34: =A34&B34 -> TesterOnsite | D34: =VLOOKUP($A34,'Onsite Role Distribution'!$B$3:$G$7,2,FALSE)+VLOOKUP($A34,'Onsite Role Distribution'!$B$8:$G$12,2,FALSE) -> 1 | E34: =VLOOKUP($A34,'Onsite Role Distribution'!$B$3:$G$7,2,FALSE)+VLOOKUP($A34,'Onsite Role Distribution'!$B$8:$G$12,2,FALSE) -> 1 | F34: =VLOOKUP($A34,'Onsite Role Distribution'!$B$3:$G$7,2,FALSE)+VLOOKUP($A34,'Onsite Role Distribution'!$B$8:$G$12,2,FALSE) -> 1 | G34: =VLOOKUP($A34,'Onsite Role Distribution'!$B$3:$G$7,2,FALSE)+VLOOKUP($A34,'Onsite Role Distribution'!$B$8:$G$12,2,FALSE) -> 1 | H34: =VLOOKUP($A34,'Onsite Role Distribution'!$B$3:$G$7,2,FALSE)+VLOOKUP($A34,'Onsite Role Distribution'!$B$8:$G$12,2,FALSE) -> 1 | I34: =VLOOKUP($A34,'Onsite Role Distribution'!$B$3:$G$7,2,FALSE)+VLOOKUP($A34,'Onsite Role Distribution'!$B$8:$G$12,2,FALSE) -> 1 | J34: =VLOOKUP($A34,'Onsite Role Distribution'!$B$3:$G$7,2,FALSE)+VLOOKUP($A34,'Onsite Role Distribution'!$B$8:$G$12,2,FALSE) -> 1 | K34: =VLOOKUP($A34,'Onsite Role Distribution'!$B$3:$G$7,2,FALSE)+VLOOKUP($A34,'Onsite Role Distribution'!$B$8:$G$12,2,FALSE) -> 1 | ... O34: =VLOOKUP($A34,'Onsite Role Distribution'!$B$3:$G$7,2,FALSE)+VLOOKUP($A34,'Onsite Role Distribution'!$B$8:$G$12,2,FALSE) -> 1 | P34: =VLOOKUP($A34,'Onsite Role Distribution'!$B$3:$G$7,3,FALSE)+VLOOKUP($A34,'Onsite Role Distribution'!$B$8:$G$12,3,FALSE) -> 1 | Q34: =VLOOKUP($A34,'Onsite Role Distribution'!$B$3:$G$7,3,FALSE)+VLOOKUP($A34,'Onsite Role Distribution'!$B$8:$G$12,3,FALSE) -> 1 | R34: =VLOOKUP($A34,'Onsite Role Distribution'!$B$3:$G$7,3,FALSE)+VLOOKUP($A34,'Onsite Role Distribution'!$B$8:$G$12,3,FALSE) -> 1 | S34: =VLOOKUP($A34,'Onsite Role Distribution'!$B$3:$G$7,3,FALSE)+VLOOKUP($A34,'Onsite Role Distribution'!$B$8:$G$12,3,FALSE) -> 1 | T34: =VLOOKUP($A34,'Onsite Role Distribution'!$B$3:$G$7,3,FALSE)+VLOOKUP($A34,'Onsite Role Distribution'!$B$8:$G$12,3,FALSE) -> 1 | U34: =VLOOKUP($A34,'Onsite Role Distribution'!$B$3:$G$7,3,FALSE)+VLOOKUP($A34,'Onsite Role Distribution'!$B$8:$G$12,3,FALSE) -> 1 | V34: =VLOOKUP($A34,'Onsite Role Distribution'!$B$3:$G$7,3,FALSE)+VLOOKUP($A34,'Onsite Role Distribution'!$B$8:$G$12,3,FALSE) -> 1 | W34: =VLOOKUP($A34,'Onsite Role Distribution'!$B$3:$G$7,3,FALSE)+VLOOKUP($A34,'Onsite Role Distribution'!$B$8:$G$12,3,FALSE) -> 1 | ... AA34: =VLOOKUP($A34,'Onsite Role Distribution'!$B$3:$G$7,3,FALSE)+VLOOKUP($A34,'Onsite Role Distribution'!$B$8:$G$12,3,FALSE) -> 1 | AB34: =VLOOKUP($A34,'Onsite Role Distribution'!$B$3:$G$7,4,FALSE)+VLOOKUP($A34,'Onsite Role Distribution'!$B$8:$G$12,4,FALSE) -> 0 | AC34: =VLOOKUP($A34,'Onsite Role Distribution'!$B$3:$G$7,4,FALSE)+VLOOKUP($A34,'Onsite Role Distribution'!$B$8:$G$12,4,FALSE) -> 0 | AD34: =VLOOKUP($A34,'Onsite Role Distribution'!$B$3:$G$7,4,FALSE)+VLOOKUP($A34,'Onsite Role Distribution'!$B$8:$G$12,4,FALSE) -> 0 | AE34: =VLOOKUP($A34,'Onsite Role Distribution'!$B$3:$G$7,4,FALSE)+VLOOKUP($A34,'Onsite Role Distribution'!$B$8:$G$12,4,FALSE) -> 0 | AF34: =VLOOKUP($A34,'Onsite Role Distribution'!$B$3:$G$7,4,FALSE)+VLOOKUP($A34,'Onsite Role Distribution'!$B$8:$G$12,4,FALSE) -> 0 | AG34: =VLOOKUP($A34,'Onsite Role Distribution'!$B$3:$G$7,4,FALSE)+VLOOKUP($A34,'Onsite Role Distribution'!$B$8:$G$12,4,FALSE) -> 0 | AH34: =VLOOKUP($A34,'Onsite Role Distribution'!$B$3:$G$7,4,FALSE)+VLOOKUP($A34,'Onsite Role Distribution'!$B$8:$G$12,4,FALSE) -> 0 | AI34: =VLOOKUP($A34,'Onsite Role Distribution'!$B$3:$G$7,4,FALSE)+VLOOKUP($A34,'Onsite Role Distribution'!$B$8:$G$12,4,FALSE) -> 0 | ... AM34: =VLOOKUP($A34,'Onsite Role Distribution'!$B$3:$G$7,4,FALSE)+VLOOKUP($A34,'Onsite Role Distribution'!$B$8:$G$12,4,FALSE) -> 0 | AN34: =VLOOKUP($A34,'Onsite Role Distribution'!$B$3:$G$7,5,FALSE)+VLOOKUP($A34,'Onsite Role Distribution'!$B$8:$G$12,5,FALSE) -> 0 | AO34: =VLOOKUP($A34,'Onsite Role Distribution'!$B$3:$G$7,5,FALSE)+VLOOKUP($A34,'Onsite Role Distribution'!$B$8:$G$12,5,FALSE) -> 0 | AP34: =VLOOKUP($A34,'Onsite Role Distribution'!$B$3:$G$7,5,FALSE)+VLOOKUP($A34,'Onsite Role Distribution'!$B$8:$G$12,5,FALSE) -> 0 | AQ34: =VLOOKUP($A34,'Onsite Role Distribution'!$B$3:$G$7,5,FALSE)+VLOOKUP($A34,'Onsite Role Distribution'!$B$8:$G$12,5,FALSE) -> 0 | AR34: =VLOOKUP($A34,'Onsite Role Distribution'!$B$3:$G$7,5,FALSE)+VLOOKUP($A34,'Onsite Role Distribution'!$B$8:$G$12,5,FALSE) -> 0 | AS34: =VLOOKUP($A34,'Onsite Role Distribution'!$B$3:$G$7,5,FALSE)+VLOOKUP($A34,'Onsite Role Distribution'!$B$8:$G$12,5,FALSE) -> 0 | AT34: =VLOOKUP($A34,'Onsite Role Distribution'!$B$3:$G$7,5,FALSE)+VLOOKUP($A34,'Onsite Role Distribution'!$B$8:$G$12,5,FALSE) -> 0 | AU34: =VLOOKUP($A34,'Onsite Role Distribution'!$B$3:$G$7,5,FALSE)+VLOOKUP($A34,'Onsite Role Distribution'!$B$8:$G$12,5,FALSE) -> 0 | ... AY34: =VLOOKUP($A34,'Onsite Role Distribution'!$B$3:$G$7,5,FALSE)+VLOOKUP($A34,'Onsite Role Distribution'!$B$8:$G$12,5,FALSE) -> 0 | AZ34: 0 | BA34: =VLOOKUP($A34,'Onsite Role Distribution'!$B$3:$G$7,6,FALSE)+VLOOKUP($A34,'Onsite Role Distribution'!$B$8:$G$12,6,FALSE) -> 0 | BB34: =VLOOKUP($A34,'Onsite Role Distribution'!$B$3:$G$7,6,FALSE)+VLOOKUP($A34,'Onsite Role Distribution'!$B$8:$G$12,6,FALSE) -> 0 | BC34: =VLOOKUP($A34,'Onsite Role Distribution'!$B$3:$G$7,6,FALSE)+VLOOKUP($A34,'Onsite Role Distribution'!$B$8:$G$12,6,FALSE) -> 0 | BD34: =VLOOKUP($A34,'Onsite Role Distribution'!$B$3:$G$7,6,FALSE)+VLOOKUP($A34,'Onsite Role Distribution'!$B$8:$G$12,6,FALSE) -> 0 | BE34: =VLOOKUP($A34,'Onsite Role Distribution'!$B$3:$G$7,6,FALSE)+VLOOKUP($A34,'Onsite Role Distribution'!$B$8:$G$12,6,FALSE) -> 0 | BF34: =VLOOKUP($A34,'Onsite Role Distribution'!$B$3:$G$7,6,FALSE)+VLOOKUP($A34,'Onsite Role Distribution'!$B$8:$G$12,6,FALSE) -> 0 | BG34: =VLOOKUP($A34,'Onsite Role Distribution'!$B$3:$G$7,6,FALSE)+VLOOKUP($A34,'Onsite Role Distribution'!$B$8:$G$12,6,FALSE) -> 0 | BH34: =VLOOKUP($A34,'Onsite Role Distribution'!$B$3:$G$7,6,FALSE)+VLOOKUP($A34,'Onsite Role Distribution'!$B$8:$G$12,6,FALSE) -> 0 | ... BK34: =VLOOKUP($A34,'Onsite Role Distribution'!$B$3:$G$7,6,FALSE)+VLOOKUP($A34,'Onsite Role Distribution'!$B$8:$G$12,6,FALSE) -> 0
A35: PM | B35: Onsite | C35: =A35&B35 -> PMOnsite | D35: =VLOOKUP($A35,'Onsite Role Distribution'!$B$3:$G$7,2,FALSE)+VLOOKUP($A35,'Onsite Role Distribution'!$B$8:$G$12,2,FALSE) -> 0 | E35: =VLOOKUP($A35,'Onsite Role Distribution'!$B$3:$G$7,2,FALSE)+VLOOKUP($A35,'Onsite Role Distribution'!$B$8:$G$12,2,FALSE) -> 0 | F35: =VLOOKUP($A35,'Onsite Role Distribution'!$B$3:$G$7,2,FALSE)+VLOOKUP($A35,'Onsite Role Distribution'!$B$8:$G$12,2,FALSE) -> 0 | G35: =VLOOKUP($A35,'Onsite Role Distribution'!$B$3:$G$7,2,FALSE)+VLOOKUP($A35,'Onsite Role Distribution'!$B$8:$G$12,2,FALSE) -> 0 | H35: =VLOOKUP($A35,'Onsite Role Distribution'!$B$3:$G$7,2,FALSE)+VLOOKUP($A35,'Onsite Role Distribution'!$B$8:$G$12,2,FALSE) -> 0 | I35: =VLOOKUP($A35,'Onsite Role Distribution'!$B$3:$G$7,2,FALSE)+VLOOKUP($A35,'Onsite Role Distribution'!$B$8:$G$12,2,FALSE) -> 0 | J35: =VLOOKUP($A35,'Onsite Role Distribution'!$B$3:$G$7,2,FALSE)+VLOOKUP($A35,'Onsite Role Distribution'!$B$8:$G$12,2,FALSE) -> 0 | K35: =VLOOKUP($A35,'Onsite Role Distribution'!$B$3:$G$7,2,FALSE)+VLOOKUP($A35,'Onsite Role Distribution'!$B$8:$G$12,2,FALSE) -> 0 | ... O35: =VLOOKUP($A35,'Onsite Role Distribution'!$B$3:$G$7,2,FALSE)+VLOOKUP($A35,'Onsite Role Distribution'!$B$8:$G$12,2,FALSE) -> 0 | P35: =VLOOKUP($A35,'Onsite Role Distribution'!$B$3:$G$7,3,FALSE)+VLOOKUP($A35,'Onsite Role Distribution'!$B$8:$G$12,3,FALSE) -> 0 | Q35: =VLOOKUP($A35,'Onsite Role Distribution'!$B$3:$G$7,3,FALSE)+VLOOKUP($A35,'Onsite Role Distribution'!$B$8:$G$12,3,FALSE) -> 0 | R35: =VLOOKUP($A35,'Onsite Role Distribution'!$B$3:$G$7,3,FALSE)+VLOOKUP($A35,'Onsite Role Distribution'!$B$8:$G$12,3,FALSE) -> 0 | S35: =VLOOKUP($A35,'Onsite Role Distribution'!$B$3:$G$7,3,FALSE)+VLOOKUP($A35,'Onsite Role Distribution'!$B$8:$G$12,3,FALSE) -> 0 | T35: =VLOOKUP($A35,'Onsite Role Distribution'!$B$3:$G$7,3,FALSE)+VLOOKUP($A35,'Onsite Role Distribution'!$B$8:$G$12,3,FALSE) -> 0 | U35: =VLOOKUP($A35,'Onsite Role Distribution'!$B$3:$G$7,3,FALSE)+VLOOKUP($A35,'Onsite Role Distribution'!$B$8:$G$12,3,FALSE) -> 0 | V35: =VLOOKUP($A35,'Onsite Role Distribution'!$B$3:$G$7,3,FALSE)+VLOOKUP($A35,'Onsite Role Distribution'!$B$8:$G$12,3,FALSE) -> 0 | W35: =VLOOKUP($A35,'Onsite Role Distribution'!$B$3:$G$7,3,FALSE)+VLOOKUP($A35,'Onsite Role Distribution'!$B$8:$G$12,3,FALSE) -> 0 | ... AA35: =VLOOKUP($A35,'Onsite Role Distribution'!$B$3:$G$7,3,FALSE)+VLOOKUP($A35,'Onsite Role Distribution'!$B$8:$G$12,3,FALSE) -> 0 | AB35: =VLOOKUP($A35,'Onsite Role Distribution'!$B$3:$G$7,4,FALSE)+VLOOKUP($A35,'Onsite Role Distribution'!$B$8:$G$12,4,FALSE) -> 0 | AC35: =VLOOKUP($A35,'Onsite Role Distribution'!$B$3:$G$7,4,FALSE)+VLOOKUP($A35,'Onsite Role Distribution'!$B$8:$G$12,4,FALSE) -> 0 | AD35: =VLOOKUP($A35,'Onsite Role Distribution'!$B$3:$G$7,4,FALSE)+VLOOKUP($A35,'Onsite Role Distribution'!$B$8:$G$12,4,FALSE) -> 0 | AE35: =VLOOKUP($A35,'Onsite Role Distribution'!$B$3:$G$7,4,FALSE)+VLOOKUP($A35,'Onsite Role Distribution'!$B$8:$G$12,4,FALSE) -> 0 | AF35: =VLOOKUP($A35,'Onsite Role Distribution'!$B$3:$G$7,4,FALSE)+VLOOKUP($A35,'Onsite Role Distribution'!$B$8:$G$12,4,FALSE) -> 0 | AG35: =VLOOKUP($A35,'Onsite Role Distribution'!$B$3:$G$7,4,FALSE)+VLOOKUP($A35,'Onsite Role Distribution'!$B$8:$G$12,4,FALSE) -> 0 | AH35: =VLOOKUP($A35,'Onsite Role Distribution'!$B$3:$G$7,4,FALSE)+VLOOKUP($A35,'Onsite Role Distribution'!$B$8:$G$12,4,FALSE) -> 0 | AI35: =VLOOKUP($A35,'Onsite Role Distribution'!$B$3:$G$7,4,FALSE)+VLOOKUP($A35,'Onsite Role Distribution'!$B$8:$G$12,4,FALSE) -> 0 | ... AM35: =VLOOKUP($A35,'Onsite Role Distribution'!$B$3:$G$7,4,FALSE)+VLOOKUP($A35,'Onsite Role Distribution'!$B$8:$G$12,4,FALSE) -> 0 | AN35: =VLOOKUP($A35,'Onsite Role Distribution'!$B$3:$G$7,5,FALSE)+VLOOKUP($A35,'Onsite Role Distribution'!$B$8:$G$12,5,FALSE) -> 0 | AO35: =VLOOKUP($A35,'Onsite Role Distribution'!$B$3:$G$7,5,FALSE)+VLOOKUP($A35,'Onsite Role Distribution'!$B$8:$G$12,5,FALSE) -> 0 | AP35: =VLOOKUP($A35,'Onsite Role Distribution'!$B$3:$G$7,5,FALSE)+VLOOKUP($A35,'Onsite Role Distribution'!$B$8:$G$12,5,FALSE) -> 0 | AQ35: =VLOOKUP($A35,'Onsite Role Distribution'!$B$3:$G$7,5,FALSE)+VLOOKUP($A35,'Onsite Role Distribution'!$B$8:$G$12,5,FALSE) -> 0 | AR35: =VLOOKUP($A35,'Onsite Role Distribution'!$B$3:$G$7,5,FALSE)+VLOOKUP($A35,'Onsite Role Distribution'!$B$8:$G$12,5,FALSE) -> 0 | AS35: =VLOOKUP($A35,'Onsite Role Distribution'!$B$3:$G$7,5,FALSE)+VLOOKUP($A35,'Onsite Role Distribution'!$B$8:$G$12,5,FALSE) -> 0 | AT35: =VLOOKUP($A35,'Onsite Role Distribution'!$B$3:$G$7,5,FALSE)+VLOOKUP($A35,'Onsite Role Distribution'!$B$8:$G$12,5,FALSE) -> 0 | AU35: =VLOOKUP($A35,'Onsite Role Distribution'!$B$3:$G$7,5,FALSE)+VLOOKUP($A35,'Onsite Role Distribution'!$B$8:$G$12,5,FALSE) -> 0 | ... AY35: =VLOOKUP($A35,'Onsite Role Distribution'!$B$3:$G$7,5,FALSE)+VLOOKUP($A35,'Onsite Role Distribution'!$B$8:$G$12,5,FALSE) -> 0 | AZ35: 0 | BA35: =VLOOKUP($A35,'Onsite Role Distribution'!$B$3:$G$7,6,FALSE)+VLOOKUP($A35,'Onsite Role Distribution'!$B$8:$G$12,6,FALSE) -> 0 | BB35: =VLOOKUP($A35,'Onsite Role Distribution'!$B$3:$G$7,6,FALSE)+VLOOKUP($A35,'Onsite Role Distribution'!$B$8:$G$12,6,FALSE) -> 0 | BC35: =VLOOKUP($A35,'Onsite Role Distribution'!$B$3:$G$7,6,FALSE)+VLOOKUP($A35,'Onsite Role Distribution'!$B$8:$G$12,6,FALSE) -> 0 | BD35: =VLOOKUP($A35,'Onsite Role Distribution'!$B$3:$G$7,6,FALSE)+VLOOKUP($A35,'Onsite Role Distribution'!$B$8:$G$12,6,FALSE) -> 0 | BE35: =VLOOKUP($A35,'Onsite Role Distribution'!$B$3:$G$7,6,FALSE)+VLOOKUP($A35,'Onsite Role Distribution'!$B$8:$G$12,6,FALSE) -> 0 | BF35: =VLOOKUP($A35,'Onsite Role Distribution'!$B$3:$G$7,6,FALSE)+VLOOKUP($A35,'Onsite Role Distribution'!$B$8:$G$12,6,FALSE) -> 0 | BG35: =VLOOKUP($A35,'Onsite Role Distribution'!$B$3:$G$7,6,FALSE)+VLOOKUP($A35,'Onsite Role Distribution'!$B$8:$G$12,6,FALSE) -> 0 | BH35: =VLOOKUP($A35,'Onsite Role Distribution'!$B$3:$G$7,6,FALSE)+VLOOKUP($A35,'Onsite Role Distribution'!$B$8:$G$12,6,FALSE) -> 0 | ... BK35: =VLOOKUP($A35,'Onsite Role Distribution'!$B$3:$G$7,6,FALSE)+VLOOKUP($A35,'Onsite Role Distribution'!$B$8:$G$12,6,FALSE) -> 0
A36: Lead | B36: Onsite | C36: =A36&B36 -> LeadOnsite | D36: =VLOOKUP($A36,'Onsite Role Distribution'!$B$3:$G$7,2,FALSE)+VLOOKUP($A36,'Onsite Role Distribution'!$B$8:$G$12,2,FALSE) -> 1 | E36: =VLOOKUP($A36,'Onsite Role Distribution'!$B$3:$G$7,2,FALSE)+VLOOKUP($A36,'Onsite Role Distribution'!$B$8:$G$12,2,FALSE) -> 1 | F36: =VLOOKUP($A36,'Onsite Role Distribution'!$B$3:$G$7,2,FALSE)+VLOOKUP($A36,'Onsite Role Distribution'!$B$8:$G$12,2,FALSE) -> 1 | G36: =VLOOKUP($A36,'Onsite Role Distribution'!$B$3:$G$7,2,FALSE)+VLOOKUP($A36,'Onsite Role Distribution'!$B$8:$G$12,2,FALSE) -> 1 | H36: =VLOOKUP($A36,'Onsite Role Distribution'!$B$3:$G$7,2,FALSE)+VLOOKUP($A36,'Onsite Role Distribution'!$B$8:$G$12,2,FALSE) -> 1 | I36: =VLOOKUP($A36,'Onsite Role Distribution'!$B$3:$G$7,2,FALSE)+VLOOKUP($A36,'Onsite Role Distribution'!$B$8:$G$12,2,FALSE) -> 1 | J36: =VLOOKUP($A36,'Onsite Role Distribution'!$B$3:$G$7,2,FALSE)+VLOOKUP($A36,'Onsite Role Distribution'!$B$8:$G$12,2,FALSE) -> 1 | K36: =VLOOKUP($A36,'Onsite Role Distribution'!$B$3:$G$7,2,FALSE)+VLOOKUP($A36,'Onsite Role Distribution'!$B$8:$G$12,2,FALSE) -> 1 | ... O36: =VLOOKUP($A36,'Onsite Role Distribution'!$B$3:$G$7,2,FALSE)+VLOOKUP($A36,'Onsite Role Distribution'!$B$8:$G$12,2,FALSE) -> 1 | P36: =VLOOKUP($A36,'Onsite Role Distribution'!$B$3:$G$7,3,FALSE)+VLOOKUP($A36,'Onsite Role Distribution'!$B$8:$G$12,3,FALSE) -> 1 | Q36: =VLOOKUP($A36,'Onsite Role Distribution'!$B$3:$G$7,3,FALSE)+VLOOKUP($A36,'Onsite Role Distribution'!$B$8:$G$12,3,FALSE) -> 1 | R36: =VLOOKUP($A36,'Onsite Role Distribution'!$B$3:$G$7,3,FALSE)+VLOOKUP($A36,'Onsite Role Distribution'!$B$8:$G$12,3,FALSE) -> 1 | S36: =VLOOKUP($A36,'Onsite Role Distribution'!$B$3:$G$7,3,FALSE)+VLOOKUP($A36,'Onsite Role Distribution'!$B$8:$G$12,3,FALSE) -> 1 | T36: =VLOOKUP($A36,'Onsite Role Distribution'!$B$3:$G$7,3,FALSE)+VLOOKUP($A36,'Onsite Role Distribution'!$B$8:$G$12,3,FALSE) -> 1 | U36: =VLOOKUP($A36,'Onsite Role Distribution'!$B$3:$G$7,3,FALSE)+VLOOKUP($A36,'Onsite Role Distribution'!$B$8:$G$12,3,FALSE) -> 1 | V36: =VLOOKUP($A36,'Onsite Role Distribution'!$B$3:$G$7,3,FALSE)+VLOOKUP($A36,'Onsite Role Distribution'!$B$8:$G$12,3,FALSE) -> 1 | W36: =VLOOKUP($A36,'Onsite Role Distribution'!$B$3:$G$7,3,FALSE)+VLOOKUP($A36,'Onsite Role Distribution'!$B$8:$G$12,3,FALSE) -> 1 | ... AA36: =VLOOKUP($A36,'Onsite Role Distribution'!$B$3:$G$7,3,FALSE)+VLOOKUP($A36,'Onsite Role Distribution'!$B$8:$G$12,3,FALSE) -> 1 | AB36: =VLOOKUP($A36,'Onsite Role Distribution'!$B$3:$G$7,4,FALSE)+VLOOKUP($A36,'Onsite Role Distribution'!$B$8:$G$12,4,FALSE) -> 0 | AC36: =VLOOKUP($A36,'Onsite Role Distribution'!$B$3:$G$7,4,FALSE)+VLOOKUP($A36,'Onsite Role Distribution'!$B$8:$G$12,4,FALSE) -> 0 | AD36: =VLOOKUP($A36,'Onsite Role Distribution'!$B$3:$G$7,4,FALSE)+VLOOKUP($A36,'Onsite Role Distribution'!$B$8:$G$12,4,FALSE) -> 0 | AE36: =VLOOKUP($A36,'Onsite Role Distribution'!$B$3:$G$7,4,FALSE)+VLOOKUP($A36,'Onsite Role Distribution'!$B$8:$G$12,4,FALSE) -> 0 | AF36: =VLOOKUP($A36,'Onsite Role Distribution'!$B$3:$G$7,4,FALSE)+VLOOKUP($A36,'Onsite Role Distribution'!$B$8:$G$12,4,FALSE) -> 0 | AG36: =VLOOKUP($A36,'Onsite Role Distribution'!$B$3:$G$7,4,FALSE)+VLOOKUP($A36,'Onsite Role Distribution'!$B$8:$G$12,4,FALSE) -> 0 | AH36: =VLOOKUP($A36,'Onsite Role Distribution'!$B$3:$G$7,4,FALSE)+VLOOKUP($A36,'Onsite Role Distribution'!$B$8:$G$12,4,FALSE) -> 0 | AI36: =VLOOKUP($A36,'Onsite Role Distribution'!$B$3:$G$7,4,FALSE)+VLOOKUP($A36,'Onsite Role Distribution'!$B$8:$G$12,4,FALSE) -> 0 | ... AM36: =VLOOKUP($A36,'Onsite Role Distribution'!$B$3:$G$7,4,FALSE)+VLOOKUP($A36,'Onsite Role Distribution'!$B$8:$G$12,4,FALSE) -> 0 | AN36: =VLOOKUP($A36,'Onsite Role Distribution'!$B$3:$G$7,5,FALSE)+VLOOKUP($A36,'Onsite Role Distribution'!$B$8:$G$12,5,FALSE) -> 0 | AO36: =VLOOKUP($A36,'Onsite Role Distribution'!$B$3:$G$7,5,FALSE)+VLOOKUP($A36,'Onsite Role Distribution'!$B$8:$G$12,5,FALSE) -> 0 | AP36: =VLOOKUP($A36,'Onsite Role Distribution'!$B$3:$G$7,5,FALSE)+VLOOKUP($A36,'Onsite Role Distribution'!$B$8:$G$12,5,FALSE) -> 0 | AQ36: =VLOOKUP($A36,'Onsite Role Distribution'!$B$3:$G$7,5,FALSE)+VLOOKUP($A36,'Onsite Role Distribution'!$B$8:$G$12,5,FALSE) -> 0 | AR36: =VLOOKUP($A36,'Onsite Role Distribution'!$B$3:$G$7,5,FALSE)+VLOOKUP($A36,'Onsite Role Distribution'!$B$8:$G$12,5,FALSE) -> 0 | AS36: =VLOOKUP($A36,'Onsite Role Distribution'!$B$3:$G$7,5,FALSE)+VLOOKUP($A36,'Onsite Role Distribution'!$B$8:$G$12,5,FALSE) -> 0 | AT36: =VLOOKUP($A36,'Onsite Role Distribution'!$B$3:$G$7,5,FALSE)+VLOOKUP($A36,'Onsite Role Distribution'!$B$8:$G$12,5,FALSE) -> 0 | AU36: =VLOOKUP($A36,'Onsite Role Distribution'!$B$3:$G$7,5,FALSE)+VLOOKUP($A36,'Onsite Role Distribution'!$B$8:$G$12,5,FALSE) -> 0 | ... AY36: =VLOOKUP($A36,'Onsite Role Distribution'!$B$3:$G$7,5,FALSE)+VLOOKUP($A36,'Onsite Role Distribution'!$B$8:$G$12,5,FALSE) -> 0 | AZ36: 0 | BA36: =VLOOKUP($A36,'Onsite Role Distribution'!$B$3:$G$7,6,FALSE)+VLOOKUP($A36,'Onsite Role Distribution'!$B$8:$G$12,6,FALSE) -> 0 | BB36: =VLOOKUP($A36,'Onsite Role Distribution'!$B$3:$G$7,6,FALSE)+VLOOKUP($A36,'Onsite Role Distribution'!$B$8:$G$12,6,FALSE) -> 0 | BC36: =VLOOKUP($A36,'Onsite Role Distribution'!$B$3:$G$7,6,FALSE)+VLOOKUP($A36,'Onsite Role Distribution'!$B$8:$G$12,6,FALSE) -> 0 | BD36: =VLOOKUP($A36,'Onsite Role Distribution'!$B$3:$G$7,6,FALSE)+VLOOKUP($A36,'Onsite Role Distribution'!$B$8:$G$12,6,FALSE) -> 0 | BE36: =VLOOKUP($A36,'Onsite Role Distribution'!$B$3:$G$7,6,FALSE)+VLOOKUP($A36,'Onsite Role Distribution'!$B$8:$G$12,6,FALSE) -> 0 | BF36: =VLOOKUP($A36,'Onsite Role Distribution'!$B$3:$G$7,6,FALSE)+VLOOKUP($A36,'Onsite Role Distribution'!$B$8:$G$12,6,FALSE) -> 0 | BG36: =VLOOKUP($A36,'Onsite Role Distribution'!$B$3:$G$7,6,FALSE)+VLOOKUP($A36,'Onsite Role Distribution'!$B$8:$G$12,6,FALSE) -> 0 | BH36: =VLOOKUP($A36,'Onsite Role Distribution'!$B$3:$G$7,6,FALSE)+VLOOKUP($A36,'Onsite Role Distribution'!$B$8:$G$12,6,FALSE) -> 0 | ... BK36: =VLOOKUP($A36,'Onsite Role Distribution'!$B$3:$G$7,6,FALSE)+VLOOKUP($A36,'Onsite Role Distribution'!$B$8:$G$12,6,FALSE) -> 0
A37: BSA | B37: Onsite-Landed | C37: =A37&B37 -> BSAOnsite-Landed | D37: =VLOOKUP($A37,'Onsite Role Distribution'!$B$13:$G$17,2,FALSE) -> 2 | E37: =VLOOKUP($A37,'Onsite Role Distribution'!$B$13:$G$17,2,FALSE) -> 2 | F37: =VLOOKUP($A37,'Onsite Role Distribution'!$B$13:$G$17,2,FALSE) -> 2 | G37: =VLOOKUP($A37,'Onsite Role Distribution'!$B$13:$G$17,2,FALSE) -> 2 | H37: =VLOOKUP($A37,'Onsite Role Distribution'!$B$13:$G$17,2,FALSE) -> 2 | I37: =VLOOKUP($A37,'Onsite Role Distribution'!$B$13:$G$17,2,FALSE) -> 2 | J37: =VLOOKUP($A37,'Onsite Role Distribution'!$B$13:$G$17,2,FALSE) -> 2 | K37: =VLOOKUP($A37,'Onsite Role Distribution'!$B$13:$G$17,2,FALSE) -> 2 | ... O37: =VLOOKUP($A37,'Onsite Role Distribution'!$B$13:$G$17,2,FALSE) -> 2 | P37: =VLOOKUP($A37,'Onsite Role Distribution'!$B$13:$G$17,3,FALSE) -> 1 | Q37: =VLOOKUP($A37,'Onsite Role Distribution'!$B$13:$G$17,3,FALSE) -> 1 | R37: =VLOOKUP($A37,'Onsite Role Distribution'!$B$13:$G$17,3,FALSE) -> 1 | S37: =VLOOKUP($A37,'Onsite Role Distribution'!$B$13:$G$17,3,FALSE) -> 1 | T37: =VLOOKUP($A37,'Onsite Role Distribution'!$B$13:$G$17,3,FALSE) -> 1 | U37: =VLOOKUP($A37,'Onsite Role Distribution'!$B$13:$G$17,3,FALSE) -> 1 | V37: =VLOOKUP($A37,'Onsite Role Distribution'!$B$13:$G$17,3,FALSE) -> 1 | W37: =VLOOKUP($A37,'Onsite Role Distribution'!$B$13:$G$17,3,FALSE) -> 1 | ... AA37: =VLOOKUP($A37,'Onsite Role Distribution'!$B$13:$G$17,3,FALSE) -> 1 | AB37: =VLOOKUP($A37,'Onsite Role Distribution'!$B$13:$G$17,4,FALSE) -> 0 | AC37: =VLOOKUP($A37,'Onsite Role Distribution'!$B$13:$G$17,4,FALSE) -> 0 | AD37: =VLOOKUP($A37,'Onsite Role Distribution'!$B$13:$G$17,4,FALSE) -> 0 | AE37: =VLOOKUP($A37,'Onsite Role Distribution'!$B$13:$G$17,4,FALSE) -> 0 | AF37: =VLOOKUP($A37,'Onsite Role Distribution'!$B$13:$G$17,4,FALSE) -> 0 | AG37: =VLOOKUP($A37,'Onsite Role Distribution'!$B$13:$G$17,4,FALSE) -> 0 | AH37: =VLOOKUP($A37,'Onsite Role Distribution'!$B$13:$G$17,4,FALSE) -> 0 | AI37: =VLOOKUP($A37,'Onsite Role Distribution'!$B$13:$G$17,4,FALSE) -> 0 | ... AM37: =VLOOKUP($A37,'Onsite Role Distribution'!$B$13:$G$17,4,FALSE) -> 0 | AN37: =VLOOKUP($A37,'Onsite Role Distribution'!$B$13:$G$17,5,FALSE) -> 0 | AO37: =VLOOKUP($A37,'Onsite Role Distribution'!$B$13:$G$17,5,FALSE) -> 0 | AP37: =VLOOKUP($A37,'Onsite Role Distribution'!$B$13:$G$17,5,FALSE) -> 0 | AQ37: =VLOOKUP($A37,'Onsite Role Distribution'!$B$13:$G$17,5,FALSE) -> 0 | AR37: =VLOOKUP($A37,'Onsite Role Distribution'!$B$13:$G$17,5,FALSE) -> 0 | AS37: =VLOOKUP($A37,'Onsite Role Distribution'!$B$13:$G$17,5,FALSE) -> 0 | AT37: =VLOOKUP($A37,'Onsite Role Distribution'!$B$13:$G$17,5,FALSE) -> 0 | AU37: =VLOOKUP($A37,'Onsite Role Distribution'!$B$13:$G$17,5,FALSE) -> 0 | ... AY37: =VLOOKUP($A37,'Onsite Role Distribution'!$B$13:$G$17,5,FALSE) -> 0 | AZ37: 0 | BA37: =VLOOKUP($A37,'Onsite Role Distribution'!$B$13:$G$17,6,FALSE) -> 0 | BB37: =VLOOKUP($A37,'Onsite Role Distribution'!$B$13:$G$17,6,FALSE) -> 0 | BC37: =VLOOKUP($A37,'Onsite Role Distribution'!$B$13:$G$17,6,FALSE) -> 0 | BD37: =VLOOKUP($A37,'Onsite Role Distribution'!$B$13:$G$17,6,FALSE) -> 0 | BE37: =VLOOKUP($A37,'Onsite Role Distribution'!$B$13:$G$17,6,FALSE) -> 0 | BF37: =VLOOKUP($A37,'Onsite Role Distribution'!$B$13:$G$17,6,FALSE) -> 0 | BG37: =VLOOKUP($A37,'Onsite Role Distribution'!$B$13:$G$17,6,FALSE) -> 0 | BH37: =VLOOKUP($A37,'Onsite Role Distribution'!$B$13:$G$17,6,FALSE) -> 0 | ... BK37: =VLOOKUP($A37,'Onsite Role Distribution'!$B$13:$G$17,6,FALSE) -> 0
A38: Dev | B38: Onsite-Landed | C38: =A38&B38 -> DevOnsite-Landed | D38: =VLOOKUP($A38,'Onsite Role Distribution'!$B$13:$G$17,2,FALSE) -> 2 | E38: =VLOOKUP($A38,'Onsite Role Distribution'!$B$13:$G$17,2,FALSE) -> 2 | F38: =VLOOKUP($A38,'Onsite Role Distribution'!$B$13:$G$17,2,FALSE) -> 2 | G38: =VLOOKUP($A38,'Onsite Role Distribution'!$B$13:$G$17,2,FALSE) -> 2 | H38: =VLOOKUP($A38,'Onsite Role Distribution'!$B$13:$G$17,2,FALSE) -> 2 | I38: =VLOOKUP($A38,'Onsite Role Distribution'!$B$13:$G$17,2,FALSE) -> 2 | J38: =VLOOKUP($A38,'Onsite Role Distribution'!$B$13:$G$17,2,FALSE) -> 2 | K38: =VLOOKUP($A38,'Onsite Role Distribution'!$B$13:$G$17,2,FALSE) -> 2 | ... O38: =VLOOKUP($A38,'Onsite Role Distribution'!$B$13:$G$17,2,FALSE) -> 2 | P38: =VLOOKUP($A38,'Onsite Role Distribution'!$B$13:$G$17,3,FALSE) -> 1 | Q38: =VLOOKUP($A38,'Onsite Role Distribution'!$B$13:$G$17,3,FALSE) -> 1 | R38: =VLOOKUP($A38,'Onsite Role Distribution'!$B$13:$G$17,3,FALSE) -> 1 | S38: =VLOOKUP($A38,'Onsite Role Distribution'!$B$13:$G$17,3,FALSE) -> 1 | T38: =VLOOKUP($A38,'Onsite Role Distribution'!$B$13:$G$17,3,FALSE) -> 1 | U38: =VLOOKUP($A38,'Onsite Role Distribution'!$B$13:$G$17,3,FALSE) -> 1 | V38: =VLOOKUP($A38,'Onsite Role Distribution'!$B$13:$G$17,3,FALSE) -> 1 | W38: =VLOOKUP($A38,'Onsite Role Distribution'!$B$13:$G$17,3,FALSE) -> 1 | ... AA38: =VLOOKUP($A38,'Onsite Role Distribution'!$B$13:$G$17,3,FALSE) -> 1 | AB38: =VLOOKUP($A38,'Onsite Role Distribution'!$B$13:$G$17,4,FALSE) -> 1 | AC38: =VLOOKUP($A38,'Onsite Role Distribution'!$B$13:$G$17,4,FALSE) -> 1 | AD38: =VLOOKUP($A38,'Onsite Role Distribution'!$B$13:$G$17,4,FALSE) -> 1 | AE38: =VLOOKUP($A38,'Onsite Role Distribution'!$B$13:$G$17,4,FALSE) -> 1 | AF38: =VLOOKUP($A38,'Onsite Role Distribution'!$B$13:$G$17,4,FALSE) -> 1 | AG38: =VLOOKUP($A38,'Onsite Role Distribution'!$B$13:$G$17,4,FALSE) -> 1 | AH38: =VLOOKUP($A38,'Onsite Role Distribution'!$B$13:$G$17,4,FALSE) -> 1 | AI38: =VLOOKUP($A38,'Onsite Role Distribution'!$B$13:$G$17,4,FALSE) -> 1 | ... AM38: =VLOOKUP($A38,'Onsite Role Distribution'!$B$13:$G$17,4,FALSE) -> 1 | AN38: =VLOOKUP($A38,'Onsite Role Distribution'!$B$13:$G$17,5,FALSE) -> 1 | AO38: =VLOOKUP($A38,'Onsite Role Distribution'!$B$13:$G$17,5,FALSE) -> 1 | AP38: =VLOOKUP($A38,'Onsite Role Distribution'!$B$13:$G$17,5,FALSE) -> 1 | AQ38: =VLOOKUP($A38,'Onsite Role Distribution'!$B$13:$G$17,5,FALSE) -> 1 | AR38: =VLOOKUP($A38,'Onsite Role Distribution'!$B$13:$G$17,5,FALSE) -> 1 | AS38: =VLOOKUP($A38,'Onsite Role Distribution'!$B$13:$G$17,5,FALSE) -> 1 | AT38: =VLOOKUP($A38,'Onsite Role Distribution'!$B$13:$G$17,5,FALSE) -> 1 | AU38: =VLOOKUP($A38,'Onsite Role Distribution'!$B$13:$G$17,5,FALSE) -> 1 | ... AY38: =VLOOKUP($A38,'Onsite Role Distribution'!$B$13:$G$17,5,FALSE) -> 1 | AZ38: 1 | BA38: =VLOOKUP($A38,'Onsite Role Distribution'!$B$13:$G$17,6,FALSE) -> 1 | BB38: =VLOOKUP($A38,'Onsite Role Distribution'!$B$13:$G$17,6,FALSE) -> 1 | BC38: =VLOOKUP($A38,'Onsite Role Distribution'!$B$13:$G$17,6,FALSE) -> 1 | BD38: =VLOOKUP($A38,'Onsite Role Distribution'!$B$13:$G$17,6,FALSE) -> 1 | BE38: =VLOOKUP($A38,'Onsite Role Distribution'!$B$13:$G$17,6,FALSE) -> 1 | BF38: =VLOOKUP($A38,'Onsite Role Distribution'!$B$13:$G$17,6,FALSE) -> 1 | BG38: =VLOOKUP($A38,'Onsite Role Distribution'!$B$13:$G$17,6,FALSE) -> 1 | BH38: =VLOOKUP($A38,'Onsite Role Distribution'!$B$13:$G$17,6,FALSE) -> 1 | ... BK38: =VLOOKUP($A38,'Onsite Role Distribution'!$B$13:$G$17,6,FALSE) -> 1
A39: Tester | B39: Onsite-Landed | C39: =A39&B39 -> TesterOnsite-Landed | D39: =VLOOKUP($A39,'Onsite Role Distribution'!$B$13:$G$17,2,FALSE) -> 2 | E39: =VLOOKUP($A39,'Onsite Role Distribution'!$B$13:$G$17,2,FALSE) -> 2 | F39: =VLOOKUP($A39,'Onsite Role Distribution'!$B$13:$G$17,2,FALSE) -> 2 | G39: =VLOOKUP($A39,'Onsite Role Distribution'!$B$13:$G$17,2,FALSE) -> 2 | H39: =VLOOKUP($A39,'Onsite Role Distribution'!$B$13:$G$17,2,FALSE) -> 2 | I39: =VLOOKUP($A39,'Onsite Role Distribution'!$B$13:$G$17,2,FALSE) -> 2 | J39: =VLOOKUP($A39,'Onsite Role Distribution'!$B$13:$G$17,2,FALSE) -> 2 | K39: =VLOOKUP($A39,'Onsite Role Distribution'!$B$13:$G$17,2,FALSE) -> 2 | ... O39: =VLOOKUP($A39,'Onsite Role Distribution'!$B$13:$G$17,2,FALSE) -> 2 | P39: =VLOOKUP($A39,'Onsite Role Distribution'!$B$13:$G$17,3,FALSE) -> 0 | Q39: =VLOOKUP($A39,'Onsite Role Distribution'!$B$13:$G$17,3,FALSE) -> 0 | R39: =VLOOKUP($A39,'Onsite Role Distribution'!$B$13:$G$17,3,FALSE) -> 0 | S39: =VLOOKUP($A39,'Onsite Role Distribution'!$B$13:$G$17,3,FALSE) -> 0 | T39: =VLOOKUP($A39,'Onsite Role Distribution'!$B$13:$G$17,3,FALSE) -> 0 | U39: =VLOOKUP($A39,'Onsite Role Distribution'!$B$13:$G$17,3,FALSE) -> 0 | V39: =VLOOKUP($A39,'Onsite Role Distribution'!$B$13:$G$17,3,FALSE) -> 0 | W39: =VLOOKUP($A39,'Onsite Role Distribution'!$B$13:$G$17,3,FALSE) -> 0 | ... AA39: =VLOOKUP($A39,'Onsite Role Distribution'!$B$13:$G$17,3,FALSE) -> 0 | AB39: =VLOOKUP($A39,'Onsite Role Distribution'!$B$13:$G$17,4,FALSE) -> 0 | AC39: =VLOOKUP($A39,'Onsite Role Distribution'!$B$13:$G$17,4,FALSE) -> 0 | AD39: =VLOOKUP($A39,'Onsite Role Distribution'!$B$13:$G$17,4,FALSE) -> 0 | AE39: =VLOOKUP($A39,'Onsite Role Distribution'!$B$13:$G$17,4,FALSE) -> 0 | AF39: =VLOOKUP($A39,'Onsite Role Distribution'!$B$13:$G$17,4,FALSE) -> 0 | AG39: =VLOOKUP($A39,'Onsite Role Distribution'!$B$13:$G$17,4,FALSE) -> 0 | AH39: =VLOOKUP($A39,'Onsite Role Distribution'!$B$13:$G$17,4,FALSE) -> 0 | AI39: =VLOOKUP($A39,'Onsite Role Distribution'!$B$13:$G$17,4,FALSE) -> 0 | ... AM39: =VLOOKUP($A39,'Onsite Role Distribution'!$B$13:$G$17,4,FALSE) -> 0 | AN39: =VLOOKUP($A39,'Onsite Role Distribution'!$B$13:$G$17,5,FALSE) -> 0 | AO39: =VLOOKUP($A39,'Onsite Role Distribution'!$B$13:$G$17,5,FALSE) -> 0 | AP39: =VLOOKUP($A39,'Onsite Role Distribution'!$B$13:$G$17,5,FALSE) -> 0 | AQ39: =VLOOKUP($A39,'Onsite Role Distribution'!$B$13:$G$17,5,FALSE) -> 0 | AR39: =VLOOKUP($A39,'Onsite Role Distribution'!$B$13:$G$17,5,FALSE) -> 0 | AS39: =VLOOKUP($A39,'Onsite Role Distribution'!$B$13:$G$17,5,FALSE) -> 0 | AT39: =VLOOKUP($A39,'Onsite Role Distribution'!$B$13:$G$17,5,FALSE) -> 0 | AU39: =VLOOKUP($A39,'Onsite Role Distribution'!$B$13:$G$17,5,FALSE) -> 0 | ... AY39: =VLOOKUP($A39,'Onsite Role Distribution'!$B$13:$G$17,5,FALSE) -> 0 | AZ39: 0 | BA39: =VLOOKUP($A39,'Onsite Role Distribution'!$B$13:$G$17,6,FALSE) -> 0 | BB39: =VLOOKUP($A39,'Onsite Role Distribution'!$B$13:$G$17,6,FALSE) -> 0 | BC39: =VLOOKUP($A39,'Onsite Role Distribution'!$B$13:$G$17,6,FALSE) -> 0 | BD39: =VLOOKUP($A39,'Onsite Role Distribution'!$B$13:$G$17,6,FALSE) -> 0 | BE39: =VLOOKUP($A39,'Onsite Role Distribution'!$B$13:$G$17,6,FALSE) -> 0 | BF39: =VLOOKUP($A39,'Onsite Role Distribution'!$B$13:$G$17,6,FALSE) -> 0 | BG39: =VLOOKUP($A39,'Onsite Role Distribution'!$B$13:$G$17,6,FALSE) -> 0 | BH39: =VLOOKUP($A39,'Onsite Role Distribution'!$B$13:$G$17,6,FALSE) -> 0 | ... BK39: =VLOOKUP($A39,'Onsite Role Distribution'!$B$13:$G$17,6,FALSE) -> 0
