Workbook

Sheet FTE
A1: TOTAL FTE Year 1 | B1: 39
B2: Year1 | C2: Year2 | D2: Year3 | E2: Year4 | F2: Year5
A3: Onsite FTE (non-FSI) | B3: 6 | C3: 6 | D3: 4 | E3: 4 | F3: 1
A4: Onsite FTE (FSI) | B4: 0 | C4: 0 | D4: 0 | E4: 1 | F4: 0
A5: Onsite FTE (Landed) | B5: 7 | C5: 3 | D5: 2 | E5: 2 | F5: 2
A6: Onsite | B6: =B3+B4+B5 -> 13 | C6: =C3+C4+C5 -> 9 | D6: =D3+D4+D5 -> 6 | E6: =E3+E4+E5 -> 7 | F6: =F3+F4+F5 -> 3
A7: Offshore | B7: 23 | C7: 22 | D7: 20 | E7: 12 | F7: 13
A8: Total | B8: =SUM(B6:B7) -> 36 | C8: =SUM(C6:C7) -> 31 | D8: =SUM(D6:D7) -> 26 | E8: =SUM(E6:E7) -> 19 | F8: =SUM(F6:F7) -> 16

Sheet India Role Distribution
A2: India | B2: BSA | C2: 0.108253
A3: India | B3: Developer | C3: 0.331456
A4: India | B4: Tester | C4: 0.176442
A5: India | B5: Maintenance | C5: 0.23342
A6: India | B6: PM | C6: 0.080962
A7: India | B7: Other | C7: 0.06945
D13: =12*C2 -> 1.299036

Sheet Onsite Role Distribution
C2: Year1 | D2: Year2 | E2: Year3 | F2: Year4 | G2: Year5
A3: Onsite | B3: PM | C3: 0 | D3: 0 | E3: 0 | F3: 0 | G3: 0
B4: Lead | C4: 1 | D4: 1 | E4: 1 | F4: 1 | G4: 0
B5: BSA | C5: 2 | D5: 2 | E5: 1 | F5: 1 | G5: 0
B6: Dev | C6: 2 | D6: 2 | E6: 2 | F6: 2 | G6: 2
B7: Tester | C7: 1 | D7: 1 | E7: 0 | F7: 0 | G7: 0
A8: Onsite-FSI | B8: PM
B9: Lead
B10: BSA | C10: 0 | D10: 0 | E10: 0 | F10: 0 | G10: 0
B11: Dev | C11: 0 | D11: 0 | E11: 0 | F11: 1 | G11: 0
B12: Tester
A13: Onsite-Landed | B13: PM
B14: Lead | C14: 1 | D14: 0 | E14: 0 | F14: 0 | G14: 0
B15: BSA | C15: 2 | D15: 1 | E15: 0 | F15: 0 | G15: 0
B16: Dev | C16: 3 | D16: 1 | E16: 1 | F16: 1 | G16: 1
B17: Tester | C17: 1 | D17: 1 | E17: 1 | F17: 1 | G17: 1

Sheet Productivity
B2: Year1 | C2: Year2 | D2: Year3 | E2: Year4 | F2: Year5
A3: Productivity | C3: 0.15 | D3: 0.34 | E3: 0.39 | F3: 0.44

Sheet Transfer
B2: Year1 | C2: Year2 | D2: Year3 | E2: Year4 | F2: Year5
A3: Transfer | E3: 0.15 | F3: 0.15

Sheet RLS
A25: Role | B25: Location | C25: RoleLocation | D25: M1 | E25: M2 | F25: M3 | G25: M4 | H25: M5 | I25: M6 | J25: M7 | K25: M8 | L25: M9 | M25: M10 | N25: M11 | O25: M12 | P25: M13 | Q25: M14 | R25: M15 | S25: M16 | T25: M17 | U25: M18 | V25: M19 | W25: M20 | X25: M21 | Y25: M22 | Z25: M23 | AA25: M24 | AB25: M25 | AC25: M26 | AD25: M27 | AE25: M28 | AF25: M29 | AG25: M30 | AH25: M31 | AI25: M32 | AJ25: M33 | AK25: M34 | AL25: M35 | AM25: M36 | AN25: M37 | AO25: M38 | AP25: M39 | AQ25: M40 | AR25: M41 | AS25: M42 | AT25: M43 | AU25: M44 | AV25: M45 | AW25: M46 | AX25: M47 | AY25: M48 | AZ25: M49 | BA25: M50 | BB25: M51 | BC25: M52 | BD25: M53 | BE25: M54 | BF25: M55 | BG25: M56 | BH25: M57 | BI25: M58 | BJ25: M59 | BK25: M60
A26: BSA | B26: India | C26: =A26&B26 -> BSAIndia | D26: =ROUND(FTE!$B$7*'India Role Distribution'!$C2,0) -> 2 | E26: =ROUND(FTE!$B$7*'India Role Distribution'!$C2,0) -> 2 | F26: =ROUND(FTE!$B$7*'India Role Distribution'!$C2,0) -> 2 | G26: =ROUND(FTE!$B$7*'India Role Distribution'!$C2,0) -> 2 | H26: =ROUND(FTE!$B$7*'India Role Distribution'!$C2,0) -> 2 | I26: =ROUND(FTE!$B$7*'India Role Distribution'!$C2,0) -> 2 | J26: =ROUND(FTE!$B$7*'India Role Distribution'!$C2,0) -> 2 | K26: =ROUND(FTE!$B$7*'India Role Distribution'!$C2,0) -> 2 | ... O26: =ROUND(FTE!$B$7*'India Role Distribution'!$C2,0) -> 2 | P26: =ROUND(FTE!$C$7*'India Role Distribution'!$C2,0) -> 2 | Q26: =ROUND(FTE!$C$7*'India Role Distribution'!$C2,0) -> 2 | R26: =ROUND(FTE!$C$7*'India Role Distribution'!$C2,0) -> 2 | S26: =ROUND(FTE!$C$7*'India Role Distribution'!$C2,0) -> 2 | T26: =ROUND(FTE!$C$7*'India Role Distribution'!$C2,0) -> 2 | U26: =ROUND(FTE!$C$7*'India Role Distribution'!$C2,0) -> 2 | V26: =ROUND(FTE!$C$7*'India Role Distribution'!$C2,0) -> 2 | W26: =ROUND(FTE!$C$7*'India Role Distribution'!$C2,0) -> 2 | ... AA26: =ROUND(FTE!$C$7*'India Role Distribution'!$C2,0) -> 2 | AB26: =ROUND(FTE!$D$7*'India Role Distribution'!$C2,0) -> 2 | AC26: =ROUND(FTE!$D$7*'India Role Distribution'!$C2,0) -> 2 | AD26: =ROUND(FTE!$D$7*'India Role Distribution'!$C2,0) -> 2 | AE26: =ROUND(FTE!$D$7*'India Role Distribution'!$C2,0) -> 2 | AF26: =ROUND(FTE!$D$7*'India Role Distribution'!$C2,0) -> 2 | AG26: =ROUND(FTE!$D$7*'India Role Distribution'!$C2,0) -> 2 | AH26: =ROUND(FTE!$D$7*'India Role Distribution'!$C2,0) -> 2 | AI26: =ROUND(FTE!$D$7*'India Role Distribution'!$C2,0) -> 2 | ... AM26: =ROUND(FTE!$D$7*'India Role Distribution'!$C2,0) -> 2 | AN26: =ROUND(FTE!$E$7*'India Role Distribution'!$C2,0) -> 1 | AO26: =ROUND(FTE!$E$7*'India Role Distribution'!$C2,0) -> 1 | AP26: =ROUND(FTE!$E$7*'India Role Distribution'!$C2,0) -> 1 | AQ26: =ROUND(FTE!$E$7*'India Role Distribution'!$C2,0) -> 1 | AR26: =ROUND(FTE!$E$7*'India Role Distribution'!$C2,0) -> 1 | AS26: =ROUND(FTE!$E$7*'India Role Distribution'!$C2,0) -> 1 | AT26: =ROUND(FTE!$E$7*'India Role Distribution'!$C2,0) -> 1 | AU26: =ROUND(FTE!$E$7*'India Role Distribution'!$C2,0) -> 1 | ... AY26: =ROUND(FTE!$E$7*'India Role Distribution'!$C2,0) -> 1 | AZ26: =ROUND(FTE!$F$7*'India Role Distribution'!$C2,0) -> 1 | BA26: =ROUND(FTE!$F$7*'India Role Distribution'!$C2,0) -> 1 | BB26: =ROUND(FTE!$F$7*'India Role Distribution'!$C2,0) -> 1 | BC26: =ROUND(FTE!$F$7*'India Role Distribution'!$C2,0) -> 1 | BD26: =ROUND(FTE!$F$7*'India Role Distribution'!$C2,0) -> 1 | BE26: =ROUND(FTE!$F$7*'India Role Distribution'!$C2,0) -> 1 | BF26: =ROUND(FTE!$F$7*'India Role Distribution'!$C2,0) -> 1 | BG26: =ROUND(FTE!$F$7*'India Role Distribution'!$C2,0) -> 1 | ... BK26: =ROUND(FTE!$F$7*'India Role Distribution'!$C2,0) -> 1
A27: Dev | B27: India | C27: =A27&B27 -> DevIndia | D27: =ROUND(FTE!$B$7*'India Role Distribution'!$C3,0) -> 8 | E27: =ROUND(FTE!$B$7*'India Role Distribution'!$C3,0) -> 8 | F27: =ROUND(FTE!$B$7*'India Role Distribution'!$C3,0) -> 8 | G27: =ROUND(FTE!$B$7*'India Role Distribution'!$C3,0) -> 8 | H27: =ROUND(FTE!$B$7*'India Role Distribution'!$C3,0) -> 8 | I27: =ROUND(FTE!$B$7*'India Role Distribution'!$C3,0) -> 8 | J27: =ROUND(FTE!$B$7*'India Role Distribution'!$C3,0) -> 8 | K27: =ROUND(FTE!$B$7*'India Role Distribution'!$C3,0) -> 8 | ... O27: =ROUND(FTE!$B$7*'India Role Distribution'!$C3,0) -> 8 | P27: =ROUND(FTE!$C$7*'India Role Distribution'!$C3,0) -> 7 | Q27: =ROUND(FTE!$C$7*'India Role Distribution'!$C3,0) -> 7 | R27: =ROUND(FTE!$C$7*'India Role Distribution'!$C3,0) -> 7 | S27: =ROUND(FTE!$C$7*'India Role Distribution'!$C3,0) -> 7 | T27: =ROUND(FTE!$C$7*'India Role Distribution'!$C3,0) -> 7 | U27: =ROUND(FTE!$C$7*'India Role Distribution'!$C3,0) -> 7 | V27: =ROUND(FTE!$C$7*'India Role Distribution'!$C3,0) -> 7 | W27: =ROUND(FTE!$C$7*'India Role Distribution'!$C3,0) -> 7 | ... AA27: =ROUND(FTE!$C$7*'India Role Distribution'!$C3,0) -> 7 | AB27: =ROUND(FTE!$D$7*'India Role Distribution'!$C3,0) -> 7 | AC27: =ROUND(FTE!$D$7*'India Role Distribution'!$C3,0) -> 7 | AD27: =ROUND(FTE!$D$7*'India Role Distribution'!$C3,0) -> 7 | AE27: =ROUND(FTE!$D$7*'India Role Distribution'!$C3,0) -> 7 | AF27: =ROUND(FTE!$D$7*'India Role Distribution'!$C3,0) -> 7 | AG27: =ROUND(FTE!$D$7*'India Role Distribution'!$C3,0) -> 7 | AH27: =ROUND(FTE!$D$7*'India Role Distribution'!$C3,0) -> 7 | AI27: =ROUND(FTE!$D$7*'India Role Distribution'!$C3,0) -> 7 | ... AM27: =ROUND(FTE!$D$7*'India Role Distribution'!$C3,0) -> 7 | AN27: =ROUND(FTE!$E$7*'India Role Distribution'!$C3,0) -> 4 | AO27: =ROUND(FTE!$E$7*'India Role Distribution'!$C3,0) -> 4 | AP27: =ROUND(FTE!$E$7*'India Role Distribution'!$C3,0) -> 4 | AQ27: =ROUND(FTE!$E$7*'India Role Distribution'!$C3,0) -> 4 | AR27: =ROUND(FTE!$E$7*'India Role Distribution'!$C3,0) -> 4 | AS27: =ROUND(FTE!$E$7*'India Role Distribution'!$C3,0) -> 4 | AT27: =ROUND(FTE!$E$7*'India Role Distribution'!$C3,0) -> 4 | AU27: =ROUND(FTE!$E$7*'India Role Distribution'!$C3,0) -> 4 | ... AY27: =ROUND(FTE!$E$7*'India Role Distribution'!$C3,0) -> 4 | AZ27: =ROUND(FTE!$F$7*'India Role Distribution'!$C3,0) -> 4 | BA27: =ROUND(FTE!$F$7*'India Role Distribution'!$C3,0) -> 4 | BB27: =ROUND(FTE!$F$7*'India Role Distribution'!$C3,0) -> 4 | BC27: =ROUND(FTE!$F$7*'India Role Distribution'!$C3,0) -> 4 | BD27: =ROUND(FTE!$F$7*'India Role Distribution'!$C3,0) -> 4 | BE27: =ROUND(FTE!$F$7*'India Role Distribution'!$C3,0) -> 4 | BF27: =ROUND(FTE!$F$7*'India Role Distribution'!$C3,0) -> 4 | BG27: =ROUND(FTE!$F$7*'India Role Distribution'!$C3,0) -> 4 | ... BK27: =ROUND(FTE!$F$7*'India Role Distribution'!$C3,0) -> 4
A28: Tester | B28: India | C28: =A28&B28 -> TesterIndia | D28: =ROUND(FTE!$B$7*'India Role Distribution'!$C4,0) -> 4 | E28: =ROUND(FTE!$B$7*'India Role Distribution'!$C4,0) -> 4 | F28: =ROUND(FTE!$B$7*'India Role Distribution'!$C4,0) -> 4 | G28: =ROUND(FTE!$B$7*'India Role Distribution'!$C4,0) -> 4 | H28: =ROUND(FTE!$B$7*'India Role Distribution'!$C4,0) -> 4 | I28: =ROUND(FTE!$B$7*'India Role Distribution'!$C4,0) -> 4 | J28: =ROUND(FTE!$B$7*'India Role Distribution'!$C4,0) -> 4 | K28: =ROUND(FTE!$B$7*'India Role Distribution'!$C4,0) -> 4 | ... O28: =ROUND(FTE!$B$7*'India Role Distribution'!$C4,0) -> 4 | P28: =ROUND(FTE!$C$7*'India Role Distribution'!$C4,0) -> 4 | Q28: =ROUND(FTE!$C$7*'India Role Distribution'!$C4,0) -> 4 | R28: =ROUND(FTE!$C$7*'India Role Distribution'!$C4,0) -> 4 | S28: =ROUND(FTE!$C$7*'India Role Distribution'!$C4,0) -> 4 | T28: =ROUND(FTE!$C$7*'India Role Distribution'!$C4,0) -> 4 | U28: =ROUND(FTE!$C$7*'India Role Distribution'!$C4,0) -> 4 | V28: =ROUND(FTE!$C$7*'India Role Distribution'!$C4,0) -> 4 | W28: =ROUND(FTE!$C$7*'India Role Distribution'!$C4,0) -> 4 | ... AA28: =ROUND(FTE!$C$7*'India Role Distribution'!$C4,0) -> 4 | AB28: =ROUND(FTE!$D$7*'India Role Distribution'!$C4,0) -> 4 | AC28: =ROUND(FTE!$D$7*'India Role Distribution'!$C4,0) -> 4 | AD28: =ROUND(FTE!$D$7*'India Role Distribution'!$C4,0) -> 4 | AE28: =ROUND(FTE!$D$7*'India Role Distribution'!$C4,0) -> 4 | AF28: =ROUND(FTE!$D$7*'India Role Distribution'!$C4,0) -> 4 | AG28: =ROUND(FTE!$D$7*'India Role Distribution'!$C4,0) -> 4 | AH28: =ROUND(FTE!$D$7*'India Role Distribution'!$C4,0) -> 4 | AI28: =ROUND(FTE!$D$7*'India Role Distribution'!$C4,0) -> 4 | ... AM28: =ROUND(FTE!$D$7*'India Role Distribution'!$C4,0) -> 4 | AN28: =ROUND(FTE!$E$7*'India Role Distribution'!$C4,0) -> 2 | AO28: =ROUND(FTE!$E$7*'India Role Distribution'!$C4,0) -> 2 | AP28: =ROUND(FTE!$E$7*'India Role Distribution'!$C4,0) -> 2 | AQ28: =ROUND(FTE!$E$7*'India Role Distribution'!$C4,0) -> 2 | AR28: =ROUND(FTE!$E$7*'India Role Distribution'!$C4,0) -> 2 | AS28: =ROUND(FTE!$E$7*'India Role Distribution'!$C4,0) -> 2 | AT28: =ROUND(FTE!$E$7*'India Role Distribution'!$C4,0) -> 2 | AU28: =ROUND(FTE!$E$7*'India Role Distribution'!$C4,0) -> 2 | ... AY28: =ROUND(FTE!$E$7*'India Role Distribution'!$C4,0) -> 2 | AZ28: =ROUND(FTE!$F$7*'India Role Distribution'!$C4,0) -> 2 | BA28: =ROUND(FTE!$F$7*'India Role Distribution'!$C4,0) -> 2 | BB28: =ROUND(FTE!$F$7*'India Role Distribution'!$C4,0) -> 2 | BC28: =ROUND(FTE!$F$7*'India Role Distribution'!$C4,0) -> 2 | BD28: =ROUND(FTE!$F$7*'India Role Distribution'!$C4,0) -> 2 | BE28: =ROUND(FTE!$F$7*'India Role Distribution'!$C4,0) -> 2 | BF28: =ROUND(FTE!$F$7*'India Role Distribution'!$C4,0) -> 2 | BG28: =ROUND(FTE!$F$7*'India Role Distribution'!$C4,0) -> 2 | ... BK28: =ROUND(FTE!$F$7*'India Role Distribution'!$C4,0) -> 2
A29: Maintenance | B29: India | C29: =A29&B29 -> MaintenanceIndia | D29: =ROUND(FTE!$B$7*'India Role Distribution'!$C5,0) -> 5 | E29: =ROUND(FTE!$B$7*'India Role Distribution'!$C5,0) -> 5 | F29: =ROUND(FTE!$B$7*'India Role Distribution'!$C5,0) -> 5 | G29: =ROUND(FTE!$B$7*'India Role Distribution'!$C5,0) -> 5 | H29: =ROUND(FTE!$B$7*'India Role Distribution'!$C5,0) -> 5 | I29: =ROUND(FTE!$B$7*'India Role Distribution'!$C5,0) -> 5 | J29: =ROUND(FTE!$B$7*'India Role Distribution'!$C5,0) -> 5 | K29: =ROUND(FTE!$B$7*'India Role Distribution'!$C5,0) -> 5 | ... O29: =ROUND(FTE!$B$7*'India Role Distribution'!$C5,0) -> 5 | P29: =ROUND(FTE!$C$7*'India Role Distribution'!$C5,0) -> 5 | Q29: =ROUND(FTE!$C$7*'India Role Distribution'!$C5,0) -> 5 | R29: =ROUND(FTE!$C$7*'India Role Distribution'!$C5,0) -> 5 | S29: =ROUND(FTE!$C$7*'India Role Distribution'!$C5,0) -> 5 | T29: =ROUND(FTE!$C$7*'India Role Distribution'!$C5,0) -> 5 | U29: =ROUND(FTE!$C$7*'India Role Distribution'!$C5,0) -> 5 | V29: =ROUND(FTE!$C$7*'India Role Distribution'!$C5,0) -> 5 | W29: =ROUND(FTE!$C$7*'India Role Distribution'!$C5,0) -> 5 | ... AA29: =ROUND(FTE!$C$7*'India Role Distribution'!$C5,0) -> 5 | AB29: =ROUND(FTE!$D$7*'India Role Distribution'!$C5,0) -> 5 | AC29: =ROUND(FTE!$D$7*'India Role Distribution'!$C5,0) -> 5 | AD29: =ROUND(FTE!$D$7*'India Role Distribution'!$C5,0) -> 5 | AE29: =ROUND(FTE!$D$7*'India Role Distribution'!$C5,0) -> 5 | AF29: =ROUND(FTE!$D$7*'India Role Distribution'!$C5,0) -> 5 | AG29: =ROUND(FTE!$D$7*'India Role Distribution'!$C5,0) -> 5 | AH29: =ROUND(FTE!$D$7*'India Role Distribution'!$C5,0) -> 5 | AI29: =ROUND(FTE!$D$7*'India Role Distribution'!$C5,0) -> 5 | ... AM29: =ROUND(FTE!$D$7*'India Role Distribution'!$C5,0) -> 5 | AN29: =ROUND(FTE!$E$7*'India Role Distribution'!$C5,0) -> 3 | AO29: =ROUND(FTE!$E$7*'India Role Distribution'!$C5,0) -> 3 | AP29: =ROUND(FTE!$E$7*'India Role Distribution'!$C5,0) -> 3 | AQ29: =ROUND(FTE!$E$7*'India Role Distribution'!$C5,0) -> 3 | AR29: =ROUND(FTE!$E$7*'India Role Distribution'!$C5,0) -> 3 | AS29: =ROUND(FTE!$E$7*'India Role Distribution'!$C5,0) -> 3 | AT29: =ROUND(FTE!$E$7*'India Role Distribution'!$C5,0) -> 3 | AU29: =ROUND(FTE!$E$7*'India Role Distribution'!$C5,0) -> 3 | ... AY29: =ROUND(FTE!$E$7*'India Role Distribution'!$C5,0) -> 3 | AZ29: =ROUND(FTE!$F$7*'India Role Distribution'!$C5,0) -> 3 | BA29: =ROUND(FTE!$F$7*'India Role Distribution'!$C5,0) -> 3 | BB29: =ROUND(FTE!$F$7*'India Role Distribution'!$C5,0) -> 3 | BC29: =ROUND(FTE!$F$7*'India Role Distribution'!$C5,0) -> 3 | BD29: =ROUND(FTE!$F$7*'India Role Distribution'!$C5,0) -> 3 | BE29: =ROUND(FTE!$F$7*'India Role Distribution'!$C5,0) -> 3 | BF29: =ROUND(FTE!$F$7*'India Role Distribution'!$C5,0) -> 3 | BG29: =ROUND(FTE!$F$7*'India Role Distribution'!$C5,0) -> 3 | ... BK29: =ROUND(FTE!$F$7*'India Role Distribution'!$C5,0) -> 3
A30: PM | B30: India | C30: =A30&B30 -> PMIndia | D30: =ROUND(FTE!$B$7*'India Role Distribution'!$C6,0) -> 2 | E30: =ROUND(FTE!$B$7*'India Role Distribution'!$C6,0) -> 2 | F30: =ROUND(FTE!$B$7*'India Role Distribution'!$C6,0) -> 2 | G30: =ROUND(FTE!$B$7*'India Role Distribution'!$C6,0) -> 2 | H30: =ROUND(FTE!$B$7*'India Role Distribution'!$C6,0) -> 2 | I30: =ROUND(FTE!$B$7*'India Role Distribution'!$C6,0) -> 2 | J30: =ROUND(FTE!$B$7*'India Role Distribution'!$C6,0) -> 2 | K30: =ROUND(FTE!$B$7*'India Role Distribution'!$C6,0) -> 2 | ... O30: =ROUND(FTE!$B$7*'India Role Distribution'!$C6,0) -> 2 | P30: =ROUND(FTE!$C$7*'India Role Distribution'!$C6,0) -> 2 | Q30: =ROUND(FTE!$C$7*'India Role Distribution'!$C6,0) -> 2 | R30: =ROUND(FTE!$C$7*'India Role Distribution'!$C6,0) -> 2 | S30: =ROUND(FTE!$C$7*'India Role Distribution'!$C6,0) -> 2 | T30: =ROUND(FTE!$C$7*'India Role Distribution'!$C6,0) -> 2 | U30: =ROUND(FTE!$C$7*'India Role Distribution'!$C6,0) -> 2 | V30: =ROUND(FTE!$C$7*'India Role Distribution'!$C6,0) -> 2 | W30: =ROUND(FTE!$C$7*'India Role Distribution'!$C6,0) -> 2 | ... AA30: =ROUND(FTE!$C$7*'India Role Distribution'!$C6,0) -> 2 | AB30: =ROUND(FTE!$D$7*'India Role Distribution'!$C6,0) -> 2 | AC30: =ROUND(FTE!$D$7*'India Role Distribution'!$C6,0) -> 2 | AD30: =ROUND(FTE!$D$7*'India Role Distribution'!$C6,0) -> 2 | AE30: =ROUND(FTE!$D$7*'India Role Distribution'!$C6,0) -> 2 | AF30: =ROUND(FTE!$D$7*'India Role Distribution'!$C6,0) -> 2 | AG30: =ROUND(FTE!$D$7*'India Role Distribution'!$C6,0) -> 2 | AH30: =ROUND(FTE!$D$7*'India Role Distribution'!$C6,0) -> 2 | AI30: =ROUND(FTE!$D$7*'India Role Distribution'!$C6,0) -> 2 | ... AM30: =ROUND(FTE!$D$7*'India Role Distribution'!$C6,0) -> 2 | AN30: =ROUND(FTE!$E$7*'India Role Distribution'!$C6,0) -> 1 | AO30: =ROUND(FTE!$E$7*'India Role Distribution'!$C6,0) -> 1 | AP30: =ROUND(FTE!$E$7*'India Role Distribution'!$C6,0) -> 1 | AQ30: =ROUND(FTE!$E$7*'India Role Distribution'!$C6,0) -> 1 | AR30: =ROUND(FTE!$E$7*'India Role Distribution'!$C6,0) -> 1 | AS30: =ROUND(FTE!$E$7*'India Role Distribution'!$C6,0) -> 1 | AT30: =ROUND(FTE!$E$7*'India Role Distribution'!$C6,0) -> 1 | AU30: =ROUND(FTE!$E$7*'India Role Distribution'!$C6,0) -> 1 | ... AY30: =ROUND(FTE!$E$7*'India Role Distribution'!$C6,0) -> 1 | AZ30: =ROUND(FTE!$F$7*'India Role Distribution'!$C6,0) -> 1 | BA30: =ROUND(FTE!$F$7*'India Role Distribution'!$C6,0) -> 1 | BB30: =ROUND(FTE!$F$7*'India Role Distribution'!$C6,0) -> 1 | BC30: =ROUND(FTE!$F$7*'India Role Distribution'!$C6,0) -> 1 | BD30: =ROUND(FTE!$F$7*'India Role Distribution'!$C6,0) -> 1 | BE30: =ROUND(FTE!$F$7*'India Role Distribution'!$C6,0) -> 1 | BF30: =ROUND(FTE!$F$7*'India Role Distribution'!$C6,0) -> 1 | BG30: =ROUND(FTE!$F$7*'India Role Distribution'!$C6,0) -> 1 | ... BK30: =ROUND(FTE!$F$7*'India Role Distribution'!$C6,0) -> 1
A31: Lead | B31: India | C31: =A31&B31 -> LeadIndia | D31: =ROUND(FTE!$B$7*'India Role Distribution'!$C7,0) -> 2 | E31: =ROUND(FTE!$B$7*'India Role Distribution'!$C7,0) -> 2 | F31: =ROUND(FTE!$B$7*'India Role Distribution'!$C7,0) -> 2 | G31: =ROUND(FTE!$B$7*'India Role Distribution'!$C7,0) -> 2 | H31: =ROUND(FTE!$B$7*'India Role Distribution'!$C7,0) -> 2 | I31: =ROUND(FTE!$B$7*'India Role Distribution'!$C7,0) -> 2 | J31: =ROUND(FTE!$B$7*'India Role Distribution'!$C7,0) -> 2 | K31: =ROUND(FTE!$B$7*'India Role Distribution'!$C7,0) -> 2 | ... O31: =ROUND(FTE!$B$7*'India Role Distribution'!$C7,0) -> 2 | P31: =ROUND(FTE!$C$7*'India Role Distribution'!$C7,0) -> 2 | Q31: =ROUND(FTE!$C$7*'India Role Distribution'!$C7,0) -> 2 | R31: =ROUND(FTE!$C$7*'India Role Distribution'!$C7,0) -> 2 | S31: =ROUND(FTE!$C$7*'India Role Distribution'!$C7,0) -> 2 | T31: =ROUND(FTE!$C$7*'India Role Distribution'!$C7,0) -> 2 | U31: =ROUND(FTE!$C$7*'India Role Distribution'!$C7,0) -> 2 | V31: =ROUND(FTE!$C$7*'India Role Distribution'!$C7,0) -> 2 | W31: =ROUND(FTE!$C$7*'India Role Distribution'!$C7,0) -> 2 | ... AA31: =ROUND(FTE!$C$7*'India Role Distribution'!$C7,0) -> 2 | AB31: =ROUND(FTE!$D$7*'India Role Distribution'!$C7,0) -> 1 | AC31: =ROUND(FTE!$D$7*'India Role Distribution'!$C7,0) -> 1 | AD31: =ROUND(FTE!$D$7*'India Role Distribution'!$C7,0) -> 1 | AE31: =ROUND(FTE!$D$7*'India Role Distribution'!$C7,0) -> 1 | AF31: =ROUND(FTE!$D$7*'India Role Distribution'!$C7,0) -> 1 | AG31: =ROUND(FTE!$D$7*'India Role Distribution'!$C7,0) -> 1 | AH31: =ROUND(FTE!$D$7*'India Role Distribution'!$C7,0) -> 1 | AI31: =ROUND(FTE!$D$7*'India Role Distribution'!$C7,0) -> 1 | ... AM31: =ROUND(FTE!$D$7*'India Role Distribution'!$C7,0) -> 1 | AN31: =ROUND(FTE!$E$7*'India Role Distribution'!$C7,0) -> 1 | AO31: =ROUND(FTE!$E$7*'India Role Distribution'!$C7,0) -> 1 | AP31: =ROUND(FTE!$E$7*'India Role Distribution'!$C7,0) -> 1 | AQ31: =ROUND(FTE!$E$7*'India Role Distribution'!$C7,0) -> 1 | AR31: =ROUND(FTE!$E$7*'India Role Distribution'!$C7,0) -> 1 | AS31: =ROUND(FTE!$E$7*'India Role Distribution'!$C7,0) -> 1 | AT31: =ROUND(FTE!$E$7*'India Role Distribution'!$C7,0) -> 1 | AU31: =ROUND(FTE!$E$7*'India Role Distribution'!$C7,0) -> 1 | ... AY31: =ROUND(FTE!$E$7*'India Role Distribution'!$C7,0) -> 1 | AZ31: =ROUND(FTE!$F$7*'India Role Distribution'!$C7,0) -> 1 | BA31: =ROUND(FTE!$F$7*'India Role Distribution'!$C7,0) -> 1 | BB31: =ROUND(FTE!$F$7*'India Role Distribution'!$C7,0) -> 1 | BC31: =ROUND(FTE!$F$7*'India Role Distribution'!$C7,0) -> 1 | BD31: =ROUND(FTE!$F$7*'India Role Distribution'!$C7,0) -> 1 | BE31: =ROUND(FTE!$F$7*'India Role Distribution'!$C7,0) -> 1 | BF31: =ROUND(FTE!$F$7*'India Role Distribution'!$C7,0) -> 1 | BG31: =ROUND(FTE!$F$7*'India Role Distribution'!$C7,0) -> 1 | ... BK31: =ROUND(FTE!$F$7*'India Role Distribution'!$C7,0) -> 1
A32: BSA | B32: Onsite | C32: =A32&B32 -> BSAOnsite | D32: =VLOOKUP($A32,'Onsite Role Distribution'!$B$3:$G$7,2,FALSE)+VLOOKUP($A32,'Onsite Role Distribution'!$B$8:$G$12,2,FALSE) -> 2 | E32: =VLOOKUP($A32,'Onsite Role Distribution'!$B$3:$G$7,2,FALSE)+VLOOKUP($A32,'Onsite Role Distribution'!$B$8:$G$12,2,FALSE) -> 2 | F32: =VLOOKUP($A32,'Onsite Role Distribution'!$B$3:$G$7,2,FALSE)+VLOOKUP($A32,'Onsite Role Distribution'!$B$8:$G$12,2,FALSE) -> 2 | G32: =VLOOKUP($A32,'Onsite Role Distribution'!$B$3:$G$7,2,FALSE)+VLOOKUP($A32,'Onsite Role Distribution'!$B$8:$G$12,2,FALSE) -> 2 | H32: =VLOOKUP($A32,'Onsite Role Distribution'!$B$3:$G$7,2,FALSE)+VLOOKUP($A32,'Onsite Role Distribution'!$B$8:$G$12,2,FALSE) -> 2 | I32: =VLOOKUP($A32,'Onsite Role Distribution'!$B$3:$G$7,2,FALSE)+VLOOKUP($A32,'Onsite Role Distribution'!$B$8:$G$12,2,FALSE) -> 2 | J32: =VLOOKUP($A32,'Onsite Role Distribution'!$B$3:$G$7,2,FALSE)+VLOOKUP($A32,'Onsite Role Distribution'!$B$8:$G$12,2,FALSE) -> 2 | K32: =VLOOKUP($A32,'Onsite Role Distribution'!$B$3:$G$7,2,FALSE)+VLOOKUP($A32,'Onsite Role Distribution'!$B$8:$G$12,2,FALSE) -> 2 | ... O32: =VLOOKUP($A32,'Onsite Role Distribution'!$B$3:$G$7,2,FALSE)+VLOOKUP($A32,'Onsite Role Distribution'!$B$8:$G$12,2,FALSE) -> 2 | P32: =VLOOKUP($A32,'Onsite Role Distribution'!$B$3:$G$7,3,FALSE)+VLOOKUP($A32,'Onsite Role Distribution'!$B$8:$G$12,3,FALSE) -> 2 | Q32: =VLOOKUP($A32,'Onsite Role Distribution'!$B$3:$G$7,3,FALSE)+VLOOKUP($A32,'Onsite Role Distribution'!$B$8:$G$12,3,FALSE) -> 2 | R32: =VLOOKUP($A32,'Onsite Role Distribution'!$B$3:$G$7,3,FALSE)+VLOOKUP($A32,'Onsite Role Distribution'!$B$8:$G$12,3,FALSE) -> 2 | S32: =VLOOKUP($A32,'Onsite Role Distribution'!$B$3:$G$7,3,FALSE)+VLOOKUP($A32,'Onsite Role Distribution'!$B$8:$G$12,3,FALSE) -> 2 | T32: =VLOOKUP($A32,'Onsite Role Distribution'!$B$3:$G$7,3,FALSE)+VLOOKUP($A32,'Onsite Role Distribution'!$B$8:$G$12,3,FALSE) -> 2 | U32: =VLOOKUP($A32,'Onsite Role Distribution'!$B$3:$G$7,3,FALSE)+VLOOKUP($A32,'Onsite Role Distribution'!$B$8:$G$12,3,FALSE) -> 2 | V32: =VLOOKUP($A32,'Onsite Role Distribution'!$B$3:$G$7,3,FALSE)+VLOOKUP($A32,'Onsite Role Distribution'!$B$8:$G$12,3,FALSE) -> 2 | W32: =VLOOKUP($A32,'Onsite Role Distribution'!$B$3:$G$7,3,FALSE)+VLOOKUP($A32,'Onsite Role Distribution'!$B$8:$G$12,3,FALSE) -> 2 | ... AA32: =VLOOKUP($A32,'Onsite Role Distribution'!$B$3:$G$7,3,FALSE)+VLOOKUP($A32,'Onsite Role Distribution'!$B$8:$G$12,3,FALSE) -> 2 | AB32: =VLOOKUP($A32,'Onsite Role Distribution'!$B$3:$G$7,4,FALSE)+VLOOKUP($A32,'Onsite Role Distribution'!$B$8:$G$12,4,FALSE) -> 1 | AC32: =VLOOKUP($A32,'Onsite Role Distribution'!$B$3:$G$7,4,FALSE)+VLOOKUP($A32,'Onsite Role Distribution'!$B$8:$G$12,4,FALSE) -> 1 | AD32: =VLOOKUP($A32,'Onsite Role Distribution'!$B$3:$G$7,4,FALSE)+VLOOKUP($A32,'Onsite Role Distribution'!$B$8:$G$12,4,FALSE) -> 1 | AE32: =VLOOKUP($A32,'Onsite Role Distribution'!$B$3:$G$7,4,FALSE)+VLOOKUP($A32,'Onsite Role Distribution'!$B$8:$G$12,4,FALSE) -> 1 | AF32: =VLOOKUP($A32,'Onsite Role Distribution'!$B$3:$G$7,4,FALSE)+VLOOKUP($A32,'Onsite Role Distribution'!$B$8:$G$12,4,FALSE) -> 1 | AG32: =VLOOKUP($A32,'Onsite Role Distribution'!$B$3:$G$7,4,FALSE)+VLOOKUP($A32,'Onsite Role Distribution'!$B$8:$G$12,4,FALSE) -> 1 | AH32: =VLOOKUP($A32,'Onsite Role Distribution'!$B$3:$G$7,4,FALSE)+VLOOKUP($A32,'Onsite Role Distribution'!$B$8:$G$12,4,FALSE) -> 1 | AI32: =VLOOKUP($A32,'Onsite Role Distribution'!$B$3:$G$7,4,FALSE)+VLOOKUP($A32,'Onsite Role Distribution'!$B$8:$G$12,4,FALSE) -> 1 | ... AM32: =VLOOKUP($A32,'Onsite Role Distribution'!$B$3:$G$7,4,FALSE)+VLOOKUP($A32,'Onsite Role Distribution'!$B$8:$G$12,4,FALSE) -> 1 | AN32: =VLOOKUP($A32,'Onsite Role Distribution'!$B$3:$G$7,5,FALSE)+VLOOKUP($A32,'Onsite Role Distribution'!$B$8:$G$12,5,FALSE) -> 1 | AO32: =VLOOKUP($A32,'Onsite Role Distribution'!$B$3:$G$7,5,FALSE)+VLOOKUP($A32,'Onsite Role Distribution'!$B$8:$G$12,5,FALSE) -> 1 | AP32: =VLOOKUP($A32,'Onsite Role Distribution'!$B$3:$G$7,5,FALSE)+VLOOKUP($A32,'Onsite Role Distribution'!$B$8:$G$12,5,FALSE) -> 1 | AQ32: =VLOOKUP($A32,'Onsite Role Distribution'!$B$3:$G$7,5,FALSE)+VLOOKUP($A32,'Onsite Role Distribution'!$B$8:$G$12,5,FALSE) -> 1 | AR32: =VLOOKUP($A32,'Onsite Role Distribution'!$B$3:$G$7,5,FALSE)+VLOOKUP($A32,'Onsite Role Distribution'!$B$8:$G$12,5,FALSE) -> 1 | AS32: =VLOOKUP($A32,'Onsite Role Distribution'!$B$3:$G$7,5,FALSE)+VLOOKUP($A32,'Onsite Role Distribution'!$B$8:$G$12,5,FALSE) -> 1 | AT32: =VLOOKUP($A32,'Onsite Role Distribution'!$B$3:$G$7,5,FALSE)+VLOOKUP($A32,'Onsite Role Distribution'!$B$8:$G$12,5,FALSE) -> 1 | AU32: =VLOOKUP($A32,'Onsite Role Distribution'!$B$3:$G$7,5,FALSE)+VLOOKUP($A32,'Onsite Role Distribution'!$B$8:$G$12,5,FALSE) -> 1 | ... AY32: =VLOOKUP($A32,'Onsite Role Distribution'!$B$3:$G$7,5,FALSE)+VLOOKUP($A32,'Onsite Role Distribution'!$B$8:$G$12,5,FALSE) -> 1 | AZ32: =VLOOKUP($A32,'Onsite Role Distribution'!$B$3:$G$7,6,FALSE)+VLOOKUP($A32,'Onsite Role Distribution'!$B$8:$G$12,6,FALSE) -> 0 | BA32: =VLOOKUP($A32,'Onsite Role Distribution'!$B$3:$G$7,6,FALSE)+VLOOKUP($A32,'Onsite Role Distribution'!$B$8:$G$12,6,FALSE) -> 0 | BB32: =VLOOKUP($A32,'Onsite Role Distribution'!$B$3:$G$7,6,FALSE)+VLOOKUP($A32,'Onsite Role Distribution'!$B$8:$G$12,6,FALSE) -> 0 | BC32: =VLOOKUP($A32,'Onsite Role Distribution'!$B$3:$G$7,6,FALSE)+VLOOKUP($A32,'Onsite Role Distribution'!$B$8:$G$12,6,FALSE) -> 0 | BD32: =VLOOKUP($A32,'Onsite Role Distribution'!$B$3:$G$7,6,FALSE)+VLOOKUP($A32,'Onsite Role Distribution'!$B$8:$G$12,6,FALSE) -> 0 | BE32: =VLOOKUP($A32,'Onsite Role Distribution'!$B$3:$G$7,6,FALSE)+VLOOKUP($A32,'Onsite Role Distribution'!$B$8:$G$12,6,FALSE) -> 0 | BF32: =VLOOKUP($A32,'Onsite Role Distribution'!$B$3:$G$7,6,FALSE)+VLOOKUP($A32,'Onsite Role Distribution'!$B$8:$G$12,6,FALSE) -> 0 | BG32: =VLOOKUP($A32,'Onsite Role Distribution'!$B$3:$G$7,6,FALSE)+VLOOKUP($A32,'Onsite Role Distribution'!$B$8:$G$12,6,FALSE) -> 0 | ... BK32: =VLOOKUP($A32,'Onsite Role Distribution'!$B$3:$G$7,6,FALSE)+VLOOKUP($A32,'Onsite Role Distribution'!$B$8:$G$12,6,FALSE) -> 0
A33: Dev | B33: Onsite | C33: =A33&B33 -> DevOnsite | D33: =VLOOKUP($A33,'Onsite Role Distribution'!$B$3:$G$7,2,FALSE)+VLOOKUP($A33,'Onsite Role Distribution'!$B$8:$G$12,2,FALSE) -> 2 | E33: =VLOOKUP($A33,'Onsite Role Distribution'!$B$3:$G$7,2,FALSE)+VLOOKUP($A33,'Onsite Role Distribution'!$B$8:$G$12,2,FALSE) -> 2 | F33: =VLOOKUP($A33,'Onsite Role Distribution'!$B$3:$G$7,2,FALSE)+VLOOKUP($A33,'Onsite Role Distribution'!$B$8:$G$12,2,FALSE) -> 2 | G33: =VLOOKUP($A33,'Onsite Role Distribution'!$B$3:$G$7,2,FALSE)+VLOOKUP($A33,'Onsite Role Distribution'!$B$8:$G$12,2,FALSE) -> 2 | H33: =VLOOKUP($A33,'Onsite Role Distribution'!$B$3:$G$7,2,FALSE)+VLOOKUP($A33,'Onsite Role Distribution'!$B$8:$G$12,2,FALSE) -> 2 | I33: =VLOOKUP($A33,'Onsite Role Distribution'!$B$3:$G$7,2,FALSE)+VLOOKUP($A33,'Onsite Role Distribution'!$B$8:$G$12,2,FALSE) -> 2 | J33: =VLOOKUP($A33,'Onsite Role Distribution'!$B$3:$G$7,2,FALSE)+VLOOKUP($A33,'Onsite Role Distribution'!$B$8:$G$12,2,FALSE) -> 2 | K33: =VLOOKUP($A33,'Onsite Role Distribution'!$B$3:$G$7,2,FALSE)+VLOOKUP($A33,'Onsite Role Distribution'!$B$8:$G$12,2,FALSE) -> 2 | ... O33: =VLOOKUP($A33,'Onsite Role Distribution'!$B$3:$G$7,2,FALSE)+VLOOKUP($A33,'Onsite Role Distribution'!$B$8:$G$12,2,FALSE) -> 2 | P33: =VLOOKUP($A33,'Onsite Role Distribution'!$B$3:$G$7,3,FALSE)+VLOOKUP($A33,'Onsite Role Distribution'!$B$8:$G$12,3,FALSE) -> 2 | Q33: =VLOOKUP($A33,'Onsite Role Distribution'!$B$3:$G$7,3,FALSE)+VLOOKUP($A33,'Onsite Role Distribution'!$B$8:$G$12,3,FALSE) -> 2 | R33: =VLOOKUP($A33,'Onsite Role Distribution'!$B$3:$G$7,3,FALSE)+VLOOKUP($A33,'Onsite Role Distribution'!$B$8:$G$12,3,FALSE) -> 2 | S33: =VLOOKUP($A33,'Onsite Role Distribution'!$B$3:$G$7,3,FALSE)+VLOOKUP($A33,'Onsite Role Distribution'!$B$8:$G$12,3,FALSE) -> 2 | T33: =VLOOKUP($A33,'Onsite Role Distribution'!$B$3:$G$7,3,FALSE)+VLOOKUP($A33,'Onsite Role Distribution'!$B$8:$G$12,3,FALSE) -> 2 | U33: =VLOOKUP($A33,'Onsite Role Distribution'!$B$3:$G$7,3,FALSE)+VLOOKUP($A33,'Onsite Role Distribution'!$B$8:$G$12,3,FALSE) -> 2 | V33: =VLOOKUP($A33,'Onsite Role Distribution'!$B$3:$G$7,3,FALSE)+VLOOKUP($A33,'Onsite Role Distribution'!$B$8:$G$12,3,FALSE) -> 2 | W33: =VLOOKUP($A33,'Onsite Role Distribution'!$B$3:$G$7,3,FALSE)+VLOOKUP($A33,'Onsite Role Distribution'!$B$8:$G$12,3,FALSE) -> 2 | ... AA33: =VLOOKUP($A33,'Onsite Role Distribution'!$B$3:$G$7,3,FALSE)+VLOOKUP($A33,'Onsite Role Distribution'!$B$8:$G$12,3,FALSE) -> 2 | AB33: =VLOOKUP($A33,'Onsite Role Distribution'!$B$3:$G$7,4,FALSE)+VLOOKUP($A33,'Onsite Role Distribution'!$B$8:$G$12,4,FALSE) -> 2 | AC33: =VLOOKUP($A33,'Onsite Role Distribution'!$B$3:$G$7,4,FALSE)+VLOOKUP($A33,'Onsite Role Distribution'!$B$8:$G$12,4,FALSE) -> 2 | AD33: =VLOOKUP($A33,'Onsite Role Distribution'!$B$3:$G$7,4,FALSE)+VLOOKUP($A33,'Onsite Role Distribution'!$B$8:$G$12,4,FALSE) -> 2 | AE33: =VLOOKUP($A33,'Onsite Role Distribution'!$B$3:$G$7,4,FALSE)+VLOOKUP($A33,'Onsite Role Distribution'!$B$8:$G$12,4,FALSE) -> 2 | AF33: =VLOOKUP($A33,'Onsite Role Distribution'!$B$3:$G$7,4,FALSE)+VLOOKUP($A33,'Onsite Role Distribution'!$B$8:$G$12,4,FALSE) -> 2 | AG33: =VLOOKUP($A33,'Onsite Role Distribution'!$B$3:$G$7,4,FALSE)+VLOOKUP($A33,'Onsite Role Distribution'!$B$8:$G$12,4,FALSE) -> 2 | AH33: =VLOOKUP($A33,'Onsite Role Distribution'!$B$3:$G$7,4,FALSE)+VLOOKUP($A33,'Onsite Role Distribution'!$B$8:$G$12,4,FALSE) -> 2 | AI33: =VLOOKUP($A33,'Onsite Role Distribution'!$B$3:$G$7,4,FALSE)+VLOOKUP($A33,'Onsite Role Distribution'!$B$8:$G$12,4,FALSE) -> 2 | ... AM33: =VLOOKUP($A33,'Onsite Role Distribution'!$B$3:$G$7,4,FALSE)+VLOOKUP($A33,'Onsite Role Distribution'!$B$8:$G$12,4,FALSE) -> 2 | AN33: =VLOOKUP($A33,'Onsite Role Distribution'!$B$3:$G$7,5,FALSE)+VLOOKUP($A33,'Onsite Role Distribution'!$B$8:$G$12,5,FALSE) -> 3 | AO33: =VLOOKUP($A33,'Onsite Role Distribution'!$B$3:$G$7,5,FALSE)+VLOOKUP($A33,'Onsite Role Distribution'!$B$8:$G$12,5,FALSE) -> 3 | AP33: =VLOOKUP($A33,'Onsite Role Distribution'!$B$3:$G$7,5,FALSE)+VLOOKUP($A33,'Onsite Role Distribution'!$B$8:$G$12,5,FALSE) -> 3 | AQ33: =VLOOKUP($A33,'Onsite Role Distribution'!$B$3:$G$7,5,FALSE)+VLOOKUP($A33,'Onsite Role Distribution'!$B$8:$G$12,5,FALSE) -> 3 | AR33: =VLOOKUP($A33,'Onsite Role Distribution'!$B$3:$G$7,5,FALSE)+VLOOKUP($A33,'Onsite Role Distribution'!$B$8:$G$12,5,FALSE) -> 3 | AS33: =VLOOKUP($A33,'Onsite Role Distribution'!$B$3:$G$7,5,FALSE)+VLOOKUP($A33,'Onsite Role Distribution'!$B$8:$G$12,5,FALSE) -> 3 | AT33: =VLOOKUP($A33,'Onsite Role Distribution'!$B$3:$G$7,5,FALSE)+VLOOKUP($A33,'Onsite Role Distribution'!$B$8:$G$12,5,FALSE) -> 3 | AU33: =VLOOKUP($A33,'Onsite Role Distribution'!$B$3:$G$7,5,FALSE)+VLOOKUP($A33,'Onsite Role Distribution'!$B$8:$G$12,5,FALSE) -> 3 | ... AY33: =VLOOKUP($A33,'Onsite Role Distribution'!$B$3:$G$7,5,FALSE)+VLOOKUP($A33,'Onsite Role Distribution'!$B$8:$G$12,5,FALSE) -> 3 | AZ33: =VLOOKUP($A33,'Onsite Role Distribution'!$B$3:$G$7,6,FALSE)+VLOOKUP($A33,'Onsite Role Distribution'!$B$8:$G$12,6,FALSE) -> 2 | BA33: =VLOOKUP($A33,'Onsite Role Distribution'!$B$3:$G$7,6,FALSE)+VLOOKUP($A33,'Onsite Role Distribution'!$B$8:$G$12,6,FALSE) -> 2 | BB33: =VLOOKUP($A33,'Onsite Role Distribution'!$B$3:$G$7,6,FALSE)+VLOOKUP($A33,'Onsite Role Distribution'!$B$8:$G$12,6,FALSE) -> 2 | BC33: =VLOOKUP($A33,'Onsite Role Distribution'!$B$3:$G$7,6,FALSE)+VLOOKUP($A33,'Onsite Role Distribution'!$B$8:$G$12,6,FALSE) -> 2 | BD33: =VLOOKUP($A33,'Onsite Role Distribution'!$B$3:$G$7,6,FALSE)+VLOOKUP($A33,'Onsite Role Distribution'!$B$8:$G$12,6,FALSE) -> 2 | BE33: =VLOOKUP($A33,'Onsite Role Distribution'!$B$3:$G$7,6,FALSE)+VLOOKUP($A33,'Onsite Role Distribution'!$B$8:$G$12,6,FALSE) -> 2 | BF33: =VLOOKUP($A33,'Onsite Role Distribution'!$B$3:$G$7,6,FALSE)+VLOOKUP($A33,'Onsite Role Distribution'!$B$8:$G$12,6,FALSE) -> 2 | BG33: =VLOOKUP($A33,'Onsite Role Distribution'!$B$3:$G$7,6,FALSE)+VLOOKUP($A33,'Onsite Role Distribution'!$B$8:$G$12,6,FALSE) -> 2 | ... BK33: =VLOOKUP($A33,'Onsite Role Distribution'!$B$3:$G$7,6,FALSE)+VLOOKUP($A33,'Onsite Role Distribution'!$B$8:$G$12,6,FALSE) -> 2
A34: Tester | B34: Onsite | C34: =A34&B34 -> TesterOnsite | D34: =VLOOKUP($A34,'Onsite Role Distribution'!$B$3:$G$7,2,FALSE)+VLOOKUP($A34,'Onsite Role Distribution'!$B$8:$G$12,2,FALSE) -> 1 | E34: =VLOOKUP($A34,'Onsite Role Distribution'!$B$3:$G$7,2,FALSE)+VLOOKUP($A34,'Onsite Role Distribution'!$B$8:$G$12,2,FALSE) -> 1 | F34: =VLOOKUP($A34,'Onsite Role Distribution'!$B$3:$G$7,2,FALSE)+VLOOKUP($A34,'Onsite Role Distribution'!$B$8:$G$12,2,FALSE) -> 1 | G34: =VLOOKUP($A34,'Onsite Role Distribution'!$B$3:$G$7,2,FALSE)+VLOOKUP($A34,'Onsite Role Distribution'!$B$8:$G$12,2,FALSE) -> 1 | H34: =VLOOKUP($A34,'Onsite Role Distribution'!$B$3:$G$7,2,FALSE)+VLOOKUP($A34,'Onsite Role Distribution'!$B$8:$G$12,2,FALSE) -> 1 | I34: =VLOOKUP($A34,'Onsite Role Distribution'!$B$3:$G$7,2,FALSE)+VLOOKUP($A34,'Onsite Role Distribution'!$B$8:$G$12,2,FALSE) -> 1 | J34: =VLOOKUP($A34,'Onsite Role Distribution'!$B$3:$G$7,2,FALSE)+VLOOKUP($A34,'Onsite Role Distribution'!$B$8:$G$12,2,FALSE) -> 1 | K34: =VLOOKUP($A34,'Onsite Role Distribution'!$B$3:$G$7,2,FALSE)+VLOOKUP($A34,'Onsite Role Distribution'!$B$8:$G$12,2,FALSE) -> 1 | ... O34: =VLOOKUP($A34,'Onsite Role Distribution'!$B$3:$G$7,2,FALSE)+VLOOKUP($A34,'Onsite Role Distribution'!$B$8:$G$12,2,FALSE) -> 1 | P34: =VLOOKUP($A34,'Onsite Role Distribution'!$B$3:$G$7,3,FALSE)+VLOOKUP($A34,'Onsite Role Distribution'!$B$8:$G$12,3,FALSE) -> 1 | Q34: =VLOOKUP($A34,'Onsite Role Distribution'!$B$3:$G$7,3,FALSE)+VLOOKUP($A34,'Onsite Role Distribution'!$B$8:$G$12,3,FALSE) -> 1 | R34: =VLOOKUP($A34,'Onsite Role Distribution'!$B$3:$G$7,3,FALSE)+VLOOKUP($A34,'Onsite Role Distribution'!$B$8:$G$12,3,FALSE) -> 1 | S34: =VLOOKUP($A34,'Onsite Role Distribution'!$B$3:$G$7,3,FALSE)+VLOOKUP($A34,'Onsite Role Distribution'!$B$8:$G$12,3,FALSE) -> 1 | T34: =VLOOKUP($A34,'Onsite Role Distribution'!$B$3:$G$7,3,FALSE)+VLOOKUP($A34,'Onsite Role Distribution'!$B$8:$G$12,3,FALSE) -> 1 | U34: =VLOOKUP($A34,'Onsite Role Distribution'!$B$3:$G$7,3,FALSE)+VLOOKUP($A34,'Onsite Role Distribution'!$B$8:$G$12,3,FALSE) -> 1 | V34: =VLOOKUP($A34,'Onsite Role Distribution'!$B$3:$G$7,3,FALSE)+VLOOKUP($A34,'Onsite Role Distribution'!$B$8:$G$12,3,FALSE) -> 1 | W34: =VLOOKUP($A34,'Onsite Role Distribution'!$B$3:$G$7,3,FALSE)+VLOOKUP($A34,'Onsite Role Distribution'!$B$8:$G$12,3,FALSE) -> 1 | ... AA34: =VLOOKUP($A34,'Onsite Role Distribution'!$B$3:$G$7,3,FALSE)+VLOOKUP($A34,'Onsite Role Distribution'!$B$8:$G$12,3,FALSE) -> 1 | AB34: =VLOOKUP($A34,'Onsite Role Distribution'!$B$3:$G$7,4,FALSE)+VLOOKUP($A34,'Onsite Role Distribution'!$B$8:$G$12,4,FALSE) -> 0 | AC34: =VLOOKUP($A34,'Onsite Role Distribution'!$B$3:$G$7,4,FALSE)+VLOOKUP($A34,'Onsite Role Distribution'!$B$8:$G$12,4,FALSE) -> 0 | AD34: =VLOOKUP($A34,'Onsite Role Distribution'!$B$3:$G$7,4,FALSE)+VLOOKUP($A34,'Onsite Role Distribution'!$B$8:$G$12,4,FALSE) -> 0 | AE34: =VLOOKUP($A34,'Onsite Role Distribution'!$B$3:$G$7,4,FALSE)+VLOOKUP($A34,'Onsite Role Distribution'!$B$8:$G$12,4,FALSE) -> 0 | AF34: =VLOOKUP($A34,'Onsite Role Distribution'!$B$3:$G$7,4,FALSE)+VLOOKUP($A34,'Onsite Role Distribution'!$B$8:$G$12,4,FALSE) -> 0 | AG34: =VLOOKUP($A34,'Onsite Role Distribution'!$B$3:$G$7,4,FALSE)+VLOOKUP($A34,'Onsite Role Distribution'!$B$8:$G$12,4,FALSE) -> 0 | AH34: =VLOOKUP($A34,'Onsite Role Distribution'!$B$3:$G$7,4,FALSE)+VLOOKUP($A34,'Onsite Role Distribution'!$B$8:$G$12,4,FALSE) -> 0 | AI34: =VLOOKUP($A34,'Onsite Role Distribution'!$B$3:$G$7,4,FALSE)+VLOOKUP($A34,'Onsite Role Distribution'!$B$8:$G$12,4,FALSE) -> 0 | ... AM34: =VLOOKUP($A34,'Onsite Role Distribution'!$B$3:$G$7,4,FALSE)+VLOOKUP($A34,'Onsite Role Distribution'!$B$8:$G$12,4,FALSE) -> 0 | AN34: =VLOOKUP($A34,'Onsite Role Distribution'!$B$3:$G$7,5,FALSE)+VLOOKUP($A34,'Onsite Role Distribution'!$B$8:$G$12,5,FALSE) -> 0 | AO34: =VLOOKUP($A34,'Onsite Role Distribution'!$B$3:$G$7,5,FALSE)+VLOOKUP($A34,'Onsite Role Distribution'!$B$8:$G$12,5,FALSE) -> 0 | AP34: =VLOOKUP($A34,'Onsite Role Distribution'!$B$3:$G$7,5,FALSE)+VLOOKUP($A34,'Onsite Role Distribution'!$B$8:$G$12,5,FALSE) -> 0 | AQ34: =VLOOKUP($A34,'Onsite Role Distribution'!$B$3:$G$7,5,FALSE)+VLOOKUP($A34,'Onsite Role Distribution'!$B$8:$G$12,5,FALSE) -> 0 | AR34: =VLOOKUP($A34,'Onsite Role Distribution'!$B$3:$G$7,5,FALSE)+VLOOKUP($A34,'Onsite Role Distribution'!$B$8:$G$12,5,FALSE) -> 0 | AS34: =VLOOKUP($A34,'Onsite Role Distribution'!$B$3:$G$7,5,FALSE)+VLOOKUP($A34,'Onsite Role Distribution'!$B$8:$G$12,5,FALSE) -> 0 | AT34: =VLOOKUP($A34,'Onsite Role Distribution'!$B$3:$G$7,5,FALSE)+VLOOKUP($A34,'Onsite Role Distribution'!$B$8:$G$12,5,FALSE) -> 0 | AU34: =VLOOKUP($A34,'Onsite Role Distribution'!$B$3:$G$7,5,FALSE)+VLOOKUP($A34,'Onsite Role Distribution'!$B$8:$G$12,5,FALSE) -> 0 | ... AY34: =VLOOKUP($A34,'Onsite Role Distribution'!$B$3:$G$7,5,FALSE)+VLOOKUP($A34,'Onsite Role Distribution'!$B$8:$G$12,5,FALSE) -> 0 | AZ34: =VLOOKUP($A34,'Onsite Role Distribution'!$B$3:$G$7,6,FALSE)+VLOOKUP($A34,'Onsite Role Distribution'!$B$8:$G$12,6,FALSE) -> 0 | BA34: =VLOOKUP($A34,'Onsite Role Distribution'!$B$3:$G$7,6,FALSE)+VLOOKUP($A34,'Onsite Role Distribution'!$B$8:$G$12,6,FALSE) -> 0 | BB34: =VLOOKUP($A34,'Onsite Role Distribution'!$B$3:$G$7,6,FALSE)+VLOOKUP($A34,'Onsite Role Distribution'!$B$8:$G$12,6,FALSE) -> 0 | BC34: =VLOOKUP($A34,'Onsite Role Distribution'!$B$3:$G$7,6,FALSE)+VLOOKUP($A34,'Onsite Role Distribution'!$B$8:$G$12,6,FALSE) -> 0 | BD34: =VLOOKUP($A34,'Onsite Role Distribution'!$B$3:$G$7,6,FALSE)+VLOOKUP($A34,'Onsite Role Distribution'!$B$8:$G$12,6,FALSE) -> 0 | BE34: =VLOOKUP($A34,'Onsite Role Distribution'!$B$3:$G$7,6,FALSE)+VLOOKUP($A34,'Onsite Role Distribution'!$B$8:$G$12,6,FALSE) -> 0 | BF34: =VLOOKUP($A34,'Onsite Role Distribution'!$B$3:$G$7,6,FALSE)+VLOOKUP($A34,'Onsite Role Distribution'!$B$8:$G$12,6,FALSE) -> 0 | BG34: =VLOOKUP($A34,'Onsite Role Distribution'!$B$3:$G$7,6,FALSE)+VLOOKUP($A34,'Onsite Role Distribution'!$B$8:$G$12,6,FALSE) -> 0 | ... BK34: =VLOOKUP($A34,'Onsite Role Distribution'!$B$3:$G$7,6,FALSE)+VLOOKUP($A34,'Onsite Role Distribution'!$B$8:$G$12,6,FALSE) -> 0
A35: PM | B35: Onsite | C35: =A35&B35 -> PMOnsite | D35: =VLOOKUP($A35,'Onsite Role Distribution'!$B$3:$G$7,2,FALSE)+VLOOKUP($A35,'Onsite Role Distribution'!$B$8:$G$12,2,FALSE) -> 0 | E35: =VLOOKUP($A35,'Onsite Role Distribution'!$B$3:$G$7,2,FALSE)+VLOOKUP($A35,'Onsite Role Distribution'!$B$8:$G$12,2,FALSE) -> 0 | F35: =VLOOKUP($A35,'Onsite Role Distribution'!$B$3:$G$7,2,FALSE)+VLOOKUP($A35,'Onsite Role Distribution'!$B$8:$G$12,2,FALSE) -> 0 | G35: =VLOOKUP($A35,'Onsite Role Distribution'!$B$3:$G$7,2,FALSE)+VLOOKUP($A35,'Onsite Role Distribution'!$B$8:$G$12,2,FALSE) -> 0 | H35: =VLOOKUP($A35,'Onsite Role Distribution'!$B$3:$G$7,2,FALSE)+VLOOKUP($A35,'Onsite Role Distribution'!$B$8:$G$12,2,FALSE) -> 0 | I35: =VLOOKUP($A35,'Onsite Role Distribution'!$B$3:$G$7,2,FALSE)+VLOOKUP($A35,'Onsite Role Distribution'!$B$8:$G$12,2,FALSE) -> 0 | J35: =VLOOKUP($A35,'Onsite Role Distribution'!$B$3:$G$7,2,FALSE)+VLOOKUP($A35,'Onsite Role Distribution'!$B$8:$G$12,2,FALSE) -> 0 | K35: =VLOOKUP($A35,'Onsite Role Distribution'!$B$3:$G$7,2,FALSE)+VLOOKUP($A35,'Onsite Role Distribution'!$B$8:$G$12,2,FALSE) -> 0 | ... O35: =VLOOKUP($A35,'Onsite Role Distribution'!$B$3:$G$7,2,FALSE)+VLOOKUP($A35,'Onsite Role Distribution'!$B$8:$G$12,2,FALSE) -> 0 | P35: =VLOOKUP($A35,'Onsite Role Distribution'!$B$3:$G$7,3,FALSE)+VLOOKUP($A35,'Onsite Role Distribution'!$B$8:$G$12,3,FALSE) -> 0 | Q35: =VLOOKUP($A35,'Onsite Role Distribution'!$B$3:$G$7,3,FALSE)+VLOOKUP($A35,'Onsite Role Distribution'!$B$8:$G$12,3,FALSE) -> 0 | R35: =VLOOKUP($A35,'Onsite Role Distribution'!$B$3:$G$7,3,FALSE)+VLOOKUP($A35,'Onsite Role Distribution'!$B$8:$G$12,3,FALSE) -> 0 | S35: =VLOOKUP($A35,'Onsite Role Distribution'!$B$3:$G$7,3,FALSE)+VLOOKUP($A35,'Onsite Role Distribution'!$B$8:$G$12,3,FALSE) -> 0 | T35: =VLOOKUP($A35,'Onsite Role Distribution'!$B$3:$G$7,3,FALSE)+VLOOKUP($A35,'Onsite Role Distribution'!$B$8:$G$12,3,FALSE) -> 0 | U35: =VLOOKUP($A35,'Onsite Role Distribution'!$B$3:$G$7,3,FALSE)+VLOOKUP($A35,'Onsite Role Distribution'!$B$8:$G$12,3,FALSE) -> 0 | V35: =VLOOKUP($A35,'Onsite Role Distribution'!$B$3:$G$7,3,FALSE)+VLOOKUP($A35,'Onsite Role Distribution'!$B$8:$G$12,3,FALSE) -> 0 | W35: =VLOOKUP($A35,'Onsite Role Distribution'!$B$3:$G$7,3,FALSE)+VLOOKUP($A35,'Onsite Role Distribution'!$B$8:$G$12,3,FALSE) -> 0 | ... AA35: =VLOOKUP($A35,'Onsite Role Distribution'!$B$3:$G$7,3,FALSE)+VLOOKUP($A35,'Onsite Role Distribution'!$B$8:$G$12,3,FALSE) -> 0 | AB35: =VLOOKUP($A35,'Onsite Role Distribution'!$B$3:$G$7,4,FALSE)+VLOOKUP($A35,'Onsite Role Distribution'!$B$8:$G$12,4,FALSE) -> 0 | AC35: =VLOOKUP($A35,'Onsite Role Distribution'!$B$3:$G$7,4,FALSE)+VLOOKUP($A35,'Onsite Role Distribution'!$B$8:$G$12,4,FALSE) -> 0 | AD35: =VLOOKUP($A35,'Onsite Role Distribution'!$B$3:$G$7,4,FALSE)+VLOOKUP($A35,'Onsite Role Distribution'!$B$8:$G$12,4,FALSE) -> 0 | AE35: =VLOOKUP($A35,'Onsite Role Distribution'!$B$3:$G$7,4,FALSE)+VLOOKUP($A35,'Onsite Role Distribution'!$B$8:$G$12,4,FALSE) -> 0 | AF35: =VLOOKUP($A35,'Onsite Role Distribution'!$B$3:$G$7,4,FALSE)+VLOOKUP($A35,'Onsite Role Distribution'!$B$8:$G$12,4,FALSE) -> 0 | AG35: =VLOOKUP($A35,'Onsite Role Distribution'!$B$3:$G$7,4,FALSE)+VLOOKUP($A35,'Onsite Role Distribution'!$B$8:$G$12,4,FALSE) -> 0 | AH35: =VLOOKUP($A35,'Onsite Role Distribution'!$B$3:$G$7,4,FALSE)+VLOOKUP($A35,'Onsite Role Distribution'!$B$8:$G$12,4,FALSE) -> 0 | AI35: =VLOOKUP($A35,'Onsite Role Distribution'!$B$3:$G$7,4,FALSE)+VLOOKUP($A35,'Onsite Role Distribution'!$B$8:$G$12,4,FALSE) -> 0 | ... AM35: =VLOOKUP($A35,'Onsite Role Distribution'!$B$3:$G$7,4,FALSE)+VLOOKUP($A35,'Onsite Role Distribution'!$B$8:$G$12,4,FALSE) -> 0 | AN35: =VLOOKUP($A35,'Onsite Role Distribution'!$B$3:$G$7,5,FALSE)+VLOOKUP($A35,'Onsite Role Distribution'!$B$8:$G$12,5,FALSE) -> 0 | AO35: =VLOOKUP($A35,'Onsite Role Distribution'!$B$3:$G$7,5,FALSE)+VLOOKUP($A35,'Onsite Role Distribution'!$B$8:$G$12,5,FALSE) -> 0 | AP35: =VLOOKUP($A35,'Onsite Role Distribution'!$B$3:$G$7,5,FALSE)+VLOOKUP($A35,'Onsite Role Distribution'!$B$8:$G$12,5,FALSE) -> 0 | AQ35: =VLOOKUP($A35,'Onsite Role Distribution'!$B$3:$G$7,5,FALSE)+VLOOKUP($A35,'Onsite Role Distribution'!$B$8:$G$12,5,FALSE) -> 0 | AR35: =VLOOKUP($A35,'Onsite Role Distribution'!$B$3:$G$7,5,FALSE)+VLOOKUP($A35,'Onsite Role Distribution'!$B$8:$G$12,5,FALSE) -> 0 | AS35: =VLOOKUP($A35,'Onsite Role Distribution'!$B$3:$G$7,5,FALSE)+VLOOKUP($A35,'Onsite Role Distribution'!$B$8:$G$12,5,FALSE) -> 0 | AT35: =VLOOKUP($A35,'Onsite Role Distribution'!$B$3:$G$7,5,FALSE)+VLOOKUP($A35,'Onsite Role Distribution'!$B$8:$G$12,5,FALSE) -> 0 | AU35: =VLOOKUP($A35,'Onsite Role Distribution'!$B$3:$G$7,5,FALSE)+VLOOKUP($A35,'Onsite Role Distribution'!$B$8:$G$12,5,FALSE) -> 0 | ... AY35: =VLOOKUP($A35,'Onsite Role Distribution'!$B$3:$G$7,5,FALSE)+VLOOKUP($A35,'Onsite Role Distribution'!$B$8:$G$12,5,FALSE) -> 0 | AZ35: =VLOOKUP($A35,'Onsite Role Distribution'!$B$3:$G$7,6,FALSE)+VLOOKUP($A35,'Onsite Role Distribution'!$B$8:$G$12,6,FALSE) -> 0 | BA35: =VLOOKUP($A35,'Onsite Role Distribution'!$B$3:$G$7,6,FALSE)+VLOOKUP($A35,'Onsite Role Distribution'!$B$8:$G$12,6,FALSE) -> 0 | BB35: =VLOOKUP($A35,'Onsite Role Distribution'!$B$3:$G$7,6,FALSE)+VLOOKUP($A35,'Onsite Role Distribution'!$B$8:$G$12,6,FALSE) -> 0 | BC35: =VLOOKUP($A35,'Onsite Role Distribution'!$B$3:$G$7,6,FALSE)+VLOOKUP($A35,'Onsite Role Distribution'!$B$8:$G$12,6,FALSE) -> 0 | BD35: =VLOOKUP($A35,'Onsite Role Distribution'!$B$3:$G$7,6,FALSE)+VLOOKUP($A35,'Onsite Role Distribution'!$B$8:$G$12,6,FALSE) -> 0 | BE35: =VLOOKUP($A35,'Onsite Role Distribution'!$B$3:$G$7,6,FALSE)+VLOOKUP($A35,'Onsite Role Distribution'!$B$8:$G$12,6,FALSE) -> 0 | BF35: =VLOOKUP($A35,'Onsite Role Distribution'!$B$3:$G$7,6,FALSE)+VLOOKUP($A35,'Onsite Role Distribution'!$B$8:$G$12,6,FALSE) -> 0 | BG35: =VLOOKUP($A35,'Onsite Role Distribution'!$B$3:$G$7,6,FALSE)+VLOOKUP($A35,'Onsite Role Distribution'!$B$8:$G$12,6,FALSE) -> 0 | ... BK35: =VLOOKUP($A35,'Onsite Role Distribution'!$B$3:$G$7,6,FALSE)+VLOOKUP($A35,'Onsite Role Distribution'!$B$8:$G$12,6,FALSE) -> 0
A36: Lead | B36: Onsite | C36: =A36&B36 -> LeadOnsite | D36: =VLOOKUP($A36,'Onsite Role Distribution'!$B$3:$G$7,2,FALSE)+VLOOKUP($A36,'Onsite Role Distribution'!$B$8:$G$12,2,FALSE) -> 1 | E36: =VLOOKUP($A36,'Onsite Role Distribution'!$B$3:$G$7,2,FALSE)+VLOOKUP($A36,'Onsite Role Distribution'!$B$8:$G$12,2,FALSE) -> 1 | F36: =VLOOKUP($A36,'Onsite Role Distribution'!$B$3:$G$7,2,FALSE)+VLOOKUP($A36,'Onsite Role Distribution'!$B$8:$G$12,2,FALSE) -> 1 | G36: =VLOOKUP($A36,'Onsite Role Distribution'!$B$3:$G$7,2,FALSE)+VLOOKUP($A36,'Onsite Role Distribution'!$B$8:$G$12,2,FALSE) -> 1 | H36: =VLOOKUP($A36,'Onsite Role Distribution'!$B$3:$G$7,2,FALSE)+VLOOKUP($A36,'Onsite Role Distribution'!$B$8:$G$12,2,FALSE) -> 1 | I36: =VLOOKUP($A36,'Onsite Role Distribution'!$B$3:$G$7,2,FALSE)+VLOOKUP($A36,'Onsite Role Distribution'!$B$8:$G$12,2,FALSE) -> 1 | J36: =VLOOKUP($A36,'Onsite Role Distribution'!$B$3:$G$7,2,FALSE)+VLOOKUP($A36,'Onsite Role Distribution'!$B$8:$G$12,2,FALSE) -> 1 | K36: =VLOOKUP($A36,'Onsite Role Distribution'!$B$3:$G$7,2,FALSE)+VLOOKUP($A36,'Onsite Role Distribution'!$B$8:$G$12,2,FALSE) -> 1 | ... O36: =VLOOKUP($A36,'Onsite Role Distribution'!$B$3:$G$7,2,FALSE)+VLOOKUP($A36,'Onsite Role Distribution'!$B$8:$G$12,2,FALSE) -> 1 | P36: =VLOOKUP($A36,'Onsite Role Distribution'!$B$3:$G$7,3,FALSE)+VLOOKUP($A36,'Onsite Role Distribution'!$B$8:$G$12,3,FALSE) -> 1 | Q36: =VLOOKUP($A36,'Onsite Role Distribution'!$B$3:$G$7,3,FALSE)+VLOOKUP($A36,'Onsite Role Distribution'!$B$8:$G$12,3,FALSE) -> 1 | R36: =VLOOKUP($A36,'Onsite Role Distribution'!$B$3:$G$7,3,FALSE)+VLOOKUP($A36,'Onsite Role Distribution'!$B$8:$G$12,3,FALSE) -> 1 | S36: =VLOOKUP($A36,'Onsite Role Distribution'!$B$3:$G$7,3,FALSE)+VLOOKUP($A36,'Onsite Role Distribution'!$B$8:$G$12,3,FALSE) -> 1 | T36: =VLOOKUP($A36,'Onsite Role Distribution'!$B$3:$G$7,3,FALSE)+VLOOKUP($A36,'Onsite Role Distribution'!$B$8:$G$12,3,FALSE) -> 1 | U36: =VLOOKUP($A36,'Onsite Role Distribution'!$B$3:$G$7,3,FALSE)+VLOOKUP($A36,'Onsite Role Distribution'!$B$8:$G$12,3,FALSE) -> 1 | V36: =VLOOKUP($A36,'Onsite Role Distribution'!$B$3:$G$7,3,FALSE)+VLOOKUP($A36,'Onsite Role Distribution'!$B$8:$G$12,3,FALSE) -> 1 | W36: =VLOOKUP($A36,'Onsite Role Distribution'!$B$3:$G$7,3,FALSE)+VLOOKUP($A36,'Onsite Role Distribution'!$B$8:$G$12,3,FALSE) -> 1 | ... AA36: =VLOOKUP($A36,'Onsite Role Distribution'!$B$3:$G$7,3,FALSE)+VLOOKUP($A36,'Onsite Role Distribution'!$B$8:$G$12,3,FALSE) -> 1 | AB36: =VLOOKUP($A36,'Onsite Role Distribution'!$B$3:$G$7,4,FALSE)+VLOOKUP($A36,'Onsite Role Distribution'!$B$8:$G$12,4,FALSE) -> 1 | AC36: =VLOOKUP($A36,'Onsite Role Distribution'!$B$3:$G$7,4,FALSE)+VLOOKUP($A36,'Onsite Role Distribution'!$B$8:$G$12,4,FALSE) -> 1 | AD36: =VLOOKUP($A36,'Onsite Role Distribution'!$B$3:$G$7,4,FALSE)+VLOOKUP($A36,'Onsite Role Distribution'!$B$8:$G$12,4,FALSE) -> 1 | AE36: =VLOOKUP($A36,'Onsite Role Distribution'!$B$3:$G$7,4,FALSE)+VLOOKUP($A36,'Onsite Role Distribution'!$B$8:$G$12,4,FALSE) -> 1 | AF36: =VLOOKUP($A36,'Onsite Role Distribution'!$B$3:$G$7,4,FALSE)+VLOOKUP($A36,'Onsite Role Distribution'!$B$8:$G$12,4,FALSE) -> 1 | AG36: =VLOOKUP($A36,'Onsite Role Distribution'!$B$3:$G$7,4,FALSE)+VLOOKUP($A36,'Onsite Role Distribution'!$B$8:$G$12,4,FALSE) -> 1 | AH36: =VLOOKUP($A36,'Onsite Role Distribution'!$B$3:$G$7,4,FALSE)+VLOOKUP($A36,'Onsite Role Distribution'!$B$8:$G$12,4,FALSE) -> 1 | AI36: =VLOOKUP($A36,'Onsite Role Distribution'!$B$3:$G$7,4,FALSE)+VLOOKUP($A36,'Onsite Role Distribution'!$B$8:$G$12,4,FALSE) -> 1 | ... AM36: =VLOOKUP($A36,'Onsite Role Distribution'!$B$3:$G$7,4,FALSE)+VLOOKUP($A36,'Onsite Role Distribution'!$B$8:$G$12,4,FALSE) -> 1 | AN36: =VLOOKUP($A36,'Onsite Role Distribution'!$B$3:$G$7,5,FALSE)+VLOOKUP($A36,'Onsite Role Distribution'!$B$8:$G$12,5,FALSE) -> 1 | AO36: =VLOOKUP($A36,'Onsite Role Distribution'!$B$3:$G$7,5,FALSE)+VLOOKUP($A36,'Onsite Role Distribution'!$B$8:$G$12,5,FALSE) -> 1 | AP36: =VLOOKUP($A36,'Onsite Role Distribution'!$B$3:$G$7,5,FALSE)+VLOOKUP($A36,'Onsite Role Distribution'!$B$8:$G$12,5,FALSE) -> 1 | AQ36: =VLOOKUP($A36,'Onsite Role Distribution'!$B$3:$G$7,5,FALSE)+VLOOKUP($A36,'Onsite Role Distribution'!$B$8:$G$12,5,FALSE) -> 1 | AR36: =VLOOKUP($A36,'Onsite Role Distribution'!$B$3:$G$7,5,FALSE)+VLOOKUP($A36,'Onsite Role Distribution'!$B$8:$G$12,5,FALSE) -> 1 | AS36: =VLOOKUP($A36,'Onsite Role Distribution'!$B$3:$G$7,5,FALSE)+VLOOKUP($A36,'Onsite Role Distribution'!$B$8:$G$12,5,FALSE) -> 1 | AT36: =VLOOKUP($A36,'Onsite Role Distribution'!$B$3:$G$7,5,FALSE)+VLOOKUP($A36,'Onsite Role Distribution'!$B$8:$G$12,5,FALSE) -> 1 | AU36: =VLOOKUP($A36,'Onsite Role Distribution'!$B$3:$G$7,5,FALSE)+VLOOKUP($A36,'Onsite Role Distribution'!$B$8:$G$12,5,FALSE) -> 1 | ... AY36: =VLOOKUP($A36,'Onsite Role Distribution'!$B$3:$G$7,5,FALSE)+VLOOKUP($A36,'Onsite Role Distribution'!$B$8:$G$12,5,FALSE) -> 1 | AZ36: =VLOOKUP($A36,'Onsite Role Distribution'!$B$3:$G$7,6,FALSE)+VLOOKUP($A36,'Onsite Role Distribution'!$B$8:$G$12,6,FALSE) -> 0 | BA36: =VLOOKUP($A36,'Onsite Role Distribution'!$B$3:$G$7,6,FALSE)+VLOOKUP($A36,'Onsite Role Distribution'!$B$8:$G$12,6,FALSE) -> 0 | BB36: =VLOOKUP($A36,'Onsite Role Distribution'!$B$3:$G$7,6,FALSE)+VLOOKUP($A36,'Onsite Role Distribution'!$B$8:$G$12,6,FALSE) -> 0 | BC36: =VLOOKUP($A36,'Onsite Role Distribution'!$B$3:$G$7,6,FALSE)+VLOOKUP($A36,'Onsite Role Distribution'!$B$8:$G$12,6,FALSE) -> 0 | BD36: =VLOOKUP($A36,'Onsite Role Distribution'!$B$3:$G$7,6,FALSE)+VLOOKUP($A36,'Onsite Role Distribution'!$B$8:$G$12,6,FALSE) -> 0 | BE36: =VLOOKUP($A36,'Onsite Role Distribution'!$B$3:$G$7,6,FALSE)+VLOOKUP($A36,'Onsite Role Distribution'!$B$8:$G$12,6,FALSE) -> 0 | BF36: =VLOOKUP($A36,'Onsite Role Distribution'!$B$3:$G$7,6,FALSE)+VLOOKUP($A36,'Onsite Role Distribution'!$B$8:$G$12,6,FALSE) -> 0 | BG36: =VLOOKUP($A36,'Onsite Role Distribution'!$B$3:$G$7,6,FALSE)+VLOOKUP($A36,'Onsite Role Distribution'!$B$8:$G$12,6,FALSE) -> 0 | ... BK36: =VLOOKUP($A36,'Onsite Role Distribution'!$B$3:$G$7,6,FALSE)+VLOOKUP($A36,'Onsite Role Distribution'!$B$8:$G$12,6,FALSE) -> 0
A37: BSA | B37: Onsite-Landed | C37: =A37&B37 -> BSAOnsite-Landed | D37: =VLOOKUP($A37,'Onsite Role Distribution'!$B$13:$G$17,2,FALSE) -> 2 | E37: =VLOOKUP($A37,'Onsite Role Distribution'!$B$13:$G$17,2,FALSE) -> 2 | F37: =VLOOKUP($A37,'Onsite Role Distribution'!$B$13:$G$17,2,FALSE) -> 2 | G37: =VLOOKUP($A37,'Onsite Role Distribution'!$B$13:$G$17,2,FALSE) -> 2 | H37: =VLOOKUP($A37,'Onsite Role Distribution'!$B$13:$G$17,2,FALSE) -> 2 | I37: =VLOOKUP($A37,'Onsite Role Distribution'!$B$13:$G$17,2,FALSE) -> 2 | J37: =VLOOKUP($A37,'Onsite Role Distribution'!$B$13:$G$17,2,FALSE) -> 2 | K37: =VLOOKUP($A37,'Onsite Role Distribution'!$B$13:$G$17,2,FALSE) -> 2 | ... O37: =VLOOKUP($A37,'Onsite Role Distribution'!$B$13:$G$17,2,FALSE) -> 2 | P37: =VLOOKUP($A37,'Onsite Role Distribution'!$B$13:$G$17,3,FALSE) -> 1 | Q37: =VLOOKUP($A37,'Onsite Role Distribution'!$B$13:$G$17,3,FALSE) -> 1 | R37: =VLOOKUP($A37,'Onsite Role Distribution'!$B$13:$G$17,3,FALSE) -> 1 | S37: =VLOOKUP($A37,'Onsite Role Distribution'!$B$13:$G$17,3,FALSE) -> 1 | T37: =VLOOKUP($A37,'Onsite Role Distribution'!$B$13:$G$17,3,FALSE) -> 1 | U37: =VLOOKUP($A37,'Onsite Role Distribution'!$B$13:$G$17,3,FALSE) -> 1 | V37: =VLOOKUP($A37,'Onsite Role Distribution'!$B$13:$G$17,3,FALSE) -> 1 | W37: =VLOOKUP($A37,'Onsite Role Distribution'!$B$13:$G$17,3,FALSE) -> 1 | ... AA37: =VLOOKUP($A37,'Onsite Role Distribution'!$B$13:$G$17,3,FALSE) -> 1 | AB37: =VLOOKUP($A37,'Onsite Role Distribution'!$B$13:$G$17,4,FALSE) -> 0 | AC37: =VLOOKUP($A37,'Onsite Role Distribution'!$B$13:$G$17,4,FALSE) -> 0 | AD37: =VLOOKUP($A37,'Onsite Role Distribution'!$B$13:$G$17,4,FALSE) -> 0 | AE37: =VLOOKUP($A37,'Onsite Role Distribution'!$B$13:$G$17,4,FALSE) -> 0 | AF37: =VLOOKUP($A37,'Onsite Role Distribution'!$B$13:$G$17,4,FALSE) -> 0 | AG37: =VLOOKUP($A37,'Onsite Role Distribution'!$B$13:$G$17,4,FALSE) -> 0 | AH37: =VLOOKUP($A37,'Onsite Role Distribution'!$B$13:$G$17,4,FALSE) -> 0 | AI37: =VLOOKUP($A37,'Onsite Role Distribution'!$B$13:$G$17,4,FALSE) -> 0 | ... AM37: =VLOOKUP($A37,'Onsite Role Distribution'!$B$13:$G$17,4,FALSE) -> 0 | AN37: =VLOOKUP($A37,'Onsite Role Distribution'!$B$13:$G$17,5,FALSE) -> 0 | AO37: =VLOOKUP($A37,'Onsite Role Distribution'!$B$13:$G$17,5,FALSE) -> 0 | AP37: =VLOOKUP($A37,'Onsite Role Distribution'!$B$13:$G$17,5,FALSE) -> 0 | AQ37: =VLOOKUP($A37,'Onsite Role Distribution'!$B$13:$G$17,5,FALSE) -> 0 | AR37: =VLOOKUP($A37,'Onsite Role Distribution'!$B$13:$G$17,5,FALSE) -> 0 | AS37: =VLOOKUP($A37,'Onsite Role Distribution'!$B$13:$G$17,5,FALSE) -> 0 | AT37: =VLOOKUP($A37,'Onsite Role Distribution'!$B$13:$G$17,5,FALSE) -> 0 | AU37: =VLOOKUP($A37,'Onsite Role Distribution'!$B$13:$G$17,5,FALSE) -> 0 | ... AY37: =VLOOKUP($A37,'Onsite Role Distribution'!$B$13:$G$17,5,FALSE) -> 0 | AZ37: =VLOOKUP($A37,'Onsite Role Distribution'!$B$13:$G$17,6,FALSE) -> 0 | BA37: =VLOOKUP($A37,'Onsite Role Distribution'!$B$13:$G$17,6,FALSE) -> 0 | BB37: =VLOOKUP($A37,'Onsite Role Distribution'!$B$13:$G$17,6,FALSE) -> 0 | BC37: =VLOOKUP($A37,'Onsite Role Distribution'!$B$13:$G$17,6,FALSE) -> 0 | BD37: =VLOOKUP($A37,'Onsite Role Distribution'!$B$13:$G$17,6,FALSE) -> 0 | BE37: =VLOOKUP($A37,'Onsite Role Distribution'!$B$13:$G$17,6,FALSE) -> 0 | BF37: =VLOOKUP($A37,'Onsite Role Distribution'!$B$13:$G$17,6,FALSE) -> 0 | BG37: =VLOOKUP($A37,'Onsite Role Distribution'!$B$13:$G$17,6,FALSE) -> 0 | ... BK37: =VLOOKUP($A37,'Onsite Role Distribution'!$B$13:$G$17,6,FALSE) -> 0
A38: Dev | B38: Onsite-Landed | C38: =A38&B38 -> DevOnsite-Landed | D38: =VLOOKUP($A38,'Onsite Role Distribution'!$B$13:$G$17,2,FALSE) -> 3 | E38: =VLOOKUP($A38,'Onsite Role Distribution'!$B$13:$G$17,2,FALSE) -> 3 | F38: =VLOOKUP($A38,'Onsite Role Distribution'!$B$13:$G$17,2,FALSE) -> 3 | G38: =VLOOKUP($A38,'Onsite Role Distribution'!$B$13:$G$17,2,FALSE) -> 3 | H38: =VLOOKUP($A38,'Onsite Role Distribution'!$B$13:$G$17,2,FALSE) -> 3 | I38: =VLOOKUP($A38,'Onsite Role Distribution'!$B$13:$G$17,2,FALSE) -> 3 | J38: =VLOOKUP($A38,'Onsite Role Distribution'!$B$13:$G$17,2,FALSE) -> 3 | K38: =VLOOKUP($A38,'Onsite Role Distribution'!$B$13:$G$17,2,FALSE) -> 3 | ... O38: =VLOOKUP($A38,'Onsite Role Distribution'!$B$13:$G$17,2,FALSE) -> 3 | P38: =VLOOKUP($A38,'Onsite Role Distribution'!$B$13:$G$17,3,FALSE) -> 1 | Q38: =VLOOKUP($A38,'Onsite Role Distribution'!$B$13:$G$17,3,FALSE) -> 1 | R38: =VLOOKUP($A38,'Onsite Role Distribution'!$B$13:$G$17,3,FALSE) -> 1 | S38: =VLOOKUP($A38,'Onsite Role Distribution'!$B$13:$G$17,3,FALSE) -> 1 | T38: =VLOOKUP($A38,'Onsite Role Distribution'!$B$13:$G$17,3,FALSE) -> 1 | U38: =VLOOKUP($A38,'Onsite Role Distribution'!$B$13:$G$17,3,FALSE) -> 1 | V38: =VLOOKUP($A38,'Onsite Role Distribution'!$B$13:$G$17,3,FALSE) -> 1 | W38: =VLOOKUP($A38,'Onsite Role Distribution'!$B$13:$G$17,3,FALSE) -> 1 | ... AA38: =VLOOKUP($A38,'Onsite Role Distribution'!$B$13:$G$17,3,FALSE) -> 1 | AB38: =VLOOKUP($A38,'Onsite Role Distribution'!$B$13:$G$17,4,FALSE) -> 1 | AC38: =VLOOKUP($A38,'Onsite Role Distribution'!$B$13:$G$17,4,FALSE) -> 1 | AD38: =VLOOKUP($A38,'Onsite Role Distribution'!$B$13:$G$17,4,FALSE) -> 1 | AE38: =VLOOKUP($A38,'Onsite Role Distribution'!$B$13:$G$17,4,FALSE) -> 1 | AF38: =VLOOKUP($A38,'Onsite Role Distribution'!$B$13:$G$17,4,FALSE) -> 1 | AG38: =VLOOKUP($A38,'Onsite Role Distribution'!$B$13:$G$17,4,FALSE) -> 1 | AH38: =VLOOKUP($A38,'Onsite Role Distribution'!$B$13:$G$17,4,FALSE) -> 1 | AI38: =VLOOKUP($A38,'Onsite Role Distribution'!$B$13:$G$17,4,FALSE) -> 1 | ... AM38: =VLOOKUP($A38,'Onsite Role Distribution'!$B$13:$G$17,4,FALSE) -> 1 | AN38: =VLOOKUP($A38,'Onsite Role Distribution'!$B$13:$G$17,5,FALSE) -> 1 | AO38: =VLOOKUP($A38,'Onsite Role Distribution'!$B$13:$G$17,5,FALSE) -> 1 | AP38: =VLOOKUP($A38,'Onsite Role Distribution'!$B$13:$G$17,5,FALSE) -> 1 | AQ38: =VLOOKUP($A38,'Onsite Role Distribution'!$B$13:$G$17,5,FALSE) -> 1 | AR38: =VLOOKUP($A38,'Onsite Role Distribution'!$B$13:$G$17,5,FALSE) -> 1 | AS38: =VLOOKUP($A38,'Onsite Role Distribution'!$B$13:$G$17,5,FALSE) -> 1 | AT38: =VLOOKUP($A38,'Onsite Role Distribution'!$B$13:$G$17,5,FALSE) -> 1 | AU38: =VLOOKUP($A38,'Onsite Role Distribution'!$B$13:$G$17,5,FALSE) -> 1 | ... AY38: =VLOOKUP($A38,'Onsite Role Distribution'!$B$13:$G$17,5,FALSE) -> 1 | AZ38: =VLOOKUP($A38,'Onsite Role Distribution'!$B$13:$G$17,6,FALSE) -> 1 | BA38: =VLOOKUP($A38,'Onsite Role Distribution'!$B$13:$G$17,6,FALSE) -> 1 | BB38: =VLOOKUP($A38,'Onsite Role Distribution'!$B$13:$G$17,6,FALSE) -> 1 | BC38: =VLOOKUP($A38,'Onsite Role Distribution'!$B$13:$G$17,6,FALSE) -> 1 | BD38: =VLOOKUP($A38,'Onsite Role Distribution'!$B$13:$G$17,6,FALSE) -> 1 | BE38: =VLOOKUP($A38,'Onsite Role Distribution'!$B$13:$G$17,6,FALSE) -> 1 | BF38: =VLOOKUP($A38,'Onsite Role Distribution'!$B$13:$G$17,6,FALSE) -> 1 | BG38: =VLOOKUP($A38,'Onsite Role Distribution'!$B$13:$G$17,6,FALSE) -> 1 | ... BK38: =VLOOKUP($A38,'Onsite Role Distribution'!$B$13:$G$17,6,FALSE) -> 1
